Workbook

Sheet 总表
A1: 2024年08月份LOS毛利表（海运）-68
A2: JOB | B2: 集装编号 | C2: 利润
A4: JOB080389 | B4: COLL004124 | C4: =SUM('JOB080389'!AF10) -> 36938.519
A9: JOB080353 | B9: COLL004085 | C9: =SUM('JOB080353'!AF17) -> 19429.606
A21: JOB080361 | B21: COLL004096 | C21: =SUM('JOB080361'!AF25) -> 19357.961
A42: JOB080362 | B42: COLL004097 | C42: =SUM('JOB080362'!AF9) -> 228.98845
A46: JOB080363 | B46: COLL004098 | C46: =SUM('JOB080363'!AF15) -> 12540.769
A56: JOB080364 | B56: COLL004100 | C56: =SUM('JOB080364'!AF17) -> 11502.074
A68: JOB080373 | B68: COLL004107 | C68: =SUM('JOB080373'!AF21) -> 8082.2163
A84: JOB080374 | B84: COLL004108 | C84: =SUM('JOB080374'!AF15) -> -11.172348
A94: JOB080371 | B94: COLL004105整柜 | C94: =SUM('JOB080371'!AF6) -> 96367.997
A95: JOB080387 | B95: COLL004121 | C95: =SUM('JOB080387'!AF24) -> 15283.59
A114: JOB100326 | B114: COLL004189 | C114: =SUM('JOB100326'!AF30) -> 8491.9024
A139: 合计 | C139: =SUM(C3:C138) -> 228212.45

Sheet 总表 (2)
A1: 2024年08月份LOS毛利表（海运）
A2: JOB | B2: 集装编号 | C2: 运单编号 | D2: 日期 | E2: 业务 | F2: 发货人 | G2: 收货人 | H2: 计费体积 | I2: 计费重量 | J2: 应 收 | Q2: 总应收 | R2: 起 运 港 成 本 | W2: 代垫运费 | X2: 起运港成本 合计 | Y2: 目的港成本 | AE2: 总支出 | AF2: 利润
J3: 应收RMB | K3: LOS Income(NGN)收到(奈拉) | L3: LOS 收到USD | M3: 美元汇率 dollar currency rate | N3: 应收 到付款USD | O3: 汇率 | P3: 人民币 | R3: 代理商 | S3: 运费+出口报关费 | T3: 提货费 | U3: 装卸费 | V3: 包装费 | Y3: 进口报关费 | Z3: 到门配送费 | AA3: 转运费 | AB3: 目的港支出 | AC3: 汇率 | AD3: 人民币 | AE3: 起运港+目的港
A4: JOB080389 | B4: COLL004124 | C4: 240708000003 | D4: 45491 | E4: 罗伟健 | F4: MailMail速运-演员 | G4: zeng hai | H4: 2.2272 | I4: 11222 | K4: 8906452 | M4: =SUM(K4/N4) -> 1620.0015 | N4: 5497.8047 | O4: 7.12 | P4: =SUM(N4*O4) -> 39144.369 | Q4: =SUM(P4:P8) -> 58091.472 | R4: 赛捷 | S4: =SUM(19204/9.8671)*H4 -> 4334.7234 | T4: =SUM(40.68/9.8671)*H4 -> 9.1822821 | V4: 350 | X4: =SUM(S4:W4) -> 4693.9056 | AA4: 100.29 | AB4: =SUM(Y4:AA4) -> 100.29 | AC4: 7.15 | AD4: =SUM(AB4*AC4) -> 717.0735 | AE4: =SUM(X4+AD4) -> 5410.9791 | AF4: =SUM(P4-AE4) -> 33733.39
C5: 240715000049 | D5: 45490 | E5: Sam.Pao | F5: Sam.Pao | G5: Yusky | H5: 0.4043 | I5: 55 | J5: 923.29 | P5: =SUBTOTAL(9,J5) -> 923.29 | S5: =SUM(19204/9.8671)*H5 -> 786.87529 | T5: =SUM(40.68/9.8671)*H5 -> 1.6668448 | X5: =SUM(S5:W5) -> 788.54214 | AB5: =SUM(Y5:AA5) -> 0 | AC5: 7.15 | AD5: =SUM(AB5*AC5) -> 0 | AE5: =SUM(X5+AD5) -> 788.54214 | AF5: =SUM(P5-AE5) -> 134.74786
C6: 240709000025 | D6: 45491 | E6: 黄颖 | F6: ying | G6: Huangpu | H6: 0.1112 | I6: 57 | J6: 556 | P6: =SUBTOTAL(9,J6) -> 556 | S6: =SUM(19204/9.8671)*H6 -> 216.42477 | T6: =SUM(40.68/9.8671)*H6 -> 0.45845446 | X6: =SUM(S6:W6) -> 216.88322 | Z6: 37.06 | AB6: =SUM(Y6:AA6) -> 37.06 | AC6: 7.15 | AD6: =SUM(AB6*AC6) -> 264.979 | AE6: =SUM(X6+AD6) -> 481.86222 | AF6: =SUM(P6-AE6) -> 74.13778
C7: 240713000006 | D7: 45491 | E7: 朱小飞 | F7: Isabel Zhu | G7: Anthonia | H7: 1.7306 | I7: 346 | J7: 5462 | P7: =SUM(J7) -> 5462 | S7: =SUM(19204/9.8671)*H7 -> 3368.2077 | T7: =SUM(40.68/9.8671)*H7 -> 7.1349037 | X7: =SUM(S7:W7) -> 3375.3426 | Z7: 70.8 | AB7: =SUM(Y7:AA7) -> 70.8 | AC7: 7.15 | AD7: =SUM(AB7*AC7) -> 506.22 | AE7: =SUM(X7+AD7) -> 3881.5626 | AF7: =SUM(P7-AE7) -> 1580.4374
C8: 240718000002 | D8: 45491 | E8: 罗伟健 | F8: MailMail速运-演员 | G8: zeng hai | H8: 5.3938 | I8: 1414 | K8: 2909624 | M8: =SUM(K8/N8) -> 1711 | N8: 1700.54 | O8: 7.06 | P8: =SUM(N8*O8) -> 12005.812 | S8: =SUM(19204/9.8671)*H8 -> 10497.769 | T8: =SUM(40.68/9.8671)*H8 -> 22.237515 | V8: 70 | X8: =SUM(S8:W8) -> 10590.006 | AB8: =SUM(Y8:AA8) -> 0 | AC8: 7.15 | AD8: =SUM(AB8*AC8) -> 0 | AE8: =SUM(X8+AD8) -> 10590.006 | AF8: =SUM(P8-AE8) -> 1415.806
A9: JOB080353 | B9: COLL004085 | C9: 240719000024 | D9: 45505 | E9: 吕沛霖 | F9: Paul | G9: Paul | H9: 0.0423 | I9: 12.5 | J9: 356 | P9: =SUBTOTAL(9,J9) -> 356 | Q9: =SUM(P9:P20) -> 156015.34 | R9: 华茂青松=56567 赛捷=1280 | S9: =SUM(57847/67.0927)*H9 -> 36.470855 | U9: =SUM(1400/67.0927)*H9 -> 0.88265937 | X9: =SUM(S9:W9) -> 37.353514 | Y9: =SUM(10235.99/67.0927)*H9 -> 6.4534946 | Z9: 9.09 | AB9: =SUM(Y9:AA9) -> 15.543495 | AC9: 7.08 | AD9: =SUM(AB9*AC9) -> 110.04794 | AE9: =SUM(X9+AD9) -> 147.40146 | AF9: =SUM(P9-AE9) -> 208.59854
C10: 240717000037 | D10: 45498 | E10: 朱小飞 | F10: Isabel Zhu | G10: Mr Michael | H10: 6.1861 | I10: 1004.71 | J10: 14822 | P10: =SUBTOTAL(9,J10) -> 14822 | S10: =SUM(57847/67.0927)*H10 -> 5333.6254 | U10: =SUM(1400/67.0927)*H10 -> 129.08319 | X10: =SUM(S10:W10) -> 5462.7086 | Y10: =SUM(10235.99/67.0927)*H10 -> 943.78163 | AB10: =SUM(Y10:AA10) -> 943.78163 | AC10: 7.08 | AD10: =SUM(AB10*AC10) -> 6681.9739 | AE10: =SUM(X10+AD10) -> 12144.682 | AF10: =SUM(P10-AE10) -> 2677.3175
C11: 240724000023 | D11: 45505 | E11: Sam.Pao | F11: Sam.Pao | G11: Yusky | H11: 0.158 | I11: 156 | J11: 337.92 | P11: =SUBTOTAL(9,J11) -> 337.92 | S11: =SUM(57847/67.0927)*H11 -> 136.22683 | U11: =SUM(1400/67.0927)*H11 -> 3.296931 | X11: =SUM(S11:W11) -> 139.52376 | Y11: =SUM(10235.99/67.0927)*H11 -> 24.105252 | AB11: =SUM(Y11:AA11) -> 24.105252 | AC11: 7.08 | AD11: =SUM(AB11*AC11) -> 170.66518 | AE11: =SUM(X11+AD11) -> 310.18895 | AF11: =SUM(P11-AE11) -> 27.731055
C12: 240718000039 | D12: 45511 | E12: 黄颖 | F12: ying | G12: Idris | H12: 0.5054 | I12: 412 | J12: 2582 | P12: =SUBTOTAL(9,J12) -> 2582 | S12: =SUM(57847/67.0927)*H12 -> 435.75342 | U12: =SUM(1400/67.0927)*H12 -> 10.546006 | X12: =SUM(S12:W12) -> 446.29943 | Y12: =SUM(10235.99/67.0927)*H12 -> 77.106292 | AB12: =SUM(Y12:AA12) -> 77.106292 | AC12: 7.08 | AD12: =SUM(AB12*AC12) -> 545.91255 | AE12: =SUM(X12+AD12) -> 992.21198 | AF12: =SUM(P12-AE12) -> 1589.788
C13: 240726000053 | D13: 45505 | E13: 朱小飞 | F13: Isabel Zhu | G13: Halifa Success | H13: 0.2452 | I13: 41 | J13: 611.38 | P13: =SUBTOTAL(9,J13) -> 611.38 | S13: =SUM(57847/67.0927)*H13 -> 211.41025 | U13: =SUM(1400/67.0927)*H13 -> 5.116503 | X13: =SUM(S13:W13) -> 216.52675 | Y13: =SUM(10235.99/67.0927)*H13 -> 37.40891 | AB13: =SUM(Y13:AA13) -> 37.40891 | AC13: 7.08 | AD13: =SUM(AB13*AC13) -> 264.85508 | AE13: =SUM(X13+AD13) -> 481.38183 | AF13: =SUM(P13-AE13) -> 129.99817
C14: 240727000003 | D14: 45505 | E14: Sam.Pao | F14: Sam.Pao | G14: Nick Wang | H14: 4.7589 | I14: 760 | J14: 17244.43 | P14: =SUBTOTAL(9,J14) -> 17244.43 | S14: =SUM(57847/67.0927)*H14 -> 4103.1005 | U14: =SUM(1400/67.0927)*H14 -> 99.302309 | X14: =SUM(S14:W14) -> 4202.4028 | Y14: =SUM(10235.99/67.0927)*H14 -> 726.04103 | Z14: 678.47 | AB14: =SUM(Y14:AA14) -> 1404.511 | AC14: 7.08 | AD14: =SUM(AB14*AC14) -> 9943.9381 | AE14: =SUM(X14+AD14) -> 14146.341 | AF14: =SUM(P14-AE14) -> 3098.0892
C15: 240729000009 | D15: 45505 | E15: 朱小飞 | F15: Isabel Zhu | G15: Joy | H15: 2.2224 | I15: 3202 | K15: 2787617 | M15: =SUM(K15/N15) -> 1741.2595 | N15: 1600.9199 | O15: 7.12 | P15: =SUM(N15*O15) -> 11398.55 | S15: =SUM(57847/67.0927)*H15 -> 1916.1425 | U15: =SUM(1400/67.0927)*H15 -> 46.374047 | X15: =SUM(S15:W15) -> 1962.5165 | Y15: =SUM(10235.99/67.0927)*H15 -> 339.0602 | AB15: =SUM(Y15:AA15) -> 339.0602 | AC15: 7.08 | AD15: =SUM(AB15*AC15) -> 2400.5462 | AE15: =SUM(X15+AD15) -> 4363.0627 | AF15: =SUM(P15-AE15) -> 7035.487
C16: 240729000055 | D16: 45505 | E16: 陆总 | F16: 喵喵速运-江 | G16: LUZHILONG | H16: 22.022 | I16: 12675 | J16: 54288.61 | P16: =SUBTOTAL(9,J16) -> 54288.61 | S16: =SUM(57847/67.0927)*H16 -> 18987.261 | U16: =SUM(1400/67.0927)*H16 -> 459.5254 | X16: =SUM(S16:W16) -> 19446.787 | Y16: =SUM(10235.99/67.0927)*H16 -> 3359.7839 | AB16: =SUM(Y16:AA16) -> 3359.7839 | AC16: 7.08 | AD16: =SUM(AB16*AC16) -> 23787.27 | AE16: =SUM(X16+AD16) -> 43234.057 | AF16: =SUM(P16-AE16) -> 11054.553
C17: 240730000017 | D17: 45505 | E17: Sam.Pao | F17: Sam.Pao | G17: MaiKaiNian | H17: 0.2622 | I17: 392 | J17: 1290.24 | P17: =SUBTOTAL(9,J17) -> 1290.24 | S17: =SUM(57847/67.0927)*H17 -> 226.06757 | U17: =SUM(1400/67.0927)*H17 -> 5.4712361 | X17: =SUM(S17:W17) -> 231.5388 | Y17: =SUM(10235.99/67.0927)*H17 -> 40.002513 | AB17: =SUM(Y17:AA17) -> 40.002513 | AC17: 7.08 | AD17: =SUM(AB17*AC17) -> 283.21779 | AE17: =SUM(X17+AD17) -> 514.75659 | AF17: =SUM(P17-AE17) -> 775.48341
C18: 240801000003 | D18: 45505 | E18: Sam.Pao | F18: Sam.Pao | G18: Yusky | H18: 2.1 | I18: 352 | J18: 4491.38 | P18: =SUBTOTAL(9,J18) -> 4491.38 | S18: =SUM(57847/67.0927)*H18 -> 1810.6098 | U18: =SUM(1400/67.0927)*H18 -> 43.819968 | X18: =SUM(S18:W18) -> 1854.4298 | Y18: =SUM(10235.99/67.0927)*H18 -> 320.38626 | AB18: =SUM(Y18:AA18) -> 320.38626 | AC18: 7.08 | AD18: =SUM(AB18*AC18) -> 2268.3347 | AE18: =SUM(X18+AD18) -> 4122.7645 | AF18: =SUM(P18-AE18) -> 368.61554
C19: 240801000001 | D19: 45506 | E19: Sam.Pao | F19: Sam.Pao | G19: SKY JET | H19: 28.4144 | I19: 2700 | J19: 48216.84 | P19: =SUBTOTAL(9,J19) -> 48216.84 | S19: =SUM(57847/67.0927)*H19 -> 24498.758 | U19: =SUM(1400/67.0927)*H19 -> 592.91339 | X19: =SUM(S19:W19) -> 25091.671 | Y19: =SUM(10235.99/67.0927)*H19 -> 4335.0396 | AB19: =SUM(Y19:AA19) -> 4335.0396 | AC19: 7.08 | AD19: =SUM(AB19*AC19) -> 30692.081 | AE19: =SUM(X19+AD19) -> 55783.752 | AF19: =SUM(P19-AE19) -> -7566.9117
C20: 240801000004 | D20: 45505 | E20: Sam.Pao | F20: Sam.Pao | G20: Yusky | H20: 0.1758 | I20: 34 | J20: 375.99 | P20: =SUBTOTAL(9,J20) -> 375.99 | S20: =SUM(57847/67.0927)*H20 -> 151.57391 | U20: =SUM(1400/67.0927)*H20 -> 3.6683574 | X20: =SUM(S20:W20) -> 155.24226 | Y20: =SUM(10235.99/67.0927)*H20 -> 26.820907 | AB20: =SUM(Y20:AA20) -> 26.820907 | AC20: 7.08 | AD20: =SUM(AB20*AC20) -> 189.89202 | AE20: =SUM(X20+AD20) -> 345.13428 | AF20: =SUM(P20-AE20) -> 30.855718
A21: JOB080361 | B21: COLL004096 | C21: 240707000004 | D21: 45506 | E21: Sam.Pao | F21: Sam.Pao | G21: ShanShan | H21: 9.3447 | I21: 5042.5 | J21: 28642.1 | P21: =SUBTOTAL(9,J21) -> 28642.1 | Q21: =SUM(P21:P40) -> 165882.73 | R21: 华茂青松=56567 赛捷=2300 | S21: =SUM(58867/68)*H21 -> 8089.6243 | U21: =SUM(2000/68)*H21 -> 274.84412 | X21: =SUM(S21:W21) -> 8364.4685 | Y21: =SUM(10117.99/68)*H21 -> 1390.435 | Z21: 88.5 | AA21: =SUM(91.45/68)*H21 -> 12.567247 | AB21: =SUM(Y21:AA21) -> 1491.5023 | AC21: 7.15 | AD21: =SUM(AB21*AC21) -> 10664.241 | AE21: =SUM(X21+AD21) -> 19028.71 | AF21: =SUM(P21-AE21) -> 9613.3904
C22: 240719000020 | D22: 45506 | E22: Sam.Pao | F22: Sam.Pao | G22: Wendy | H22: 0.645 | I22: 148 | J22: 2922.21 | P22: =SUBTOTAL(9,J22) -> 2922.21 | S22: =SUM(58867/68)*H22 -> 558.37081 | U22: =SUM(2000/68)*H22 -> 18.970588 | X22: =SUM(S22:W22) -> 577.3414 | Y22: =SUM(10117.99/68)*H22 -> 95.972111 | Z22: 160.91 | AA22: =SUM(91.45/68)*H22 -> 0.86743015 | AB22: =SUM(Y22:AA22) -> 257.74954 | AC22: 7.15 | AD22: =SUM(AB22*AC22) -> 1842.9092 | AE22: =SUM(X22+AD22) -> 2420.2506 | AF22: =SUM(P22-AE22) -> 501.95938
C23: 240719000037 | D23: 45506 | E23: 吕沛霖 | F23: 喵喵速运-Layne | G23: Hu Hai Liang | H23: 0.9193 | I23: 430 | K23: 579841.5 | M23: =SUM(K23/N23) -> 1744.5663 | N23: 332.37 | O23: 7.12 | P23: =SUM(N23*O23) -> 2366.4744 | S23: =SUM(58867/68)*H23 -> 795.8299 | U23: =SUM(2000/68)*H23 -> 27.038235 | X23: =SUM(S23:W23) -> 822.86813 | Y23: =SUM(10117.99/68)*H23 -> 136.7863 | AA23: =SUM(91.45/68)*H23 -> 1.2363233 | AB23: =SUM(Y23:AA23) -> 138.02262 | AC23: 7.15 | AD23: =SUM(AB23*AC23) -> 986.86174 | AE23: =SUM(X23+AD23) -> 1809.7299 | AF23: =SUM(P23-AE23) -> 556.74453
C24: 240723000028 | D24: 45506 | E24: 朱小飞 | F24: Isabel Zhu | G24: Musa Garuba | H24: 0.4159 | I24: 53.8 | K24: 286650 | M24: =SUM(K24/N24) -> 1750 | N24: 163.8 | O24: 7.12 | P24: =SUM(N24*O24) -> 1166.256 | S24: =SUM(58867/68)*H24 -> 360.04096 | U24: =SUM(2000/68)*H24 -> 12.232353 | X24: =SUM(S24:W24) -> 372.27331 | Y24: =SUM(10117.99/68)*H24 -> 61.883412 | AA24: =SUM(91.45/68)*H24 -> 0.55932434 | AB24: =SUM(Y24:AA24) -> 62.442737 | AC24: 7.15 | AD24: =SUM(AB24*AC24) -> 446.46557 | AE24: =SUM(X24+AD24) -> 818.73888 | AF24: =SUM(P24-AE24) -> 347.51712
C25: 240717000037 | D25: 45498 | E25: 朱小飞 | F25: Isabel Zhu | G25: Mr Michael | H25: 8.2 | I25: 882 | J25: 19661.07 | P25: =SUBTOTAL(9,J25) -> 19661.07 | S25: =SUM(58867/68)*H25 -> 7098.6676 | U25: =SUM(2000/68)*H25 -> 241.17647 | X25: =SUM(S25:W25) -> 7339.8441 | Y25: =SUM(10117.99/68)*H25 -> 1220.1106 | AA25: =SUM(91.45/68)*H25 -> 11.027794 | AB25: =SUM(Y25:AA25) -> 1231.1384 | AC25: 7.15 | AD25: =SUM(AB25*AC25) -> 8802.6392 | AE25: =SUM(X25+AD25) -> 16142.483 | AF25: =SUM(P25-AE25) -> 3518.5867
C26: 240718000039 | D26: 45511 | E26: 黄颖 | F26: ying | G26: Idris | H26: 2.7869 | I26: 2167 | J26: 14238 | P26: =SUBTOTAL(9,J26) -> 14238 | S26: =SUM(58867/68)*H26 -> 2412.5947 | U26: =SUM(2000/68)*H26 -> 81.967647 | X26: =SUM(S26:W26) -> 2494.5624 | Y26: =SUM(10117.99/68)*H26 -> 414.67392 | AA26: =SUM(91.45/68)*H26 -> 3.7479707 | AB26: =SUM(Y26:AA26) -> 418.42189 | AC26: 7.15 | AD26: =SUM(AB26*AC26) -> 2991.7165 | AE26: =SUM(X26+AD26) -> 5486.2789 | AF26: =SUM(P26-AE26) -> 8751.7211
C27: 240630000010 | D27: 45511 | E27: 吕沛霖 | F27: 喵喵速运-Layne | G27: WEI PING | H27: 1.6128 | I27: 637 | J27: 3432 | P27: =SUM(J27) -> 3432 | S27: =SUM(58867/68)*H27 -> 1396.1867 | U27: =SUM(2000/68)*H27 -> 47.435294 | X27: =SUM(S27:W27) -> 1443.622 | Y27: =SUM(10117.99/68)*H27 -> 239.97492 | AA27: =SUM(91.45/68)*H27 -> 2.1689788 | AB27: =SUM(Y27:AA27) -> 242.14389 | AC27: 7.15 | AD27: =SUM(AB27*AC27) -> 1731.3288 | AE27: =SUM(X27+AD27) -> 3174.9509 | AF27: =SUM(P27-AE27) -> 257.04913
C28: 240726000008 | D28: 45506 | E28: Bella | F28: Bella Chan | G28: zhong zi xin | H28: 0.835 | I28: 1254 | K28: 1830068.5 | M28: =SUM(K28/N28) -> 1711 | N28: 1069.59 | O28: 7.12 | P28: =SUM(N28*O28) -> 7615.4808 | S28: =SUM(58867/68)*H28 -> 722.85213 | U28: =SUM(2000/68)*H28 -> 24.558824 | X28: =SUM(S28:W28) -> 747.41096 | Y28: =SUM(10117.99/68)*H28 -> 124.24297 | Z28: 284.87 | AA28: =SUM(91.45/68)*H28 -> 1.1229522 | AB28: =SUM(Y28:AA28) -> 410.23592 | AC28: 7.15 | AD28: =SUM(AB28*AC28) -> 2933.1868 | AE28: =SUM(X28+AD28) -> 3680.5978 | AF28: =SUM(P28-AE28) -> 3934.883
C29: 240729000013 | D29: 45506 | E29: 朱小飞 | F29: Isabel Zhu | G29: Halifa Success | H29: 0.3557 | I29: 50 | J29: 801.54 | P29: =SUBTOTAL(9,J29) -> 801.54 | S29: =SUM(58867/68)*H29 -> 307.92635 | U29: =SUM(2000/68)*H29 -> 10.461765 | X29: =SUM(S29:W29) -> 318.38812 | Y29: =SUM(10117.99/68)*H29 -> 52.926015 | AA29: =SUM(91.45/68)*H29 -> 0.47836419 | AB29: =SUM(Y29:AA29) -> 53.40438 | AC29: 7.15 | AD29: =SUM(AB29*AC29) -> 381.84131 | AE29: =SUM(X29+AD29) -> 700.22943 | AF29: =SUM(P29-AE29) -> 101.31057
C30: 240724000026 | D30: 45506 | E30: Bella | F30: Bella Chan | G30: zhong zi xin | H30: 3.0722 | I30: 4949 | K30: 1723658 | M30: =SUM(K30/N30) -> 1711.0136 | N30: 1007.39 | O30: 7.12 | P30: =SUM(N30*O30) -> 7172.6168 | S30: =SUM(58867/68)*H30 -> 2659.5764 | U30: =SUM(2000/68)*H30 -> 90.358824 | X30: =SUM(S30:W30) -> 2749.9353 | Y30: =SUM(10117.99/68)*H30 -> 457.12484 | AA30: =SUM(91.45/68)*H30 -> 4.1316572 | AB30: =SUM(Y30:AA30) -> 461.25649 | AC30: 7.15 | AD30: =SUM(AB30*AC30) -> 3297.9839 | AE30: =SUM(X30+AD30) -> 6047.9192 | AF30: =SUM(P30-AE30) -> 1124.6976
C31: 240729000017 | D31: 45506 | E31: Bella | F31: Bella Chan | G31: zhang jian fei | H31: 1.1178 | I31: 1055 | K31: 776250 | M31: =SUM(K31/N31) -> 1725 | N31: 450 | O31: 7.12 | P31: =SUM(N31*O31) -> 3204 | S31: =SUM(58867/68)*H31 -> 967.6696 | U31: =SUM(2000/68)*H31 -> 32.876471 | X31: =SUM(S31:W31) -> 1000.5461 | Y31: =SUM(10117.99/68)*H31 -> 166.3219 | AA31: =SUM(91.45/68)*H31 -> 1.5032766 | AB31: =SUM(Y31:AA31) -> 167.82518 | AC31: 7.15 | AD31: =SUM(AB31*AC31) -> 1199.95 | AE31: =SUM(X31+AD31) -> 2200.4961 | AF31: =SUM(P31-AE31) -> 1003.5039
C32: 240729000020 | D32: 45506 | E32: 黄颖 | F32: ying | G32: zhounengquan | H32: 0.0032 | I32: 2.7 | J32: 235.2 | P32: =SUBTOTAL(9,J32) -> 235.2 | S32: =SUM(58867/68)*H32 -> 2.7702118 | U32: =SUM(2000/68)*H32 -> 0.094117647 | X32: =SUM(S32:W32) -> 2.8643294 | Y32: =SUM(10117.99/68)*H32 -> 0.47614071 | AA32: =SUM(91.45/68)*H32 -> 0.0043035294 | AB32: =SUM(Y32:AA32) -> 0.48044424 | AC32: 7.15 | AD32: =SUM(AB32*AC32) -> 3.4351763 | AE32: =SUM(X32+AD32) -> 6.2995057 | AF32: =SUM(P32-AE32) -> 228.90049
C33: 240730000010 | D33: 45506 | E33: 朱小飞 | F33: Isabel Zhu | G33: Halifa Success | H33: 3.0014 | I33: 502 | J33: 6679.5 | P33: =SUBTOTAL(9,J33) -> 6679.5 | S33: =SUM(58867/68)*H33 -> 2598.2855 | U33: =SUM(2000/68)*H33 -> 88.276471 | X33: =SUM(S33:W33) -> 2686.562 | Y33: =SUM(10117.99/68)*H33 -> 446.59022 | AA33: =SUM(91.45/68)*H33 -> 4.0364416 | AB33: =SUM(Y33:AA33) -> 450.62666 | AC33: 7.15 | AD33: =SUM(AB33*AC33) -> 3221.9807 | AE33: =SUM(X33+AD33) -> 5908.5426 | AF33: =SUM(P33-AE33) -> 770.95738
C34: 240731000038 | D34: 45506 | E34: 陆总 | F34: 喵喵速运-江 | G34: LUZHILONG | H34: 3.6015 | I34: 1074 | J34: 8038.58 | P34: =SUBTOTAL(9,J34) -> 8038.58 | S34: =SUM(58867/68)*H34 -> 3117.7868 | U34: =SUM(2000/68)*H34 -> 105.92647 | X34: =SUM(S34:W34) -> 3223.7132 | Y34: =SUM(10117.99/68)*H34 -> 535.88149 | AA34: =SUM(91.45/68)*H34 -> 4.8434879 | AB34: =SUM(Y34:AA34) -> 540.72497 | AC34: 7.15 | AD34: =SUM(AB34*AC34) -> 3866.1836 | AE34: =SUM(X34+AD34) -> 7089.8968 | AF34: =SUM(P34-AE34) -> 948.6832
C35: 240801000001 | D35: 45506 | E35: Sam.Pao | F35: Sam.Pao | G35: SKY JET | H35: 32.88 | I35: 4188 | J35: 51584.98 | P35: =SUBTOTAL(9,J35) -> 51584.98 | S35: =SUM(58867/68)*H35 -> 28463.926 | U35: =SUM(2000/68)*H35 -> 967.05882 | X35: =SUM(S35:W35) -> 29430.985 | Y35: =SUM(10117.99/68)*H35 -> 4892.3458 | AA35: =SUM(91.45/68)*H35 -> 44.218765 | AB35: =SUM(Y35:AA35) -> 4936.5645 | AC35: 7.15 | AD35: =SUM(AB35*AC35) -> 35296.436 | AE35: =SUM(X35+AD35) -> 64727.421 | AF35: =SUM(P35-AE35) -> -13142.441
C36: 240728000003 | D36: 45506 | E36: Sam.Pao | F36: Sam.Pao | G36: Nick Wang | H36: 0.2595 | I36: 100 | J36: 699 | P36: =SUBTOTAL(9,J36) -> 699 | S36: =SUM(58867/68)*H36 -> 224.64686 | U36: =SUM(2000/68)*H36 -> 7.6323529 | X36: =SUM(S36:W36) -> 232.27921 | Y36: =SUM(10117.99/68)*H36 -> 38.612035 | AA36: =SUM(91.45/68)*H36 -> 0.34898934 | AB36: =SUM(Y36:AA36) -> 38.961025 | AC36: 7.15 | AD36: =SUM(AB36*AC36) -> 278.57133 | AE36: =SUM(X36+AD36) -> 510.85054 | AF36: =SUM(P36-AE36) -> 188.14946
C37: 240801000022 | D37: 45506 | E37: Bella | F37: Bella Chan | G37: new hope 边鹏飞 | H37: 1.8732 | I37: 1420 | K37: 1129654.4 | M37: =SUM(K37/N37) -> 1739 | N37: 649.6 | O37: 7.06 | P37: =SUM(N37*O37) -> 4586.176 | S37: =SUM(58867/68)*H37 -> 1621.6127 | U37: =SUM(2000/68)*H37 -> 55.094118 | X37: =SUM(S37:W37) -> 1676.7068 | Y37: =SUM(10117.99/68)*H37 -> 278.72087 | AA37: =SUM(91.45/68)*H37 -> 2.5191785 | AB37: =SUM(Y37:AA37) -> 281.24004 | AC37: 7.15 | AD37: =SUM(AB37*AC37) -> 2010.8663 | AE37: =SUM(X37+AD37) -> 3687.5731 | AF37: =SUM(P37-AE37) -> 898.60285
C38: 240802000022 | D38: 45506 | E38: Sam.Pao | F38: Sam.Pao | G38: ShanShan | H38: 0.02 | I38: 5.5 | J38: 61.48 | P38: =SUBTOTAL(9,J38) -> 61.48 | S38: =SUM(58867/68)*H38 -> 17.313824 | U38: =SUM(2000/68)*H38 -> 0.58823529 | X38: =SUM(S38:W38) -> 17.902059 | Y38: =SUM(10117.99/68)*H38 -> 2.9758794 | AA38: =SUM(91.45/68)*H38 -> 0.026897059 | AB38: =SUM(Y38:AA38) -> 3.0027765 | AC38: 7.15 | AD38: =SUM(AB38*AC38) -> 21.469852 | AE38: =SUM(X38+AD38) -> 39.371911 | AF38: =SUM(P38-AE38) -> 22.108089
C39: 240802000026 | D39: 45506 | E39: 陆总 | F39: 喵喵速运-江 | G39: LUZHILONG | H39: 0.0391 | I39: 42.5 | J39: 98.57 | P39: =SUBTOTAL(9,J39) -> 98.57 | S39: =SUM(58867/68)*H39 -> 33.848525 | U39: =SUM(2000/68)*H39 -> 1.15 | X39: =SUM(S39:W39) -> 34.998525 | Y39: =SUM(10117.99/68)*H39 -> 5.8178443 | AA39: =SUM(91.45/68)*H39 -> 0.05258375 | AB39: =SUM(Y39:AA39) -> 5.870428 | AC39: 7.15 | AD39: =SUM(AB39*AC39) -> 41.97356 | AE39: =SUM(X39+AD39) -> 76.972085 | AF39: =SUM(P39-AE39) -> 21.597915
C40: 240802000029 | D40: 45506 | E40: Sam.Pao | F40: Sam.Pao | G40: Yusky | H40: 1.5074 | I40: 207 | J40: 2677.5 | P40: =SUBTOTAL(9,J40) -> 2677.5 | S40: =SUM(58867/68)*H40 -> 1304.9429 | U40: =SUM(2000/68)*H40 -> 44.335294 | X40: =SUM(S40:W40) -> 1349.2782 | Y40: =SUM(10117.99/68)*H40 -> 224.29203 | AA40: =SUM(91.45/68)*H40 -> 2.0272313 | AB40: =SUM(Y40:AA40) -> 226.31926 | AC40: 7.15 | AD40: =SUM(AB40*AC40) -> 1618.1827 | AE40: =SUM(X40+AD40) -> 2967.4609 | AF40: =SUM(P40-AE40) -> -289.9609
...

Sheet JOB080389
A1: 2024年08月份LOS毛利表（海运）
A2: PSL表 | B2: 体积cbm | C2: 9.8671
A3: JOB | B3: 集装编号 | C3: 运单编号 | D3: 日期 | E3: 业务 | F3: 发货人 | G3: 收货人 | H3: 计费体积 | I3: 计费重量 | J3: 应 收 | Q3: 总应收 | R3: 起 运 港 成 本 | W3: 代垫运费 | X3: 起运港成本 合计 | Y3: 目的港成本 | AE3: 总支出 | AF3: 利润
J4: 应收RMB | K4: LOS Income(NGN)收到(奈拉) | L4: LOS 收到USD | M4: 美元汇率 dollar currency rate | N4: 应收 到付款USD | O4: 汇率 | P4: 人民币 | R4: 代理商 | S4: 运费+出口报关费 | T4: 提货费 | U4: 装卸费 | V4: 包装费 | Y4: 进口报关费 | Z4: 到门配送费 | AA4: 转运费 | AB4: 目的港支出 | AC4: 汇率 | AD4: 人民币 | AE4: 起运港+目的港
A5: JOB080389 | B5: COLL004124 | C5: 240708000003 | D5: 45491 | E5: 罗伟健 | F5: MailMail速运-演员 | G5: zeng hai | H5: 2.2272 | I5: 11222 | K5: 8906452 | M5: =SUM(K5/N5) -> 1620.0015 | N5: 5497.8047 | O5: 7.12 | P5: =SUM(N5*O5) -> 39144.369 | Q5: =SUM(P5:P9) -> 58091.472 | R5: 赛捷 | S5: =SUM(19204/9.8671)*H5 -> 4334.7234 | T5: =SUM(40.68/9.8671)*H5 -> 9.1822821 | V5: 350 | X5: =SUM(S5:W5) -> 4693.9056 | AA5: 100.29 | AB5: =SUM(Y5:AA5) -> 100.29 | AC5: 7.15 | AD5: =SUM(AB5*AC5) -> 717.0735 | AE5: =SUM(X5+AD5) -> 5410.9791 | AF5: =SUM(P5-AE5) -> 33733.39
C6: 240715000049 | D6: 45490 | E6: Sam.Pao | F6: Sam.Pao | G6: Yusky | H6: 0.4043 | I6: 55 | J6: 923.29 | P6: =SUBTOTAL(9,J6) -> 923.29 | S6: =SUM(19204/9.8671)*H6 -> 786.87529 | T6: =SUM(40.68/9.8671)*H6 -> 1.6668448 | X6: =SUM(S6:W6) -> 788.54214 | AB6: =SUM(Y6:AA6) -> 0 | AC6: 7.15 | AD6: =SUM(AB6*AC6) -> 0 | AE6: =SUM(X6+AD6) -> 788.54214 | AF6: =SUM(P6-AE6) -> 134.74786
C7: 240709000025 | D7: 45491 | E7: 黄颖 | F7: ying | G7: Huangpu | H7: 0.1112 | I7: 57 | J7: 556 | P7: =SUBTOTAL(9,J7) -> 556 | S7: =SUM(19204/9.8671)*H7 -> 216.42477 | T7: =SUM(40.68/9.8671)*H7 -> 0.45845446 | X7: =SUM(S7:W7) -> 216.88322 | Z7: 37.06 | AB7: =SUM(Y7:AA7) -> 37.06 | AC7: 7.15 | AD7: =SUM(AB7*AC7) -> 264.979 | AE7: =SUM(X7+AD7) -> 481.86222 | AF7: =SUM(P7-AE7) -> 74.13778
C8: 240713000006 | D8: 45491 | E8: 朱小飞 | F8: Isabel Zhu | G8: Anthonia | H8: 1.7306 | I8: 346 | J8: 5462 | P8: =SUM(J8) -> 5462 | S8: =SUM(19204/9.8671)*H8 -> 3368.2077 | T8: =SUM(40.68/9.8671)*H8 -> 7.1349037 | X8: =SUM(S8:W8) -> 3375.3426 | Z8: 70.8 | AB8: =SUM(Y8:AA8) -> 70.8 | AC8: 7.15 | AD8: =SUM(AB8*AC8) -> 506.22 | AE8: =SUM(X8+AD8) -> 3881.5626 | AF8: =SUM(P8-AE8) -> 1580.4374
C9: 240718000002 | D9: 45491 | E9: 罗伟健 | F9: MailMail速运-演员 | G9: zeng hai | H9: 5.3938 | I9: 1414 | K9: 2909624 | M9: =SUM(K9/N9) -> 1711 | N9: 1700.54 | O9: 7.06 | P9: =SUM(N9*O9) -> 12005.812 | S9: =SUM(19204/9.8671)*H9 -> 10497.769 | T9: =SUM(40.68/9.8671)*H9 -> 22.237515 | V9: 70 | X9: =SUM(S9:W9) -> 10590.006 | AB9: =SUM(Y9:AA9) -> 0 | AC9: 7.15 | AD9: =SUM(AB9*AC9) -> 0 | AE9: =SUM(X9+AD9) -> 10590.006 | AF9: =SUM(P9-AE9) -> 1415.806
A10: 合计 | J10: =SUM(J4:J4) -> 0 | N10: =SUM(N4:N4) -> 0 | P10: =SUM(P4:P4) -> 0 | Q10: =SUM(Q4:Q4) -> 0 | X10: =SUM(X4:X4) -> 0 | AD10: =SUM(AD4:AD4) -> 0 | AF10: =SUM(AF4:AF9) -> 36938.519

Sheet JOB080353
A1: 2024年08月份LOS毛利表（海运）
A2: PSL表 | B2: 体积cbm | C2: 67.0927
A3: JOB | B3: 集装编号 | C3: 运单编号 | D3: 日期 | E3: 业务 | F3: 发货人 | G3: 收货人 | H3: 计费体积 | I3: 计费重量 | J3: 应 收 | Q3: 总应收 | R3: 起 运 港 成 本 | W3: 代垫运费 | X3: 起运港成本 合计 | Y3: 目的港成本 | AE3: 总支出 | AF3: 利润
J4: 应收RMB | K4: LOS Income(NGN)收到(奈拉) | L4: LOS 收到USD | M4: 美元汇率 dollar currency rate | N4: 应收 到付款USD | O4: 汇率 | P4: 人民币 | R4: 代理商 | S4: 运费+出口报关费 | T4: 提货费 | U4: 装卸费 | V4: 包装费 | Y4: 进口报关费 | Z4: 到门配送费 | AA4: 转运费 | AB4: 目的港支出 | AC4: 汇率 | AD4: 人民币 | AE4: 起运港+目的港
A5: JOB080353 | B5: COLL004085 | C5: 240719000024 | D5: 45505 | E5: 吕沛霖 | F5: Paul | G5: Paul | H5: 0.0423 | I5: 12.5 | J5: 356 | P5: =SUBTOTAL(9,J5) -> 356 | Q5: =SUM(P5:P16) -> 156015.34 | R5: 华茂青松=56567 赛捷=1280 | S5: =SUM(57847/67.0927)*H5 -> 36.470855 | U5: =SUM(1400/67.0927)*H5 -> 0.88265937 | X5: =SUM(S5:W5) -> 37.353514 | Y5: =SUM(10235.99/67.0927)*H5 -> 6.4534946 | Z5: 9.09 | AB5: =SUM(Y5:AA5) -> 15.543495 | AC5: 7.08 | AD5: =SUM(AB5*AC5) -> 110.04794 | AE5: =SUM(X5+AD5) -> 147.40146 | AF5: =SUM(P5-AE5) -> 208.59854
C6: 240717000037 | D6: 45498 | E6: 朱小飞 | F6: Isabel Zhu | G6: Mr Michael | H6: 6.1861 | I6: 1004.71 | J6: 14822 | P6: =SUBTOTAL(9,J6) -> 14822 | S6: =SUM(57847/67.0927)*H6 -> 5333.6254 | U6: =SUM(1400/67.0927)*H6 -> 129.08319 | X6: =SUM(S6:W6) -> 5462.7086 | Y6: =SUM(10235.99/67.0927)*H6 -> 943.78163 | AB6: =SUM(Y6:AA6) -> 943.78163 | AC6: 7.08 | AD6: =SUM(AB6*AC6) -> 6681.9739 | AE6: =SUM(X6+AD6) -> 12144.682 | AF6: =SUM(P6-AE6) -> 2677.3175
C7: 240724000023 | D7: 45505 | E7: Sam.Pao | F7: Sam.Pao | G7: Yusky | H7: 0.158 | I7: 156 | J7: 337.92 | P7: =SUBTOTAL(9,J7) -> 337.92 | S7: =SUM(57847/67.0927)*H7 -> 136.22683 | U7: =SUM(1400/67.0927)*H7 -> 3.296931 | X7: =SUM(S7:W7) -> 139.52376 | Y7: =SUM(10235.99/67.0927)*H7 -> 24.105252 | AB7: =SUM(Y7:AA7) -> 24.105252 | AC7: 7.08 | AD7: =SUM(AB7*AC7) -> 170.66518 | AE7: =SUM(X7+AD7) -> 310.18895 | AF7: =SUM(P7-AE7) -> 27.731055
C8: 240718000039 | D8: 45511 | E8: 黄颖 | F8: ying | G8: Idris | H8: 0.5054 | I8: 412 | J8: 2582 | P8: =SUBTOTAL(9,J8) -> 2582 | S8: =SUM(57847/67.0927)*H8 -> 435.75342 | U8: =SUM(1400/67.0927)*H8 -> 10.546006 | X8: =SUM(S8:W8) -> 446.29943 | Y8: =SUM(10235.99/67.0927)*H8 -> 77.106292 | AB8: =SUM(Y8:AA8) -> 77.106292 | AC8: 7.08 | AD8: =SUM(AB8*AC8) -> 545.91255 | AE8: =SUM(X8+AD8) -> 992.21198 | AF8: =SUM(P8-AE8) -> 1589.788
C9: 240726000053 | D9: 45505 | E9: 朱小飞 | F9: Isabel Zhu | G9: Halifa Success | H9: 0.2452 | I9: 41 | J9: 611.38 | P9: =SUBTOTAL(9,J9) -> 611.38 | S9: =SUM(57847/67.0927)*H9 -> 211.41025 | U9: =SUM(1400/67.0927)*H9 -> 5.116503 | X9: =SUM(S9:W9) -> 216.52675 | Y9: =SUM(10235.99/67.0927)*H9 -> 37.40891 | AB9: =SUM(Y9:AA9) -> 37.40891 | AC9: 7.08 | AD9: =SUM(AB9*AC9) -> 264.85508 | AE9: =SUM(X9+AD9) -> 481.38183 | AF9: =SUM(P9-AE9) -> 129.99817
C10: 240727000003 | D10: 45505 | E10: Sam.Pao | F10: Sam.Pao | G10: Nick Wang | H10: 4.7589 | I10: 760 | J10: 17244.43 | P10: =SUBTOTAL(9,J10) -> 17244.43 | S10: =SUM(57847/67.0927)*H10 -> 4103.1005 | U10: =SUM(1400/67.0927)*H10 -> 99.302309 | X10: =SUM(S10:W10) -> 4202.4028 | Y10: =SUM(10235.99/67.0927)*H10 -> 726.04103 | Z10: 678.47 | AB10: =SUM(Y10:AA10) -> 1404.511 | AC10: 7.08 | AD10: =SUM(AB10*AC10) -> 9943.9381 | AE10: =SUM(X10+AD10) -> 14146.341 | AF10: =SUM(P10-AE10) -> 3098.0892
C11: 240729000009 | D11: 45505 | E11: 朱小飞 | F11: Isabel Zhu | G11: Joy | H11: 2.2224 | I11: 3202 | K11: 2787617 | M11: =SUM(K11/N11) -> 1741.2595 | N11: 1600.9199 | O11: 7.12 | P11: =SUM(N11*O11) -> 11398.55 | S11: =SUM(57847/67.0927)*H11 -> 1916.1425 | U11: =SUM(1400/67.0927)*H11 -> 46.374047 | X11: =SUM(S11:W11) -> 1962.5165 | Y11: =SUM(10235.99/67.0927)*H11 -> 339.0602 | AB11: =SUM(Y11:AA11) -> 339.0602 | AC11: 7.08 | AD11: =SUM(AB11*AC11) -> 2400.5462 | AE11: =SUM(X11+AD11) -> 4363.0627 | AF11: =SUM(P11-AE11) -> 7035.487
C12: 240729000055 | D12: 45505 | E12: 陆总 | F12: 喵喵速运-江 | G12: LUZHILONG | H12: 22.022 | I12: 12675 | J12: 54288.61 | P12: =SUBTOTAL(9,J12) -> 54288.61 | S12: =SUM(57847/67.0927)*H12 -> 18987.261 | U12: =SUM(1400/67.0927)*H12 -> 459.5254 | X12: =SUM(S12:W12) -> 19446.787 | Y12: =SUM(10235.99/67.0927)*H12 -> 3359.7839 | AB12: =SUM(Y12:AA12) -> 3359.7839 | AC12: 7.08 | AD12: =SUM(AB12*AC12) -> 23787.27 | AE12: =SUM(X12+AD12) -> 43234.057 | AF12: =SUM(P12-AE12) -> 11054.553
C13: 240730000017 | D13: 45505 | E13: Sam.Pao | F13: Sam.Pao | G13: MaiKaiNian | H13: 0.2622 | I13: 392 | J13: 1290.24 | P13: =SUBTOTAL(9,J13) -> 1290.24 | S13: =SUM(57847/67.0927)*H13 -> 226.06757 | U13: =SUM(1400/67.0927)*H13 -> 5.4712361 | X13: =SUM(S13:W13) -> 231.5388 | Y13: =SUM(10235.99/67.0927)*H13 -> 40.002513 | AB13: =SUM(Y13:AA13) -> 40.002513 | AC13: 7.08 | AD13: =SUM(AB13*AC13) -> 283.21779 | AE13: =SUM(X13+AD13) -> 514.75659 | AF13: =SUM(P13-AE13) -> 775.48341
C14: 240801000003 | D14: 45505 | E14: Sam.Pao | F14: Sam.Pao | G14: Yusky | H14: 2.1 | I14: 352 | J14: 4491.38 | P14: =SUBTOTAL(9,J14) -> 4491.38 | S14: =SUM(57847/67.0927)*H14 -> 1810.6098 | U14: =SUM(1400/67.0927)*H14 -> 43.819968 | X14: =SUM(S14:W14) -> 1854.4298 | Y14: =SUM(10235.99/67.0927)*H14 -> 320.38626 | AB14: =SUM(Y14:AA14) -> 320.38626 | AC14: 7.08 | AD14: =SUM(AB14*AC14) -> 2268.3347 | AE14: =SUM(X14+AD14) -> 4122.7645 | AF14: =SUM(P14-AE14) -> 368.61554
C15: 240801000001 | D15: 45506 | E15: Sam.Pao | F15: Sam.Pao | G15: SKY JET | H15: 28.4144 | I15: 2700 | J15: 48216.84 | P15: =SUBTOTAL(9,J15) -> 48216.84 | S15: =SUM(57847/67.0927)*H15 -> 24498.758 | U15: =SUM(1400/67.0927)*H15 -> 592.91339 | X15: =SUM(S15:W15) -> 25091.671 | Y15: =SUM(10235.99/67.0927)*H15 -> 4335.0396 | AB15: =SUM(Y15:AA15) -> 4335.0396 | AC15: 7.08 | AD15: =SUM(AB15*AC15) -> 30692.081 | AE15: =SUM(X15+AD15) -> 55783.752 | AF15: =SUM(P15-AE15) -> -7566.9117
C16: 240801000004 | D16: 45505 | E16: Sam.Pao | F16: Sam.Pao | G16: Yusky | H16: 0.1758 | I16: 34 | J16: 375.99 | P16: =SUBTOTAL(9,J16) -> 375.99 | S16: =SUM(57847/67.0927)*H16 -> 151.57391 | U16: =SUM(1400/67.0927)*H16 -> 3.6683574 | X16: =SUM(S16:W16) -> 155.24226 | Y16: =SUM(10235.99/67.0927)*H16 -> 26.820907 | AB16: =SUM(Y16:AA16) -> 26.820907 | AC16: 7.08 | AD16: =SUM(AB16*AC16) -> 189.89202 | AE16: =SUM(X16+AD16) -> 345.13428 | AF16: =SUM(P16-AE16) -> 30.855718
A17: 合计 | J17: =SUM(J4:J4) -> 0 | N17: =SUM(N4:N4) -> 0 | P17: =SUM(P4:P4) -> 0 | Q17: =SUM(Q4:Q4) -> 0 | X17: =SUM(X4:X4) -> 0 | AD17: =SUM(AD4:AD4) -> 0 | AF17: =SUM(AF4:AF16) -> 19429.606

Sheet JOB080361
A1: 2024年08月份LOS毛利表（海运）
A2: PSL表 | B2: 体积cbm | C2: 72.4906
A3: JOB | B3: 集装编号 | C3: 运单编号 | D3: 日期 | E3: 业务 | F3: 发货人 | G3: 收货人 | H3: 计费体积 | I3: 计费重量 | J3: 应 收 | Q3: 总应收 | R3: 起 运 港 成 本 | W3: 代垫运费 | X3: 起运港成本 合计 | Y3: 目的港成本 | AE3: 总支出 | AF3: 利润
J4: 应收RMB | K4: LOS Income(NGN)收到(奈拉) | L4: LOS 收到USD | M4: 美元汇率 dollar currency rate | N4: 应收 到付款USD | O4: 汇率 | P4: 人民币 | R4: 代理商 | S4: 运费+出口报关费 | T4: 提货费 | U4: 装卸费 | V4: 包装费 | Y4: 进口报关费 | Z4: 到门配送费 | AA4: 转运费 | AB4: 目的港支出 | AC4: 汇率 | AD4: 人民币 | AE4: 起运港+目的港
A5: JOB080361 | B5: COLL004096 | C5: 240707000004 | D5: 45506 | E5: Sam.Pao | F5: Sam.Pao | G5: ShanShan | H5: 9.3447 | I5: 5042.5 | J5: 28642.1 | P5: =SUBTOTAL(9,J5) -> 28642.1 | Q5: =SUM(P5:P24) -> 165882.73 | R5: 华茂青松=56567 赛捷=2300 | S5: =SUM(58867/68)*H5 -> 8089.6243 | U5: =SUM(2000/68)*H5 -> 274.84412 | X5: =SUM(S5:W5) -> 8364.4685 | Y5: =SUM(10117.99/68)*H5 -> 1390.435 | Z5: 88.5 | AA5: =SUM(91.45/68)*H5 -> 12.567247 | AB5: =SUM(Y5:AA5) -> 1491.5023 | AC5: 7.15 | AD5: =SUM(AB5*AC5) -> 10664.241 | AE5: =SUM(X5+AD5) -> 19028.71 | AF5: =SUM(P5-AE5) -> 9613.3904
C6: 240719000020 | D6: 45506 | E6: Sam.Pao | F6: Sam.Pao | G6: Wendy | H6: 0.645 | I6: 148 | J6: 2922.21 | P6: =SUBTOTAL(9,J6) -> 2922.21 | S6: =SUM(58867/68)*H6 -> 558.37081 | U6: =SUM(2000/68)*H6 -> 18.970588 | X6: =SUM(S6:W6) -> 577.3414 | Y6: =SUM(10117.99/68)*H6 -> 95.972111 | Z6: 160.91 | AA6: =SUM(91.45/68)*H6 -> 0.86743015 | AB6: =SUM(Y6:AA6) -> 257.74954 | AC6: 7.15 | AD6: =SUM(AB6*AC6) -> 1842.9092 | AE6: =SUM(X6+AD6) -> 2420.2506 | AF6: =SUM(P6-AE6) -> 501.95938
C7: 240719000037 | D7: 45506 | E7: 吕沛霖 | F7: 喵喵速运-Layne | G7: Hu Hai Liang | H7: 0.9193 | I7: 430 | K7: 579841.5 | M7: =SUM(K7/N7) -> 1744.5663 | N7: 332.37 | O7: 7.12 | P7: =SUM(N7*O7) -> 2366.4744 | S7: =SUM(58867/68)*H7 -> 795.8299 | U7: =SUM(2000/68)*H7 -> 27.038235 | X7: =SUM(S7:W7) -> 822.86813 | Y7: =SUM(10117.99/68)*H7 -> 136.7863 | AA7: =SUM(91.45/68)*H7 -> 1.2363233 | AB7: =SUM(Y7:AA7) -> 138.02262 | AC7: 7.15 | AD7: =SUM(AB7*AC7) -> 986.86174 | AE7: =SUM(X7+AD7) -> 1809.7299 | AF7: =SUM(P7-AE7) -> 556.74453
C8: 240723000028 | D8: 45506 | E8: 朱小飞 | F8: Isabel Zhu | G8: Musa Garuba | H8: 0.4159 | I8: 53.8 | K8: 286650 | M8: =SUM(K8/N8) -> 1750 | N8: 163.8 | O8: 7.12 | P8: =SUM(N8*O8) -> 1166.256 | S8: =SUM(58867/68)*H8 -> 360.04096 | U8: =SUM(2000/68)*H8 -> 12.232353 | X8: =SUM(S8:W8) -> 372.27331 | Y8: =SUM(10117.99/68)*H8 -> 61.883412 | AA8: =SUM(91.45/68)*H8 -> 0.55932434 | AB8: =SUM(Y8:AA8) -> 62.442737 | AC8: 7.15 | AD8: =SUM(AB8*AC8) -> 446.46557 | AE8: =SUM(X8+AD8) -> 818.73888 | AF8: =SUM(P8-AE8) -> 347.51712
C9: 240717000037 | D9: 45498 | E9: 朱小飞 | F9: Isabel Zhu | G9: Mr Michael | H9: 8.2 | I9: 882 | J9: 19661.07 | P9: =SUBTOTAL(9,J9) -> 19661.07 | S9: =SUM(58867/68)*H9 -> 7098.6676 | U9: =SUM(2000/68)*H9 -> 241.17647 | X9: =SUM(S9:W9) -> 7339.8441 | Y9: =SUM(10117.99/68)*H9 -> 1220.1106 | AA9: =SUM(91.45/68)*H9 -> 11.027794 | AB9: =SUM(Y9:AA9) -> 1231.1384 | AC9: 7.15 | AD9: =SUM(AB9*AC9) -> 8802.6392 | AE9: =SUM(X9+AD9) -> 16142.483 | AF9: =SUM(P9-AE9) -> 3518.5867
C10: 240718000039 | D10: 45511 | E10: 黄颖 | F10: ying | G10: Idris | H10: 2.7869 | I10: 2167 | J10: 14238 | P10: =SUBTOTAL(9,J10) -> 14238 | S10: =SUM(58867/68)*H10 -> 2412.5947 | U10: =SUM(2000/68)*H10 -> 81.967647 | X10: =SUM(S10:W10) -> 2494.5624 | Y10: =SUM(10117.99/68)*H10 -> 414.67392 | AA10: =SUM(91.45/68)*H10 -> 3.7479707 | AB10: =SUM(Y10:AA10) -> 418.42189 | AC10: 7.15 | AD10: =SUM(AB10*AC10) -> 2991.7165 | AE10: =SUM(X10+AD10) -> 5486.2789 | AF10: =SUM(P10-AE10) -> 8751.7211
C11: 240630000010 | D11: 45511 | E11: 吕沛霖 | F11: 喵喵速运-Layne | G11: WEI PING | H11: 1.6128 | I11: 637 | J11: 3432 | P11: =SUM(J11) -> 3432 | S11: =SUM(58867/68)*H11 -> 1396.1867 | U11: =SUM(2000/68)*H11 -> 47.435294 | X11: =SUM(S11:W11) -> 1443.622 | Y11: =SUM(10117.99/68)*H11 -> 239.97492 | AA11: =SUM(91.45/68)*H11 -> 2.1689788 | AB11: =SUM(Y11:AA11) -> 242.14389 | AC11: 7.15 | AD11: =SUM(AB11*AC11) -> 1731.3288 | AE11: =SUM(X11+AD11) -> 3174.9509 | AF11: =SUM(P11-AE11) -> 257.04913
C12: 240726000008 | D12: 45506 | E12: Bella | F12: Bella Chan | G12: zhong zi xin | H12: 0.835 | I12: 1254 | K12: 1830068.5 | M12: =SUM(K12/N12) -> 1711 | N12: 1069.59 | O12: 7.12 | P12: =SUM(N12*O12) -> 7615.4808 | S12: =SUM(58867/68)*H12 -> 722.85213 | U12: =SUM(2000/68)*H12 -> 24.558824 | X12: =SUM(S12:W12) -> 747.41096 | Y12: =SUM(10117.99/68)*H12 -> 124.24297 | Z12: 284.87 | AA12: =SUM(91.45/68)*H12 -> 1.1229522 | AB12: =SUM(Y12:AA12) -> 410.23592 | AC12: 7.15 | AD12: =SUM(AB12*AC12) -> 2933.1868 | AE12: =SUM(X12+AD12) -> 3680.5978 | AF12: =SUM(P12-AE12) -> 3934.883
C13: 240729000013 | D13: 45506 | E13: 朱小飞 | F13: Isabel Zhu | G13: Halifa Success | H13: 0.3557 | I13: 50 | J13: 801.54 | P13: =SUBTOTAL(9,J13) -> 801.54 | S13: =SUM(58867/68)*H13 -> 307.92635 | U13: =SUM(2000/68)*H13 -> 10.461765 | X13: =SUM(S13:W13) -> 318.38812 | Y13: =SUM(10117.99/68)*H13 -> 52.926015 | AA13: =SUM(91.45/68)*H13 -> 0.47836419 | AB13: =SUM(Y13:AA13) -> 53.40438 | AC13: 7.15 | AD13: =SUM(AB13*AC13) -> 381.84131 | AE13: =SUM(X13+AD13) -> 700.22943 | AF13: =SUM(P13-AE13) -> 101.31057
C14: 240724000026 | D14: 45506 | E14: Bella | F14: Bella Chan | G14: zhong zi xin | H14: 3.0722 | I14: 4949 | K14: 1723658 | M14: =SUM(K14/N14) -> 1711.0136 | N14: 1007.39 | O14: 7.12 | P14: =SUM(N14*O14) -> 7172.6168 | S14: =SUM(58867/68)*H14 -> 2659.5764 | U14: =SUM(2000/68)*H14 -> 90.358824 | X14: =SUM(S14:W14) -> 2749.9353 | Y14: =SUM(10117.99/68)*H14 -> 457.12484 | AA14: =SUM(91.45/68)*H14 -> 4.1316572 | AB14: =SUM(Y14:AA14) -> 461.25649 | AC14: 7.15 | AD14: =SUM(AB14*AC14) -> 3297.9839 | AE14: =SUM(X14+AD14) -> 6047.9192 | AF14: =SUM(P14-AE14) -> 1124.6976
C15: 240729000017 | D15: 45506 | E15: Bella | F15: Bella Chan | G15: zhang jian fei | H15: 1.1178 | I15: 1055 | K15: 776250 | M15: =SUM(K15/N15) -> 1725 | N15: 450 | O15: 7.12 | P15: =SUM(N15*O15) -> 3204 | S15: =SUM(58867/68)*H15 -> 967.6696 | U15: =SUM(2000/68)*H15 -> 32.876471 | X15: =SUM(S15:W15) -> 1000.5461 | Y15: =SUM(10117.99/68)*H15 -> 166.3219 | AA15: =SUM(91.45/68)*H15 -> 1.5032766 | AB15: =SUM(Y15:AA15) -> 167.82518 | AC15: 7.15 | AD15: =SUM(AB15*AC15) -> 1199.95 | AE15: =SUM(X15+AD15) -> 2200.4961 | AF15: =SUM(P15-AE15) -> 1003.5039
C16: 240729000020 | D16: 45506 | E16: 黄颖 | F16: ying | G16: zhounengquan | H16: 0.0032 | I16: 2.7 | J16: 235.2 | P16: =SUBTOTAL(9,J16) -> 235.2 | S16: =SUM(58867/68)*H16 -> 2.7702118 | U16: =SUM(2000/68)*H16 -> 0.094117647 | X16: =SUM(S16:W16) -> 2.8643294 | Y16: =SUM(10117.99/68)*H16 -> 0.47614071 | AA16: =SUM(91.45/68)*H16 -> 0.0043035294 | AB16: =SUM(Y16:AA16) -> 0.48044424 | AC16: 7.15 | AD16: =SUM(AB16*AC16) -> 3.4351763 | AE16: =SUM(X16+AD16) -> 6.2995057 | AF16: =SUM(P16-AE16) -> 228.90049
C17: 240730000010 | D17: 45506 | E17: 朱小飞 | F17: Isabel Zhu | G17: Halifa Success | H17: 3.0014 | I17: 502 | J17: 6679.5 | P17: =SUBTOTAL(9,J17) -> 6679.5 | S17: =SUM(58867/68)*H17 -> 2598.2855 | U17: =SUM(2000/68)*H17 -> 88.276471 | X17: =SUM(S17:W17) -> 2686.562 | Y17: =SUM(10117.99/68)*H17 -> 446.59022 | AA17: =SUM(91.45/68)*H17 -> 4.0364416 | AB17: =SUM(Y17:AA17) -> 450.62666 | AC17: 7.15 | AD17: =SUM(AB17*AC17) -> 3221.9807 | AE17: =SUM(X17+AD17) -> 5908.5426 | AF17: =SUM(P17-AE17) -> 770.95738
C18: 240731000038 | D18: 45506 | E18: 陆总 | F18: 喵喵速运-江 | G18: LUZHILONG | H18: 3.6015 | I18: 1074 | J18: 8038.58 | P18: =SUBTOTAL(9,J18) -> 8038.58 | S18: =SUM(58867/68)*H18 -> 3117.7868 | U18: =SUM(2000/68)*H18 -> 105.92647 | X18: =SUM(S18:W18) -> 3223.7132 | Y18: =SUM(10117.99/68)*H18 -> 535.88149 | AA18: =SUM(91.45/68)*H18 -> 4.8434879 | AB18: =SUM(Y18:AA18) -> 540.72497 | AC18: 7.15 | AD18: =SUM(AB18*AC18) -> 3866.1836 | AE18: =SUM(X18+AD18) -> 7089.8968 | AF18: =SUM(P18-AE18) -> 948.6832
C19: 240801000001 | D19: 45506 | E19: Sam.Pao | F19: Sam.Pao | G19: SKY JET | H19: 32.88 | I19: 4188 | J19: 51584.98 | P19: =SUBTOTAL(9,J19) -> 51584.98 | S19: =SUM(58867/68)*H19 -> 28463.926 | U19: =SUM(2000/68)*H19 -> 967.05882 | X19: =SUM(S19:W19) -> 29430.985 | Y19: =SUM(10117.99/68)*H19 -> 4892.3458 | AA19: =SUM(91.45/68)*H19 -> 44.218765 | AB19: =SUM(Y19:AA19) -> 4936.5645 | AC19: 7.15 | AD19: =SUM(AB19*AC19) -> 35296.436 | AE19: =SUM(X19+AD19) -> 64727.421 | AF19: =SUM(P19-AE19) -> -13142.441
C20: 240728000003 | D20: 45506 | E20: Sam.Pao | F20: Sam.Pao | G20: Nick Wang | H20: 0.2595 | I20: 100 | J20: 699 | P20: =SUBTOTAL(9,J20) -> 699 | S20: =SUM(58867/68)*H20 -> 224.64686 | U20: =SUM(2000/68)*H20 -> 7.6323529 | X20: =SUM(S20:W20) -> 232.27921 | Y20: =SUM(10117.99/68)*H20 -> 38.612035 | AA20: =SUM(91.45/68)*H20 -> 0.34898934 | AB20: =SUM(Y20:AA20) -> 38.961025 | AC20: 7.15 | AD20: =SUM(AB20*AC20) -> 278.57133 | AE20: =SUM(X20+AD20) -> 510.85054 | AF20: =SUM(P20-AE20) -> 188.14946
C21: 240801000022 | D21: 45506 | E21: Bella | F21: Bella Chan | G21: new hope 边鹏飞 | H21: 1.8732 | I21: 1420 | K21: 1129654.4 | M21: =SUM(K21/N21) -> 1739 | N21: 649.6 | O21: 7.06 | P21: =SUM(N21*O21) -> 4586.176 | S21: =SUM(58867/68)*H21 -> 1621.6127 | U21: =SUM(2000/68)*H21 -> 55.094118 | X21: =SUM(S21:W21) -> 1676.7068 | Y21: =SUM(10117.99/68)*H21 -> 278.72087 | AA21: =SUM(91.45/68)*H21 -> 2.5191785 | AB21: =SUM(Y21:AA21) -> 281.24004 | AC21: 7.15 | AD21: =SUM(AB21*AC21) -> 2010.8663 | AE21: =SUM(X21+AD21) -> 3687.5731 | AF21: =SUM(P21-AE21) -> 898.60285
C22: 240802000022 | D22: 45506 | E22: Sam.Pao | F22: Sam.Pao | G22: ShanShan | H22: 0.02 | I22: 5.5 | J22: 61.48 | P22: =SUBTOTAL(9,J22) -> 61.48 | S22: =SUM(58867/68)*H22 -> 17.313824 | U22: =SUM(2000/68)*H22 -> 0.58823529 | X22: =SUM(S22:W22) -> 17.902059 | Y22: =SUM(10117.99/68)*H22 -> 2.9758794 | AA22: =SUM(91.45/68)*H22 -> 0.026897059 | AB22: =SUM(Y22:AA22) -> 3.0027765 | AC22: 7.15 | AD22: =SUM(AB22*AC22) -> 21.469852 | AE22: =SUM(X22+AD22) -> 39.371911 | AF22: =SUM(P22-AE22) -> 22.108089
C23: 240802000026 | D23: 45506 | E23: 陆总 | F23: 喵喵速运-江 | G23: LUZHILONG | H23: 0.0391 | I23: 42.5 | J23: 98.57 | P23: =SUBTOTAL(9,J23) -> 98.57 | S23: =SUM(58867/68)*H23 -> 33.848525 | U23: =SUM(2000/68)*H23 -> 1.15 | X23: =SUM(S23:W23) -> 34.998525 | Y23: =SUM(10117.99/68)*H23 -> 5.8178443 | AA23: =SUM(91.45/68)*H23 -> 0.05258375 | AB23: =SUM(Y23:AA23) -> 5.870428 | AC23: 7.15 | AD23: =SUM(AB23*AC23) -> 41.97356 | AE23: =SUM(X23+AD23) -> 76.972085 | AF23: =SUM(P23-AE23) -> 21.597915
C24: 240802000029 | D24: 45506 | E24: Sam.Pao | F24: Sam.Pao | G24: Yusky | H24: 1.5074 | I24: 207 | J24: 2677.5 | P24: =SUBTOTAL(9,J24) -> 2677.5 | S24: =SUM(58867/68)*H24 -> 1304.9429 | U24: =SUM(2000/68)*H24 -> 44.335294 | X24: =SUM(S24:W24) -> 1349.2782 | Y24: =SUM(10117.99/68)*H24 -> 224.29203 | AA24: =SUM(91.45/68)*H24 -> 2.0272313 | AB24: =SUM(Y24:AA24) -> 226.31926 | AC24: 7.15 | AD24: =SUM(AB24*AC24) -> 1618.1827 | AE24: =SUM(X24+AD24) -> 2967.4609 | AF24: =SUM(P24-AE24) -> -289.9609
A25: 合计 | J25: =SUM(J4:J4) -> 0 | N25: =SUM(N4:N4) -> 0 | P25: =SUM(P4:P4) -> 0 | Q25: =SUM(Q4:Q4) -> 0 | X25: =SUM(X4:X4) -> 0 | AD25: =SUM(AD4:AD4) -> 0 | AF25: =SUM(AF4:AF24) -> 19357.961

Sheet JOB080362
A1: 2024年08月份LOS毛利表（海运）
A2: PSL表 | B2: 体积cbm | C2: 70.927
A3: JOB | B3: 集装编号 | C3: 运单编号 | D3: 日期 | E3: 业务 | F3: 发货人 | G3: 收货人 | H3: 计费体积 | I3: 计费重量 | J3: 应 收 | Q3: 总应收 | R3: 起 运 港 成 本 | W3: 代垫运费 | X3: 起运港成本 合计 | Y3: 目的港成本 | AE3: 总支出 | AF3: 利润
J4: 应收RMB | K4: LOS Income(NGN)收到(奈拉) | L4: LOS 收到USD | M4: 美元汇率 dollar currency rate | N4: 应收 到付款USD | O4: 汇率 | P4: 人民币 | R4: 代理商 | S4: 运费+出口报关费 | T4: 提货费 | U4: 装卸费 | V4: 包装费 | Y4: 进口报关费 | Z4: 到门配送费 | AA4: 转运费 | AB4: 目的港支出 | AC4: 汇率 | AD4: 人民币 | AE4: 起运港+目的港
A5: JOB080362 | B5: COLL004097 | C5: 240804000005 | D5: 45511 | E5: 黄颖 | F5: ying | G5: Sunday Adelena | H5: 34.5199 | I5: 9224 | J5: 77059.62 | P5: =SUBTOTAL(9,J5) -> 77059.62 | Q5: =SUM(P5:P8) -> 141684.32 | R5: 赛捷=56732.25 赛捷=800 | S5: =SUM(57532.25/68)*H5 -> 29205.993 | U5: =SUM(1450/68)*H5 -> 736.0861 | X5: =SUM(S5:W5) -> 29942.079 | Y5: =SUM(10529/68)*H5 -> 5345.0004 | AA5: =SUM(206.48/68)*H5 -> 104.81866 | AB5: =SUM(Y5:AA5) -> 5449.8191 | AC5: 7.09 | AD5: =SUM(AB5*AC5) -> 38639.217 | AE5: =SUM(X5+AD5) -> 68581.296 | AF5: =SUM(P5-AE5) -> 8478.3239
C6: 240630000010 | D6: 45511 | E6: 吕沛霖 | F6: 喵喵速运-Layne | G6: WEI PING | H6: 1.5552 | I6: 912 | J6: 3309 | P6: =SUM(J6) -> 3309 | S6: =SUM(57532.25/68)*H6 -> 1315.7964 | U6: =SUM(1450/68)*H6 -> 33.162353 | X6: =SUM(S6:W6) -> 1348.9588 | Y6: =SUM(10529/68)*H6 -> 240.80442 | AA6: =SUM(206.48/68)*H6 -> 4.7223191 | AB6: =SUM(Y6:AA6) -> 245.52674 | AC6: 7.09 | AD6: =SUM(AB6*AC6) -> 1740.7846 | AE6: =SUM(X6+AD6) -> 3089.7434 | AF6: =SUM(P6-AE6) -> 219.25664
C7: 240806000035 | D7: 45511 | E7: Sam.Pao | F7: Sam.Pao | G7: SKY JET | H7: 34.38 | I7: 4304 | J7: 59321.31 | P7: =SUBTOTAL(9,J7) -> 59321.31 | S7: =SUM(57532.25/68)*H7 -> 29087.629 | U7: =SUM(1450/68)*H7 -> 733.10294 | X7: =SUM(S7:W7) -> 29820.732 | Y7: =SUM(10529/68)*H7 -> 5323.3385 | AA7: =SUM(206.48/68)*H7 -> 104.39386 | AB7: =SUM(Y7:AA7) -> 5427.7324 | AC7: 7.09 | AD7: =SUM(AB7*AC7) -> 38482.623 | AE7: =SUM(X7+AD7) -> 68303.354 | AF7: =SUM(P7-AE7) -> -8982.0443
C8: 240805000030 | D8: 45511 | E8: 朱小飞 | F8: Isabel Zhu | G8: Abdul Aziz | H8: 0.4717 | I8: 63 | J8: 1994.39 | P8: =SUBTOTAL(9,J8) -> 1994.39 | S8: =SUM(57532.25/68)*H8 -> 399.08768 | U8: =SUM(1450/68)*H8 -> 10.058309 | X8: =SUM(S8:W8) -> 409.14599 | Y8: =SUM(10529/68)*H8 -> 73.037196 | Z8: 76.7 | AA8: =SUM(206.48/68)*H8 -> 1.4323032 | AB8: =SUM(Y8:AA8) -> 151.1695 | AC8: 7.09 | AD8: =SUM(AB8*AC8) -> 1071.7917 | AE8: =SUM(X8+AD8) -> 1480.9377 | AF8: =SUM(P8-AE8) -> 513.45226
A9: 合计 | J9: =SUM(J4:J4) -> 0 | N9: =SUM(N4:N4) -> 0 | P9: =SUM(P4:P4) -> 0 | Q9: =SUM(Q4:Q4) -> 0 | X9: =SUM(X4:X4) -> 0 | AD9: =SUM(AD4:AD4) -> 0 | AF9: =SUM(AF4:AF8) -> 228.98845

Sheet JOB080363
A1: 2024年08月份LOS毛利表（海运）
A2: PSL表 | B2: 体积cbm | C2: 75.072
A3: JOB | B3: 集装编号 | C3: 运单编号 | D3: 日期 | E3: 业务 | F3: 发货人 | G3: 收货人 | H3: 计费体积 | I3: 计费重量 | J3: 应 收 | Q3: 总应收 | R3: 起 运 港 成 本 | W3: 代垫运费 | X3: 起运港成本 合计 | Y3: 目的港成本 | AE3: 总支出 | AF3: 利润
J4: 应收RMB | K4: LOS Income(NGN)收到(奈拉) | L4: LOS 收到USD | M4: 美元汇率 dollar currency rate | N4: 应收 到付款USD | O4: 汇率 | P4: 人民币 | R4: 代理商 | S4: 运费+出口报关费 | T4: 提货费 | U4: 装卸费 | V4: 包装费 | Y4: 进口报关费 | Z4: 到门配送费 | AA4: 转运费 | AB4: 目的港支出 | AC4: 汇率 | AD4: 人民币 | AE4: 起运港+目的港
A5: JOB080363 | B5: COLL004098 | C5: 240718000039 | D5: 45511 | E5: 黄颖 | F5: ying | G5: Idris | H5: 9.29 | I5: 13260 | J5: 47474 | P5: =SUBTOTAL(9,J5) -> 47474 | Q5: =SUM(P5:P14) -> 179665.7 | R5: 赛捷=56837.25 赛捷=2300 | S5: =SUM(59137.25/68)*H5 -> 8079.1919 | U5: =SUM(1450/68)*H5 -> 198.09559 | V5: 960 | X5: =SUM(S5:W5) -> 9237.2875 | Y5: =SUM(10529/68)*H5 -> 1438.4472 | Z5: 1823.01 | AA5: =SUM(259.58/68)*H5 -> 35.463209 | AB5: =SUM(Y5:AA5) -> 3296.9204 | AC5: 7.09 | AD5: =SUM(AB5*AC5) -> 23375.166 | AE5: =SUM(X5+AD5) -> 32612.453 | AF5: =SUM(P5-AE5) -> 14861.547
C6: 240724000012 | D6: 45511 | E6: Bella | F6: Bella Chan | G6: zhang yong chong | H6: 5.7046 | I6: 942 | J6: 14778 | P6: =SUBTOTAL(9,J6) -> 14778 | S6: =SUM(59137.25/68)*H6 -> 4961.0935 | U6: =SUM(1450/68)*H6 -> 121.64221 | V6: 1400 | X6: =SUM(S6:W6) -> 6482.7357 | Y6: =SUM(10529/68)*H6 -> 883.2902 | AA6: =SUM(259.58/68)*H6 -> 21.776472 | AB6: =SUM(Y6:AA6) -> 905.06667 | AC6: 7.09 | AD6: =SUM(AB6*AC6) -> 6416.9227 | AE6: =SUM(X6+AD6) -> 12899.658 | AF6: =SUM(P6-AE6) -> 1878.3416
C7: 240730000015 | D7: 45511 | E7: 黄颖 | F7: ying | G7: Huangpu | H7: 0.159 | I7: 26.5 | J7: 376.32 | P7: =SUBTOTAL(9,J7) -> 376.32 | S7: =SUM(59137.25/68)*H7 -> 138.27681 | U7: =SUM(1450/68)*H7 -> 3.3904412 | X7: =SUM(S7:W7) -> 141.66725 | Y7: =SUM(10529/68)*H7 -> 24.619279 | AA7: =SUM(259.58/68)*H7 -> 0.60695912 | AB7: =SUM(Y7:AA7) -> 25.226239 | AC7: 7.09 | AD7: =SUM(AB7*AC7) -> 178.85403 | AE7: =SUM(X7+AD7) -> 320.52128 | AF7: =SUM(P7-AE7) -> 55.798723
C8: 240801000020 | D8: 45512 | E8: 朱小飞 | F8: Isabel Zhu | G8: Mr Michael | H8: 5.1796 | I8: 572 | J8: 12648 | P8: =SUBTOTAL(9,J8) -> 12648 | S8: =SUM(59137.25/68)*H8 -> 4504.5191 | U8: =SUM(1450/68)*H8 -> 110.44735 | X8: =SUM(S8:W8) -> 4614.9665 | Y8: =SUM(10529/68)*H8 -> 802.00012 | AA8: =SUM(259.58/68)*H8 -> 19.772361 | AB8: =SUM(Y8:AA8) -> 821.77248 | AC8: 7.09 | AD8: =SUM(AB8*AC8) -> 5826.3669 | AE8: =SUM(X8+AD8) -> 10441.333 | AF8: =SUM(P8-AE8) -> 2206.6666
C9: 240630000010 | D9: 45534 | E9: 吕沛霖 | F9: 喵喵速运-Layne | G9: WEI PING | H9: 4.6083 | I9: 761.3 | J9: 9806 | P9: =SUM(J9) -> 9806 | S9: =SUM(59137.25/68)*H9 -> 4007.6793 | U9: =SUM(1450/68)*H9 -> 98.265221 | X9: =SUM(S9:W9) -> 4105.9445 | Y9: =SUM(10529/68)*H9 -> 713.54104 | AA9: =SUM(259.58/68)*H9 -> 17.591508 | AB9: =SUM(Y9:AA9) -> 731.13255 | AC9: 7.09 | AD9: =SUM(AB9*AC9) -> 5183.7298 | AE9: =SUM(X9+AD9) -> 9289.6742 | AF9: =SUM(P9-AE9) -> 516.32577
C10: 240728000003 | D10: 45506 | E10: Sam.Pao | F10: Sam.Pao | G10: Nick Wang | H10: 0.29 | I10: 135 | J10: 782 | P10: =SUBTOTAL(9,J10) -> 782 | S10: =SUM(59137.25/68)*H10 -> 252.20298 | U10: =SUM(1450/68)*H10 -> 6.1838235 | X10: =SUM(S10:W10) -> 258.3868 | Y10: =SUM(10529/68)*H10 -> 44.903088 | AA10: =SUM(259.58/68)*H10 -> 1.1070324 | AB10: =SUM(Y10:AA10) -> 46.010121 | AC10: 7.09 | AD10: =SUM(AB10*AC10) -> 326.21175 | AE10: =SUM(X10+AD10) -> 584.59856 | AF10: =SUM(P10-AE10) -> 197.40144
C11: 240730000035 | D11: 45511 | E11: 吕沛霖 | F11: 喵喵速运-Layne | G11: MR MANBO | H11: 1.0597 | I11: 336 | J11: 3645.46 | P11: =SUBTOTAL(9,J11) -> 3645.46 | S11: =SUM(59137.25/68)*H11 -> 921.58447 | U11: =SUM(1450/68)*H11 -> 22.596544 | X11: =SUM(S11:W11) -> 944.18101 | Y11: =SUM(10529/68)*H11 -> 164.08208 | Z11: 50.15 | AA11: =SUM(259.58/68)*H11 -> 4.0452489 | AB11: =SUM(Y11:AA11) -> 218.27733 | AC11: 7.09 | AD11: =SUM(AB11*AC11) -> 1547.5862 | AE11: =SUM(X11+AD11) -> 2491.7673 | AF11: =SUM(P11-AE11) -> 1153.6927
C12: 240802000009 | D12: 45511 | E12: Bella | F12: Bella Chan | G12: zhang long ting | H12: 0.1283 | I12: 12.76 | J12: 327.6 | P12: =SUBTOTAL(9,J12) -> 327.6 | S12: =SUM(59137.25/68)*H12 -> 111.57808 | U12: =SUM(1450/68)*H12 -> 2.7358088 | X12: =SUM(S12:W12) -> 114.31388 | Y12: =SUM(10529/68)*H12 -> 19.865746 | AA12: =SUM(259.58/68)*H12 -> 0.48976638 | AB12: =SUM(Y12:AA12) -> 20.355512 | AC12: 7.09 | AD12: =SUM(AB12*AC12) -> 144.32058 | AE12: =SUM(X12+AD12) -> 258.63446 | AF12: =SUM(P12-AE12) -> 68.965535
C13: 240804000004 | D13: 45511 | E13: 罗伟健 | F13: MailMail速运-演员 | G13: zeng hai | H13: 10.2324 | I13: 1319 | K13: 5637625 | M13: =SUM(K13/N13) -> 1710.9999 | N13: 3294.93 | O13: 7.06 | P13: =SUM(N13*O13) -> 23262.206 | S13: =SUM(59137.25/68)*H13 -> 8898.7647 | U13: =SUM(1450/68)*H13 -> 218.19088 | V13: 150 | X13: =SUM(S13:W13) -> 9266.9555 | Y13: =SUM(10529/68)*H13 -> 1584.3668 | AA13: =SUM(259.58/68)*H13 -> 39.060682 | AB13: =SUM(Y13:AA13) -> 1623.4274 | AC13: 7.09 | AD13: =SUM(AB13*AC13) -> 11510.101 | AE13: =SUM(X13+AD13) -> 20777.056 | AF13: =SUM(P13-AE13) -> 2485.1497
C14: 240806000035 | D14: 45511 | E14: Sam.Pao | F14: Sam.Pao | G14: SKY JET | H14: 38.42 | I14: 4700 | J14: 66566.11 | P14: =SUBTOTAL(9,J14) -> 66566.11 | S14: =SUM(59137.25/68)*H14 -> 33412.546 | U14: =SUM(1450/68)*H14 -> 819.25 | X14: =SUM(S14:W14) -> 34231.796 | Y14: =SUM(10529/68)*H14 -> 5948.885 | AA14: =SUM(259.58/68)*H14 -> 146.6627 | AB14: =SUM(Y14:AA14) -> 6095.5477 | AC14: 7.09 | AD14: =SUM(AB14*AC14) -> 43217.433 | AE14: =SUM(X14+AD14) -> 77449.229 | AF14: =SUM(P14-AE14) -> -10883.119
A15: 合计 | J15: =SUM(J4:J4) -> 0 | N15: =SUM(N4:N4) -> 0 | P15: =SUM(P4:P4) -> 0 | Q15: =SUM(Q4:Q4) -> 0 | X15: =SUM(X4:X4) -> 0 | AD15: =SUM(AD4:AD4) -> 0 | AF15: =SUM(AF4:AF14) -> 12540.769

Sheet JOB080364
A1: 2024年08月份LOS毛利表（海运）
A2: PSL表 | B2: 体积cbm | C2: 72.4244
A3: JOB | B3: 集装编号 | C3: 运单编号 | D3: 日期 | E3: 业务 | F3: 发货人 | G3: 收货人 | H3: 计费体积 | I3: 计费重量 | J3: 应 收 | Q3: 总应收 | R3: 起 运 港 成 本 | W3: 代垫运费 | X3: 起运港成本 合计 | Y3: 目的港成本 | AE3: 总支出 | AF3: 利润
J4: 应收RMB | K4: LOS Income(NGN)收到(奈拉) | L4: LOS 收到USD | M4: 美元汇率 dollar currency rate | N4: 应收 到付款USD | O4: 汇率 | P4: 人民币 | R4: 代理商 | S4: 运费+出口报关费 | T4: 提货费 | U4: 装卸费 | V4: 包装费 | Y4: 进口报关费 | Z4: 到门配送费 | AA4: 转运费 | AB4: 目的港支出 | AC4: 汇率 | AD4: 人民币 | AE4: 起运港+目的港
A5: JOB080364 | B5: COLL004100 | C5: 240801000020 | D5: 45512 | E5: 朱小飞 | F5: Isabel Zhu | G5: Mr Michael | H5: 5.7204 | I5: 603 | J5: 13956 | P5: =SUBTOTAL(9,J5) -> 13956 | Q5: =SUM(P5:P16) -> 154255.39 | R5: 赛捷=57732.25 赛捷=800 | S5: =SUM(58532.25/68)*H5 -> 4923.9395 | T5: =SUM(54.99/68)*H5 -> 4.6259529 | U5: =SUM(1000/68)*H5 -> 84.123529 | X5: =SUM(S5:W5) -> 5012.6889 | Y5: =SUM(10435/68)*H5 -> 877.82903 | AB5: =SUM(Y5:AA5) -> 877.82903 | AC5: 7.12 | AD5: =SUM(AB5*AC5) -> 6250.1427 | AE5: =SUM(X5+AD5) -> 11262.832 | AF5: =SUM(P5-AE5) -> 2693.1684
C6: 240802000002 | D6: 45512 | E6: 黄颖 | F6: ying | G6: huangzhaoyong | H6: 1.848 | I6: 1035 | J6: 4482.5 | P6: =SUBTOTAL(9,J6) -> 4482.5 | S6: =SUM(58532.25/68)*H6 -> 1590.7 | T6: =SUM(54.99/68)*H6 -> 1.4944341 | U6: =SUM(1000/68)*H6 -> 27.176471 | X6: =SUM(S6:W6) -> 1619.3709 | Y6: =SUM(10435/68)*H6 -> 283.58647 | AB6: =SUM(Y6:AA6) -> 283.58647 | AC6: 7.12 | AD6: =SUM(AB6*AC6) -> 2019.1357 | AE6: =SUM(X6+AD6) -> 3638.5065 | AF6: =SUM(P6-AE6) -> 843.99345
C7: 240803000005 | D7: 45512 | E7: Sam.Pao | F7: Sam.Pao | G7: Cherry | H7: 2.6248 | I7: 630 | J7: 6236.5 | P7: =SUBTOTAL(9,J7) -> 6236.5 | S7: =SUM(58532.25/68)*H7 -> 2259.3448 | T7: =SUM(54.99/68)*H7 -> 2.122614 | U7: =SUM(1000/68)*H7 -> 38.6 | X7: =SUM(S7:W7) -> 2300.0675 | Y7: =SUM(10435/68)*H7 -> 402.791 | AB7: =SUM(Y7:AA7) -> 402.791 | AC7: 7.12 | AD7: =SUM(AB7*AC7) -> 2867.8719 | AE7: =SUM(X7+AD7) -> 5167.9394 | AF7: =SUM(P7-AE7) -> 1068.5606
C8: 240803000017 | D8: 45512 | E8: 黄颖 | F8: ying | G8: Sunday Adelena | H8: 17.17 | I8: 12298 | J8: 38477.75 | P8: =SUBTOTAL(9,J8) -> 38477.75 | S8: =SUM(58532.25/68)*H8 -> 14779.393 | T8: =SUM(54.99/68)*H8 -> 13.884975 | U8: =SUM(1000/68)*H8 -> 252.5 | X8: =SUM(S8:W8) -> 15045.778 | Y8: =SUM(10435/68)*H8 -> 2634.8375 | AB8: =SUM(Y8:AA8) -> 2634.8375 | AC8: 7.12 | AD8: =SUM(AB8*AC8) -> 18760.043 | AE8: =SUM(X8+AD8) -> 33805.821 | AF8: =SUM(P8-AE8) -> 4671.9289
C9: 240807000012 | D9: 45512 | E9: Sam.Pao | F9: Sam.Pao | G9: Yusky | H9: 3.79 | I9: 780 | J9: 7638.75 | P9: =SUBTOTAL(9,J9) -> 7638.75 | S9: =SUM(58532.25/68)*H9 -> 3262.3122 | T9: =SUM(54.99/68)*H9 -> 3.0648838 | U9: =SUM(1000/68)*H9 -> 55.735294 | X9: =SUM(S9:W9) -> 3321.1123 | Y9: =SUM(10435/68)*H9 -> 581.59779 | AB9: =SUM(Y9:AA9) -> 581.59779 | AC9: 7.12 | AD9: =SUM(AB9*AC9) -> 4140.9763 | AE9: =SUM(X9+AD9) -> 7462.0886 | AF9: =SUM(P9-AE9) -> 176.66136
C10: 240808000010 | D10: 45512 | E10: Sam.Pao | F10: Sam.Pao | G10: SKY JET | H10: 9.8 | I10: 1059 | J10: 15645.79 | P10: =SUBTOTAL(9,J10) -> 15645.79 | S10: =SUM(58532.25/68)*H10 -> 8435.5301 | T10: =SUM(54.99/68)*H10 -> 7.9250294 | U10: =SUM(1000/68)*H10 -> 144.11765 | X10: =SUM(S10:W10) -> 8587.5728 | Y10: =SUM(10435/68)*H10 -> 1503.8676 | AB10: =SUM(Y10:AA10) -> 1503.8676 | AC10: 7.12 | AD10: =SUM(AB10*AC10) -> 10707.538 | AE10: =SUM(X10+AD10) -> 19295.11 | AF10: =SUM(P10-AE10) -> -3649.3205
C11: 240728000003 | D11: 45506 | E11: Sam.Pao | F11: Sam.Pao | G11: Nick Wang | H11: 0.632 | I11: 166 | J11: 1705 | P11: =SUBTOTAL(9,J11) -> 1705 | S11: =SUM(58532.25/68)*H11 -> 544.00562 | T11: =SUM(54.99/68)*H11 -> 0.51108353 | U11: =SUM(1000/68)*H11 -> 9.2941176 | X11: =SUM(S11:W11) -> 553.81082 | Y11: =SUM(10435/68)*H11 -> 96.984118 | AB11: =SUM(Y11:AA11) -> 96.984118 | AC11: 7.12 | AD11: =SUM(AB11*AC11) -> 690.52692 | AE11: =SUM(X11+AD11) -> 1244.3377 | AF11: =SUM(P11-AE11) -> 460.66226
C12: 240613000018 | D12: 45506 | E12: Sam.Pao | F12: Sam.Pao | G12: ChenGaoHong | H12: 1.6564 | I12: 313 | J12: 3117 | P12: =SUBTOTAL(9,J12) -> 3117 | S12: =SUM(58532.25/68)*H12 -> 1425.7767 | T12: =SUM(54.99/68)*H12 -> 1.3394917 | U12: =SUM(1000/68)*H12 -> 24.358824 | X12: =SUM(S12:W12) -> 1451.4751 | Y12: =SUM(10435/68)*H12 -> 254.18432 | AB12: =SUM(Y12:AA12) -> 254.18432 | AC12: 7.12 | AD12: =SUM(AB12*AC12) -> 1809.7924 | AE12: =SUM(X12+AD12) -> 3261.2674 | AF12: =SUM(P12-AE12) -> -144.26745
C13: 240808000011 | D13: 45534 | E13: Sam.Pao | F13: Sam.Pao | G13: Yusky | H13: 0.6332 | I13: 114 | J13: 1276.22 | P13: =SUBTOTAL(9,J13) -> 1276.22 | S13: =SUM(58532.25/68)*H13 -> 545.03854 | T13: =SUM(54.99/68)*H13 -> 0.51205394 | U13: =SUM(1000/68)*H13 -> 9.3117647 | X13: =SUM(S13:W13) -> 554.86236 | Y13: =SUM(10435/68)*H13 -> 97.168265 | AB13: =SUM(Y13:AA13) -> 97.168265 | AC13: 7.12 | AD13: =SUM(AB13*AC13) -> 691.83804 | AE13: =SUM(X13+AD13) -> 1246.7004 | AF13: =SUM(P13-AE13) -> 29.519597
C14: 240808000012 | D14: 45512 | E14: 吕沛霖 | F14: 喵喵速运-Layne | G14: YA | H14: 0.2465 | I14: 35.5 | J14: 821 | P14: =SUM(J14) -> 821 | S14: =SUM(58532.25/68)*H14 -> 212.17941 | T14: =SUM(54.99/68)*H14 -> 0.19933875 | U14: =SUM(1000/68)*H14 -> 3.625 | X14: =SUM(S14:W14) -> 216.00375 | Y14: =SUM(10435/68)*H14 -> 37.826875 | AA14: 22.18 | AB14: =SUM(Y14:AA14) -> 60.006875 | AC14: 7.12 | AD14: =SUM(AB14*AC14) -> 427.24895 | AE14: =SUM(X14+AD14) -> 643.2527 | AF14: =SUM(P14-AE14) -> 177.74731
C15: 240630000010 | D15: 45534 | E15: 吕沛霖 | F15: 喵喵速运-Layne | G15: WEI PING | H15: 20.8295 | I15: 1472 | J15: 44333.83 | P15: =SUM(J15) -> 44333.83 | S15: =SUM(58532.25/68)*H15 -> 17929.375 | T15: =SUM(54.99/68)*H15 -> 16.844327 | U15: =SUM(1000/68)*H15 -> 306.31618 | X15: =SUM(S15:W15) -> 18252.536 | Y15: =SUM(10435/68)*H15 -> 3196.4093 | AB15: =SUM(Y15:AA15) -> 3196.4093 | AC15: 7.12 | AD15: =SUM(AB15*AC15) -> 22758.434 | AE15: =SUM(X15+AD15) -> 41010.97 | AF15: =SUM(P15-AE15) -> 3322.8603
C16: 240808000019 | D16: 45512 | E16: 陆总 | F16: Sam.Pao | G16: LuZhiLong | H16: 7.4735 | I16: 1000 | J16: 16565.05 | P16: =SUBTOTAL(9,J16) -> 16565.05 | S16: =SUM(58532.25/68)*H16 -> 6432.9525 | T16: =SUM(54.99/68)*H16 -> 6.0436436 | U16: =SUM(1000/68)*H16 -> 109.90441 | X16: =SUM(S16:W16) -> 6548.9006 | Y16: =SUM(10435/68)*H16 -> 1146.8525 | AB16: =SUM(Y16:AA16) -> 1146.8525 | AC16: 7.12 | AD16: =SUM(AB16*AC16) -> 8165.5901 | AE16: =SUM(X16+AD16) -> 14714.491 | AF16: =SUM(P16-AE16) -> 1850.5594
A17: 合计 | J17: =SUM(J4:J4) -> 0 | N17: =SUM(N4:N4) -> 0 | P17: =SUM(P4:P4) -> 0 | Q17: =SUM(Q4:Q4) -> 0 | X17: =SUM(X4:X4) -> 0 | AD17: =SUM(AD4:AD4) -> 0 | AF17: =SUM(AF4:AF16) -> 11502.074

Sheet JOB080373
A1: 2024年08月份LOS毛利表（海运）
A2: PSL表 | B2: 体积cbm | C2: 76.3591
A3: JOB | B3: 集装编号 | C3: 运单编号 | D3: 日期 | E3: 业务 | F3: 发货人 | G3: 收货人 | H3: 计费体积 | I3: 计费重量 | J3: 应 收 | Q3: 总应收 | R3: 起 运 港 成 本 | W3: 代垫运费 | X3: 起运港成本 合计 | Y3: 目的港成本 | AE3: 总支出 | AF3: 利润
J4: 应收RMB | K4: LOS Income(NGN)收到(奈拉) | L4: LOS 收到USD | M4: 美元汇率 dollar currency rate | N4: 应收 到付款USD | O4: 汇率 | P4: 人民币 | R4: 代理商 | S4: 运费+出口报关费 | T4: 提货费 | U4: 装卸费 | V4: 包装费 | Y4: 进口报关费 | Z4: 到门配送费 | AA4: 转运费 | AB4: 目的港支出 | AC4: 汇率 | AD4: 人民币 | AE4: 起运港+目的港
A5: JOB080373 | B5: COLL004107 | C5: 240630000010 | D5: 45534 | E5: 吕沛霖 | F5: 喵喵速运-Layne | G5: WEI PING | H5: 4.5207 | I5: 744 | J5: 9620 | P5: =SUM(J5) -> 9620 | Q5: =SUM(P5:P20) -> 160773.2 | R5: 赛捷=56265.25 赛捷=1280 | S5: =SUM(57545.25/68)*H5 -> 3825.659 | U5: =SUM(2100/68)*H5 -> 139.60985 | V5: 900 | X5: =SUM(S5:W5) -> 4865.2688 | Y5: =SUM(10417/68)*H5 -> 692.53135 | Z5: 70.8 | AB5: =SUM(Y5:AA5) -> 763.33135 | AC5: 7.07 | AD5: =SUM(AB5*AC5) -> 5396.7527 | AE5: =SUM(X5+AD5) -> 10262.022 | AF5: =SUM(P5-AE5) -> -642.0215
C6: 240725000027 | D6: 45534 | E6: 黄颖 | F6: ying | G6: Huangpu | H6: 0.0213 | I6: 3.7 | K6: 85293 | M6: =SUM(K6/N6) -> 1730.4321 | N6: 49.29 | O6: 7.12 | P6: =SUM(N6*O6) -> 350.9448 | S6: =SUM(57545.25/68)*H6 -> 18.025203 | U6: =SUM(2100/68)*H6 -> 0.65779412 | X6: =SUM(S6:W6) -> 18.682997 | Y6: =SUM(10417/68)*H6 -> 3.2629721 | Z6: 7.25 | AB6: =SUM(Y6:AA6) -> 10.512972 | AC6: 7.07 | AD6: =SUM(AB6*AC6) -> 74.326712 | AE6: =SUM(X6+AD6) -> 93.00971 | AF6: =SUM(P6-AE6) -> 257.93509
C7: 240806000025 | D7: 45534 | E7: 吕沛霖 | F7: 喵喵速运-Layne | G7: FRANK | H7: 4.665 | I7: 886 | J7: 10755.219 | P7: =SUM(J7) -> 10755.219 | S7: =SUM(57545.25/68)*H7 -> 3947.7734 | U7: =SUM(2100/68)*H7 -> 144.06618 | X7: =SUM(S7:W7) -> 4091.8396 | Y7: =SUM(10417/68)*H7 -> 714.63684 | AB7: =SUM(Y7:AA7) -> 714.63684 | AC7: 7.07 | AD7: =SUM(AB7*AC7) -> 5052.4824 | AE7: =SUM(X7+AD7) -> 9144.322 | AF7: =SUM(P7-AE7) -> 1610.897
C8: 240807000004 | D8: 45534 | E8: 朱小飞 | F8: Isabel Zhu | G8: Inemesit udoh | H8: 2.4662 | I8: 160 | K8: 1842570 | M8: =SUM(K8/N8) -> 1735 | N8: 1062 | O8: 7.12 | P8: =SUM(N8*O8) -> 7561.44 | S8: =SUM(57545.25/68)*H8 -> 2087.0308 | U8: =SUM(2100/68)*H8 -> 76.162059 | X8: =SUM(S8:W8) -> 2163.1929 | Y8: =SUM(10417/68)*H8 -> 377.80008 | AB8: =SUM(Y8:AA8) -> 377.80008 | AC8: 7.07 | AD8: =SUM(AB8*AC8) -> 2671.0466 | AE8: =SUM(X8+AD8) -> 4834.2394 | AF8: =SUM(P8-AE8) -> 2727.2006
C9: 240807000010 | D9: 45534 | E9: 黄颖 | F9: ying | G9: Huangpu | H9: 0.0207 | I9: 4.2 | K9: 59049 | M9: =SUM(K9/N9) -> 1786.1162 | N9: 33.06 | O9: 7.12 | P9: =SUM(N9*O9) -> 235.3872 | S9: =SUM(57545.25/68)*H9 -> 17.517451 | U9: =SUM(2100/68)*H9 -> 0.63926471 | X9: =SUM(S9:W9) -> 18.156716 | Y9: =SUM(10417/68)*H9 -> 3.1710574 | Z9: 7.5 | AB9: =SUM(Y9:AA9) -> 10.671057 | AC9: 7.07 | AD9: =SUM(AB9*AC9) -> 75.444375 | AE9: =SUM(X9+AD9) -> 93.601091 | AF9: =SUM(P9-AE9) -> 141.78611
C10: 240808000002 | D10: 45534 | E10: 吕沛霖 | F10: 喵喵速运-Layne | G10: FRANK | H10: 2.1795 | I10: 785 | K10: 1256000 | M10: =SUM(K10/N10) -> 1751.89 | N10: 716.94 | O10: 7.15 | P10: =SUM(N10*O10) -> 5126.121 | S10: =SUM(57545.25/68)*H10 -> 1844.4099 | U10: =SUM(2100/68)*H10 -> 67.308088 | X10: =SUM(S10:W10) -> 1911.718 | Y10: =SUM(10417/68)*H10 -> 333.88017 | AB10: =SUM(Y10:AA10) -> 333.88017 | AC10: 7.07 | AD10: =SUM(AB10*AC10) -> 2360.5328 | AE10: =SUM(X10+AD10) -> 4272.2508 | AF10: =SUM(P10-AE10) -> 853.87023
C11: 240808000011 | D11: 45534 | E11: Sam.Pao | F11: Sam.Pao | G11: Yusky | H11: 1.8652 | I11: 420 | J11: 3624.06 | P11: =SUBTOTAL(9,J11) -> 3624.06 | S11: =SUM(57545.25/68)*H11 -> 1578.4324 | U11: =SUM(2100/68)*H11 -> 57.601765 | X11: =SUM(S11:W11) -> 1636.0341 | Y11: =SUM(10417/68)*H11 -> 285.73218 | AB11: =SUM(Y11:AA11) -> 285.73218 | AC11: 7.07 | AD11: =SUM(AB11*AC11) -> 2020.1265 | AE11: =SUM(X11+AD11) -> 3656.1607 | AF11: =SUM(P11-AE11) -> -32.100651
C12: 240728000003 | D12: 45506 | E12: Sam.Pao | F12: Sam.Pao | G12: Nick Wang | H12: 0.354 | I12: 131 | J12: 954 | P12: =SUBTOTAL(9,J12) -> 954 | S12: =SUM(57545.25/68)*H12 -> 299.5738 | U12: =SUM(2100/68)*H12 -> 10.932353 | X12: =SUM(S12:W12) -> 310.50615 | Y12: =SUM(10417/68)*H12 -> 54.229676 | AB12: =SUM(Y12:AA12) -> 54.229676 | AC12: 7.07 | AD12: =SUM(AB12*AC12) -> 383.40381 | AE12: =SUM(X12+AD12) -> 693.90997 | AF12: =SUM(P12-AE12) -> 260.09003
