Workbook

Sheet 黄颖
A1: LOS毛利表
A3: JOB | B3: 集装编号 | C3: 运单编号 | D3: 日期 | E3: 业务 | F3: 发货人 | G3: 收货人 | H3: 计费体积 | I3: 计费重量 | J3: 应 收 | Q3: 总应收 | R3: 起 运 港 成 本 | W3: 代垫运费 | X3: 起运港成本 合计 | Y3: 目的港成本 | AE3: 总支出 | AF3: 利润
J4: 应收RMB | K4: LOS Income(NGN)收到(奈拉) | L4: LOS 收到USD | M4: 美元汇率 dollar currency rate | N4: 应收 到付款USD | O4: 汇率 | P4: 人民币 | R4: 代理商 | S4: 运费+出口报关费 | T4: 提货费 | U4: 装卸费 | V4: 包装费 | Y4: 进口报关费 | Z4: 到门配送费 | AA4: 转运费 | AB4: 目的港支出 | AC4: 汇率 | AD4: 人民币 | AE4: 起运港+目的港
C5: 241123000017 | D5: 45631 | E5: 黄颖 | F5: ying | G5: Nura | H5: 0.3608 | I5: 202 | J5: 792 | P5: 792 | S5: 249.18148 | U5: 13.264706 | X5: 262.44619 | Y5: 58.794482 | AB5: 58.794482 | AC5: 7.24 | AD5: 425.67205 | AE5: 688.11824 | AF5: 103.88176
C6: 241125000061 | D6: 45631 | E6: 黄颖 | F6: ying | G6: makus | H6: 0.8795 | I6: 210 | J6: 2670.5 | P6: 2670.5 | S6: 607.41439 | U6: 32.334559 | X6: 639.74895 | Y6: 143.3197 | Z6: 104.36 | AB6: 247.6797 | AC6: 7.24 | AD6: 1793.201 | AE6: 2432.95 | AF6: 237.55004
C7: 241127000042 | D7: 45631 | E7: 黄颖 | F7: ying | G7: wangweijun | H7: 0.3625 | I7: 15 | J7: 870 | P7: 870 | S7: 250.35556 | U7: 13.327206 | W7: 62 | X7: 325.68277 | Y7: 59.071507 | AB7: 59.071507 | AC7: 7.24 | AD7: 427.67771 | AE7: 753.36048 | AF7: 116.63952
C8: 241127000053 | D8: 45631 | E8: 黄颖 | F8: ying | G8: baikaibo | H8: 0.6069 | I8: 165 | J8: 2195 | P8: 2195 | S8: 419.14701 | U8: 22.3125 | X8: 441.45951 | Y8: 98.897925 | Z8: 111.31 | AB8: 210.20792 | AC8: 7.24 | AD8: 1521.9054 | AE8: 1963.3649 | AF8: 231.63512
C9: 241128000041 | D9: 45631 | E9: 黄颖 | F9: ying | G9: linxiao | H9: 0.2074 | I9: 60 | J9: 463 | P9: 463 | S9: 143.23791 | U9: 7.625 | X9: 150.86291 | Y9: 33.79705 | AB9: 33.79705 | AC9: 7.24 | AD9: 244.69064 | AE9: 395.55355 | AF9: 67.446445
C10: 241129000035 | D10: 45631 | E10: 黄颖 | F10: ying | G10: liangdawei | H10: 0.3468 | I10: 269 | J10: 1003 | P10: 1003 | S10: 239.51257 | U10: 12.75 | X10: 252.26257 | Y10: 56.5131 | AB10: 56.5131 | AC10: 7.24 | AD10: 409.15484 | AE10: 661.41742 | AF10: 341.58258
C11: 241202000031 | D11: 45631 | E11: 黄颖 | F11: ying | G11: Jacky | H11: 0.6255 | I11: 265 | K11: 283185 | M11: 1588.5172 | N11: 178.27002 | O11: 7.27 | P11: 1296.023 | S11: 431.99284 | U11: 22.996324 | X11: 454.98916 | Y11: 101.9289 | AB11: 101.9289 | AC11: 7.24 | AD11: 737.96527 | AE11: 1192.9544 | AF11: 103.06862
C12: 241202000044 | D12: 45636 | E12: 黄颖 | F12: ying | G12: Jacky | H12: 3.774 | I12: 1521 | K12: 1698783.8 | M12: 1579.397 | N12: 1075.5901 | O12: 7.27 | P12: 7819.54 | S12: 2751.0518 | U12: 116.55 | X12: 2867.6017 | Y12: 645.0765 | AA12: 3.08691 | AB12: 648.16341 | AC12: 7.3 | AD12: 4731.5929 | AE12: 7599.1946 | AF12: 220.34538
C13: 241205000007 | D13: 45636 | E13: 黄颖 | F13: ying | G13: Jacky | H13: 1.2288 | I13: 508 | K13: 552776.25 | M13: 1578.4138 | N13: 350.20996 | O13: 7.27 | P13: 2546.0264 | S13: 895.73195 | U13: 37.948235 | X13: 933.68019 | Y13: 210.03445 | AA13: 1.0050861 | AB13: 211.03953 | AC13: 7.3 | AD13: 1540.5886 | AE13: 2474.2688 | AF13: 71.757629
A14: JOB120387 | B14: COLL004326 | C14: 241127000030 | D14: 45643 | E14: 黄颖 | F14: ying | G14: baikaibo | H14: 0.4598 | I14: 114 | J14: 860.5 | P14: 860.5 | Q14: 30945.687 | R14: 登凯=45460.5 报关=2800 拖车费=1670 杂费=86 过磅费=64 | S14: 338.63256 | U14: 13.523529 | X14: 352.15609 | Y14: 82.966853 | Z14: 76.28 | AA14: 0.374737 | AB14: 159.62159 | AC14: 7.25 | AD14: 1157.2565 | AE14: 1509.4126 | AF14: -648.91261
C15: 241209000092 | D15: 45643 | E15: 黄颖 | F15: ying | G15: yuhuichao | H15: 0.1652 | I15: 33 | J15: 565 | P15: 565 | S15: 121.66616 | U15: 4.8588235 | X15: 126.52498 | Y15: 29.808882 | Z15: 19.6 | AA15: 0.134638 | AB15: 49.54352 | AC15: 7.25 | AD15: 359.19052 | AE15: 485.7155 | AF15: 79.284498
C16: 241210000030 | D16: 45643 | E16: 黄颖 | F16: ying | G16: Frank | H16: 0.5114 | I16: 65 | K16: 312494 | M16: 1651.485 | N16: 189.22 | O16: 7.27 | P16: 1375.6294 | S16: 376.63482 | U16: 15.041176 | X16: 391.676 | Y16: 92.277618 | AA16: 0.416791 | AB16: 92.694409 | AC16: 7.25 | AD16: 672.03446 | AE16: 1063.7105 | AF16: 311.91894
C17: 241210000041 | D17: 45643 | E17: 黄颖 | F17: ying | G17: Mr Rell | H17: 0.7637 | I17: 207 | J17: 1810.4 | P17: 1810.4 | S17: 562.4482 | U17: 22.461765 | X17: 584.90997 | Y17: 137.80293 | AA17: 0.6224155 | AB17: 138.42534 | AC17: 7.25 | AD17: 1003.5837 | AE17: 1588.4937 | AF17: 221.9063
C18: 241212000006 | D18: 45643 | E18: 黄颖 | F18: ying | G18: MISS Huang | H18: 3.0701 | I18: 1383 | K18: 1406444 | M18: 1607.4013 | N18: 874.98 | O18: 7.3 | P18: 6387.354 | S18: 2261.0609 | U18: 90.297059 | X18: 2351.358 | Y18: 553.97246 | AA18: 2.5021315 | AB18: 556.47459 | AC18: 7.25 | AD18: 4034.4408 | AE18: 6385.7987 | AF18: 1.5552554
C19: 241213000032 | D19: 45643 | E19: 黄颖 | F19: ying | G19: sven | H19: 1.137 | I19: 240 | J19: 2906 | P19: 2906 | S19: 837.37542 | U19: 33.441176 | X19: 870.8166 | Y19: 205.16162 | Z19: 41.99 | AA19: 0.926655 | AB19: 248.07827 | AC19: 7.25 | AD19: 1798.5675 | AE19: 2669.3841 | AF19: 236.61593
C20: 241213000053 | D20: 45643 | E20: 黄颖 | F20: ying | G20: sven | H20: 0.0959 | I20: 16 | J20: 228 | P20: 228 | S20: 70.628235 | U20: 2.8205882 | X20: 73.448823 | Y20: 17.304309 | Z20: 35.58 | AA20: 0.0781585 | AB20: 52.962467 | AC20: 7.25 | AD20: 383.97789 | AE20: 457.42671 | AF20: -229.42671
C21: 241214000030 | D21: 45643 | E21: 黄颖 | F21: ying | G21: ss | H21: 0.823 | I21: 696 | J21: 3584 | P21: 3584 | S21: 606.12135 | U21: 24.205882 | X21: 630.32723 | Y21: 148.50309 | Z21: 136.53 | AA21: 0.670745 | AB21: 285.70383 | AC21: 7.25 | AD21: 2071.3528 | AE21: 2701.68 | AF21: 882.31998
C22: 241212000021 | D22: 45643 | E22: 黄颖 | F22: ying | G22: ss | H22: 1.9011 | I22: 816.18 | K22: 846007 | M22: 1561.4459 | N22: 541.81 | O22: 7.27 | P22: 3938.9587 | S22: 1400.1182 | U22: 55.914706 | X22: 1456.0329 | Y22: 343.03672 | AA22: 1.5493965 | AB22: 344.58612 | AC22: 7.25 | AD22: 2498.2493 | AE22: 3954.2823 | AF22: -15.323569
C23: 241209000079 | D23: 45643 | E23: 黄颖 | F23: ying | G23: fanglijuan | H23: 0.0757 | I23: 16 | J23: 195 | P23: 195 | S23: 55.75138 | U23: 2.2264706 | X23: 57.977851 | Y23: 13.659397 | AA23: 0.0616955 | AB23: 13.721093 | AC23: 7.25 | AD23: 99.477921 | AE23: 157.45577 | AF23: 37.544228
C24: 241217000024 | D24: 45643 | E24: 黄颖 | F24: ying | G24: wuchengxing | H24: 0.4017 | I24: 36 | J24: 876 | P24: 876 | S24: 295.84319 | U24: 11.814706 | X24: 307.65789 | Y24: 72.483221 | AA24: 0.3273855 | AB24: 72.810606 | AC24: 7.25 | AD24: 527.87689 | AE24: 835.53479 | AF24: 40.465211
A25: JOB120390 | B25: COLL004328 | C25: 241212000021 | D25: 46010 | E25: 黄颖 | F25: ying | G25: ss | H25: 0.1207 | I25: 51.82 | K25: 53713 | M25: 1561.4244 | N25: 34.4 | O25: 7.27 | P25: 250.088 | Q25: 37717.588 | R25: 登凯=45460.5 陆总=1500 拖车费=1670 杂费=86 过磅费=61 | S25: 86.580062 | T25: 0.157762 | U25: 3.3725 | X25: 90.110325 | Y25: 21.365675 | AA25: 0.102098 | AB25: 21.467773 | AC25: 7.25 | AD25: 155.64135 | AE25: 245.75168 | AF25: 4.3363213
C26: 241219000033 | D26: 46010 | E26: 黄颖 | F26: ying | G26: MISS Huang | H26: 15.7779 | I26: 9654 | J26: 37467.5 | P26: 37467.5 | S26: 11317.743 | T26: 20.622643 | U26: 440.85309 | X26: 11779.219 | Y26: 2792.9203 | AA26: 13.346247 | AB26: 2806.2666 | AC26: 7.25 | AD26: 20345.433 | AE26: 32124.651 | AF26: 5342.8487
C27: 241205000022 | D27: 46018 | E27: 黄颖 | F27: ying | G27: linxiao | H27: 1.5787 | I27: 305 | J27: 3483.9 | P27: 3483.9 | S27: 1175.0868 | U27: 48.753971 | X27: 1223.8407 | Y27: 267.4074 | AA27: 1.379273 | AB27: 268.78668 | AC27: 7.26 | AD27: 1951.3913 | AE27: 3175.232 | AF27: 308.66799
C28: 241210000059 | D28: 46018 | E28: 黄颖 | F28: ying | G28: linxiao | H28: 3.2498 | I28: 683 | K28: 1855578 | M28: 1576.5319 | N28: 1177 | O28: 7.22 | P28: 8497.94 | S28: 2418.9504 | U28: 100.36147 | X28: 2519.3119 | Y28: 550.46594 | Z28: 251.58 | AA28: 2.8392738 | AB28: 804.88521 | AC28: 7.26 | AD28: 5843.4666 | AE28: 8362.7785 | AF28: 135.16149
C29: 241218000004 | D29: 46018 | E29: 黄颖 | F29: ying | G29: ss | H29: 2.7589 | I29: 1023 | J29: 5703 | P29: 5703 | S29: 2053.5548 | U29: 85.201324 | X29: 2138.7561 | Y29: 467.31506 | AA29: 2.410386 | AB29: 469.72545 | AC29: 7.26 | AD29: 3410.2067 | AE29: 5548.9628 | AF29: 154.03719
C30: 241219000030 | D30: 46018 | E30: 黄颖 | F30: ying | G30: Nura | H30: 0.5462 | I30: 242 | J30: 1156 | P30: 1156 | S30: 406.55754 | U30: 16.867941 | X30: 423.42549 | Y30: 92.517846 | AA30: 0.47720209 | AB30: 92.995048 | AC30: 7.26 | AD30: 675.14405 | AE30: 1098.5695 | AF30: 57.430465
C31: 241216000051 | D31: 46018 | E31: 黄颖 | F31: ying | G31: Nura | H31: 13.6398 | I31: 2540 | J31: 28688 | P31: 28688 | S31: 10152.625 | U31: 421.22912 | X31: 10573.854 | Y31: 2310.3715 | AA31: 11.916772 | AB31: 2322.2883 | AC31: 7.26 | AD31: 16859.813 | AE31: 27433.667 | AF31: 1254.3333
C32: 241221000013 | D32: 46018 | E32: 黄颖 | F32: ying | G32: ss | H32: 2.0286 | I32: 791 | J32: 4194.5 | P32: 4194.5 | S32: 1509.9645 | U32: 62.647941 | X32: 1572.6125 | Y32: 343.61352 | AA32: 1.7723401 | AB32: 345.38586 | AC32: 7.26 | AD32: 2507.5013 | AE32: 4080.1138 | AF32: 114.3862
C33: 241222000003 | D33: 46018 | E33: 黄颖 | F33: ying | G33: ss | H33: 11.2441 | I33: 3412 | J33: 24501 | P33: 24501 | S33: 8369.4136 | U33: 347.24426 | X33: 8716.6578 | Y33: 1904.5769 | AA33: 9.8237056 | AB33: 1914.4006 | AC33: 7.26 | AD33: 13898.549 | AE33: 22615.206 | AF33: 1885.7937
C34: 241209000079 | D34: 46020 | E34: 黄颖 | F34: ying | G34: fanglijuan | H34: 3.7703 | I34: 879 | J34: 9709 | P34: 9709 | S34: 2782.8141 | U34: 99.802059 | X34: 2882.6161 | Y34: 617.83241 | AA34: 7.4352534 | AB34: 625.26766 | AC34: 7.25 | AD34: 4533.1905 | AE34: 7415.8067 | AF34: 2293.1933
A35: JOB0202178 | B35: COLL004395 | C35: 241124000003 | D35: 46018 | E35: 黄颖 | F35: ying | G35: MISS Huang | H35: 18.78 | I35: 11408 | J35: 37467.5 | P35: 37467.5 | Q35: 37467.5 | R35: 赛捷 | S35: 32772 | V35: 628.5 | X35: 33400.5 | AB35: 0 | AD35: 0 | AE35: 33400.5 | AF35: 4067
A36: 合 计 | H36: =SUM(H5:H35) -> 91.2918 | AF36: =SUM(AF5:AF35) -> 18029.043
C38: 基本任务：小于6千 | F38: 不够基本任务6千， 公司将根据空运提成里抽出补足基数 | K38: 黄颖 提成
K39: 名称 | L39: 计费体积 | M39: 毛利
C40: 基本任务：6千-3.5万 | F40: 按40%提成 | K40: LOS | L40: =SUM(H36) -> 91.2918 | M40: =SUM(AF36) -> 18029.043
K41: 基数 | M41: 6000
C42: 基本任务：3.5万以上 | F42: 按50%提成 | K42: 提成计数 | M42: =SUM(M40-M41) -> 12029.043
...

Sheet 三凤
A1: LOS毛利表
A2: JOB | B2: 集装编号 | C2: 运单编号 | D2: 日期 | E2: 业务 | F2: 发货人 | G2: 收货人 | H2: 计费体积 | I2: 计费重量 | J2: 应 收 | Q2: 总应收 | R2: 起 运 港 成 本 | W2: 代垫运费 | X2: 起运港成本 合计 | Y2: 目的港成本 | AE2: 总支出 | AF2: 利润
J3: 应收RMB | K3: LOS Income(NGN)收到(奈拉) | L3: LOS 收到USD | M3: 美元汇率 dollar currency rate | N3: 应收 到付款USD | O3: 汇率 | P3: 人民币 | R3: 代理商 | S3: 运费+出口报关费 | T3: 提货费 | U3: 装卸费 | V3: 包装费 | Y3: 进口报关费 | Z3: 到门配送费 | AA3: 转运费 | AB3: 目的港支出 | AC3: 汇率 | AD3: 人民币 | AE3: 起运港+目的港
C4: 241123000018 | D4: 45631 | E4: Bella | F4: Bella Chan | G4: zhong zi xin | H4: 11.1459 | I4: 16993 | J4: 36986 | P4: 36986 | S4: 7697.7601 | U4: 409.77574 | V4: 280 | X4: 8387.5359 | Y4: 1816.29 | Z4: 288.81 | AB4: 2105.1 | AC4: 7.24 | AD4: 15240.924 | AE4: 23628.46 | AF4: 13357.54
C5: 241203000015 | D5: 45636 | E5: Bella | F5: Bella Chan | G5: zhong zi xin | H5: 7.8671 | I5: 16682 | J5: 33835.5 | P5: 33835.5 | S5: 5734.711 | U5: 242.95456 | X5: 5977.6655 | Y5: 1344.6956 | AA5: 6.434825 | AB5: 1351.1305 | AC5: 7.3 | AD5: 9863.2524 | AE5: 15840.918 | AF5: 17994.582
C6: 241203000014 | D6: 45636 | E6: Bella | F6: Bella Chan | G6: zhong zi xin | H6: 13.3392 | I6: 17441 | J6: 35368.5 | P6: 35368.5 | S6: 9582.9401 | U6: 196.16471 | X6: 9779.1048 | Y6: 2269.6747 | AA6: 27.486599 | AB6: 2297.1613 | AC6: 7.25 | AD6: 16654.419 | AE6: 26433.524 | AF6: 8934.9758
C7: 241211000002 | D7: 45638 | E7: Bella | F7: Bella Chan | G7: zhong zi xin | H7: 13.0793 | I7: 19192 | J7: 38909 | P7: 38909 | S7: 9378.5313 | U7: 346.21676 | X7: 9724.7481 | Y7: 2235.4005 | AA7: 26.951052 | AB7: 2262.3515 | AC7: 7.25 | AD7: 16402.049 | AE7: 26126.797 | AF7: 12782.203
C8: 241227000020 | D8: 46020 | E8: Bella | F8: Bella Chan | G8: zhong zi xin | H8: 13.5726 | I8: 6092 | J8: 27674.5 | P8: 27674.5 | S8: 10017.776 | U8: 359.27471 | X8: 10377.051 | Y8: 2224.118 | AA8: 26.765966 | AB8: 2250.884 | AC8: 7.25 | AD8: 16318.909 | AE8: 26695.96 | AF8: 978.54009 | AG8: =SUM(AF4:AF8) -> 54047.842
C9: 241120000012 | D9: 45631 | E9: Bella | F9: Bella Chan | G9: FENG | H9: 0.1878 | I9: 62 | K9: 94651.2 | M9: 1680.0001 | N9: 56.339996 | O9: 7.3 | P9: 411.28197 | S9: 129.70145 | U9: 6.9044118 | X9: 136.60586 | Y9: 30.603115 | AB9: 30.603115 | AC9: 7.24 | AD9: 221.56655 | AE9: 358.17241 | AF9: 53.109562 | AG9: =SUM(AG8/2) -> 27023.921
C10: 241128000012 | D10: 45636 | E10: Bella | F10: Bella Chan | G10: FENG | H10: 0.196 | I10: 106 | K10: 98784 | M10: 1679.9994 | N10: 58.80002 | O10: 7.3 | P10: 429.24015 | S10: 142.87391 | U10: 6.0529412 | X10: 148.92685 | Y10: 33.501588 | AA10: 0.16031647 | AB10: 33.661905 | AC10: 7.3 | AD10: 245.7319 | AE10: 394.65876 | AF10: 34.581389
A11: JOB120399 | B11: COLL004330 | C11: 241125000030 | D11: 46018 | E11: Bella | F11: Bella Chan | G11: Alice | H11: 0.0122 | I11: 2 | J11: 202 | P11: 202 | Q11: 44190.22 | R11: 登凯=45639 创泽=3175 拖车费=1670 杂费=61 过磅费=70 | S11: 9.0809265 | U11: 0.37676471 | X11: 9.4576912 | Y11: 2.0664916 | AA11: 0.010658853 | AB11: 2.0771505 | AC11: 7.26 | AD11: 15.080112 | AE11: 24.537804 | AF11: 177.4622
C12: 241220000030 | D12: 46018 | E12: Bella | F12: Bella Chan | G12: new hope 边鹏飞 | H12: 0.8815 | I12: 304 | K12: 414128.7 | M12: 1566.0003 | N12: 264.44995 | O12: 7.27 | P12: 1922.5511 | S12: 656.13415 | U12: 27.222794 | X12: 683.35695 | Y12: 149.31249 | AA12: 0.77014581 | AB12: 150.08263 | AC12: 7.26 | AD12: 1089.5999 | AE12: 1772.9569 | AF12: 149.59426
A13: 合 计 | H13: =SUM(H4:H8) -> 59.0041 | AF13: =SUM(AF4:AF12) -> 54462.589
AF14: 27023.92
C15: 基本任务：小于6千 | F15: 不够基本任务6千， 公司将根据空运提成里抽出补足基数 | K15: 三凤 提成 | AF15: =SUM(AF13-AF14) -> 27438.669
K16: 名称 | L16: 计费体积 | M16: 毛利 | N16: 备注
C17: 基本任务：6千-3.5万 | F17: 按40%提成 | K17: LOS | L17: =SUM(H13) -> 59.0041 | M17: 27438.669 | N17: 总利润减zhong zi xin 利润的 一半27023.92
K18: 基数 | M18: 6000
C19: 基本任务：3.5万以上 | F19: 按50%提成 | K19: 提成计数 | M19: =SUM(M17-M18) -> 21438.669
K20: 提成点数 | M20: 0.4
K21: 提成金额 | M21: =SUM(M19*M20) -> 8575.4677

Sheet 朱小飞
A1: LOS毛利表
A3: JOB | B3: 集装编号 | C3: 运单编号 | D3: 日期 | E3: 业务 | F3: 发货人 | G3: 收货人 | H3: 计费体积 | I3: 计费重量 | J3: 应 收 | Q3: 总应收 | R3: 起 运 港 成 本 | W3: 代垫运费 | X3: 起运港成本 合计 | Y3: 目的港成本 | AE3: 总支出 | AF3: 利润
J4: 应收RMB | K4: LOS Income(NGN)收到(奈拉) | L4: LOS 收到USD | M4: 美元汇率 dollar currency rate | N4: 应收 到付款USD | O4: 汇率 | P4: 人民币 | R4: 代理商 | S4: 运费+出口报关费 | T4: 提货费 | U4: 装卸费 | V4: 包装费 | Y4: 进口报关费 | Z4: 到门配送费 | AA4: 转运费 | AB4: 目的港支出 | AC4: 汇率 | AD4: 人民币 | AE4: 起运港+目的港
C5: 241202000011 | D5: 45631 | E5: 朱小飞 | F5: Isabel Zhu | G5: Halifa Success | H5: 0.4399 | I5: 73 | J5: 900.59 | P5: 900.59 | S5: 303.81079 | U5: 16.172794 | X5: 319.98358 | Y5: 71.684293 | AB5: 71.684293 | AC5: 7.24 | AD5: 518.99428 | AE5: 838.97786 | AF5: 61.612138
C6: 241204000060 | D6: 45631 | E6: 朱小飞 | F6: Isabel Zhu | G6: Halifa Success | H6: 0.6256 | I6: 144 | J6: 1269.02 | P6: 1269.02 | S6: 432.0619 | U6: 23 | X6: 455.0619 | Y6: 101.9452 | AB6: 101.9452 | AC6: 7.24 | AD6: 738.08325 | AE6: 1193.1451 | AF6: 75.874852
C7: 241219000017 | D7: 46010 | E7: 朱小飞 | F7: Isabel Zhu | G7: Halifa Success | H7: 2.2361 | I7: 234 | J7: 4542.5 | P7: 4542.5 | S7: 1603.9907 | T7: 2.9227142 | U7: 62.479265 | X7: 1669.3927 | Y7: 395.82258 | AA7: 1.8914775 | AB7: 397.71406 | AC7: 7.25 | AD7: 2883.4269 | AE7: 4552.8196 | AF7: -10.319626
C8: 241219000017 | D8: 46018 | E8: 朱小飞 | F8: Isabel Zhu | G8: Halifa Success | H8: 1.1975 | I8: 205 | J8: 2430 | P8: 2430 | S8: 891.34504 | U8: 36.981618 | X8: 928.32665 | Y8: 202.83801 | AA8: 1.0462276 | AB8: 203.88424 | AC8: 7.26 | AD8: 1480.1996 | AE8: 2408.5262 | AF8: 21.473787
C9: 241223000069 | D9: 46018 | E9: 朱小飞 | F9: Isabel Zhu | G9: Halifa Success | H9: 5.4144 | I9: 1858 | J9: 10997.45 | P9: 10997.45 | S9: 4030.1449 | U9: 167.20941 | X9: 4197.3544 | Y9: 917.11576 | AA9: 4.7304339 | AB9: 921.84619 | AC9: 7.26 | AD9: 6692.6033 | AE9: 10889.958 | AF9: 107.49231
C10: 241224000009 | D10: 46018 | E10: 朱小飞 | F10: Isabel Zhu | G10: Halifa Success | H10: 3.9648 | I10: 516 | J10: 8070.22 | P10: 8070.22 | S10: 2951.1522 | U10: 122.44235 | X10: 3073.5946 | Y10: 671.5759 | AA10: 3.4639525 | AB10: 675.03985 | AC10: 7.26 | AD10: 4900.7893 | AE10: 7974.3839 | AF10: 95.836091
C11: 241220000032 | D11: 46020 | E11: 朱小飞 | F11: Isabel Zhu | G11: Halifa Success | H11: 0.1307 | I11: 18 | J11: 264.26 | P11: 264.26 | S11: 96.468132 | U11: 3.4597059 | X11: 99.927838 | Y11: 21.417578 | AA11: 0.25774809 | AB11: 21.675326 | AC11: 7.25 | AD11: 157.14612 | AE11: 257.07395 | AF11: 7.1860451
C12: 241220000033 | D12: 46020 | E12: 朱小飞 | F12: Isabel Zhu | G12: Halifa Success | H12: 4.4833 | I12: 535 | J12: 9724.04 | P12: 9724.04 | S12: 3309.071 | U12: 118.67559 | V12: 600 | X12: 4027.7466 | Y12: 734.67046 | AA12: 8.8413313 | AB12: 743.51179 | AC12: 7.25 | AD12: 5390.4605 | AE12: 9418.2071 | AF12: 305.83294 | AG12: =SUM(AF5:AF12) -> 664.98855
C13: 241202000005 | D13: 45631 | E13: 朱小飞 | F13: Isabel Zhu | G13: Ife Oyelami | H13: 0.8261 | I13: 59 | K13: 424545 | M13: 1657.7959 | N13: 256.09003 | O13: 7.27 | P13: 1861.7745 | S13: 570.53442 | U13: 30.371324 | X13: 600.90575 | Y13: 134.61785 | AB13: 134.61785 | AC13: 7.24 | AD13: 974.63327 | AE13: 1575.539 | AF13: 286.2355 | AG13: =SUM(AG12/2) -> 332.49427
C14: 241217000014 | D14: 45643 | E14: 朱小飞 | F14: Isabel Zhu | G14: Maryam Tukur | H14: 1.1639 | I14: 148 | K14: 687330 | M14: 1536.0016 | N14: 447.48 | O14: 7.27 | P14: 3253.1796 | S14: 857.18668 | U14: 34.232353 | X14: 891.41903 | Y14: 210.01549 | Z14: 66.75 | AA14: 0.9485785 | AB14: 277.71406 | AC14: 7.25 | AD14: 2013.427 | AE14: 2904.846 | AF14: 348.33361
C15: 241217000015 | D15: 45643 | E15: 朱小飞 | F15: Isabel Zhu | G15: Sadiq | H15: 0.322 | I15: 85 | K15: 186847 | M15: 1582.1084 | N15: 118.1 | O15: 7.25 | P15: 856.225 | S15: 237.1459 | U15: 9.4705882 | X15: 246.61649 | Y15: 58.102059 | AA15: 0.26243 | AB15: 58.364489 | AC15: 7.25 | AD15: 423.14254 | AE15: 669.75903 | AF15: 186.46597
C16: 241216000032 | D16: 46018 | E16: 朱小飞 | F16: Isabel Zhu | G16: Joy | H16: 1.8673 | I16: 857 | K16: 984715.9 | M16: 1582 | N16: 622.45 | O16: 7.24 | P16: 4506.538 | S16: 1389.9028 | U16: 57.666618 | X16: 1447.5694 | Y16: 316.29179 | Z16: 8.14 | AA16: 1.6314161 | AB16: 326.0632 | AC16: 7.26 | AD16: 2367.2189 | AE16: 3814.7883 | AF16: 691.74974
C17: 241217000015 | D17: 46018 | E17: 朱小飞 | F17: Isabel Zhu | G17: Sadiq | H17: 2.0946 | I17: 144 | K17: 1215438 | M17: 1581.9836 | N17: 768.3 | O17: 7.25 | P17: 5570.175 | S17: 1559.0909 | U17: 64.686176 | X17: 1623.777 | Y17: 354.7929 | Z17: 103.35 | AA17: 1.8300027 | AB17: 459.9729 | AC17: 7.26 | AD17: 3339.4033 | AE17: 4963.1803 | AF17: 606.9947
C18: 241226000023 | D18: 46018 | E18: 朱小飞 | F18: Isabel Zhu | G18: Maryam Tukur | H18: 0.8304 | I18: 88 | K18: 488305 | M18: 1581.2986 | N18: 308.8 | O18: 7.27 | P18: 2244.976 | S18: 618.09847 | U18: 25.644706 | X18: 643.74318 | Y18: 140.65694 | Z18: 35.59 | AA18: 0.72550094 | AB18: 176.97244 | AC18: 7.26 | AD18: 1284.8199 | AE18: 1928.5631 | AF18: 316.41292
C19: 241225000006 | D19: 46020 | E19: 朱小飞 | F19: Isabel Zhu | G19: Joy | H19: 2.399 | I19: 1988 | K19: 1244263 | M19: 1573.0253 | N19: 791 | O19: 7.25 | P19: 5734.75 | S19: 1785.6674 | U19: 74.086765 | X19: 1859.7542 | Y19: 406.35356 | AA19: 2.0959499 | AB19: 408.44951 | AC19: 7.26 | AD19: 2965.3434 | AE19: 4825.0976 | AF19: 909.65239
C20: 241225000006 | D20: 46020 | E20: 朱小飞 | F20: Isabel Zhu | G20: Joy | H20: 1.7317 | I20: 1184 | K20: 898163 | M20: 1572.965 | N20: 571 | O20: 7.25 | P20: 4139.75 | S20: 1278.1474 | U20: 45.839118 | X20: 1323.9865 | Y20: 283.77062 | Z20: 52.28 | AA20: 3.4150143 | AB20: 339.46564 | AC20: 7.25 | AD20: 2461.1259 | AE20: 3785.1124 | AF20: 354.63761
A21: 合计 | H21: =SUM(H5:H20) -> 29.7273 | AF21: =SUM(AF5:AF20) -> 4365.471
AF22: 332.49
C23: 基本任务：小于6千 | F23: 不够基本任务6千， 公司将根据空运提成里抽出补足基数 | K23: 朱小飞 提成 | AF23: =SUM(AF21-AF22) -> 4032.981
K24: 名称 | L24: 计费体积 | M24: 毛利 | N24: 备注
C25: 基本任务：6千-3.5万 | F25: 按40%提成 | K25: LOS | L25: =SUM(H21) -> 29.7273 | M25: 4032.981 | N25: 总利润减Halifa 利润的 一半332.49
K26: 基数 | M26: 6000
C27: 基本任务：3.5万以上 | F27: 按50%提成 | K27: 提成计数 | M27: =SUM(M25-M26) -> -1967.019
K28: 提成点数
K29: 提成金额

Sheet 吕沛霖
A1: LOS毛利表
A2: JOB | B2: 集装编号 | C2: 运单编号 | D2: 日期 | E2: 业务 | F2: 发货人 | G2: 收货人 | H2: 计费体积 | I2: 计费重量 | J2: 应 收 | Q2: 总应收 | R2: 起 运 港 成 本 | W2: 代垫运费 | X2: 起运港成本 合计 | Y2: 目的港成本 | AE2: 总支出 | AF2: 利润
J3: 应收RMB | K3: LOS Income(NGN)收到(奈拉) | L3: LOS 收到USD | M3: 美元汇率 dollar currency rate | N3: 应收 到付款USD | O3: 汇率 | P3: 人民币 | R3: 代理商 | S3: 运费+出口报关费 | T3: 提货费 | U3: 装卸费 | V3: 包装费 | Y3: 进口报关费 | Z3: 到门配送费 | AA3: 转运费 | AB3: 目的港支出 | AC3: 汇率 | AD3: 人民币 | AE3: 起运港+目的港
C4: 241130000012 | D4: 45631 | E4: 吕沛霖 | F4: Paul | G4: Paul | H4: 0.0882 | I4: 30 | K4: 56179 | M4: 1679.994 | N4: 33.44 | O4: 7.27 | P4: 243.1088 | S4: 60.914098 | U4: 3.2426471 | X4: 64.156745 | Y4: 14.372709 | AB4: 14.372709 | AC4: 7.24 | AD4: 104.05841 | AE4: 168.21516 | AF4: 74.893643
A5: JOB120375 | B5: COLL004323 | C5: 241109000014 | D5: 45636 | E5: 吕沛霖 | F5: 喵喵速运-Layne | G5: KE ZONG | H5: 1.5052 | I5: 360 | J5: 3329.55 | P5: 3329.55 | Q5: 137719.03 | R5: 登凯=46552.5 创泽=1215 拖车费=1670 杂费=61 过磅费=70 | S5: 1097.2133 | U5: 46.484118 | X5: 1143.6974 | Y5: 257.27852 | AA5: 1.2311651 | AB5: 258.50969 | AC5: 7.3 | AD5: 1887.1207 | AE5: 3030.8182 | AF5: 298.73183
C6: 241127000004 | D6: 45636 | E6: 吕沛霖 | F6: 喵喵速运-Layne | G6: Candice Ding | H6: 2.3335 | I6: 2600 | K6: 1863312 | M6: 1600 | N6: 1164.57 | O6: 7.28 | P6: 8478.0696 | S6: 1701.0014 | U6: 72.063971 | X6: 1773.0654 | Y6: 398.85692 | AA6: 1.9086657 | AB6: 400.76558 | AC6: 7.3 | AD6: 2925.5888 | AE6: 4698.6541 | AF6: 3779.4155
A7: JOB120376 | B7: COLL004324 | C7: 241122000025 | D7: 45636 | E7: 吕沛霖 | F7: 喵喵速运-Layne | G7: WENDY | H7: 3.6276 | I7: 1507 | K7: 2696680 | M7: 1630.0048 | N7: 1654.4 | O7: 7.27 | P7: 12027.488 | Q7: 71273.186 | R7: 登凯=46552.5 报关=500 拖车费=1670 杂费=61 过磅费=68 | S7: 2606.0838 | U7: 53.347059 | X7: 2659.4309 | Y7: 617.23881 | Z7: 315.51 | AA7: 7.4749899 | AB7: 940.2238 | AC7: 7.25 | AD7: 6816.6225 | AE7: 9476.0534 | AF7: 2551.4346
C8: 241202000029 | D8: 45636 | E8: 吕沛霖 | F8: 喵喵速运-Layne | G8: Mr. Wen Pu | H8: 8.2313 | I8: 1683 | K8: 4862127 | M8: 1630 | N8: 2982.9 | O8: 7.28 | P8: 21715.512 | S8: 5913.4022 | U8: 121.04853 | X8: 6034.4508 | Y8: 1400.5617 | Z8: 715.9 | AA8: 16.96132 | AB8: 2133.4231 | AC8: 7.25 | AD8: 15467.317 | AE8: 21501.768 | AF8: 213.744
C9: 241204000017 | D9: 45636 | E9: 吕沛霖 | F9: 喵喵速运-Layne | G9: Frank | H9: 0.5672 | I9: 104 | K9: 270180 | M9: 1580 | N9: 171 | O9: 7.29 | P9: 1246.59 | S9: 407.47898 | U9: 8.3411765 | X9: 415.82016 | Y9: 96.509497 | Z9: 49.33 | AA9: 1.1687656 | AB9: 147.00826 | AC9: 7.25 | AD9: 1065.8099 | AE9: 1481.6301 | AF9: -235.04006
C10: 241216000056 | D10: 45636 | E10: 吕沛霖 | F10: 喵喵速运-Layne | G10: LEO WEI | H10: 0.3809 | I10: 90 | K10: 197726.1 | M10: 1573 | N10: 125.7 | O10: 7.28 | P10: 915.096 | S10: 273.64024 | U10: 5.6014706 | X10: 279.24171 | Y10: 64.810415 | AA10: 0.78487806 | AB10: 65.595293 | AC10: 7.25 | AD10: 475.56588 | AE10: 754.80759 | AF10: 160.28841
C11: 241209000082 | D11: 45638 | E11: 吕沛霖 | F11: 喵喵速运-Layne | G11: BI AN | H11: 2.4778 | I11: 1373 | J11: 6015.2 | P11: 6015.2 | S11: 1776.7101 | U11: 65.588824 | X11: 1842.299 | Y11: 423.48408 | AA11: 5.1057255 | AB11: 428.5898 | AC11: 7.25 | AD11: 3107.2761 | AE11: 4949.575 | AF11: 1065.625
C12: 250110000026 | D12: 45643 | E12: 吕沛霖 | F12: 喵喵速运-Layne | G12: KE ZONG | H12: 1.0248 | I12: 276 | J12: 2271.15 | P12: 2271.15 | S12: 754.74259 | U12: 30.141176 | X12: 784.88377 | Y12: 184.91612 | AA12: 0.835212 | AB12: 185.75133 | AC12: 7.25 | AD12: 1346.6971 | AE12: 2131.5809 | AF12: 139.56909
C13: 241126000018 | D13: 46018 | E13: 吕沛霖 | F13: 喵喵速运-Layne | G13: MA ZONG | H13: 4.3979 | I13: 10079 | J13: 20016.76 | P13: 20016.76 | S13: 3273.5251 | U13: 135.8175 | W13: 255 | X13: 3664.3426 | Y13: 744.93635 | AA13: 3.8423418 | AB13: 748.77869 | AC13: 7.26 | AD13: 5436.1333 | AE13: 9100.4759 | AF13: 10916.284
A14: JOB120404 | B14: COLL004342 | C14: 241126000018 | D14: 46020 | E14: 吕沛霖 | F14: 喵喵速运-Layne | G14: MA ZONG | H14: 4.16 | I14: 10000 | J14: 18934.4 | P14: 18934.4 | S14: 3070.4471 | U14: 110.11765 | X14: 3180.5647 | Y14: 681.69186 | AA14: 8.2037647 | AB14: 689.89562 | AC14: 7.25 | AD14: 5001.7433 | AE14: 8182.308 | AF14: 10752.092
A15: 合计 | H15: =SUM(H4:H14) -> 28.7944 | AF15: =SUM(AF4:AF14) -> 29717.038
C18: 基本任务：小于6千 | F18: 不够基本任务6千， 公司将根据空运提成里抽出补足基数 | K18: 吕沛霖 提成
K19: 名称 | L19: 计费体积 | M19: 毛利
C20: 基本任务：6千-3.5万 | F20: 按40%提成 | K20: LOS | L20: =SUM(H15) -> 28.7944 | M20: =SUM(AF15) -> 29717.038
K21: 基数 | M21: 6000
C22: 基本任务：3.5万以上 | F22: 按50%提成 | K22: 提成计数 | M22: =SUM(M20-M21) -> 23717.038
K23: 提成点数 | M23: 0.4
K24: 提成金额 | M24: =SUM(M22*M23) -> 9486.8152

Sheet 罗珮文
A1: LOS毛利表
A3: JOB | B3: 集装编号 | C3: 运单编号 | D3: 日期 | E3: 业务 | F3: 发货人 | G3: 收货人 | H3: 计费体积 | I3: 计费重量 | J3: 应 收 | Q3: 总应收 | R3: 起 运 港 成 本 | W3: 代垫运费 | X3: 起运港成本 合计 | Y3: 目的港成本 | AE3: 总支出 | AF3: 利润
J4: 应收RMB | K4: LOS Income(NGN)收到(奈拉) | L4: LOS 收到USD | M4: 美元汇率 dollar currency rate | N4: 应收 到付款USD | O4: 汇率 | P4: 人民币 | R4: 代理商 | S4: 运费+出口报关费 | T4: 提货费 | U4: 装卸费 | V4: 包装费 | Y4: 进口报关费 | Z4: 到门配送费 | AA4: 转运费 | AB4: 目的港支出 | AC4: 汇率 | AD4: 人民币 | AE4: 起运港+目的港
C5: 241118000063 | D5: 45631 | E5: 罗珮文 | F5: Shirley | G5: Yusky | H5: 1.6585 | I5: 270 | K5: 719837.28 | M5: 1608 | N5: 447.66 | O5: 7.3 | P5: 3267.918 | S5: 1145.4199 | U5: 60.974265 | X5: 1206.3941 | Y5: 270.26233 | AB5: 270.26233 | AC5: 7.24 | AD5: 1956.6993 | AE5: 3163.0934 | AF5: 104.8246
C6: 241118000066 | D6: 45631 | E6: 罗珮文 | F6: Shirley | G6: Yusky | H6: 1.2581 | I6: 125 | K6: 546173.28 | M6: 1608 | N6: 339.66 | O6: 7.3 | P6: 2479.518 | S6: 868.88919 | U6: 46.253676 | X6: 915.14287 | Y6: 205.0148 | AB6: 205.0148 | AC6: 7.24 | AD6: 1484.3071 | AE6: 2399.45 | AF6: 80.068015
C7: 241127000012 | D7: 45631 | E7: 罗珮文 | F7: Shirley | G7: Yusky | H7: 3.0636 | I7: 768 | K7: 1330089.4 | M7: 1608 | N7: 827.17 | O7: 7.3 | P7: 6038.341 | S7: 2115.8325 | U7: 112.63235 | X7: 2228.4649 | Y7: 499.23164 | AB7: 499.23164 | AC7: 7.24 | AD7: 3614.4371 | AE7: 5842.902 | AF7: 195.43903
C8: 241127000014 | D8: 45631 | E8: 罗珮文 | F8: Shirley | G8: Yusky | H8: 0.4158 | I8: 55 | K8: 180530.16 | M8: 1608 | N8: 112.27 | O8: 7.3 | P8: 819.571 | S8: 287.16646 | U8: 15.286765 | X8: 302.45323 | Y8: 67.757056 | AB8: 67.757056 | AC8: 7.24 | AD8: 490.56108 | AE8: 793.01431 | AF8: 26.55669
C9: 241204000043 | D9: 45631 | E9: 罗珮文 | F9: Shirley | G9: Yusky | H9: 1.3963 | I9: 248 | K9: 606216 | M9: 1608 | N9: 377 | O9: 7.3 | P9: 2752.1 | S9: 964.33509 | U9: 51.334559 | X9: 1015.6696 | Y9: 227.5353 | AB9: 227.5353 | AC9: 7.24 | AD9: 1647.3556 | AE9: 2663.0252 | AF9: 89.074792
C10: 241204000044 | D10: 45631 | E10: 罗珮文 | F10: Shirley | G10: Yusky | H10: 0.7235 | I10: 107 | K10: 314122.8 | M10: 1608 | N10: 195.35 | O10: 7.3 | P10: 1426.055 | S10: 499.67517 | U10: 26.599265 | X10: 526.27443 | Y10: 117.89858 | AB10: 117.89858 | AC10: 7.24 | AD10: 853.58573 | AE10: 1379.8602 | AF10: 46.194842
C11: 241204000045 | D11: 45631 | E11: 罗珮文 | F11: Shirley | G11: Yusky | H11: 0.26 | I11: 48 | K11: 112929.84 | M11: 1608 | N11: 70.23 | O11: 7.3 | P11: 512.679 | S11: 179.56537 | U11: 9.5588235 | X11: 189.12419 | Y11: 42.368529 | AB11: 42.368529 | AC11: 7.24 | AD11: 306.74815 | AE11: 495.87234 | AF11: 16.806656
C12: 241204000046 | D12: 45631 | E12: 罗珮文 | F12: Shirley | G12: Yusky | H12: 0.2492 | I12: 51 | K12: 108090.06 | M12: 1606.5705 | N12: 67.28 | O12: 7.3 | P12: 491.144 | S12: 172.1065 | U12: 9.1617647 | X12: 181.26826 | Y12: 40.608606 | AB12: 40.608606 | AC12: 7.24 | AD12: 294.00631 | AE12: 475.27457 | AF12: 15.86943
C13: 241204000047 | D13: 45631 | E13: 罗珮文 | F13: Shirley | G13: Yusky | H13: 0.2023 | I13: 17 | K13: 87064.28 | M13: 1594 | N13: 54.62 | O13: 7.29 | P13: 398.1798 | S13: 139.71567 | U13: 7.4375 | X13: 147.15317 | Y13: 32.965975 | AB13: 32.965975 | AC13: 7.24 | AD13: 238.67366 | AE13: 385.82683 | AF13: 12.352972
C14: 241204000048 | D14: 45631 | E14: 罗珮文 | F14: Shirley | G14: Yusky | H14: 0.5307 | I14: 90 | K14: 228404.26 | M14: 1594 | N14: 143.29 | O14: 7.29 | P14: 1044.5841 | S14: 366.52054 | U14: 19.511029 | X14: 386.03157 | Y14: 86.480687 | AB14: 86.480687 | AC14: 7.24 | AD14: 626.12017 | AE14: 1012.1517 | AF14: 32.432358
C15: 241204000050 | D15: 45631 | E15: 罗珮文 | F15: Shirley | G15: Yusky | H15: 14.6981 | I15: 2994 | K15: 6392673.2 | M15: 1594 | N15: 4010.46 | O15: 7.27 | P15: 29156.044 | S15: 10151.037 | U15: 540.37132 | X15: 10691.409 | Y15: 2395.1419 | AB15: 2395.1419 | AC15: 7.24 | AD15: 17340.827 | AE15: 28032.236 | AF15: 1123.8084
C16: 241204000052 | D16: 45631 | E16: 罗珮文 | F16: Shirley | G16: Yusky | H16: 21.052 | I16: 2202 | K16: 9257809 | M16: 1616.7908 | N16: 5726.04 | O16: 7.22 | P16: 41342.009 | S16: 14539.27 | U16: 773.97059 | X16: 15313.24 | Y16: 3430.5472 | AB16: 3430.5472 | AC16: 7.24 | AD16: 24837.162 | AE16: 40150.402 | AF16: 1191.6065
C17: 241204000053 | D17: 45631 | E17: 罗珮文 | F17: Shirley | G17: Yusky | H17: 0.1958 | I17: 447 | K17: 85649.4 | M17: 1620 | N17: 52.87 | O17: 7.22 | P17: 381.7214 | S17: 135.22653 | U17: 7.1985294 | X17: 142.42506 | Y17: 31.906762 | AB17: 31.906762 | AC17: 7.24 | AD17: 231.00496 | AE17: 373.43002 | AF17: 8.2913809
C18: 241204000049 | D18: 45636 | E18: 罗珮文 | F18: Shirley | G18: Yusky | H18: 14.985 | I18: 2696 | K18: 6707917.9 | M18: 1582.8774 | N18: 4237.8 | O18: 7.18 | P18: 30427.404 | S18: 10923.294 | U18: 462.77206 | X18: 11386.066 | Y18: 2561.3332 | AA18: 12.256849 | AB18: 2573.59 | AC18: 7.3 | AD18: 18787.207 | AE18: 30173.273 | AF18: 254.13115
C19: 241204000051 | D19: 45636 | E19: 罗珮文 | F19: Shirley | G19: Yusky | H19: 2.1818 | I19: 358 | K19: 966443.8 | M19: 1582 | N19: 610.9 | O19: 7.18 | P19: 4386.262 | S19: 1590.4199 | U19: 67.379118 | X19: 1657.799 | Y19: 372.92737 | AA19: 1.7845841 | AB19: 374.71196 | AC19: 7.3 | AD19: 2735.3973 | AE19: 4393.1963 | AF19: -6.9343095
C20: 241210000005 | D20: 45636 | E20: 罗珮文 | F20: Shirley | G20: Abubakar Badaru Abubakar | H20: 17.6161 | I20: 1662 | K20: 7918392 | M20: 1550 | N20: 5108.64 | O20: 7.27 | P20: 37139.813 | S20: 12841.23 | U20: 544.02662 | V20: 200 | X20: 13585.257 | Y20: 3011.0578 | AA20: 14.408934 | AB20: 3025.4667 | AC20: 7.3 | AD20: 22085.907 | AE20: 35671.164 | AF20: 1468.6488
C21: 241210000006 | D21: 45636 | E21: 罗珮文 | F21: Shirley | G21: SKY JET | H21: 35.4 | I21: 5354 | J21: 56540.88 | P21: 56540.88 | S21: 25431.516 | U21: 520.58824 | X21: 25952.104 | Y21: 6023.336 | AA21: 72.944824 | AB21: 6096.2809 | AC21: 7.25 | AD21: 44198.036 | AE21: 70150.141 | AF21: -13609.261
C22: 241209000084 | D22: 45638 | E22: 罗珮文 | F22: Shirley | G22: Yusky | H22: 3.5753 | I22: 397 | K22: 1527152.1 | M22: 1582 | N22: 965.33 | O22: 7.18 | P22: 6931.0694 | S22: 2563.6741 | U22: 94.640294 | X22: 2658.3144 | Y22: 611.05926 | AA22: 7.3672211 | AB22: 618.42648 | AC22: 7.25 | AD22: 4483.592 | AE22: 7141.9064 | AF22: -210.83697
C23: 241211000045 | D23: 45638 | E23: 罗珮文 | F23: Shirley | G23: Yusky | H23: 10.4649 | I23: 835 | K23: 4470020.1 | M23: 1582 | N23: 2825.55 | O23: 7.18 | P23: 20287.449 | S23: 7503.8719 | U23: 277.01206 | X23: 7780.884 | Y23: 1788.5699 | AA23: 21.56385 | AB23: 1810.1338 | AC23: 7.25 | AD23: 13123.47 | AE23: 20904.354 | AF23: -616.90475
C24: 241212000002 | D24: 45638 | E24: 罗珮文 | F24: Shirley | G24: SKY JET | H24: 29.57 | I24: 4902 | J24: 47229.2 | P24: 47229.2 | S24: 21203.212 | U24: 782.73529 | X24: 21985.947 | Y24: 5053.8478 | AA24: 60.931594 | AB24: 5114.7794 | AC24: 7.25 | AD24: 37082.151 | AE24: 59068.098 | AF24: -11838.898
C25: 241217000016 | D25: 45643 | E25: 罗珮文 | F25: Shirley | G25: Abubakar Badaru Abubakar | H25: 0.6596 | I25: 58 | K25: 296670 | M25: 1550 | N25: 191.4 | O25: 7.27 | P25: 1391.478 | S25: 485.78085 | U25: 19.4 | X25: 505.18085 | Y25: 119.019 | AA25: 0.537574 | AB25: 119.55657 | AC25: 7.25 | AD25: 866.78516 | AE25: 1371.966 | AF25: 19.511989
C26: 241219000028 | D26: 46010 | E26: 罗珮文 | F26: Shirley | G26: SKY JET | H26: 22.11 | I26: 2603 | J26: 36919.28 | P26: 36919.28 | S26: 15859.861 | T26: 28.899071 | U26: 617.77941 | X26: 16506.539 | Y26: 3913.7951 | AA26: 18.702459 | AB26: 3932.4976 | AC26: 7.25 | AD26: 28510.608 | AE26: 45017.147 | AF26: -8097.8668
C27: 241224000024 | D27: 46018 | E27: 罗珮文 | F27: Shirley | G27: Yusky | H27: 1.4079 | I27: 246 | K27: 605826.9 | M27: 1582 | N27: 382.95 | O27: 7.18 | P27: 2749.581 | S27: 1047.9538 | U27: 43.479265 | X27: 1091.4331 | Y27: 238.47652 | AA27: 1.2300491 | AB27: 239.70657 | AC27: 7.26 | AD27: 1740.2697 | AE27: 2831.7028 | AF27: -82.121761
C28: 241224000025 | D28: 46018 | E28: 罗珮文 | F28: Shirley | G28: Yusky | H28: 2.2252 | I28: 847 | K28: 957505.5 | M28: 1582 | N28: 605.25 | O28: 7.18 | P28: 4345.695 | S28: 1656.3014 | U28: 68.719412 | X28: 1725.0209 | Y28: 376.91452 | AA28: 1.9441049 | AB28: 378.85863 | AC28: 7.26 | AD28: 2750.5136 | AE28: 4475.5345 | AF28: -129.83947
C29: 241224000026 | D29: 46018 | E29: 罗珮文 | F29: Shirley | G29: Yusky | H29: 0.8547 | I29: 81 | K29: 367783.36 | M29: 1582 | N29: 232.48 | O29: 7.18 | P29: 1669.2064 | S29: 636.18589 | U29: 26.395147 | X29: 662.58104 | Y29: 144.77298 | AA29: 0.74673128 | AB29: 145.51971 | AC29: 7.26 | AD29: 1056.4731 | AE29: 1719.0542 | AF29: -49.847758
C30: 241226000032 | D30: 46018 | E30: 罗珮文 | F30: Shirley | G30: Yusky | H30: 0.19 | I30: 26 | K30: 81805.22 | M30: 1582 | N30: 51.71 | O30: 7.18 | P30: 371.2778 | S30: 141.42426 | U30: 5.8676471 | X30: 147.29191 | Y30: 32.183066 | AA30: 0.16599853 | AB30: 32.349065 | AC30: 7.26 | AD30: 234.85421 | AE30: 382.14612 | AF30: -10.868322
C31: 241226000033 | D31: 46018 | E31: 罗珮文 | F31: Shirley | G31: Yusky | H31: 1.481 | I31: 251 | K31: 637277.06 | M31: 1582 | N31: 402.83 | O31: 7.18 | P31: 2892.3194 | S31: 1102.3649 | U31: 45.736765 | X31: 1148.1017 | Y31: 250.85853 | AA31: 1.2939149 | AB31: 252.15245 | AC31: 7.26 | AD31: 1830.6268 | AE31: 2978.7285 | AF31: -86.409053
C32: 241226000034 | D32: 46018 | E32: 罗珮文 | F32: Shirley | G32: Yusky | H32: 0.3501 | I32: 96 | K32: 150653.86 | M32: 1582 | N32: 95.23 | O32: 7.18 | P32: 683.7514 | S32: 260.59282 | U32: 10.811912 | X32: 271.40473 | Y32: 59.301534 | AA32: 0.30587413 | AB32: 59.607408 | AC32: 7.26 | AD32: 432.74978 | AE32: 704.15451 | AF32: -20.403111
C33: 241229000001 | D33: 46020 | E33: 罗珮文 | F33: Shirley | G33: SKY JET | H33: 32.35 | I33: 3811 | J33: 53783.17 | P33: 53783.17 | S33: 23877.154 | U33: 856.32353 | X33: 24733.478 | Y33: 5301.1374 | AA33: 63.796103 | AB33: 5364.9335 | AC33: 7.25 | AD33: 38895.768 | AE33: 63629.246 | AF33: -9846.0759
C34: 241229000003 | D34: 46020 | E34: 罗珮文 | F34: Shirley | G34: SKY JET | H34: 1.51 | I34: 270 | J34: 2510.44 | P34: 2510.44 | S34: 1114.5132 | U34: 39.970588 | X34: 1154.4838 | Y34: 247.44104 | AA34: 2.9778088 | AB34: 250.41884 | AC34: 7.25 | AD34: 1815.5366 | AE34: 2970.0204 | AF34: -459.58044
A35: 合计 | H35: =SUM(H5:H34) -> 222.6355 | AF35: =SUM(AF5:AF34) -> -40380.23
C37: 基本任务：小于6千 | F37: 不够基本任务6千， 公司将根据空运提成里抽出补足基数 | K37: 罗珮文 提成
K38: 名称 | L38: 计费体积 | M38: 毛利
C39: 基本任务：6千-3.5万 | F39: 按40%提成 | K39: LOS | L39: =SUM(H35) -> 222.6355 | M39: =SUM(AF35) -> -40380.23
K40: 基数
C41: 基本任务：3.5万以上 | F41: 按50%提成 | K41: 提成计数
K42: 提成点数
...

Sheet 苏慧琪
A1: LOS毛利表
A3: JOB | B3: 集装编号 | C3: 运单编号 | D3: 日期 | E3: 业务 | F3: 发货人 | G3: 收货人 | H3: 计费体积 | I3: 计费重量 | J3: 应 收 | Q3: 总应收 | R3: 起 运 港 成 本 | W3: 代垫运费 | X3: 起运港成本 合计 | Y3: 目的港成本 | AE3: 总支出 | AF3: 利润
J4: 应收RMB | K4: LOS Income(NGN)收到(奈拉) | L4: LOS 收到USD | M4: 美元汇率 dollar currency rate | N4: 应收 到付款USD | O4: 汇率 | P4: 人民币 | R4: 代理商 | S4: 运费+出口报关费 | T4: 提货费 | U4: 装卸费 | V4: 包装费 | Y4: 进口报关费 | Z4: 到门配送费 | AA4: 转运费 | AB4: 目的港支出 | AC4: 汇率 | AD4: 人民币 | AE4: 起运港+目的港
C5: 241223000042 | D5: 46018 | E5: 苏慧琪 | F5: KAY | G5: WENXIAOBING | H5: 0.0662 | I5: 13 | J5: 155.7 | P5: =SUM(J5) -> 155.7 | S5: =SUM(50615/68)*H5 -> 49.275191 | U5: =SUM(2100/68)*H5 -> 2.0444118 | X5: =SUM(S5:W5) -> 51.319603 | Y5: =SUM(11518.15/68)*H5 -> 11.213258 | AA5: =SUM(59.41/68)*H5 -> 0.057837382 | AB5: =SUM(Y5:AA5) -> 11.271095 | AC5: 7.26 | AD5: =SUM(AB5*AC5) -> 81.828151 | AE5: =SUM(X5+AD5) -> 133.14775 | AF5: =SUM(P5-AE5) -> 22.552246
A6: 合计 | H6: =SUM(H5:H5) -> 0.0662 | AF6: =SUM(AF5:AF5) -> 22.552246
C8: 基本任务：小于6千 | F8: 不够基本任务6千， 公司将根据空运提成里抽出补足基数 | K8: 苏慧琪 提成
K9: 名称 | L9: 计费体积 | M9: 毛利
C10: 基本任务：6千-3.5万 | F10: 按40%提成 | K10: LOS | L10: =SUM(H6) -> 0.0662 | M10: =SUM(AF6) -> 22.552246
K11: 基数
C12: 基本任务：3.5万以上 | F12: 按50%提成 | K12: 提成计数
K13: 提成点数
K14: 提成金额

Sheet 陆总
A1: LOS毛利表
A3: JOB | B3: 集装编号 | C3: 运单编号 | D3: 日期 | E3: 业务 | F3: 发货人 | G3: 收货人 | H3: 计费体积 | I3: 计费重量 | J3: 应 收 | Q3: 总应收 | R3: 起 运 港 成 本 | W3: 代垫运费 | X3: 起运港成本 合计 | Y3: 目的港成本 | AE3: 总支出 | AF3: 利润
J4: 应收RMB | K4: LOS Income(NGN)收到(奈拉) | L4: LOS 收到USD | M4: 美元汇率 dollar currency rate | N4: 应收 到付款USD | O4: 汇率 | P4: 人民币 | R4: 代理商 | S4: 运费+出口报关费 | T4: 提货费 | U4: 装卸费 | V4: 包装费 | Y4: 进口报关费 | Z4: 到门配送费 | AA4: 转运费 | AB4: 目的港支出 | AC4: 汇率 | AD4: 人民币 | AE4: 起运港+目的港
C5: 241129000029 | D5: 45631 | E5: 陆总 | F5: 陆梓龙 | G5: xiantian | H5: 0.19 | I5: 24 | J5: 369.36 | P5: 369.36 | S5: 131.22085 | U5: 6.9852941 | X5: 138.20614 | Y5: 30.961618 | AB5: 30.961618 | AC5: 7.24 | AD5: 224.16211 | AE5: 362.36825 | AF5: 6.9917485
C6: 241204000039 | D6: 45631 | E6: 陆总 | F6: 陆梓龙 | G6: xinlong | H6: 0.0608 | I6: 12 | J6: 113.83 | P6: 113.83 | S6: 41.990671 | U6: 2.2352941 | X6: 44.225965 | Y6: 9.9077176 | AB6: 9.9077176 | AC6: 7.24 | AD6: 71.731876 | AE6: 115.95784 | AF6: -2.1278405
C7: 241216000026 | D7: 45638 | E7: 陆总 | F7: 陆梓龙 | G7: luk | H7: 12.7436 | I7: 1324.23 | J7: 22939.2 | P7: 22939.2 | S7: 9289.4285 | U7: 393.55235 | X7: 9682.9808 | Y7: 2178.2186 | AA7: 10.423515 | AB7: 2188.6421 | AC7: 7.3 | AD7: 15977.087 | AE7: 25660.068 | AF7: -2720.8681
C8: 241216000026 | D8: 45638 | E8: 陆总 | F8: 陆梓龙 | G8: luk | H8: 11.0893 | I8: 1146.94 | J8: 19958.4 | P8: 19958.4 | S8: 7966.602 | U8: 163.07794 | X8: 8129.68 | Y8: 1886.8525 | AA8: 22.850481 | AB8: 1909.703 | AC8: 7.25 | AD8: 13845.347 | AE8: 21975.027 | AF8: -2016.627
C9: 241212000013 | D9: 45638 | E9: 陆总 | F9: 陆梓龙 | G9: luk | H9: 0.0957 | I9: 26 | J9: 186.05 | P9: 186.05 | S9: 68.621826 | U9: 2.5332353 | X9: 71.155061 | Y9: 16.356214 | AA9: 0.19719829 | AB9: 16.553412 | AC9: 7.25 | AD9: 120.01224 | AE9: 191.1673 | AF9: -5.1172977
C10: 241216000026 | D10: 45638 | E10: 陆总 | F10: 陆梓龙 | G10: luk | H10: 9.6179 | I10: 931.83 | J10: 17313.84 | P10: 17313.84 | S10: 6896.5293 | U10: 254.59147 | X10: 7151.1208 | Y10: 1643.808 | AA10: 19.818532 | AB10: 1663.6266 | AC10: 7.25 | AD10: 12061.292 | AE10: 19212.413 | AF10: -1898.5733
C11: 241219000027 | D11: 46010 | E11: 陆总 | F11: 陆梓龙 | G11: xiantian | H11: 0.9378 | I11: 1454 | J11: 4037.69 | P11: 4037.69 | S11: 672.69911 | T11: 1.2257598 | U11: 26.203235 | X11: 700.12811 | Y11: 166.00439 | AA11: 0.79326847 | AB11: 166.79766 | AC11: 7.25 | AD11: 1209.283 | AE11: 1909.4111 | AF11: 2128.2789
C12: 241227000049 | D12: 46020 | E12: 陆总 | F12: 陆梓龙 | G12: WANG | H12: 2.8728 | I12: 1490 | J12: 5584.75 | P12: 5584.75 | S12: 2120.3799 | U12: 76.044706 | X12: 2196.4246 | Y12: 470.76067 | AA12: 5.6653306 | AB12: 476.426 | AC12: 7.25 | AD12: 3454.0885 | AE12: 5650.5131 | AF12: -65.763066
C13: 241227000050 | D13: 46020 | E13: 陆总 | F13: 陆梓龙 | G13: xinlong | H13: 0.4118 | I13: 482 | J13: 1338.62 | P13: 1338.62 | S13: 303.94474 | U13: 10.900588 | X13: 314.84532 | Y13: 67.480939 | AA13: 0.81209382 | AB13: 68.293033 | AC13: 7.25 | AD13: 495.12449 | AE13: 809.96981 | AF13: 528.65019
C14: 241227000051 | D14: 46020 | E14: 陆总 | F14: 陆梓龙 | G14: luk | H14: 0.0622 | I14: 8 | J14: 120.89 | P14: 120.89 | S14: 45.909088 | U14: 1.6464706 | X14: 47.555559 | Y14: 10.192604 | AA14: 0.12266206 | AB14: 10.315266 | AC14: 7.25 | AD14: 74.785681 | AE14: 122.34124 | AF14: -1.4512395
A15: 合计 | H15: =SUM(H5:H14) -> 38.0819 | AF15: =SUM(AF5:AF14) -> -4046.607
C17: 基本任务：小于6千 | F17: 不够基本任务6千， 公司将根据空运提成里抽出补足基数 | K17: 陆总 提成
K18: 名称 | L18: 计费体积 | M18: 毛利
C19: 基本任务：6千-3.5万 | F19: 按40%提成 | K19: LOS | L19: =SUM(H15) -> 38.0819 | M19: =SUM(AF15) -> -4046.607
K20: 提成计数
C21: 基本任务：3.5万以上 | F21: 按50%提成 | K21: 提成点数
K22: 提成金额

Sheet 浦生
A1: LOS毛利表
A3: JOB | B3: 集装编号 | C3: 运单编号 | D3: 日期 | E3: 业务 | F3: 发货人 | G3: 收货人 | H3: 计费体积 | I3: 计费重量 | J3: 应 收 | Q3: 总应收 | R3: 起 运 港 成 本 | W3: 代垫运费 | X3: 起运港成本 合计 | Y3: 目的港成本 | AE3: 总支出 | AF3: 利润
J4: 应收RMB | K4: LOS Income(NGN)收到(奈拉) | L4: LOS 收到USD | M4: 美元汇率 dollar currency rate | N4: 应收 到付款USD | O4: 汇率 | P4: 人民币 | R4: 代理商 | S4: 运费+出口报关费 | T4: 提货费 | U4: 装卸费 | V4: 包装费 | Y4: 进口报关费 | Z4: 到门配送费 | AA4: 转运费 | AB4: 目的港支出 | AC4: 汇率 | AD4: 人民币 | AE4: 起运港+目的港
C5: 241120000023 | D5: 45631 | E5: Sam.Pao | F5: Sam.Pao | G5: Mr. Jiang | H5: 1.3317 | I5: 326 | J5: 4965 | P5: 4965 | S5: 919.72 | U5: 48.959559 | V5: 500 | X5: 1468.6796 | Y5: 217.00835 | AB5: 217.00835 | AC5: 7.24 | AD5: 1571.1404 | AE5: 3039.82 | AF5: 1925.18
C6: 241121000013 | D6: 45631 | E6: Sam.Pao | F6: Sam.Pao | G6: Mr. Jiang | H6: 2.2982 | I6: 612 | J6: 7707 | P6: 7707 | S6: 1587.2197 | U6: 84.492647 | V6: 400 | X6: 2071.7124 | Y6: 374.50521 | AB6: 374.50521 | AC6: 7.24 | AD6: 2711.4177 | AE6: 4783.1301 | AF6: 2923.8699
C7: 241121000018 | D7: 45631 | E7: Sam.Pao | F7: Sam.Pao | G7: Nick Wang | H7: 0.0768 | I7: 14 | J7: 296.22 | P7: 296.22 | S7: 53.040847 | U7: 2.8235294 | X7: 55.864376 | Y7: 12.515012 | Z7: 4.51 | AB7: 17.025012 | AC7: 7.24 | AD7: 123.26109 | AE7: 179.12546 | AF7: 117.09454
C8: 241121000019 | D8: 45631 | E8: Sam.Pao | F8: Sam.Pao | G8: Mr. Jiang | H8: 1.4834 | I8: 471 | J8: 3598 | P8: 3598 | S8: 1024.4895 | U8: 54.536765 | X8: 1079.0263 | Y8: 241.72876 | AB8: 241.72876 | AC8: 7.24 | AD8: 1750.1162 | AE8: 2829.1424 | AF8: 768.85756
C9: 241206000037 | D9: 45636 | E9: Sam.Pao | F9: Sam.Pao | G9: Mr. Jiang | H9: 0.6414 | I9: 108 | J9: 2673 | P9: 2673 | S9: 467.54759 | U9: 19.807941 | V9: 300 | X9: 787.35553 | Y9: 109.63224 | AA9: 0.52462747 | AB9: 110.15687 | AC9: 7.3 | AD9: 804.14512 | AE9: 1591.5006 | AF9: 1081.4994
C10: 241206000040 | D10: 45636 | E10: Sam.Pao | F10: Sam.Pao | G10: Mr. Jiang | H10: 0.7876 | I10: 213 | J10: 2732 | P10: 2732 | S10: 574.11986 | U10: 24.322941 | V10: 300 | X10: 898.4428 | Y10: 134.62169 | AA10: 0.64421047 | AB10: 135.2659 | AC10: 7.3 | AD10: 987.44106 | AE10: 1885.8839 | AF10: 846.11614
C11: 241209000071 | D11: 45636 | E11: Sam.Pao | F11: Sam.Pao | G11: ShanShan | H11: 0.1971 | I11: 30.5 | J11: 788.4 | P11: 788.4 | S11: 141.59751 | U11: 2.8985294 | X11: 144.49604 | Y11: 33.53671 | Z11: 0.84 | AA11: 0.40614194 | AB11: 34.782852 | AC11: 7.25 | AD11: 252.17568 | AE11: 396.67172 | AF11: 391.72828
A12: JOB120381 | B12: COLL004325 | C12: 241023000034 | D12: 45638 | E12: Sam.Pao | F12: Sam.Pao | G12: Nick Wang | H12: 0.3134 | I12: 126 | J12: 906 | P12: 906 | Q12: 75691.518 | R12: 登凯=46552.5 报关=300 拖车费=1670 杂费=166 过磅费=71 | S12: 224.72393 | U12: 8.2958824 | X12: 233.01981 | Y12: 53.563609 | AA12: 0.64578835 | AB12: 54.209397 | AC12: 7.25 | AD12: 393.01813 | AE12: 626.03794 | AF12: 279.96206
C13: 241115000013 | D13: 45638 | E13: Sam.Pao | F13: Sam.Pao | G13: ChenGaoHong | H13: 0.367 | I13: 106 | J13: 780 | P13: 780 | S13: 263.15789 | U13: 9.7147059 | V13: 240 | X13: 512.8726 | Y13: 62.724456 | AA13: 0.75623588 | AB13: 63.480692 | AC13: 7.25 | AD13: 460.23501 | AE13: 973.10761 | AF13: -193.10761
C14: 241126000049 | D14: 45638 | E14: Sam.Pao | F14: Sam.Pao | G14: AiGeLi | H14: 2.7422 | I14: 1148 | J14: 7878 | P14: 7878 | S14: 1966.2985 | U14: 72.587647 | V14: 1000 | X14: 3038.8862 | Y14: 468.67303 | AA14: 5.6505451 | AB14: 474.32358 | AC14: 7.25 | AD14: 3438.8459 | AE14: 6477.7321 | AF14: 1400.2679
C15: 241209000067 | D15: 45643 | E15: Sam.Pao | F15: Sam.Pao | G15: MaiKaiNian | H15: 0.023 | I15: 43 | J15: 152.5 | P15: 152.5 | S15: 16.938993 | U15: 0.67647059 | X15: 17.615463 | Y15: 4.1501471 | AA15: 0.018745 | AB15: 4.1688921 | AC15: 7.25 | AD15: 30.224467 | AE15: 47.839931 | AF15: 104.66007
C16: 241211000027 | D16: 45643 | E16: Sam.Pao | F16: Sam.Pao | G16: ShanShan | H16: 23.8172 | I16: 4565 | J16: 54267 | P16: 54267 | S16: 17540.842 | U16: 700.50588 | X16: 18241.348 | Y16: 4297.6036 | Z16: 136.87 | AA16: 19.411018 | AB16: 4453.8846 | AC16: 7.25 | AD16: 32290.663 | AE16: 50532.012 | AF16: 3734.9883
C17: 241212000015 | D17: 45643 | E17: Sam.Pao | F17: Sam.Pao | G17: MaiKaiNian | H17: 2.957 | I17: 1339 | J17: 7123.63 | P17: 7123.63 | S17: 2177.7653 | U17: 86.970588 | X17: 2264.7359 | Y17: 533.56456 | AA17: 2.409955 | AB17: 535.97451 | AC17: 7.25 | AD17: 3885.8152 | AE17: 6150.5511 | AF17: 973.07891
C18: 241214000027 | D18: 45643 | E18: Sam.Pao | F18: Sam.Pao | G18: Sampao | H18: 0.0295 | I18: 50 | J18: 555.8 | P18: 555.8 | S18: 21.726099 | U18: 0.86764706 | X18: 22.593746 | Y18: 5.3230147 | Z18: 44.59 | AA18: 0.0240425 | AB18: 49.937057 | AC18: 7.25 | AD18: 362.04366 | AE18: 384.63741 | AF18: 171.16259
C19: 241128000030 | D19: 45643 | E19: Sam.Pao | F19: Sam.Pao | G19: ShanShan | H19: 6.1439 | I19: 3510 | J19: 18062 | P19: 18062 | S19: 4524.8468 | U19: 180.70294 | X19: 4705.5498 | Y19: 1108.6125 | AA19: 5.0072785 | AB19: 1113.6198 | AC19: 7.25 | AD19: 8073.7437 | AE19: 12779.293 | AF19: 5282.7065
C20: 241126000049 | D20: 45638 | E20: Sam.Pao | F20: Sam.Pao | G20: AiGeLi | H20: 20.5166 | I20: 8722 | J20: 58944 | P20: 58944 | S20: 15110.023 | U20: 603.42941 | X20: 15713.453 | Y20: 3702.0394 | Z20: 1082.8 | AA20: 16.721029 | AB20: 4801.5605 | AC20: 7.25 | AD20: 34811.313 | AE20: 50524.766 | AF20: 8419.2339
C21: 241115000013 | D21: 45638 | E21: Sam.Pao | F21: Sam.Pao | G21: ChenGaoHong | H21: 6.3827 | I21: 2355 | J21: 13563 | P21: 13563 | S21: 4700.7178 | U21: 187.72647 | X21: 4888.4442 | Y21: 1151.7019 | AA21: 5.2019005 | AB21: 1156.9038 | AC21: 7.25 | AD21: 8387.5525 | AE21: 13275.997 | AF21: 287.00324
C22: 241219000026 | D22: 46010 | E22: Sam.Pao | F22: Sam.Pao | G22: ShanShan | H22: 6.1439 | I22: 3510 | J22: 18062 | P22: 18062 | S22: 4407.1189 | T22: 8.0304387 | U22: 171.66779 | X22: 4586.8171 | Y22: 1087.5607 | AA22: 5.1970166 | AB22: 1092.7577 | AC22: 7.25 | AD22: 7922.4931 | AE22: 12509.31 | AF22: 5552.6898
C23: 241115000013 | D23: 45638 | E23: Sam.Pao | F23: Sam.Pao | G23: ChenGaoHong | H23: 25.3204 | I23: 5102 | J23: 53816 | P23: 53816 | S23: 18162.733 | T23: 33.095252 | U23: 707.48176 | X23: 18903.31 | Y23: 4482.0832 | AA23: 21.41808 | AB23: 4503.5012 | AC23: 7.25 | AD23: 32650.384 | AE23: 51553.694 | AF23: 2262.3065
C24: 241211000027 | D24: 45643 | E24: Sam.Pao | F24: Sam.Pao | G24: ShanShan | H24: 0.228 | I24: 45 | J24: 520 | P24: 520 | S24: 169.70912 | U24: 7.0411765 | X24: 176.75029 | Y24: 38.619679 | AA24: 0.19919824 | AB24: 38.818878 | AC24: 7.26 | AD24: 281.82505 | AE24: 458.57535 | AF24: 61.424654
C25: 241213000046 | D25: 46018 | E25: Sam.Pao | F25: Sam.Pao | G25: Mr. Jiang | H25: 5.2541 | I25: 1423 | J25: 15725.5 | P25: 15725.5 | S25: 3910.8275 | U25: 162.25897 | X25: 4073.0865 | Y25: 889.96341 | AA25: 4.5903835 | AB25: 894.55379 | AC25: 7.26 | AD25: 6494.4605 | AE25: 10567.547 | AF25: 5157.953
C26: 241223000048 | D26: 46018 | E26: Sam.Pao | F26: Sam.Pao | G26: Mr. Jiang | H26: 0.8576 | I26: 189 | J26: 3063 | P26: 3063 | S26: 638.34447 | U26: 26.484706 | W26: 53.42 | X26: 718.24918 | Y26: 145.2642 | AA26: 0.74926494 | AB26: 146.01346 | AC26: 7.26 | AD26: 1060.0577 | AE26: 1778.3069 | AF26: 1284.6931
C27: 241224000043 | D27: 46018 | E27: Sam.Pao | F27: Sam.Pao | G27: Mr. Jiang | H27: 0.4278 | I27: 118 | J27: 1777 | P27: 1777 | S27: 318.4279 | U27: 13.211471 | W27: 57.82 | X27: 389.45937 | Y27: 72.462714 | AA27: 0.37375879 | AB27: 72.836473 | AC27: 7.26 | AD27: 528.79279 | AE27: 918.25216 | AF27: 858.74784
C28: 241023000034 | D28: 45617 | E28: Sam.Pao | F28: Sam.Pao | G28: Nick Wang | H28: 0.0452 | I28: 13 | J28: 131.2 | P28: 131.2 | S28: 33.644088 | U28: 1.3958824 | X28: 35.039971 | Y28: 7.6561821 | AA28: 0.039490176 | AB28: 7.6956722 | AC28: 7.26 | AD28: 55.87058 | AE28: 90.910551 | AF28: 40.289449
A29: JOB120404 | B29: COLL004342 | C29: 241128000030 | D29: 46020 | E29: Sam.Pao | F29: Sam.Pao | G29: ShanShan | H29: 5.8708 | I29: 3354 | J29: 17261.3 | P29: 17261.3 | Q29: 29064.05 | R29: 登凯=45401 报关=2960 拖车费=1670 杂费=89 过磅费=70 | S29: 4333.1684 | U29: 155.40353 | X29: 4488.5719 | Y29: 962.03764 | Z29: 114.79 | AA29: 11.577563 | AB29: 1088.4052 | AC29: 7.25 | AD29: 7890.9377 | AE29: 12379.51 | AF29: 4881.7904
C30: 241222000001 | D30: 46020 | E30: Sam.Pao | F30: Sam.Pao | G30: AiGeLi | H30: 2.8117 | I30: 782 | J30: 7663 | P30: 7663 | S30: 2075.2827 | U30: 74.427353 | X30: 2149.71 | Y30: 460.74832 | AA30: 5.5448378 | AB30: 466.29315 | AC30: 7.25 | AD30: 3380.6254 | AE30: 5530.3354 | AF30: 2132.6646
A31: 合计 | H31: =SUM(H5:H30) -> 117.0682 | AF31: =SUM(AF5:AF30) -> 50746.861
C33: 基本任务：小于6千 | F33: 不够基本任务6千， 公司将根据空运提成里抽出补足基数 | K33: 浦生 提成
K34: 名称 | L34: 计费体积 | M34: 毛利
C35: 基本任务：6千-3.5万 | F35: 按40%提成 | K35: LOS | L35: =SUM(H31) -> 117.0682 | M35: =SUM(AF31) -> 50746.861
K36: 任务 | M36: 6000
C37: 基本任务：3.5万以上 | F37: 按50%提成 | K37: 提成计数 | M37: =SUM(M35-M36) -> 44746.861
K38: 基数 | M38: 35000
K39: 提成计数40% | M39: 0.4
K40: 提成金额 | M40: =SUM(M38*M39) -> 14000
K41: 实提成计数 | M41: =SUM(M37-M38) -> 9746.8609
K42: 提成点数50% | M42: 0.5
...

Sheet 无人
A1: LOS毛利表
A3: JOB | B3: 集装编号 | C3: 运单编号 | D3: 日期 | E3: 业务 | F3: 发货人 | G3: 收货人 | H3: 计费体积 | I3: 计费重量 | J3: 应 收 | Q3: 总应收 | R3: 起 运 港 成 本 | W3: 代垫运费 | X3: 起运港成本 合计 | Y3: 目的港成本 | AE3: 总支出 | AF3: 利润
J4: 应收RMB | K4: LOS Income(NGN)收到(奈拉) | L4: LOS 收到USD | M4: 美元汇率 dollar currency rate | N4: 应收 到付款USD | O4: 汇率 | P4: 人民币 | R4: 代理商 | S4: 运费+出口报关费 | T4: 提货费 | U4: 装卸费 | V4: 包装费 | Y4: 进口报关费 | Z4: 到门配送费 | AA4: 转运费 | AB4: 目的港支出 | AC4: 汇率 | AD4: 人民币 | AE4: 起运港+目的港
A5: JOB120360 | B5: COLL004315 | C5: 240925000017 | D5: 45631 | E5: 无人 | F5: dejare James | G5: James | H5: 0.1799 | I5: 17 | K5: 84600 | M5: 1679.5713 | N5: 50.369995 | O5: 7.27 | P5: 366.18986 | Q5: 98060.718 | R5: 登凯=43870.25 创泽=1270 拖车费=1670 杂费=84 过磅费=69 | S5: 124.24542 | U5: 6.6139706 | X5: 130.85939 | Y5: 29.315763 | AB5: 29.315763 | AC5: 7.24 | AD5: 212.24613 | AE5: 343.10552 | AF5: 23.084346
C6: 241125000067 | D6: 45631 | E6: 无人 | F6: dejare James | G6: Adam e | H6: 1.0967 | I6: 203 | K6: 552736 | M6: 1679.9977 | N6: 329.00998 | O6: 7.27 | P6: 2391.9026 | S6: 757.42053 | U6: 40.319853 | X6: 797.74039 | Y6: 178.71372 | AB6: 178.71372 | AC6: 7.24 | AD6: 1293.8873 | AE6: 2091.6277 | AF6: 300.27486
C7: 241128000039 | D7: 45631 | E7: 无人 | F7: dejare James | G7: James | H7: 0.5074 | I7: 252 | K7: 239442 | M7: 1572.9993 | N7: 152.22003 | O7: 7.27 | P7: 1106.6396 | S7: 350.42872 | U7: 18.654412 | X7: 369.08313 | Y7: 82.683815 | AB7: 82.683815 | AC7: 7.24 | AD7: 598.63082 | AE7: 967.71395 | AF7: 138.92567
C8: 241202000042 | D8: 45631 | E8: 无人 | F8: dejare James | G8: James | H8: 0.1256 | I8: 54 | K8: 63300 | M8: 1679.9359 | N8: 37.680008 | O8: 7.27 | P8: 273.93366 | S8: 86.743885 | U8: 4.6176471 | X8: 91.361532 | Y8: 20.467259 | AB8: 20.467259 | AC8: 7.24 | AD8: 148.18295 | AE8: 239.54449 | AF8: 34.389172
C9: 241208000009 | D9: 45636 | E9: 无人 | F9: Mailmail Abv sales person 1 | G9: Obetta U | H9: 4.1388 | I9: 540 | K9: 2050281 | M9: 1597.9993 | N9: 1283.03 | O9: 7.27 | P9: 9327.6281 | S9: 3016.9722 | U9: 127.81588 | X9: 3144.7881 | Y9: 707.43048 | AA9: 3.3852949 | AB9: 710.81577 | AC9: 7.3 | AD9: 5188.9551 | AE9: 8333.7432 | AF9: 993.88491
C10: 241213000056 | D10: 45643 | E10: 无人 | F10: dejare James | G10: James | H10: 1.2461 | I10: 230 | K10: 116181 | L10: 300 | M10: 310.76071 | N10: 373.86 | O10: 7.27 | P10: 2717.9622 | S10: 917.72516 | U10: 36.65 | X10: 954.37516 | Y10: 224.84775 | AA10: 1.0155715 | AB10: 225.86332 | AC10: 7.25 | AD10: 1637.5091 | AE10: 2591.8842 | AF10: 126.07796
C11: 241223000044 | D11: 46018 | E11: 无人 | F11: dejare James | G11: James | H11: 0.7236 | I11: 173 | K11: 336691 | M11: 1550.9991 | N11: 217.08008 | O11: 7.24 | P11: 1571.6598 | S11: 538.60315 | U11: 22.346471 | X11: 560.94962 | Y11: 122.56667 | AA11: 0.63219229 | AB11: 123.19886 | AC11: 7.26 | AD11: 894.42372 | AE11: 1455.3733 | AF11: 116.28644
C12: 241224000028 | D12: 46018 | E12: 无人 | F12: dejare James | G12: James | H12: 0.4936 | I12: 87 | K12: 229672 | M12: 1550.9996 | N12: 148.07999 | O12: 7.24 | P12: 1072.0991 | S12: 367.40535 | U12: 15.243529 | X12: 382.64888 | Y12: 83.608218 | AA12: 0.43124671 | AB12: 84.039465 | AC12: 7.26 | AD12: 610.12652 | AE12: 992.7754 | AF12: 79.32373
A13: 合计 | H13: =SUM(H5:H12) -> 8.5117 | AF13: =SUM(AF5:AF12) -> 1812.2471
C15: 基本任务：小于6千 | F15: 不够基本任务6千， 公司将根据空运提成里抽出补足基数 | K15: 无人 提成
K16: 名称 | L16: 计费体积 | M16: 毛利
C17: 基本任务：6千-3.5万 | F17: 按40%提成 | K17: LOS | L17: =SUM(H13) -> 8.5117 | M17: =SUM(AF13) -> 1812.2471
K18: 基数
C19: 基本任务：3.5万以上 | F19: 按50%提成 | K19: 提成计数
K20: 提成点数
K21: 提成金额

Sheet 提成总表
A1: 24年12月份业务员提成总表-68³
A3: 名称 姓名 | B3: LOS毛利 | C3: 计费体积 立方 | D3: 6千-3.5万 | I3: 3.5万以上 | M3: 合计 提成金额 | N3: 备注 | P3: 基本任务：小于6千 | R3: 不够基本任务6千， 公司将根据空运提成里抽出补足基数
D4: 基数 | E4: 提成计数 | F4: 提成计数 | G4: 提成点 数40% | H4: 提成金额 | I4: 基数 | J4: 提成计数 | K4: 提成点 数50% | L4: 提成金额
A5: 黄 颖 | B5: =SUM(黄颖!M40) -> 18029.043 | C5: =SUM(黄颖!L40) -> 91.2918 | D5: 6000 | E5: =SUM(B5-D5) -> 12029.043 | G5: 0.4 | H5: =SUM(E5*G5) -> 4811.6173 | M5: =SUM(H5+L5) -> 4811.6173 | P5: 基本任务：6千-3.5万 | R5: 按40%提成
A6: 陈三凤 | B6: =SUM(三凤!M17) -> 27438.669 | C6: =SUM(三凤!L17) -> 59.0041 | D6: 6000 | E6: =SUM(B6-D6) -> 21438.669 | G6: 0.4 | H6: =SUM(E6*G6) -> 8575.4677 | M6: =SUM(H6+L6) -> 8575.4677 | N6: zhong zi xin利润的一半27023.92
A7: 吕沛霖 | B7: =SUM(吕沛霖!M20) -> 29717.038 | C7: =SUM(吕沛霖!L20) -> 28.7944 | D7: 6000 | E7: =SUM(B7-D7) -> 23717.038 | G7: 0.4 | H7: =SUM(E7*G7) -> 9486.8152 | M7: =SUM(H7+L7) -> 9486.8152 | P7: 基本任务：3.5万以上 | R7: 按50%提成
A8: 朱小飞 | B8: =SUM(朱小飞!M25) -> 4032.981 | C8: =SUM(朱小飞!L25) -> 29.7273 | D8: 6000 | E8: =SUM(B8-D8) -> -1967.019 | G8: 0.4 | N8: Halifa利润的一半332.49 不够基数，下个月基本数为7967.02
A9: 陆总 | B9: =SUM(陆总!M19) -> -4046.607 | C9: =SUM(陆总!L19) -> 38.0819
A10: 苏慧琪 | B10: =SUM(苏慧琪!M10) -> 22.552246 | C10: =SUM(苏慧琪!L10) -> 0.0662
A11: 罗珮文 | B11: =SUM(罗珮文!M39) -> -40380.23 | C11: =SUM(罗珮文!L39) -> 222.6355 | P11: 领款人：
A12: 浦海森 | B12: =SUM(浦生!M35) -> 50746.861 | C12: =SUM(浦生!L35) -> 117.0682 | D12: 6000 | E12: =SUM(B12-D12) -> 44746.861 | F12: 35000 | G12: 0.4 | H12: =SUM(F12*G12) -> 14000 | I12: 35000 | J12: =SUM(E12-I12) -> 9746.8609 | K12: 0.5 | L12: =SUM(J12*K12) -> 4873.4304 | M12: =SUM(H12+L12) -> 18873.43 | P12: 日期：
A13: 无人 | B13: =SUM(无人!M17) -> 1812.2471 | C13: =SUM(无人!L17) -> 8.5117
A14: 合计 | B14: =SUM(B5:B13) -> 87372.555 | C14: =SUM(C5:C13) -> 595.1811 | M14: =SUM(M5:M13) -> 41747.331
A16: 确认人： | J16: 日期：

Sheet 黄颖 陈三凤 朱小飞 吕沛霖 2025年10月份发放
A1: 24年12月份业务员提成总表-68³
A3: 名称 姓名 | B3: LOS毛利 | C3: 计费体积 立方 | D3: 6千-3.5万 | I3: 3.5万以上 | M3: 合计 提成金额 | N3: 备注
D4: 基数 | E4: 提成计数 | F4: 提成计数 | G4: 提成点 数40% | H4: 提成金额 | I4: 基数 | J4: 提成计数 | K4: 提成点 数50% | L4: 提成金额
A5: 黄 颖 | B5: =SUM(黄颖!M40) -> 18029.043 | C5: =SUM(黄颖!L40) -> 91.2918 | D5: 6000 | E5: =SUM(B5-D5) -> 12029.043 | G5: 0.4 | H5: =SUM(E5*G5) -> 4811.6173 | M5: =SUM(H5+L5) -> 4811.6173
L6: 领款人：
A7: 陈三凤 | B7: =SUM(三凤!M17) -> 27438.669 | C7: =SUM(三凤!L17) -> 59.0041 | D7: 6000 | E7: =SUM(B7-D7) -> 21438.669 | G7: 0.4 | H7: =SUM(E7*G7) -> 8575.4677 | M7: =SUM(H7+L7) -> 8575.4677 | N7: zhong zi xin利润的一半27023.92
L8: 领款人：
A9: 朱小飞 | B9: =SUM(朱小飞!M25) -> 4032.981 | C9: =SUM(朱小飞!L25) -> 29.7273 | D9: 6000 | E9: =SUM(B9-D9) -> -1967.019 | G9: 0.4 | N9: Halifa利润的一半332.49 不够基数，下个月基本数为7967.02
L10: 确认人：
A11: 吕沛霖 | B11: =SUM(吕沛霖!M20) -> 29717.038 | C11: =SUM(吕沛霖!L20) -> 28.7944 | D11: 6000 | E11: =SUM(B11-D11) -> 23717.038 | G11: 0.4 | H11: =SUM(E11*G11) -> 9486.8152 | M11: =SUM(H11+L11) -> 9486.8152
L12: 领款人：
A13: 合计 | B13: =SUM(B5:B9) -> 49500.693 | C13: =SUM(C5:C9) -> 180.0232 | M13: =SUM(M5:M11) -> 22873.9
A15: 确认人： | J15: 日期：
