Workbook

Sheet 黄颖
A1: LOS毛利表
A3: JOB | B3: 集装编号 | C3: 运单编号 | D3: 日期 | E3: 业务 | F3: 发货人 | G3: 收货人 | H3: 计费体积 | I3: 计费重量 | J3: 应 收 | Q3: 总应收 | R3: 起 运 港 成 本 | W3: 代垫运费 | X3: 起运港成本 合计 | Y3: 目的港成本 | AE3: 总支出 | AF3: 利润
J4: 应收RMB | K4: LOS Income(NGN)收到(奈拉) | L4: LOS 收到USD | M4: 美元汇率 dollar currency rate | N4: 应收 到付款USD | O4: 汇率 | P4: 人民币 | R4: 代理商 | S4: 运费+出口报关费 | T4: 提货费 | U4: 装卸费 | V4: 包装费 | Y4: 进口报关费 | Z4: 到门配送费 | AA4: 转运费 | AB4: 目的港支出 | AC4: 汇率 | AD4: 人民币 | AE4: 起运港+目的港
C5: 240904000027 | D5: 45539 | E5: 黄颖 | F5: ying | G5: zhounengquan | H5: 0.057 | I5: 22 | K5: 55920 | M5: 1679.2793 | N5: 33.3 | O5: 7.12 | P5: 237.1 | S5: 43.07775 | U5: 1.2154412 | X5: 44.293191 | Y5: 9.0005179 | Z5: 7.02 | AB5: 16.020518 | AC5: 7.12 | AD5: 114.06609 | AE5: 158.35928 | AF5: 78.740721
C6: 240902000015 | D6: 45547 | E6: 黄颖 | F6: ying | G6: Ms PEJU | H6: 3.028 | I6: 338 | J6: 7000 | P6: 7000 | S6: 1992.1568 | U6: 57.888235 | X6: 2050.0451 | Y6: 478.13278 | AB6: 478.13278 | AC6: 7.12 | AD6: 3404.3054 | AE6: 5454.3504 | AF6: 1545.6496
C7: 240904000027 | D7: 45547 | E7: 黄颖 | F7: ying | G7: zhounengquan | H7: 0.0074 | I7: 6 | K7: 7260 | M7: 2261.6822 | N7: 3.21 | O7: 7.12 | P7: 22.9 | S7: 4.8685471 | U7: 0.14147059 | X7: 5.0100176 | Y7: 1.1684883 | AB7: 1.1684883 | AC7: 7.12 | AD7: 8.3196367 | AE7: 13.329654 | AF7: 9.5703457
C8: 240904000032 | D8: 45547 | E8: 黄颖 | F8: ying | G8: Bruce | H8: 2.736 | I8: 1216 | J8: 5623 | P8: 5623 | S8: 1800.0466 | U8: 52.305882 | X8: 1852.3525 | Y8: 432.02486 | AB8: 432.02486 | AC8: 7.12 | AD8: 3076.017 | AE8: 4928.3695 | AF8: 694.63052
C9: 240905000028 | D9: 45547 | E9: 黄颖 | F9: ying | G9: Bruce | H9: 2.499 | I9: 970 | J9: 5265 | P9: 5265 | S9: 1644.1215 | U9: 47.775 | X9: 1691.8965 | Y9: 394.60165 | AB9: 394.60165 | AC9: 7.12 | AD9: 2809.5638 | AE9: 4501.4603 | AF9: 763.53972
C10: 240905000029 | D10: 45547 | E10: 黄颖 | F10: ying | G10: zhounengquan | H10: 0.0359 | I10: 12 | K10: 63180 | M10: 1730.4848 | N10: 36.51 | O10: 7.12 | P10: 259.9512 | S10: 23.619032 | U10: 0.68632353 | X10: 24.305356 | Y10: 5.6687473 | Z10: 7.06 | AB10: 12.728747 | AC10: 7.12 | AD10: 90.628681 | AE10: 114.93404 | AF10: 145.01716
C11: 240816000024 | D11: 45554 | E11: 黄颖 | F11: ying | G11: Sunday Adelena | H11: 22.5 | I11: 11357 | J11: 51447.45 | P11: 51447.45 | S11: 14803.015 | U11: 430.14706 | X11: 15233.162 | Y11: 3552.836 | AB11: 3552.836 | AC11: 7.12 | AD11: 25296.193 | AE11: 40529.354 | AF11: 10918.096
C12: 240906000035 | D12: 45547 | E12: 黄颖 | F12: ying | G12: Sanusi samad | H12: 2.343 | I12: 480 | J12: 5181.75 | P12: 5181.75 | S12: 1541.4873 | U12: 44.792647 | X12: 1586.2799 | Y12: 369.96866 | AB12: 369.96866 | AC12: 7.12 | AD12: 2634.1768 | AE12: 4220.4568 | AF12: 961.29324
C13: 240909000047 | D13: 45547 | E13: 黄颖 | F13: ying | G13: Bruce | H13: 2.709 | I13: 1034 | J13: 5562 | P13: 5562 | S13: 1782.283 | U13: 51.789706 | X13: 1834.0727 | Y13: 427.76146 | AB13: 427.76146 | AC13: 7.12 | AD13: 3045.6616 | AE13: 4879.7343 | AF13: 682.26574
C14: 240911000011 | D14: 45547 | E14: 黄颖 | F14: ying | G14: Bruce | H14: 1.019 | I14: 374 | J14: 2095 | P14: 2095 | S14: 670.41209 | U14: 19.480882 | X14: 689.89297 | Y14: 160.904 | AB14: 160.904 | AC14: 7.12 | AD14: 1145.6365 | AE14: 1835.5294 | AF14: 259.47058
A15: JOB090375 | B15: COLL004167 | C15: 240816000024 | D15: 45554 | E15: 黄颖 | F15: ying | G15: Sunday Adelena | H15: 4.5226 | I15: 5204 | J15: 10335.77 | P15: 10335.77 | Q15: 67001.276 | R15: 卓志=41025 赛捷=2800 拖车费=1670 杂费=61 过磅费=67 | S15: 3034.3321 | U15: 106.41412 | X15: 3140.7462 | Y15: 714.13583 | AA15: 3.5316185 | AB15: 717.66745 | AC15: 7.18 | AD15: 5152.8523 | AE15: 8293.5985 | AF15: 2042.1715
C16: 240911000014 | D16: 45554 | E16: 黄颖 | F16: ying | G16: jiangnan | H16: 0.546 | I16: 153 | J16: 1212.75 | P16: 1212.75 | S16: 366.32585 | U16: 12.847059 | X16: 379.17291 | Y16: 86.215488 | AA16: 0.42636176 | AB16: 86.641849 | AC16: 7.18 | AD16: 622.08848 | AE16: 1001.2614 | AF16: 211.48861
C17: 240912000029 | D17: 45554 | E17: 黄颖 | F17: ying | G17: Bruce | H17: 1.2975 | I17: 506 | J17: 2649 | P17: 2649 | S17: 870.5271 | U17: 30.529412 | X17: 901.05651 | Y17: 204.88021 | AA17: 1.0131949 | AB17: 205.89341 | AC17: 7.18 | AD17: 1478.3147 | AE17: 2379.3712 | AF17: 269.62884
C18: 240912000039 | D18: 45554 | E18: 黄颖 | F18: ying | G18: Sunday Adelena | H18: 2.7009 | I18: 1774 | J18: 5427.88 | P18: 5427.88 | S18: 1812.1053 | U18: 63.550588 | X18: 1875.6559 | Y18: 426.48244 | AA18: 2.1090851 | AB18: 428.59152 | AC18: 7.18 | AD18: 3077.2871 | AE18: 4952.943 | AF18: 474.93698
C19: 240913000030 | D19: 45554 | E19: 黄颖 | F19: ying | G19: jiangnan | H19: 0.6324 | I19: 181 | J19: 1411.2 | P19: 1411.2 | S19: 424.2939 | U19: 14.88 | X19: 439.1739 | Y19: 99.858378 | AA19: 0.49383 | AB19: 100.35221 | AC19: 7.18 | AD19: 720.52885 | AE19: 1159.7028 | AF19: 251.49725
C20: 240917000017 | D20: 45554 | E20: 黄颖 | F20: ying | G20: makus | H20: 1.7265 | I20: 349 | J20: 4987.5 | P20: 4987.5 | S20: 1158.3546 | U20: 40.623529 | X20: 1198.9781 | Y20: 272.62095 | AA20: 1.3481934 | AB20: 273.96914 | AC20: 7.18 | AD20: 1967.0985 | AE20: 3166.0765 | AF20: 1821.4235
C21: 240910000011 | D21: 45559 | E21: 黄颖 | F21: ying | G21: Sunday Adelena | H21: 4.9278 | I21: 2354 | J21: 10516 | P21: 10516 | S21: 3306.1915 | U21: 115.94824 | V21: 400 | X21: 3822.1397 | Y21: 778.11846 | AA21: 3.8480321 | AB21: 781.96649 | AC21: 7.18 | AD21: 5614.5194 | AE21: 9436.6591 | AF21: 1079.3409
C22: 240912000038 | D22: 45559 | E22: 黄颖 | F22: ying | G22: Nura | H22: 6.5307 | I22: 1272 | J22: 13726 | P22: 13726 | S22: 4381.6195 | U22: 153.66353 | X22: 4535.283 | Y22: 1031.2225 | AA22: 5.0997084 | AB22: 1036.3222 | AC22: 7.18 | AD22: 7440.7935 | AE22: 11976.076 | AF22: 1749.9235
C23: 240910000011 | D23: 45559 | E23: 黄颖 | F23: ying | G23: Sunday Adelena | H23: 1.8876 | I23: 1002 | J23: 4020.83 | P23: 4020.83 | S23: 1187.2366 | U23: 41.638235 | X23: 1228.8748 | Y23: 298.05926 | AA23: 1.4739935 | AB23: 299.53325 | AC23: 7.18 | AD23: 2150.6487 | AE23: 3379.5235 | AF23: 641.30647
A24: JOB090388 | B24: COLL004181 | C24: 240912000038 | D24: 45560 | E24: 黄颖 | F24: ying | G24: Nura | H24: 6.0188 | I24: 1018 | J24: 12660 | P24: 12660 | Q24: 62687.443 | R24: 登凯=38533 赛捷=1620 拖车费=1670 杂费=61 过磅费=59 | S24: 3712.4489 | U24: 115.06529 | X24: 3827.5142 | Y24: 950.39153 | AA24: 4.6999747 | AB24: 955.09151 | AC24: 7.18 | AD24: 6857.557 | AE24: 10685.071 | AF24: 1974.9287
C25: 240914000053 | D25: 45560 | E25: 黄颖 | F25: ying | G25: Nura | H25: 0.3137 | I25: 144.5 | J25: 672.8 | P25: 672.8 | S25: 193.49293 | U25: 5.9972059 | X25: 199.49013 | Y25: 49.534429 | AA25: 0.24496279 | AB25: 49.779392 | AC25: 7.18 | AD25: 357.41604 | AE25: 556.90617 | AF25: 115.89383
C26: 240923000035 | D26: 45547 | E26: 黄颖 | F26: ying | G26: Bruce | H26: 0.7148 | I26: 310 | J26: 1406 | P26: 1406 | S26: 440.89495 | U26: 13.665294 | X26: 454.56024 | Y26: 112.86965 | AA26: 0.55817471 | AB26: 113.42783 | AC26: 7.18 | AD26: 814.4118 | AE26: 1268.972 | AF26: 137.02796
A27: 合 计 | H27: =SUM(H5:H26) -> 68.7536 | AF27: =SUM(AF5:AF26) -> 26827.841
C29: 基本任务：小于6千 | F29: 不够基本任务6千， 公司将根据空运提成里抽出补足基数 | K29: 黄颖 提成
K30: 名称 | L30: 计费体积 | M30: 毛利
C31: 基本任务：6千-3.5万 | F31: 按40%提成 | K31: LOS | L31: =SUM(H27) -> 68.7536 | M31: =SUM(AF27) -> 26827.841
K32: 基数 | M32: 6000
C33: 基本任务：3.5万以上 | F33: 按50%提成 | K33: 提成计数 | M33: =SUM(M31-M32) -> 20827.841
K34: 提成点数 | M34: 0.4
K35: 提成金额 | M35: =SUM(M33*M34) -> 8331.1365

Sheet 三凤
A1: LOS毛利表
A2: JOB | B2: 集装编号 | C2: 运单编号 | D2: 日期 | E2: 业务 | F2: 发货人 | G2: 收货人 | H2: 计费体积 | I2: 计费重量 | J2: 应 收 | Q2: 总应收 | R2: 起 运 港 成 本 | W2: 代垫运费 | X2: 起运港成本 合计 | Y2: 目的港成本 | AE2: 总支出 | AF2: 利润
J3: 应收RMB | K3: LOS Income(NGN)收到(奈拉) | L3: LOS 收到USD | M3: 美元汇率 dollar currency rate | N3: 应收 到付款USD | O3: 汇率 | P3: 人民币 | R3: 代理商 | S3: 运费+出口报关费 | T3: 提货费 | U3: 装卸费 | V3: 包装费 | Y3: 进口报关费 | Z3: 到门配送费 | AA3: 转运费 | AB3: 目的港支出 | AC3: 汇率 | AD3: 人民币 | AE3: 起运港+目的港
C4: 240828000064 | D4: 45539 | E4: Bella | F4: Bella Chan | G4: zhong zi xin | H4: 2.368 | I4: 2617 | K4: 2020000 | M4: 1688.522 | N4: 1196.3125 | O4: 7.23 | P4: 8649.3394 | S4: 1789.616 | U4: 50.494118 | X4: 1840.1101 | Y4: 373.91625 | Z4: 70.8 | AB4: 444.71625 | AC4: 7.12 | AD4: 3166.3797 | AE4: 5006.4898 | AF4: 3642.8495
C5: 240812000057 | D5: 45518 | E5: Bella | F5: Bella Chan | G5: zhong zi xin | H5: 2.0765 | I5: 1506 | K5: 1325000 | M5: 1924.5854 | N5: 688.45996 | O5: 7.12 | P5: 4901.8349 | S5: 3933.9783 | T5: 66.204458 | X5: 4000.1828 | AA5: 15.579739 | AB5: 15.579739 | AC5: 7.12 | AD5: 110.92774 | AE5: 4111.1105 | AF5: 790.72442 | AG5: =SUM(AF4:AF5) -> 4433.5739
C6: 240827000016 | D6: 45539 | E6: Bella | F6: Bella Chan | G6: new hope 边鹏飞 | H6: 0.2537 | I6: 138 | K6: 202127.5 | M6: 1735 | N6: 116.5 | O6: 7.12 | P6: 829.48 | S6: 191.73378 | U6: 5.4097794 | W6: 240 | X6: 437.14355 | Y6: 40.0602 | AB6: 40.0602 | AC6: 7.12 | AD6: 285.22862 | AE6: 722.37218 | AF6: 107.10782 | AG6: =SUM(AG5/2) -> 2216.787
C7: 240914000051 | D7: 45554 | E7: Bella | F7: Bella Chan | G7: Shuaibu musa | H7: 0.3911 | I7: 120 | J7: 907.12 | P7: 907.12 | S7: 262.39934 | U7: 9.2023529 | X7: 271.6017 | Y7: 61.756185 | AA7: 0.30540309 | AB7: 62.061588 | AC7: 7.18 | AD7: 445.60221 | AE7: 717.2039 | AF7: 189.9161
A8: JOB100351 | B8: COLL004217 | C8: 241015000029 | D8: 45547 | E8: Bella | F8: Bella Chan | G8: Yang Bo | H8: 181.1178 | J8: 257973.5 | K8: 60800000 | L8: 到付 | M8: 1770.0001 | N8: 34350.28 | O8: 7.12 | P8: 502547.49 | Q8: 502547.49 | R8: 鼎程=245686.66 鼎程出口=750 | S8: 246436.66 | X8: 246436.66 | Y8: 31498.56 | AB8: 31498.56 | AC8: 7.12 | AD8: 224269.75 | AE8: 470706.41 | AF8: 31841.086
A9: 合 计 | H9: =SUM(H4:H8) -> 186.2071 | AF9: =SUM(AF4:AF8) -> 36571.684
AF10: 2216.787
C11: 基本任务：小于6千 | F11: 不够基本任务6千， 公司将根据空运提成里抽出补足基数 | K11: 三凤 提成 | AF11: =SUM(AF9-AF10) -> 34354.897
K12: 名称 | L12: 计费体积 | M12: 毛利 | N12: 备注
C13: 基本任务：6千-3.5万 | F13: 按40%提成 | K13: LOS | L13: =SUM(H9) -> 186.2071 | M13: 34354.9 | N13: 总利润减zhong zi xin 利润的 一半2216.79
K14: 基数 | M14: 2000
C15: 基本任务：3.5万以上 | F15: 按50%提成 | K15: 提成计数 | M15: =SUM(M13-M14) -> 32354.9
K16: 提成点数 | M16: 0.1
K17: 提成金额 | M17: =SUM(M15*M16) -> 3235.49

Sheet 朱小飞
A1: LOS毛利表
A3: JOB | B3: 集装编号 | C3: 运单编号 | D3: 日期 | E3: 业务 | F3: 发货人 | G3: 收货人 | H3: 计费体积 | I3: 计费重量 | J3: 应 收 | Q3: 总应收 | R3: 起 运 港 成 本 | W3: 代垫运费 | X3: 起运港成本 合计 | Y3: 目的港成本 | AE3: 总支出 | AF3: 利润
J4: 应收RMB | K4: LOS Income(NGN)收到(奈拉) | L4: LOS 收到USD | M4: 美元汇率 dollar currency rate | N4: 应收 到付款USD | O4: 汇率 | P4: 人民币 | R4: 代理商 | S4: 运费+出口报关费 | T4: 提货费 | U4: 装卸费 | V4: 包装费 | Y4: 进口报关费 | Z4: 到门配送费 | AA4: 转运费 | AB4: 目的港支出 | AC4: 汇率 | AD4: 人民币 | AE4: 起运港+目的港
C5: 240903000015 | D5: 45539 | E5: 朱小飞 | F5: Isabel Zhu | G5: Halifa Success | H5: 0.42 | I5: 62 | J5: 959.18 | P5: 959.18 | S5: 310.36147 | T5: 0.7203 | U5: 10.808824 | X5: 321.89059 | Y5: 66.319606 | AA5: 0.43729412 | AB5: 66.7569 | AC5: 7.12 | AD5: 475.30913 | AE5: 797.19972 | AF5: 161.98028
C6: 240912000025 | D6: 45554 | E6: 朱小飞 | F6: Isabel Zhu | G6: Halifa Success | H6: 0.0329 | I6: 7.28 | J6: 221.13 | P6: 221.13 | S6: 22.073481 | U6: 0.77411765 | X6: 22.847599 | Y6: 5.1950358 | AA6: 0.025691029 | AB6: 5.2207268 | AC6: 7.18 | AD6: 37.484819 | AE6: 60.332417 | AF6: 160.79758 | AG6: =SUM(AF5:AF6) -> 322.77786
C7: 240902000041 | D7: 45539 | E7: 朱小飞 | F7: Isabel Zhu | G7: Mr Qiu | H7: 0.5458 | I7: 230 | K7: 436950 | M7: 1779.04 | N7: 245.60999 | O7: 7.08 | P7: 1738.9187 | S7: 403.32212 | T7: 0.936047 | U7: 14.046324 | X7: 418.30449 | Y7: 86.183907 | AA7: 0.56827412 | AB7: 86.752181 | AC7: 7.12 | AD7: 617.67553 | AE7: 1035.98 | AF7: 702.93871 | AG7: =SUM(AG6/2) -> 161.38893
C8: 240904000040 | D8: 45547 | E8: 朱小飞 | F8: Isabel Zhu | G8: Victor Nnamdi | H8: 1.449 | I8: 227 | K8: 761250 | M8: 1751.1952 | N8: 434.70312 | O8: 7.08 | P8: 3077.6981 | S8: 953.31415 | U8: 27.701471 | X8: 981.01562 | Y8: 228.80264 | AB8: 228.80264 | AC8: 7.12 | AD8: 1629.0748 | AE8: 2610.0904 | AF8: 467.60767
C9: 240909000038 | D9: 45547 | E9: 朱小飞 | F9: Isabel Zhu | G9: Lin Bao Zhen | H9: 0.577 | I9: 154 | K9: 305348.4 | M9: 1762.7907 | N9: 173.21875 | O9: 7.08 | P9: 1226.3888 | S9: 379.61509 | U9: 11.030882 | X9: 390.64597 | Y9: 91.110506 | AB9: 91.110506 | AC9: 7.12 | AD9: 648.7068 | AE9: 1039.3528 | AF9: 187.03598
C10: 240913000002 | D10: 45554 | E10: 朱小飞 | F10: Isabel Zhu | G10: Lin Bao Zhen | H10: 0.64 | I10: 208 | K10: 485452.8 | M10: 1764.0001 | N10: 275.19998 | O10: 7.08 | P10: 1948.4159 | S10: 429.39294 | U10: 15.058824 | X10: 444.45176 | Y10: 101.05845 | AA10: 0.49976471 | AB10: 101.55821 | AC10: 7.18 | AD10: 729.18796 | AE10: 1173.6397 | AF10: 774.77613
C11: 240913000032 | D11: 45554 | E11: 朱小飞 | F11: Isabel Zhu | G11: Gbenga | H11: 0.2805 | I11: 35 | K11: 156631 | M11: 1744.9979 | N11: 89.759995 | O11: 7.08 | P11: 635.50076 | S11: 188.19487 | U11: 6.6 | X11: 194.79487 | Y11: 44.292023 | AA11: 0.2190375 | AB11: 44.51106 | AC11: 7.18 | AD11: 319.58941 | AE11: 514.38429 | AF11: 121.11648
A12: 合计 | H12: =SUM(H5:H11) -> 3.9452 | AF12: =SUM(AF5:AF11) -> 2576.2528
AF13: 161.39
C14: 基本任务：小于6千 | F14: 不够基本任务6千， 公司将根据空运提成里抽出补足基数 | K14: 朱小飞 提成 | AF14: =SUM(AF12-AF13) -> 2414.8628
K15: 名称 | L15: 计费体积 | M15: 毛利 | N15: 备注
C16: 基本任务：6千-3.5万 | F16: 按40%提成 | K16: LOS | L16: =SUM(H12) -> 3.9452 | M16: 2414.8628 | N16: 总利润减Halifa 利润的 一半161.39
K17: 基数 | M17: 2000
C18: 基本任务：3.5万以上 | F18: 按50%提成 | K18: 提成计数 | M18: =SUM(M16-M17) -> 414.86283
K19: 提成点数 | M19: 0.1
K20: 提成金额 | M20: =SUM(M18*M19) -> 41.486283

Sheet 吕沛霖
A1: LOS毛利表
A2: JOB | B2: 集装编号 | C2: 运单编号 | D2: 日期 | E2: 业务 | F2: 发货人 | G2: 收货人 | H2: 计费体积 | I2: 计费重量 | J2: 应 收 | Q2: 总应收 | R2: 起 运 港 成 本 | W2: 代垫运费 | X2: 起运港成本 合计 | Y2: 目的港成本 | AE2: 总支出 | AF2: 利润
J3: 应收RMB | K3: LOS Income(NGN)收到(奈拉) | L3: LOS 收到USD | M3: 美元汇率 dollar currency rate | N3: 应收 到付款USD | O3: 汇率 | P3: 人民币 | R3: 代理商 | S3: 运费+出口报关费 | T3: 提货费 | U3: 装卸费 | V3: 包装费 | Y3: 进口报关费 | Z3: 到门配送费 | AA3: 转运费 | AB3: 目的港支出 | AC3: 汇率 | AD3: 人民币 | AE3: 起运港+目的港
C4: 240828000016 | D4: 45539 | E4: 吕沛霖 | F4: 喵喵速运-Layne | G4: SHAEK | H4: 0.1625 | I4: 169 | J4: 1258.39 | P4: 1258.39 | S4: 122.80938 | U4: 3.4650735 | X4: 126.27445 | Y4: 25.659371 | Z4: 93.95 | AB4: 119.60937 | AC4: 7.12 | AD4: 851.61872 | AE4: 977.89317 | AF4: 280.49683
A5: JOB090351 | B5: COLL004143 | C5: 240828000043 | D5: 45539 | E5: 吕沛霖 | F5: 喵喵速运-Layne | G5: ABDUL | H5: 6.8939 | I5: 3722 | K5: 3417687 | M5: 1690 | N5: 2022.3 | O5: 7.3 | P5: 14762.79 | Q5: 28169.659 | R5: 登凯=44776 赛捷=1750 拖车费=2270 杂费=1388 过磅费=65 | S5: 5094.288 | T5: 11.823038 | U5: 177.41654 | X5: 5283.5275 | Y5: 1088.5732 | Z5: 91.45 | AA5: 7.1777665 | AB5: 1187.2009 | AC5: 7.12 | AD5: 8452.8707 | AE5: 13736.398 | AF5: 1026.3918
C6: 240819000017 | D6: 45516 | E6: 吕沛霖 | F6: 喵喵速运-Layne | G6: WEI PING | H6: 4.904 | I6: 848 | J6: 10475 | P6: 10475 | S6: 3623.8396 | T6: 8.41036 | U6: 126.20588 | X6: 3758.4559 | Y6: 774.36035 | AA6: 5.1059294 | AB6: 779.46628 | AC6: 7.12 | AD6: 5549.7999 | AE6: 9308.2558 | AF6: 1166.7442
C7: 240902000056 | D7: 45547 | E7: 吕沛霖 | F7: 喵喵速运-Layne | G7: Hu Hai Liang | H7: 0.512 | I7: 51 | K7: 289240 | M7: 1752.9697 | N7: 165 | O7: 7.23 | P7: 1192.95 | S7: 378.34541 | T7: 0.87808 | U7: 13.176471 | X7: 392.39996 | Y7: 80.846758 | AA7: 0.53308235 | AB7: 81.37984 | AC7: 7.12 | AD7: 579.42446 | AE7: 971.82442 | AF7: 221.12558
C8: 240902000056 | D8: 45547 | E8: 吕沛霖 | F8: 喵喵速运-Layne | G8: Hu Hai Liang | H8: 3.078 | I8: 521 | K8: 1738835 | M8: 1754.4319 | N8: 991.11 | O8: 7.23 | P8: 7165.7253 | S8: 2025.0524 | U8: 58.844118 | V8: 580 | X8: 2663.8965 | Y8: 486.02797 | AB8: 486.02797 | AC8: 7.12 | AD8: 3460.5191 | AE8: 6124.4157 | AF8: 1041.3096
C9: 240905000039 | D9: 45547 | E9: 吕沛霖 | F9: 喵喵速运-Layne | G9: Mr.Wang | H9: 1.0166 | I9: 193 | K9: 466616 | M9: 1700 | N9: 274.48 | O9: 7.27 | P9: 1995.4696 | S9: 668.8331 | U9: 19.435 | X9: 688.2681 | Y9: 160.52503 | AB9: 160.52503 | AC9: 7.12 | AD9: 1142.9382 | AE9: 1831.2063 | AF9: 164.26331
A10: JOB090366 | B10: COLL004158 | C10: 240812000038 | D10: 45518 | E10: 吕沛霖 | F10: 喵喵速运-Layne | G10: Candice Ding | H10: 3.8495 | I10: 2234 | K10: 2249445 | M10: 1750.2855 | N10: 1285.1875 | O10: 7.1 | P10: 9124.8312 | Q10: 18617.338 | R10: 赛捷 | S10: 7292.9687 | T10: 122.73251 | X10: 7415.7012 | Z10: 53.1 | AA10: 28.882352 | AB10: 81.982352 | AC10: 7.12 | AD10: 583.71435 | AE10: 7999.4155 | AF10: 1125.4157
C11: 240905000030 | D11: 45554 | E11: 吕沛霖 | F11: 喵喵速运-Layne | G11: Hu Hai Liang | H11: 6.5636 | I11: 3760 | K11: 3334275 | M11: 1750.0459 | N11: 1905.25 | O11: 7.23 | P11: 13774.958 | S11: 4403.693 | U11: 154.43765 | X11: 4558.1306 | Y11: 1036.4175 | AA11: 5.1253994 | AB11: 1041.5429 | AC11: 7.18 | AD11: 7478.2783 | AE11: 12036.409 | AF11: 1738.5486
C12: 240915000008 | D12: 45559 | E12: 吕沛霖 | F12: 喵喵速运-Layne | G12: FRANK | H12: 0.5143 | I12: 152 | K12: 248724 | M12: 1727.25 | N12: 144 | O12: 7.27 | P12: 1046.88 | S12: 323.4773 | U12: 11.344853 | X12: 334.82216 | Y12: 81.209936 | AA12: 0.40160779 | AB12: 81.611544 | AC12: 7.18 | AD12: 585.97089 | AE12: 920.79305 | AF12: 126.08695
C13: 240918000030 | D13: 45560 | E13: 吕沛霖 | F13: 喵喵速运-Layne | G13: WYLB | H13: 6.4512 | I13: 2312 | K13: 3152063.3 | M13: 1745 | N13: 1806.34 | O13: 7.21 | P13: 13023.711 | S13: 3979.1571 | U13: 123.33176 | X13: 4102.4888 | Y13: 1018.6691 | AA13: 5.0376282 | AB13: 1023.7068 | AC13: 7.18 | AD13: 7350.2146 | AE13: 11452.703 | AF13: 1571.0079
A14: 合计 | H14: =SUM(H4:H13) -> 33.9456 | AF14: =SUM(AF4:AF13) -> 8461.3905
C17: 基本任务：小于6千 | F17: 不够基本任务6千， 公司将根据空运提成里抽出补足基数 | K17: 吕沛霖 提成
K18: 名称 | L18: 计费体积 | M18: 毛利
C19: 基本任务：6千-3.5万 | F19: 按40%提成 | K19: LOS | L19: =SUM(H14) -> 33.9456 | M19: =SUM(AF14) -> 8461.3905
K20: 基数 | M20: 6000
C21: 基本任务：3.5万以上 | F21: 按50%提成 | K21: 提成计数 | M21: =SUM(M19-M20) -> 2461.3905
K22: 提成点数 | M22: 0.4
K23: 提成金额 | M23: =SUM(M21*M22) -> 984.55621

Sheet 罗伟健
A1: LOS毛利表
A3: JOB | B3: 集装编号 | C3: 运单编号 | D3: 日期 | E3: 业务 | F3: 发货人 | G3: 收货人 | H3: 计费体积 | I3: 计费重量 | J3: 应 收 | Q3: 总应收 | R3: 起 运 港 成 本 | W3: 代垫运费 | X3: 起运港成本 合计 | Y3: 目的港成本 | AE3: 总支出 | AF3: 利润
J4: 应收RMB | K4: LOS Income(NGN)收到(奈拉) | L4: LOS 收到USD | M4: 美元汇率 dollar currency rate | N4: 应收 到付款USD | O4: 汇率 | P4: 人民币 | R4: 代理商 | S4: 运费+出口报关费 | T4: 提货费 | U4: 装卸费 | V4: 包装费 | Y4: 进口报关费 | Z4: 到门配送费 | AA4: 转运费 | AB4: 目的港支出 | AC4: 汇率 | AD4: 人民币 | AE4: 起运港+目的港
C5: 240830000027 | D5: 45539 | E5: 罗伟健 | F5: MailMail速运-演员 | G5: Harvey Wang | H5: 0.866 | I5: 98 | J5: 1871 | P5: 1871 | S5: 654.4795 | U5: 18.466176 | X5: 672.94568 | Y5: 136.74471 | AB5: 136.74471 | AC5: 7.12 | AD5: 973.62234 | AE5: 1646.568 | AF5: 224.43198
C6: 240909000018 | D6: 45547 | E6: 罗伟健 | F6: MailMail速运-演员 | G6: Mr.Joseph Ezekiel | H6: 0.42 | I6: 106 | J6: 500 | K6: 214855 | M6: 1802.6261 | N6: 119.19 | O6: 7.08 | P6: 1343.8652 | S6: 276.32294 | U6: 8.0294118 | X6: 284.35235 | Y6: 66.319606 | AB6: 66.319606 | AC6: 7.12 | AD6: 472.19559 | AE6: 756.54795 | AF6: 587.31725
C7: 240910000031 | D7: 45547 | E7: 罗伟健 | F7: MailMail速运-演员 | G7: Mr.Joseph Ezekiel | H7: 2.926 | I7: 2628 | K7: 2040383 | M7: 1763.8928 | N7: 1156.75 | O7: 7.08 | P7: 8189.79 | S7: 1925.0498 | U7: 55.938235 | X7: 1980.9881 | Y7: 462.02659 | AB7: 462.02659 | AC7: 7.12 | AD7: 3289.6293 | AE7: 5270.6174 | AF7: 2919.1726
C8: 240921000018 | D8: 45559 | E8: 罗伟健 | F8: MailMail速运-演员 | G8: Mr.Ahamed Tijani Danmallam | H8: 3.6205 | I8: 786 | J8: 7297 | P8: 7297 | S8: 2277.172 | U8: 79.863971 | X8: 2357.036 | Y8: 571.69079 | AA8: 2.8271846 | AB8: 574.51798 | AC8: 7.18 | AD8: 4125.0391 | AE8: 6482.0751 | AF8: 814.92491
A9: 合计 | H9: =SUM(H5:H8) -> 7.8325 | AF9: =SUM(AF5:AF8) -> 4545.8468
C11: 基本任务：小于6千 | F11: 不够基本任务6千， 公司将根据空运提成里抽出补足基数 | K11: 罗伟健 提成
K12: 名称 | L12: 计费体积 | M12: 毛利
C13: 基本任务：6千-3.5万 | F13: 按40%提成 | K13: LOS | L13: =SUM(H9) -> 7.8325 | M13: =SUM(AF9) -> 4545.8468
K14: 基数
C15: 基本任务：3.5万以上 | F15: 按50%提成 | K15: 提成计数
K16: 提成点数
K17: 提成金额

Sheet 罗珮文
A1: LOS毛利表
A3: JOB | B3: 集装编号 | C3: 运单编号 | D3: 日期 | E3: 业务 | F3: 发货人 | G3: 收货人 | H3: 计费体积 | I3: 计费重量 | J3: 应 收 | Q3: 总应收 | R3: 起 运 港 成 本 | W3: 代垫运费 | X3: 起运港成本 合计 | Y3: 目的港成本 | AE3: 总支出 | AF3: 利润
J4: 应收RMB | K4: LOS Income(NGN)收到(奈拉) | L4: LOS 收到USD | M4: 美元汇率 dollar currency rate | N4: 应收 到付款USD | O4: 汇率 | P4: 人民币 | R4: 代理商 | S4: 运费+出口报关费 | T4: 提货费 | U4: 装卸费 | V4: 包装费 | Y4: 进口报关费 | Z4: 到门配送费 | AA4: 转运费 | AB4: 目的港支出 | AC4: 汇率 | AD4: 人民币 | AE4: 起运港+目的港
C5: 240925000014 | D5: 45559 | E5: 罗珮文 | F5: Shirley | G5: Yusky | H5: 25.12 | I5: 4000 | J5: 47873.94 | P5: =SUBTOTAL(9,J5) -> 47873.94 | S5: =SUM(42769.7/68)*H5 -> 15799.63 | U5: =SUM(1500/68)*H5 -> 554.11765 | X5: =SUM(S5:W5) -> 16353.748 | Y5: =SUM(10737.46/68)*H5 -> 3966.544 | AA5: =SUM(53.1/68)*H5 -> 19.615765 | AB5: =SUM(Y5:AA5) -> 3986.1598 | AC5: 7.18 | AD5: =SUM(AB5*AC5) -> 28620.627 | AE5: =SUM(X5+AD5) -> 44974.375 | AF5: =SUM(P5-AE5) -> 2899.5646
A6: 合计 | H6: =SUM(H2:H5) -> 25.12 | AF6: =SUM(AF5:AF5) -> 2899.5646
C8: 基本任务：小于6千 | F8: 不够基本任务6千， 公司将根据空运提成里抽出补足基数 | K8: 罗珮文 提成
K9: 名称 | L9: 计费体积 | M9: 毛利
C10: 基本任务：6千-3.5万 | F10: 按40%提成 | K10: LOS | L10: =SUM(H6) -> 25.12 | M10: =SUM(AF6) -> 2899.5646
K11: 基数
C12: 基本任务：3.5万以上 | F12: 按50%提成 | K12: 提成计数
K13: 提成点数
K14: 提成金额

Sheet 陆总
A1: LOS毛利表
A3: JOB | B3: 集装编号 | C3: 运单编号 | D3: 日期 | E3: 业务 | F3: 发货人 | G3: 收货人 | H3: 计费体积 | I3: 计费重量 | J3: 应 收 | Q3: 总应收 | R3: 起 运 港 成 本 | W3: 代垫运费 | X3: 起运港成本 合计 | Y3: 目的港成本 | AE3: 总支出 | AF3: 利润
J4: 应收RMB | K4: LOS Income(NGN)收到(奈拉) | L4: LOS 收到USD | M4: 美元汇率 dollar currency rate | N4: 应收 到付款USD | O4: 汇率 | P4: 人民币 | R4: 代理商 | S4: 运费+出口报关费 | T4: 提货费 | U4: 装卸费 | V4: 包装费 | Y4: 进口报关费 | Z4: 到门配送费 | AA4: 转运费 | AB4: 目的港支出 | AC4: 汇率 | AD4: 人民币 | AE4: 起运港+目的港
C5: 240904000021 | D5: 45539 | E5: 陆总 | F5: 陆梓龙 | G5: luk | H5: 0.469 | I5: 105 | J5: 959.66 | P5: 959.66 | S5: 354.44675 | U5: 10.000735 | X5: 364.44749 | Y5: 74.056893 | AB5: 74.056893 | AC5: 7.12 | AD5: 527.28508 | AE5: 891.73257 | AF5: 67.927435
C6: 240828000069 | D6: 45539 | E6: 陆总 | F6: 陆梓龙 | G6: xiantian | H6: 3.615 | I6: 1442 | J6: 9176.76 | P6: 9176.76 | S6: 2671.3255 | T6: 6.199725 | U6: 93.033088 | X6: 2770.5583 | Y6: 570.82232 | Z6: 100.29 | AA6: 3.7638529 | AB6: 674.87617 | AC6: 7.12 | AD6: 4805.1184 | AE6: 7575.6767 | AF6: 1601.0833
C7: 240902000057 | D7: 45539 | E7: 陆总 | F7: 陆梓龙 | G7: WANG | H7: 0.2102 | I7: 74 | J7: 573.06 | P7: 573.06 | S7: 155.32853 | T7: 0.360493 | U7: 5.4095588 | X7: 161.09858 | Y7: 33.191384 | AA7: 0.21885529 | AB7: 33.410239 | AC7: 7.12 | AD7: 237.8809 | AE7: 398.97948 | AF7: 174.08052
C8: 240905000026 | D8: 45547 | E8: 陆总 | F8: 陆梓龙 | G8: xiantian | H8: 6.2 | I8: 4920 | J8: 14483.2 | P8: 14483.2 | S8: 4079.0529 | U8: 118.52941 | X8: 4197.5824 | Y8: 979.00371 | AB8: 979.00371 | AC8: 7.12 | AD8: 6970.5064 | AE8: 11168.089 | AF8: 3315.1113
C9: 240905000027 | D9: 45547 | E9: 陆总 | F9: 陆梓龙 | G9: luk | H9: 0.3485 | I9: 70 | J9: 686.93 | P9: 686.93 | S9: 229.28225 | U9: 6.6625 | X9: 235.94475 | Y9: 55.029483 | AB9: 55.029483 | AC9: 7.12 | AD9: 391.80992 | AE9: 627.75467 | AF9: 59.175335
C10: 240906000040 | D10: 45547 | E10: 陆总 | F10: 陆梓龙 | G10: jizong | H10: 0.714 | I10: 240 | J10: 1563.66 | P10: 1563.66 | S10: 469.749 | U10: 13.65 | X10: 483.399 | Y10: 112.74333 | AB10: 112.74333 | AC10: 7.12 | AD10: 802.73251 | AE10: 1286.1315 | AF10: 277.52849
C11: 240911000023 | D11: 45547 | E11: 陆总 | F11: 陆梓龙 | G11: luk | H11: 0.0849 | I11: 40 | J11: 210.75 | P11: 210.75 | S11: 55.856709 | U11: 1.6230882 | X11: 57.479797 | Y11: 13.406035 | AB11: 13.406035 | AC11: 7.12 | AD11: 95.450966 | AE11: 152.93076 | AF11: 57.819236
C12: 240911000008 | D12: 45559 | E12: 陆总 | F12: 陆梓龙 | G12: jizong | H12: 6.1104 | I12: 5000 | J12: 15665.8 | P12: 15665.8 | S12: 4099.6291 | U12: 143.77412 | X12: 4243.4032 | Y12: 964.85552 | AA12: 4.7715035 | AB12: 969.62703 | AC12: 7.18 | AD12: 6961.9221 | AE12: 11205.325 | AF12: 4460.4747
C13: 240918000048 | D13: 45554 | E13: 陆总 | F13: 陆梓龙 | G13: luk | H13: 7.1974 | I13: 2213 | J13: 16287.69 | P13: 16287.69 | S13: 4828.9262 | U13: 169.35059 | X13: 4998.2768 | Y13: 1136.497 | AA13: 5.6203226 | AB13: 1142.1173 | AC13: 7.18 | AD13: 8200.4022 | AE13: 13198.679 | AF13: 3089.011
C14: 240919000029 | D14: 45554 | E14: 陆总 | F14: 陆梓龙 | G14: jizong | H14: 3.1 | I14: 472 | J14: 6336.4 | P14: 6336.4 | S14: 2079.8721 | U14: 72.941176 | X14: 2152.8132 | Y14: 489.50185 | AA14: 2.4207353 | AB14: 491.92259 | AC14: 7.18 | AD14: 3532.0042 | AE14: 5684.8174 | AF14: 651.58258
A15: JOB090387 | B15: COLL004180 | C15: 240919000028 | D15: 45559 | E15: 陆总 | F15: 陆梓龙 | G15: jizong | H15: 4.5 | I15: 3775 | J15: 10643.4 | P15: 10643.4 | Q15: 14885.78 | R15: 登凯=39969.7 赛捷=2800 | S15: 2830.3478 | U15: 99.264706 | X15: 2929.6125 | Y15: 710.56721 | AA15: 3.5139706 | AB15: 714.08118 | AC15: 7.18 | AD15: 5127.1028 | AE15: 8056.7153 | AF15: 2586.6847
C16: 240911000008 | D16: 45559 | E16: 陆总 | F16: 陆梓龙 | G16: jizong | H16: 3.0552 | I16: 2500 | J16: 7840.2 | P16: 7840.2 | S16: 1921.6175 | U16: 67.394118 | X16: 1989.0116 | Y16: 482.42776 | AA16: 2.3857518 | AB16: 484.81351 | AC16: 7.18 | AD16: 3480.961 | AE16: 5469.9726 | AF16: 2370.2274
C17: 240913000016 | D17: 45559 | E17: 陆总 | F17: 陆梓龙 | G17: WDG | H17: 2.9348 | I17: 1250 | J17: 5998.7 | P17: 5998.7 | S17: 1845.8899 | U17: 64.738235 | X17: 1910.6282 | Y17: 463.41614 | AA17: 2.2917335 | AB17: 465.70787 | AC17: 7.18 | AD17: 3343.7825 | AE17: 5254.4107 | AF17: 744.28929
C18: 240921000019 | D18: 45547 | E18: 陆总 | F18: 陆梓龙 | G18: xiantian | H18: 9.0628 | I18: 3434.65 | J18: 18527.4 | P18: 18527.4 | S18: 5590.015 | U18: 173.25941 | X18: 5763.2744 | Y18: 1431.0508 | AA18: 7.0769806 | AB18: 1438.1278 | AC18: 7.18 | AD18: 10325.757 | AE18: 16089.032 | AF18: 2438.3683
A19: 合计 | H19: =SUM(H5:H18) -> 47.6022 | AF19: =SUM(AF5:AF18) -> 21893.364
C21: 基本任务：小于6千 | F21: 不够基本任务6千， 公司将根据空运提成里抽出补足基数 | K21: 陆总 提成
K22: 名称 | L22: 计费体积 | M22: 毛利
C23: 基本任务：6千-3.5万 | F23: 按40%提成 | K23: LOS | L23: =SUM(H19) -> 47.6022 | M23: =SUM(AF19) -> 21893.364
K24: 提成计数 | M24: =SUM(M23:M23) -> 21893.364
C25: 基本任务：3.5万以上 | F25: 按50%提成 | K25: 提成点数 | M25: 0.4
K26: 提成金额 | M26: =SUM(M24*M25) -> 8757.3454

Sheet 浦生
A1: LOS毛利表
A3: JOB | B3: 集装编号 | C3: 运单编号 | D3: 日期 | E3: 业务 | F3: 发货人 | G3: 收货人 | H3: 计费体积 | I3: 计费重量 | J3: 应 收 | Q3: 总应收 | R3: 起 运 港 成 本 | W3: 代垫运费 | X3: 起运港成本 合计 | Y3: 目的港成本 | AE3: 总支出 | AF3: 利润
J4: 应收RMB | K4: LOS Income(NGN)收到(奈拉) | L4: LOS 收到USD | M4: 美元汇率 dollar currency rate | N4: 应收 到付款USD | O4: 汇率 | P4: 人民币 | R4: 代理商 | S4: 运费+出口报关费 | T4: 提货费 | U4: 装卸费 | V4: 包装费 | Y4: 进口报关费 | Z4: 到门配送费 | AA4: 转运费 | AB4: 目的港支出 | AC4: 汇率 | AD4: 人民币 | AE4: 起运港+目的港
A5: JOB090350 | B5: COLL004142 | C5: 240807000019 | D5: 45539 | E5: Sam.Pao | F5: Sam.Pao | G5: Nick Wang | H5: 55.0796 | I5: 14200 | J5: 26216.12 | K5: 21550555 | M5: 1560.2607 | N5: 13812.15 | O5: 7.24 | P5: 126216.09 | Q5: 192404.59 | R5: 登凯=48459 赛捷=1120 拖车费=1670 杂费=81 过磅费=61 | S5: 41626.408 | U5: 1174.4915 | V5: 600 | W5: 1035.5 | X5: 44436.399 | Y5: 8697.2794 | Z5: 1858.41 | AB5: 10555.689 | AC5: 7.12 | AD5: 75156.509 | AE5: 119592.91 | AF5: 6623.178
C6: 240827000023 | D6: 45539 | E6: Sam.Pao | F6: Sam.Pao | G6: Adesoye | H6: 3.027 | I6: 2480 | K6: 1916044.9 | M6: 1745 | N6: 1098.02 | O6: 7.12 | P6: 7817.9024 | S6: 2287.6552 | U6: 64.546324 | X6: 2352.2016 | Y6: 477.97487 | AB6: 477.97487 | AC6: 7.12 | AD6: 3403.1811 | AE6: 5755.3827 | AF6: 2062.5197
C7: 240830000003 | D7: 45539 | E7: Sam.Pao | F7: Sam.Pao | G7: ERICA | H7: 0.1448 | I7: 20 | J7: 333.6 | P7: 333.6 | S7: 109.4326 | U7: 3.0876471 | X7: 112.52025 | Y7: 22.864474 | Z7: 5.9 | AB7: 28.764474 | AC7: 7.12 | AD7: 204.80305 | AE7: 317.3233 | AF7: 16.276701
C8: 240728000003 | D8: 45506 | E8: Sam.Pao | F8: Sam.Pao | G8: Nick Wang | H8: 0.42 | I8: 160 | J8: 1132 | P8: 1132 | S8: 317.415 | U8: 8.9558824 | X8: 326.37088 | Y8: 66.319606 | Z8: 31.76 | AB8: 98.079606 | AC8: 7.12 | AD8: 698.32679 | AE8: 1024.6977 | AF8: 107.30232
C9: 240904000001 | D9: 45539 | E9: Sam.Pao | F9: Sam.Pao | G9: SKY JET | H9: 19.05 | I9: 2484 | J9: 25671.21 | P9: 25671.21 | S9: 14397.038 | U9: 406.21324 | X9: 14803.251 | Y9: 3008.0678 | AB9: 3008.0678 | AC9: 7.12 | AD9: 21417.443 | AE9: 36220.694 | AF9: -10549.484
C10: 240904000002 | D10: 45539 | E10: Sam.Pao | F10: Sam.Pao | G10: SKY JET | H10: 12.5 | I10: 19 | J10: 16844.63 | P10: 16844.63 | S10: 9446.875 | U10: 266.54412 | X10: 9713.4191 | Y10: 1973.7978 | AB10: 1973.7978 | AC10: 7.12 | AD10: 14053.44 | AE10: 23766.859 | AF10: -6922.2294
C11: 240903000009 | D11: 45539 | E11: Sam.Pao | F11: Sam.Pao | G11: MaiKaiNian | H11: 0.2574 | I11: 150 | J11: 630.11 | P11: 630.11 | S11: 190.20724 | T11: 0.441441 | U11: 6.6242647 | X11: 197.27295 | Y11: 40.644444 | AA11: 0.26799882 | AB11: 40.912443 | AC11: 7.12 | AD11: 291.29659 | AE11: 488.56954 | AF11: 141.54046
C12: 240813000017 | D12: 45539 | E12: Sam.Pao | F12: Sam.Pao | G12: AiGeLi | H12: 21.51 | I12: 13906 | J12: 59293 | P12: 59293 | S12: 15894.941 | T12: 36.88965 | U12: 553.56618 | V12: 500 | X12: 16985.397 | Y12: 3396.5112 | Z12: 1415.93 | AA12: 22.395706 | AB12: 4834.8369 | AC12: 7.12 | AD12: 34424.039 | AE12: 51409.436 | AF12: 7883.5641
C13: 240828000061 | D13: 45539 | E13: Sam.Pao | F13: Sam.Pao | G13: JunYue hotel | H13: 2.6171 | I13: 719.5 | J13: 5838 | P13: 5838 | S13: 1933.9214 | T13: 4.4883265 | U13: 67.351838 | X13: 2005.7616 | Y13: 413.2501 | AA13: 2.7248629 | AB13: 415.97496 | AC13: 7.12 | AD13: 2961.7417 | AE13: 4967.5033 | AF13: 870.49668
C14: 240904000002 | D14: 45539 | E14: Sam.Pao | F14: Sam.Pao | G14: SKY JET | H14: 30.96 | I14: 3682.5 | J14: 48967.52 | P14: 48967.52 | S14: 22878.074 | T14: 53.0964 | U14: 796.76471 | X14: 23727.935 | Y14: 4888.7024 | AA14: 32.234824 | AB14: 4920.9372 | AC14: 7.12 | AD14: 35037.073 | AE14: 58765.008 | AF14: -9797.4881
A15: JOB090364 | B15: COLL004256 | C15: 240726000055 | D15: 45547 | E15: Sam.Pao | F15: Sam.Pao | G15: ShanShan | H15: 5.09 | I15: 677 | J15: 13067 | P15: 13067 | Q15: 64558.428 | R15: 登凯=41647 赛捷=1280 拖车费=1670 杂费=73 过磅费=68 | S15: 3348.7709 | U15: 97.308824 | X15: 3446.0797 | Y15: 803.73046 | Z15: 47.2 | AB15: 850.93046 | AC15: 7.12 | AD15: 6058.6249 | AE15: 9504.7046 | AF15: 3562.2954
C16: 240813000017 | D16: 45547 | E16: Sam.Pao | F16: Sam.Pao | G16: AiGeLi | H16: 2.1368 | I16: 256 | J16: 5889 | P16: 5889 | S16: 1405.8259 | U16: 40.850588 | X16: 1446.6764 | Y16: 337.40889 | AB16: 337.40889 | AC16: 7.12 | AD16: 2402.3513 | AE16: 3849.0277 | AF16: 2039.9723
C17: 240828000061 | D17: 45539 | E17: Sam.Pao | F17: Sam.Pao | G17: JunYue hotel | H17: 5.2294 | I17: 555 | J17: 11683.3 | P17: 11683.3 | S17: 3440.4838 | U17: 99.973824 | X17: 3540.4576 | Y17: 825.74225 | AB17: 825.74225 | AC17: 7.12 | AD17: 5879.2849 | AE17: 9419.7425 | AF17: 2263.5575
C18: 240908000020 | D18: 45547 | E18: Sam.Pao | F18: Sam.Pao | G18: MaiKaiNian | H18: 0.164 | I18: 156 | J18: 569.4 | P18: 569.4 | S18: 107.89753 | U18: 3.1352941 | X18: 111.03282 | Y18: 25.896227 | AB18: 25.896227 | AC18: 7.12 | AD18: 184.38114 | AE18: 295.41396 | AF18: 273.98604
C19: 240728000003 | D19: 45506 | E19: Sam.Pao | F19: Sam.Pao | G19: Nick Wang | H19: 0.145 | I19: 52 | J19: 396 | P19: 396 | S19: 95.397206 | U19: 2.7720588 | X19: 98.169265 | Y19: 22.896054 | AB19: 22.896054 | AC19: 7.12 | AD19: 163.01991 | AE19: 261.18917 | AF19: 134.81083
C20: 240812000053 | D20: 45518 | E20: Sam.Pao | F20: Sam.Pao | G20: Yusky | H20: 1.2271 | I20: 166 | J20: 2491.03 | P20: 2491.03 | S20: 2324.7699 | T20: 39.12328 | X20: 2363.8932 | AA20: 9.2067889 | AB20: 9.2067889 | AC20: 7.12 | AD20: 65.552337 | AE20: 2429.4456 | AF20: 61.584447
C21: 240813000031 | D21: 45518 | E21: Sam.Pao | F21: Sam.Pao | G21: Yusky | H21: 2.3157 | I21: 122 | M21: 0 | N21: 648.4 | O21: 7.08 | P21: 4590.672 | S21: 4387.1484 | T21: 73.830804 | X21: 4460.9792 | AA21: 17.374428 | AB21: 17.374428 | AC21: 7.12 | AD21: 123.70593 | AE21: 4584.6851 | AF21: 5.986916
C22: 240814000030 | D22: 45518 | E22: Sam.Pao | F22: Sam.Pao | G22: LuZhiLong | H22: 1.5403 | I22: 189.9 | J22: 2643.36 | P22: 2643.36 | S22: 2918.1347 | T22: 49.108946 | X22: 2967.2437 | AA22: 11.556692 | AB22: 11.556692 | AC22: 7.12 | AD22: 82.283648 | AE22: 3049.5273 | AF22: -406.16733
A23: JOB090367 | B23: COLL004161 | C23: 240830000002 | D23: 45583 | E23: Sam.Pao | F23: Sam.Pao | G23: Mr. Jason | H23: 只清关 | K23: 18000000 | M23: 1744.9909 | N23: 10315.24 | O23: 7.12 | P23: 73444.509 | Q23: 73444.509 | X23: 0 | Y23: 10324.48 | AB23: 10324.48 | AC23: 7.12 | AD23: 73510.298 | AE23: 73510.298 | AF23: -65.7888
A24: JOB090368 | B24: COLL004162 | C24: 240830000001 | D24: 45583 | E24: Sam.Pao | F24: Sam.Pao | G24: Mr. Jason | H24: 只清关 | K24: 15200000 | M24: 1710.999 | N24: 8883.699 | O24: 7.12 | P24: 63251.937 | Q24: 63251.937 | X24: 0 | Y24: 7374.63 | AB24: 7374.63 | AC24: 7.12 | AD24: 52507.366 | AE24: 52507.366 | AF24: 10744.571
C25: 240828000061 | D25: 45554 | E25: Sam.Pao | F25: Sam.Pao | G25: JunYue hotel | H25: 8.526 | I25: 1229 | J25: 19021 | P25: 19021 | S25: 5720.3191 | U25: 200.61176 | X25: 5920.9309 | Y25: 1346.288 | AA25: 6.6578029 | AB25: 1352.9458 | AC25: 7.18 | AD25: 9714.1509 | AE25: 15635.082 | AF25: 3385.9183
C26: 240918000051 | D26: 45554 | E26: Sam.Pao | F26: Sam.Pao | G26: SKY JET | H26: 13.66 | I26: 2003 | J26: 21916.92 | P26: 21916.92 | S26: 9164.8556 | U26: 321.41176 | X26: 9486.2674 | Y26: 2156.9662 | AA26: 10.666853 | AB26: 2167.6331 | AC26: 7.18 | AD26: 15563.606 | AE26: 25049.873 | AF26: -3132.9529
C27: 240728000003 | D27: 45506 | E27: Sam.Pao | F27: Sam.Pao | G27: Nick Wang | H27: 0.183 | I27: 74 | J27: 493 | P27: 493 | S27: 122.77954 | U27: 4.3058824 | X27: 127.08543 | Y27: 28.8964 | AA27: 0.14290147 | AB27: 29.039301 | AC27: 7.18 | AD27: 208.50218 | AE27: 335.58761 | AF27: 157.41239
C28: 240906000023 | D28: 45559 | E28: Sam.Pao | F28: Sam.Pao | G28: ChenGaoHong | H28: 10.189 | I28: 4334 | J28: 20928 | P28: 20928 | S28: 6408.5364 | U28: 224.75735 | X28: 6633.2937 | Y28: 1608.8821 | AA28: 7.9564103 | AB28: 1616.8385 | AC28: 7.18 | AD28: 11608.9 | AE28: 18242.194 | AF28: 2685.8061
C29: 240924000002 | D29: 45559 | E29: Sam.Pao | F29: Sam.Pao | G29: Yusky | H29: 2.1628 | I29: 650 | J29: 4123.95 | P29: 4123.95 | S29: 1360.328 | U29: 47.708824 | X29: 1408.0369 | Y29: 341.51439 | AA29: 1.6888924 | AB29: 343.20328 | AC29: 7.18 | AD29: 2464.1996 | AE29: 3872.2364 | AF29: 251.71357
C30: 240924000003 | D30: 45559 | E30: Sam.Pao | F30: Sam.Pao | G30: Yusky | H30: 7.5034 | I30: 1232 | J30: 14307.08 | P30: 14307.08 | S30: 4719.3848 | U30: 165.51618 | X30: 4884.901 | Y30: 1184.8155 | AA30: 5.8592726 | AB30: 1190.6748 | AC30: 7.18 | AD30: 8549.0452 | AE30: 13433.946 | AF30: 873.13379
C31: 240924000004 | D31: 45559 | E31: Sam.Pao | F31: Sam.Pao | G31: Yusky | H31: 0.1491 | I31: 143 | J31: 284.49 | P31: 284.49 | S31: 93.778857 | U31: 3.2889706 | X31: 97.067828 | Y31: 23.54346 | AA31: 0.11642956 | AB31: 23.65989 | AC31: 7.18 | AD31: 169.87801 | AE31: 266.94584 | AF31: 17.544165
C32: 240924000005 | D32: 45559 | E32: Sam.Pao | F32: Sam.Pao | G32: Yusky | H32: 0.817 | I32: 358 | J32: 1558.03 | P32: 1558.03 | S32: 513.86537 | U32: 18.022059 | X32: 531.88743 | Y32: 129.00742 | AA32: 0.63798088 | AB32: 129.6454 | AC32: 7.18 | AD32: 930.85401 | AE32: 1462.7414 | AF32: 95.288569
C33: 240924000006 | D33: 45559 | E33: Sam.Pao | F33: Sam.Pao | G33: Yusky | H33: 4.261 | I33: 638 | J33: 8122.76 | P33: 8122.76 | S33: 2680.0249 | U33: 93.992647 | X33: 2774.0175 | Y33: 672.82819 | AA33: 3.3273397 | AB33: 676.15553 | AC33: 7.18 | AD33: 4854.7967 | AE33: 7628.8142 | AF33: 493.94576
C34: 240924000007 | D34: 45559 | E34: Sam.Pao | F34: Sam.Pao | G34: Yusky | H34: 3.099 | I34: 438 | J34: 5908.61 | P34: 5908.61 | S34: 1949.1662 | U34: 68.360294 | X34: 2017.5265 | Y34: 489.34395 | AA34: 2.4199544 | AB34: 491.7639 | AC34: 7.18 | AD34: 3530.8648 | AE34: 5548.3913 | AF34: 360.2187
C35: 240912000064 | D35: 45560 | E35: Sam.Pao | F35: Sam.Pao | G35: Mr Liu | H35: 5.0147 | I35: 766 | J35: 10109.64 | P35: 10109.64 | S35: 3093.1112 | U35: 95.869265 | X35: 3188.9805 | Y35: 791.8403 | AA35: 3.9158907 | AB35: 795.75619 | AC35: 7.18 | AD35: 5713.5295 | AE35: 8902.5099 | AF35: 1207.1301
C36: 240924000002 | D36: 45560 | E36: Sam.Pao | F36: Sam.Pao | G36: Yusky | H36: 1.6316 | I36: 279.5 | J36: 2779.87 | P36: 2779.87 | S36: 1006.3853 | U36: 31.192353 | X36: 1037.5776 | Y36: 257.63588 | AA36: 1.2740876 | AB36: 258.90997 | AC36: 7.18 | AD36: 1858.9736 | AE36: 2896.5512 | AF36: -116.68119
... C38: 240924000008 | D38: 45560 | E38: Sam.Pao | F38: Sam.Pao | G38: Yusky | H38: 6.42 | I38: 1637 | J38: 11242.58 | P38: 11242.58 | S38: 3959.9126 | U38: 122.73529 | X38: 4082.6479 | Y38: 1013.7425 | AA38: 5.0132647 | AB38: 1018.7558 | AC38: 7.18 | AD38: 7314.6667 | AE38: 11397.315 | AF38: -154.73467
C39: 240924000028 | D39: 45560 | E39: Sam.Pao | F39: Sam.Pao | G39: FEMEB NIGERIA LIMITED | H39: 15.66 | I39: 10000 | K39: 8627642.1 | M39: 1749 | N39: 4932.9 | O39: 7.08 | P39: 34924.932 | S39: 9659.2262 | U39: 299.38235 | X39: 9958.6085 | Y39: 2472.7739 | AA39: 12.228618 | AB39: 2485.0025 | AC39: 7.18 | AD39: 17842.318 | AE39: 27800.926 | AF39: 7124.0056
A40: JOB110331 | B40: COLL004224 | C40: 241018000035 | D40: 45551 | E40: Sam.Pao | F40: Sam.Pao | G40: ShanShan | H40: 68 | J40: 51892 | K40: 21300000 | L40: 到付 | M40: 1745.0005 | N40: 12206.3 | O40: 7.12 | P40: 138800.86 | Q40: 138800.86 | R40: 登凯=41647 陆总=2000 拖车费=1670 杂费=101 过磅费=58 | S40: 45476 | X40: 45476 | Y40: 10888.25 | AB40: 10888.25 | AC40: 7.12 | AD40: 77524.34 | AE40: 123000.34 | AF40: 15800.516
A41: 合计 | H41: =SUM(H5:H40) -> 340.0108 | AF41: =SUM(AF5:AF40) -> 36001.412
C43: 基本任务：小于6千 | F43: 不够基本任务6千， 公司将根据空运提成里抽出补足基数 | K43: 浦生 提成
...

Sheet 无人
A1: LOS毛利表
A3: JOB | B3: 集装编号 | C3: 运单编号 | D3: 日期 | E3: 业务 | F3: 发货人 | G3: 收货人 | H3: 计费体积 | I3: 计费重量 | J3: 应 收 | Q3: 总应收 | R3: 起 运 港 成 本 | W3: 代垫运费 | X3: 起运港成本 合计 | Y3: 目的港成本 | AE3: 总支出 | AF3: 利润
J4: 应收RMB | K4: LOS Income(NGN)收到(奈拉) | L4: LOS 收到USD | M4: 美元汇率 dollar currency rate | N4: 应收 到付款USD | O4: 汇率 | P4: 人民币 | R4: 代理商 | S4: 运费+出口报关费 | T4: 提货费 | U4: 装卸费 | V4: 包装费 | Y4: 进口报关费 | Z4: 到门配送费 | AA4: 转运费 | AB4: 目的港支出 | AC4: 汇率 | AD4: 人民币 | AE4: 起运港+目的港
C5: 240830000048 | D5: 45539 | E5: 无人 | F5: dejare James | G5: James | H5: 2.146 | I5: 268 | L5: 640.17 | M5: 0 | N5: 640.17 | O5: 7.3 | P5: 4673.241 | S5: 1621.8395 | U5: 45.760294 | X5: 1667.5998 | Y5: 338.86161 | AB5: 338.86161 | AC5: 7.12 | AD5: 2412.6946 | AE5: 4080.2944 | AF5: 592.94658
C6: 240906000030 | D6: 45547 | E6: 无人 | F6: dejare James | G6: James | H6: 1.934 | I6: 395 | L6: 580.5 | M6: 0 | N6: 580.5 | O6: 7.08 | P6: 4109.94 | S6: 1272.4014 | U6: 36.973529 | X6: 1309.3749 | Y6: 305.38599 | AB6: 305.38599 | AC6: 7.12 | AD6: 2174.3483 | AE6: 3483.7232 | AF6: 626.21684
C7: 240909000050 | D7: 45554 | E7: 无人 | F7: dejare James | G7: James | H7: 0.0321 | I7: 3.5 | L7: 8.99 | M7: 0 | N7: 8.990002 | O7: 7.08 | P7: 63.649214 | S7: 21.53674 | U7: 0.75529412 | X7: 22.292034 | Y7: 5.0687127 | AA7: 0.025066324 | AB7: 5.0937791 | AC7: 7.18 | AD7: 36.573334 | AE7: 58.865367 | AF7: 4.7838467
C8: 240917000018 | D8: 45554 | E8: 无人 | F8: Mailmail Abv sales person 1 | G8: Ugochukwu | H8: 0.1378 | I8: 49 | K8: 77059.2 | M8: 1744.9998 | N8: 44.160004 | O8: 7.08 | P8: 312.65283 | S8: 92.453668 | U8: 3.2423529 | X8: 95.696021 | Y8: 21.759147 | AA8: 0.10760559 | AB8: 21.866752 | AC8: 7.18 | AD8: 157.00328 | AE8: 252.6993 | AF8: 59.953525
A9: 合计 | H9: =SUM(H5:H8) -> 4.2499 | AF9: =SUM(AF5:AF8) -> 1283.9008
C11: 基本任务：小于6千 | F11: 不够基本任务6千， 公司将根据空运提成里抽出补足基数 | K11: 无人 提成
K12: 名称 | L12: 计费体积 | M12: 毛利
C13: 基本任务：6千-3.5万 | F13: 按40%提成 | K13: LOS | L13: =SUM(H9) -> 4.2499 | M13: =SUM(AF9) -> 1283.9008
K14: 基数
C15: 基本任务：3.5万以上 | F15: 按50%提成 | K15: 提成计数
K16: 提成点数
K17: 提成金额

Sheet 提成总表
A1: 24年9月份业务员提成总表-68³
A3: 名称 姓名 | B3: LOS毛利 | C3: 计费体积 立方 | D3: 6千-3.5万 | I3: 3.5万以上 | M3: 合计 提成金额 | N3: 备注 | P3: 基本任务：小于6千 | R3: 不够基本任务6千， 公司将根据空运提成里抽出补足基数
D4: 基数 | E4: 提成计数 | F4: 提成计数 | G4: 提成点 数40% | H4: 提成金额 | I4: 基数 | J4: 提成计数 | K4: 提成点 数50% | L4: 提成金额
A5: 黄 颖 | B5: =SUM(黄颖!M31) -> 26827.841 | C5: =SUM(黄颖!L31) -> 68.7536 | D5: 6000 | E5: =SUM(B5-D5) -> 20827.841 | G5: 0.4 | H5: =SUM(E5*G5) -> 8331.1365 | M5: =SUM(H5+L5) -> 8331.1365 | P5: 基本任务：6千-3.5万 | R5: 按40%提成
A6: 陈三凤 | B6: =SUM(三凤!M13) -> 34354.9 | C6: =SUM(三凤!L13) -> 186.2071 | D6: 2000 | E6: =SUM(B6-D6) -> 32354.9 | G6: 0.15 | H6: =SUM(E6*G6) -> 4853.235 | M6: =SUM(H6+L6) -> 4853.235 | N6: 小飞8-9月份原方案10% （zhong zi xin利润的一半2216.79）
A7: 朱小飞 | B7: =SUM(朱小飞!M16) -> 2414.8628 | C7: =SUM(朱小飞!L16) -> 3.9452 | D7: 2000 | E7: =SUM(B7-D7) -> 414.86283 | G7: 0.15 | H7: =SUM(E7*G7) -> 62.229425 | M7: =SUM(H7+L7) -> 62.229425 | N7: 小飞8-9月份原方案10% （Halifa利润的一半161.39） | P7: 基本任务：3.5万以上 | R7: 按50%提成
A8: 吕沛霖 | B8: =SUM(吕沛霖!M19) -> 8461.3905 | C8: =SUM(吕沛霖!L19) -> 33.9456 | D8: 6000 | E8: =SUM(B8-D8) -> 2461.3905 | G8: 0.4 | H8: =SUM(E8*G8) -> 984.55621 | M8: =SUM(H8+L8) -> 984.55621
A9: 陆总 | B9: =SUM(陆总!M23) -> 21893.364 | C9: =SUM(陆总!L23) -> 47.6022 | G9: 0.4 | H9: =SUM(B9*G9) -> 8757.3454 | M9: =SUM(H9+L9) -> 8757.3454
A10: 浦海森 | B10: =SUM(浦生!M45) -> 36001.412 | C10: =SUM(浦生!L45) -> 340.0108 | D10: 6000 | E10: =SUM(B10-D10) -> 30001.412 | F10: 35000 | G10: 0.4 | H10: =SUM(F10*G10) -> 14000 | M10: =SUM(H10+L10) -> 14000 | P10: 领款人：
A11: 罗伟健 | B11: =SUM(罗伟健!M13) -> 4545.8468 | C11: =SUM(罗伟健!L13) -> 7.8325 | N11: 空运毛利￥4399.01加海运=8944.86-15000，不达标 | P11: 日期：
A12: 罗珮文 | B12: =SUM(罗珮文!M10) -> 2899.5646 | C12: =SUM(罗珮文!L10) -> 25.12
A13: 无人 | B13: =SUM(无人!M13) -> 1283.9008 | C13: =SUM(无人!L13) -> 4.2499
A14: 合计 | B14: =SUM(B5:B13) -> 138683.08 | C14: =SUM(C5:C13) -> 717.6669 | M14: =SUM(M5:M11) -> 36988.503
A16: 确认人： | J16: 日期：

Sheet 黄颖 陈三凤 朱小飞 吕沛霖 2025年10月份发放
A1: 24年9月份业务员提成总表-68³
A3: 名称 姓名 | B3: LOS毛利 | C3: 计费体积 立方 | D3: 6千-3.5万 | I3: 3.5万以上 | M3: 合计 提成金额 | N3: 备注
D4: 基数 | E4: 提成计数 | F4: 提成计数 | G4: 提成点 数40% | H4: 提成金额 | I4: 基数 | J4: 提成计数 | K4: 提成点 数50% | L4: 提成金额
A5: 黄 颖 | B5: =SUM(黄颖!M31) -> 26827.841 | C5: =SUM(黄颖!L31) -> 68.7536 | D5: 6000 | E5: =SUM(B5-D5) -> 20827.841 | G5: 0.4 | H5: =SUM(E5*G5) -> 8331.1365 | M5: =SUM(H5+L5) -> 8331.1365
L6: 领款人：
A7: 陈三凤 | B7: =SUM(三凤!M13) -> 34354.9 | C7: =SUM(三凤!L13) -> 186.2071 | D7: 2000 | E7: =SUM(B7-D7) -> 32354.9 | G7: 0.15 | H7: =SUM(E7*G7) -> 4853.235 | M7: =SUM(H7+L7) -> 4853.235 | N7: 小飞8-9月份原方案10% （zhong zi xin利润的一半2216.79）
L8: 领款人：
A9: 朱小飞 | B9: =SUM(朱小飞!M16) -> 2414.8628 | C9: =SUM(朱小飞!L16) -> 3.9452 | D9: 2000 | E9: =SUM(B9-D9) -> 414.86283 | G9: 0.15 | H9: =SUM(E9*G9) -> 62.229425 | M9: =SUM(H9+L9) -> 62.229425 | N9: 小飞8-9月份原方案10% （Halifa利润的一半161.39）
L10: 领款人：
A11: 吕沛霖 | B11: =SUM(吕沛霖!M19) -> 8461.3905 | C11: =SUM(吕沛霖!L19) -> 33.9456 | D11: 6000 | E11: =SUM(B11-D11) -> 2461.3905 | G11: 0.4 | H11: =SUM(E11*G11) -> 984.55621 | M11: =SUM(H11+L11) -> 984.55621
L12: 领款人：
A13: 合计 | B13: =SUM(B5:B11) -> 72058.995 | C13: =SUM(C5:C11) -> 292.8515 | M13: =SUM(M5:M11) -> 14231.157
A15: 确认人： | J15: 日期：
