Workbook

Sheet 黄颖
A1: LOS毛利表
A3: JOB | B3: 集装编号 | C3: 运单编号 | D3: 日期 | E3: 业务 | F3: 发货人 | G3: 收货人 | H3: 计费体积 | I3: 计费重量 | J3: 应 收 | Q3: 总应收 | R3: 起 运 港 成 本 | W3: 代垫运费 | X3: 起运港成本 合计 | Y3: 目的港成本 | AE3: 总支出 | AF3: 利润
J4: 应收RMB | K4: LOS Income(NGN)收到(奈拉) | L4: LOS 收到USD | M4: 美元汇率 dollar currency rate | N4: 应收 到付款USD | O4: 汇率 | P4: 人民币 | R4: 代理商 | S4: 运费+出口报关费 | T4: 提货费 | U4: 装卸费 | V4: 包装费 | Y4: 进口报关费 | Z4: 到门配送费 | AA4: 转运费 | AB4: 目的港支出 | AC4: 汇率 | AD4: 人民币 | AE4: 起运港+目的港
C5: 240709000025 | D5: 45491 | E5: 黄颖 | F5: ying | G5: Huangpu | H5: 0.1112 | I5: 57 | J5: 556 | P5: 556 | S5: 216.42477 | T5: 0.45845446 | X5: 216.88322 | Z5: 37.06 | AB5: 37.06 | AC5: 7.15 | AD5: 264.979 | AE5: 481.86222 | AF5: 74.13778
C6: 240718000039 | D6: 45511 | E6: 黄颖 | F6: ying | G6: Idris | H6: 0.5054 | I6: 412 | J6: 2582 | P6: 2582 | S6: 435.75342 | U6: 10.546006 | X6: 446.29943 | Y6: 77.106292 | AB6: 77.106292 | AC6: 7.08 | AD6: 545.91255 | AE6: 992.21198 | AF6: 1589.788
C7: 240718000039 | D7: 45511 | E7: 黄颖 | F7: ying | G7: Idris | H7: 2.7869 | I7: 2167 | J7: 14238 | P7: 14238 | S7: 2412.5947 | U7: 81.967647 | X7: 2494.5624 | Y7: 414.67392 | AA7: 3.7479707 | AB7: 418.42189 | AC7: 7.15 | AD7: 2991.7165 | AE7: 5486.2789 | AF7: 8751.7211
C8: 240729000020 | D8: 45506 | E8: 黄颖 | F8: ying | G8: zhounengquan | H8: 0.0032 | I8: 2.7 | J8: 235.2 | P8: 235.2 | S8: 2.7702118 | U8: 0.094117647 | X8: 2.8643294 | Y8: 0.47614071 | AA8: 0.0043035294 | AB8: 0.48044424 | AC8: 7.15 | AD8: 3.4351763 | AE8: 6.2995057 | AF8: 228.90049
A9: JOB080362 | B9: COLL004097 | C9: 240804000005 | D9: 45511 | E9: 黄颖 | F9: ying | G9: Sunday Adelena | H9: 34.5199 | I9: 9224 | J9: 77059.62 | P9: 77059.62 | Q9: 80368.62 | R9: 赛捷=56732.25 赛捷=800 | S9: 29205.993 | U9: 736.0861 | X9: 29942.079 | Y9: 5345.0004 | AA9: 104.81866 | AB9: 5449.8191 | AC9: 7.09 | AD9: 38639.217 | AE9: 68581.296 | AF9: 8478.3239
A10: JOB080363 | B10: COLL004098 | C10: 240718000039 | D10: 45511 | E10: 黄颖 | F10: ying | G10: Idris | H10: 9.29 | I10: 13260 | J10: 47474 | P10: 47474 | Q10: 80918.526 | R10: 赛捷=56837.25 赛捷=2300 | S10: 8079.1919 | U10: 198.09559 | V10: 960 | X10: 9237.2875 | Y10: 1438.4472 | Z10: 1823.01 | AA10: 35.463209 | AB10: 3296.9204 | AC10: 7.09 | AD10: 23375.166 | AE10: 32612.453 | AF10: 14861.547
C11: 240730000015 | D11: 45511 | E11: 黄颖 | F11: ying | G11: Huangpu | H11: 0.159 | I11: 26.5 | J11: 376.32 | P11: 376.32 | S11: 138.27681 | U11: 3.3904412 | X11: 141.66725 | Y11: 24.619279 | AA11: 0.60695912 | AB11: 25.226239 | AC11: 7.09 | AD11: 178.85403 | AE11: 320.52128 | AF11: 55.798723
C12: 240802000002 | D12: 45512 | E12: 黄颖 | F12: ying | G12: huangzhaoyong | H12: 1.848 | I12: 1035 | J12: 4482.5 | P12: 4482.5 | S12: 1590.7 | T12: 1.4944341 | U12: 27.176471 | X12: 1619.3709 | Y12: 283.58647 | AB12: 283.58647 | AC12: 7.12 | AD12: 2019.1357 | AE12: 3638.5065 | AF12: 843.99345
C13: 240803000017 | D13: 45512 | E13: 黄颖 | F13: ying | G13: Sunday Adelena | H13: 17.17 | I13: 12298 | J13: 38477.75 | P13: 38477.75 | S13: 14779.393 | T13: 13.884975 | U13: 252.5 | X13: 15045.778 | Y13: 2634.8375 | AB13: 2634.8375 | AC13: 7.12 | AD13: 18760.043 | AE13: 33805.821 | AF13: 4671.9289
C14: 240725000027 | D14: 45534 | E14: 黄颖 | F14: ying | G14: Huangpu | H14: 0.0213 | I14: 3.7 | K14: 85293 | M14: 1730.4321 | N14: 49.29 | O14: 7.12 | P14: 350.9448 | S14: 18.025203 | U14: 0.65779412 | X14: 18.682997 | Y14: 3.2629721 | Z14: 7.25 | AB14: 10.512972 | AC14: 7.07 | AD14: 74.326712 | AE14: 93.00971 | AF14: 257.93509
C15: 240807000010 | D15: 45534 | E15: 黄颖 | F15: ying | G15: Huangpu | H15: 0.0207 | I15: 4.2 | K15: 59049 | M15: 1786.1162 | N15: 33.06 | O15: 7.12 | P15: 235.3872 | S15: 17.517451 | U15: 0.63926471 | X15: 18.156716 | Y15: 3.1710574 | Z15: 7.5 | AB15: 10.671057 | AC15: 7.07 | AD15: 75.444375 | AE15: 93.601091 | AF15: 141.78611
C16: 240808000024 | D16: 45534 | E16: 黄颖 | F16: ying | G16: Emma | H16: 2.295 | I16: 107 | L16: 827 | M16: 0 | N16: 827 | O16: 7.12 | P16: 5888.24 | S16: 1942.1522 | U16: 70.875 | X16: 2013.0272 | Y16: 351.57375 | Z16: 70.8 | AB16: 422.37375 | AC16: 7.07 | AD16: 2986.1824 | AE16: 4999.2096 | AF16: 889.0304
A17: JOB080374 | B17: COLL004108 | C17: 240729000025 | D17: 45534 | E17: 黄颖 | F17: ying | G17: leoyang | H17: 0.3136 | I17: 10 | J17: 753 | P17: 753 | Q17: 72543.05 | R17: 赛捷=56265.25 赛捷=1000 | S17: 264.09386 | U17: 6.4564706 | X17: 270.55033 | Y17: 47.630306 | AA17: 1.2780122 | AB17: 48.908318 | AC17: 7.06 | AD17: 345.29273 | AE17: 615.84306 | AF17: 137.15694
C18: 240804000005 | D18: 45534 | E18: 黄颖 | F18: ying | G18: Sunday Adelena | H18: 31.7366 | I18: 8596 | J18: 70573.12 | P18: 70573.12 | S18: 26726.534 | U18: 653.40059 | X18: 27379.935 | Y18: 4820.2295 | AA18: 129.33598 | AB18: 4949.5655 | AC18: 7.06 | AD18: 34943.932 | AE18: 62323.867 | AF18: 8249.2529
C19: 240811000002 | D19: 45534 | E19: 黄颖 | F19: ying | G19: yanjiafu | H19: 0.293 | I19: 65.5 | K19: 295731 | M19: 1737.5499 | N19: 170.2 | O19: 7.15 | P19: 1216.93 | S19: 246.74586 | T19: 355.58 | U19: 6.0323529 | W19: 54.56 | X19: 662.91821 | Y19: 44.501529 | Z19: 27.05 | AA19: 1.1940612 | AB19: 72.745591 | AC19: 7.06 | AD19: 513.58387 | AE19: 1176.5021 | AF19: 40.427921
C20: 240810000003 | D20: 45516 | E20: 黄颖 | F20: ying | G20: Sunday Adelena | H20: 0.693 | I20: 463 | J20: 1600 | P20: 1600 | S20: 542.77187 | U20: 13.248529 | X20: 556.0204 | Y20: 109.42735 | AB20: 109.42735 | AC20: 7.06 | AD20: 772.55709 | AE20: 1328.5775 | AF20: 271.42251
C21: 240812000069 | D21: 45516 | E21: 黄颖 | F21: ying | G21: zhounengquan | H21: 0.045 | I21: 52.5 | J21: 565.2 | P21: 565.2 | S21: 35.244926 | U21: 0.86029412 | X21: 36.105221 | Y21: 7.1056721 | Z21: 50.15 | AB21: 57.255672 | AC21: 7.06 | AD21: 404.22504 | AE21: 440.33027 | AF21: 124.86973
C22: 240814000018 | D22: 45516 | E22: 黄颖 | F22: ying | G22: baikaibo | H22: 0.414 | I22: 225 | J22: 1588 | P22: 1588 | S22: 324.25332 | U22: 7.9147059 | X22: 332.16803 | Y22: 65.372183 | Z22: 81.63 | AB22: 147.00218 | AC22: 7.06 | AD22: 1037.8354 | AE22: 1370.0034 | AF22: 217.99656
C23: 240814000019 | D23: 45516 | E23: 黄颖 | F23: ying | G23: Nura | H23: 1.0206 | I23: 428 | J23: 2389.6 | P23: 2389.6 | S23: 799.35493 | U23: 19.511471 | X23: 818.8664 | Y23: 161.15664 | AB23: 161.15664 | AC23: 7.06 | AD23: 1137.7659 | AE23: 1956.6323 | AF23: 432.9677
C24: 240814000024 | D24: 45516 | E24: 黄颖 | F24: ying | G24: baikaibo | H24: 0.0407 | I24: 2 | J24: 835.2 | P24: 835.2 | S24: 31.877078 | U24: 0.77808824 | X24: 32.655166 | Y24: 6.4266856 | Z24: 81.63 | AB24: 88.056686 | AC24: 7.06 | AD24: 621.6802 | AE24: 654.33537 | AF24: 180.86463
C25: 240815000013 | D25: 45516 | E25: 黄颖 | F25: ying | G25: liangyu | H25: 0.2945 | I25: 235 | J25: 1105 | P25: 1105 | S25: 230.65846 | U25: 5.6301471 | W25: 316 | X25: 552.28861 | Y25: 46.502676 | AB25: 46.502676 | AC25: 7.06 | AD25: 328.30889 | AE25: 880.5975 | AF25: 224.4025
C26: 240816000023 | D26: 45516 | E26: 黄颖 | F26: ying | G26: libiao | H26: 1.9876 | I26: 92 | J26: 4277.5 | P26: 4277.5 | S26: 1556.7292 | U26: 37.998235 | W26: 99 | X26: 1693.7275 | Y26: 313.84964 | Z26: 47.2 | AB26: 361.04964 | AC26: 7.06 | AD26: 2549.0105 | AE26: 4242.7379 | AF26: 34.762068
C27: 240818000042 | D27: 45532 | E27: 黄颖 | F27: ying | G27: zhounengquan | H27: 0.0276 | I27: 60 | K27: 120050 | M27: 1800.66 | N27: 66.67 | O27: 7.12 | P27: 474.6904 | S27: 21.453521 | U27: 0.60882353 | X27: 22.062344 | Y27: 4.3581455 | Z27: 35.4 | AA27: 0.10057359 | AB27: 39.858719 | AC27: 7.12 | AD27: 283.79408 | AE27: 305.85642 | AF27: 168.83398
C28: 240826000045 | D28: 45532 | E28: 黄颖 | F28: ying | G28: Nura | H28: 0.4085 | I28: 179 | J28: 904 | P28: 904 | S28: 317.52765 | U28: 9.0110294 | X28: 326.53868 | Y28: 64.503712 | AA28: 1.488562 | AB28: 65.992274 | AC28: 7.12 | AD28: 469.86499 | AE28: 796.40367 | AF28: 107.59633
A29: 合 计 | AF29: =SUM(AF5:AF28) -> 51035.445
C31: 基本任务：小于6千 | F31: 不够基本任务6千， 公司将根据空运提成里抽出补足基数 | K31: 黄颖 提成
K32: 名称 | L32: 计费体积 | M32: 毛利
C33: 基本任务：6千-3.5万 | F33: 按40%提成 | K33: LOS | L33: =SUM(H5:H28) -> 106.0053 | M33: =SUM(AF29) -> 51035.445
K34: 任务 | M34: 6000
C35: 基本任务：3.5万以上 | F35: 按50%提成 | K35: 提成计数 | M35: =SUM(M33-M34) -> 45035.445
K36: 基数 | M36: 35000
K37: 提成计数40% | M37: 0.4
K38: 提成金额 | M38: =SUM(M36*M37) -> 14000
K39: 实提成计数 | M39: =SUM(M35-M36) -> 10035.445
K40: 提成点数50% | M40: 0.5
K41: 提成金额 | M41: =SUM(M39*M40) -> 5017.7223
K42: 合计提成金额 | M42: =SUM(M38+M41) -> 19017.722

Sheet 三凤
A1: LOS毛利表
A2: JOB | B2: 集装编号 | C2: 运单编号 | D2: 日期 | E2: 业务 | F2: 发货人 | G2: 收货人 | H2: 计费体积 | I2: 计费重量 | J2: 应 收 | Q2: 总应收 | R2: 起 运 港 成 本 | W2: 代垫运费 | X2: 起运港成本 合计 | Y2: 目的港成本 | AE2: 总支出 | AF2: 利润
J3: 应收RMB | K3: LOS Income(NGN)收到(奈拉) | L3: LOS 收到USD | M3: 美元汇率 dollar currency rate | N3: 应收 到付款USD | O3: 汇率 | P3: 人民币 | R3: 代理商 | S3: 运费+出口报关费 | T3: 提货费 | U3: 装卸费 | V3: 包装费 | Y3: 进口报关费 | Z3: 到门配送费 | AA3: 转运费 | AB3: 目的港支出 | AC3: 汇率 | AD3: 人民币 | AE3: 起运港+目的港
C4: 240726000008 | D4: 45506 | E4: Bella | F4: Bella Chan | G4: zhong zi xin | H4: 0.835 | I4: 1254 | K4: 1830068.5 | M4: 1711 | N4: 1069.59 | O4: 7.12 | P4: 7615.4808 | S4: 722.85213 | U4: 24.558824 | X4: 747.41096 | Y4: 124.24297 | Z4: 284.87 | AA4: 1.1229522 | AB4: 410.23592 | AC4: 7.15 | AD4: 2933.1868 | AE4: 3680.5978 | AF4: 3934.883
C5: 240724000026 | D5: 45506 | E5: Bella | F5: Bella Chan | G5: zhong zi xin | H5: 3.0722 | I5: 4949 | K5: 1723658 | M5: 1711.0136 | N5: 1007.39 | O5: 7.12 | P5: 7172.6168 | S5: 2659.5764 | U5: 90.358824 | X5: 2749.9353 | Y5: 457.12484 | AA5: 4.1316572 | AB5: 461.25649 | AC5: 7.15 | AD5: 3297.9839 | AE5: 6047.9192 | AF5: 1124.6976 | AG5: =SUM(AF4:AF5) -> 5059.5806 | AH5: =SUM(AG5/2) -> 2529.7903
C6: 240729000017 | D6: 45506 | E6: Bella | F6: Bella Chan | G6: zhang jian fei | H6: 1.1178 | I6: 1055 | K6: 776250 | M6: 1725 | N6: 450 | O6: 7.12 | P6: 3204 | S6: 967.6696 | U6: 32.876471 | X6: 1000.5461 | Y6: 166.3219 | AA6: 1.5032766 | AB6: 167.82518 | AC6: 7.15 | AD6: 1199.95 | AE6: 2200.4961 | AF6: 1003.5039
C7: 240801000022 | D7: 45506 | E7: Bella | F7: Bella Chan | G7: new hope 边鹏飞 | H7: 1.8732 | I7: 1420 | K7: 1129654.4 | M7: 1739 | N7: 649.6 | O7: 7.06 | P7: 4586.176 | S7: 1621.6127 | U7: 55.094118 | X7: 1676.7068 | Y7: 278.72087 | AA7: 2.5191785 | AB7: 281.24004 | AC7: 7.15 | AD7: 2010.8663 | AE7: 3687.5731 | AF7: 898.60285
C8: 240724000012 | D8: 45511 | E8: Bella | F8: Bella Chan | G8: zhang yong chong | H8: 5.7046 | I8: 942 | J8: 14778 | P8: 14778 | S8: 4961.0935 | U8: 121.64221 | V8: 1400 | X8: 6482.7357 | Y8: 883.2902 | AA8: 21.776472 | AB8: 905.06667 | AC8: 7.09 | AD8: 6416.9227 | AE8: 12899.658 | AF8: 1878.3416
C9: 240802000009 | D9: 45511 | E9: Bella | F9: Bella Chan | G9: zhang long ting | H9: 0.1283 | I9: 12.76 | J9: 327.6 | P9: 327.6 | S9: 111.57808 | U9: 2.7358088 | X9: 114.31388 | Y9: 19.865746 | AA9: 0.48976638 | AB9: 20.355512 | AC9: 7.09 | AD9: 144.32058 | AE9: 258.63446 | AF9: 68.965535
C10: 240809000038 | D10: 45534 | E10: Bella | F10: Bella Chan | G10: FENG | H10: 2.0316 | I10: 173 | J10: 4667 | P10: 4667 | S10: 1719.249 | U10: 62.740588 | X10: 1781.9896 | Y10: 311.22319 | AB10: 311.22319 | AC10: 7.07 | AD10: 2200.348 | AE10: 3982.3375 | AF10: 684.66246
C11: 240815000041 | D11: 45516 | E11: Bella | F11: Bella Chan | G11: Shuaibu musa | H11: 6.6096 | I11: 2430 | J11: 20266.26 | P11: 20266.26 | S11: 5176.7748 | U11: 126.36 | X11: 5303.1348 | Y11: 1043.6811 | AB11: 1043.6811 | AC11: 7.06 | AD11: 7368.3887 | AE11: 12671.523 | AF11: 7594.7365
C12: 240819000004 | D12: 45532 | E12: Bella | F12: Bella Chan | G12: FENG | H12: 4.6 | I12: 2063 | J12: 9940 | P12: 9940 | S12: 3602.8147 | U12: 87.941176 | X12: 3690.7559 | Y12: 726.35759 | AB12: 726.35759 | AC12: 7.06 | AD12: 5128.0846 | AE12: 8818.8405 | AF12: 1121.1595
C13: 240819000004 | D13: 45532 | E13: Bella | F13: Bella Chan | G13: FENG | H13: 0.0982 | I13: 59 | J13: 212 | P13: 212 | S13: 76.331004 | U13: 2.1661765 | X13: 78.497181 | Y13: 15.506155 | AA13: 0.35783791 | AB13: 15.863993 | AC13: 7.12 | AD13: 112.95163 | AE13: 191.44881 | AF13: 20.551186
A14: 合 计 | AF14: =SUM(AF4:AF13) -> 18330.104
AF15: 2529.7903
C16: 基本任务：小于6千 | F16: 不够基本任务6千， 公司将根据空运提成里抽出补足基数 | K16: 三凤 提成 | AF16: =SUM(AF14-AF15) -> 15800.314
K17: 名称 | L17: 计费体积 | M17: 毛利 | N17: 备注
C18: 基本任务：6千-3.5万 | F18: 按40%提成 | K18: LOS | L18: =SUM(H4:H13) -> 26.0705 | M18: 15800.314 | N18: 总利润减zhong zi xin 利润的 一半2529.79
K19: 基数 | M19: 2000
C20: 基本任务：3.5万以上 | F20: 按50%提成 | K20: 提成计数 | M20: =SUM(M18-M19) -> 13800.314
K21: 提成点数 | M21: 0.1
K22: 提成金额 | M22: =SUM(M20*M21) -> 1380.0314

Sheet 吕沛霖
A1: LOS毛利表
A2: JOB | B2: 集装编号 | C2: 运单编号 | D2: 日期 | E2: 业务 | F2: 发货人 | G2: 收货人 | H2: 计费体积 | I2: 计费重量 | J2: 应 收 | Q2: 总应收 | R2: 起 运 港 成 本 | W2: 代垫运费 | X2: 起运港成本 合计 | Y2: 目的港成本 | AE2: 总支出 | AF2: 利润
J3: 应收RMB | K3: LOS Income(NGN)收到(奈拉) | L3: LOS 收到USD | M3: 美元汇率 dollar currency rate | N3: 应收 到付款USD | O3: 汇率 | P3: 人民币 | R3: 代理商 | S3: 运费+出口报关费 | T3: 提货费 | U3: 装卸费 | V3: 包装费 | Y3: 进口报关费 | Z3: 到门配送费 | AA3: 转运费 | AB3: 目的港支出 | AC3: 汇率 | AD3: 人民币 | AE3: 起运港+目的港
A4: JOB080353 | B4: COLL004085 | C4: 240719000024 | D4: 45505 | E4: 吕沛霖 | F4: Paul | G4: Paul | H4: 0.0423 | I4: 12.5 | J4: 356 | P4: 356 | Q4: 11754.55 | R4: 华茂青松=56567 赛捷=1280 | S4: 36.470855 | U4: 0.88265937 | X4: 37.353514 | Y4: 6.4534946 | Z4: 9.09 | AB4: 15.543495 | AC4: 7.08 | AD4: 110.04794 | AE4: 147.40146 | AF4: 208.59854
C5: 240719000037 | D5: 45506 | E5: 吕沛霖 | F5: 喵喵速运-Layne | G5: Hu Hai Liang | H5: 0.9193 | I5: 430 | K5: 579841.5 | M5: 1744.5663 | N5: 332.37 | O5: 7.12 | P5: 2366.4744 | S5: 795.8299 | U5: 27.038235 | X5: 822.86813 | Y5: 136.7863 | AA5: 1.2363233 | AB5: 138.02262 | AC5: 7.15 | AD5: 986.86174 | AE5: 1809.7299 | AF5: 556.74453
C6: 240630000010 | D6: 45511 | E6: 吕沛霖 | F6: 喵喵速运-Layne | G6: WEI PING | H6: 1.6128 | I6: 637 | J6: 3432 | P6: 3432 | S6: 1396.1867 | U6: 47.435294 | X6: 1443.622 | Y6: 239.97492 | AA6: 2.1689788 | AB6: 242.14389 | AC6: 7.15 | AD6: 1731.3288 | AE6: 3174.9509 | AF6: 257.04913
C7: 240630000010 | D7: 45511 | E7: 吕沛霖 | F7: 喵喵速运-Layne | G7: WEI PING | H7: 1.5552 | I7: 912 | J7: 3309 | P7: 3309 | S7: 1315.7964 | U7: 33.162353 | X7: 1348.9588 | Y7: 240.80442 | AA7: 4.7223191 | AB7: 245.52674 | AC7: 7.09 | AD7: 1740.7846 | AE7: 3089.7434 | AF7: 219.25664
C8: 240630000010 | D8: 45534 | E8: 吕沛霖 | F8: 喵喵速运-Layne | G8: WEI PING | H8: 4.6083 | I8: 761.3 | J8: 9806 | P8: 9806 | S8: 4007.6793 | U8: 98.265221 | X8: 4105.9445 | Y8: 713.54104 | AA8: 17.591508 | AB8: 731.13255 | AC8: 7.09 | AD8: 5183.7298 | AE8: 9289.6742 | AF8: 516.32577
C9: 240730000035 | D9: 45511 | E9: 吕沛霖 | F9: 喵喵速运-Layne | G9: MR MANBO | H9: 1.0597 | I9: 336 | J9: 3645.46 | P9: 3645.46 | S9: 921.58447 | U9: 22.596544 | X9: 944.18101 | Y9: 164.08208 | Z9: 50.15 | AA9: 4.0452489 | AB9: 218.27733 | AC9: 7.09 | AD9: 1547.5862 | AE9: 2491.7673 | AF9: 1153.6927
C10: 240808000012 | D10: 45512 | E10: 吕沛霖 | F10: 喵喵速运-Layne | G10: YA | H10: 0.2465 | I10: 35.5 | J10: 821 | P10: 821 | S10: 212.17941 | T10: 0.19933875 | U10: 3.625 | X10: 216.00375 | Y10: 37.826875 | AA10: 22.18 | AB10: 60.006875 | AC10: 7.12 | AD10: 427.24895 | AE10: 643.2527 | AF10: 177.74731
C11: 240630000010 | D11: 45534 | E11: 吕沛霖 | F11: 喵喵速运-Layne | G11: WEI PING | H11: 20.8295 | I11: 1472 | J11: 44333.83 | P11: 44333.83 | S11: 17929.375 | T11: 16.844327 | U11: 306.31618 | X11: 18252.536 | Y11: 3196.4093 | AB11: 3196.4093 | AC11: 7.12 | AD11: 22758.434 | AE11: 41010.97 | AF11: 3322.8603
A12: JOB080373 | B12: COLL004107 | C12: 240630000010 | D12: 45534 | E12: 吕沛霖 | F12: 喵喵速运-Layne | G12: WEI PING | H12: 4.5207 | I12: 744 | J12: 9620 | P12: 9620 | Q12: 59706.034 | R12: 赛捷=56265.25 赛捷=1280 | S12: 3825.659 | U12: 139.60985 | V12: 900 | X12: 4865.2688 | Y12: 692.53135 | Z12: 70.8 | AB12: 763.33135 | AC12: 7.07 | AD12: 5396.7527 | AE12: 10262.022 | AF12: -642.0215
C13: 240806000025 | D13: 45534 | E13: 吕沛霖 | F13: 喵喵速运-Layne | G13: FRANK | H13: 4.665 | I13: 886 | J13: 10755.219 | P13: 10755.219 | S13: 3947.7734 | U13: 144.06618 | X13: 4091.8396 | Y13: 714.63684 | AB13: 714.63684 | AC13: 7.07 | AD13: 5052.4824 | AE13: 9144.322 | AF13: 1610.897
C14: 240808000002 | D14: 45534 | E14: 吕沛霖 | F14: 喵喵速运-Layne | G14: FRANK | H14: 2.1795 | I14: 785 | K14: 1256000 | M14: 1751.89 | N14: 716.94 | O14: 7.15 | P14: 5126.121 | S14: 1844.4099 | U14: 67.308088 | X14: 1911.718 | Y14: 333.88017 | AB14: 333.88017 | AC14: 7.07 | AD14: 2360.5328 | AE14: 4272.2508 | AF14: 853.87023
A15: JOB080387 | B15: COLL004121 | C15: 240807000029 | D15: 45516 | E15: 吕沛霖 | F15: 喵喵速运-Layne | G15: Candice Ding | H15: 0.55 | I15: 148 | J15: 1768.88 | P15: 1768.88 | Q15: 85027.907 | R15: 登凯=50475 赛捷=1000 拖车费=1670 杂费=61 过磅费=53 | S15: 430.77132 | U15: 10.514706 | X15: 441.28603 | Y15: 86.847103 | Z15: 47.2 | AB15: 134.0471 | AC15: 7.06 | AD15: 946.37255 | AE15: 1387.6586 | AF15: 381.22142
C16: 240811000001 | D16: 45516 | E16: 吕沛霖 | F16: 喵喵速运-Layne | G16: FRANK | H16: 8.3155 | I16: 4780 | K16: 4494672 | M16: 1773.8649 | N16: 2533.83 | O16: 7.24 | P16: 18344.929 | S16: 6512.8708 | U16: 158.97279 | X16: 6671.8436 | Y16: 1313.0492 | AB16: 1313.0492 | AC16: 7.06 | AD16: 9270.1277 | AE16: 15941.971 | AF16: 2402.9579
C17: 240813000034 | D17: 45516 | E17: 吕沛霖 | F17: 喵喵速运-Layne | G17: Hu Hai Liang | H17: 4.253 | I17: 1141 | K17: 2383535 | M17: 1751.2714 | N17: 1361.0312 | O17: 7.12 | P17: 9690.5421 | S17: 3331.0372 | U17: 81.307353 | X17: 3412.3445 | Y17: 671.56496 | AB17: 671.56496 | AC17: 7.06 | AD17: 4741.2486 | AE17: 8153.5931 | AF17: 1536.949
C18: 240819000017 | D18: 45516 | E18: 吕沛霖 | F18: 喵喵速运-Layne | G18: WEI PING | H18: 23.494 | I18: 2608 | J18: 50190.17 | P18: 50190.17 | S18: 18400.984 | U18: 449.15 | V18: 960 | W18: 146.5 | X18: 19956.635 | Y18: 3709.7924 | AB18: 3709.7924 | AC18: 7.06 | AD18: 26191.135 | AE18: 46147.769 | AF18: 4042.4009
C19: 240819000033 | D19: 45532 | E19: 吕沛霖 | F19: 喵喵速运-Layne | G19: Candice Ding | H19: 0.2086 | I19: 344 | K19: 383195 | M19: 1811.7967 | N19: 211.5 | O19: 7.3 | P19: 1543.95 | S19: 162.14509 | U19: 4.6014706 | X19: 166.74656 | Y19: 32.938738 | Z19: 46.5 | AA19: 0.76013226 | AB19: 80.19887 | AC19: 7.12 | AD19: 571.01595 | AE19: 737.76251 | AF19: 806.18749
C20: 240823000021 | D20: 45532 | E20: 吕沛霖 | F20: 喵喵速运-Layne | G20: FRANK | H20: 7.4589 | I20: 3300 | K20: 3229875 | M20: 1650 | N20: 1957.5 | O20: 7.12 | P20: 13937.4 | S20: 5797.8139 | U20: 164.53456 | X20: 5962.3485 | Y20: 1177.7888 | AA20: 27.180012 | AB20: 1204.9688 | AC20: 7.12 | AD20: 8579.3782 | AE20: 14541.727 | AF20: -604.32665
C21: 240828000017 | D21: 45532 | E21: 吕沛霖 | F21: 喵喵速运-Layne | G21: Sule Adekunle | H21: 0.1138 | I21: 45 | J21: 421 | P21: 421 | S21: 88.456907 | U21: 2.5102941 | X21: 90.967201 | Y21: 17.969455 | Z21: 20.65 | AA21: 0.41468385 | AB21: 39.034139 | AC21: 7.12 | AD21: 277.92307 | AE21: 368.89027 | AF21: 52.109729
A22: 合计 | AF22: =SUM(AF4:AF21) -> 16852.52
C25: 基本任务：小于6千 | F25: 不够基本任务6千， 公司将根据空运提成里抽出补足基数 | K25: 吕沛霖 提成
K26: 名称 | L26: 计费体积 | M26: 毛利
C27: 基本任务：6千-3.5万 | F27: 按40%提成 | K27: LOS | L27: =SUM(H4:H21) -> 86.6326 | M27: =SUM(AF22) -> 16852.52
K28: 基数 | M28: 8595.8056
C29: 基本任务：3.5万以上 | F29: 按50%提成 | K29: 提成计数 | M29: =SUM(M27-M28) -> 8256.7149
K30: 提成点数 | M30: 0.4
K31: 提成金额 | M31: =SUM(M29*M30) -> 3302.686

Sheet 朱小飞
A1: LOS毛利表
A3: JOB | B3: 集装编号 | C3: 运单编号 | D3: 日期 | E3: 业务 | F3: 发货人 | G3: 收货人 | H3: 计费体积 | I3: 计费重量 | J3: 应 收 | Q3: 总应收 | R3: 起 运 港 成 本 | W3: 代垫运费 | X3: 起运港成本 合计 | Y3: 目的港成本 | AE3: 总支出 | AF3: 利润
J4: 应收RMB | K4: LOS Income(NGN)收到(奈拉) | L4: LOS 收到USD | M4: 美元汇率 dollar currency rate | N4: 应收 到付款USD | O4: 汇率 | P4: 人民币 | R4: 代理商 | S4: 运费+出口报关费 | T4: 提货费 | U4: 装卸费 | V4: 包装费 | Y4: 进口报关费 | Z4: 到门配送费 | AA4: 转运费 | AB4: 目的港支出 | AC4: 汇率 | AD4: 人民币 | AE4: 起运港+目的港
C5: 240726000053 | D5: 45505 | E5: 朱小飞 | F5: Isabel Zhu | G5: Halifa Success | H5: 0.2452 | I5: 41 | J5: 611.38 | P5: 611.38 | S5: 211.41025 | U5: 5.116503 | X5: 216.52675 | Y5: 37.40891 | AB5: 37.40891 | AC5: 7.08 | AD5: 264.85508 | AE5: 481.38183 | AF5: 129.99817
C6: 240729000013 | D6: 45506 | E6: 朱小飞 | F6: Isabel Zhu | G6: Halifa Success | H6: 0.3557 | I6: 50 | J6: 801.54 | P6: 801.54 | S6: 307.92635 | U6: 10.461765 | X6: 318.38812 | Y6: 52.926015 | AA6: 0.47836419 | AB6: 53.40438 | AC6: 7.15 | AD6: 381.84131 | AE6: 700.22943 | AF6: 101.31057
C7: 240730000010 | D7: 45506 | E7: 朱小飞 | F7: Isabel Zhu | G7: Halifa Success | H7: 3.0014 | I7: 502 | J7: 6679.5 | P7: 6679.5 | S7: 2598.2855 | U7: 88.276471 | X7: 2686.562 | Y7: 446.59022 | AA7: 4.0364416 | AB7: 450.62666 | AC7: 7.15 | AD7: 3221.9807 | AE7: 5908.5426 | AF7: 770.95738 | AG7: =SUM(AF5:AF7) -> 1002.2661 | AH7: =SUM(AG7/2) -> 501.13306
C8: 240713000006 | D8: 45491 | E8: 朱小飞 | F8: Isabel Zhu | G8: Anthonia | H8: 1.7306 | I8: 346 | J8: 5462 | P8: 5462 | S8: 3368.2077 | T8: 7.1349037 | X8: 3375.3426 | Z8: 70.8 | AB8: 70.8 | AC8: 7.15 | AD8: 506.22 | AE8: 3881.5626 | AF8: 1580.4374
C9: 240717000037 | D9: 45498 | E9: 朱小飞 | F9: Isabel Zhu | G9: Mr Michael | H9: 6.1861 | I9: 1004.71 | J9: 14822 | P9: 14822 | S9: 5333.6254 | U9: 129.08319 | X9: 5462.7086 | Y9: 943.78163 | AB9: 943.78163 | AC9: 7.08 | AD9: 6681.9739 | AE9: 12144.682 | AF9: 2677.3175
C10: 240729000009 | D10: 45505 | E10: 朱小飞 | F10: Isabel Zhu | G10: Joy | H10: 2.2224 | I10: 3202 | K10: 2787617 | M10: 1741.2595 | N10: 1600.9199 | O10: 7.12 | P10: 11398.55 | S10: 1916.1425 | U10: 46.374047 | X10: 1962.5165 | Y10: 339.0602 | AB10: 339.0602 | AC10: 7.08 | AD10: 2400.5462 | AE10: 4363.0627 | AF10: 7035.487
C11: 240723000028 | D11: 45506 | E11: 朱小飞 | F11: Isabel Zhu | G11: Musa Garuba | H11: 0.4159 | I11: 53.8 | K11: 286650 | M11: 1750 | N11: 163.8 | O11: 7.12 | P11: 1166.256 | S11: 360.04096 | U11: 12.232353 | X11: 372.27331 | Y11: 61.883412 | AA11: 0.55932434 | AB11: 62.442737 | AC11: 7.15 | AD11: 446.46557 | AE11: 818.73888 | AF11: 347.51712
C12: 240717000037 | D12: 45498 | E12: 朱小飞 | F12: Isabel Zhu | G12: Mr Michael | H12: 8.2 | I12: 882 | J12: 19661.07 | P12: 19661.07 | S12: 7098.6676 | U12: 241.17647 | X12: 7339.8441 | Y12: 1220.1106 | AA12: 11.027794 | AB12: 1231.1384 | AC12: 7.15 | AD12: 8802.6392 | AE12: 16142.483 | AF12: 3518.5867
C13: 240805000030 | D13: 45511 | E13: 朱小飞 | F13: Isabel Zhu | G13: Abdul Aziz | H13: 0.4717 | I13: 63 | J13: 1994.39 | P13: 1994.39 | S13: 399.08768 | U13: 10.058309 | X13: 409.14599 | Y13: 73.037196 | Z13: 76.7 | AA13: 1.4323032 | AB13: 151.1695 | AC13: 7.09 | AD13: 1071.7917 | AE13: 1480.9377 | AF13: 513.45226
C14: 240801000020 | D14: 45512 | E14: 朱小飞 | F14: Isabel Zhu | G14: Mr Michael | H14: 5.1796 | I14: 572 | J14: 12648 | P14: 12648 | S14: 4504.5191 | U14: 110.44735 | X14: 4614.9665 | Y14: 802.00012 | AA14: 19.772361 | AB14: 821.77248 | AC14: 7.09 | AD14: 5826.3669 | AE14: 10441.333 | AF14: 2206.6666
A15: JOB080364 | B15: COLL004100 | C15: 240801000020 | D15: 45512 | E15: 朱小飞 | F15: Isabel Zhu | G15: Mr Michael | H15: 5.7204 | I15: 603 | J15: 13956 | P15: 13956 | Q15: 59110.83 | R15: 赛捷=57732.25 赛捷=800 | S15: 4923.9395 | T15: 4.6259529 | U15: 84.123529 | X15: 5012.6889 | Y15: 877.82903 | AB15: 877.82903 | AC15: 7.12 | AD15: 6250.1427 | AE15: 11262.832 | AF15: 2693.1684
C16: 240807000004 | D16: 45534 | E16: 朱小飞 | F16: Isabel Zhu | G16: Inemesit udoh | H16: 2.4662 | I16: 160 | K16: 1842570 | M16: 1735 | N16: 1062 | O16: 7.12 | P16: 7561.44 | S16: 2087.0308 | U16: 76.162059 | X16: 2163.1929 | Y16: 377.80008 | AB16: 377.80008 | AC16: 7.07 | AD16: 2671.0466 | AE16: 4834.2394 | AF16: 2727.2006
C17: 240809000034 | D17: 45534 | E17: 朱小飞 | F17: Isabel Zhu | G17: Victor Nnamdi | H17: 0.9292 | I17: 144 | K17: 548260 | M17: 1735 | N17: 316 | O17: 7.12 | P17: 2249.92 | S17: 786.33892 | U17: 28.695882 | X17: 815.0348 | Y17: 142.34524 | AB17: 142.34524 | AC17: 7.07 | AD17: 1006.3809 | AE17: 1821.4157 | AF17: 428.50435
C18: 240818000009 | D18: 45516 | E18: 朱小飞 | F18: Isabel Zhu | G18: Wu Jiao Xing | H18: 0.1955 | I18: 39 | J18: 468 | P18: 468 | S18: 153.11963 | U18: 3.7375 | X18: 156.85712 | Y18: 30.870197 | AB18: 30.870197 | AC18: 7.06 | AD18: 217.94359 | AE18: 374.80072 | AF18: 93.199281
C19: 240818000013 | D19: 45516 | E19: 朱小飞 | F19: Isabel Zhu | G19: Lin Bao Zhen | H19: 1.5335 | I19: 305 | K19: 1228413.6 | M19: 1744.98 | N19: 703.97 | O19: 7.15 | P19: 5033.3855 | S19: 1201.0688 | U19: 29.316912 | X19: 1230.3857 | Y19: 242.14551 | Z19: 248 | AB19: 490.14551 | AC19: 7.06 | AD19: 3460.4273 | AE19: 4690.813 | AF19: 342.57249
C20: 240816000038 | D20: 45532 | E20: 朱小飞 | F20: Isabel Zhu | G20: Nicolas | H20: 0.1557 | I20: 40.2 | J20: 602 | P20: 602 | S20: 121.02584 | U20: 3.4345588 | X20: 124.4604 | Y20: 24.585625 | Z20: 21.12 | AA20: 0.56736622 | AB20: 46.272992 | AC20: 7.12 | AD20: 329.4637 | AE20: 453.9241 | AF20: 148.0759
C21: 240820000001 | D21: 45532 | E21: 朱小飞 | F21: Isabel Zhu | G21: Mr Michael | H21: 7.0865 | I21: 599 | J21: 17258.7 | P21: 17258.7 | S21: 5508.3469 | U21: 156.31985 | V21: 300 | X21: 5964.6667 | Y21: 1118.9854 | AA21: 25.822998 | AB21: 1144.8084 | AC21: 7.12 | AD21: 8151.0361 | AE21: 14115.703 | AF21: 3142.9972
C22: 240826000039 | D22: 45532 | E22: 朱小飞 | F22: Isabel Zhu | G22: Lin Bao Zhen | H22: 1.823 | I22: 321 | K22: 964731.6 | M22: 1764.005 | N22: 546.89844 | O22: 7.23 | P22: 3954.0757 | S22: 1417.0206 | U22: 40.213235 | X22: 1457.2338 | Y22: 287.85867 | AA22: 6.6429584 | AB22: 294.50163 | AC22: 7.12 | AD22: 2096.8516 | AE22: 3554.0854 | AF22: 399.99031
A23: 合计 | AF23: =SUM(AF5:AF22) -> 28857.439
AF24: 501.13306
C25: 基本任务：小于6千 | F25: 不够基本任务6千， 公司将根据空运提成里抽出补足基数 | K25: 朱小飞 提成 | AF25: =SUM(AF23-AF24) -> 28356.306
K26: 名称 | L26: 计费体积 | M26: 毛利 | N26: 备注
C27: 基本任务：6千-3.5万 | F27: 按40%提成 | K27: LOS | L27: =SUM(H5:H22) -> 47.9186 | M27: 28356.306 | N27: 总利润减Halifa 利润的 一半501.13
K28: 基数 | M28: 2000
C29: 基本任务：3.5万以上 | F29: 按50%提成 | K29: 提成计数 | M29: =SUM(M27-M28) -> 26356.306
K30: 提成点数 | M30: 0.1
K31: 提成金额 | M31: =SUM(M29*M30) -> 2635.6306

Sheet 罗伟健
A1: LOS毛利表
A3: JOB | B3: 集装编号 | C3: 运单编号 | D3: 日期 | E3: 业务 | F3: 发货人 | G3: 收货人 | H3: 计费体积 | I3: 计费重量 | J3: 应 收 | Q3: 总应收 | R3: 起 运 港 成 本 | W3: 代垫运费 | X3: 起运港成本 合计 | Y3: 目的港成本 | AE3: 总支出 | AF3: 利润
J4: 应收RMB | K4: LOS Income(NGN)收到(奈拉) | L4: LOS 收到USD | M4: 美元汇率 dollar currency rate | N4: 应收 到付款USD | O4: 汇率 | P4: 人民币 | R4: 代理商 | S4: 运费+出口报关费 | T4: 提货费 | U4: 装卸费 | V4: 包装费 | Y4: 进口报关费 | Z4: 到门配送费 | AA4: 转运费 | AB4: 目的港支出 | AC4: 汇率 | AD4: 人民币 | AE4: 起运港+目的港
A5: JOB080389 | B5: COLL004124 | C5: 240708000003 | D5: 45491 | E5: 罗伟健 | F5: MailMail速运-演员 | G5: zeng hai | H5: 2.2272 | I5: 11222 | K5: 8906452 | M5: 1620.0015 | N5: 5497.8047 | O5: 7.12 | P5: 39144.369 | Q5: 56612.182 | R5: 赛捷 | S5: 4334.7234 | T5: 9.1822821 | V5: 350 | X5: 4693.9056 | AA5: 100.29 | AB5: 100.29 | AC5: 7.15 | AD5: 717.0735 | AE5: 5410.9791 | AF5: 33733.39
C6: 240718000002 | D6: 45491 | E6: 罗伟健 | F6: MailMail速运-演员 | G6: zeng hai | H6: 5.3938 | I6: 1414 | K6: 2909624 | M6: 1711 | N6: 1700.54 | O6: 7.06 | P6: 12005.812 | S6: 10497.769 | T6: 22.237515 | V6: 70 | X6: 10590.006 | AB6: 0 | AC6: 7.15 | AD6: 0 | AE6: 10590.006 | AF6: 1415.806
C7: 240804000004 | D7: 45511 | E7: 罗伟健 | F7: MailMail速运-演员 | G7: zeng hai | H7: 10.2324 | I7: 1319 | K7: 5637625 | M7: 1710.9999 | N7: 3294.93 | O7: 7.06 | P7: 23262.206 | S7: 8898.7647 | U7: 218.19088 | V7: 150 | X7: 9266.9555 | Y7: 1584.3668 | AA7: 39.060682 | AB7: 1623.4274 | AC7: 7.09 | AD7: 11510.101 | AE7: 20777.056 | AF7: 2485.1497
C8: 240810000008 | D8: 45534 | E8: 罗伟健 | F8: MailMail速运-演员 | G8: Mr.Joseph Ezekiel | H8: 7.4021 | I8: 2808 | K8: 4341273 | M8: 1725 | N8: 2516.68 | O8: 7.12 | P8: 17918.762 | S8: 6264.0543 | U8: 228.59426 | X8: 6492.6486 | Y8: 1133.9364 | AB8: 1133.9364 | AC8: 7.07 | AD8: 8016.9304 | AE8: 14509.579 | AF8: 3409.1826
A9: 合计 | AF9: =SUM(AF5:AF8) -> 41043.529
C11: 基本任务：小于6千 | F11: 不够基本任务6千， 公司将根据空运提成里抽出补足基数 | K11: 罗伟健 提成
K12: 名称 | L12: 计费体积 | M12: 毛利
C13: 基本任务：6千-3.5万 | F13: 按40%提成 | K13: LOS | L13: =SUM(H5:H8) -> 25.2555 | M13: =SUM(AF9) -> 41043.529
K14: 任务 | M14: 6000
C15: 基本任务：3.5万以上 | F15: 按50%提成 | K15: 提成计数 | M15: =SUM(M13-M14) -> 35043.529
K16: 基数 | M16: 35000
K17: 提成计数40% | M17: 0.4
K18: 提成金额 | M18: =SUM(M16*M17) -> 14000
K19: 实提成计数 | M19: =SUM(M15-M16) -> 43.528642
K20: 提成点数50% | M20: 0.5
K21: 提成金额 | M21: =SUM(M19*M20) -> 21.764321
K22: 合计提成金额 | M22: =SUM(M18+M21) -> 14021.764

Sheet 罗珮文
A1: LOS毛利表
A3: JOB | B3: 集装编号 | C3: 运单编号 | D3: 日期 | E3: 业务 | F3: 发货人 | G3: 收货人 | H3: 计费体积 | I3: 计费重量 | J3: 应 收 | Q3: 总应收 | R3: 起 运 港 成 本 | W3: 代垫运费 | X3: 起运港成本 合计 | Y3: 目的港成本 | AE3: 总支出 | AF3: 利润
J4: 应收RMB | K4: LOS Income(NGN)收到(奈拉) | L4: LOS 收到USD | M4: 美元汇率 dollar currency rate | N4: 应收 到付款USD | O4: 汇率 | P4: 人民币 | R4: 代理商 | S4: 运费+出口报关费 | T4: 提货费 | U4: 装卸费 | V4: 包装费 | Y4: 进口报关费 | Z4: 到门配送费 | AA4: 转运费 | AB4: 目的港支出 | AC4: 汇率 | AD4: 人民币 | AE4: 起运港+目的港
C5: 240826000011 | D5: 45532 | E5: 罗珮文 | F5: Shirley | G5: Yusky | H5: 6.3305 | I5: 880 | J5: 10555.28 | P5: 10555.28 | S5: 4920.707 | U5: 139.64338 | X5: 5060.3503 | Y5: 999.61015 | AA5: 23.068156 | AB5: 1022.6783 | AC5: 7.12 | AD5: 7281.4696 | AE5: 12341.82 | AF5: -1786.5399
C6: 240826000013 | D6: 45532 | E6: 罗珮文 | F6: Shirley | G6: Yusky | H6: 0.699 | I6: 105 | J6: 1165.58 | P6: 1165.58 | S6: 543.33373 | U6: 15.419118 | X6: 558.75285 | Y6: 110.37477 | AA6: 2.5471354 | AB6: 112.92191 | AC6: 7.12 | AD6: 804.00399 | AE6: 1362.7568 | AF6: -197.17683
C7: 240826000015 | D7: 45532 | E7: 罗珮文 | F7: Shirley | G7: Yusky | H7: 0.2907 | I7: 36 | J7: 483.58 | P7: 483.58 | S7: 225.96154 | U7: 6.4125 | X7: 232.37404 | Y7: 45.902642 | AA7: 1.0593023 | AB7: 46.961944 | AC7: 7.12 | AD7: 334.36904 | AE7: 566.74308 | AF7: -83.163077
C8: 240826000016 | D8: 45532 | E8: 罗珮文 | F8: Shirley | G8: Yusky | H8: 0.5572 | I8: 42 | J8: 928.8 | P8: 928.8 | S8: 433.11238 | U8: 12.291176 | X8: 445.40356 | Y8: 87.98401 | AA8: 2.0304204 | AB8: 90.014431 | AC8: 7.12 | AD8: 640.90275 | AE8: 1086.3063 | AF8: -157.5063
C9: 240826000017 | D9: 45532 | E9: 罗珮文 | F9: Shirley | G9: Yusky | H9: 0.1598 | I9: 78 | J9: 266.44 | P9: 266.44 | S9: 124.21277 | U9: 3.525 | X9: 127.73777 | Y9: 25.233031 | AA9: 0.5823065 | AB9: 25.815337 | AC9: 7.12 | AD9: 183.8052 | AE9: 311.54298 | AF9: -45.102978
C10: 240826000018 | D10: 45532 | E10: 罗珮文 | F10: Shirley | G10: Yusky | H10: 0.141 | I10: 37 | J10: 235.26 | P10: 235.26 | S10: 109.59951 | U10: 3.1102941 | X10: 112.7098 | Y10: 22.264439 | AA10: 0.51379985 | AB10: 22.778239 | AC10: 7.12 | AD10: 162.18106 | AE10: 274.89086 | AF10: -39.630863
C11: 240826000019 | D11: 45532 | E11: 罗珮文 | F11: Shirley | G11: Yusky | H11: 1.4354 | I11: 186 | J11: 2392.86 | P11: 2392.86 | S11: 1115.7385 | U11: 31.663235 | X11: 1147.4018 | Y11: 226.65515 | AA11: 5.2305554 | AB11: 231.8857 | AC11: 7.12 | AD11: 1651.0262 | AE11: 2798.428 | AF11: -405.56798
C12: 240828000003 | D12: 45532 | E12: 罗珮文 | F12: Shirley | G12: Yusky | H12: 0.807 | I12: 46 | J12: 1345.67 | P12: 1345.67 | S12: 627.28229 | U12: 17.801471 | X12: 645.08376 | Y12: 127.42839 | AA12: 2.9406843 | AB12: 130.36907 | AC12: 7.12 | AD12: 928.22778 | AE12: 1573.3115 | AF12: -227.64153
C13: 240828000005 | D13: 45532 | E13: 罗珮文 | F13: Shirley | G13: Yusky | H13: 0.6964 | I13: 42 | J13: 1161.45 | P13: 1161.45 | S13: 541.31274 | U13: 15.361765 | X13: 556.67451 | Y13: 109.96422 | AA13: 2.5376611 | AB13: 112.50188 | AC13: 7.12 | AD13: 801.01341 | AE13: 1357.6879 | AF13: -196.23792
C14: 240828000008 | D14: 45532 | E14: 罗珮文 | F14: Shirley | G14: Yusky | H14: 0.0844 | I14: 25 | J14: 140.94 | P14: 140.94 | S14: 65.604244 | U14: 1.8617647 | X14: 67.466009 | Y14: 13.327083 | AA14: 0.30755112 | AB14: 13.634634 | AC14: 7.12 | AD14: 97.078593 | AE14: 164.5446 | AF14: -23.604602
C15: 240828000062 | D15: 45532 | E15: 罗珮文 | F15: Shirley | G15: Yusky | H15: 1.8606 | I15: 279 | J15: 6598.3 | P15: 6598.3 | S15: 1446.2471 | U15: 41.042647 | X15: 1487.2898 | Y15: 293.79585 | AA15: 6.7799717 | AB15: 300.57583 | AC15: 7.12 | AD15: 2140.0999 | AE15: 3627.3896 | AF15: 2970.9104
A16: 合计 | AF16: =SUM(AF5:AF15) -> -191.26164
C18: 基本任务：小于6千 | F18: 不够基本任务6千， 公司将根据空运提成里抽出补足基数 | K18: 罗珮文 提成
K19: 名称 | L19: 计费体积 | M19: 毛利
C20: 基本任务：6千-3.5万 | F20: 按40%提成 | K20: LOS | L20: =SUM(H5:H15) -> 13.062 | M20: =SUM(AF16) -> -191.26164
K21: 基数
C22: 基本任务：3.5万以上 | F22: 按50%提成 | K22: 提成计数
K23: 提成点数
K24: 提成金额

Sheet 陆总
A1: LOS毛利表
A3: JOB | B3: 集装编号 | C3: 运单编号 | D3: 日期 | E3: 业务 | F3: 发货人 | G3: 收货人 | H3: 计费体积 | I3: 计费重量 | J3: 应 收 | Q3: 总应收 | R3: 起 运 港 成 本 | W3: 代垫运费 | X3: 起运港成本 合计 | Y3: 目的港成本 | AE3: 总支出 | AF3: 利润
J4: 应收RMB | K4: LOS Income(NGN)收到(奈拉) | L4: LOS 收到USD | M4: 美元汇率 dollar currency rate | N4: 应收 到付款USD | O4: 汇率 | P4: 人民币 | R4: 代理商 | S4: 运费+出口报关费 | T4: 提货费 | U4: 装卸费 | V4: 包装费 | Y4: 进口报关费 | Z4: 到门配送费 | AA4: 转运费 | AB4: 目的港支出 | AC4: 汇率 | AD4: 人民币 | AE4: 起运港+目的港
C5: 240729000055 | D5: 45505 | E5: 陆总 | F5: 喵喵速运-江 | G5: LUZHILONG | H5: 22.022 | I5: 12675 | J5: 54288.61 | P5: 54288.61 | S5: 18987.261 | U5: 459.5254 | X5: 19446.787 | Y5: 3359.7839 | AB5: 3359.7839 | AC5: 7.08 | AD5: 23787.27 | AE5: 43234.057 | AF5: 11054.553
C6: 240731000038 | D6: 45506 | E6: 陆总 | F6: 喵喵速运-江 | G6: LUZHILONG | H6: 3.6015 | I6: 1074 | J6: 8038.58 | P6: 8038.58 | S6: 3117.7868 | U6: 105.92647 | X6: 3223.7132 | Y6: 535.88149 | AA6: 4.8434879 | AB6: 540.72497 | AC6: 7.15 | AD6: 3866.1836 | AE6: 7089.8968 | AF6: 948.6832
C7: 240802000026 | D7: 45506 | E7: 陆总 | F7: 喵喵速运-江 | G7: LUZHILONG | H7: 0.0391 | I7: 42.5 | J7: 98.57 | P7: 98.57 | S7: 33.848525 | U7: 1.15 | X7: 34.998525 | Y7: 5.8178443 | AA7: 0.05258375 | AB7: 5.870428 | AC7: 7.15 | AD7: 41.97356 | AE7: 76.972085 | AF7: 21.597915
C8: 240808000019 | D8: 45512 | E8: 陆总 | F8: Sam.Pao | G8: LuZhiLong | H8: 7.4735 | I8: 1000 | J8: 16565.05 | P8: 16565.05 | S8: 6432.9525 | T8: 6.0436436 | U8: 109.90441 | X8: 6548.9006 | Y8: 1146.8525 | AB8: 1146.8525 | AC8: 7.12 | AD8: 8165.5901 | AE8: 14714.491 | AF8: 1850.5594
C9: 240812000043 | D9: 45534 | E9: 陆总 | F9: Sam.Pao | G9: LuZhiLong | H9: 5.313 | I9: 2925 | J9: 13463.78 | P9: 13463.78 | S9: 4496.1458 | U9: 164.07794 | X9: 4660.2237 | Y9: 813.90472 | AB9: 813.90472 | AC9: 7.07 | AD9: 5754.3064 | AE9: 10414.53 | AF9: 3049.2499
C10: 240827000034 | D10: 45532 | E10: 陆总 | F10: 陆梓龙 | G10: jizong | H10: 9.2 | I10: 7350 | J10: 24057.26 | P10: 24057.26 | S10: 7151.1735 | U10: 202.94118 | X10: 7354.1147 | Y10: 1452.7152 | AA10: 33.524529 | AB10: 1486.2397 | AC10: 7.12 | AD10: 10582.027 | AE10: 17936.141 | AF10: 6121.1186
A11: 合计 | AF11: =SUM(AF5:AF10) -> 23045.762
C13: 基本任务：小于6千 | F13: 不够基本任务6千， 公司将根据空运提成里抽出补足基数 | K13: 陆总 提成
K14: 名称 | L14: 计费体积 | M14: 毛利
C15: 基本任务：6千-3.5万 | F15: 按40%提成 | K15: LOS | L15: =SUM(H5:H10) -> 47.6491 | M15: =SUM(AF11) -> 23045.762
K16: 提成计数 | M16: =SUM(M15:M15) -> 23045.762
C17: 基本任务：3.5万以上 | F17: 按50%提成 | K17: 提成点数 | M17: 0.4
K18: 提成金额 | M18: =SUM(M16*M17) -> 9218.3049

Sheet 浦生
A1: LOS毛利表
A3: JOB | B3: 集装编号 | C3: 运单编号 | D3: 日期 | E3: 业务 | F3: 发货人 | G3: 收货人 | H3: 计费体积 | I3: 计费重量 | J3: 应 收 | Q3: 总应收 | R3: 起 运 港 成 本 | W3: 代垫运费 | X3: 起运港成本 合计 | Y3: 目的港成本 | AE3: 总支出 | AF3: 利润
J4: 应收RMB | K4: LOS Income(NGN)收到(奈拉) | L4: LOS 收到USD | M4: 美元汇率 dollar currency rate | N4: 应收 到付款USD | O4: 汇率 | P4: 人民币 | R4: 代理商 | S4: 运费+出口报关费 | T4: 提货费 | U4: 装卸费 | V4: 包装费 | Y4: 进口报关费 | Z4: 到门配送费 | AA4: 转运费 | AB4: 目的港支出 | AC4: 汇率 | AD4: 人民币 | AE4: 起运港+目的港
C5: 240715000049 | D5: 45490 | E5: Sam.Pao | F5: Sam.Pao | G5: Yusky | H5: 0.4043 | I5: 55 | J5: 923.29 | P5: 923.29 | S5: 786.87529 | T5: 1.6668448 | X5: 788.54214 | AB5: 0 | AC5: 7.15 | AD5: 0 | AE5: 788.54214 | AF5: 134.74786
C6: 240724000023 | D6: 45505 | E6: Sam.Pao | F6: Sam.Pao | G6: Yusky | H6: 0.158 | I6: 156 | J6: 337.92 | P6: 337.92 | S6: 136.22683 | U6: 3.296931 | X6: 139.52376 | Y6: 24.105252 | AB6: 24.105252 | AC6: 7.08 | AD6: 170.66518 | AE6: 310.18895 | AF6: 27.731055
C7: 240727000003 | D7: 45505 | E7: Sam.Pao | F7: Sam.Pao | G7: Nick Wang | H7: 4.7589 | I7: 760 | J7: 17244.43 | P7: 17244.43 | S7: 4103.1005 | U7: 99.302309 | X7: 4202.4028 | Y7: 726.04103 | Z7: 678.47 | AB7: 1404.511 | AC7: 7.08 | AD7: 9943.9381 | AE7: 14146.341 | AF7: 3098.0892
C8: 240730000017 | D8: 45505 | E8: Sam.Pao | F8: Sam.Pao | G8: MaiKaiNian | H8: 0.2622 | I8: 392 | J8: 1290.24 | P8: 1290.24 | S8: 226.06757 | U8: 5.4712361 | X8: 231.5388 | Y8: 40.002513 | AB8: 40.002513 | AC8: 7.08 | AD8: 283.21779 | AE8: 514.75659 | AF8: 775.48341
C9: 240801000003 | D9: 45505 | E9: Sam.Pao | F9: Sam.Pao | G9: Yusky | H9: 2.1 | I9: 352 | J9: 4491.38 | P9: 4491.38 | S9: 1810.6098 | U9: 43.819968 | X9: 1854.4298 | Y9: 320.38626 | AB9: 320.38626 | AC9: 7.08 | AD9: 2268.3347 | AE9: 4122.7645 | AF9: 368.61554
C10: 240801000001 | D10: 45506 | E10: Sam.Pao | F10: Sam.Pao | G10: SKY JET | H10: 28.4144 | I10: 2700 | J10: 48216.84 | P10: 48216.84 | S10: 24498.758 | U10: 592.91339 | X10: 25091.671 | Y10: 4335.0396 | AB10: 4335.0396 | AC10: 7.08 | AD10: 30692.081 | AE10: 55783.752 | AF10: -7566.9117
C11: 240801000004 | D11: 45505 | E11: Sam.Pao | F11: Sam.Pao | G11: Yusky | H11: 0.1758 | I11: 34 | J11: 375.99 | P11: 375.99 | S11: 151.57391 | U11: 3.6683574 | X11: 155.24226 | Y11: 26.820907 | AB11: 26.820907 | AC11: 7.08 | AD11: 189.89202 | AE11: 345.13428 | AF11: 30.855718
A12: JOB080361 | B12: COLL004096 | C12: 240707000004 | D12: 45506 | E12: Sam.Pao | F12: Sam.Pao | G12: ShanShan | H12: 9.3447 | I12: 5042.5 | J12: 28642.1 | P12: 28642.1 | Q12: 116130.27 | R12: 华茂青松=56567 赛捷=2300 | S12: 8089.6243 | U12: 274.84412 | X12: 8364.4685 | Y12: 1390.435 | Z12: 88.5 | AA12: 12.567247 | AB12: 1491.5023 | AC12: 7.15 | AD12: 10664.241 | AE12: 19028.71 | AF12: 9613.3904
C13: 240719000020 | D13: 45506 | E13: Sam.Pao | F13: Sam.Pao | G13: Wendy | H13: 0.645 | I13: 148 | J13: 2922.21 | P13: 2922.21 | S13: 558.37081 | U13: 18.970588 | X13: 577.3414 | Y13: 95.972111 | Z13: 160.91 | AA13: 0.86743015 | AB13: 257.74954 | AC13: 7.15 | AD13: 1842.9092 | AE13: 2420.2506 | AF13: 501.95938
C14: 240801000001 | D14: 45506 | E14: Sam.Pao | F14: Sam.Pao | G14: SKY JET | H14: 32.88 | I14: 4188 | J14: 51584.98 | P14: 51584.98 | S14: 28463.926 | U14: 967.05882 | X14: 29430.985 | Y14: 4892.3458 | AA14: 44.218765 | AB14: 4936.5645 | AC14: 7.15 | AD14: 35296.436 | AE14: 64727.421 | AF14: -13142.441
C15: 240728000003 | D15: 45506 | E15: Sam.Pao | F15: Sam.Pao | G15: Nick Wang | H15: 0.2595 | I15: 100 | J15: 699 | P15: 699 | S15: 224.64686 | U15: 7.6323529 | X15: 232.27921 | Y15: 38.612035 | AA15: 0.34898934 | AB15: 38.961025 | AC15: 7.15 | AD15: 278.57133 | AE15: 510.85054 | AF15: 188.14946
C16: 240802000022 | D16: 45506 | E16: Sam.Pao | F16: Sam.Pao | G16: ShanShan | H16: 0.02 | I16: 5.5 | J16: 61.48 | P16: 61.48 | S16: 17.313824 | U16: 0.58823529 | X16: 17.902059 | Y16: 2.9758794 | AA16: 0.026897059 | AB16: 3.0027765 | AC16: 7.15 | AD16: 21.469852 | AE16: 39.371911 | AF16: 22.108089
C17: 240802000029 | D17: 45506 | E17: Sam.Pao | F17: Sam.Pao | G17: Yusky | H17: 1.5074 | I17: 207 | J17: 2677.5 | P17: 2677.5 | S17: 1304.9429 | U17: 44.335294 | X17: 1349.2782 | Y17: 224.29203 | AA17: 2.0272313 | AB17: 226.31926 | AC17: 7.15 | AD17: 1618.1827 | AE17: 2967.4609 | AF17: -289.9609
C18: 240806000035 | D18: 45511 | E18: Sam.Pao | F18: Sam.Pao | G18: SKY JET | H18: 34.38 | I18: 4304 | J18: 59321.31 | P18: 59321.31 | S18: 29087.629 | U18: 733.10294 | X18: 29820.732 | Y18: 5323.3385 | AA18: 104.39386 | AB18: 5427.7324 | AC18: 7.09 | AD18: 38482.623 | AE18: 68303.354 | AF18: -8982.0443
C19: 240728000003 | D19: 45506 | E19: Sam.Pao | F19: Sam.Pao | G19: Nick Wang | H19: 0.29 | I19: 135 | J19: 782 | P19: 782 | S19: 252.20298 | U19: 6.1838235 | X19: 258.3868 | Y19: 44.903088 | AA19: 1.1070324 | AB19: 46.010121 | AC19: 7.09 | AD19: 326.21175 | AE19: 584.59856 | AF19: 197.40144
C20: 240806000035 | D20: 45511 | E20: Sam.Pao | F20: Sam.Pao | G20: SKY JET | H20: 38.42 | I20: 4700 | J20: 66566.11 | P20: 66566.11 | S20: 33412.546 | U20: 819.25 | X20: 34231.796 | Y20: 5948.885 | AA20: 146.6627 | AB20: 6095.5477 | AC20: 7.09 | AD20: 43217.433 | AE20: 77449.229 | AF20: -10883.119
C21: 240803000005 | D21: 45512 | E21: Sam.Pao | F21: Sam.Pao | G21: Cherry | H21: 2.6248 | I21: 630 | J21: 6236.5 | P21: 6236.5 | S21: 2259.3448 | T21: 2.122614 | U21: 38.6 | X21: 2300.0675 | Y21: 402.791 | AB21: 402.791 | AC21: 7.12 | AD21: 2867.8719 | AE21: 5167.9394 | AF21: 1068.5606
C22: 240807000012 | D22: 45512 | E22: Sam.Pao | F22: Sam.Pao | G22: Yusky | H22: 3.79 | I22: 780 | J22: 7638.75 | P22: 7638.75 | S22: 3262.3122 | T22: 3.0648838 | U22: 55.735294 | X22: 3321.1123 | Y22: 581.59779 | AB22: 581.59779 | AC22: 7.12 | AD22: 4140.9763 | AE22: 7462.0886 | AF22: 176.66136
C23: 240808000010 | D23: 45512 | E23: Sam.Pao | F23: Sam.Pao | G23: SKY JET | H23: 9.8 | I23: 1059 | J23: 15645.79 | P23: 15645.79 | S23: 8435.5301 | T23: 7.9250294 | U23: 144.11765 | X23: 8587.5728 | Y23: 1503.8676 | AB23: 1503.8676 | AC23: 7.12 | AD23: 10707.538 | AE23: 19295.11 | AF23: -3649.3205
C24: 240728000003 | D24: 45506 | E24: Sam.Pao | F24: Sam.Pao | G24: Nick Wang | H24: 0.632 | I24: 166 | J24: 1705 | P24: 1705 | S24: 544.00562 | T24: 0.51108353 | U24: 9.2941176 | X24: 553.81082 | Y24: 96.984118 | AB24: 96.984118 | AC24: 7.12 | AD24: 690.52692 | AE24: 1244.3377 | AF24: 460.66226
C25: 240613000018 | D25: 45506 | E25: Sam.Pao | F25: Sam.Pao | G25: ChenGaoHong | H25: 1.6564 | I25: 313 | J25: 3117 | P25: 3117 | S25: 1425.7767 | T25: 1.3394917 | U25: 24.358824 | X25: 1451.4751 | Y25: 254.18432 | AB25: 254.18432 | AC25: 7.12 | AD25: 1809.7924 | AE25: 3261.2674 | AF25: -144.26745
C26: 240808000011 | D26: 45534 | E26: Sam.Pao | F26: Sam.Pao | G26: Yusky | H26: 0.6332 | I26: 114 | J26: 1276.22 | P26: 1276.22 | S26: 545.03854 | T26: 0.51205394 | U26: 9.3117647 | X26: 554.86236 | Y26: 97.168265 | AB26: 97.168265 | AC26: 7.12 | AD26: 691.83804 | AE26: 1246.7004 | AF26: 29.519597
C27: 240808000011 | D27: 45534 | E27: Sam.Pao | F27: Sam.Pao | G27: Yusky | H27: 1.8652 | I27: 420 | J27: 3624.06 | P27: 3624.06 | S27: 1578.4324 | U27: 57.601765 | X27: 1636.0341 | Y27: 285.73218 | AB27: 285.73218 | AC27: 7.07 | AD27: 2020.1265 | AE27: 3656.1607 | AF27: -32.100651
C28: 240728000003 | D28: 45506 | E28: Sam.Pao | F28: Sam.Pao | G28: Nick Wang | H28: 0.354 | I28: 131 | J28: 954 | P28: 954 | S28: 299.5738 | U28: 10.932353 | X28: 310.50615 | Y28: 54.229676 | AB28: 54.229676 | AC28: 7.07 | AD28: 383.40381 | AE28: 693.90997 | AF28: 260.09003
C29: 240809000022 | D29: 45534 | E29: Sam.Pao | F29: Sam.Pao | G29: Oladunni Eludire | H29: 8.119 | I29: 5120 | J29: 22858.98 | P29: 22858.98 | S29: 6870.7336 | U29: 250.73382 | W29: 1000 | X29: 8121.4674 | Y29: 1243.7592 | AB29: 1243.7592 | AC29: 7.07 | AD29: 8793.3773 | AE29: 16914.845 | AF29: 5944.1353
C30: 240813000001 | D30: 45534 | E30: Sam.Pao | F30: Sam.Pao | G30: SKY JET | H30: 33.04 | I30: 4133 | J30: 53646.12 | P30: 53646.12 | S30: 27960.221 | U30: 1020.3529 | X30: 28980.574 | Y30: 5061.4365 | AB30: 5061.4365 | AC30: 7.07 | AD30: 35784.356 | AE30: 64764.93 | AF30: -11118.81
C31: 240813000002 | D31: 45534 | E31: Sam.Pao | F31: Sam.Pao | G31: SKY JET | H31: 1.14 | I31: 155 | J31: 1853.23 | P31: 1853.23 | S31: 964.72919 | U31: 35.205882 | X31: 999.93507 | Y31: 174.63794 | AB31: 174.63794 | AC31: 7.07 | AD31: 1234.6902 | AE31: 2234.6253 | AF31: -381.39532
C32: 240812000053 | D32: 45534 | E32: Sam.Pao | F32: Sam.Pao | G32: Yusky | H32: 1.748 | I32: 203 | J32: 3548.44 | P32: 3548.44 | S32: 1472.0538 | U32: 35.988235 | X32: 1508.042 | Y32: 265.49035 | AA32: 7.1236141 | AB32: 272.61397 | AC32: 7.06 | AD32: 1924.6546 | AE32: 3432.6966 | AF32: 115.74338
C33: 240812000054 | D33: 45534 | E33: Sam.Pao | F33: Sam.Pao | G33: Yusky | H33: 0.2239 | I33: 43 | J33: 454.5 | P33: 454.5 | S33: 188.55426 | U33: 4.6097059 | X33: 193.16396 | Y33: 34.006459 | AA33: 0.91245835 | AB33: 34.918917 | AC33: 7.06 | AD33: 246.52756 | AE33: 439.69152 | AF33: 14.808482
C34: 240812000055 | D34: 45534 | E34: Sam.Pao | F34: Sam.Pao | G34: Yusky | H34: 0.1922 | I34: 29 | J34: 390.2 | P34: 390.2 | S34: 161.85854 | U34: 3.9570588 | X34: 165.8156 | Y34: 29.191788 | AA34: 0.78327153 | AB34: 29.97506 | AC34: 7.06 | AD34: 211.62392 | AE34: 377.43953 | AF34: 12.760474
C35: 240812000056 | D35: 45534 | E35: Sam.Pao | F35: Sam.Pao | G35: Yusky | H35: 0.1689 | I35: 34 | J35: 342.85 | P35: 342.85 | S35: 142.23678 | U35: 3.4773529 | X35: 145.71413 | Y35: 25.652929 | AA35: 0.68831718 | AB35: 26.341247 | AC35: 7.06 | AD35: 185.9692 | AE35: 331.68333 | AF35: 11.166671
C36: 240813000001 | D36: 45534 | E36: Sam.Pao | F36: Sam.Pao | G36: SKY JET | H36: 1.98 | I36: 736 | J36: 3388.18 | P36: 3388.18 | S36: 1667.4293 | U36: 40.764706 | X36: 1708.194 | Y36: 300.72706 | AA36: 8.0690824 | AB36: 308.79614 | AC36: 7.06 | AD36: 2180.1008 | AE36: 3888.2948 | AF36: -500.1148
C37: 240613000018 | D37: 45506 | E37: Sam.Pao | F37: Sam.Pao | G37: ChenGaoHong | H37: 1.087 | I37: 234 | J37: 2370 | P37: 2370 | S37: 915.40186 | U37: 22.379412 | X37: 937.78128 | Y37: 165.09612 | AA37: 4.4298447 | AB37: 169.52596 | AC37: 7.06 | AD37: 1196.8533 | AE37: 2134.6346 | AF37: 235.36543
C38: 240813000002 | D38: 45534 | E38: Sam.Pao | F38: Sam.Pao | G38: SKY JET | H38: 32.97 | I38: 3574 | J38: 56418.26 | P38: 56418.26 | S38: 27765.225 | U38: 678.79412 | X38: 28444.019 | Y38: 5007.5612 | AA38: 134.36245 | AB38: 5141.9236 | AC38: 7.06 | AD38: 36301.981 | AE38: 64746 | AF38: -8327.7398
A39: JOB080371 | B39: COLL004105整柜 | C39: 240812000027 | D39: 45498 | E39: Sam.Pao | F39: Sam.Pao | G39: JunYue hotel | H39: 68 | I39: 21890 | J39: 68172 | K39: 21300000 | M39: 1694.5579 | N39: 12569.65 | O39: 7.15 | P39: 158045 | Q39: 158045 | R39: 华茂青松 | S39: 61677 | X39: 61677 | Y39: 0 | AB39: 0 | AC39: 7.15 | AD39: 0 | AE39: 61677 | AF39: 96367.997
C40: 240613000018 | D40: 45506 | E40: Sam.Pao | F40: Sam.Pao | G40: ChenGaoHong | H40: 0.044 | I40: 28 | J40: 96 | P40: 96 | S40: 34.461706 | U40: 0.84117647 | X40: 35.302882 | Y40: 6.9477682 | AB40: 6.9477682 | AC40: 7.06 | AD40: 49.051244 | AE40: 84.354126 | AF40: 11.645874
C41: 240728000003 | D41: 45506 | E41: Sam.Pao | F41: Sam.Pao | G41: Nick Wang | H41: 0.236 | I41: 94 | J41: 636 | P41: 636 | S41: 184.84006 | U41: 4.5117647 | X41: 189.35182 | Y41: 37.265302 | AB41: 37.265302 | AC41: 7.06 | AD41: 263.09303 | AE41: 452.44486 | AF41: 183.55514
...

Sheet 提成总表
A1: 24年8月份业务员提成总表-68³
A3: 名称 姓名 | B3: LOS毛利 | C3: 计费体积 立方 | D3: 6千-3.5万 | I3: 3.5万以上 | M3: 合计 提成金额 | N3: 备注
D4: 基数 | E4: 提成计数 | F4: 提成计数 | G4: 提成点 数40% | H4: 提成金额 | I4: 基数 | J4: 提成计数 | K4: 提成点 数50% | L4: 提成金额
A5: 黄 颖 | B5: =SUM(黄颖!M33) -> 51035.445 | C5: =SUM(黄颖!L33) -> 106.0053 | D5: 6000 | E5: =SUM(B5-D5) -> 45035.445 | F5: 35000 | G5: 0.4 | H5: =SUM(F5*G5) -> 14000 | I5: 35000 | J5: =SUM(E5-I5) -> 10035.445 | K5: 0.5 | L5: =SUM(J5*K5) -> 5017.7223 | M5: =SUM(H5+L5) -> 19017.722
A6: 陈三凤 | B6: =SUM(三凤!M18) -> 15800.314 | C6: =SUM(三凤!L18) -> 26.0705 | D6: 2000 | E6: =SUM(B6-D6) -> 13800.314 | G6: 0.15 | H6: =SUM(E6*G6) -> 2070.0471 | M6: =SUM(H6+L6) -> 2070.0471 | N6: 小飞8-9月份原方案10% （zhong zi xin利润的一半2529.79）
A7: 吕沛霖 | B7: =SUM(吕沛霖!M27) -> 16852.52 | C7: =SUM(吕沛霖!L27) -> 86.6326 | D7: 8595.8056 | E7: =SUM(B7-D7) -> 8256.7149 | G7: 0.4 | H7: =SUM(E7*G7) -> 3302.686 | M7: =SUM(H7+L7) -> 3302.686
A8: 朱小飞 | B8: =SUM(朱小飞!M27) -> 28356.306 | C8: =SUM(朱小飞!L27) -> 47.9186 | D8: 2000 | E8: =SUM(B8-D8) -> 26356.306 | G8: 0.15 | H8: =SUM(E8*G8) -> 3953.4459 | M8: =SUM(H8+L8) -> 3953.4459 | N8: 小飞8-9月份原方案10% （Halifa利润的一半501.13）
A9: 陆总 | B9: =SUM(陆总!M15) -> 23045.762 | C9: =SUM(陆总!L15) -> 47.6491 | G9: 0.4 | H9: =SUM(B9*G9) -> 9218.3049 | M9: =SUM(H9+L9) -> 9218.3049
A10: 罗伟健 | B10: =SUM(罗伟健!M13) -> 41043.529 | C10: =SUM(罗伟健!L13) -> 25.2555 | M10: 5119.95 | N10: 空运毛利8089.45加海运=49132.98， 49132.98-15000=34132.98*0.15 =￥5119.95
A11: 罗珮文 | B11: =SUM(罗珮文!M20) -> -191.26164 | C11: =SUM(罗珮文!M20) -> -191.26164
A12: 浦海森 | B12: =SUM(浦生!M52) -> 49238.914 | C12: =SUM(浦生!L52) -> 390.4147 | D12: 6000 | E12: =SUM(B12-D12) -> 43238.914 | F12: 35000 | G12: 0.4 | H12: =SUM(F12*G12) -> 14000 | I12: 35000 | J12: =SUM(E12-I12) -> 8238.9136 | K12: 0.5 | L12: =SUM(J12*K12) -> 4119.4568 | M12: =SUM(H12+L12) -> 18119.457
A13: 合计 | B13: =SUM(B5:B12) -> 225181.53 | C13: =SUM(C5:C12) -> 538.68466 | M13: =SUM(M5:M12) -> 60801.613
A15: 确认人： | J15: 日期：

Sheet 黄颖 陈三凤 朱小飞 吕沛霖 2025年10月份发放
A1: 24年8月份业务员提成总表-68³
A3: 名称 姓名 | B3: LOS毛利 | C3: 计费体积 立方 | D3: 6千-3.5万 | I3: 3.5万以上 | M3: 合计 提成金额 | N3: 备注
D4: 基数 | E4: 提成计数 | F4: 提成计数 | G4: 提成点 数40% | H4: 提成金额 | I4: 基数 | J4: 提成计数 | K4: 提成点 数50% | L4: 提成金额
A5: 黄 颖 | B5: =SUM(黄颖!M33) -> 51035.445 | C5: =SUM(黄颖!L33) -> 106.0053 | D5: 6000 | E5: =SUM(B5-D5) -> 45035.445 | F5: 35000 | G5: 0.4 | H5: =SUM(F5*G5) -> 14000 | I5: 35000 | J5: =SUM(E5-I5) -> 10035.445 | K5: 0.5 | L5: =SUM(J5*K5) -> 5017.7223 | M5: =SUM(H5+L5) -> 19017.722
L6: 领款人：
A7: 陈三凤 | B7: =SUM(三凤!M18) -> 15800.314 | C7: =SUM(三凤!L18) -> 26.0705 | D7: 2000 | E7: =SUM(B7-D7) -> 13800.314 | G7: 0.15 | H7: =SUM(E7*G7) -> 2070.0471 | M7: =SUM(H7+L7) -> 2070.0471 | N7: 小飞8-9月份原方案10% （zhong zi xin利润的一半2529.79）
L8: 领款人：
A9: 朱小飞 | B9: =SUM(朱小飞!M27) -> 28356.306 | C9: =SUM(朱小飞!L27) -> 47.9186 | D9: 2000 | E9: =SUM(B9-D9) -> 26356.306 | G9: 0.15 | H9: =SUM(E9*G9) -> 3953.4459 | M9: =SUM(H9+L9) -> 3953.4459 | N9: 小飞8-9月份原方案10% （Halifa利润的一半501.13）
L10: 领款人：
A11: 吕沛霖 | B11: =SUM(吕沛霖!M27) -> 16852.52 | C11: =SUM(吕沛霖!L27) -> 86.6326 | D11: 8595.8056 | E11: =SUM(B11-D11) -> 8256.7149 | G11: 0.4 | H11: =SUM(E11*G11) -> 3302.686 | M11: =SUM(H11+L11) -> 3302.686
L12: 领款人：
A13: 合计 | B13: =SUM(B5:B9) -> 95192.064 | C13: =SUM(C5:C9) -> 179.9944 | M13: =SUM(M5:M12) -> 28343.901
A15: 确认人： | J15: 日期：
