Workbook

Sheet 黄颖
A1: LOS毛利表
A3: JOB | B3: 集装编号 | C3: 运单编号 | D3: 日期 | E3: 业务 | F3: 发货人 | G3: 收货人 | H3: 计费体积 | I3: 计费重量 | J3: 应 收 | Q3: 总应收 | R3: 起 运 港 成 本 | W3: 代垫运费 | X3: 起运港成本 合计 | Y3: 目的港成本 | AE3: 总支出 | AF3: 利润
J4: 应收RMB | K4: LOS Income(NGN)收到(奈拉) | L4: LOS 收到USD | M4: 美元汇率 dollar currency rate | N4: 应收 到付款USD | O4: 汇率 | P4: 人民币 | R4: 代理商 | S4: 运费+出口报关费 | T4: 提货费 | U4: 装卸费 | V4: 包装费 | Y4: 进口报关费 | Z4: 到门配送费 | AA4: 转运费 | AB4: 目的港支出 | AC4: 汇率 | AD4: 人民币 | AE4: 起运港+目的港
C5: 241023000029 | D5: 45601 | E5: 黄颖 | F5: ying | G5: Wole Rasak | H5: 0.0288 | I5: 5 | J5: 224.75 | P5: 224.75 | S5: 20.843788 | T5: 0.048129882 | U5: 1.0164706 | X5: 21.908389 | Y5: 4.6375285 | AB5: 4.6375285 | AC5: 7.33 | AD5: 33.993084 | AE5: 55.901472 | AF5: 168.84853
C6: 241031000033 | D6: 45601 | E6: 黄颖 | F6: ying | G6: Bruce | H6: 1.9968 | I6: 845 | K6: 960734 | M6: 1653.0179 | N6: 581.2 | O6: 7.29 | P6: 4236.948 | S6: 1445.1693 | T6: 3.3370052 | U6: 70.475294 | X6: 1518.9816 | Y6: 321.53531 | AB6: 321.53531 | AC6: 7.33 | AD6: 2356.8538 | AE6: 3875.8354 | AF6: 361.11258
C7: 241028000022 | D7: 45601 | E7: 黄颖 | F7: ying | G7: Barrister Hammed | H7: 1.211 | I7: 331 | J7: 2690 | P7: 2690 | S7: 876.45235 | T7: 2.0237947 | U7: 42.741176 | X7: 921.21732 | Y7: 195.00163 | AB7: 195.00163 | AC7: 7.33 | AD7: 1429.362 | AE7: 2350.5793 | AF7: 339.42073
C8: 241029000017 | D8: 45601 | E8: 黄颖 | F8: ying | G8: jiangnan | H8: 0.2948 | I8: 65 | J8: 683.5 | P8: 683.5 | S8: 213.35933 | T8: 0.49266282 | U8: 10.404706 | X8: 224.2567 | Y8: 47.470257 | AB8: 47.470257 | AC8: 7.33 | AD8: 347.95698 | AE8: 572.21368 | AF8: 111.28632
C9: 241030000039 | D9: 45601 | E9: 黄颖 | F9: ying | G9: jiangnan | H9: 1.069 | I9: 138 | J9: 2506 | P9: 2506 | S9: 773.68089 | T9: 1.7864876 | U9: 37.729412 | X9: 813.19679 | Y9: 172.13604 | AB9: 172.13604 | AC9: 7.33 | AD9: 1261.7572 | AE9: 2074.954 | AF9: 431.04604
C10: 241029000048 | D10: 45602 | E10: 黄颖 | F10: ying | G10: Sunday Adelena | H10: 0.4438 | I10: 310 | J10: 964.05 | P10: 964.05 | S10: 318.41671 | U10: 11.747647 | X10: 330.16436 | Y10: 69.940661 | AA10: 0.33050047 | AB10: 70.271161 | AC10: 7.33 | AD10: 515.08761 | AE10: 845.25197 | AF10: 118.79803
C11: 241030000025 | D11: 45602 | E11: 黄颖 | F11: ying | G11: Nura | H11: 0.4092 | I11: 180 | J11: 876.05 | P11: 876.05 | S11: 293.59197 | U11: 10.831765 | X11: 304.42374 | Y11: 64.487874 | AA11: 0.30473365 | AB11: 64.792608 | AC11: 7.33 | AD11: 474.92981 | AE11: 779.35355 | AF11: 96.696448
C12: 241031000033 | D12: 45602 | E12: 黄颖 | F12: ying | G12: Bruce | H12: 0.5837 | I12: 247 | K12: 280840 | M12: 1652.9723 | N12: 169.9 | O12: 7.29 | P12: 1238.571 | S12: 418.79187 | U12: 15.450882 | X12: 434.24276 | Y12: 91.988202 | AA12: 0.43468482 | AB12: 92.422886 | AC12: 7.33 | AD12: 677.45976 | AE12: 1111.7025 | AF12: 126.86849
C13: 241104000038 | D13: 45602 | E13: 黄颖 | F13: ying | G13: Sunday Adelena | H13: 0.0737 | I13: 26 | J13: 214.23 | P13: 214.23 | S13: 52.878124 | U13: 1.9508824 | X13: 54.829007 | Y13: 11.614752 | AA13: 0.054884824 | AB13: 11.669636 | AC13: 7.33 | AD13: 85.538434 | AE13: 140.36744 | AF13: 73.862559
A14: JOB120363 | B14: COLL004291 | C14: 240930000009 | D14: 45608 | E14: 黄颖 | F14: ying | G14: Tom chen | H14: 0.0977 | I14: 28.5 | K14: 132820 | M14: 1648.9137 | N14: 80.55 | O14: 7.3 | P14: 588.015 | Q14: 44400.027 | R14: 登凯=43330 陆总=8000 拖车费=1670 杂费=93 过磅费=125 | S14: 76.461744 | U14: 2.808875 | X14: 79.270619 | Y14: 16.322854 | Z14: 11.38 | AA14: 0.076924382 | AB14: 27.779778 | AC14: 7.3 | AD14: 202.79238 | AE14: 282.063 | AF14: 305.952
C15: 241105000025 | D15: 45608 | E15: 黄颖 | F15: ying | G15: Oba Adeoriyomi Oyebo | H15: 3.7323 | I15: 536 | K15: 1998941 | M15: 1712.4484 | N15: 1167.3 | O15: 7.3 | P15: 8521.29 | S15: 2920.9638 | U15: 107.30362 | W15: 350 | X15: 3378.2675 | Y15: 623.55975 | AA15: 2.9386374 | AB15: 626.49839 | AC15: 7.3 | AD15: 4573.4382 | AE15: 7951.7057 | AF15: 569.58429
C16: 241106000020 | D16: 45608 | E16: 黄颖 | F16: ying | G16: yuhuichao | H16: 0.3 | I16: 65 | J16: 908 | P16: 908 | S16: 234.78529 | U16: 8.625 | X16: 243.41029 | Y16: 50.121353 | Z16: 34.85 | AA16: 0.23620588 | AB16: 85.207559 | AC16: 7.3 | AD16: 622.01518 | AE16: 865.42547 | AF16: 42.574526
C17: 241106000034 | D17: 45608 | E17: 黄颖 | F17: ying | G17: Mr.zhang | H17: 0.3814 | I17: 55 | J17: 1213 | P17: 1213 | S17: 298.49037 | U17: 10.96525 | X17: 309.45562 | Y17: 63.720947 | Z17: 44.32 | AA17: 0.30029641 | AB17: 108.34124 | AC17: 7.3 | AD17: 790.89107 | AE17: 1100.3467 | AF17: 112.6533
C18: 241106000049 | D18: 45608 | E18: 黄颖 | F18: ying | G18: wuchengxing | H18: 0.0224 | I18: 5.5 | J18: 228 | P18: 228 | S18: 17.530635 | U18: 0.644 | X18: 18.174635 | Y18: 3.7423944 | AA18: 0.017636706 | AB18: 3.7600311 | AC18: 7.3 | AD18: 27.448227 | AE18: 45.622862 | AF18: 182.37714
A19: JOB120364 | B19: COLL004298 | C19: 241030000025 | D19: 45609 | E19: 黄颖 | F19: ying | G19: Nura | H19: 0.0306 | I19: 10 | J19: 65 | P19: 65 | Q19: 36440.483 | R19: 登凯=43330 赛捷=1660 拖车费=1670 杂费=73 过磅费=70 | S19: 21.06135 | U19: 0.81 | X19: 21.87135 | Y19: 4.8572415 | AA19: 0.042741 | AB19: 4.8999825 | AC19: 7.33 | AD19: 35.916872 | AE19: 57.788222 | AF19: 7.2117783
C20: 241102000008 | D20: 45609 | E20: 黄颖 | F20: ying | G20: Bruce | H20: 2.0582 | I20: 755 | K20: 957151 | M20: 1603.5903 | N20: 596.88 | O20: 7.3 | P20: 4357.224 | S20: 1416.6167 | U20: 54.481765 | X20: 1471.0984 | Y20: 326.70505 | AA20: 2.8748211 | AB20: 329.57987 | AC20: 7.33 | AD20: 2415.8204 | AE20: 3886.9189 | AF20: 470.30511
C21: 241107000009 | D21: 45609 | E21: 黄颖 | F21: ying | G21: MISS Huang | H21: 1.6128 | I21: 1251 | J21: 3794.79 | P21: 3794.79 | S21: 1110.057 | U21: 42.691765 | X21: 1152.7488 | Y21: 256.0052 | AA21: 2.2527021 | AB21: 258.2579 | AC21: 7.33 | AD21: 1893.0304 | AE21: 3045.7792 | AF21: 749.01078
A22: JOB120365 | B22: COLL004301 | C22: 241030000050 | D22: 45615 | E22: 黄颖 | F22: ying | G22: Sunday Adelena | H22: 20.9121 | I22: 2224 | J22: 44817.94 | P22: 44817.94 | Q22: 116746.04 | R22: 登凯=43386.5 陆总=1800 拖车费=1670 杂费=661 过磅费=71 | S22: 14634.933 | U22: 707.32103 | X22: 15342.254 | Y22: 3408.9798 | AA22: 23.10172 | AB22: 3432.0816 | AC22: 7.3 | AD22: 25054.195 | AE22: 40396.45 | AF22: 4421.4903
C23: 241102000012 | D23: 45615 | E23: 黄颖 | F23: ying | G23: Bruce | H23: 2.1458 | I23: 808 | K23: 1041860 | M23: 1674.262 | N23: 622.28015 | O23: 7.27 | P23: 4523.9767 | S23: 1501.6971 | U23: 72.578529 | X23: 1574.2756 | Y23: 349.79696 | AA23: 2.3704779 | AB23: 352.16743 | AC23: 7.3 | AD23: 2570.8223 | AE23: 4145.0979 | AF23: 378.87879
C24: 241102000009 | D24: 45615 | E24: 黄颖 | F24: ying | G24: Bruce | H24: 1.3109 | I24: 450 | K24: 638809 | M24: 1680.413 | N24: 380.15 | O24: 7.27 | P24: 2763.6905 | S24: 917.4083 | U24: 44.339265 | X24: 961.74757 | Y24: 213.69598 | AA24: 1.4481589 | AB24: 215.14414 | AC24: 7.3 | AD24: 1570.5522 | AE24: 2532.2998 | AF24: 231.39073
C25: 241107000048 | D25: 45615 | E25: 黄颖 | F25: ying | G25: Nura | H25: 1.9284 | I25: 1039 | J25: 4628 | P25: 4628 | S25: 1349.5539 | U25: 65.225294 | X25: 1414.7792 | Y25: 314.35756 | AA25: 2.1303148 | AB25: 316.48787 | AC25: 7.3 | AD25: 2310.3615 | AE25: 3725.1406 | AF25: 902.85935
C26: 241107000009 | D26: 45615 | E26: 黄颖 | F26: ying | G26: MISS Huang | H26: 18.3103 | I26: 10792 | J26: 43083.21 | P26: 43083.21 | S26: 12814.113 | U26: 619.31897 | X26: 13433.432 | Y26: 2984.8482 | AA26: 20.227496 | AB26: 3005.0757 | AC26: 7.3 | AD26: 21937.052 | AE26: 35370.485 | AF26: 7712.7253
C27: 241116000004 | D27: 45615 | E27: 黄颖 | F27: ying | G27: wangmuma | H27: 0.9249 | I27: 172 | J27: 3030 | P27: 3030 | S27: 647.27358 | U27: 31.283382 | X27: 678.55697 | Y27: 150.7723 | AA27: 1.0217425 | AB27: 151.79404 | AC27: 7.3 | AD27: 1108.0965 | AE27: 1786.6535 | AF27: 1243.3465
C28: 241113000042 | D28: 45615 | E28: 黄颖 | F28: ying | G28: Nura | H28: 0.3419 | I28: 190 | J28: 748.5 | P28: 748.5 | S28: 239.27218 | U28: 11.564265 | X28: 250.83644 | Y28: 55.734728 | AA28: 0.37769894 | AB28: 56.112427 | AC28: 7.3 | AD28: 409.62072 | AE28: 660.45716 | AF28: 88.04284
C29: 241114000023 | D29: 45615 | E29: 黄颖 | F29: ying | G29: Hao wangjun | H29: 3.1076 | I29: 643 | J29: 6811 | P29: 6811 | S29: 2174.7944 | U29: 105.11 | X29: 2279.9044 | Y29: 506.5845 | AA29: 3.432984 | AB29: 510.01748 | AC29: 7.3 | AD29: 3723.1276 | AE29: 6003.0321 | AF29: 807.96792
A30: JOB120366 | B30: COLL004305 | C30: 241102000009 | D30: 45616 | E30: 黄颖 | F30: ying | G30: Bruce | H30: 0.3399 | I30: 118 | K30: 165636 | M30: 1680.2191 | N30: 98.58 | O30: 7.27 | P30: 716.6766 | Q30: 67588.267 | R30: 登凯=43386.5 赛捷=500 拖车费=1670 杂费=61 过磅费=68 | S30: 228.36032 | U30: 9.9970588 | X30: 238.35737 | Y30: 55.408699 | AA30: 0.38678621 | AB30: 55.795485 | AC30: 7.3 | AD30: 407.30704 | AE30: 645.66441 | AF30: 71.012187
C31: 241107000009 | D31: 45616 | E31: 黄颖 | F31: ying | G31: MISS Huang | H31: 6.8102 | I31: 4442 | J31: 16020.41 | P31: 16020.41 | S31: 4575.4028 | U31: 200.3 | X31: 4775.7028 | Y31: 1110.1627 | AA31: 7.749607 | AB31: 1117.9124 | AC31: 7.3 | AD31: 8160.7602 | AE31: 12936.463 | AF31: 3083.947
C32: 241106000050 | D32: 45616 | E32: 黄颖 | F32: ying | G32: Sunday Adelena | H32: 0.6913 | I32: 774 | J32: 3860.58 | P32: 3860.58 | S32: 464.44686 | U32: 20.332353 | V32: 150 | X32: 634.77921 | Y32: 112.69207 | AA32: 0.78665874 | AB32: 113.47872 | AC32: 7.3 | AD32: 828.39469 | AE32: 1463.1739 | AF32: 2397.4061
C33: 241106000051 | D33: 45616 | E33: 黄颖 | F33: ying | G33: Sunday Adelena | H33: 0.4698 | I33: 547 | J33: 1670.3 | P33: 1670.3 | S33: 315.63306 | U33: 13.817647 | X33: 329.4507 | Y33: 76.584309 | AA33: 0.53460476 | AB33: 77.118914 | AC33: 7.3 | AD33: 562.96807 | AE33: 892.41877 | AF33: 777.88123
C34: 241115000042 | D34: 45616 | E34: 黄颖 | F34: ying | G34: MISS Huang | H34: 2.5805 | I34: 1066 | K34: 1255187.8 | M34: 1706.7169 | N34: 735.43994 | O34: 7.27 | P34: 5346.6484 | S34: 1733.6975 | U34: 75.897059 | X34: 1809.5946 | Y34: 420.65945 | AA34: 2.9364572 | AB34: 423.59591 | AC34: 7.3 | AD34: 3092.2501 | AE34: 4901.8447 | AF34: 444.80365
C35: 241118000051 | D35: 45616 | E35: 黄颖 | F35: ying | G35: wuchengxing | H35: 0.2898 | I35: 30 | J35: 639.5 | P35: 639.5 | S35: 194.70085 | U35: 8.5235294 | X35: 203.22438 | Y35: 47.241662 | AA35: 0.32977535 | AB35: 47.571437 | AC35: 7.3 | AD35: 347.27149 | AE35: 550.49587 | AF35: 89.004128
A36: JOB120367 | B36: COLL004308 | C36: 241107000009 | D36: 45617 | E36: 黄颖 | F36: ying | G36: MISS Huang | H36: 3.597 | I36: 2893 | J36: 8527.49 | P36: 8527.49 | Q36: 43425.829 | R36: 登凯=43386.5 赛捷=600 拖车费=1670 杂费=75 过磅费=57 | S36: 2422.077 | U36: 68.766176 | X36: 2490.8432 | Y36: 594.19266 | AA36: 11.105738 | AB36: 605.2984 | AC36: 7.3 | AD36: 4418.6783 | AE36: 6909.5215 | AF36: 1617.9685
C37: 241108000020 | D37: 45617 | E37: 黄颖 | F37: ying | G37: shola | H37: 4.4226 | I37: 1416 | J37: 13696 | P37: 13696 | S37: 2978.0032 | U37: 84.549706 | V37: 800 | W37: 80 | X37: 3942.5529 | Y37: 730.5745 | Z37: 256.98 | AA37: 13.654777 | AB37: 1001.2093 | AC37: 7.3 | AD37: 7308.8277 | AE37: 11251.381 | AF37: 2444.6194
A38: JOB120368 | B38: COLL004310 | C38: 241116000004 | D38: 45623 | E38: 黄颖 | F38: ying | G38: wangmuma | H38: 0.076 | I38: 13 | J38: 250 | P38: 250 | Q38: 21398.955 | R38: 登凯=43941.65 创泽=1300 拖车费=1670 杂费=63 过磅费=59 | S38: 52.567021 | U38: 2.1235294 | X38: 54.69055 | Y38: 12.384647 | Z38: 59.52 | AA38: 0.059872353 | AB38: 71.964519 | AC38: 7.3 | AD38: 525.34099 | AE38: 580.03154 | AF38: -330.03154
C39: 241119000027 | D39: 45623 | E39: 黄颖 | F39: ying | G39: wuchengxing | H39: 0.0148 | I39: 6 | J39: 220 | P39: 220 | S39: 10.236736 | U39: 0.41352941 | X39: 10.650265 | Y39: 2.4117471 | AA39: 0.011659353 | AB39: 2.4234064 | AC39: 7.3 | AD39: 17.690867 | AE39: 28.341132 | AF39: 191.65887
A40: 合 计 | H40: =SUM(H5:H39) -> 82.62 | AF40: =SUM(AF5:AF39) -> 30842.58
C42: 基本任务：小于6千 | F42: 不够基本任务6千， 公司将根据空运提成里抽出补足基数 | K42: 黄颖 提成
...

Sheet 三凤
A1: LOS毛利表
A2: JOB | B2: 集装编号 | C2: 运单编号 | D2: 日期 | E2: 业务 | F2: 发货人 | G2: 收货人 | H2: 计费体积 | I2: 计费重量 | J2: 应 收 | Q2: 总应收 | R2: 起 运 港 成 本 | W2: 代垫运费 | X2: 起运港成本 合计 | Y2: 目的港成本 | AE2: 总支出 | AF2: 利润
J3: 应收RMB | K3: LOS Income(NGN)收到(奈拉) | L3: LOS 收到USD | M3: 美元汇率 dollar currency rate | N3: 应收 到付款USD | O3: 汇率 | P3: 人民币 | R3: 代理商 | S3: 运费+出口报关费 | T3: 提货费 | U3: 装卸费 | V3: 包装费 | Y3: 进口报关费 | Z3: 到门配送费 | AA3: 转运费 | AB3: 目的港支出 | AC3: 汇率 | AD3: 人民币 | AE3: 起运港+目的港
C4: 241022000035 | D4: 45602 | E4: Bella | F4: Bella Chan | G4: zhong zi xin | H4: 27.424 | I4: 19896 | J4: 60720 | P4: 60720 | S4: 19676.115 | U4: 725.92941 | X4: 20402.044 | Y4: 4321.8853 | AA4: 20.422814 | AB4: 4342.3081 | AC4: 7.33 | AD4: 31829.118 | AE4: 52231.163 | AF4: 8488.8372
C5: 241022000035 | D5: 45608 | E5: Bella | F5: Bella Chan | G5: zhong zi xin | H5: 28.3553 | I5: 15100 | J5: 62780 | P5: 62780 | S5: 22191.358 | U5: 815.21488 | V5: 300 | X5: 23306.573 | Y5: 4737.3533 | Z5: 785.15 | AA5: 22.325629 | AB5: 5544.829 | AC5: 7.3 | AD5: 40477.251 | AE5: 63783.824 | AF5: -1003.8244 | AG5: =SUM(AF4:AF5) -> 7485.0128
C6: 241106000018 | D6: 45602 | E6: Bella | F6: Bella Chan | G6: zhang long ting | H6: 0.0019 | I6: 1 | K6: 51150 | M6: 1650 | N6: 31 | O6: 7.2 | P6: 223.2 | S6: 1.3632081 | U6: 0.050294118 | X6: 1.4135022 | Y6: 0.2994305 | AA6: 0.0014149412 | AB6: 0.30084544 | AC6: 7.33 | AD6: 2.2051971 | AE6: 3.6186993 | AF6: 219.5813 | AG6: =SUM(AG5/2) -> 3742.5064
C7: 241104000071 | D7: 45608 | E7: Bella | F7: Bella Chan | G7: FENG | H7: 0.2523 | I7: 27 | K7: 116127 | M7: 1684.4648 | N7: 68.94 | O7: 7.3 | P7: 503.262 | S7: 197.45443 | U7: 7.253625 | X7: 204.70806 | Y7: 42.152058 | AA7: 0.19864915 | AB7: 42.350707 | AC7: 7.3 | AD7: 309.16016 | AE7: 513.86822 | AF7: -10.606218
C8: 241108000043 | D8: 45609 | E8: Bella | F8: Bella Chan | G8: weng zixian | H8: 1.4833 | I8: 598 | K8: 1160958 | M8: 1666.4389 | N8: 696.67 | O8: 7.3 | P8: 5085.691 | S8: 1020.9249 | U8: 39.263824 | X8: 1060.1887 | Y8: 235.44923 | Z8: 251.65 | AA8: 2.0718211 | AB8: 489.17105 | AC8: 7.33 | AD8: 3585.6238 | AE8: 4645.8125 | AF8: 439.87855
C9: 241111000032 | D9: 45609 | E9: Bella | F9: Bella Chan | G9: FENG | H9: 0.2174 | I9: 57 | K9: 107613 | M9: 1650.0003 | N9: 65.21999 | O9: 7.2 | P9: 469.58393 | S9: 149.63194 | U9: 5.7547059 | X9: 155.38665 | Y9: 34.508637 | AA9: 0.30365665 | AB9: 34.812294 | AC9: 7.33 | AD9: 255.17411 | AE9: 410.56076 | AF9: 59.023163
C10: 241114000046 | D10: 45615 | E10: Bella | F10: Bella Chan | G10: new hope 边鹏飞 | H10: 0.0703 | I10: 43 | K10: 47100 | M10: 2230.1133 | N10: 21.120003 | O10: 7.28 | P10: 153.75362 | S10: 49.198111 | U10: 2.3777941 | X10: 51.575905 | Y10: 11.459934 | AA10: 0.077660824 | AB10: 11.537595 | AC10: 7.3 | AD10: 84.224441 | AE10: 135.80035 | AF10: 17.953276
C11: 241125000029 | D11: 45623 | E11: Bella | F11: Bella Chan | G11: FENG | H11: 0.2641 | I11: 318 | K11: 228967.2 | M11: 1680.0002 | N11: 136.28998 | O11: 7.3 | P11: 994.91685 | S11: 182.6704 | U11: 7.3792647 | X11: 190.04966 | Y11: 43.036649 | AA11: 0.20805643 | AB11: 43.244705 | AC11: 7.3 | AD11: 315.68635 | AE11: 505.73601 | AF11: 489.18085
A12: 合 计 | H12: =SUM(H4:H11) -> 58.0686 | AF12: =SUM(AF4:AF11) -> 8700.0237
AF13: 3742.51
C14: 基本任务：小于6千 | F14: 不够基本任务6千， 公司将根据空运提成里抽出补足基数 | K14: 三凤 提成 | AF14: =SUM(AF12-AF13) -> 4957.5137
K15: 名称 | L15: 计费体积 | M15: 毛利 | N15: 备注
C16: 基本任务：6千-3.5万 | F16: 按40%提成 | K16: LOS | L16: =SUM(H12) -> 58.0686 | M16: 4957.5137 | N16: 总利润减zhong zi xin 利润的 一半3742.51
K17: 基数 | M17: 3000
C18: 基本任务：3.5万以上 | F18: 按50%提成 | K18: 提成计数 | M18: =SUM(M16-M17) -> 1957.5137
K19: 提成点数 | M19: 0.15
K20: 提成金额 | M20: =SUM(M18*M19) -> 293.62705

Sheet 朱小飞
A1: LOS毛利表
A3: JOB | B3: 集装编号 | C3: 运单编号 | D3: 日期 | E3: 业务 | F3: 发货人 | G3: 收货人 | H3: 计费体积 | I3: 计费重量 | J3: 应 收 | Q3: 总应收 | R3: 起 运 港 成 本 | W3: 代垫运费 | X3: 起运港成本 合计 | Y3: 目的港成本 | AE3: 总支出 | AF3: 利润
J4: 应收RMB | K4: LOS Income(NGN)收到(奈拉) | L4: LOS 收到USD | M4: 美元汇率 dollar currency rate | N4: 应收 到付款USD | O4: 汇率 | P4: 人民币 | R4: 代理商 | S4: 运费+出口报关费 | T4: 提货费 | U4: 装卸费 | V4: 包装费 | Y4: 进口报关费 | Z4: 到门配送费 | AA4: 转运费 | AB4: 目的港支出 | AC4: 汇率 | AD4: 人民币 | AE4: 起运港+目的港
C5: 241028000057 | D5: 45601 | E5: 朱小飞 | F5: Isabel Zhu | G5: Halifa Success | H5: 0.8721 | I5: 153 | J5: 1785.59 | P5: 1785.59 | S5: 631.17596 | T5: 1.457433 | U5: 30.78 | X5: 663.4134 | Y5: 140.43016 | AB5: 140.43016 | AC5: 7.33 | AD5: 1029.3531 | AE5: 1692.7665 | AF5: 92.823539
C6: 241101000033 | D6: 45601 | E6: 朱小飞 | F6: Isabel Zhu | G6: Halifa Success | H6: 0.8844 | I6: 155 | J6: 1806.11 | P6: 1806.11 | S6: 640.078 | T6: 1.4779885 | U6: 31.214118 | X6: 672.7701 | Y6: 142.41077 | AB6: 142.41077 | AC6: 7.33 | AD6: 1043.8709 | AE6: 1716.641 | AF6: 89.468952
C7: 241015000034 | D7: 45608 | E7: 朱小飞 | F7: Isabel Zhu | G7: Halifa Success | H7: 4.77 | I7: 451 | J7: 9789.95 | P7: 9789.95 | S7: 3733.0862 | U7: 137.1375 | X7: 3870.2237 | Y7: 796.92951 | AA7: 3.7556735 | AB7: 800.68519 | AC7: 7.3 | AD7: 5845.0019 | AE7: 9715.2255 | AF7: 74.724471
C8: 241104000057 | D8: 45608 | E8: 朱小飞 | F8: Isabel Zhu | G8: Halifa Success | H8: 2.3978 | I8: 447 | J8: 4925.76 | P8: 4925.76 | S8: 1876.5606 | U8: 68.93675 | X8: 1945.4973 | Y8: 400.60327 | AA8: 1.8879149 | AB8: 402.49118 | AC8: 7.3 | AD8: 2938.1856 | AE8: 4883.683 | AF8: 42.077029
C9: 241111000055 | D9: 45609 | E9: 朱小飞 | F9: Isabel Zhu | G9: Halifa Success | H9: 2.9026 | I9: 435 | J9: 5972.48 | P9: 5972.48 | S9: 1997.7998 | U9: 76.833529 | V9: 20 | X9: 2094.6334 | Y9: 460.73952 | AA9: 4.0542492 | AB9: 464.79376 | AC9: 7.33 | AD9: 3406.9383 | AE9: 5501.5716 | AF9: 470.90835
C10: 241111000056 | D10: 45609 | E10: 朱小飞 | F10: Isabel Zhu | G10: Halifa Success | H10: 2.4588 | I10: 346 | J10: 5048.9 | P10: 5048.9 | S10: 1692.3414 | U10: 65.085882 | X10: 1757.4273 | Y10: 390.29364 | AA10: 3.4343651 | AB10: 393.72801 | AC10: 7.33 | AD10: 2886.0263 | AE10: 4643.4536 | AF10: 405.44642
C11: 241112000044 | D11: 45609 | E11: 朱小飞 | F11: Isabel Zhu | G11: Halifa Success | H11: 0.936 | I11: 422 | J11: 2195.26 | P11: 2195.26 | S11: 644.22953 | U11: 24.776471 | W11: 266 | X11: 935.006 | Y11: 148.57445 | Z11: 17.33 | AA11: 1.3073718 | AB11: 167.21182 | AC11: 7.33 | AD11: 1225.6626 | AE11: 2160.6686 | AF11: 34.591377
C12: 241115000005 | D12: 45615 | E12: 朱小飞 | F12: Isabel Zhu | G12: Halifa Success | H12: 1.0641 | I12: 52 | J12: 2244.61 | P12: 2244.61 | S12: 744.69004 | U12: 35.991618 | W12: 72.29 | X12: 852.97166 | Y12: 173.46395 | AA12: 1.1755175 | AB12: 174.63947 | AC12: 7.3 | AD12: 1274.8681 | AE12: 2127.8398 | AF12: 116.77024
C13: 241119000012 | D13: 45623 | E13: 朱小飞 | F13: Isabel Zhu | G13: Halifa Success | H13: 0.9901 | I13: 222 | J13: 2046.8 | P13: 2046.8 | S13: 684.82378 | U13: 27.664559 | X13: 712.48834 | Y13: 161.34262 | AA13: 0.77999496 | AB13: 162.12261 | AC13: 7.3 | AD13: 1183.4951 | AE13: 1895.9834 | AF13: 150.81658
C14: 241124000008 | D14: 45623 | E14: 朱小飞 | F14: Isabel Zhu | G14: Halifa Success | H14: 3.0541 | I14: 317 | J14: 6242.74 | P14: 6242.74 | S14: 2112.4334 | U14: 85.335147 | X14: 2197.7685 | Y14: 497.68356 | AA14: 2.406002 | AB14: 500.08956 | AC14: 7.3 | AD14: 3650.6538 | AE14: 5848.4223 | AF14: 394.31766
C15: 241125000035 | D15: 45623 | E15: 朱小飞 | F15: Isabel Zhu | G15: Halifa Success | H15: 1.1856 | I15: 142 | J15: 2595.69 | P15: 2595.69 | S15: 820.04552 | U15: 33.127059 | W15: 157.53 | X15: 1010.7026 | Y15: 193.20049 | AA15: 0.93400871 | AB15: 194.1345 | AC15: 7.3 | AD15: 1417.1819 | AE15: 2427.8845 | AF15: 167.80555
C16: 241126000027 | D16: 45623 | E16: 朱小飞 | F16: Isabel Zhu | G16: Halifa Success | H16: 0.4539 | I16: 85 | J16: 921.06 | P16: 921.06 | S16: 313.94961 | U16: 12.6825 | X16: 326.63211 | Y16: 73.965675 | AA16: 0.35757975 | AB16: 74.323255 | AC16: 7.3 | AD16: 542.55976 | AE16: 869.19187 | AF16: 51.868127 | AG16: =SUM(AF5:AF16) -> 2091.6183
C17: 241027000011 | D17: 45601 | E17: 朱小飞 | F17: Isabel Zhu | G17: Maryam Tukur | H17: 0.5618 | I17: 55 | K17: 434000 | M17: 1671.8028 | N17: 259.6 | O17: 7.3 | P17: 1895.08 | S17: 406.59862 | T17: 0.93886694 | U17: 19.828235 | V17: 310 | W17: 59 | X17: 796.36572 | Y17: 90.46401 | AB17: 90.46401 | AC17: 7.33 | AD17: 663.1012 | AE17: 1459.4669 | AF17: 435.61308 | AG17: =SUM(AG16/2) -> 1045.8091
C18: 241105000034 | D18: 45602 | E18: 朱小飞 | F18: Isabel Zhu | G18: Joy | H18: 0.7455 | I18: 854 | K18: 641427.2 | M18: 1643 | N18: 390.4 | O18: 7.3 | P18: 2849.92 | S18: 534.87981 | U18: 19.733824 | X18: 554.61363 | Y18: 117.48707 | Z18: 29.21 | AA18: 0.55517824 | AB18: 147.25225 | AC18: 7.33 | AD18: 1079.359 | AE18: 1633.9726 | AF18: 1215.9474
C19: 241106000015 | D19: 45608 | E19: 朱小飞 | F19: Isabel Zhu | G19: Komebility gift | H19: 0.2358 | I19: 43 | K19: 132422.4 | M19: 1672 | N19: 79.2 | O19: 7.3 | P19: 578.16 | S19: 184.54124 | U19: 6.77925 | X19: 191.32049 | Y19: 39.395383 | AA19: 0.18565782 | AB19: 39.581041 | AC19: 7.3 | AD19: 288.9416 | AE19: 480.26209 | AF19: 97.897908
C20: 241107000010 | D20: 45608 | E20: 朱小飞 | F20: Isabel Zhu | G20: Joy | H20: 0.616 | I20: 188 | K20: 331724.8 | M20: 1672 | N20: 198.4 | O20: 7.3 | P20: 1448.32 | S20: 482.09247 | U20: 17.71 | X20: 499.80247 | Y20: 102.91584 | Z20: 3.11 | AA20: 0.48500941 | AB20: 106.51085 | AC20: 7.3 | AD20: 777.52924 | AE20: 1277.3317 | AF20: 170.98829
C21: 241107000011 | D21: 45608 | E21: 朱小飞 | F21: Isabel Zhu | G21: Joy | H21: 2.028 | I21: 358 | K21: 1086131.2 | M21: 1672 | N21: 649.6 | O21: 7.3 | P21: 4742.08 | S21: 1587.1486 | U21: 58.305 | X21: 1645.4536 | Y21: 338.82035 | Z21: 10.18 | AA21: 1.5967518 | AB21: 350.5971 | AC21: 7.3 | AD21: 2559.3588 | AE21: 4204.8124 | AF21: 537.2676
C22: 241107000012 | D22: 45608 | E22: 朱小飞 | F22: Isabel Zhu | G22: Joy | H22: 7.8483 | I22: 1598 | K22: 4200064 | M22: 1672 | N22: 2512 | O22: 7.3 | P22: 18337.6 | S22: 6142.2181 | U22: 225.63862 | X22: 6367.8567 | Y22: 1311.2247 | Z22: 39.27 | AA22: 6.1793821 | AB22: 1356.6741 | AC22: 7.3 | AD22: 9903.7209 | AE22: 16271.578 | AF22: 2066.0224
C23: 241109000008 | D23: 45608 | E23: 朱小飞 | F23: Isabel Zhu | G23: Komebility gift | H23: 1.344 | I23: 254 | K23: 696622.08 | M23: 1672 | N23: 416.64 | O23: 7.3 | P23: 3041.472 | S23: 1051.8381 | U23: 38.64 | X23: 1090.4781 | Y23: 224.54366 | AA23: 1.0582024 | AB23: 225.60186 | AC23: 7.3 | AD23: 1646.8936 | AE23: 2737.3717 | AF23: 304.10028
C24: 241111000011 | D24: 45609 | E24: 朱小飞 | F24: Isabel Zhu | G24: Ope Olofinjana | H24: 0.1421 | I24: 36 | K24: 93936 | M24: 1651.1865 | N24: 56.89 | O24: 7.3 | P24: 415.297 | S24: 97.804504 | U24: 3.7614706 | X24: 101.56597 | Y24: 22.556014 | Z24: 10 | AA24: 0.19848026 | AB24: 32.754494 | AC24: 7.33 | AD24: 240.09044 | AE24: 341.65642 | AF24: 73.640585
C25: 241111000012 | D25: 45609 | E25: 朱小飞 | F25: Isabel Zhu | G25: Ope Olofinjana | H25: 0.2386 | I25: 52 | K25: 148176 | M25: 1651.17 | N25: 89.74 | O25: 7.3 | P25: 655.102 | S25: 164.22347 | U25: 6.3158824 | X25: 170.53935 | Y25: 37.873785 | Z25: 11.3 | AA25: 0.33326806 | AB25: 49.507053 | AC25: 7.33 | AD25: 362.8867 | AE25: 533.42605 | AF25: 121.67595
C26: 241112000045 | D26: 45615 | E26: 朱小飞 | F26: Isabel Zhu | G26: Mr Zhou | H26: 0.8383 | I26: 181 | J26: 3448 | P26: 3448 | S26: 586.66823 | U26: 28.354265 | X26: 615.02249 | Y26: 136.65523 | Z26: 95.12 | AA26: 0.92607494 | AB26: 232.7013 | AC26: 7.3 | AD26: 1698.7195 | AE26: 2313.742 | AF26: 1134.258
C27: 241113000029 | D27: 45615 | E27: 朱小飞 | F27: Isabel Zhu | G27: Mr Olusola Abidemi | H27: 1.7575 | I27: 1244.5 | K27: 1064044.8 | M27: 1680.0004 | N27: 633.35986 | O27: 7.27 | P27: 4604.5262 | S27: 1229.9528 | T27: 735 | U27: 59.444853 | X27: 2024.3976 | Y27: 286.49835 | AA27: 1.9415206 | AB27: 288.43987 | AC27: 7.3 | AD27: 2105.611 | AE27: 4130.0087 | AF27: 474.51753
A28: 合计 | H28: =SUM(H5:H16) -> 21.9695 | AF28: =SUM(AF5:AF27) -> 8723.5473
AF29: 1045.81
C30: 基本任务：小于6千 | F30: 不够基本任务6千， 公司将根据空运提成里抽出补足基数 | K30: 朱小飞 提成 | AF30: =SUM(AF28-AF29) -> 7677.7373
K31: 名称 | L31: 计费体积 | M31: 毛利 | N31: 备注
C32: 基本任务：6千-3.5万 | F32: 按40%提成 | K32: LOS | L32: =SUM(H28) -> 21.9695 | M32: 7677.7373 | N32: 总利润减Halifa 利润的 一半1045.81
K33: 基数 | M33: 3000
C34: 基本任务：3.5万以上 | F34: 按50%提成 | K34: 提成计数 | M34: =SUM(M32-M33) -> 4677.7373
K35: 提成点数 | M35: 0.15
K36: 提成金额 | M36: =SUM(M34*M35) -> 701.66059

Sheet 吕沛霖
A1: LOS毛利表
A2: JOB | B2: 集装编号 | C2: 运单编号 | D2: 日期 | E2: 业务 | F2: 发货人 | G2: 收货人 | H2: 计费体积 | I2: 计费重量 | J2: 应 收 | Q2: 总应收 | R2: 起 运 港 成 本 | W2: 代垫运费 | X2: 起运港成本 合计 | Y2: 目的港成本 | AE2: 总支出 | AF2: 利润
J3: 应收RMB | K3: LOS Income(NGN)收到(奈拉) | L3: LOS 收到USD | M3: 美元汇率 dollar currency rate | N3: 应收 到付款USD | O3: 汇率 | P3: 人民币 | R3: 代理商 | S3: 运费+出口报关费 | T3: 提货费 | U3: 装卸费 | V3: 包装费 | Y3: 进口报关费 | Z3: 到门配送费 | AA3: 转运费 | AB3: 目的港支出 | AC3: 汇率 | AD3: 人民币 | AE3: 起运港+目的港
A4: JOB120361 | B4: COLL004287 | C4: 240910000015 | D4: 45601 | E4: 吕沛霖 | F4: 喵喵速运-Layne | G4: Hu Hai Liang | H4: 5.1959 | I4: 743 | K4: 2382640 | M4: 1580 | N4: 1508 | O4: 7.29 | P4: 10993.32 | Q4: 76332.008 | R4: 登凯=46189.5 陆总=1200 拖车费=1670 杂费=89 过磅费=66 | S4: 3760.4944 | T4: 8.6832658 | U4: 183.38471 | X4: 3952.5624 | Y4: 836.67133 | AB4: 836.67133 | AC4: 7.33 | AD4: 6132.8008 | AE4: 10085.363 | AF4: 907.95679
C5: 241026000006 | D5: 45601 | E5: 吕沛霖 | F5: 喵喵速运-Layne | G5: LEO WEI | H5: 0.6549 | I5: 72 | K5: 363730 | M5: 1683.0002 | N5: 216.12 | O5: 7.3 | P5: 1577.676 | S5: 473.97906 | T5: 1.0944535 | U5: 23.114118 | X5: 498.18763 | Y5: 105.45547 | AB5: 105.45547 | AC5: 7.33 | AD5: 772.98856 | AE5: 1271.1762 | AF5: 306.49981
C6: 241028000025 | D6: 45601 | E6: 吕沛霖 | F6: 喵喵速运-Layne | G6: Candice Ding | H6: 0.7015 | I6: 168 | K6: 432424.8 | M6: 1710 | N6: 252.88 | O6: 7.3 | P6: 1846.024 | S6: 507.70547 | T6: 1.1723303 | U6: 24.758824 | X6: 533.63662 | Y6: 112.95924 | Z6: 42.43 | AB6: 155.38924 | AC6: 7.33 | AD6: 1139.0032 | AE6: 1672.6398 | AF6: 173.38422
C7: 241030000002 | D7: 45601 | E7: 吕沛霖 | F7: 喵喵速运-Layne | G7: Mu Shi Shi | H7: 7.4945 | I7: 520 | J7: 18324.8 | P7: 18324.8 | S7: 5424.0893 | T7: 12.524632 | U7: 264.51176 | X7: 5701.1257 | Y7: 1206.8041 | Z7: 47.85 | AB7: 1254.6541 | AC7: 7.33 | AD7: 9196.6143 | AE7: 14897.74 | AF7: 3427.06
C8: 241030000041 | D8: 45601 | E8: 吕沛霖 | F8: 喵喵速运-Layne | G8: WEI PING | H8: 1.5338 | I8: 336 | K8: 755361 | M8: 1700 | N8: 444.33 | O8: 7.27 | P8: 3230.2791 | S8: 1110.0765 | T8: 2.5632505 | U8: 54.134118 | X8: 1166.7738 | Y8: 246.9806 | Z8: 29.9 | AB8: 276.8806 | AC8: 7.33 | AD8: 2029.5348 | AE8: 3196.3086 | AF8: 33.97049
C9: 241101000029 | D9: 45601 | E9: 吕沛霖 | F9: 喵喵速运-Layne | G9: YA | H9: 0.8656 | I9: 346 | J9: 2978.64 | P9: 2978.64 | S9: 626.47164 | T9: 1.4465704 | U9: 30.550588 | X9: 658.46879 | Y9: 139.38349 | Z9: 12.36 | AA9: 83.19 | AB9: 234.93349 | AC9: 7.33 | AD9: 1722.0625 | AE9: 2380.5313 | AF9: 598.10869
C10: 241030000021 | D10: 45602 | E10: 吕沛霖 | F10: 喵喵速运-Layne | G10: MA ZONG | H10: 0.6626 | I10: 405 | J10: 1624.5 | P10: 1624.5 | S10: 475.40088 | U10: 17.539412 | X10: 492.9403 | Y10: 104.42245 | Z10: 35.38 | AA10: 0.49344212 | AB10: 140.29589 | AC10: 7.33 | AD10: 1028.3689 | AE10: 1521.3092 | AF10: 103.19084
C11: 241021000005 | D11: 45608 | E11: 吕沛霖 | F11: 喵喵速运-Layne | G11: Hu Hai Liang | H11: 1.1795 | I11: 335 | K11: 583853 | M11: 1650.0015 | N11: 353.84998 | O11: 7.3 | P11: 2583.1049 | S11: 923.09751 | U11: 33.910625 | X11: 957.00814 | Y11: 197.06045 | AA11: 0.92868279 | AB11: 197.98914 | AC11: 7.3 | AD11: 1445.3207 | AE11: 2402.3288 | AF11: 180.77603
C12: 241106000026 | D12: 45608 | E12: 吕沛霖 | F12: 喵喵速运-Layne | G12: Mr.Shen | H12: 0.1938 | I12: 63 | K12: 188972 | M12: 1700 | N12: 111.16 | O12: 7.27 | P12: 808.1332 | S12: 151.6713 | U12: 5.57175 | X12: 157.24305 | Y12: 32.378394 | Z12: 53.58 | AA12: 0.152589 | AB12: 86.110983 | AC12: 7.3 | AD12: 628.61018 | AE12: 785.85323 | AF12: 22.279974
C13: 241104000001 | D13: 45609 | E13: 吕沛霖 | F13: 喵喵速运-Layne | G13: Isa | H13: 0.462 | I13: 90 | K13: 368397.9 | M13: 1665 | N13: 221.26 | O13: 7.3 | P13: 1615.198 | S13: 317.98509 | U13: 12.229412 | X13: 330.2145 | Y13: 73.334823 | Z13: 57.94 | AA13: 0.64530529 | AB13: 131.92013 | AC13: 7.33 | AD13: 966.97454 | AE13: 1297.189 | AF13: 318.00896
C14: 241105000045 | D14: 45609 | E14: 吕沛霖 | F14: 喵喵速运-Layne | G14: Abdulsheldu | H14: 0.8486 | I14: 297 | K14: 432928.65 | M14: 1663.255 | N14: 260.29 | O14: 7.3 | P14: 1900.117 | S14: 584.07391 | U14: 22.462941 | X14: 606.53685 | Y14: 134.70115 | Z14: 10.07 | AA14: 1.1852945 | AB14: 145.95644 | AC14: 7.33 | AD14: 1069.8607 | AE14: 1676.3976 | AF14: 223.71942
C15: 241218000023 | D15: 45615 | E15: 吕沛霖 | F15: 喵喵速运-Layne | G15: Isa | H15: 0.0592 | I15: 10 | K15: 70231 | M15: 1580 | N15: 44.45 | O15: 7.29 | P15: 324.0405 | S15: 41.429988 | U15: 2.0023529 | X15: 43.432341 | Y15: 9.6504706 | AA15: 0.065398588 | AB15: 9.7158692 | AC15: 7.3 | AD15: 70.925845 | AE15: 114.35819 | AF15: 209.68231
C16: 241114000027 | D16: 45616 | E16: 吕沛霖 | F16: 喵喵速运-Layne | G16: Abdulsheldu | H16: 7.3094 | I16: 4250 | K16: 3823031.5 | M16: 1663.2 | N16: 2298.6 | O16: 7.3 | P16: 16779.78 | S16: 4910.7881 | U16: 214.98235 | X16: 5125.7705 | Y16: 1191.5397 | Z16: 97.22 | AA16: 8.3176672 | AB16: 1297.0774 | AC16: 7.3 | AD16: 9468.6647 | AE16: 14594.435 | AF16: 2185.3448
C17: 241121000016 | D17: 45623 | E17: 吕沛霖 | F17: 喵喵速运-Layne | G17: Hu Hai Liang | H17: 2.2928 | I17: 1066 | K17: 1070400 | M17: 1600 | N17: 669 | O17: 7.27 | P17: 4863.63 | S17: 1585.864 | U17: 64.063529 | X17: 1649.9275 | Y17: 373.62525 | AA17: 1.8062544 | AB17: 375.4315 | AC17: 7.3 | AD17: 2740.65 | AE17: 4390.5775 | AF17: 473.0525
A18: 合计 | H18: =SUM(H4:H17) -> 29.4541 | AF18: =SUM(AF4:AF17) -> 9163.0349
C21: 基本任务：小于6千 | F21: 不够基本任务6千， 公司将根据空运提成里抽出补足基数 | K21: 吕沛霖 提成
K22: 名称 | L22: 计费体积 | M22: 毛利
C23: 基本任务：6千-3.5万 | F23: 按40%提成 | K23: LOS | L23: =SUM(H18) -> 29.4541 | M23: =SUM(AF18) -> 9163.0349
K24: 基数 | M24: 6000
C25: 基本任务：3.5万以上 | F25: 按50%提成 | K25: 提成计数 | M25: =SUM(M23-M24) -> 3163.0349
K26: 提成点数 | M26: 0.4
K27: 提成金额 | M27: =SUM(M25*M26) -> 1265.2139

Sheet 罗珮文
A1: LOS毛利表
A3: JOB | B3: 集装编号 | C3: 运单编号 | D3: 日期 | E3: 业务 | F3: 发货人 | G3: 收货人 | H3: 计费体积 | I3: 计费重量 | J3: 应 收 | Q3: 总应收 | R3: 起 运 港 成 本 | W3: 代垫运费 | X3: 起运港成本 合计 | Y3: 目的港成本 | AE3: 总支出 | AF3: 利润
J4: 应收RMB | K4: LOS Income(NGN)收到(奈拉) | L4: LOS 收到USD | M4: 美元汇率 dollar currency rate | N4: 应收 到付款USD | O4: 汇率 | P4: 人民币 | R4: 代理商 | S4: 运费+出口报关费 | T4: 提货费 | U4: 装卸费 | V4: 包装费 | Y4: 进口报关费 | Z4: 到门配送费 | AA4: 转运费 | AB4: 目的港支出 | AC4: 汇率 | AD4: 人民币 | AE4: 起运港+目的港
C5: 241107000022 | D5: 45602 | E5: 罗珮文 | F5: Shirley | G5: SKY JET | H5: 32.635 | I5: 4165 | J5: 52361.59 | P5: 52361.59 | S5: 23414.893 | U5: 863.86765 | X5: 24278.76 | Y5: 5143.1128 | AA5: 24.303476 | AB5: 5167.4163 | AC5: 7.33 | AD5: 37877.161 | AE5: 62155.922 | AF5: -9794.3317
C6: 241210000044 | D6: 45609 | E6: 罗珮文 | F6: Shirley | G6: SKY JET | H6: 5.104 | I6: 471 | J6: 7929.81 | P6: 7929.81 | S6: 3994.4805 | U6: 146.74 | X6: 4141.2205 | Y6: 852.73128 | AA6: 4.0186494 | AB6: 856.74993 | AC6: 7.3 | AD6: 6254.2745 | AE6: 10395.495 | AF6: -2465.685
C7: 241113000012 | D7: 45609 | E7: 罗珮文 | F7: Shirley | G7: Yusky | H7: 5.5016 | I7: 2874 | K7: 2264723.3 | M7: 1608 | N7: 1408.41 | O7: 7.3 | P7: 10281.393 | S7: 3786.638 | U7: 145.63059 | X7: 3932.2686 | Y7: 873.28758 | AA7: 7.6844407 | AB7: 880.97202 | AC7: 7.33 | AD7: 6457.5249 | AE7: 10389.793 | AF7: -108.40049
C8: 241210000044 | D8: 45609 | E8: 罗珮文 | F8: Shirley | G8: SKY JET | H8: 5.896 | I8: 922 | J8: 9160.23 | P8: 9160.23 | S8: 4058.0954 | U8: 156.07059 | X8: 4214.166 | Y8: 935.89202 | AA8: 8.2353247 | AB8: 944.12735 | AC8: 7.33 | AD8: 6920.4535 | AE8: 11134.619 | AF8: -1974.3895
C9: 241213000052 | D9: 45609 | E9: 罗珮文 | F9: Shirley | G9: SKY JET | H9: 20.97 | I9: 2633 | J9: 32579.83 | P9: 32579.83 | S9: 14433.219 | U9: 555.08824 | X9: 14988.308 | Y9: 3328.639 | AA9: 29.290156 | AB9: 3357.9292 | AC9: 7.33 | AD9: 24613.621 | AE9: 39601.928 | AF9: -7022.0984
C10: 241213000054 | D10: 45609 | E10: 罗珮文 | F10: Shirley | G10: SKY JET | H10: 3.5 | I10: 419 | J10: 5437.74 | P10: 5437.74 | S10: 2408.9779 | U10: 92.647059 | X10: 2501.625 | Y10: 555.56684 | AA10: 4.8886765 | AB10: 560.45551 | AC10: 7.33 | AD10: 4108.1389 | AE10: 6609.7639 | AF10: -1172.0239
C11: 241113000044 | D11: 45616 | E11: 罗珮文 | F11: Shirley | G11: Yusky | H11: 2.0156 | I11: 301 | K11: 829711.92 | M11: 1608 | N11: 515.99 | O11: 7.3 | P11: 3766.727 | S11: 1354.172 | U11: 59.282353 | X11: 1413.4543 | Y11: 328.57244 | AA11: 2.2936342 | AB11: 330.86608 | AC11: 7.3 | AD11: 2415.3224 | AE11: 3828.7767 | AF11: -62.049671
C12: 241114000013 | D12: 45616 | E12: 罗珮文 | F12: Shirley | G12: Yusky | H12: 0.0902 | I12: 76 | K12: 37176.96 | M12: 1608 | N12: 23.12 | O12: 7.3 | P12: 168.776 | S12: 60.600472 | U12: 2.6529412 | X12: 63.253413 | Y12: 14.703926 | AA12: 0.10264229 | AB12: 14.806569 | AC12: 7.3 | AD12: 108.08795 | AE12: 171.34137 | AF12: -2.5653652
C13: 241118000062 | D13: 45616 | E13: 罗珮文 | F13: Shirley | G13: Yusky | H13: 0.3791 | I13: 53 | K13: 156056.4 | M13: 1608 | N13: 97.05 | O13: 7.3 | P13: 708.465 | S13: 254.69666 | U13: 11.15 | X13: 265.84666 | Y13: 61.798875 | AA13: 0.4313935 | AB13: 62.230269 | AC13: 7.3 | AD13: 454.28096 | AE13: 720.12762 | AF13: -11.662623
C14: 241119000022 | D14: 45616 | E14: 罗珮文 | F14: Shirley | G14: Yusky | H14: 2.3578 | I14: 388 | K14: 970588.8 | M14: 1608 | N14: 603.6 | O14: 7.3 | P14: 4406.28 | S14: 1584.0775 | U14: 69.347059 | X14: 1653.4246 | Y14: 384.35607 | AA14: 2.6830377 | AB14: 387.03911 | AC14: 7.3 | AD14: 2825.3855 | AE14: 4478.8101 | AF14: -72.530099
C15: 241113000043 | D15: 45616 | E15: 罗珮文 | F15: Shirley | G15: Yusky | H15: 7.2261 | I15: 7740 | K15: 2974607 | M15: 1608 | N15: 1849.88 | O15: 7.3 | P15: 13504.124 | S15: 4854.8234 | U15: 212.53235 | X15: 5067.3558 | Y15: 1177.9606 | AA15: 8.2228767 | AB15: 1186.1834 | AC15: 7.3 | AD15: 8659.1391 | AE15: 13726.495 | AF15: -222.37089
C16: 241120000022 | D16: 45616 | E16: 罗珮文 | F16: Shirley | G16: SKY JET | H16: 24.63 | I16: 3402 | J16: 38444.97 | P16: 38444.97 | S16: 16547.557 | U16: 724.41176 | X16: 17271.969 | Y16: 4015.0522 | AA16: 28.027491 | AB16: 4043.0797 | AC16: 7.3 | AD16: 29514.482 | AE16: 46786.45 | AF16: -8341.4804
C17: 241113000043 | D17: 45617 | E17: 罗珮文 | F17: Shirley | G17: Yusky | H17: 4.8174 | I17: 5160 | K17: 1944345.4 | M17: 1608 | N17: 1209.17 | O17: 7.3 | P17: 8826.941 | S17: 3243.8459 | U17: 92.097353 | X17: 3335.9432 | Y17: 795.79197 | AA17: 14.873722 | AB17: 810.6657 | AC17: 7.3 | AD17: 5917.8596 | AE17: 9253.8028 | AF17: -426.86181
C18: 241113000045 | D18: 45617 | E18: 罗珮文 | F18: Shirley | G18: Yusky | H18: 0.164 | I18: 134 | K18: 66217.44 | M18: 1608 | N18: 41.18 | O18: 7.3 | P18: 300.614 | S18: 110.43109 | U18: 3.1352941 | X18: 113.56638 | Y18: 27.091353 | AA18: 0.50635 | AB18: 27.597703 | AC18: 7.3 | AD18: 201.46323 | AE18: 315.02961 | AF18: -14.415614
C19: 241114000012 | D19: 45617 | E19: 罗珮文 | F19: Shirley | G19: Yusky | H19: 4.9075 | I19: 496 | K19: 1980702.2 | M19: 1608 | N19: 1231.78 | O19: 7.3 | P19: 8991.994 | S19: 3304.5156 | U19: 93.819853 | X19: 3398.3355 | Y19: 810.6757 | AA19: 15.151906 | AB19: 825.8276 | AC19: 7.3 | AD19: 6028.5415 | AE19: 9426.877 | AF19: -434.88301
C20: 241118000061 | D20: 45617 | E20: 罗珮文 | F20: Shirley | G20: Yusky | H20: 0.2475 | I20: 27 | K20: 99937.2 | M20: 1608 | N20: 62.15 | O20: 7.3 | P20: 453.695 | S20: 166.65667 | U20: 4.7316176 | X20: 171.38829 | Y20: 40.884816 | AA20: 0.76415625 | AB20: 41.648972 | AC20: 7.3 | AD20: 304.0375 | AE20: 475.42579 | AF20: -21.730789
C21: 241118000064 | D21: 45617 | E21: 罗珮文 | F21: Shirley | G21: Yusky | H21: 0.0647 | I21: 9 | K21: 26097.84 | M21: 1608 | N21: 16.23 | O21: 7.3 | P21: 118.479 | S21: 43.566411 | U21: 1.2369118 | X21: 44.803323 | Y21: 10.687869 | AA21: 0.19976125 | AB21: 10.88763 | AC21: 7.3 | AD21: 79.479702 | AE21: 124.28302 | AF21: -5.8040245
C22: 241119000018 | D22: 45617 | E22: 罗珮文 | F22: Shirley | G22: Yusky | H22: 0.3528 | I22: 60 | K22: 142388.4 | M22: 1608 | N22: 88.55 | O22: 7.3 | P22: 646.415 | S22: 237.56151 | U22: 6.7447059 | X22: 244.30622 | Y22: 58.279447 | AA22: 1.08927 | AB22: 59.368717 | AC22: 7.3 | AD22: 433.39163 | AE22: 677.69785 | AF22: -31.282852
C23: 241119000019 | D23: 45617 | E23: 罗珮文 | F23: Shirley | G23: Yusky | H23: 0.8465 | I23: 76 | K23: 341667.84 | M23: 1608 | N23: 212.48 | O23: 7.3 | P23: 1551.104 | S23: 569.99949 | U23: 16.183088 | X23: 586.18258 | Y23: 139.83433 | AA23: 2.6135688 | AB23: 142.4479 | AC23: 7.3 | AD23: 1039.8697 | AE23: 1626.0522 | AF23: -74.948245
C24: 241119000020 | D24: 45617 | E24: 罗珮文 | F24: Shirley | G24: Yusky | H24: 0.1709 | I24: 14 | K24: 68967.12 | M24: 1608 | N24: 42.89 | O24: 7.3 | P24: 313.097 | S24: 115.07727 | U24: 3.2672059 | X24: 118.34448 | Y24: 28.231172 | AA24: 0.52765375 | AB24: 28.758826 | AC24: 7.3 | AD24: 209.93943 | AE24: 328.28391 | AF24: -15.186909
C25: 241120000030 | D25: 45617 | E25: 罗珮文 | F25: Shirley | G25: SKY JET | H25: 33.45 | I25: 4005 | J25: 52212.11 | P25: 52212.11 | S25: 22523.902 | U25: 639.48529 | X25: 23163.387 | Y25: 5525.6449 | AA25: 103.27688 | AB25: 5628.9217 | AC25: 7.3 | AD25: 41091.129 | AE25: 64254.516 | AF25: -12042.406
C26: 241118000058 | D26: 45623 | E26: 罗珮文 | F26: Shirley | G26: Yusky | H26: 0.5167 | I26: 71 | K26: 214362.48 | M26: 1608 | N26: 133.31 | O26: 7.3 | P26: 973.163 | S26: 357.38657 | U26: 14.437206 | X26: 371.82378 | Y26: 84.199304 | AA26: 0.40705322 | AB26: 84.606358 | AC26: 7.3 | AD26: 617.62641 | AE26: 989.45019 | AF26: -16.287189
C27: 241118000059 | D27: 45623 | E27: 罗珮文 | F27: Shirley | G27: Yusky | H27: 0.8256 | I27: 31 | K27: 342504 | M27: 1608 | N27: 213 | O27: 7.3 | P27: 1554.9 | S27: 571.04384 | U27: 23.068235 | X27: 594.11208 | Y27: 134.53638 | AA27: 0.65040282 | AB27: 135.18678 | AC27: 7.3 | AD27: 986.86349 | AE27: 1580.9756 | AF27: -26.075569
C28: 241118000060 | D28: 45623 | E28: 罗珮文 | F28: Shirley | G28: Yusky | H28: 0.132 | I28: 50 | K28: 54768.48 | M28: 1608 | N28: 34.06 | O28: 7.3 | P28: 248.638 | S28: 91.300615 | U28: 3.6882353 | X28: 94.98885 | Y28: 21.510176 | AA28: 0.10398882 | AB28: 21.614165 | AC28: 7.3 | AD28: 157.78341 | AE28: 252.77226 | AF28: -4.1342566
C29: 241118000065 | D29: 45623 | E29: 罗珮文 | F29: Shirley | G29: Yusky | H29: 1.2613 | I29: 266 | K29: 523146.72 | M29: 1608 | N29: 325.34 | O29: 7.3 | P29: 2374.982 | S29: 872.40504 | U29: 35.242206 | X29: 907.64725 | Y29: 205.53625 | AA29: 0.99364472 | AB29: 206.5299 | AC29: 7.3 | AD29: 1507.6683 | AE29: 2415.3155 | AF29: -40.33351
C30: 241118000067 | D30: 45623 | E30: 罗珮文 | F30: Shirley | G30: Yusky | H30: 0.2938 | I30: 56 | K30: 121886.4 | M30: 1608 | N30: 75.8 | O30: 7.3 | P30: 553.34 | S30: 203.21303 | U30: 8.2091176 | X30: 211.42215 | Y30: 47.876438 | AA30: 0.23145391 | AB30: 48.107892 | AC30: 7.3 | AD30: 351.18761 | AE30: 562.60977 | AF30: -9.2697652
C31: 241127000014 | D31: 45623 | E31: 罗珮文 | F31: Shirley | G31: Yusky | H31: 0.8732 | I31: 115 | K31: 362266.32 | M31: 1608 | N31: 225.29 | O31: 7.3 | P31: 1644.617 | S31: 603.9674 | U31: 24.398235 | X31: 628.36563 | Y31: 142.29308 | AA31: 0.68790182 | AB31: 142.98098 | AC31: 7.3 | AD31: 1043.7611 | AE31: 1672.1268 | AF31: -27.509777
C32: 241119000021 | D32: 45623 | E32: 罗珮文 | F32: Shirley | G32: Yusky | H32: 1.3774 | I32: 231 | K32: 571274.16 | M32: 1608 | N32: 355.27 | O32: 7.3 | P32: 2593.471 | S32: 952.70808 | U32: 38.486176 | X32: 991.19426 | Y32: 224.45543 | AA32: 1.0851076 | AB32: 225.54054 | AC32: 7.3 | AD32: 1646.4459 | AE32: 2637.6402 | AF32: -44.169199
C33: 241127000011 | D33: 45623 | E33: 罗珮文 | F33: Shirley | G33: Yusky | H33: 2.5492 | I33: 684 | K33: 1057565.5 | M33: 1608 | N33: 657.69 | O33: 7.3 | P33: 4801.137 | S33: 1763.2085 | U33: 71.227647 | X33: 1834.4362 | Y33: 415.40714 | AA33: 2.0082448 | AB33: 417.41538 | AC33: 7.3 | AD33: 3047.1323 | AE33: 4881.5685 | AF33: -80.431459
C34: 241127000015 | D34: 45623 | E34: 罗珮文 | F34: Shirley | G34: SKY JET | H34: 33.06 | I34: 5293 | J34: 51603.35 | P34: 51603.35 | S34: 22866.654 | U34: 923.73529 | X34: 23790.389 | Y34: 5387.3215 | AA34: 26.044474 | AB34: 5413.3659 | AC34: 7.3 | AD34: 39517.571 | AE34: 63307.961 | AF34: -11704.611
A35: 合计 | H35: =SUM(H5:H34) -> 196.2159 | AF35: =SUM(AF5:AF34) -> -56269.928
C37: 基本任务：小于6千 | F37: 不够基本任务6千， 公司将根据空运提成里抽出补足基数 | K37: 罗珮文 提成
K38: 名称 | L38: 计费体积 | M38: 毛利
C39: 基本任务：6千-3.5万 | F39: 按40%提成 | K39: LOS | L39: =SUM(H35) -> 196.2159 | M39: =SUM(AF35) -> -56269.928
K40: 基数
C41: 基本任务：3.5万以上 | F41: 按50%提成 | K41: 提成计数
K42: 提成点数
...

Sheet 苏慧琪
A1: LOS毛利表
A3: JOB | B3: 集装编号 | C3: 运单编号 | D3: 日期 | E3: 业务 | F3: 发货人 | G3: 收货人 | H3: 计费体积 | I3: 计费重量 | J3: 应 收 | Q3: 总应收 | R3: 起 运 港 成 本 | W3: 代垫运费 | X3: 起运港成本 合计 | Y3: 目的港成本 | AE3: 总支出 | AF3: 利润
J4: 应收RMB | K4: LOS Income(NGN)收到(奈拉) | L4: LOS 收到USD | M4: 美元汇率 dollar currency rate | N4: 应收 到付款USD | O4: 汇率 | P4: 人民币 | R4: 代理商 | S4: 运费+出口报关费 | T4: 提货费 | U4: 装卸费 | V4: 包装费 | Y4: 进口报关费 | Z4: 到门配送费 | AA4: 转运费 | AB4: 目的港支出 | AC4: 汇率 | AD4: 人民币 | AE4: 起运港+目的港
C5: 241025000058 | D5: 45601 | E5: 苏慧琪 | F5: KAY | G5: BOYOU 吕 | H5: 13.7 | I5: 2550 | K5: 7067746.5 | M5: 1648.8039 | N5: 4286.59 | O5: 7.29 | P5: 31249.241 | S5: 9915.2743 | T5: 22.895118 | U5: 483.52941 | X5: 10421.699 | Y5: 2206.0465 | Z5: 90.97 | AB5: 2297.0165 | AC5: 7.33 | AD5: 16837.131 | AE5: 27258.83 | AF5: 3990.4111
C6: 241105000054 | D6: 45608 | E6: 苏慧琪 | F6: KAY | G6: R李金 | H6: 0.3709 | I6: 167 | K6: 206012.98 | M6: 1664.8859 | N6: 123.74 | O6: 7.27 | P6: 899.5898 | S6: 290.27289 | U6: 10.663375 | X6: 300.93626 | Y6: 61.966699 | AA6: 0.29202921 | AB6: 62.258729 | AC6: 7.3 | AD6: 454.48872 | AE6: 755.42498 | AF6: 144.16482
C7: 241111000061 | D7: 45615 | E7: 苏慧琪 | F7: KAY | G7: xiaobai小白 | H7: 0.45 | I7: 124 | J7: 1257.4 | P7: 1257.4 | S7: 314.9239 | U7: 15.220588 | X7: 330.14449 | Y7: 73.356618 | Z7: 20.81 | AA7: 0.49711765 | AB7: 94.663735 | AC7: 7.3 | AD7: 691.04527 | AE7: 1021.1898 | AF7: 236.21025
A8: 合计 | H8: =SUM(H5:H7) -> 14.5209 | AF8: =SUM(AF5:AF7) -> 4370.7862
C10: 基本任务：小于6千 | F10: 不够基本任务6千， 公司将根据空运提成里抽出补足基数 | K10: 苏慧琪 提成
K11: 名称 | L11: 计费体积 | M11: 毛利
C12: 基本任务：6千-3.5万 | F12: 按40%提成 | K12: LOS | L12: =SUM(H8) -> 14.5209 | M12: =SUM(AF8) -> 4370.7862
K13: 基数
C14: 基本任务：3.5万以上 | F14: 按50%提成 | K14: 提成计数
K15: 提成点数
K16: 提成金额

Sheet 陆总
A1: LOS毛利表
A3: JOB | B3: 集装编号 | C3: 运单编号 | D3: 日期 | E3: 业务 | F3: 发货人 | G3: 收货人 | H3: 计费体积 | I3: 计费重量 | J3: 应 收 | Q3: 总应收 | R3: 起 运 港 成 本 | W3: 代垫运费 | X3: 起运港成本 合计 | Y3: 目的港成本 | AE3: 总支出 | AF3: 利润
J4: 应收RMB | K4: LOS Income(NGN)收到(奈拉) | L4: LOS 收到USD | M4: 美元汇率 dollar currency rate | N4: 应收 到付款USD | O4: 汇率 | P4: 人民币 | R4: 代理商 | S4: 运费+出口报关费 | T4: 提货费 | U4: 装卸费 | V4: 包装费 | Y4: 进口报关费 | Z4: 到门配送费 | AA4: 转运费 | AB4: 目的港支出 | AC4: 汇率 | AD4: 人民币 | AE4: 起运港+目的港
C5: 241209000060 | D5: 45601 | E5: 陆总 | F5: 陆梓龙 | G5: xinlong | H5: 17.902 | I5: 17472 | J5: 41296.32 | P5: 41296.32 | S5: 12956.441 | T5: 29.917401 | U5: 631.83529 | X5: 13618.194 | Y5: 2882.6748 | AB5: 2882.6748 | AC5: 7.33 | AD5: 21130.006 | AE5: 34748.2 | AF5: 6548.12
C6: 241101000057 | D6: 45602 | E6: 陆总 | F6: 陆梓龙 | G6: jizong | H6: 1.1063 | I6: 567 | J6: 2422.8 | P6: 2422.8 | S6: 793.74585 | U6: 29.284412 | X6: 823.03026 | Y6: 174.34735 | AA6: 0.82386812 | AB6: 175.17122 | AC6: 7.33 | AD6: 1284.005 | AE6: 2107.0353 | AF6: 315.76472
C7: 241105000024 | D7: 45608 | E7: 陆总 | F7: 陆梓龙 | G7: luk | H7: 2.0026 | I7: 262.5 | J7: 4385.69 | P7: 4385.69 | S7: 1567.2701 | U7: 57.57475 | X7: 1624.8448 | Y7: 334.57674 | AA7: 1.576753 | AB7: 336.15349 | AC7: 7.3 | AD7: 2453.9205 | AE7: 4078.7653 | AF7: 306.92467
C8: 241112000025 | D8: 45608 | E8: 陆总 | F8: 陆梓龙 | G8: xinlong | H8: 0.2838 | I8: 166 | J8: 621.3 | P8: 621.3 | S8: 222.10689 | U8: 8.15925 | X8: 230.26614 | Y8: 47.4148 | AA8: 0.22345076 | AB8: 47.638251 | AC8: 7.3 | AD8: 347.75923 | AE8: 578.02537 | AF8: 43.274632
C9: 241209000061 | D9: 45609 | E9: 陆总 | F9: 陆梓龙 | G9: xinlong | H9: 16.4369 | I9: 16042 | J9: 37916.64 | P9: 37916.64 | S9: 11313.18 | U9: 435.09441 | X9: 11748.274 | Y9: 2609.0847 | Z9: 162.02 | AA9: 22.958482 | AB9: 2794.0632 | AC9: 7.33 | AD9: 20480.483 | AE9: 32228.758 | AF9: 5687.8824
C10: 241118000073 | D10: 45615 | E10: 陆总 | F10: 陆梓龙 | G10: xiantian | H10: 10.1365 | I10: 5464 | J10: 21201.16 | P10: 21201.16 | S10: 7093.8357 | U10: 342.85221 | X10: 7436.6879 | Y10: 1652.3986 | AA10: 11.197851 | AB10: 1663.5964 | AC10: 7.3 | AD10: 12144.254 | AE10: 19580.942 | AF10: 1620.2182
C11: 241209000062 | D11: 45615 | E11: 陆总 | F11: 陆梓龙 | G11: xinlong | H11: 4.9817 | I11: 4862 | J11: 11334.38 | P11: 11334.38 | S11: 3486.3475 | U11: 168.49868 | X11: 3654.8462 | Y11: 812.09036 | Z11: 77.38 | AA11: 5.5033133 | AB11: 894.97367 | AC11: 7.3 | AD11: 6533.3078 | AE11: 10188.154 | AF11: 1146.226
C12: 241118000074 | D12: 45617 | E12: 陆总 | F12: 陆梓龙 | G12: jizong | H12: 4.524 | I12: 2048 | J12: 10687.32 | P12: 10687.32 | S12: 3046.282 | U12: 86.488235 | X12: 3132.7702 | Y12: 747.32488 | Z12: 262.87 | AA12: 13.96785 | AB12: 1024.1627 | AC12: 7.3 | AD12: 7476.3879 | AE12: 10609.158 | AF12: 78.161848
C13: 241127000027 | D13: 45623 | E13: 陆总 | F13: 陆梓龙 | G13: xiantian | H13: 3.145 | I13: 1753 | J13: 6114.46 | P13: 6114.46 | S13: 2175.3063 | U13: 87.875 | X13: 2263.1813 | Y13: 512.49625 | AA13: 2.4776125 | AB13: 514.97386 | AC13: 7.3 | AD13: 3759.3092 | AE13: 6022.4905 | AF13: 91.969491
A14: 合计 | H14: =SUM(H5:H13) -> 60.5188 | AF14: =SUM(AF5:AF13) -> 15838.542
C16: 基本任务：小于6千 | F16: 不够基本任务6千， 公司将根据空运提成里抽出补足基数 | K16: 陆总 提成
K17: 名称 | L17: 计费体积 | M17: 毛利
C18: 基本任务：6千-3.5万 | F18: 按40%提成 | K18: LOS | L18: =SUM(H14) -> 60.5188 | M18: =SUM(AF14) -> 15838.542
K19: 提成计数 | M19: =SUM(M18:M18) -> 15838.542
C20: 基本任务：3.5万以上 | F20: 按50%提成 | K20: 提成点数 | M20: 0.4
K21: 提成金额 | M21: =SUM(M19*M20) -> 6335.4168

Sheet 浦生
A1: LOS毛利表
A3: JOB | B3: 集装编号 | C3: 运单编号 | D3: 日期 | E3: 业务 | F3: 发货人 | G3: 收货人 | H3: 计费体积 | I3: 计费重量 | J3: 应 收 | Q3: 总应收 | R3: 起 运 港 成 本 | W3: 代垫运费 | X3: 起运港成本 合计 | Y3: 目的港成本 | AE3: 总支出 | AF3: 利润
J4: 应收RMB | K4: LOS Income(NGN)收到(奈拉) | L4: LOS 收到USD | M4: 美元汇率 dollar currency rate | N4: 应收 到付款USD | O4: 汇率 | P4: 人民币 | R4: 代理商 | S4: 运费+出口报关费 | T4: 提货费 | U4: 装卸费 | V4: 包装费 | Y4: 进口报关费 | Z4: 到门配送费 | AA4: 转运费 | AB4: 目的港支出 | AC4: 汇率 | AD4: 人民币 | AE4: 起运港+目的港
C5: 241028000036 | D5: 45601 | E5: Sam.Pao | F5: Sam.Pao | G5: Chizoba | H5: 19.1974 | I5: 2413 | J5: 38000 | P5: 38000 | S5: 13893.977 | T5: 32.082243 | U5: 677.55529 | X5: 14603.615 | Y5: 3091.267 | AB5: 3091.267 | AC5: 7.33 | AD5: 22658.987 | AE5: 37262.602 | AF5: 737.3984
A6: JOB120362 | B6: COLL004290 | C6: 241028000047 | D6: 45602 | E6: Sam.Pao | F6: Sam.Pao | G6: Nick Wang | H6: 3.0981 | I6: 231 | J6: 8037.16 | P6: 8037.16 | Q6: 15749.841 | R6: 登凯=46189.5 陆总=800 拖车费=1670 杂费=61 过磅费=68 | S6: 2222.8184 | U6: 82.008529 | X6: 2304.8269 | Y6: 488.24507 | AA6: 2.3071733 | AB6: 490.55224 | AC6: 7.33 | AD6: 3595.7479 | AE6: 5900.5749 | AF6: 2136.5851
C7: 241106000001 | D7: 45602 | E7: Sam.Pao | F7: Sam.Pao | G7: MaiKaiNian | H7: 0.4542 | I7: 69 | J7: 1060.98 | P7: 1060.98 | S7: 325.87848 | U7: 12.022941 | X7: 337.90142 | Y7: 71.579649 | AA7: 0.33824541 | AB7: 71.917894 | AC7: 7.33 | AD7: 527.15817 | AE7: 865.05959 | AF7: 195.92041
C8: 241106000002 | D8: 45602 | E8: Sam.Pao | F8: Sam.Pao | G8: Angel | H8: 0.3458 | I8: 98 | J8: 757 | P8: 757 | S8: 248.10387 | U8: 9.1535294 | X8: 257.2574 | Y8: 54.496351 | AA8: 0.25751929 | AB8: 54.75387 | AC8: 7.33 | AD8: 401.34587 | AE8: 658.60327 | AF8: 98.396729
C9: 241106000037 | D9: 45602 | E9: Sam.Pao | F9: Sam.Pao | G9: JunYue hotel | H9: 0.6996 | I9: 76 | J9: 1583.01 | P9: 1583.01 | S9: 501.94757 | U9: 18.518824 | X9: 520.46639 | Y9: 110.25346 | AA9: 0.52099624 | AB9: 110.77446 | AC9: 7.33 | AD9: 811.97678 | AE9: 1332.4432 | AF9: 250.56683
C10: 241024000054 | D10: 45608 | E10: Sam.Pao | F10: Sam.Pao | G10: ShanShan | H10: 16.835 | I10: 7500 | J10: 48779 | P10: 48779 | S10: 13175.368 | U10: 484.00625 | X10: 13659.374 | Y10: 2812.6433 | Z10: 97.38 | AA10: 13.255087 | AB10: 2923.2783 | AC10: 7.3 | AD10: 21339.932 | AE10: 34999.306 | AF10: 13779.694
C11: 241108000001 | D11: 45608 | E11: Sam.Pao | F11: Sam.Pao | G11: Mr. Jiang | H11: 1.6887 | I11: 558 | J11: 5053 | P11: 5053 | S11: 1321.6064 | U11: 48.550125 | X11: 1370.1565 | Y11: 282.1331 | Z11: 57.94 | AA11: 1.3296029 | AB11: 341.4027 | AC11: 7.3 | AD11: 2492.2397 | AE11: 3862.3962 | AF11: 1190.6038
C12: 241112000043 | D12: 45609 | E12: Sam.Pao | F12: Sam.Pao | G12: MaiKaiNian | H12: 4.9039 | I12: 546 | J12: 10739.54 | P12: 10739.54 | S12: 3375.2534 | U12: 129.80912 | X12: 3505.0625 | Y12: 778.41263 | AA12: 6.8495944 | AB12: 785.26223 | AC12: 7.33 | AD12: 5755.9721 | AE12: 9261.0347 | AF12: 1478.5053
C13: 241113000017 | D13: 45609 | E13: Sam.Pao | F13: Sam.Pao | G13: FanXiangGuo | H13: 1.4152 | I13: 656 | K13: 851651 | M13: 1671.5099 | N13: 509.51 | O13: 7.29 | P13: 3714.3279 | S13: 974.05302 | U13: 37.461176 | W13: 98.72 | X13: 1110.2342 | Y13: 224.63948 | AA13: 1.9767014 | AB13: 226.61618 | AC13: 7.33 | AD13: 1661.0966 | AE13: 2771.3308 | AF13: 942.99707
C14: 241116000018 | D14: 45615 | E14: Sam.Pao | F14: Sam.Pao | G14: MaiKaiNian | H14: 6.0469 | I14: 528 | J14: 13684.14 | P14: 13684.14 | S14: 4231.8074 | U14: 204.5275 | X14: 4436.3349 | Y14: 985.73362 | AA14: 6.680046 | AB14: 992.41367 | AC14: 7.3 | AD14: 7244.6198 | AE14: 11680.955 | AF14: 2003.1853
C15: 241118000049 | D15: 45616 | E15: Sam.Pao | F15: Sam.Pao | G15: Mr LiuQiSheng | H15: 18.8558 | I15: 3372 | J15: 41577.26 | P15: 41577.26 | S15: 12668.186 | U15: 554.58235 | X15: 13222.768 | Y15: 3073.7727 | AA15: 21.456791 | AB15: 3095.2295 | AC15: 7.3 | AD15: 22595.175 | AE15: 35817.944 | AF15: 5759.3164
C16: 241118000049 | D16: 45617 | E16: Sam.Pao | F16: Sam.Pao | G16: Mr LiuQiSheng | H16: 18.8558 | I16: 3470 | J16: 41577.26 | P16: 41577.26 | S16: 12696.747 | U16: 360.47853 | X16: 13057.226 | Y16: 3114.8118 | Z16: 1481.48 | AA16: 58.217283 | AB16: 4654.5091 | AC16: 7.3 | AD16: 33977.916 | AE16: 47035.142 | AF16: -5457.8818
C17: 241023000034 | D17: 45617 | E17: Sam.Pao | F17: Sam.Pao | G17: Nick Wang | H17: 0.535 | I17: 223 | J17: 1547 | P17: 1547 | S17: 360.24776 | U17: 10.227941 | X17: 370.4757 | Y17: 88.377279 | AA17: 1.6518125 | AB17: 90.029092 | AC17: 7.3 | AD17: 657.21237 | AE17: 1027.6881 | AF17: 519.31193
C18: 241115000013 | D18: 45617 | E18: Sam.Pao | F18: Sam.Pao | G18: ChenGaoHong | H18: 0.0579 | I18: 37 | J18: 123 | P18: 123 | S18: 38.987561 | U18: 1.1069118 | X18: 40.094473 | Y18: 9.5645691 | AA18: 0.17876625 | AB18: 9.7433354 | AC18: 7.3 | AD18: 71.126348 | AE18: 111.22082 | AF18: 11.779179
C19: 241120000029 | D19: 45623 | E19: Sam.Pao | F19: Sam.Pao | G19: Nick Wang | H19: 1.1485 | I19: 243 | J19: 4092.46 | P19: 4092.46 | S19: 794.38452 | U19: 32.090441 | V19: 230 | W19: 408 | X19: 1464.475 | Y19: 187.15483 | Z19: 67.46 | AA19: 0.90478154 | AB19: 255.51961 | AC19: 7.3 | AD19: 1865.2932 | AE19: 3329.7681 | AF19: 762.69187
C20: 241121000012 | D20: 45623 | E20: Sam.Pao | F20: Sam.Pao | G20: AiGeLi | H20: 21.5631 | I20: 10414 | J20: 62286 | P20: 62286 | S20: 14914.578 | U20: 602.49838 | V20: 800 | X20: 16317.076 | Y20: 3513.834 | Z20: 902.53 | AA20: 16.987283 | AB20: 4433.3513 | AC20: 7.3 | AD20: 32363.464 | AE20: 48680.541 | AF20: 13605.459
A21: 合计 | H21: =SUM(H5:H20) -> 115.7009 | AF21: =SUM(AF5:AF20) -> 38014.53
C23: 基本任务：小于6千 | F23: 不够基本任务6千， 公司将根据空运提成里抽出补足基数 | K23: 浦生 提成
K24: 名称 | L24: 计费体积 | M24: 毛利
C25: 基本任务：6千-3.5万 | F25: 按40%提成 | K25: LOS | L25: =SUM(H21) -> 115.7009 | M25: =SUM(AF21) -> 38014.53
K26: 任务 | M26: 6000
C27: 基本任务：3.5万以上 | F27: 按50%提成 | K27: 提成计数 | M27: =SUM(M25-M26) -> 32014.53
K28: 基数 | M28: 35000
K29: 提成计数40% | M29: 0.4
K30: 提成金额 | M30: =SUM(M28*M29) -> 14000
K31: 实提成计数
K32: 提成点数50%
K33: 提成金额
K34: 合计提成金额

Sheet 无人
A1: LOS毛利表
A3: JOB | B3: 集装编号 | C3: 运单编号 | D3: 日期 | E3: 业务 | F3: 发货人 | G3: 收货人 | H3: 计费体积 | I3: 计费重量 | J3: 应 收 | Q3: 总应收 | R3: 起 运 港 成 本 | W3: 代垫运费 | X3: 起运港成本 合计 | Y3: 目的港成本 | AE3: 总支出 | AF3: 利润
J4: 应收RMB | K4: LOS Income(NGN)收到(奈拉) | L4: LOS 收到USD | M4: 美元汇率 dollar currency rate | N4: 应收 到付款USD | O4: 汇率 | P4: 人民币 | R4: 代理商 | S4: 运费+出口报关费 | T4: 提货费 | U4: 装卸费 | V4: 包装费 | Y4: 进口报关费 | Z4: 到门配送费 | AA4: 转运费 | AB4: 目的港支出 | AC4: 汇率 | AD4: 人民币 | AE4: 起运港+目的港
C5: 241111000039 | D5: 45609 | E5: 无人 | F5: dejare James | G5: James | H5: 1.8662 | I5: 626 | L5: 559.83 | M5: 0 | N5: 559.82996 | O5: 7.3 | P5: 4086.7587 | S5: 1284.467 | U5: 49.399412 | X5: 1333.8664 | Y5: 296.22824 | AA5: 2.6066423 | AB5: 298.83488 | AC5: 7.33 | AD5: 2190.4597 | AE5: 3524.3261 | AF5: 562.43258
C6: 241125000066 | D6: 45623 | E6: 无人 | F6: dejare James | G6: James | H6: 0.151 | I6: 45 | K6: 76000 | M6: 1677.7041 | N6: 45.300003 | O6: 7.2 | P6: 326.16002 | S6: 104.44237 | U6: 4.2191176 | X6: 108.66149 | Y6: 24.606338 | AA6: 0.11895691 | AB6: 24.725295 | AC6: 7.3 | AD6: 180.49465 | AE6: 289.15614 | AF6: 37.00388
A7: 合计 | H7: =SUM(H5:H6) -> 2.0172 | AF7: =SUM(AF5:AF6) -> 599.43646
C9: 基本任务：小于6千 | F9: 不够基本任务6千， 公司将根据空运提成里抽出补足基数 | K9: 无人 提成
K10: 名称 | L10: 计费体积 | M10: 毛利
C11: 基本任务：6千-3.5万 | F11: 按40%提成 | K11: LOS | L11: =SUM(H7) -> 2.0172 | M11: =SUM(AF7) -> 599.43646
K12: 基数
C13: 基本任务：3.5万以上 | F13: 按50%提成 | K13: 提成计数
K14: 提成点数
K15: 提成金额

Sheet 提成总表
A1: 24年11月份业务员提成总表-68³
A3: 名称 姓名 | B3: LOS毛利 | C3: 计费体积 立方 | D3: 6千-3.5万 | I3: 3.5万以上 | M3: 合计 提成金额 | N3: 备注 | P3: 基本任务：小于6千 | R3: 不够基本任务6千， 公司将根据空运提成里抽出补足基数
D4: 基数 | E4: 提成计数 | F4: 提成计数 | G4: 提成点 数40% | H4: 提成金额 | I4: 基数 | J4: 提成计数 | K4: 提成点 数50% | L4: 提成金额
A5: 黄 颖 | B5: =SUM(黄颖!M44) -> 30842.58 | C5: =SUM(黄颖!L44) -> 82.62 | D5: 6000 | E5: =SUM(B5-D5) -> 24842.58 | G5: 0.4 | H5: =SUM(E5*G5) -> 9937.0319 | M5: =SUM(H5+L5) -> 9937.0319 | P5: 基本任务：6千-3.5万 | R5: 按40%提成
A6: 陈三凤 | B6: =SUM(三凤!M16) -> 4957.5137 | C6: =SUM(三凤!L16) -> 58.0686 | D6: 3000 | E6: =SUM(B6-D6) -> 1957.5137 | G6: 0.15 | H6: =SUM(E6*G6) -> 293.62705 | M6: =SUM(H6+L6) -> 293.62705 | N6: 小飞10-11月份原方案15% （zhong zi xin利润的一半3742.51）
A7: 朱小飞 | B7: =SUM(朱小飞!M32) -> 7677.7373 | C7: =SUM(朱小飞!L32) -> 21.9695 | D7: 3000 | E7: =SUM(B7-D7) -> 4677.7373 | G7: 0.15 | H7: =SUM(E7*G7) -> 701.66059 | M7: =SUM(H7+L7) -> 701.66059 | N7: 小飞10-11月份原方案15% （Halifa利润的一半1045.81） | P7: 基本任务：3.5万以上 | R7: 按50%提成
A8: 吕沛霖 | B8: =SUM(吕沛霖!M23) -> 9163.0349 | C8: =SUM(吕沛霖!L23) -> 29.4541 | D8: 6000 | E8: =SUM(B8-D8) -> 3163.0349 | G8: 0.4 | H8: =SUM(E8*G8) -> 1265.2139 | M8: =SUM(H8+L8) -> 1265.2139
A9: 陆总 | B9: =SUM(陆总!M18) -> 15838.542 | C9: =SUM(陆总!L18) -> 60.5188 | G9: 0.4 | H9: =SUM(B9*G9) -> 6335.4168 | M9: =SUM(H9+L9) -> 6335.4168
A10: 苏慧琪 | B10: =SUM(苏慧琪!M12) -> 4370.7862 | C10: =SUM(苏慧琪!L12) -> 14.5209 | P10: 领款人：
A11: 罗珮文 | B11: =SUM(罗珮文!M39) -> -56269.928 | C11: =SUM(罗珮文!L39) -> 196.2159 | P11: 日期：
A12: 浦海森 | B12: =SUM(浦生!M25) -> 38014.53 | C12: =SUM(浦生!L25) -> 115.7009 | D12: 6000 | E12: =SUM(B12-D12) -> 32014.53 | F12: 35000 | G12: 0.4 | H12: =SUM(F12*G12) -> 14000 | M12: =SUM(H12+L12) -> 14000
A13: 无人 | B13: =SUM(无人!M11) -> 599.43646 | C13: =SUM(无人!L11) -> 2.0172
A14: 合计 | B14: =SUM(B5:B12) -> 54594.795 | C14: =SUM(C5:C12) -> 579.0687 | M14: =SUM(M5:M12) -> 32532.95
A16: 确认人： | J16: 日期：

Sheet 黄颖 陈三凤 朱小飞 吕沛霖 2025年10份发放
A1: 24年11月份业务员提成总表-68³
A3: 名称 姓名 | B3: LOS毛利 | C3: 计费体积 立方 | D3: 6千-3.5万 | I3: 3.5万以上 | M3: 合计 提成金额 | N3: 备注
D4: 基数 | E4: 提成计数 | F4: 提成计数 | G4: 提成点 数40% | H4: 提成金额 | I4: 基数 | J4: 提成计数 | K4: 提成点 数50% | L4: 提成金额
A5: 黄 颖 | B5: =SUM(黄颖!M44) -> 30842.58 | C5: =SUM(黄颖!L44) -> 82.62 | D5: 6000 | E5: =SUM(B5-D5) -> 24842.58 | G5: 0.4 | H5: =SUM(E5*G5) -> 9937.0319 | M5: =SUM(H5+L5) -> 9937.0319
L6: 领款人：
A7: 陈三凤 | B7: =SUM(三凤!M16) -> 4957.5137 | C7: =SUM(三凤!L16) -> 58.0686 | D7: 3000 | E7: =SUM(B7-D7) -> 1957.5137 | G7: 0.15 | H7: =SUM(E7*G7) -> 293.62705 | M7: =SUM(H7+L7) -> 293.62705 | N7: 小飞10-11月份原方案15% （zhong zi xin利润的一半3742.51）
L8: 领款人：
A9: 朱小飞 | B9: =SUM(朱小飞!M32) -> 7677.7373 | C9: =SUM(朱小飞!L32) -> 21.9695 | D9: 3000 | E9: =SUM(B9-D9) -> 4677.7373 | G9: 0.15 | H9: =SUM(E9*G9) -> 701.66059 | M9: =SUM(H9+L9) -> 701.66059 | N9: 小飞10-11月份原方案15% （Halifa利润的一半1045.81）
L10: 领款人：
A11: 吕沛霖 | B11: =SUM(吕沛霖!M23) -> 9163.0349 | C11: =SUM(吕沛霖!L23) -> 29.4541 | D11: 6000 | E11: =SUM(B11-D11) -> 3163.0349 | G11: 0.4 | H11: =SUM(E11*G11) -> 1265.2139 | M11: =SUM(H11+L11) -> 1265.2139
L12: 领款人：
A13: 合计 | B13: =SUM(B5:B11) -> 52640.866 | C13: =SUM(C5:C11) -> 192.1122 | M13: =SUM(M5:M11) -> 12197.534
A15: 确认人： | J15: 日期：
