Workbook

Sheet 总表 
A1: 2024年10月份LOS毛利表（海运）
A2: JOB | B2: 集装编号 | C2: 利润
A4: JOB100358 | B4: COLL004182 | C4: =SUM('JOB100358'!AF26) -> 19174.556
A25: JOB100359 | B25: COLL004278 | C25: =SUM('JOB100359'!AF15) -> 12918.367
A35: JOB100360 | B35: COLL004247 | C35: =SUM('JOB100360'!AF15) -> 21765.368
A45: JOB100361 | B45: COLL004248 | C45: =SUM('JOB100361'!AF23) -> -2488.9901
A63: JOB100331 | B63: COLL004195 | C63: =SUM('JOB100331'!AF31) -> 15990.29
A89: JOB100362 | B89: COLL004260 | C89: =SUM('JOB100362'!AF26) -> 9117.6077
A110: JOB100363 | B110: COLL004265 | C110: =SUM('JOB100363'!AF30) -> 36506.369
A135: JOB100364 | B135: COLL004268 | C135: =SUM('JOB100364'!AF25) -> 15930.088
A155: JOB100365 | B155: COLL004270 | C155: =SUM('JOB100365'!AF14) -> -6520.687
A164: JOB100366 | B164: COLL004269 | C164: =SUM('JOB100366'!AF15) -> -1425.4322
A175: JOB120359 | B175: COLL004280 | C175: =SUM('JOB120359'!AF5) -> 11665.491
A176: 合计 | C176: =SUM(C3:C175) -> 132633.03

Sheet 总表  (2)
A1: 2024年10月份LOS毛利表（海运）
A2: JOB | B2: 集装编号 | C2: 运单编号 | D2: 日期 | E2: 业务 | F2: 发货人 | G2: 收货人 | H2: 计费体积 | I2: 计费重量 | J2: 应 收 | Q2: 总应收 | R2: 起 运 港 成 本 | W2: 代垫运费 | X2: 起运港成本 合计 | Y2: 目的港成本 | AE2: 总支出 | AF2: 利润
J3: 应收RMB | K3: LOS Income(NGN)收到(奈拉) | L3: LOS 收到USD | M3: 美元汇率 dollar currency rate | N3: 应收 到付款USD | O3: 汇率 | P3: 人民币 | R3: 代理商 | S3: 运费+出口报关费 | T3: 提货费 | U3: 装卸费 | V3: 包装费 | Y3: 进口报关费 | Z3: 到门配送费 | AA3: 转运费 | AB3: 目的港支出 | AC3: 汇率 | AD3: 人民币 | AE3: 起运港+目的港
A4: JOB100358 | B4: COLL004182 | C4: 240907000011 | D4: 45563 | E4: 吕沛霖 | F4: 喵喵速运-Layne | G4: MA ZONG | H4: 0.4074 | I4: 404 | J4: 1549.3 | P4: =SUBTOTAL(9,J4) -> 1549.3 | Q4: =SUM(P4:P24) -> 163992.94 | R4: 登凯=36617 赛捷=1660 拖车费=1670 杂费=499 过磅费=69 | S4: =SUM(40515/68)*H4 -> 242.73251 | U4: =SUM(2200/68)*H4 -> 13.180588 | X4: =SUM(S4:W4) -> 255.9131 | Y4: =SUM(10381.23/68)*H4 -> 62.195781 | Z4: 48.54 | AB4: =SUM(Y4:AA4) -> 110.73578 | AC4: 7.23 | AD4: =SUM(AB4*AC4) -> 800.6197 | AE4: =SUM(X4+AD4) -> 1056.5328 | AF4: =SUM(P4-AE4) -> 492.7672
C5: 240909000011 | D5: 45563 | E5: 黄颖 | F5: ying | G5: ying | H5: 0.036 | I5: 12 | K5: 87324 | M5: =SUM(K5/N5) -> 5916.2594 | N5: 14.760002 | O5: 7.24 | P5: =SUM(N5*O5) -> 106.86241 | S5: =SUM(40515/68)*H5 -> 21.449118 | U5: =SUM(2200/68)*H5 -> 1.1647059 | X5: =SUM(S5:W5) -> 22.613824 | Y5: =SUM(10381.23/68)*H5 -> 5.4959453 | Z5: 0.54 | AB5: =SUM(Y5:AA5) -> 6.0359453 | AC5: 7.23 | AD5: =SUM(AB5*AC5) -> 43.639884 | AE5: =SUM(X5+AD5) -> 66.253708 | AF5: =SUM(P5-AE5) -> 40.608706
C6: 240915000027 | D6: 45563 | E6: 吕沛霖 | F6: 喵喵速运-Layne | G6: Gao Hui | H6: 0.554 | I6: 177 | J6: 1986.97 | P6: =SUM(J6) -> 1986.97 | S6: =SUM(40515/68)*H6 -> 330.07809 | U6: =SUM(2200/68)*H6 -> 17.923529 | V6: 60 | X6: =SUM(S6:W6) -> 408.00162 | Y6: =SUM(10381.23/68)*H6 -> 84.576491 | Z6: 83.97 | AB6: =SUM(Y6:AA6) -> 168.54649 | AC6: 7.23 | AD6: =SUM(AB6*AC6) -> 1218.5911 | AE6: =SUM(X6+AD6) -> 1626.5928 | AF6: =SUM(P6-AE6) -> 360.37725
C7: 240919000042 | D7: 45563 | E7: 黄颖 | F7: ying | G7: MISS Huang | H7: 0.2211 | I7: 118 | J7: 468.7 | P7: =SUBTOTAL(9,J7) -> 468.7 | S7: =SUM(40515/68)*H7 -> 131.73333 | U7: =SUM(2200/68)*H7 -> 7.1532353 | X7: =SUM(S7:W7) -> 138.88657 | Y7: =SUM(10381.23/68)*H7 -> 33.754264 | AB7: =SUM(Y7:AA7) -> 33.754264 | AC7: 7.23 | AD7: =SUM(AB7*AC7) -> 244.04333 | AE7: =SUM(X7+AD7) -> 382.9299 | AF7: =SUM(P7-AE7) -> 85.770105
C8: 240920000027 | D8: 45563 | E8: 吕沛霖 | F8: 喵喵速运-Layne | G8: YA | H8: 1.1252 | I8: 111 | J8: 3500.8 | P8: =SUBTOTAL(9,J8) -> 3500.8 | S8: =SUM(40515/68)*H8 -> 670.40409 | U8: =SUM(2200/68)*H8 -> 36.403529 | X8: =SUM(S8:W8) -> 706.80762 | Y8: =SUM(10381.23/68)*H8 -> 171.77882 | Z8: 8.31 | AA8: 117.69 | AB8: =SUM(Y8:AA8) -> 297.77882 | AC8: 7.23 | AD8: =SUM(AB8*AC8) -> 2152.9409 | AE8: =SUM(X8+AD8) -> 2859.7485 | AF8: =SUM(P8-AE8) -> 641.05149
C9: 240920000030 | D9: 45563 | E9: 黄颖 | F9: ying | G9: baikaibo | H9: 0.319 | I9: 321 | K9: 385317 | M9: =SUM(K9/N9) -> 1767.347 | N9: 218.02 | O9: 7.24 | P9: =SUM(N9*O9) -> 1578.4648 | S9: =SUM(40515/68)*H9 -> 190.06301 | U9: =SUM(2200/68)*H9 -> 10.320588 | X9: =SUM(S9:W9) -> 200.3836 | Y9: =SUM(10381.23/68)*H9 -> 48.700182 | Z9: 85.03 | AB9: =SUM(Y9:AA9) -> 133.73018 | AC9: 7.23 | AD9: =SUM(AB9*AC9) -> 966.86922 | AE9: =SUM(X9+AD9) -> 1167.2528 | AF9: =SUM(P9-AE9) -> 411.21198
C10: 240923000009 | D10: 45563 | E10: 朱小飞 | F10: Isabel Zhu | G10: Wu Jiao Xing | H10: 0.5281 | I10: 104.5 | K10: 313621.07 | M10: =SUM(K10/N10) -> 1855.8559 | N10: 168.98999 | O10: 7.26 | P10: =SUM(N10*O10) -> 1226.8673 | S10: =SUM(40515/68)*H10 -> 314.64664 | U10: =SUM(2200/68)*H10 -> 17.085588 | X10: =SUM(S10:W10) -> 331.73223 | Y10: =SUM(10381.23/68)*H10 -> 80.622464 | AB10: =SUM(Y10:AA10) -> 80.622464 | AC10: 7.23 | AD10: =SUM(AB10*AC10) -> 582.90042 | AE10: =SUM(X10+AD10) -> 914.63264 | AF10: =SUM(P10-AE10) -> 312.23468
C11: 240923000035 | D11: 45547 | E11: 黄颖 | F11: ying | G11: Bruce | H11: 1.0584 | I11: 465 | J11: 2082 | P11: =SUBTOTAL(9,J11) -> 2082 | S11: =SUM(40515/68)*H11 -> 630.60406 | U11: =SUM(2200/68)*H11 -> 34.242353 | X11: =SUM(S11:W11) -> 664.84641 | Y11: =SUM(10381.23/68)*H11 -> 161.58079 | AB11: =SUM(Y11:AA11) -> 161.58079 | AC11: 7.23 | AD11: =SUM(AB11*AC11) -> 1168.2291 | AE11: =SUM(X11+AD11) -> 1833.0755 | AF11: =SUM(P11-AE11) -> 248.92446
C12: 240923000047 | D12: 45563 | E12: 吕沛霖 | F12: 喵喵速运-Layne | G12: WYLB | H12: 0.8 | I12: 197 | K12: 390880 | M12: =SUM(K12/N12) -> 1744.9998 | N12: 224.00003 | O12: 7.21 | P12: =SUM(N12*O12) -> 1615.0402 | S12: =SUM(40515/68)*H12 -> 476.64706 | U12: =SUM(2200/68)*H12 -> 25.882353 | X12: =SUM(S12:W12) -> 502.52941 | Y12: =SUM(10381.23/68)*H12 -> 122.13212 | AB12: =SUM(Y12:AA12) -> 122.13212 | AC12: 7.23 | AD12: =SUM(AB12*AC12) -> 883.01521 | AE12: =SUM(X12+AD12) -> 1385.5446 | AF12: =SUM(P12-AE12) -> 229.49559
C13: 240924000001 | D13: 45563 | E13: Sam.Pao | F13: Sam.Pao | G13: Yusky | H13: 8.51 | I13: 209 | J13: 14859.77 | P13: =SUBTOTAL(9,J13) -> 14859.77 | S13: =SUM(40515/68)*H13 -> 5070.3331 | U13: =SUM(2200/68)*H13 -> 275.32353 | X13: =SUM(S13:W13) -> 5345.6566 | Y13: =SUM(10381.23/68)*H13 -> 1299.1804 | AB13: =SUM(Y13:AA13) -> 1299.1804 | AC13: 7.23 | AD13: =SUM(AB13*AC13) -> 9393.0743 | AE13: =SUM(X13+AD13) -> 14738.731 | AF13: =SUM(P13-AE13) -> 121.03908
C14: 240925000028 | D14: 45563 | E14: 朱小飞 | F14: Isabel Zhu | G14: Halifa Success | H14: 1.2354 | I14: 125 | J14: 2382.35 | P14: =SUBTOTAL(9,J14) -> 2382.35 | S14: =SUM(40515/68)*H14 -> 736.06222 | U14: =SUM(2200/68)*H14 -> 39.968824 | X14: =SUM(S14:W14) -> 776.03104 | Y14: =SUM(10381.23/68)*H14 -> 188.60252 | AB14: =SUM(Y14:AA14) -> 188.60252 | AC14: 7.23 | AD14: =SUM(AB14*AC14) -> 1363.5962 | AE14: =SUM(X14+AD14) -> 2139.6273 | AF14: =SUM(P14-AE14) -> 242.72272
C15: 240926000027 | D15: 45563 | E15: Sam.Pao | F15: Sam.Pao | G15: ShanShan | H15: 1.555 | I15: 237 | J15: 3879 | P15: =SUBTOTAL(9,J15) -> 3879 | S15: =SUM(40515/68)*H15 -> 926.48272 | U15: =SUM(2200/68)*H15 -> 50.308824 | X15: =SUM(S15:W15) -> 976.79154 | Y15: =SUM(10381.23/68)*H15 -> 237.3943 | Z15: 36.85 | AB15: =SUM(Y15:AA15) -> 274.2443 | AC15: 7.23 | AD15: =SUM(AB15*AC15) -> 1982.7863 | AE15: =SUM(X15+AD15) -> 2959.5779 | AF15: =SUM(P15-AE15) -> 919.42214
C16: 240924000057 | D16: 45564 | E16: Sam.Pao | F16: Sam.Pao | G16: Arni | H16: 5.543 | I16: 3101 | J16: 12233 | P16: =SUBTOTAL(9,J16) -> 12233 | S16: =SUM(40515/68)*H16 -> 3302.5683 | U16: =SUM(2200/68)*H16 -> 179.33235 | X16: =SUM(S16:W16) -> 3481.9007 | Y16: =SUM(10381.23/68)*H16 -> 846.22291 | AB16: =SUM(Y16:AA16) -> 846.22291 | AC16: 7.23 | AD16: =SUM(AB16*AC16) -> 6118.1916 | AE16: =SUM(X16+AD16) -> 9600.0923 | AF16: =SUM(P16-AE16) -> 2632.9077
C17: 240906000023 | D17: 45559 | E17: Sam.Pao | F17: Sam.Pao | G17: ChenGaoHong | H17: 33.5175 | I17: 8313 | J17: 68845 | P17: =SUBTOTAL(9,J17) -> 68845 | S17: =SUM(40515/68)*H17 -> 19970.022 | U17: =SUM(2200/68)*H17 -> 1084.3897 | X17: =SUM(S17:W17) -> 21054.412 | Y17: =SUM(10381.23/68)*H17 -> 5116.9541 | AB17: =SUM(Y17:AA17) -> 5116.9541 | AC17: 7.23 | AD17: =SUM(AB17*AC17) -> 36995.578 | AE17: =SUM(X17+AD17) -> 58049.99 | AF17: =SUM(P17-AE17) -> 10795.01
C18: 240927000007 | D18: 45563 | E18: 黄颖 | F18: ying | G18: MISS Huang | H18: 1.745 | I18: 656 | J18: 3441 | P18: =SUBTOTAL(9,J18) -> 3441 | S18: =SUM(40515/68)*H18 -> 1039.6864 | U18: =SUM(2200/68)*H18 -> 56.455882 | X18: =SUM(S18:W18) -> 1096.1423 | Y18: =SUM(10381.23/68)*H18 -> 266.40068 | AB18: =SUM(Y18:AA18) -> 266.40068 | AC18: 7.23 | AD18: =SUM(AB18*AC18) -> 1926.0769 | AE18: =SUM(X18+AD18) -> 3022.2192 | AF18: =SUM(P18-AE18) -> 418.78079
C19: 240927000017 | D19: 45563 | E19: 朱小飞 | F19: Isabel Zhu | G19: Lin Bao Zhen | H19: 1.1235 | I19: 241 | K19: 594820.8 | M19: =SUM(K19/N19) -> 1891.0213 | N19: 314.55002 | O19: 7.26 | P19: =SUM(N19*O19) -> 2283.6331 | S19: =SUM(40515/68)*H19 -> 669.39121 | U19: =SUM(2200/68)*H19 -> 36.348529 | X19: =SUM(S19:W19) -> 705.73974 | Y19: =SUM(10381.23/68)*H19 -> 171.51929 | AB19: =SUM(Y19:AA19) -> 171.51929 | AC19: 7.23 | AD19: =SUM(AB19*AC19) -> 1240.0845 | AE19: =SUM(X19+AD19) -> 1945.8242 | AF19: =SUM(P19-AE19) -> 337.80892
C20: 240927000029 | D20: 45563 | E20: 朱小飞 | F20: Isabel Zhu | G20: Joy | H20: 1.7289 | I20: 1316 | K20: 1061222.4 | M20: =SUM(K20/N20) -> 1612.7994 | N20: 658.00024 | O20: 7.26 | P20: =SUM(N20*O20) -> 4777.0817 | S20: =SUM(40515/68)*H20 -> 1030.0939 | U20: =SUM(2200/68)*H20 -> 55.935 | X20: =SUM(S20:W20) -> 1086.0289 | Y20: =SUM(10381.23/68)*H20 -> 263.94277 | Z20: 7.97 | AB20: =SUM(Y20:AA20) -> 271.91277 | AC20: 7.23 | AD20: =SUM(AB20*AC20) -> 1965.9293 | AE20: =SUM(X20+AD20) -> 3051.9582 | AF20: =SUM(P20-AE20) -> 1725.1235
C21: 240921000019 | D21: 45563 | E21: 陆总 | F21: 陆梓龙 | G21: xiantian | H21: 0.3318 | I21: 185 | J21: 678.17 | P21: =SUBTOTAL(9,J21) -> 678.17 | S21: =SUM(40515/68)*H21 -> 197.68937 | U21: =SUM(2200/68)*H21 -> 10.734706 | X21: =SUM(S21:W21) -> 208.42407 | Y21: =SUM(10381.23/68)*H21 -> 50.654296 | AB21: =SUM(Y21:AA21) -> 50.654296 | AC21: 7.23 | AD21: =SUM(AB21*AC21) -> 366.23056 | AE21: =SUM(X21+AD21) -> 574.65463 | AF21: =SUM(P21-AE21) -> 103.51537
C22: 240927000032 | D22: 45563 | E22: 罗珮文 | F22: Shirley | G22: Yusky | H22: 0.4929 | I22: 47.1 | J22: 860.11 | P22: =SUBTOTAL(9,J22) -> 860.11 | S22: =SUM(40515/68)*H22 -> 293.67417 | U22: =SUM(2200/68)*H22 -> 15.946765 | X22: =SUM(S22:W22) -> 309.62093 | Y22: =SUM(10381.23/68)*H22 -> 75.248651 | AB22: =SUM(Y22:AA22) -> 75.248651 | AC22: 7.23 | AD22: =SUM(AB22*AC22) -> 544.04775 | AE22: =SUM(X22+AD22) -> 853.66868 | AF22: =SUM(P22-AE22) -> 6.4413196
C23: 240927000070 | D23: 45563 | E23: 陆总 | F23: 陆梓龙 | G23: xinlong | H23: 17.4127 | I23: 10650 | J23: 29515.58 | P23: =SUBTOTAL(9,J23) -> 29515.58 | S23: =SUM(40515/68)*H23 -> 10374.64 | U23: =SUM(2200/68)*H23 -> 563.35206 | X23: =SUM(S23:W23) -> 10937.992 | Y23: =SUM(10381.23/68)*H23 -> 2658.3124 | Z23: 85.88 | AB23: =SUM(Y23:AA23) -> 2744.1924 | AC23: 7.23 | AD23: =SUM(AB23*AC23) -> 19840.511 | AE23: =SUM(X23+AD23) -> 30778.503 | AF23: =SUM(P23-AE23) -> -1262.9235
C24: 240928000018 | D24: 45563 | E24: 陆总 | F24: 陆梓龙 | G24: leoluang | H24: 3.3552 | I24: 1105 | J24: 6123.24 | P24: =SUBTOTAL(9,J24) -> 6123.24 | S24: =SUM(40515/68)*H24 -> 1999.0578 | U24: =SUM(2200/68)*H24 -> 108.55059 | X24: =SUM(S24:W24) -> 2107.6084 | Y24: =SUM(10381.23/68)*H24 -> 512.2221 | AB24: =SUM(Y24:AA24) -> 512.2221 | AC24: 7.23 | AD24: =SUM(AB24*AC24) -> 3703.3658 | AE24: =SUM(X24+AD24) -> 5810.9741 | AF24: =SUM(P24-AE24) -> 312.26585
A25: JOB100359 | B25: COLL004278 | C25: 240919000034 | D25: 45563 | E25: 朱小飞 | F25: Isabel Zhu | G25: Wu Jiao Xing | H25: 0.8132 | I25: 104 | K25: 607758.93 | M25: =SUM(K25/N25) -> 1737 | N25: 349.89 | O25: 7.26 | P25: =SUM(N25*O25) -> 2540.2014 | Q25: =SUM(P25:P34) -> 148903 | R25: 登凯=39001 赛捷=1660 | S25: =SUM(40661/68)*H25 -> 486.25772 | T25: =SUM(94.72/68)*H25 -> 1.1327398 | U25: =SUM(2000/68)*H25 -> 23.917647 | V25: 420 | X25: =SUM(S25:W25) -> 931.30811 | Y25: =SUM(10381.24/68)*H25 -> 124.14742 | AB25: =SUM(Y25:AA25) -> 124.14742 | AC25: 7.24 | AD25: =SUM(AB25*AC25) -> 898.8273 | AE25: =SUM(X25+AD25) -> 1830.1354 | AF25: =SUM(P25-AE25) -> 710.06599
C26: 240921000009 | D26: 45563 | E26: 苏慧琪 | F26: KAY | G26: OKECHUKWU | H26: 0.075 | I26: 19 | J26: 318 | P26: =SUM(J26) -> 318 | S26: =SUM(40661/68)*H26 -> 44.846691 | T26: =SUM(94.72/68)*H26 -> 0.10447059 | U26: =SUM(2000/68)*H26 -> 2.2058824 | X26: =SUM(S26:W26) -> 47.157044 | Y26: =SUM(10381.24/68)*H26 -> 11.449897 | AB26: =SUM(Y26:AA26) -> 11.449897 | AC26: 7.24 | AD26: =SUM(AB26*AC26) -> 82.897255 | AE26: =SUM(X26+AD26) -> 130.0543 | AF26: =SUM(P26-AE26) -> 187.9457
C27: 240921000019 | D27: 45563 | E27: 陆总 | F27: 陆梓龙 | G27: xiantian | H27: 10.1452 | I27: 2149.35 | J27: 20732 | P27: =SUBTOTAL(9,J27) -> 20732 | S27: =SUM(40661/68)*H27 -> 6066.382 | T27: =SUM(94.72/68)*H27 -> 14.131667 | U27: =SUM(2000/68)*H27 -> 298.38824 | V27: =SUM(450+350) -> 800 | X27: =SUM(S27:W27) -> 7178.9019 | Y27: =SUM(10381.24/68)*H27 -> 1548.8199 | AB27: =SUM(Y27:AA27) -> 1548.8199 | AC27: 7.24 | AD27: =SUM(AB27*AC27) -> 11213.456 | AE27: =SUM(X27+AD27) -> 18392.358 | AF27: =SUM(P27-AE27) -> 2339.6417
C28: 240923000035 | D28: 45563 | E28: 黄颖 | F28: ying | G28: Bruce | H28: 7.0714 | I28: 3083 | J28: 13913.3 | P28: =SUBTOTAL(9,J28) -> 13913.3 | S28: =SUM(40661/68)*H28 -> 4228.3852 | T28: =SUM(94.72/68)*H28 -> 9.8500442 | U28: =SUM(2000/68)*H28 -> 207.98235 | X28: =SUM(S28:W28) -> 4446.2176 | Y28: =SUM(10381.24/68)*H28 -> 1079.5574 | AB28: =SUM(Y28:AA28) -> 1079.5574 | AC28: 7.24 | AD28: =SUM(AB28*AC28) -> 7815.9953 | AE28: =SUM(X28+AD28) -> 12262.213 | AF28: =SUM(P28-AE28) -> 1651.0871
C29: 240906000023 | D29: 45559 | E29: Sam.Pao | F29: Sam.Pao | G29: ChenGaoHong | H29: 24.9775 | I29: 6522 | J29: 51303 | P29: =SUBTOTAL(9,J29) -> 51303 | S29: =SUM(40661/68)*H29 -> 14935.443 | T29: =SUM(94.72/68)*H29 -> 34.792188 | U29: =SUM(2000/68)*H29 -> 734.63235 | X29: =SUM(S29:W29) -> 15704.868 | Y29: =SUM(10381.24/68)*H29 -> 3813.1974 | AB29: =SUM(Y29:AA29) -> 3813.1974 | AC29: 7.24 | AD29: =SUM(AB29*AC29) -> 27607.549 | AE29: =SUM(X29+AD29) -> 43312.417 | AF29: =SUM(P29-AE29) -> 7990.5833
C30: 240919000020 | D30: 45564 | E30: 吕沛霖 | F30: 喵喵速运-Layne | G30: ABDUL | H30: 1.06 | I30: 594 | J30: 2180 | P30: =SUBTOTAL(9,J30) -> 2180 | S30: =SUM(40661/68)*H30 -> 633.83324 | T30: =SUM(94.72/68)*H30 -> 1.4765176 | U30: =SUM(2000/68)*H30 -> 31.176471 | X30: =SUM(S30:W30) -> 666.48622 | Y30: =SUM(10381.24/68)*H30 -> 161.82521 | AB30: =SUM(Y30:AA30) -> 161.82521 | AC30: 7.24 | AD30: =SUM(AB30*AC30) -> 1171.6145 | AE30: =SUM(X30+AD30) -> 1838.1008 | AF30: =SUM(P30-AE30) -> 341.89924
C31: 240924000057 | D31: 45564 | E31: Sam.Pao | F31: Sam.Pao | G31: Arni | H31: 5.543 | I31: 3097 | J31: 12233 | P31: =SUBTOTAL(9,J31) -> 12233 | S31: =SUM(40661/68)*H31 -> 3314.4695 | T31: =SUM(94.72/68)*H31 -> 7.7210729 | U31: =SUM(2000/68)*H31 -> 163.02941 | X31: =SUM(S31:W31) -> 3485.2199 | Y31: =SUM(10381.24/68)*H31 -> 846.22373 | AB31: =SUM(Y31:AA31) -> 846.22373 | AC31: 7.24 | AD31: =SUM(AB31*AC31) -> 6126.6598 | AE31: =SUM(X31+AD31) -> 9611.8797 | AF31: =SUM(P31-AE31) -> 2621.1203
C32: 240928000023 | D32: 45564 | E32: Sam.Pao | F32: Sam.Pao | G32: SKY JET | H32: 6.37 | I32: 908.5 | J32: 9341.73 | P32: =SUBTOTAL(9,J32) -> 9341.73 | S32: =SUM(40661/68)*H32 -> 3808.979 | T32: =SUM(94.72/68)*H32 -> 8.8730353 | U32: =SUM(2000/68)*H32 -> 187.35294 | X32: =SUM(S32:W32) -> 4005.2049 | Y32: =SUM(10381.24/68)*H32 -> 972.47792 | AB32: =SUM(Y32:AA32) -> 972.47792 | AC32: 7.24 | AD32: =SUM(AB32*AC32) -> 7040.7402 | AE32: =SUM(X32+AD32) -> 11045.945 | AF32: =SUM(P32-AE32) -> -1704.2151
C33: 240927000032 | D33: 45563 | E33: 罗珮文 | F33: Shirley | G33: Yusky | H33: 4.4364 | I33: 423.9 | J33: 7740.66 | P33: =SUBTOTAL(9,J33) -> 7740.66 | S33: =SUM(40661/68)*H33 -> 2652.7715 | T33: =SUM(94.72/68)*H33 -> 6.1796442 | U33: =SUM(2000/68)*H33 -> 130.48235 | X33: =SUM(S33:W33) -> 2789.4335 | Y33: =SUM(10381.24/68)*H33 -> 677.28431 | AB33: =SUM(Y33:AA33) -> 677.28431 | AC33: 7.24 | AD33: =SUM(AB33*AC33) -> 4903.5384 | AE33: =SUM(X33+AD33) -> 7692.9719 | AF33: =SUM(P33-AE33) -> 47.688116
C34: 240927000071 | D34: 45563 | E34: 陆总 | F34: 陆梓龙 | G34: xinlong | H34: 16.8732 | I34: 10470 | J34: 28601.11 | P34: =SUBTOTAL(9,J34) -> 28601.11 | S34: =SUM(40661/68)*H34 -> 10089.429 | T34: =SUM(94.72/68)*H34 -> 23.503375 | U34: =SUM(2000/68)*H34 -> 496.27059 | X34: =SUM(S34:W34) -> 10609.203 | Y34: =SUM(10381.24/68)*H34 -> 2575.952 | Z34: 84.18 | AB34: =SUM(Y34:AA34) -> 2660.132 | AC34: 7.24 | AD34: =SUM(AB34*AC34) -> 19259.356 | AE34: =SUM(X34+AD34) -> 29868.559 | AF34: =SUM(P34-AE34) -> -1267.4491
A35: JOB100360 | B35: COLL004247 | C35: 240918000046 | D35: 45564 | E35: 朱小飞 | F35: Isabel Zhu | G35: Lin Bao Zhen | H35: 11.5853 | I35: 3144 | K35: 7151961.6 | M35: =SUM(K35/N35) -> 1754.9707 | N35: 4075.2598 | O35: 7.26 | P35: =SUM(N35*O35) -> 29586.386 | Q35: =SUM(P35:P44) -> 153384.01 | R35: 登凯=36901 赛捷=2800 拖车费=1670 杂费=497 过磅费=65 | S35: =SUM(41933/68)*H35 -> 7144.2115 | U35: =SUM(1400/68)*H35 -> 238.52088 | V35: 150 | X35: =SUM(S35:W35) -> 7532.7324 | Y35: =SUM(10381.24/68)*H35 -> 1768.6732 | AB35: =SUM(Y35:AA35) -> 1768.6732 | AC35: 7.24 | AD35: =SUM(AB35*AC35) -> 12805.194 | AE35: =SUM(X35+AD35) -> 20337.927 | AF35: =SUM(P35-AE35) -> 9248.4595
C36: 240919000028 | D36: 45564 | E36: 陆总 | F36: 陆梓龙 | G36: jizong | H36: 4.5828 | I36: 3750 | J36: 10847.8 | P36: =SUBTOTAL(9,J36) -> 10847.8 | S36: =SUM(41933/68)*H36 -> 2826.0375 | U36: =SUM(1400/68)*H36 -> 94.351765 | X36: =SUM(S36:W36) -> 2920.3893 | Y36: =SUM(10381.24/68)*H36 -> 699.63451 | AB36: =SUM(Y36:AA36) -> 699.63451 | AC36: 7.24 | AD36: =SUM(AB36*AC36) -> 5065.3539 | AE36: =SUM(X36+AD36) -> 7985.7432 | AF36: =SUM(P36-AE36) -> 2862.0568
C37: 240906000023 | D37: 45559 | E37: Sam.Pao | F37: Sam.Pao | G37: ChenGaoHong | H37: 17.6195 | I37: 5514 | J37: 36190 | P37: =SUBTOTAL(9,J37) -> 36190 | S37: =SUM(41933/68)*H37 -> 10865.272 | U37: =SUM(1400/68)*H37 -> 362.75441 | X37: =SUM(S37:W37) -> 11228.026 | Y37: =SUM(10381.24/68)*H37 -> 2689.8861 | AB37: =SUM(Y37:AA37) -> 2689.8861 | AC37: 7.24 | AD37: =SUM(AB37*AC37) -> 19474.776 | AE37: =SUM(X37+AD37) -> 30702.802 | AF37: =SUM(P37-AE37) -> 5487.1979
C38: 240924000057 | D38: 45564 | E38: Sam.Pao | F38: Sam.Pao | G38: Arni | H38: 4.4869 | I38: 2510.11 | J38: 9902 | P38: =SUBTOTAL(9,J38) -> 9902 | S38: =SUM(41933/68)*H38 -> 2766.8997 | U38: =SUM(1400/68)*H38 -> 92.377353 | X38: =SUM(S38:W38) -> 2859.277 | Y38: =SUM(10381.24/68)*H38 -> 684.99391 | AB38: =SUM(Y38:AA38) -> 684.99391 | AC38: 7.24 | AD38: =SUM(AB38*AC38) -> 4959.3559 | AE38: =SUM(X38+AD38) -> 7818.6329 | AF38: =SUM(P38-AE38) -> 2083.3671
C39: 240919000020 | D39: 45564 | E39: 吕沛霖 | F39: 喵喵速运-Layne | G39: ABDUL | H39: 3.887 | I39: 1821.5 | J39: 8001.8 | P39: =SUBTOTAL(9,J39) -> 8001.8 | S39: =SUM(41933/68)*H39 -> 2396.9643 | U39: =SUM(1400/68)*H39 -> 80.026471 | X39: =SUM(S39:W39) -> 2476.9907 | Y39: =SUM(10381.24/68)*H39 -> 593.41 | AB39: =SUM(Y39:AA39) -> 593.41 | AC39: 7.24 | AD39: =SUM(AB39*AC39) -> 4296.2884 | AE39: =SUM(X39+AD39) -> 6773.2791 | AF39: =SUM(P39-AE39) -> 1228.5209
C40: 240929000009 | D40: 45564 | E40: 朱小飞 | F40: Isabel Zhu | G40: Joy | H40: 6.7645 | I40: 2500 | K40: 3821265 | M40: =SUM(K40/N40) -> 1883.3243 | N40: 2029 | O40: 7.26 | P40: =SUM(N40*O40) -> 14730.54 | S40: =SUM(41933/68)*H40 -> 4171.4085 | U40: =SUM(1400/68)*H40 -> 139.26912 | X40: =SUM(S40:W40) -> 4310.6776 | Y40: =SUM(10381.24/68)*H40 -> 1032.7044 | AB40: =SUM(Y40:AA40) -> 1032.7044 | AC40: 7.24 | AD40: =SUM(AB40*AC40) -> 7476.7797 | AE40: =SUM(X40+AD40) -> 11787.457 | AF40: =SUM(P40-AE40) -> 2943.0826
...

Sheet JOB100358
A1: 2024年10月份LOS毛利表（海运）
A2: PSL表 | B2: 体积cbm | C2: 81.6001
A3: JOB | B3: 集装编号 | C3: 运单编号 | D3: 日期 | E3: 业务 | F3: 发货人 | G3: 收货人 | H3: 计费体积 | I3: 计费重量 | J3: 应 收 | Q3: 总应收 | R3: 起 运 港 成 本 | W3: 代垫运费 | X3: 起运港成本 合计 | Y3: 目的港成本 | AE3: 总支出 | AF3: 利润
J4: 应收RMB | K4: LOS Income(NGN)收到(奈拉) | L4: LOS 收到USD | M4: 美元汇率 dollar currency rate | N4: 应收 到付款USD | O4: 汇率 | P4: 人民币 | R4: 代理商 | S4: 运费+出口报关费 | T4: 提货费 | U4: 装卸费 | V4: 包装费 | Y4: 进口报关费 | Z4: 到门配送费 | AA4: 转运费 | AB4: 目的港支出 | AC4: 汇率 | AD4: 人民币 | AE4: 起运港+目的港
A5: JOB100358 | B5: COLL004182 | C5: 240907000011 | D5: 45563 | E5: 吕沛霖 | F5: 喵喵速运-Layne | G5: MA ZONG | H5: 0.4074 | I5: 404 | J5: 1549.3 | P5: =SUBTOTAL(9,J5) -> 1549.3 | Q5: =SUM(P5:P25) -> 163992.94 | R5: 登凯=36617 赛捷=1660 拖车费=1670 杂费=499 过磅费=69 | S5: =SUM(40515/68)*H5 -> 242.73251 | U5: =SUM(2200/68)*H5 -> 13.180588 | X5: =SUM(S5:W5) -> 255.9131 | Y5: =SUM(10381.23/68)*H5 -> 62.195781 | Z5: 48.54 | AB5: =SUM(Y5:AA5) -> 110.73578 | AC5: 7.23 | AD5: =SUM(AB5*AC5) -> 800.6197 | AE5: =SUM(X5+AD5) -> 1056.5328 | AF5: =SUM(P5-AE5) -> 492.7672
C6: 240909000011 | D6: 45563 | E6: 黄颖 | F6: ying | G6: ying | H6: 0.036 | I6: 12 | K6: 87324 | M6: =SUM(K6/N6) -> 5916.2594 | N6: 14.760002 | O6: 7.24 | P6: =SUM(N6*O6) -> 106.86241 | S6: =SUM(40515/68)*H6 -> 21.449118 | U6: =SUM(2200/68)*H6 -> 1.1647059 | X6: =SUM(S6:W6) -> 22.613824 | Y6: =SUM(10381.23/68)*H6 -> 5.4959453 | Z6: 0.54 | AB6: =SUM(Y6:AA6) -> 6.0359453 | AC6: 7.23 | AD6: =SUM(AB6*AC6) -> 43.639884 | AE6: =SUM(X6+AD6) -> 66.253708 | AF6: =SUM(P6-AE6) -> 40.608706
C7: 240915000027 | D7: 45563 | E7: 吕沛霖 | F7: 喵喵速运-Layne | G7: Gao Hui | H7: 0.554 | I7: 177 | J7: 1986.97 | P7: =SUM(J7) -> 1986.97 | S7: =SUM(40515/68)*H7 -> 330.07809 | U7: =SUM(2200/68)*H7 -> 17.923529 | V7: 60 | X7: =SUM(S7:W7) -> 408.00162 | Y7: =SUM(10381.23/68)*H7 -> 84.576491 | Z7: 83.97 | AB7: =SUM(Y7:AA7) -> 168.54649 | AC7: 7.23 | AD7: =SUM(AB7*AC7) -> 1218.5911 | AE7: =SUM(X7+AD7) -> 1626.5928 | AF7: =SUM(P7-AE7) -> 360.37725
C8: 240919000042 | D8: 45563 | E8: 黄颖 | F8: ying | G8: MISS Huang | H8: 0.2211 | I8: 118 | J8: 468.7 | P8: =SUBTOTAL(9,J8) -> 468.7 | S8: =SUM(40515/68)*H8 -> 131.73333 | U8: =SUM(2200/68)*H8 -> 7.1532353 | X8: =SUM(S8:W8) -> 138.88657 | Y8: =SUM(10381.23/68)*H8 -> 33.754264 | AB8: =SUM(Y8:AA8) -> 33.754264 | AC8: 7.23 | AD8: =SUM(AB8*AC8) -> 244.04333 | AE8: =SUM(X8+AD8) -> 382.9299 | AF8: =SUM(P8-AE8) -> 85.770105
C9: 240920000027 | D9: 45563 | E9: 吕沛霖 | F9: 喵喵速运-Layne | G9: YA | H9: 1.1252 | I9: 111 | J9: 3500.8 | P9: =SUBTOTAL(9,J9) -> 3500.8 | S9: =SUM(40515/68)*H9 -> 670.40409 | U9: =SUM(2200/68)*H9 -> 36.403529 | X9: =SUM(S9:W9) -> 706.80762 | Y9: =SUM(10381.23/68)*H9 -> 171.77882 | Z9: 8.31 | AA9: 117.69 | AB9: =SUM(Y9:AA9) -> 297.77882 | AC9: 7.23 | AD9: =SUM(AB9*AC9) -> 2152.9409 | AE9: =SUM(X9+AD9) -> 2859.7485 | AF9: =SUM(P9-AE9) -> 641.05149
C10: 240920000030 | D10: 45563 | E10: 黄颖 | F10: ying | G10: baikaibo | H10: 0.319 | I10: 321 | K10: 385317 | M10: =SUM(K10/N10) -> 1767.347 | N10: 218.02 | O10: 7.24 | P10: =SUM(N10*O10) -> 1578.4648 | S10: =SUM(40515/68)*H10 -> 190.06301 | U10: =SUM(2200/68)*H10 -> 10.320588 | X10: =SUM(S10:W10) -> 200.3836 | Y10: =SUM(10381.23/68)*H10 -> 48.700182 | Z10: 85.03 | AB10: =SUM(Y10:AA10) -> 133.73018 | AC10: 7.23 | AD10: =SUM(AB10*AC10) -> 966.86922 | AE10: =SUM(X10+AD10) -> 1167.2528 | AF10: =SUM(P10-AE10) -> 411.21198
C11: 240923000009 | D11: 45563 | E11: 朱小飞 | F11: Isabel Zhu | G11: Wu Jiao Xing | H11: 0.5281 | I11: 104.5 | K11: 313621.07 | M11: =SUM(K11/N11) -> 1855.8559 | N11: 168.98999 | O11: 7.26 | P11: =SUM(N11*O11) -> 1226.8673 | S11: =SUM(40515/68)*H11 -> 314.64664 | U11: =SUM(2200/68)*H11 -> 17.085588 | X11: =SUM(S11:W11) -> 331.73223 | Y11: =SUM(10381.23/68)*H11 -> 80.622464 | AB11: =SUM(Y11:AA11) -> 80.622464 | AC11: 7.23 | AD11: =SUM(AB11*AC11) -> 582.90042 | AE11: =SUM(X11+AD11) -> 914.63264 | AF11: =SUM(P11-AE11) -> 312.23468
C12: 240923000035 | D12: 45547 | E12: 黄颖 | F12: ying | G12: Bruce | H12: 1.0584 | I12: 465 | J12: 2082 | P12: =SUBTOTAL(9,J12) -> 2082 | S12: =SUM(40515/68)*H12 -> 630.60406 | U12: =SUM(2200/68)*H12 -> 34.242353 | X12: =SUM(S12:W12) -> 664.84641 | Y12: =SUM(10381.23/68)*H12 -> 161.58079 | AB12: =SUM(Y12:AA12) -> 161.58079 | AC12: 7.23 | AD12: =SUM(AB12*AC12) -> 1168.2291 | AE12: =SUM(X12+AD12) -> 1833.0755 | AF12: =SUM(P12-AE12) -> 248.92446
C13: 240923000047 | D13: 45563 | E13: 吕沛霖 | F13: 喵喵速运-Layne | G13: WYLB | H13: 0.8 | I13: 197 | K13: 390880 | M13: =SUM(K13/N13) -> 1744.9998 | N13: 224.00003 | O13: 7.21 | P13: =SUM(N13*O13) -> 1615.0402 | S13: =SUM(40515/68)*H13 -> 476.64706 | U13: =SUM(2200/68)*H13 -> 25.882353 | X13: =SUM(S13:W13) -> 502.52941 | Y13: =SUM(10381.23/68)*H13 -> 122.13212 | AB13: =SUM(Y13:AA13) -> 122.13212 | AC13: 7.23 | AD13: =SUM(AB13*AC13) -> 883.01521 | AE13: =SUM(X13+AD13) -> 1385.5446 | AF13: =SUM(P13-AE13) -> 229.49559
C14: 240924000001 | D14: 45563 | E14: Sam.Pao | F14: Sam.Pao | G14: Yusky | H14: 8.51 | I14: 209 | J14: 14859.77 | P14: =SUBTOTAL(9,J14) -> 14859.77 | S14: =SUM(40515/68)*H14 -> 5070.3331 | U14: =SUM(2200/68)*H14 -> 275.32353 | X14: =SUM(S14:W14) -> 5345.6566 | Y14: =SUM(10381.23/68)*H14 -> 1299.1804 | AB14: =SUM(Y14:AA14) -> 1299.1804 | AC14: 7.23 | AD14: =SUM(AB14*AC14) -> 9393.0743 | AE14: =SUM(X14+AD14) -> 14738.731 | AF14: =SUM(P14-AE14) -> 121.03908
C15: 240925000028 | D15: 45563 | E15: 朱小飞 | F15: Isabel Zhu | G15: Halifa Success | H15: 1.2354 | I15: 125 | J15: 2382.35 | P15: =SUBTOTAL(9,J15) -> 2382.35 | S15: =SUM(40515/68)*H15 -> 736.06222 | U15: =SUM(2200/68)*H15 -> 39.968824 | X15: =SUM(S15:W15) -> 776.03104 | Y15: =SUM(10381.23/68)*H15 -> 188.60252 | AB15: =SUM(Y15:AA15) -> 188.60252 | AC15: 7.23 | AD15: =SUM(AB15*AC15) -> 1363.5962 | AE15: =SUM(X15+AD15) -> 2139.6273 | AF15: =SUM(P15-AE15) -> 242.72272
C16: 240926000027 | D16: 45563 | E16: Sam.Pao | F16: Sam.Pao | G16: ShanShan | H16: 1.555 | I16: 237 | J16: 3879 | P16: =SUBTOTAL(9,J16) -> 3879 | S16: =SUM(40515/68)*H16 -> 926.48272 | U16: =SUM(2200/68)*H16 -> 50.308824 | X16: =SUM(S16:W16) -> 976.79154 | Y16: =SUM(10381.23/68)*H16 -> 237.3943 | Z16: 36.85 | AB16: =SUM(Y16:AA16) -> 274.2443 | AC16: 7.23 | AD16: =SUM(AB16*AC16) -> 1982.7863 | AE16: =SUM(X16+AD16) -> 2959.5779 | AF16: =SUM(P16-AE16) -> 919.42214
C17: 240924000057 | D17: 45564 | E17: Sam.Pao | F17: Sam.Pao | G17: Arni | H17: 5.543 | I17: 3101 | J17: 12233 | P17: =SUBTOTAL(9,J17) -> 12233 | S17: =SUM(40515/68)*H17 -> 3302.5683 | U17: =SUM(2200/68)*H17 -> 179.33235 | X17: =SUM(S17:W17) -> 3481.9007 | Y17: =SUM(10381.23/68)*H17 -> 846.22291 | AB17: =SUM(Y17:AA17) -> 846.22291 | AC17: 7.23 | AD17: =SUM(AB17*AC17) -> 6118.1916 | AE17: =SUM(X17+AD17) -> 9600.0923 | AF17: =SUM(P17-AE17) -> 2632.9077
C18: 240906000023 | D18: 45559 | E18: Sam.Pao | F18: Sam.Pao | G18: ChenGaoHong | H18: 33.5175 | I18: 8313 | J18: 68845 | P18: =SUBTOTAL(9,J18) -> 68845 | S18: =SUM(40515/68)*H18 -> 19970.022 | U18: =SUM(2200/68)*H18 -> 1084.3897 | X18: =SUM(S18:W18) -> 21054.412 | Y18: =SUM(10381.23/68)*H18 -> 5116.9541 | AB18: =SUM(Y18:AA18) -> 5116.9541 | AC18: 7.23 | AD18: =SUM(AB18*AC18) -> 36995.578 | AE18: =SUM(X18+AD18) -> 58049.99 | AF18: =SUM(P18-AE18) -> 10795.01
C19: 240927000007 | D19: 45563 | E19: 黄颖 | F19: ying | G19: MISS Huang | H19: 1.745 | I19: 656 | J19: 3441 | P19: =SUBTOTAL(9,J19) -> 3441 | S19: =SUM(40515/68)*H19 -> 1039.6864 | U19: =SUM(2200/68)*H19 -> 56.455882 | X19: =SUM(S19:W19) -> 1096.1423 | Y19: =SUM(10381.23/68)*H19 -> 266.40068 | AB19: =SUM(Y19:AA19) -> 266.40068 | AC19: 7.23 | AD19: =SUM(AB19*AC19) -> 1926.0769 | AE19: =SUM(X19+AD19) -> 3022.2192 | AF19: =SUM(P19-AE19) -> 418.78079
C20: 240927000017 | D20: 45563 | E20: 朱小飞 | F20: Isabel Zhu | G20: Lin Bao Zhen | H20: 1.1235 | I20: 241 | K20: 594820.8 | M20: =SUM(K20/N20) -> 1891.0213 | N20: 314.55002 | O20: 7.26 | P20: =SUM(N20*O20) -> 2283.6331 | S20: =SUM(40515/68)*H20 -> 669.39121 | U20: =SUM(2200/68)*H20 -> 36.348529 | X20: =SUM(S20:W20) -> 705.73974 | Y20: =SUM(10381.23/68)*H20 -> 171.51929 | AB20: =SUM(Y20:AA20) -> 171.51929 | AC20: 7.23 | AD20: =SUM(AB20*AC20) -> 1240.0845 | AE20: =SUM(X20+AD20) -> 1945.8242 | AF20: =SUM(P20-AE20) -> 337.80892
C21: 240927000029 | D21: 45563 | E21: 朱小飞 | F21: Isabel Zhu | G21: Joy | H21: 1.7289 | I21: 1316 | K21: 1061222.4 | M21: =SUM(K21/N21) -> 1612.7994 | N21: 658.00024 | O21: 7.26 | P21: =SUM(N21*O21) -> 4777.0817 | S21: =SUM(40515/68)*H21 -> 1030.0939 | U21: =SUM(2200/68)*H21 -> 55.935 | X21: =SUM(S21:W21) -> 1086.0289 | Y21: =SUM(10381.23/68)*H21 -> 263.94277 | Z21: 7.97 | AB21: =SUM(Y21:AA21) -> 271.91277 | AC21: 7.23 | AD21: =SUM(AB21*AC21) -> 1965.9293 | AE21: =SUM(X21+AD21) -> 3051.9582 | AF21: =SUM(P21-AE21) -> 1725.1235
C22: 240921000019 | D22: 45563 | E22: 陆总 | F22: 陆梓龙 | G22: xiantian | H22: 0.3318 | I22: 185 | J22: 678.17 | P22: =SUBTOTAL(9,J22) -> 678.17 | S22: =SUM(40515/68)*H22 -> 197.68937 | U22: =SUM(2200/68)*H22 -> 10.734706 | X22: =SUM(S22:W22) -> 208.42407 | Y22: =SUM(10381.23/68)*H22 -> 50.654296 | AB22: =SUM(Y22:AA22) -> 50.654296 | AC22: 7.23 | AD22: =SUM(AB22*AC22) -> 366.23056 | AE22: =SUM(X22+AD22) -> 574.65463 | AF22: =SUM(P22-AE22) -> 103.51537
C23: 240927000032 | D23: 45563 | E23: 罗珮文 | F23: Shirley | G23: Yusky | H23: 0.4929 | I23: 47.1 | J23: 860.11 | P23: =SUBTOTAL(9,J23) -> 860.11 | S23: =SUM(40515/68)*H23 -> 293.67417 | U23: =SUM(2200/68)*H23 -> 15.946765 | X23: =SUM(S23:W23) -> 309.62093 | Y23: =SUM(10381.23/68)*H23 -> 75.248651 | AB23: =SUM(Y23:AA23) -> 75.248651 | AC23: 7.23 | AD23: =SUM(AB23*AC23) -> 544.04775 | AE23: =SUM(X23+AD23) -> 853.66868 | AF23: =SUM(P23-AE23) -> 6.4413196
C24: 240927000070 | D24: 45563 | E24: 陆总 | F24: 陆梓龙 | G24: xinlong | H24: 17.4127 | I24: 10650 | J24: 29515.58 | P24: =SUBTOTAL(9,J24) -> 29515.58 | S24: =SUM(40515/68)*H24 -> 10374.64 | U24: =SUM(2200/68)*H24 -> 563.35206 | X24: =SUM(S24:W24) -> 10937.992 | Y24: =SUM(10381.23/68)*H24 -> 2658.3124 | Z24: 85.88 | AB24: =SUM(Y24:AA24) -> 2744.1924 | AC24: 7.23 | AD24: =SUM(AB24*AC24) -> 19840.511 | AE24: =SUM(X24+AD24) -> 30778.503 | AF24: =SUM(P24-AE24) -> -1262.9235
C25: 240928000018 | D25: 45563 | E25: 陆总 | F25: 陆梓龙 | G25: leoluang | H25: 3.3552 | I25: 1105 | J25: 6123.24 | P25: =SUBTOTAL(9,J25) -> 6123.24 | S25: =SUM(40515/68)*H25 -> 1999.0578 | U25: =SUM(2200/68)*H25 -> 108.55059 | X25: =SUM(S25:W25) -> 2107.6084 | Y25: =SUM(10381.23/68)*H25 -> 512.2221 | AB25: =SUM(Y25:AA25) -> 512.2221 | AC25: 7.23 | AD25: =SUM(AB25*AC25) -> 3703.3658 | AE25: =SUM(X25+AD25) -> 5810.9741 | AF25: =SUM(P25-AE25) -> 312.26585
A26: 合计 | J26: =SUM(J4:J4) -> 0 | N26: =SUM(N4:N4) -> 0 | P26: =SUM(P4:P4) -> 0 | Q26: =SUM(Q4:Q4) -> 0 | X26: =SUM(X4:X4) -> 0 | AD26: =SUM(AD4:AD4) -> 0 | AF26: =SUM(AF4:AF25) -> 19174.556

Sheet JOB100359
A1: 2024年10月份LOS毛利表（海运）
A2: PSL表 | B2: 体积cbm | C2: 77.3653
A3: JOB | B3: 集装编号 | C3: 运单编号 | D3: 日期 | E3: 业务 | F3: 发货人 | G3: 收货人 | H3: 计费体积 | I3: 计费重量 | J3: 应 收 | Q3: 总应收 | R3: 起 运 港 成 本 | W3: 代垫运费 | X3: 起运港成本 合计 | Y3: 目的港成本 | AE3: 总支出 | AF3: 利润
J4: 应收RMB | K4: LOS Income(NGN)收到(奈拉) | L4: LOS 收到USD | M4: 美元汇率 dollar currency rate | N4: 应收 到付款USD | O4: 汇率 | P4: 人民币 | R4: 代理商 | S4: 运费+出口报关费 | T4: 提货费 | U4: 装卸费 | V4: 包装费 | Y4: 进口报关费 | Z4: 到门配送费 | AA4: 转运费 | AB4: 目的港支出 | AC4: 汇率 | AD4: 人民币 | AE4: 起运港+目的港
A5: JOB100359 | B5: COLL004278 | C5: 240919000034 | D5: 45563 | E5: 朱小飞 | F5: Isabel Zhu | G5: Wu Jiao Xing | H5: 0.8132 | I5: 104 | K5: 607758.93 | M5: =SUM(K5/N5) -> 1737 | N5: 349.89 | O5: 7.26 | P5: =SUM(N5*O5) -> 2540.2014 | Q5: =SUM(P5:P14) -> 148903 | R5: 登凯=39001 赛捷=1660 | S5: =SUM(40661/68)*H5 -> 486.25772 | T5: =SUM(94.72/68)*H5 -> 1.1327398 | U5: =SUM(2000/68)*H5 -> 23.917647 | V5: 420 | X5: =SUM(S5:W5) -> 931.30811 | Y5: =SUM(10381.24/68)*H5 -> 124.14742 | AB5: =SUM(Y5:AA5) -> 124.14742 | AC5: 7.24 | AD5: =SUM(AB5*AC5) -> 898.8273 | AE5: =SUM(X5+AD5) -> 1830.1354 | AF5: =SUM(P5-AE5) -> 710.06599
C6: 240921000009 | D6: 45563 | E6: 苏慧琪 | F6: KAY | G6: OKECHUKWU | H6: 0.075 | I6: 19 | J6: 318 | P6: =SUM(J6) -> 318 | S6: =SUM(40661/68)*H6 -> 44.846691 | T6: =SUM(94.72/68)*H6 -> 0.10447059 | U6: =SUM(2000/68)*H6 -> 2.2058824 | X6: =SUM(S6:W6) -> 47.157044 | Y6: =SUM(10381.24/68)*H6 -> 11.449897 | AB6: =SUM(Y6:AA6) -> 11.449897 | AC6: 7.24 | AD6: =SUM(AB6*AC6) -> 82.897255 | AE6: =SUM(X6+AD6) -> 130.0543 | AF6: =SUM(P6-AE6) -> 187.9457
C7: 240921000019 | D7: 45563 | E7: 陆总 | F7: 陆梓龙 | G7: xiantian | H7: 10.1452 | I7: 2149.35 | J7: 20732 | P7: =SUBTOTAL(9,J7) -> 20732 | S7: =SUM(40661/68)*H7 -> 6066.382 | T7: =SUM(94.72/68)*H7 -> 14.131667 | U7: =SUM(2000/68)*H7 -> 298.38824 | V7: =SUM(450+350) -> 800 | X7: =SUM(S7:W7) -> 7178.9019 | Y7: =SUM(10381.24/68)*H7 -> 1548.8199 | AB7: =SUM(Y7:AA7) -> 1548.8199 | AC7: 7.24 | AD7: =SUM(AB7*AC7) -> 11213.456 | AE7: =SUM(X7+AD7) -> 18392.358 | AF7: =SUM(P7-AE7) -> 2339.6417
C8: 240923000035 | D8: 45563 | E8: 黄颖 | F8: ying | G8: Bruce | H8: 7.0714 | I8: 3083 | J8: 13913.3 | P8: =SUBTOTAL(9,J8) -> 13913.3 | S8: =SUM(40661/68)*H8 -> 4228.3852 | T8: =SUM(94.72/68)*H8 -> 9.8500442 | U8: =SUM(2000/68)*H8 -> 207.98235 | X8: =SUM(S8:W8) -> 4446.2176 | Y8: =SUM(10381.24/68)*H8 -> 1079.5574 | AB8: =SUM(Y8:AA8) -> 1079.5574 | AC8: 7.24 | AD8: =SUM(AB8*AC8) -> 7815.9953 | AE8: =SUM(X8+AD8) -> 12262.213 | AF8: =SUM(P8-AE8) -> 1651.0871
C9: 240906000023 | D9: 45559 | E9: Sam.Pao | F9: Sam.Pao | G9: ChenGaoHong | H9: 24.9775 | I9: 6522 | J9: 51303 | P9: =SUBTOTAL(9,J9) -> 51303 | S9: =SUM(40661/68)*H9 -> 14935.443 | T9: =SUM(94.72/68)*H9 -> 34.792188 | U9: =SUM(2000/68)*H9 -> 734.63235 | X9: =SUM(S9:W9) -> 15704.868 | Y9: =SUM(10381.24/68)*H9 -> 3813.1974 | AB9: =SUM(Y9:AA9) -> 3813.1974 | AC9: 7.24 | AD9: =SUM(AB9*AC9) -> 27607.549 | AE9: =SUM(X9+AD9) -> 43312.417 | AF9: =SUM(P9-AE9) -> 7990.5833
C10: 240919000020 | D10: 45564 | E10: 吕沛霖 | F10: 喵喵速运-Layne | G10: ABDUL | H10: 1.06 | I10: 594 | J10: 2180 | P10: =SUBTOTAL(9,J10) -> 2180 | S10: =SUM(40661/68)*H10 -> 633.83324 | T10: =SUM(94.72/68)*H10 -> 1.4765176 | U10: =SUM(2000/68)*H10 -> 31.176471 | X10: =SUM(S10:W10) -> 666.48622 | Y10: =SUM(10381.24/68)*H10 -> 161.82521 | AB10: =SUM(Y10:AA10) -> 161.82521 | AC10: 7.24 | AD10: =SUM(AB10*AC10) -> 1171.6145 | AE10: =SUM(X10+AD10) -> 1838.1008 | AF10: =SUM(P10-AE10) -> 341.89924
C11: 240924000057 | D11: 45564 | E11: Sam.Pao | F11: Sam.Pao | G11: Arni | H11: 5.543 | I11: 3097 | J11: 12233 | P11: =SUBTOTAL(9,J11) -> 12233 | S11: =SUM(40661/68)*H11 -> 3314.4695 | T11: =SUM(94.72/68)*H11 -> 7.7210729 | U11: =SUM(2000/68)*H11 -> 163.02941 | X11: =SUM(S11:W11) -> 3485.2199 | Y11: =SUM(10381.24/68)*H11 -> 846.22373 | AB11: =SUM(Y11:AA11) -> 846.22373 | AC11: 7.24 | AD11: =SUM(AB11*AC11) -> 6126.6598 | AE11: =SUM(X11+AD11) -> 9611.8797 | AF11: =SUM(P11-AE11) -> 2621.1203
C12: 240928000023 | D12: 45564 | E12: Sam.Pao | F12: Sam.Pao | G12: SKY JET | H12: 6.37 | I12: 908.5 | J12: 9341.73 | P12: =SUBTOTAL(9,J12) -> 9341.73 | S12: =SUM(40661/68)*H12 -> 3808.979 | T12: =SUM(94.72/68)*H12 -> 8.8730353 | U12: =SUM(2000/68)*H12 -> 187.35294 | X12: =SUM(S12:W12) -> 4005.2049 | Y12: =SUM(10381.24/68)*H12 -> 972.47792 | AB12: =SUM(Y12:AA12) -> 972.47792 | AC12: 7.24 | AD12: =SUM(AB12*AC12) -> 7040.7402 | AE12: =SUM(X12+AD12) -> 11045.945 | AF12: =SUM(P12-AE12) -> -1704.2151
C13: 240927000032 | D13: 45563 | E13: 罗珮文 | F13: Shirley | G13: Yusky | H13: 4.4364 | I13: 423.9 | J13: 7740.66 | P13: =SUBTOTAL(9,J13) -> 7740.66 | S13: =SUM(40661/68)*H13 -> 2652.7715 | T13: =SUM(94.72/68)*H13 -> 6.1796442 | U13: =SUM(2000/68)*H13 -> 130.48235 | X13: =SUM(S13:W13) -> 2789.4335 | Y13: =SUM(10381.24/68)*H13 -> 677.28431 | AB13: =SUM(Y13:AA13) -> 677.28431 | AC13: 7.24 | AD13: =SUM(AB13*AC13) -> 4903.5384 | AE13: =SUM(X13+AD13) -> 7692.9719 | AF13: =SUM(P13-AE13) -> 47.688116
C14: 240927000071 | D14: 45563 | E14: 陆总 | F14: 陆梓龙 | G14: xinlong | H14: 16.8732 | I14: 10470 | J14: 28601.11 | P14: =SUBTOTAL(9,J14) -> 28601.11 | S14: =SUM(40661/68)*H14 -> 10089.429 | T14: =SUM(94.72/68)*H14 -> 23.503375 | U14: =SUM(2000/68)*H14 -> 496.27059 | X14: =SUM(S14:W14) -> 10609.203 | Y14: =SUM(10381.24/68)*H14 -> 2575.952 | Z14: 84.18 | AB14: =SUM(Y14:AA14) -> 2660.132 | AC14: 7.24 | AD14: =SUM(AB14*AC14) -> 19259.356 | AE14: =SUM(X14+AD14) -> 29868.559 | AF14: =SUM(P14-AE14) -> -1267.4491
A15: 合计 | J15: =SUM(J4:J4) -> 0 | N15: =SUM(N4:N4) -> 0 | P15: =SUM(P4:P4) -> 0 | Q15: =SUM(Q4:Q4) -> 0 | X15: =SUM(X4:X4) -> 0 | AD15: =SUM(AD4:AD4) -> 0 | AF15: =SUM(AF4:AF14) -> 12918.367

Sheet JOB100360
A1: 2024年10月份LOS毛利表（海运）
A2: PSL表 | B2: 体积cbm | C2: 75.3622
A3: JOB | B3: 集装编号 | C3: 运单编号 | D3: 日期 | E3: 业务 | F3: 发货人 | G3: 收货人 | H3: 计费体积 | I3: 计费重量 | J3: 应 收 | Q3: 总应收 | R3: 起 运 港 成 本 | W3: 代垫运费 | X3: 起运港成本 合计 | Y3: 目的港成本 | AE3: 总支出 | AF3: 利润
J4: 应收RMB | K4: LOS Income(NGN)收到(奈拉) | L4: LOS 收到USD | M4: 美元汇率 dollar currency rate | N4: 应收 到付款USD | O4: 汇率 | P4: 人民币 | R4: 代理商 | S4: 运费+出口报关费 | T4: 提货费 | U4: 装卸费 | V4: 包装费 | Y4: 进口报关费 | Z4: 到门配送费 | AA4: 转运费 | AB4: 目的港支出 | AC4: 汇率 | AD4: 人民币 | AE4: 起运港+目的港
A5: JOB100360 | B5: COLL004247 | C5: 240918000046 | D5: 45564 | E5: 朱小飞 | F5: Isabel Zhu | G5: Lin Bao Zhen | H5: 11.5853 | I5: 3144 | K5: 7151961.6 | M5: =SUM(K5/N5) -> 1754.9707 | N5: 4075.2598 | O5: 7.26 | P5: =SUM(N5*O5) -> 29586.386 | Q5: =SUM(P5:P14) -> 153384.01 | R5: 登凯=36901 赛捷=2800 拖车费=1670 杂费=497 过磅费=65 | S5: =SUM(41933/68)*H5 -> 7144.2115 | U5: =SUM(1400/68)*H5 -> 238.52088 | V5: 150 | X5: =SUM(S5:W5) -> 7532.7324 | Y5: =SUM(10381.24/68)*H5 -> 1768.6732 | AB5: =SUM(Y5:AA5) -> 1768.6732 | AC5: 7.24 | AD5: =SUM(AB5*AC5) -> 12805.194 | AE5: =SUM(X5+AD5) -> 20337.927 | AF5: =SUM(P5-AE5) -> 9248.4595
C6: 240919000028 | D6: 45564 | E6: 陆总 | F6: 陆梓龙 | G6: jizong | H6: 4.5828 | I6: 3750 | J6: 10847.8 | P6: =SUBTOTAL(9,J6) -> 10847.8 | S6: =SUM(41933/68)*H6 -> 2826.0375 | U6: =SUM(1400/68)*H6 -> 94.351765 | X6: =SUM(S6:W6) -> 2920.3893 | Y6: =SUM(10381.24/68)*H6 -> 699.63451 | AB6: =SUM(Y6:AA6) -> 699.63451 | AC6: 7.24 | AD6: =SUM(AB6*AC6) -> 5065.3539 | AE6: =SUM(X6+AD6) -> 7985.7432 | AF6: =SUM(P6-AE6) -> 2862.0568
C7: 240906000023 | D7: 45559 | E7: Sam.Pao | F7: Sam.Pao | G7: ChenGaoHong | H7: 17.6195 | I7: 5514 | J7: 36190 | P7: =SUBTOTAL(9,J7) -> 36190 | S7: =SUM(41933/68)*H7 -> 10865.272 | U7: =SUM(1400/68)*H7 -> 362.75441 | X7: =SUM(S7:W7) -> 11228.026 | Y7: =SUM(10381.24/68)*H7 -> 2689.8861 | AB7: =SUM(Y7:AA7) -> 2689.8861 | AC7: 7.24 | AD7: =SUM(AB7*AC7) -> 19474.776 | AE7: =SUM(X7+AD7) -> 30702.802 | AF7: =SUM(P7-AE7) -> 5487.1979
C8: 240924000057 | D8: 45564 | E8: Sam.Pao | F8: Sam.Pao | G8: Arni | H8: 4.4869 | I8: 2510.11 | J8: 9902 | P8: =SUBTOTAL(9,J8) -> 9902 | S8: =SUM(41933/68)*H8 -> 2766.8997 | U8: =SUM(1400/68)*H8 -> 92.377353 | X8: =SUM(S8:W8) -> 2859.277 | Y8: =SUM(10381.24/68)*H8 -> 684.99391 | AB8: =SUM(Y8:AA8) -> 684.99391 | AC8: 7.24 | AD8: =SUM(AB8*AC8) -> 4959.3559 | AE8: =SUM(X8+AD8) -> 7818.6329 | AF8: =SUM(P8-AE8) -> 2083.3671
C9: 240919000020 | D9: 45564 | E9: 吕沛霖 | F9: 喵喵速运-Layne | G9: ABDUL | H9: 3.887 | I9: 1821.5 | J9: 8001.8 | P9: =SUBTOTAL(9,J9) -> 8001.8 | S9: =SUM(41933/68)*H9 -> 2396.9643 | U9: =SUM(1400/68)*H9 -> 80.026471 | X9: =SUM(S9:W9) -> 2476.9907 | Y9: =SUM(10381.24/68)*H9 -> 593.41 | AB9: =SUM(Y9:AA9) -> 593.41 | AC9: 7.24 | AD9: =SUM(AB9*AC9) -> 4296.2884 | AE9: =SUM(X9+AD9) -> 6773.2791 | AF9: =SUM(P9-AE9) -> 1228.5209
C10: 240929000009 | D10: 45564 | E10: 朱小飞 | F10: Isabel Zhu | G10: Joy | H10: 6.7645 | I10: 2500 | K10: 3821265 | M10: =SUM(K10/N10) -> 1883.3243 | N10: 2029 | O10: 7.26 | P10: =SUM(N10*O10) -> 14730.54 | S10: =SUM(41933/68)*H10 -> 4171.4085 | U10: =SUM(1400/68)*H10 -> 139.26912 | X10: =SUM(S10:W10) -> 4310.6776 | Y10: =SUM(10381.24/68)*H10 -> 1032.7044 | AB10: =SUM(Y10:AA10) -> 1032.7044 | AC10: 7.24 | AD10: =SUM(AB10*AC10) -> 7476.7797 | AE10: =SUM(X10+AD10) -> 11787.457 | AF10: =SUM(P10-AE10) -> 2943.0826
C11: 240928000023 | D11: 45564 | E11: Sam.Pao | F11: Sam.Pao | G11: SKY JET | H11: 22.557 | I11: 3296 | J11: 33080.26 | P11: =SUBTOTAL(9,J11) -> 33080.26 | S11: =SUM(41933/68)*H11 -> 13910.039 | U11: =SUM(1400/68)*H11 -> 464.40882 | X11: =SUM(S11:W11) -> 14374.448 | Y11: =SUM(10381.24/68)*H11 -> 3443.671 | AB11: =SUM(Y11:AA11) -> 3443.671 | AC11: 7.24 | AD11: =SUM(AB11*AC11) -> 24932.178 | AE11: =SUM(X11+AD11) -> 39306.627 | AF11: =SUM(P11-AE11) -> -6226.3666
C12: 240929000010 | D12: 45564 | E12: 朱小飞 | F12: Isabel Zhu | G12: Joy | H12: 1.3975 | I12: 377 | K12: 790272 | M12: =SUM(K12/N12) -> 1885.1008 | N12: 419.22003 | O12: 7.26 | P12: =SUM(N12*O12) -> 3043.5374 | S12: =SUM(41933/68)*H12 -> 861.78482 | U12: =SUM(1400/68)*H12 -> 28.772059 | X12: =SUM(S12:W12) -> 890.55687 | Y12: =SUM(10381.24/68)*H12 -> 213.34975 | Z12: 9.86 | AB12: =SUM(Y12:AA12) -> 223.20975 | AC12: 7.24 | AD12: =SUM(AB12*AC12) -> 1616.0386 | AE12: =SUM(X12+AD12) -> 2506.5955 | AF12: =SUM(P12-AE12) -> 536.94196
C13: 240929000011（补单） | D13: 45564 | E13: 朱小飞 | F13: Isabel Zhu | G13: Joy | H13: 2.4334 | I13: 2340 | K13: 1822400 | M13: =SUM(K13/N13) -> 1700 | N13: 1072 | O13: 7.29 | P13: =SUM(N13*O13) -> 7814.88 | S13: =SUM(41933/68)*H13 -> 1500.5847 | U13: =SUM(1400/68)*H13 -> 50.099412 | X13: =SUM(S13:W13) -> 1550.6842 | Y13: =SUM(10381.24/68)*H13 -> 371.49573 | AB13: =SUM(Y13:AA13) -> 371.49573 | AC13: 7.24 | AD13: =SUM(AB13*AC13) -> 2689.6291 | AE13: =SUM(X13+AD13) -> 4240.3132 | AF13: =SUM(P13-AE13) -> 3574.5668
C14: 240929000057 | D14: 45564 | E14: 陆总 | F14: 陆梓龙 | G14: luk | H14: 0.0914 | I14: 64 | J14: 186.81 | P14: =SUBTOTAL(9,J14) -> 186.81 | S14: =SUM(41933/68)*H14 -> 56.362885 | U14: =SUM(1400/68)*H14 -> 1.8817647 | X14: =SUM(S14:W14) -> 58.24465 | Y14: =SUM(10381.24/68)*H14 -> 13.953608 | AB14: =SUM(Y14:AA14) -> 13.953608 | AC14: 7.24 | AD14: =SUM(AB14*AC14) -> 101.02412 | AE14: =SUM(X14+AD14) -> 159.26877 | AF14: =SUM(P14-AE14) -> 27.541229
A15: 合计 | J15: =SUM(J4:J4) -> 0 | N15: =SUM(N4:N4) -> 0 | P15: =SUM(P4:P4) -> 0 | Q15: =SUM(Q4:Q4) -> 0 | X15: =SUM(X4:X4) -> 0 | AD15: =SUM(AD4:AD4) -> 0 | AF15: =SUM(AF4:AF14) -> 21765.368

Sheet JOB100361
A1: 2024年10月份LOS毛利表（海运）
A2: PSL表 | B2: 体积cbm | C2: 69.5919
A3: JOB | B3: 集装编号 | C3: 运单编号 | D3: 日期 | E3: 业务 | F3: 发货人 | G3: 收货人 | H3: 计费体积 | I3: 计费重量 | J3: 应 收 | Q3: 总应收 | R3: 起 运 港 成 本 | W3: 代垫运费 | X3: 起运港成本 合计 | Y3: 目的港成本 | AE3: 总支出 | AF3: 利润
J4: 应收RMB | K4: LOS Income(NGN)收到(奈拉) | L4: LOS 收到USD | M4: 美元汇率 dollar currency rate | N4: 应收 到付款USD | O4: 汇率 | P4: 人民币 | R4: 代理商 | S4: 运费+出口报关费 | T4: 提货费 | U4: 装卸费 | V4: 包装费 | Y4: 进口报关费 | Z4: 到门配送费 | AA4: 转运费 | AB4: 目的港支出 | AC4: 汇率 | AD4: 人民币 | AE4: 起运港+目的港
A5: JOB100361 | B5: COLL004248 | C5: 240906000023 | D5: 45564 | E5: Sam.Pao | F5: Sam.Pao | G5: ChenGaoHong | H5: 11.9955 | I5: 4372 | J5: 24695 | P5: =SUBTOTAL(9,J5) -> 24695 | Q5: =SUM(P5:P22) -> 122040.48 | R5: 登凯=37199 赛捷=1500 拖车费=1670 杂费=495 过磅费=50 | S5: =SUM(40914/68)*H5 -> 7217.4101 | U5: =SUM(1000/68)*H5 -> 176.40441 | V5: =SUM(800+800) -> 1600 | X5: =SUM(S5:W5) -> 8993.8145 | Y5: =SUM(10381.24/68)*H5 -> 1831.2965 | AA5: =SUM(114.28/68)*H5 -> 20.159496 | AB5: =SUM(Y5:AA5) -> 1851.456 | AC5: 7.27 | AD5: =SUM(AB5*AC5) -> 13460.085 | AE5: =SUM(X5+AD5) -> 22453.9 | AF5: =SUM(P5-AE5) -> 2241.1001
C6: 240919000020 | D6: 45564 | E6: 吕沛霖 | F6: 喵喵速运-Layne | G6: ABDUL | H6: 1.4136 | I6: 664.5 | J6: 2907 | P6: =SUBTOTAL(9,J6) -> 2907 | S6: =SUM(40914/68)*H6 -> 850.52986 | U6: =SUM(1000/68)*H6 -> 20.788235 | X6: =SUM(S6:W6) -> 871.31809 | Y6: =SUM(10381.24/68)*H6 -> 215.80766 | AA6: =SUM(114.28/68)*H6 -> 2.3756795 | AB6: =SUM(Y6:AA6) -> 218.18334 | AC6: 7.27 | AD6: =SUM(AB6*AC6) -> 1586.1929 | AE6: =SUM(X6+AD6) -> 2457.511 | AF6: =SUM(P6-AE6) -> 449.48903
C7: 240924000057 | D7: 45564 | E7: Sam.Pao | F7: Sam.Pao | G7: Arni | H7: 1.1877 | I7: 664.44 | J7: 2625 | P7: =SUBTOTAL(9,J7) -> 2625 | S7: =SUM(40914/68)*H7 -> 714.61114 | U7: =SUM(1000/68)*H7 -> 17.466176 | X7: =SUM(S7:W7) -> 732.07732 | Y7: =SUM(10381.24/68)*H7 -> 181.32057 | AA7: =SUM(114.28/68)*H7 -> 1.9960346 | AB7: =SUM(Y7:AA7) -> 183.3166 | AC7: 7.27 | AD7: =SUM(AB7*AC7) -> 1332.7117 | AE7: =SUM(X7+AD7) -> 2064.789 | AF7: =SUM(P7-AE7) -> 560.21096
C8: 240925000034 | D8: 45564 | E8: 无人 | F8: dejare James | G8: ALH RAKIM | H8: 0.8264 | I8: 605 | J8: 3329.79 | P8: =SUBTOTAL(9,J8) -> 3329.79 | S8: =SUM(40914/68)*H8 -> 497.22544 | U8: =SUM(1000/68)*H8 -> 12.152941 | X8: =SUM(S8:W8) -> 509.37838 | Y8: =SUM(10381.24/68)*H8 -> 126.1626 | Z8: 194.84 | AA8: =SUM(114.28/68)*H8 -> 1.3888381 | AB8: =SUM(Y8:AA8) -> 322.39144 | AC8: 7.27 | AD8: =SUM(AB8*AC8) -> 2343.7857 | AE8: =SUM(X8+AD8) -> 2853.1641 | AF8: =SUM(P8-AE8) -> 476.62588
C9: 240926000001 | D9: 45564 | E9: 陆总 | F9: 陆梓龙 | G9: jizong | H9: 0.5358 | I9: 276 | J9: 1095.15 | P9: =SUBTOTAL(9,J9) -> 1095.15 | S9: =SUM(40914/68)*H9 -> 322.37825 | U9: =SUM(1000/68)*H9 -> 7.8794118 | X9: =SUM(S9:W9) -> 330.25766 | Y9: =SUM(10381.24/68)*H9 -> 81.798065 | AA9: =SUM(114.28/68)*H9 -> 0.90045918 | AB9: =SUM(Y9:AA9) -> 82.698524 | AC9: 7.27 | AD9: =SUM(AB9*AC9) -> 601.21827 | AE9: =SUM(X9+AD9) -> 931.47593 | AF9: =SUM(P9-AE9) -> 163.67407
C10: 240919000043 | D10: 45564 | E10: 黄颖 | F10: ying | G10: Mr wang | H10: 0.4921 | I10: 109 | J10: 1159 | P10: =SUBTOTAL(9,J10) -> 1159 | S10: =SUM(40914/68)*H10 -> 296.08499 | U10: =SUM(1000/68)*H10 -> 7.2367647 | X10: =SUM(S10:W10) -> 303.32176 | Y10: =SUM(10381.24/68)*H10 -> 75.126591 | AA10: =SUM(114.28/68)*H10 -> 0.82701747 | AB10: =SUM(Y10:AA10) -> 75.953609 | AC10: 7.27 | AD10: =SUM(AB10*AC10) -> 552.18274 | AE10: =SUM(X10+AD10) -> 855.50449 | AF10: =SUM(P10-AE10) -> 303.49551
C11: 240926000008 | D11: 45564 | E11: 黄颖 | F11: ying | G11: Nura | H11: 0.102 | I11: 67 | J11: 223.3 | P11: =SUBTOTAL(9,J11) -> 223.3 | S11: =SUM(40914/68)*H11 -> 61.371 | U11: =SUM(1000/68)*H11 -> 1.5 | X11: =SUM(S11:W11) -> 62.871 | Y11: =SUM(10381.24/68)*H11 -> 15.57186 | AA11: =SUM(114.28/68)*H11 -> 0.17142 | AB11: =SUM(Y11:AA11) -> 15.74328 | AC11: 7.27 | AD11: =SUM(AB11*AC11) -> 114.45365 | AE11: =SUM(X11+AD11) -> 177.32465 | AF11: =SUM(P11-AE11) -> 45.975354
C12: 240928000014 | D12: 45564 | E12: 朱小飞 | F12: Isabel Zhu | G12: Halifa Success | H12: 0.6152 | I12: 107 | J12: 1191.18 | P12: =SUBTOTAL(9,J12) -> 1191.18 | S12: =SUM(40914/68)*H12 -> 370.15136 | U12: =SUM(1000/68)*H12 -> 9.0470588 | X12: =SUM(S12:W12) -> 379.19842 | Y12: =SUM(10381.24/68)*H12 -> 93.919689 | AA12: =SUM(114.28/68)*H12 -> 1.0338979 | AB12: =SUM(Y12:AA12) -> 94.953587 | AC12: 7.27 | AD12: =SUM(AB12*AC12) -> 690.31258 | AE12: =SUM(X12+AD12) -> 1069.511 | AF12: =SUM(P12-AE12) -> 121.669
C13: 240928000015 | D13: 45564 | E13: 朱小飞 | F13: Isabel Zhu | G13: Halifa Success | H13: 0.1359 | I13: 19.5 | J13: 309.58 | P13: =SUBTOTAL(9,J13) -> 309.58 | S13: =SUM(40914/68)*H13 -> 81.767832 | U13: =SUM(1000/68)*H13 -> 1.9985294 | X13: =SUM(S13:W13) -> 83.766362 | Y13: =SUM(10381.24/68)*H13 -> 20.747213 | AA13: =SUM(114.28/68)*H13 -> 0.22839194 | AB13: =SUM(Y13:AA13) -> 20.975605 | AC13: 7.27 | AD13: =SUM(AB13*AC13) -> 152.49265 | AE13: =SUM(X13+AD13) -> 236.25901 | AF13: =SUM(P13-AE13) -> 73.320987
C14: 240929000070 | D14: 45564 | E14: Sam.Pao | F14: Sam.Pao | G14: SKY JET | H14: 14.91 | I14: 1595 | J14: 21865.81 | P14: =SUBTOTAL(9,J14) -> 21865.81 | S14: =SUM(40914/68)*H14 -> 8970.9962 | U14: =SUM(1000/68)*H14 -> 219.26471 | X14: =SUM(S14:W14) -> 9190.2609 | Y14: =SUM(10381.24/68)*H14 -> 2276.2395 | AA14: =SUM(114.28/68)*H14 -> 25.057571 | AB14: =SUM(Y14:AA14) -> 2301.2971 | AC14: 7.27 | AD14: =SUM(AB14*AC14) -> 16730.43 | AE14: =SUM(X14+AD14) -> 25920.691 | AF14: =SUM(P14-AE14) -> -4054.8808
C15: 240928000023 | D15: 45564 | E15: Sam.Pao | F15: Sam.Pao | G15: SKY JET | H15: 0.8638 | I15: 110 | J15: 1266.8 | P15: =SUBTOTAL(9,J15) -> 1266.8 | S15: =SUM(40914/68)*H15 -> 519.72814 | U15: =SUM(1000/68)*H15 -> 12.702941 | X15: =SUM(S15:W15) -> 532.43108 | Y15: =SUM(10381.24/68)*H15 -> 131.87228 | AA15: =SUM(114.28/68)*H15 -> 1.4516921 | AB15: =SUM(Y15:AA15) -> 133.32397 | AC15: 7.27 | AD15: =SUM(AB15*AC15) -> 969.26528 | AE15: =SUM(X15+AD15) -> 1501.6964 | AF15: =SUM(P15-AE15) -> -234.89636
C16: 240929000001 | D16: 45564 | E16: Sam.Pao | F16: Sam.Pao | G16: SKY JET | H16: 23.97 | I16: 2873 | J16: 35152.53 | P16: =SUBTOTAL(9,J16) -> 35152.53 | S16: =SUM(40914/68)*H16 -> 14422.185 | U16: =SUM(1000/68)*H16 -> 352.5 | X16: =SUM(S16:W16) -> 14774.685 | Y16: =SUM(10381.24/68)*H16 -> 3659.3871 | AA16: =SUM(114.28/68)*H16 -> 40.2837 | AB16: =SUM(Y16:AA16) -> 3699.6708 | AC16: 7.27 | AD16: =SUM(AB16*AC16) -> 26896.607 | AE16: =SUM(X16+AD16) -> 41671.292 | AF16: =SUM(P16-AE16) -> -6518.7617
C17: 240929000009 | D17: 45564 | E17: 朱小飞 | F17: Isabel Zhu | G17: Joy | H17: 6.006 | I17: 2236 | K17: 3392789.4 | M17: =SUM(K17/N17) -> 1883 | N17: 1801.8 | O17: 7.26 | P17: =SUM(N17*O17) -> 13081.068 | S17: =SUM(40914/68)*H17 -> 3613.6689 | U17: =SUM(1000/68)*H17 -> 88.323529 | X17: =SUM(S17:W17) -> 3701.9924 | Y17: =SUM(10381.24/68)*H17 -> 916.90776 | Z17: 72.87 | AA17: =SUM(114.28/68)*H17 -> 10.093613 | AB17: =SUM(Y17:AA17) -> 999.87137 | AC17: 7.27 | AD17: =SUM(AB17*AC17) -> 7269.0649 | AE17: =SUM(X17+AD17) -> 10971.057 | AF17: =SUM(P17-AE17) -> 2110.0107
C18: 240929000042 | D18: 45564 | E18: 罗珮文 | F18: Shirley | G18: Yusky | H18: 0.3433 | I18: 125 | J18: 643.9 | P18: =SUBTOTAL(9,J18) -> 643.9 | S18: =SUM(40914/68)*H18 -> 206.55553 | U18: =SUM(1000/68)*H18 -> 5.0485294 | X18: =SUM(S18:W18) -> 211.60406 | Y18: =SUM(10381.24/68)*H18 -> 52.409995 | AA18: =SUM(114.28/68)*H18 -> 0.57694594 | AB18: =SUM(Y18:AA18) -> 52.986941 | AC18: 7.27 | AD18: =SUM(AB18*AC18) -> 385.21506 | AE18: =SUM(X18+AD18) -> 596.81913 | AF18: =SUM(P18-AE18) -> 47.080874
C19: 240921000019 | D19: 45547 | E19: 陆总 | F19: 陆梓龙 | G19: xiantian | H19: 2.7091 | I19: 1182 | J19: 5539.61 | P19: =SUBTOTAL(9,J19) -> 5539.61 | S19: =SUM(40914/68)*H19 -> 1630.0017 | U19: =SUM(1000/68)*H19 -> 39.839706 | X19: =SUM(S19:W19) -> 1669.8414 | Y19: =SUM(10381.24/68)*H19 -> 413.58555 | AA19: =SUM(114.28/68)*H19 -> 4.5528816 | AB19: =SUM(Y19:AA19) -> 418.13843 | AC19: 7.27 | AD19: =SUM(AB19*AC19) -> 3039.8664 | AE19: =SUM(X19+AD19) -> 4709.7078 | AF19: =SUM(P19-AE19) -> 829.90218
C20: 240929000044 | D20: 45564 | E20: 罗珮文 | F20: Shirley | G20: Yusky | H20: 0.701 | I20: 79 | J20: 1314.85 | P20: =SUBTOTAL(9,J20) -> 1314.85 | S20: =SUM(40914/68)*H20 -> 421.77521 | U20: =SUM(1000/68)*H20 -> 10.308824 | X20: =SUM(S20:W20) -> 432.08403 | Y20: =SUM(10381.24/68)*H20 -> 107.01837 | AA20: =SUM(114.28/68)*H20 -> 1.1780924 | AB20: =SUM(Y20:AA20) -> 108.19646 | AC20: 7.27 | AD20: =SUM(AB20*AC20) -> 786.58829 | AE20: =SUM(X20+AD20) -> 1218.6723 | AF20: =SUM(P20-AE20) -> 96.177681
C21: 240929000045 | D21: 45564 | E21: 罗珮文 | F21: Shirley | G21: Yusky | H21: 0.2958 | I21: 34 | J21: 554.85 | P21: =SUBTOTAL(9,J21) -> 554.85 | S21: =SUM(40914/68)*H21 -> 177.9759 | U21: =SUM(1000/68)*H21 -> 4.35 | X21: =SUM(S21:W21) -> 182.3259 | Y21: =SUM(10381.24/68)*H21 -> 45.158394 | AA21: =SUM(114.28/68)*H21 -> 0.497118 | AB21: =SUM(Y21:AA21) -> 45.655512 | AC21: 7.27 | AD21: =SUM(AB21*AC21) -> 331.91557 | AE21: =SUM(X21+AD21) -> 514.24147 | AF21: =SUM(P21-AE21) -> 40.608528
C22: 240929000053 | D22: 45564 | E22: 陆总 | F22: 陆梓龙 | G22: jizong | H22: 2.4883 | I22: 449.5 | J22: 5086.06 | P22: =SUBTOTAL(9,J22) -> 5086.06 | S22: =SUM(40914/68)*H22 -> 1497.1516 | U22: =SUM(1000/68)*H22 -> 36.592647 | X22: =SUM(S22:W22) -> 1533.7442 | Y22: =SUM(10381.24/68)*H22 -> 379.87705 | AA22: =SUM(114.28/68)*H22 -> 4.1818077 | AB22: =SUM(Y22:AA22) -> 384.05886 | AC22: 7.27 | AD22: =SUM(AB22*AC22) -> 2792.1079 | AE22: =SUM(X22+AD22) -> 4325.8521 | AF22: =SUM(P22-AE22) -> 760.20789
A23: 合计 | J23: =SUM(J4:J4) -> 0 | N23: =SUM(N4:N4) -> 0 | P23: =SUM(P4:P4) -> 0 | Q23: =SUM(Q4:Q4) -> 0 | X23: =SUM(X4:X4) -> 0 | AD23: =SUM(AD4:AD4) -> 0 | AF23: =SUM(AF4:AF22) -> -2488.9901

Sheet JOB100362
A1: 2024年10月份LOS毛利表（海运）
A2: PSL表 | B2: 体积cbm | C2: 70.028
A3: JOB | B3: 集装编号 | C3: 运单编号 | D3: 日期 | E3: 业务 | F3: 发货人 | G3: 收货人 | H3: 计费体积 | I3: 计费重量 | J3: 应 收 | Q3: 总应收 | R3: 起 运 港 成 本 | W3: 代垫运费 | X3: 起运港成本 合计 | Y3: 目的港成本 | AE3: 总支出 | AF3: 利润
J4: 应收RMB | K4: LOS Income(NGN)收到(奈拉) | L4: LOS 收到USD | M4: 美元汇率 dollar currency rate | N4: 应收 到付款USD | O4: 汇率 | P4: 人民币 | R4: 代理商 | S4: 运费+出口报关费 | T4: 提货费 | U4: 装卸费 | V4: 包装费 | Y4: 进口报关费 | Z4: 到门配送费 | AA4: 转运费 | AB4: 目的港支出 | AC4: 汇率 | AD4: 人民币 | AE4: 起运港+目的港
A5: JOB100362 | B5: COLL004260 | C5: 240926000039 | D5: 45583 | E5: Sam.Pao | F5: Sam.Pao | G5: ShanShan | H5: 0.3 | I5: 65 | J5: 772 | P5: =SUBTOTAL(9,J5) -> 772 | Q5: =SUM(P5:P25) -> 135484.86 | R5: 登凯=38748 赛捷=1160 拖车费=1670 杂费=61 过磅费=67 | S5: =SUM(41706/68)*H5 -> 183.99706 | T5: =SUM(99.72/68)*H5 -> 0.43994118 | U5: =SUM(1500/68)*H5 -> 6.6176471 | X5: =SUM(S5:W5) -> 191.05465 | Y5: =SUM(10523.89/68)*H5 -> 46.428926 | Z5: 14.39 | AB5: =SUM(Y5:AA5) -> 60.818926 | AC5: 7.28 | AD5: =SUM(AB5*AC5) -> 442.76178 | AE5: =SUM(X5+AD5) -> 633.81643 | AF5: =SUM(P5-AE5) -> 138.18357
C6: 240926000032 | D6: 45580 | E6: 黄颖 | F6: ying | G6: Sunday Adelena | H6: 7.5159 | I6: 6108 | J6: 15370 | P6: =SUBTOTAL(9,J6) -> 15370 | S6: =SUM(41706/68)*H6 -> 4609.6783 | T6: =SUM(99.72/68)*H6 -> 11.021846 | U6: =SUM(1500/68)*H6 -> 165.79191 | X6: =SUM(S6:W6) -> 4786.4921 | Y6: =SUM(10523.89/68)*H6 -> 1163.1839 | AB6: =SUM(Y6:AA6) -> 1163.1839 | AC6: 7.28 | AD6: =SUM(AB6*AC6) -> 8467.9788 | AE6: =SUM(X6+AD6) -> 13254.471 | AF6: =SUM(P6-AE6) -> 2115.5292
C7: 241008000045 | D7: 45580 | E7: 黄颖 | F7: ying | G7: Wuchengxing | H7: 1.3298 | I7: 142 | J7: 2841 | P7: =SUBTOTAL(9,J7) -> 2841 | S7: =SUM(41706/68)*H7 -> 815.59763 | T7: =SUM(99.72/68)*H7 -> 1.9501126 | U7: =SUM(1500/68)*H7 -> 29.333824 | X7: =SUM(S7:W7) -> 846.88157 | Y7: =SUM(10523.89/68)*H7 -> 205.80395 | AB7: =SUM(Y7:AA7) -> 205.80395 | AC7: 7.28 | AD7: =SUM(AB7*AC7) -> 1498.2528 | AE7: =SUM(X7+AD7) -> 2345.1344 | AF7: =SUM(P7-AE7) -> 495.86564
C8: 240927000028 | D8: 45583 | E8: 吕沛霖 | F8: 喵喵速运-Layne | G8: MA ZONG | H8: 1.7904 | I8: 1841 | J8: 5660.38 | P8: =SUBTOTAL(9,J8) -> 5660.38 | S8: =SUM(41706/68)*H8 -> 1098.0944 | T8: =SUM(99.72/68)*H8 -> 2.6255689 | U8: =SUM(1500/68)*H8 -> 39.494118 | V8: 450 | X8: =SUM(S8:W8) -> 1590.2141 | Y8: =SUM(10523.89/68)*H8 -> 277.08783 | Z8: 68 | AB8: =SUM(Y8:AA8) -> 345.08783 | AC8: 7.28 | AD8: =SUM(AB8*AC8) -> 2512.2394 | AE8: =SUM(X8+AD8) -> 4102.4536 | AF8: =SUM(P8-AE8) -> 1557.9264
C9: 241008000110 | D9: 45583 | E9: Sam.Pao | F9: Sam.Pao | G9: MaiKaiNian | H9: 0.1724 | I9: 432 | J9: 1396.56 | P9: =SUBTOTAL(9,J9) -> 1396.56 | S9: =SUM(41706/68)*H9 -> 105.73698 | T9: =SUM(99.72/68)*H9 -> 0.25281953 | U9: =SUM(1500/68)*H9 -> 3.8029412 | X9: =SUM(S9:W9) -> 109.79274 | Y9: =SUM(10523.89/68)*H9 -> 26.681156 | AB9: =SUM(Y9:AA9) -> 26.681156 | AC9: 7.28 | AD9: =SUM(AB9*AC9) -> 194.23882 | AE9: =SUM(X9+AD9) -> 304.03156 | AF9: =SUM(P9-AE9) -> 1092.5284
C10: 241005000007 | D10: 45580 | E10: 黄颖 | F10: ying | G10: MISS Huang | H10: 1.7287 | I10: 674.73 | K10: 797943.5 | M10: =SUM(K10/N10) -> 1679.174 | N10: 475.2 | O10: 7.27 | P10: =SUM(N10*O10) -> 3454.704 | S10: =SUM(41706/68)*H10 -> 1060.2524 | T10: =SUM(99.72/68)*H10 -> 2.5350877 | U10: =SUM(1500/68)*H10 -> 38.133088 | X10: =SUM(S10:W10) -> 1100.9206 | Y10: =SUM(10523.89/68)*H10 -> 267.53895 | AB10: =SUM(Y10:AA10) -> 267.53895 | AC10: 7.28 | AD10: =SUM(AB10*AC10) -> 1947.6836 | AE10: =SUM(X10+AD10) -> 3048.6041 | AF10: =SUM(P10-AE10) -> 406.09988
C11: 241009000019 | D11: 45583 | E11: 黄颖 | F11: ying | G11: Wole Rasak | H11: 0.7338 | I11: 73 | J11: 1502.2 | P11: =SUBTOTAL(9,J11) -> 1502.2 | S11: =SUM(41706/68)*H11 -> 450.05681 | T11: =SUM(99.72/68)*H11 -> 1.0760961 | U11: =SUM(1500/68)*H11 -> 16.186765 | X11: =SUM(S11:W11) -> 467.31967 | Y11: =SUM(10523.89/68)*H11 -> 113.56515 | Z11: 3.45 | AB11: =SUM(Y11:AA11) -> 117.01515 | AC11: 7.28 | AD11: =SUM(AB11*AC11) -> 851.87032 | AE11: =SUM(X11+AD11) -> 1319.19 | AF11: =SUM(P11-AE11) -> 183.01001
C12: 241009000033 | D12: 45583 | E12: 陆总 | F12: 陆梓龙 | G12: leoluang | H12: 5.69 | I12: 3984 | J12: 9968.88 | P12: =SUBTOTAL(9,J12) -> 9968.88 | S12: =SUM(41706/68)*H12 -> 3489.8109 | T12: =SUM(99.72/68)*H12 -> 8.3442176 | U12: =SUM(1500/68)*H12 -> 125.51471 | X12: =SUM(S12:W12) -> 3623.6698 | Y12: =SUM(10523.89/68)*H12 -> 880.60197 | AB12: =SUM(Y12:AA12) -> 880.60197 | AC12: 7.28 | AD12: =SUM(AB12*AC12) -> 6410.7824 | AE12: =SUM(X12+AD12) -> 10034.452 | AF12: =SUM(P12-AE12) -> -65.572162
C13: 241010000022 | D13: 45583 | E13: Bella | F13: Bella Chan | G13: zhong zi xin | H13: 5.5556 | I13: 5276 | J13: 16400 | P13: =SUBTOTAL(9,J13) -> 16400 | S13: =SUM(41706/68)*H13 -> 3407.3802 | T13: =SUM(99.72/68)*H13 -> 8.147124 | U13: =SUM(1500/68)*H13 -> 122.55 | X13: =SUM(S13:W13) -> 3538.0773 | Y13: =SUM(10523.89/68)*H13 -> 859.80181 | Z13: 138.17 | AB13: =SUM(Y13:AA13) -> 997.97181 | AC13: 7.28 | AD13: =SUM(AB13*AC13) -> 7265.2348 | AE13: =SUM(X13+AD13) -> 10803.312 | AF13: =SUM(P13-AE13) -> 5596.6879
C14: 241012000025 | D14: 45583 | E14: 吕沛霖 | F14: 喵喵速运-Layne | G14: Sue | H14: 0.9445 | I14: 434 | K14: 559350 | M14: =SUM(K14/N14) -> 1650 | N14: 339 | O14: 7.29 | P14: =SUM(N14*O14) -> 2471.31 | S14: =SUM(41706/68)*H14 -> 579.28407 | T14: =SUM(99.72/68)*H14 -> 1.3850815 | U14: =SUM(1500/68)*H14 -> 20.834559 | X14: =SUM(S14:W14) -> 601.50371 | Y14: =SUM(10523.89/68)*H14 -> 146.17374 | AB14: =SUM(Y14:AA14) -> 146.17374 | AC14: 7.28 | AD14: =SUM(AB14*AC14) -> 1064.1448 | AE14: =SUM(X14+AD14) -> 1665.6485 | AF14: =SUM(P14-AE14) -> 805.66148
C15: 241012000031 | D15: 45583 | E15: 黄颖 | F15: ying | G15: liufang | H15: 2.0788 | I15: 174 | K15: 1322400 | M15: =SUM(K15/N15) -> 1675.812 | N15: 789.11 | O15: 7.29 | P15: =SUM(N15*O15) -> 5752.6119 | S15: =SUM(41706/68)*H15 -> 1274.977 | T15: =SUM(99.72/68)*H15 -> 3.0484991 | U15: =SUM(1500/68)*H15 -> 45.855882 | V15: 240 | X15: =SUM(S15:W15) -> 1563.8813 | Y15: =SUM(10523.89/68)*H15 -> 321.72151 | AB15: =SUM(Y15:AA15) -> 321.72151 | AC15: 7.28 | AD15: =SUM(AB15*AC15) -> 2342.1326 | AE15: =SUM(X15+AD15) -> 3906.0139 | AF15: =SUM(P15-AE15) -> 1846.598
C16: 241014000064 | D16: 45583 | E16: 苏慧琪 | F16: KAY | G16: WENXIAOBING | H16: 0.1024 | I16: 35 | K16: 71551 | M16: =SUM(K16/N16) -> 1690.3142 | N16: 42.33 | O16: 7.27 | P16: =SUM(N16*O16) -> 307.7391 | S16: =SUM(41706/68)*H16 -> 62.804329 | T16: =SUM(99.72/68)*H16 -> 0.15016659 | U16: =SUM(1500/68)*H16 -> 2.2588235 | X16: =SUM(S16:W16) -> 65.21332 | Y16: =SUM(10523.89/68)*H16 -> 15.84774 | AB16: =SUM(Y16:AA16) -> 15.84774 | AC16: 7.28 | AD16: =SUM(AB16*AC16) -> 115.37155 | AE16: =SUM(X16+AD16) -> 180.58487 | AF16: =SUM(P16-AE16) -> 127.15423
C17: 241015000036 | D17: 45583 | E17: 罗珮文 | F17: Shirley | G17: Yusky | H17: 1.1644 | I17: 178 | K17: 480476 | M17: =SUM(K17/N17) -> 1630.999 | N17: 294.59 | O17: 7.35 | P17: =SUM(N17*O17) -> 2165.2365 | S17: =SUM(41706/68)*H17 -> 714.15392 | T17: =SUM(99.72/68)*H17 -> 1.7075584 | U17: =SUM(1500/68)*H17 -> 25.685294 | X17: =SUM(S17:W17) -> 741.54677 | Y17: =SUM(10523.89/68)*H17 -> 180.20614 | AB17: =SUM(Y17:AA17) -> 180.20614 | AC17: 7.28 | AD17: =SUM(AB17*AC17) -> 1311.9007 | AE17: =SUM(X17+AD17) -> 2053.4475 | AF17: =SUM(P17-AE17) -> 111.78903
C18: 241015000037 | D18: 45583 | E18: 罗珮文 | F18: Shirley | G18: Yusky | H18: 1.8977 | I18: 816 | K18: 783075 | M18: =SUM(K18/N18) -> 1630.9985 | N18: 480.12 | O18: 7.35 | P18: =SUM(N18*O18) -> 3528.882 | S18: =SUM(41706/68)*H18 -> 1163.9041 | T18: =SUM(99.72/68)*H18 -> 2.7829212 | U18: =SUM(1500/68)*H18 -> 41.861029 | X18: =SUM(S18:W18) -> 1208.548 | Y18: =SUM(10523.89/68)*H18 -> 293.69391 | AB18: =SUM(Y18:AA18) -> 293.69391 | AC18: 7.28 | AD18: =SUM(AB18*AC18) -> 2138.0917 | AE18: =SUM(X18+AD18) -> 3346.6397 | AF18: =SUM(P18-AE18) -> 182.2423
C19: 241015000040 | D19: 45583 | E19: 罗珮文 | F19: Shirley | G19: Yusky | H19: 1.7374 | I19: 1047 | K19: 716971 | M19: =SUM(K19/N19) -> 1630.9993 | N19: 439.59 | O19: 7.35 | P19: =SUM(N19*O19) -> 3230.9865 | S19: =SUM(41706/68)*H19 -> 1065.5883 | T19: =SUM(99.72/68)*H19 -> 2.547846 | U19: =SUM(1500/68)*H19 -> 38.325 | X19: =SUM(S19:W19) -> 1106.4611 | Y19: =SUM(10523.89/68)*H19 -> 268.88539 | AB19: =SUM(Y19:AA19) -> 268.88539 | AC19: 7.28 | AD19: =SUM(AB19*AC19) -> 1957.4856 | AE19: =SUM(X19+AD19) -> 3063.9468 | AF19: =SUM(P19-AE19) -> 167.03972
