Workbook

Sheet 总表 
A1: 2024年09月份LOS毛利表（海运）
A2: JOB | B2: 集装编号 | C2: 利润
A4: JOB090350 | B4: COLL004142 | C4: =SUM('JOB090350'!AF18) -> -3667.9355
A17: JOB090351 | B17: COLL004143 | C17: =SUM('JOB090351'!AF16) -> 4152.4575
A28: JOB090364 | B28: COLL004256 | C28: =SUM('JOB090364'!AF30) -> 33956.712
A53: JOB090366 | B53: COLL004158 | C53: =SUM('JOB090366'!AF10) -> 1577.5442
A58: JOB090367 | B58: COLL004161 | C58: =SUM('JOB090367'!AF5) -> -65.7888
A59: JOB090368 | B59: COLL004162 | C59: =SUM('JOB090368'!AF5) -> 10744.571
A60: JOB090375 | B60: COLL004167 | C60: =SUM('JOB090375'!AF26) -> 19561.749
A81: JOB090387 | B81: COLL004180 | C81: =SUM('JOB090387'!AF19) -> 14960.735
A95: JOB090388 | B95: COLL004181 | C95: =SUM('JOB090388'!AF15) -> 12199.609
A105: JOB110331 | B105: COLL004224 | C105: =SUM('JOB110331'!AF5) -> 15800.516
A106: JOB100351 | B106: COLL004217 | C106: =SUM('JOB100351'!AF5) -> 31841.086
A107: 合计 | C107: =SUM(C3:C106) -> 141061.26

Sheet 总表 (2)
A1: 2024年09月份LOS毛利表（海运）
A2: JOB | B2: 集装编号 | C2: 运单编号 | D2: 日期 | E2: 业务 | F2: 发货人 | G2: 收货人 | H2: 计费体积 | I2: 计费重量 | J2: 应 收 | Q2: 总应收 | R2: 起 运 港 成 本 | W2: 代垫运费 | X2: 起运港成本 合计 | Y2: 目的港成本 | AE2: 总支出 | AF2: 利润
J3: 应收RMB | K3: LOS Income(NGN)收到(奈拉) | L3: LOS 收到USD | M3: 美元汇率 dollar currency rate | N3: 应收 到付款USD | O3: 汇率 | P3: 人民币 | R3: 代理商 | S3: 运费+出口报关费 | T3: 提货费 | U3: 装卸费 | V3: 包装费 | Y3: 进口报关费 | Z3: 到门配送费 | AA3: 转运费 | AB3: 目的港支出 | AC3: 汇率 | AD3: 人民币 | AE3: 起运港+目的港
A4: JOB090350 | B4: COLL004142 | C4: 240807000019 | D4: 45539 | E4: Sam.Pao | F4: Sam.Pao | G4: Nick Wang | H4: 55.0796 | I4: 14200 | J4: 26216.12 | K4: 21550555 | M4: =SUM(K4/N4) -> 1560.2607 | N4: 13812.15 | O4: 7.24 | P4: =SUM(N4*O4+J4) -> 126216.09 | Q4: =SUM(P4:P16) -> 196493.64 | R4: 登凯=48459 赛捷=1120 拖车费=1670 杂费=81 过磅费=61 | S4: =SUM(51391/68)*H4 -> 41626.408 | U4: =SUM(1450/68)*H4 -> 1174.4915 | V4: 600 | W4: =SUM(235.5+800) -> 1035.5 | X4: =SUM(S4:W4) -> 44436.399 | Y4: =SUM(10737.46/68)*H4 -> 8697.2794 | Z4: 1858.41 | AB4: =SUM(Y4:AA4) -> 10555.689 | AC4: 7.12 | AD4: =SUM(AB4*AC4) -> 75156.509 | AE4: =SUM(X4+AD4) -> 119592.91 | AF4: =SUM(P4-AE4) -> 6623.178
C5: 240827000016 | D5: 45539 | E5: Bella | F5: Bella Chan | G5: new hope 边鹏飞 | H5: 0.2537 | I5: 138 | K5: 202127.5 | M5: =SUM(K5/N5) -> 1735 | N5: 116.5 | O5: 7.12 | P5: =SUM(N5*O5) -> 829.48 | S5: =SUM(51391/68)*H5 -> 191.73378 | U5: =SUM(1450/68)*H5 -> 5.4097794 | W5: 240 | X5: =SUM(S5:W5) -> 437.14355 | Y5: =SUM(10737.46/68)*H5 -> 40.0602 | AB5: =SUM(Y5:AA5) -> 40.0602 | AC5: 7.12 | AD5: =SUM(AB5*AC5) -> 285.22862 | AE5: =SUM(X5+AD5) -> 722.37218 | AF5: =SUM(P5-AE5) -> 107.10782
C6: 240827000023 | D6: 45539 | E6: Sam.Pao | F6: Sam.Pao | G6: Adesoye | H6: 3.027 | I6: 2480 | K6: 1916044.9 | M6: =SUM(K6/N6) -> 1745 | N6: 1098.02 | O6: 7.12 | P6: =SUM(N6*O6) -> 7817.9024 | S6: =SUM(51391/68)*H6 -> 2287.6552 | U6: =SUM(1450/68)*H6 -> 64.546324 | X6: =SUM(S6:W6) -> 2352.2016 | Y6: =SUM(10737.46/68)*H6 -> 477.97487 | AB6: =SUM(Y6:AA6) -> 477.97487 | AC6: 7.12 | AD6: =SUM(AB6*AC6) -> 3403.1811 | AE6: =SUM(X6+AD6) -> 5755.3827 | AF6: =SUM(P6-AE6) -> 2062.5197
C7: 240828000016 | D7: 45539 | E7: 吕沛霖 | F7: 喵喵速运-Layne | G7: SHAEK | H7: 0.1625 | I7: 169 | J7: 1258.39 | P7: =SUBTOTAL(9,J7) -> 1258.39 | S7: =SUM(51391/68)*H7 -> 122.80938 | U7: =SUM(1450/68)*H7 -> 3.4650735 | X7: =SUM(S7:W7) -> 126.27445 | Y7: =SUM(10737.46/68)*H7 -> 25.659371 | Z7: 93.95 | AB7: =SUM(Y7:AA7) -> 119.60937 | AC7: 7.12 | AD7: =SUM(AB7*AC7) -> 851.61872 | AE7: =SUM(X7+AD7) -> 977.89317 | AF7: =SUM(P7-AE7) -> 280.49683
C8: 240828000064 | D8: 45539 | E8: Bella | F8: Bella Chan | G8: zhong zi xin | H8: 2.368 | I8: 2617 | K8: 2020000 | M8: =SUM(K8/N8) -> 1688.522 | N8: 1196.3125 | O8: 7.23 | P8: =SUM(N8*O8) -> 8649.3394 | S8: =SUM(51391/68)*H8 -> 1789.616 | U8: =SUM(1450/68)*H8 -> 50.494118 | X8: =SUM(S8:W8) -> 1840.1101 | Y8: =SUM(10737.46/68)*H8 -> 373.91625 | Z8: 70.8 | AB8: =SUM(Y8:AA8) -> 444.71625 | AC8: 7.12 | AD8: =SUM(AB8*AC8) -> 3166.3797 | AE8: =SUM(X8+AD8) -> 5006.4898 | AF8: =SUM(P8-AE8) -> 3642.8495
C9: 240830000003 | D9: 45539 | E9: Sam.Pao | F9: Sam.Pao | G9: ERICA | H9: 0.1448 | I9: 20 | J9: 333.6 | P9: =SUBTOTAL(9,J9) -> 333.6 | S9: =SUM(51391/68)*H9 -> 109.4326 | U9: =SUM(1450/68)*H9 -> 3.0876471 | X9: =SUM(S9:W9) -> 112.52025 | Y9: =SUM(10737.46/68)*H9 -> 22.864474 | Z9: 5.9 | AB9: =SUM(Y9:AA9) -> 28.764474 | AC9: 7.12 | AD9: =SUM(AB9*AC9) -> 204.80305 | AE9: =SUM(X9+AD9) -> 317.3233 | AF9: =SUM(P9-AE9) -> 16.276701
C10: 240830000027 | D10: 45539 | E10: 罗伟健 | F10: MailMail速运-演员 | G10: Harvey Wang | H10: 0.866 | I10: 98 | J10: 1871 | P10: =SUBTOTAL(9,J10) -> 1871 | S10: =SUM(51391/68)*H10 -> 654.4795 | U10: =SUM(1450/68)*H10 -> 18.466176 | X10: =SUM(S10:W10) -> 672.94568 | Y10: =SUM(10737.46/68)*H10 -> 136.74471 | AB10: =SUM(Y10:AA10) -> 136.74471 | AC10: 7.12 | AD10: =SUM(AB10*AC10) -> 973.62234 | AE10: =SUM(X10+AD10) -> 1646.568 | AF10: =SUM(P10-AE10) -> 224.43198
C11: 240830000048 | D11: 45539 | E11: 无人 | F11: dejare James | G11: James | H11: 2.146 | I11: 268 | L11: 640.17 | M11: =SUM(K11/N11) -> 0 | N11: 640.17 | O11: 7.3 | P11: =SUM(N11*O11) -> 4673.241 | S11: =SUM(51391/68)*H11 -> 1621.8395 | U11: =SUM(1450/68)*H11 -> 45.760294 | X11: =SUM(S11:W11) -> 1667.5998 | Y11: =SUM(10737.46/68)*H11 -> 338.86161 | AB11: =SUM(Y11:AA11) -> 338.86161 | AC11: 7.12 | AD11: =SUM(AB11*AC11) -> 2412.6946 | AE11: =SUM(X11+AD11) -> 4080.2944 | AF11: =SUM(P11-AE11) -> 592.94658
C12: 240728000003 | D12: 45506 | E12: Sam.Pao | F12: Sam.Pao | G12: Nick Wang | H12: 0.42 | I12: 160 | J12: 1132 | P12: =SUBTOTAL(9,J12) -> 1132 | S12: =SUM(51391/68)*H12 -> 317.415 | U12: =SUM(1450/68)*H12 -> 8.9558824 | X12: =SUM(S12:W12) -> 326.37088 | Y12: =SUM(10737.46/68)*H12 -> 66.319606 | Z12: 31.76 | AB12: =SUM(Y12:AA12) -> 98.079606 | AC12: 7.12 | AD12: =SUM(AB12*AC12) -> 698.32679 | AE12: =SUM(X12+AD12) -> 1024.6977 | AF12: =SUM(P12-AE12) -> 107.30232
C13: 240904000001 | D13: 45539 | E13: Sam.Pao | F13: Sam.Pao | G13: SKY JET | H13: 19.05 | I13: 2484 | J13: 25671.21 | P13: =SUBTOTAL(9,J13) -> 25671.21 | S13: =SUM(51391/68)*H13 -> 14397.038 | U13: =SUM(1450/68)*H13 -> 406.21324 | X13: =SUM(S13:W13) -> 14803.251 | Y13: =SUM(10737.46/68)*H13 -> 3008.0678 | AB13: =SUM(Y13:AA13) -> 3008.0678 | AC13: 7.12 | AD13: =SUM(AB13*AC13) -> 21417.443 | AE13: =SUM(X13+AD13) -> 36220.694 | AF13: =SUM(P13-AE13) -> -10549.484
C14: 240904000027 | D14: 45539 | E14: 黄颖 | F14: ying | G14: zhounengquan | H14: 0.057 | I14: 22 | K14: 55920 | M14: =SUM(K14/N14) -> 1679.2793 | N14: 33.3 | O14: 7.12 | P14: 237.1 | S14: =SUM(51391/68)*H14 -> 43.07775 | U14: =SUM(1450/68)*H14 -> 1.2154412 | X14: =SUM(S14:W14) -> 44.293191 | Y14: =SUM(10737.46/68)*H14 -> 9.0005179 | Z14: 7.02 | AB14: =SUM(Y14:AA14) -> 16.020518 | AC14: 7.12 | AD14: =SUM(AB14*AC14) -> 114.06609 | AE14: =SUM(X14+AD14) -> 158.35928 | AF14: =SUM(P14-AE14) -> 78.740721
C15: 240904000002 | D15: 45539 | E15: Sam.Pao | F15: Sam.Pao | G15: SKY JET | H15: 12.5 | I15: 19 | J15: 16844.63 | P15: =SUBTOTAL(9,J15) -> 16844.63 | S15: =SUM(51391/68)*H15 -> 9446.875 | U15: =SUM(1450/68)*H15 -> 266.54412 | X15: =SUM(S15:W15) -> 9713.4191 | Y15: =SUM(10737.46/68)*H15 -> 1973.7978 | AB15: =SUM(Y15:AA15) -> 1973.7978 | AC15: 7.12 | AD15: =SUM(AB15*AC15) -> 14053.44 | AE15: =SUM(X15+AD15) -> 23766.859 | AF15: =SUM(P15-AE15) -> -6922.2294
C16: 240904000021 | D16: 45539 | E16: 陆总 | F16: 陆梓龙 | G16: luk | H16: 0.469 | I16: 105 | J16: 959.66 | P16: =SUBTOTAL(9,J16) -> 959.66 | S16: =SUM(51391/68)*H16 -> 354.44675 | U16: =SUM(1450/68)*H16 -> 10.000735 | X16: =SUM(S16:W16) -> 364.44749 | Y16: =SUM(10737.46/68)*H16 -> 74.056893 | AB16: =SUM(Y16:AA16) -> 74.056893 | AC16: 7.12 | AD16: =SUM(AB16*AC16) -> 527.28508 | AE16: =SUM(X16+AD16) -> 891.73257 | AF16: =SUM(P16-AE16) -> 67.927435
A17: JOB090351 | B17: COLL004143 | C17: 240828000043 | D17: 45539 | E17: 吕沛霖 | F17: 喵喵速运-Layne | G17: ABDUL | H17: 6.8939 | I17: 3722 | K17: 3417687 | M17: =SUM(K17/N17) -> 1690 | N17: 2022.3 | O17: 7.3 | P17: =SUM(N17*O17) -> 14762.79 | Q17: =SUM(P17:P27) -> 153607.29 | R17: 登凯=44776 赛捷=1750 拖车费=2270 杂费=1388 过磅费=65 | S17: =SUM(50249/68)*H17 -> 5094.288 | T17: =SUM(116.62/68)*H17 -> 11.823038 | U17: =SUM(1750/68)*H17 -> 177.41654 | X17: =SUM(S17:W17) -> 5283.5275 | Y17: =SUM(10737.46/68)*H17 -> 1088.5732 | Z17: 91.45 | AA17: =SUM(70.8/68)*H17 -> 7.1777665 | AB17: =SUM(Y17:AA17) -> 1187.2009 | AC17: 7.12 | AD17: =SUM(AB17*AC17) -> 8452.8707 | AE17: =SUM(X17+AD17) -> 13736.398 | AF17: =SUM(P17-AE17) -> 1026.3918
C18: 240828000069 | D18: 45539 | E18: 陆总 | F18: 陆梓龙 | G18: xiantian | H18: 3.615 | I18: 1442 | J18: 9176.76 | P18: =SUBTOTAL(9,J18) -> 9176.76 | S18: =SUM(50249/68)*H18 -> 2671.3255 | T18: =SUM(116.62/68)*H18 -> 6.199725 | U18: =SUM(1750/68)*H18 -> 93.033088 | X18: =SUM(S18:W18) -> 2770.5583 | Y18: =SUM(10737.46/68)*H18 -> 570.82232 | Z18: 100.29 | AA18: =SUM(70.8/68)*H18 -> 3.7638529 | AB18: =SUM(Y18:AA18) -> 674.87617 | AC18: 7.12 | AD18: =SUM(AB18*AC18) -> 4805.1184 | AE18: =SUM(X18+AD18) -> 7575.6767 | AF18: =SUM(P18-AE18) -> 1601.0833
C19: 240819000017 | D19: 45516 | E19: 吕沛霖 | F19: 喵喵速运-Layne | G19: WEI PING | H19: 4.904 | I19: 848 | J19: 10475 | P19: =SUBTOTAL(9,J19) -> 10475 | S19: =SUM(50249/68)*H19 -> 3623.8396 | T19: =SUM(116.62/68)*H19 -> 8.41036 | U19: =SUM(1750/68)*H19 -> 126.20588 | X19: =SUM(S19:W19) -> 3758.4559 | Y19: =SUM(10737.46/68)*H19 -> 774.36035 | AA19: =SUM(70.8/68)*H19 -> 5.1059294 | AB19: =SUM(Y19:AA19) -> 779.46628 | AC19: 7.12 | AD19: =SUM(AB19*AC19) -> 5549.7999 | AE19: =SUM(X19+AD19) -> 9308.2558 | AF19: =SUM(P19-AE19) -> 1166.7442
C20: 240902000041 | D20: 45539 | E20: 朱小飞 | F20: Isabel Zhu | G20: Mr Qiu | H20: 0.5458 | I20: 230 | K20: 436950 | M20: =SUM(K20/N20) -> 1779.04 | N20: 245.60999 | O20: 7.08 | P20: =SUM(N20*O20) -> 1738.9187 | S20: =SUM(50249/68)*H20 -> 403.32212 | T20: =SUM(116.62/68)*H20 -> 0.936047 | U20: =SUM(1750/68)*H20 -> 14.046324 | X20: =SUM(S20:W20) -> 418.30449 | Y20: =SUM(10737.46/68)*H20 -> 86.183907 | AA20: =SUM(70.8/68)*H20 -> 0.56827412 | AB20: =SUM(Y20:AA20) -> 86.752181 | AC20: 7.12 | AD20: =SUM(AB20*AC20) -> 617.67553 | AE20: =SUM(X20+AD20) -> 1035.98 | AF20: =SUM(P20-AE20) -> 702.93871
C21: 240902000057 | D21: 45539 | E21: 陆总 | F21: 陆梓龙 | G21: WANG | H21: 0.2102 | I21: 74 | J21: 573.06 | P21: =SUBTOTAL(9,J21) -> 573.06 | S21: =SUM(50249/68)*H21 -> 155.32853 | T21: =SUM(116.62/68)*H21 -> 0.360493 | U21: =SUM(1750/68)*H21 -> 5.4095588 | X21: =SUM(S21:W21) -> 161.09858 | Y21: =SUM(10737.46/68)*H21 -> 33.191384 | AA21: =SUM(70.8/68)*H21 -> 0.21885529 | AB21: =SUM(Y21:AA21) -> 33.410239 | AC21: 7.12 | AD21: =SUM(AB21*AC21) -> 237.8809 | AE21: =SUM(X21+AD21) -> 398.97948 | AF21: =SUM(P21-AE21) -> 174.08052
C22: 240903000009 | D22: 45539 | E22: Sam.Pao | F22: Sam.Pao | G22: MaiKaiNian | H22: 0.2574 | I22: 150 | J22: 630.11 | P22: =SUBTOTAL(9,J22) -> 630.11 | S22: =SUM(50249/68)*H22 -> 190.20724 | T22: =SUM(116.62/68)*H22 -> 0.441441 | U22: =SUM(1750/68)*H22 -> 6.6242647 | X22: =SUM(S22:W22) -> 197.27295 | Y22: =SUM(10737.46/68)*H22 -> 40.644444 | AA22: =SUM(70.8/68)*H22 -> 0.26799882 | AB22: =SUM(Y22:AA22) -> 40.912443 | AC22: 7.12 | AD22: =SUM(AB22*AC22) -> 291.29659 | AE22: =SUM(X22+AD22) -> 488.56954 | AF22: =SUM(P22-AE22) -> 141.54046
C23: 240903000015 | D23: 45539 | E23: 朱小飞 | F23: Isabel Zhu | G23: Halifa Success | H23: 0.42 | I23: 62 | J23: 959.18 | P23: =SUBTOTAL(9,J23) -> 959.18 | S23: =SUM(50249/68)*H23 -> 310.36147 | T23: =SUM(116.62/68)*H23 -> 0.7203 | U23: =SUM(1750/68)*H23 -> 10.808824 | X23: =SUM(S23:W23) -> 321.89059 | Y23: =SUM(10737.46/68)*H23 -> 66.319606 | AA23: =SUM(70.8/68)*H23 -> 0.43729412 | AB23: =SUM(Y23:AA23) -> 66.7569 | AC23: 7.12 | AD23: =SUM(AB23*AC23) -> 475.30913 | AE23: =SUM(X23+AD23) -> 797.19972 | AF23: =SUM(P23-AE23) -> 161.98028
C24: 240902000056 | D24: 45547 | E24: 吕沛霖 | F24: 喵喵速运-Layne | G24: Hu Hai Liang | H24: 0.512 | I24: 51 | K24: 289240 | M24: =SUM(K24/N24) -> 1752.9697 | N24: 165 | O24: 7.23 | P24: =SUM(N24*O24) -> 1192.95 | S24: =SUM(50249/68)*H24 -> 378.34541 | T24: =SUM(116.62/68)*H24 -> 0.87808 | U24: =SUM(1750/68)*H24 -> 13.176471 | X24: =SUM(S24:W24) -> 392.39996 | Y24: =SUM(10737.46/68)*H24 -> 80.846758 | AA24: =SUM(70.8/68)*H24 -> 0.53308235 | AB24: =SUM(Y24:AA24) -> 81.37984 | AC24: 7.12 | AD24: =SUM(AB24*AC24) -> 579.42446 | AE24: =SUM(X24+AD24) -> 971.82442 | AF24: =SUM(P24-AE24) -> 221.12558
C25: 240813000017 | D25: 45539 | E25: Sam.Pao | F25: Sam.Pao | G25: AiGeLi | H25: 21.51 | I25: 13906 | J25: 59293 | P25: =SUBTOTAL(9,J25) -> 59293 | S25: =SUM(50249/68)*H25 -> 15894.941 | T25: =SUM(116.62/68)*H25 -> 36.88965 | U25: =SUM(1750/68)*H25 -> 553.56618 | V25: 500 | X25: =SUM(S25:W25) -> 16985.397 | Y25: =SUM(10737.46/68)*H25 -> 3396.5112 | Z25: 1415.93 | AA25: =SUM(70.8/68)*H25 -> 22.395706 | AB25: =SUM(Y25:AA25) -> 4834.8369 | AC25: 7.12 | AD25: =SUM(AB25*AC25) -> 34424.039 | AE25: =SUM(X25+AD25) -> 51409.436 | AF25: =SUM(P25-AE25) -> 7883.5641
C26: 240828000061 | D26: 45539 | E26: Sam.Pao | F26: Sam.Pao | G26: JunYue hotel | H26: 2.6171 | I26: 719.5 | J26: 5838 | P26: =SUBTOTAL(9,J26) -> 5838 | S26: =SUM(50249/68)*H26 -> 1933.9214 | T26: =SUM(116.62/68)*H26 -> 4.4883265 | U26: =SUM(1750/68)*H26 -> 67.351838 | X26: =SUM(S26:W26) -> 2005.7616 | Y26: =SUM(10737.46/68)*H26 -> 413.2501 | AA26: =SUM(70.8/68)*H26 -> 2.7248629 | AB26: =SUM(Y26:AA26) -> 415.97496 | AC26: 7.12 | AD26: =SUM(AB26*AC26) -> 2961.7417 | AE26: =SUM(X26+AD26) -> 4967.5033 | AF26: =SUM(P26-AE26) -> 870.49668
C27: 240904000002 | D27: 45539 | E27: Sam.Pao | F27: Sam.Pao | G27: SKY JET | H27: 30.96 | I27: 3682.5 | J27: 48967.52 | P27: =SUBTOTAL(9,J27) -> 48967.52 | S27: =SUM(50249/68)*H27 -> 22878.074 | T27: =SUM(116.62/68)*H27 -> 53.0964 | U27: =SUM(1750/68)*H27 -> 796.76471 | X27: =SUM(S27:W27) -> 23727.935 | Y27: =SUM(10737.46/68)*H27 -> 4888.7024 | AA27: =SUM(70.8/68)*H27 -> 32.234824 | AB27: =SUM(Y27:AA27) -> 4920.9372 | AC27: 7.12 | AD27: =SUM(AB27*AC27) -> 35037.073 | AE27: =SUM(X27+AD27) -> 58765.008 | AF27: =SUM(P27-AE27) -> -9797.4881
A28: JOB090364 | B28: COLL004256 | C28: 240726000055 | D28: 45547 | E28: Sam.Pao | F28: Sam.Pao | G28: ShanShan | H28: 5.09 | I28: 677 | J28: 13067 | P28: =SUBTOTAL(9,J28) -> 13067 | Q28: =SUM(P28:P52) -> 158115.17 | R28: 登凯=41647 赛捷=1280 拖车费=1670 杂费=73 过磅费=68 | S28: =SUM(44738/68)*H28 -> 3348.7709 | U28: =SUM(1300/68)*H28 -> 97.308824 | X28: =SUM(S28:W28) -> 3446.0797 | Y28: =SUM(10737.46/68)*H28 -> 803.73046 | Z28: 47.2 | AB28: =SUM(Y28:AA28) -> 850.93046 | AC28: 7.12 | AD28: =SUM(AB28*AC28) -> 6058.6249 | AE28: =SUM(X28+AD28) -> 9504.7046 | AF28: =SUM(P28-AE28) -> 3562.2954
C29: 240813000017 | D29: 45547 | E29: Sam.Pao | F29: Sam.Pao | G29: AiGeLi | H29: 2.1368 | I29: 256 | J29: 5889 | P29: =SUBTOTAL(9,J29) -> 5889 | S29: =SUM(44738/68)*H29 -> 1405.8259 | U29: =SUM(1300/68)*H29 -> 40.850588 | X29: =SUM(S29:W29) -> 1446.6764 | Y29: =SUM(10737.46/68)*H29 -> 337.40889 | AB29: =SUM(Y29:AA29) -> 337.40889 | AC29: 7.12 | AD29: =SUM(AB29*AC29) -> 2402.3513 | AE29: =SUM(X29+AD29) -> 3849.0277 | AF29: =SUM(P29-AE29) -> 2039.9723
C30: 240902000015 | D30: 45547 | E30: 黄颖 | F30: ying | G30: Ms PEJU | H30: 3.028 | I30: 338 | J30: 7000 | P30: =SUBTOTAL(9,J30) -> 7000 | S30: =SUM(44738/68)*H30 -> 1992.1568 | U30: =SUM(1300/68)*H30 -> 57.888235 | X30: =SUM(S30:W30) -> 2050.0451 | Y30: =SUM(10737.46/68)*H30 -> 478.13278 | AB30: =SUM(Y30:AA30) -> 478.13278 | AC30: 7.12 | AD30: =SUM(AB30*AC30) -> 3404.3054 | AE30: =SUM(X30+AD30) -> 5454.3504 | AF30: =SUM(P30-AE30) -> 1545.6496
C31: 240902000056 | D31: 45547 | E31: 吕沛霖 | F31: 喵喵速运-Layne | G31: Hu Hai Liang | H31: 3.078 | I31: 521 | K31: 1738835 | M31: =SUM(K31/N31) -> 1754.4319 | N31: 991.11 | O31: 7.23 | P31: =SUM(N31*O31) -> 7165.7253 | S31: =SUM(44738/68)*H31 -> 2025.0524 | U31: =SUM(1300/68)*H31 -> 58.844118 | V31: 580 | X31: =SUM(S31:W31) -> 2663.8965 | Y31: =SUM(10737.46/68)*H31 -> 486.02797 | AB31: =SUM(Y31:AA31) -> 486.02797 | AC31: 7.12 | AD31: =SUM(AB31*AC31) -> 3460.5191 | AE31: =SUM(X31+AD31) -> 6124.4157 | AF31: =SUM(P31-AE31) -> 1041.3096
C32: 240904000027 | D32: 45547 | E32: 黄颖 | F32: ying | G32: zhounengquan | H32: 0.0074 | I32: 6 | K32: 7260 | M32: =SUM(K32/N32) -> 2261.6822 | N32: 3.21 | O32: 7.12 | P32: 22.9 | S32: =SUM(44738/68)*H32 -> 4.8685471 | U32: =SUM(1300/68)*H32 -> 0.14147059 | X32: =SUM(S32:W32) -> 5.0100176 | Y32: =SUM(10737.46/68)*H32 -> 1.1684883 | AB32: =SUM(Y32:AA32) -> 1.1684883 | AC32: 7.12 | AD32: =SUM(AB32*AC32) -> 8.3196367 | AE32: =SUM(X32+AD32) -> 13.329654 | AF32: =SUM(P32-AE32) -> 9.5703457
C33: 240904000032 | D33: 45547 | E33: 黄颖 | F33: ying | G33: Bruce | H33: 2.736 | I33: 1216 | J33: 5623 | P33: =SUBTOTAL(9,J33) -> 5623 | S33: =SUM(44738/68)*H33 -> 1800.0466 | U33: =SUM(1300/68)*H33 -> 52.305882 | X33: =SUM(S33:W33) -> 1852.3525 | Y33: =SUM(10737.46/68)*H33 -> 432.02486 | AB33: =SUM(Y33:AA33) -> 432.02486 | AC33: 7.12 | AD33: =SUM(AB33*AC33) -> 3076.017 | AE33: =SUM(X33+AD33) -> 4928.3695 | AF33: =SUM(P33-AE33) -> 694.63052
C34: 240904000040 | D34: 45547 | E34: 朱小飞 | F34: Isabel Zhu | G34: Victor Nnamdi | H34: 1.449 | I34: 227 | K34: 761250 | M34: =SUM(K34/N34) -> 1751.1952 | N34: 434.70312 | O34: 7.08 | P34: =SUM(N34*O34) -> 3077.6981 | S34: =SUM(44738/68)*H34 -> 953.31415 | U34: =SUM(1300/68)*H34 -> 27.701471 | X34: =SUM(S34:W34) -> 981.01562 | Y34: =SUM(10737.46/68)*H34 -> 228.80264 | AB34: =SUM(Y34:AA34) -> 228.80264 | AC34: 7.12 | AD34: =SUM(AB34*AC34) -> 1629.0748 | AE34: =SUM(X34+AD34) -> 2610.0904 | AF34: =SUM(P34-AE34) -> 467.60767
C35: 240828000061 | D35: 45539 | E35: Sam.Pao | F35: Sam.Pao | G35: JunYue hotel | H35: 5.2294 | I35: 555 | J35: 11683.3 | P35: =SUBTOTAL(9,J35) -> 11683.3 | S35: =SUM(44738/68)*H35 -> 3440.4838 | U35: =SUM(1300/68)*H35 -> 99.973824 | X35: =SUM(S35:W35) -> 3540.4576 | Y35: =SUM(10737.46/68)*H35 -> 825.74225 | AB35: =SUM(Y35:AA35) -> 825.74225 | AC35: 7.12 | AD35: =SUM(AB35*AC35) -> 5879.2849 | AE35: =SUM(X35+AD35) -> 9419.7425 | AF35: =SUM(P35-AE35) -> 2263.5575
C36: 240905000026 | D36: 45547 | E36: 陆总 | F36: 陆梓龙 | G36: xiantian | H36: 6.2 | I36: 4920 | J36: 14483.2 | P36: =SUBTOTAL(9,J36) -> 14483.2 | S36: =SUM(44738/68)*H36 -> 4079.0529 | U36: =SUM(1300/68)*H36 -> 118.52941 | X36: =SUM(S36:W36) -> 4197.5824 | Y36: =SUM(10737.46/68)*H36 -> 979.00371 | AB36: =SUM(Y36:AA36) -> 979.00371 | AC36: 7.12 | AD36: =SUM(AB36*AC36) -> 6970.5064 | AE36: =SUM(X36+AD36) -> 11168.089 | AF36: =SUM(P36-AE36) -> 3315.1113
C37: 240905000027 | D37: 45547 | E37: 陆总 | F37: 陆梓龙 | G37: luk | H37: 0.3485 | I37: 70 | J37: 686.93 | P37: =SUBTOTAL(9,J37) -> 686.93 | S37: =SUM(44738/68)*H37 -> 229.28225 | U37: =SUM(1300/68)*H37 -> 6.6625 | X37: =SUM(S37:W37) -> 235.94475 | Y37: =SUM(10737.46/68)*H37 -> 55.029483 | AB37: =SUM(Y37:AA37) -> 55.029483 | AC37: 7.12 | AD37: =SUM(AB37*AC37) -> 391.80992 | AE37: =SUM(X37+AD37) -> 627.75467 | AF37: =SUM(P37-AE37) -> 59.175335
C38: 240905000028 | D38: 45547 | E38: 黄颖 | F38: ying | G38: Bruce | H38: 2.499 | I38: 970 | J38: 5265 | P38: =SUBTOTAL(9,J38) -> 5265 | S38: =SUM(44738/68)*H38 -> 1644.1215 | U38: =SUM(1300/68)*H38 -> 47.775 | X38: =SUM(S38:W38) -> 1691.8965 | Y38: =SUM(10737.46/68)*H38 -> 394.60165 | AB38: =SUM(Y38:AA38) -> 394.60165 | AC38: 7.12 | AD38: =SUM(AB38*AC38) -> 2809.5638 | AE38: =SUM(X38+AD38) -> 4501.4603 | AF38: =SUM(P38-AE38) -> 763.53972
C39: 240905000029 | D39: 45547 | E39: 黄颖 | F39: ying | G39: zhounengquan | H39: 0.0359 | I39: 12 | K39: 63180 | M39: =SUM(K39/N39) -> 1730.4848 | N39: 36.51 | O39: 7.12 | P39: =SUM(N39*O39) -> 259.9512 | S39: =SUM(44738/68)*H39 -> 23.619032 | U39: =SUM(1300/68)*H39 -> 0.68632353 | X39: =SUM(S39:W39) -> 24.305356 | Y39: =SUM(10737.46/68)*H39 -> 5.6687473 | Z39: 7.06 | AB39: =SUM(Y39:AA39) -> 12.728747 | AC39: 7.12 | AD39: =SUM(AB39*AC39) -> 90.628681 | AE39: =SUM(X39+AD39) -> 114.93404 | AF39: =SUM(P39-AE39) -> 145.01716
C40: 240905000039 | D40: 45547 | E40: 吕沛霖 | F40: 喵喵速运-Layne | G40: Mr.Wang | H40: 1.0166 | I40: 193 | K40: 466616 | M40: =SUM(K40/N40) -> 1700 | N40: 274.48 | O40: 7.27 | P40: =SUM(N40*O40) -> 1995.4696 | S40: =SUM(44738/68)*H40 -> 668.8331 | U40: =SUM(1300/68)*H40 -> 19.435 | X40: =SUM(S40:W40) -> 688.2681 | Y40: =SUM(10737.46/68)*H40 -> 160.52503 | AB40: =SUM(Y40:AA40) -> 160.52503 | AC40: 7.12 | AD40: =SUM(AB40*AC40) -> 1142.9382 | AE40: =SUM(X40+AD40) -> 1831.2063 | AF40: =SUM(P40-AE40) -> 164.26331
...

Sheet JOB090350
A1: 2024年09月份LOS毛利表（海运）
A2: PSL表 | B2: 体积cbm | C2: 96.544
A3: JOB | B3: 集装编号 | C3: 运单编号 | D3: 日期 | E3: 业务 | F3: 发货人 | G3: 收货人 | H3: 计费体积 | I3: 计费重量 | J3: 应 收 | Q3: 总应收 | R3: 起 运 港 成 本 | W3: 代垫运费 | X3: 起运港成本 合计 | Y3: 目的港成本 | AE3: 总支出 | AF3: 利润
J4: 应收RMB | K4: LOS Income(NGN)收到(奈拉) | L4: LOS 收到USD | M4: 美元汇率 dollar currency rate | N4: 应收 到付款USD | O4: 汇率 | P4: 人民币 | R4: 代理商 | S4: 运费+出口报关费 | T4: 提货费 | U4: 装卸费 | V4: 包装费 | Y4: 进口报关费 | Z4: 到门配送费 | AA4: 转运费 | AB4: 目的港支出 | AC4: 汇率 | AD4: 人民币 | AE4: 起运港+目的港
A5: JOB090350 | B5: COLL004142 | C5: 240807000019 | D5: 45539 | E5: Sam.Pao | F5: Sam.Pao | G5: Nick Wang | H5: 55.0796 | I5: 14200 | J5: 26216.12 | K5: 21550555 | M5: =SUM(K5/N5) -> 1560.2607 | N5: 13812.15 | O5: 7.24 | P5: =SUM(N5*O5+J5) -> 126216.09 | Q5: =SUM(P5:P17) -> 196493.64 | R5: 登凯=48459 赛捷=1120 拖车费=1670 杂费=81 过磅费=61 | S5: =SUM(51391/68)*H5 -> 41626.408 | U5: =SUM(1450/68)*H5 -> 1174.4915 | V5: 600 | W5: =SUM(235.5+800) -> 1035.5 | X5: =SUM(S5:W5) -> 44436.399 | Y5: =SUM(10737.46/68)*H5 -> 8697.2794 | Z5: 1858.41 | AB5: =SUM(Y5:AA5) -> 10555.689 | AC5: 7.12 | AD5: =SUM(AB5*AC5) -> 75156.509 | AE5: =SUM(X5+AD5) -> 119592.91 | AF5: =SUM(P5-AE5) -> 6623.178
C6: 240827000016 | D6: 45539 | E6: Bella | F6: Bella Chan | G6: new hope 边鹏飞 | H6: 0.2537 | I6: 138 | K6: 202127.5 | M6: =SUM(K6/N6) -> 1735 | N6: 116.5 | O6: 7.12 | P6: =SUM(N6*O6) -> 829.48 | S6: =SUM(51391/68)*H6 -> 191.73378 | U6: =SUM(1450/68)*H6 -> 5.4097794 | W6: 240 | X6: =SUM(S6:W6) -> 437.14355 | Y6: =SUM(10737.46/68)*H6 -> 40.0602 | AB6: =SUM(Y6:AA6) -> 40.0602 | AC6: 7.12 | AD6: =SUM(AB6*AC6) -> 285.22862 | AE6: =SUM(X6+AD6) -> 722.37218 | AF6: =SUM(P6-AE6) -> 107.10782
C7: 240827000023 | D7: 45539 | E7: Sam.Pao | F7: Sam.Pao | G7: Adesoye | H7: 3.027 | I7: 2480 | K7: 1916044.9 | M7: =SUM(K7/N7) -> 1745 | N7: 1098.02 | O7: 7.12 | P7: =SUM(N7*O7) -> 7817.9024 | S7: =SUM(51391/68)*H7 -> 2287.6552 | U7: =SUM(1450/68)*H7 -> 64.546324 | X7: =SUM(S7:W7) -> 2352.2016 | Y7: =SUM(10737.46/68)*H7 -> 477.97487 | AB7: =SUM(Y7:AA7) -> 477.97487 | AC7: 7.12 | AD7: =SUM(AB7*AC7) -> 3403.1811 | AE7: =SUM(X7+AD7) -> 5755.3827 | AF7: =SUM(P7-AE7) -> 2062.5197
C8: 240828000016 | D8: 45539 | E8: 吕沛霖 | F8: 喵喵速运-Layne | G8: SHAEK | H8: 0.1625 | I8: 169 | J8: 1258.39 | P8: =SUBTOTAL(9,J8) -> 1258.39 | S8: =SUM(51391/68)*H8 -> 122.80938 | U8: =SUM(1450/68)*H8 -> 3.4650735 | X8: =SUM(S8:W8) -> 126.27445 | Y8: =SUM(10737.46/68)*H8 -> 25.659371 | Z8: 93.95 | AB8: =SUM(Y8:AA8) -> 119.60937 | AC8: 7.12 | AD8: =SUM(AB8*AC8) -> 851.61872 | AE8: =SUM(X8+AD8) -> 977.89317 | AF8: =SUM(P8-AE8) -> 280.49683
C9: 240828000064 | D9: 45539 | E9: Bella | F9: Bella Chan | G9: zhong zi xin | H9: 2.368 | I9: 2617 | K9: 2020000 | M9: =SUM(K9/N9) -> 1688.522 | N9: 1196.3125 | O9: 7.23 | P9: =SUM(N9*O9) -> 8649.3394 | S9: =SUM(51391/68)*H9 -> 1789.616 | U9: =SUM(1450/68)*H9 -> 50.494118 | X9: =SUM(S9:W9) -> 1840.1101 | Y9: =SUM(10737.46/68)*H9 -> 373.91625 | Z9: 70.8 | AB9: =SUM(Y9:AA9) -> 444.71625 | AC9: 7.12 | AD9: =SUM(AB9*AC9) -> 3166.3797 | AE9: =SUM(X9+AD9) -> 5006.4898 | AF9: =SUM(P9-AE9) -> 3642.8495
C10: 240830000003 | D10: 45539 | E10: Sam.Pao | F10: Sam.Pao | G10: ERICA | H10: 0.1448 | I10: 20 | J10: 333.6 | P10: =SUBTOTAL(9,J10) -> 333.6 | S10: =SUM(51391/68)*H10 -> 109.4326 | U10: =SUM(1450/68)*H10 -> 3.0876471 | X10: =SUM(S10:W10) -> 112.52025 | Y10: =SUM(10737.46/68)*H10 -> 22.864474 | Z10: 5.9 | AB10: =SUM(Y10:AA10) -> 28.764474 | AC10: 7.12 | AD10: =SUM(AB10*AC10) -> 204.80305 | AE10: =SUM(X10+AD10) -> 317.3233 | AF10: =SUM(P10-AE10) -> 16.276701
C11: 240830000027 | D11: 45539 | E11: 罗伟健 | F11: MailMail速运-演员 | G11: Harvey Wang | H11: 0.866 | I11: 98 | J11: 1871 | P11: =SUBTOTAL(9,J11) -> 1871 | S11: =SUM(51391/68)*H11 -> 654.4795 | U11: =SUM(1450/68)*H11 -> 18.466176 | X11: =SUM(S11:W11) -> 672.94568 | Y11: =SUM(10737.46/68)*H11 -> 136.74471 | AB11: =SUM(Y11:AA11) -> 136.74471 | AC11: 7.12 | AD11: =SUM(AB11*AC11) -> 973.62234 | AE11: =SUM(X11+AD11) -> 1646.568 | AF11: =SUM(P11-AE11) -> 224.43198
C12: 240830000048 | D12: 45539 | E12: 无人 | F12: dejare James | G12: James | H12: 2.146 | I12: 268 | L12: 640.17 | M12: =SUM(K12/N12) -> 0 | N12: 640.17 | O12: 7.3 | P12: =SUM(N12*O12) -> 4673.241 | S12: =SUM(51391/68)*H12 -> 1621.8395 | U12: =SUM(1450/68)*H12 -> 45.760294 | X12: =SUM(S12:W12) -> 1667.5998 | Y12: =SUM(10737.46/68)*H12 -> 338.86161 | AB12: =SUM(Y12:AA12) -> 338.86161 | AC12: 7.12 | AD12: =SUM(AB12*AC12) -> 2412.6946 | AE12: =SUM(X12+AD12) -> 4080.2944 | AF12: =SUM(P12-AE12) -> 592.94658
C13: 240728000003 | D13: 45506 | E13: Sam.Pao | F13: Sam.Pao | G13: Nick Wang | H13: 0.42 | I13: 160 | J13: 1132 | P13: =SUBTOTAL(9,J13) -> 1132 | S13: =SUM(51391/68)*H13 -> 317.415 | U13: =SUM(1450/68)*H13 -> 8.9558824 | X13: =SUM(S13:W13) -> 326.37088 | Y13: =SUM(10737.46/68)*H13 -> 66.319606 | Z13: 31.76 | AB13: =SUM(Y13:AA13) -> 98.079606 | AC13: 7.12 | AD13: =SUM(AB13*AC13) -> 698.32679 | AE13: =SUM(X13+AD13) -> 1024.6977 | AF13: =SUM(P13-AE13) -> 107.30232
C14: 240904000001 | D14: 45539 | E14: Sam.Pao | F14: Sam.Pao | G14: SKY JET | H14: 19.05 | I14: 2484 | J14: 25671.21 | P14: =SUBTOTAL(9,J14) -> 25671.21 | S14: =SUM(51391/68)*H14 -> 14397.038 | U14: =SUM(1450/68)*H14 -> 406.21324 | X14: =SUM(S14:W14) -> 14803.251 | Y14: =SUM(10737.46/68)*H14 -> 3008.0678 | AB14: =SUM(Y14:AA14) -> 3008.0678 | AC14: 7.12 | AD14: =SUM(AB14*AC14) -> 21417.443 | AE14: =SUM(X14+AD14) -> 36220.694 | AF14: =SUM(P14-AE14) -> -10549.484
C15: 240904000027 | D15: 45539 | E15: 黄颖 | F15: ying | G15: zhounengquan | H15: 0.057 | I15: 22 | K15: 55920 | M15: =SUM(K15/N15) -> 1679.2793 | N15: 33.3 | O15: 7.12 | P15: 237.1 | S15: =SUM(51391/68)*H15 -> 43.07775 | U15: =SUM(1450/68)*H15 -> 1.2154412 | X15: =SUM(S15:W15) -> 44.293191 | Y15: =SUM(10737.46/68)*H15 -> 9.0005179 | Z15: 7.02 | AB15: =SUM(Y15:AA15) -> 16.020518 | AC15: 7.12 | AD15: =SUM(AB15*AC15) -> 114.06609 | AE15: =SUM(X15+AD15) -> 158.35928 | AF15: =SUM(P15-AE15) -> 78.740721
C16: 240904000002 | D16: 45539 | E16: Sam.Pao | F16: Sam.Pao | G16: SKY JET | H16: 12.5 | I16: 19 | J16: 16844.63 | P16: =SUBTOTAL(9,J16) -> 16844.63 | S16: =SUM(51391/68)*H16 -> 9446.875 | U16: =SUM(1450/68)*H16 -> 266.54412 | X16: =SUM(S16:W16) -> 9713.4191 | Y16: =SUM(10737.46/68)*H16 -> 1973.7978 | AB16: =SUM(Y16:AA16) -> 1973.7978 | AC16: 7.12 | AD16: =SUM(AB16*AC16) -> 14053.44 | AE16: =SUM(X16+AD16) -> 23766.859 | AF16: =SUM(P16-AE16) -> -6922.2294
C17: 240904000021 | D17: 45539 | E17: 陆总 | F17: 陆梓龙 | G17: luk | H17: 0.469 | I17: 105 | J17: 959.66 | P17: =SUBTOTAL(9,J17) -> 959.66 | S17: =SUM(51391/68)*H17 -> 354.44675 | U17: =SUM(1450/68)*H17 -> 10.000735 | X17: =SUM(S17:W17) -> 364.44749 | Y17: =SUM(10737.46/68)*H17 -> 74.056893 | AB17: =SUM(Y17:AA17) -> 74.056893 | AC17: 7.12 | AD17: =SUM(AB17*AC17) -> 527.28508 | AE17: =SUM(X17+AD17) -> 891.73257 | AF17: =SUM(P17-AE17) -> 67.927435
A18: 合计 | J18: =SUM(J4:J4) -> 0 | N18: =SUM(N4:N4) -> 0 | P18: =SUM(P4:P4) -> 0 | Q18: =SUM(Q4:Q4) -> 0 | X18: =SUM(X4:X4) -> 0 | AD18: =SUM(AD4:AD4) -> 0 | AF18: =SUM(AF4:AF17) -> -3667.9355

Sheet JOB090351
A1: 2024年09月份LOS毛利表（海运）
A2: PSL表 | B2: 体积cbm | C2: 72.4455
A3: JOB | B3: 集装编号 | C3: 运单编号 | D3: 日期 | E3: 业务 | F3: 发货人 | G3: 收货人 | H3: 计费体积 | I3: 计费重量 | J3: 应 收 | Q3: 总应收 | R3: 起 运 港 成 本 | W3: 代垫运费 | X3: 起运港成本 合计 | Y3: 目的港成本 | AE3: 总支出 | AF3: 利润
J4: 应收RMB | K4: LOS Income(NGN)收到(奈拉) | L4: LOS 收到USD | M4: 美元汇率 dollar currency rate | N4: 应收 到付款USD | O4: 汇率 | P4: 人民币 | R4: 代理商 | S4: 运费+出口报关费 | T4: 提货费 | U4: 装卸费 | V4: 包装费 | Y4: 进口报关费 | Z4: 到门配送费 | AA4: 转运费 | AB4: 目的港支出 | AC4: 汇率 | AD4: 人民币 | AE4: 起运港+目的港
A5: JOB090351 | B5: COLL004143 | C5: 240828000043 | D5: 45539 | E5: 吕沛霖 | F5: 喵喵速运-Layne | G5: ABDUL | H5: 6.8939 | I5: 3722 | K5: 3417687 | M5: =SUM(K5/N5) -> 1690 | N5: 2022.3 | O5: 7.3 | P5: =SUM(N5*O5) -> 14762.79 | Q5: =SUM(P5:P15) -> 153607.29 | R5: 登凯=44776 赛捷=1750 拖车费=2270 杂费=1388 过磅费=65 | S5: =SUM(50249/68)*H5 -> 5094.288 | T5: =SUM(116.62/68)*H5 -> 11.823038 | U5: =SUM(1750/68)*H5 -> 177.41654 | X5: =SUM(S5:W5) -> 5283.5275 | Y5: =SUM(10737.46/68)*H5 -> 1088.5732 | Z5: 91.45 | AA5: =SUM(70.8/68)*H5 -> 7.1777665 | AB5: =SUM(Y5:AA5) -> 1187.2009 | AC5: 7.12 | AD5: =SUM(AB5*AC5) -> 8452.8707 | AE5: =SUM(X5+AD5) -> 13736.398 | AF5: =SUM(P5-AE5) -> 1026.3918
C6: 240828000069 | D6: 45539 | E6: 陆总 | F6: 陆梓龙 | G6: xiantian | H6: 3.615 | I6: 1442 | J6: 9176.76 | P6: =SUBTOTAL(9,J6) -> 9176.76 | S6: =SUM(50249/68)*H6 -> 2671.3255 | T6: =SUM(116.62/68)*H6 -> 6.199725 | U6: =SUM(1750/68)*H6 -> 93.033088 | X6: =SUM(S6:W6) -> 2770.5583 | Y6: =SUM(10737.46/68)*H6 -> 570.82232 | Z6: 100.29 | AA6: =SUM(70.8/68)*H6 -> 3.7638529 | AB6: =SUM(Y6:AA6) -> 674.87617 | AC6: 7.12 | AD6: =SUM(AB6*AC6) -> 4805.1184 | AE6: =SUM(X6+AD6) -> 7575.6767 | AF6: =SUM(P6-AE6) -> 1601.0833
C7: 240819000017 | D7: 45516 | E7: 吕沛霖 | F7: 喵喵速运-Layne | G7: WEI PING | H7: 4.904 | I7: 848 | J7: 10475 | P7: =SUBTOTAL(9,J7) -> 10475 | S7: =SUM(50249/68)*H7 -> 3623.8396 | T7: =SUM(116.62/68)*H7 -> 8.41036 | U7: =SUM(1750/68)*H7 -> 126.20588 | X7: =SUM(S7:W7) -> 3758.4559 | Y7: =SUM(10737.46/68)*H7 -> 774.36035 | AA7: =SUM(70.8/68)*H7 -> 5.1059294 | AB7: =SUM(Y7:AA7) -> 779.46628 | AC7: 7.12 | AD7: =SUM(AB7*AC7) -> 5549.7999 | AE7: =SUM(X7+AD7) -> 9308.2558 | AF7: =SUM(P7-AE7) -> 1166.7442
C8: 240902000041 | D8: 45539 | E8: 朱小飞 | F8: Isabel Zhu | G8: Mr Qiu | H8: 0.5458 | I8: 230 | K8: 436950 | M8: =SUM(K8/N8) -> 1779.04 | N8: 245.60999 | O8: 7.08 | P8: =SUM(N8*O8) -> 1738.9187 | S8: =SUM(50249/68)*H8 -> 403.32212 | T8: =SUM(116.62/68)*H8 -> 0.936047 | U8: =SUM(1750/68)*H8 -> 14.046324 | X8: =SUM(S8:W8) -> 418.30449 | Y8: =SUM(10737.46/68)*H8 -> 86.183907 | AA8: =SUM(70.8/68)*H8 -> 0.56827412 | AB8: =SUM(Y8:AA8) -> 86.752181 | AC8: 7.12 | AD8: =SUM(AB8*AC8) -> 617.67553 | AE8: =SUM(X8+AD8) -> 1035.98 | AF8: =SUM(P8-AE8) -> 702.93871
C9: 240902000057 | D9: 45539 | E9: 陆总 | F9: 陆梓龙 | G9: WANG | H9: 0.2102 | I9: 74 | J9: 573.06 | P9: =SUBTOTAL(9,J9) -> 573.06 | S9: =SUM(50249/68)*H9 -> 155.32853 | T9: =SUM(116.62/68)*H9 -> 0.360493 | U9: =SUM(1750/68)*H9 -> 5.4095588 | X9: =SUM(S9:W9) -> 161.09858 | Y9: =SUM(10737.46/68)*H9 -> 33.191384 | AA9: =SUM(70.8/68)*H9 -> 0.21885529 | AB9: =SUM(Y9:AA9) -> 33.410239 | AC9: 7.12 | AD9: =SUM(AB9*AC9) -> 237.8809 | AE9: =SUM(X9+AD9) -> 398.97948 | AF9: =SUM(P9-AE9) -> 174.08052
C10: 240903000009 | D10: 45539 | E10: Sam.Pao | F10: Sam.Pao | G10: MaiKaiNian | H10: 0.2574 | I10: 150 | J10: 630.11 | P10: =SUBTOTAL(9,J10) -> 630.11 | S10: =SUM(50249/68)*H10 -> 190.20724 | T10: =SUM(116.62/68)*H10 -> 0.441441 | U10: =SUM(1750/68)*H10 -> 6.6242647 | X10: =SUM(S10:W10) -> 197.27295 | Y10: =SUM(10737.46/68)*H10 -> 40.644444 | AA10: =SUM(70.8/68)*H10 -> 0.26799882 | AB10: =SUM(Y10:AA10) -> 40.912443 | AC10: 7.12 | AD10: =SUM(AB10*AC10) -> 291.29659 | AE10: =SUM(X10+AD10) -> 488.56954 | AF10: =SUM(P10-AE10) -> 141.54046
C11: 240903000015 | D11: 45539 | E11: 朱小飞 | F11: Isabel Zhu | G11: Halifa Success | H11: 0.42 | I11: 62 | J11: 959.18 | P11: =SUBTOTAL(9,J11) -> 959.18 | S11: =SUM(50249/68)*H11 -> 310.36147 | T11: =SUM(116.62/68)*H11 -> 0.7203 | U11: =SUM(1750/68)*H11 -> 10.808824 | X11: =SUM(S11:W11) -> 321.89059 | Y11: =SUM(10737.46/68)*H11 -> 66.319606 | AA11: =SUM(70.8/68)*H11 -> 0.43729412 | AB11: =SUM(Y11:AA11) -> 66.7569 | AC11: 7.12 | AD11: =SUM(AB11*AC11) -> 475.30913 | AE11: =SUM(X11+AD11) -> 797.19972 | AF11: =SUM(P11-AE11) -> 161.98028
C12: 240902000056 | D12: 45547 | E12: 吕沛霖 | F12: 喵喵速运-Layne | G12: Hu Hai Liang | H12: 0.512 | I12: 51 | K12: 289240 | M12: =SUM(K12/N12) -> 1752.9697 | N12: 165 | O12: 7.23 | P12: =SUM(N12*O12) -> 1192.95 | S12: =SUM(50249/68)*H12 -> 378.34541 | T12: =SUM(116.62/68)*H12 -> 0.87808 | U12: =SUM(1750/68)*H12 -> 13.176471 | X12: =SUM(S12:W12) -> 392.39996 | Y12: =SUM(10737.46/68)*H12 -> 80.846758 | AA12: =SUM(70.8/68)*H12 -> 0.53308235 | AB12: =SUM(Y12:AA12) -> 81.37984 | AC12: 7.12 | AD12: =SUM(AB12*AC12) -> 579.42446 | AE12: =SUM(X12+AD12) -> 971.82442 | AF12: =SUM(P12-AE12) -> 221.12558
C13: 240813000017 | D13: 45539 | E13: Sam.Pao | F13: Sam.Pao | G13: AiGeLi | H13: 21.51 | I13: 13906 | J13: 59293 | P13: =SUBTOTAL(9,J13) -> 59293 | S13: =SUM(50249/68)*H13 -> 15894.941 | T13: =SUM(116.62/68)*H13 -> 36.88965 | U13: =SUM(1750/68)*H13 -> 553.56618 | V13: 500 | X13: =SUM(S13:W13) -> 16985.397 | Y13: =SUM(10737.46/68)*H13 -> 3396.5112 | Z13: 1415.93 | AA13: =SUM(70.8/68)*H13 -> 22.395706 | AB13: =SUM(Y13:AA13) -> 4834.8369 | AC13: 7.12 | AD13: =SUM(AB13*AC13) -> 34424.039 | AE13: =SUM(X13+AD13) -> 51409.436 | AF13: =SUM(P13-AE13) -> 7883.5641
C14: 240828000061 | D14: 45539 | E14: Sam.Pao | F14: Sam.Pao | G14: JunYue hotel | H14: 2.6171 | I14: 719.5 | J14: 5838 | P14: =SUBTOTAL(9,J14) -> 5838 | S14: =SUM(50249/68)*H14 -> 1933.9214 | T14: =SUM(116.62/68)*H14 -> 4.4883265 | U14: =SUM(1750/68)*H14 -> 67.351838 | X14: =SUM(S14:W14) -> 2005.7616 | Y14: =SUM(10737.46/68)*H14 -> 413.2501 | AA14: =SUM(70.8/68)*H14 -> 2.7248629 | AB14: =SUM(Y14:AA14) -> 415.97496 | AC14: 7.12 | AD14: =SUM(AB14*AC14) -> 2961.7417 | AE14: =SUM(X14+AD14) -> 4967.5033 | AF14: =SUM(P14-AE14) -> 870.49668
C15: 240904000002 | D15: 45539 | E15: Sam.Pao | F15: Sam.Pao | G15: SKY JET | H15: 30.96 | I15: 3682.5 | J15: 48967.52 | P15: =SUBTOTAL(9,J15) -> 48967.52 | S15: =SUM(50249/68)*H15 -> 22878.074 | T15: =SUM(116.62/68)*H15 -> 53.0964 | U15: =SUM(1750/68)*H15 -> 796.76471 | X15: =SUM(S15:W15) -> 23727.935 | Y15: =SUM(10737.46/68)*H15 -> 4888.7024 | AA15: =SUM(70.8/68)*H15 -> 32.234824 | AB15: =SUM(Y15:AA15) -> 4920.9372 | AC15: 7.12 | AD15: =SUM(AB15*AC15) -> 35037.073 | AE15: =SUM(X15+AD15) -> 58765.008 | AF15: =SUM(P15-AE15) -> -9797.4881
A16: 合计 | J16: =SUM(J4:J4) -> 0 | N16: =SUM(N4:N4) -> 0 | P16: =SUM(P4:P4) -> 0 | Q16: =SUM(Q4:Q4) -> 0 | X16: =SUM(X4:X4) -> 0 | AD16: =SUM(AD4:AD4) -> 0 | AF16: =SUM(AF4:AF15) -> 4152.4575

Sheet JOB090364
A1: 2024年09月份LOS毛利表（海运）
A2: PSL表 | B2: 体积cbm | C2: 68.2656
A3: JOB | B3: 集装编号 | C3: 运单编号 | D3: 日期 | E3: 业务 | F3: 发货人 | G3: 收货人 | H3: 计费体积 | I3: 计费重量 | J3: 应 收 | Q3: 总应收 | R3: 起 运 港 成 本 | W3: 代垫运费 | X3: 起运港成本 合计 | Y3: 目的港成本 | AE3: 总支出 | AF3: 利润
J4: 应收RMB | K4: LOS Income(NGN)收到(奈拉) | L4: LOS 收到USD | M4: 美元汇率 dollar currency rate | N4: 应收 到付款USD | O4: 汇率 | P4: 人民币 | R4: 代理商 | S4: 运费+出口报关费 | T4: 提货费 | U4: 装卸费 | V4: 包装费 | Y4: 进口报关费 | Z4: 到门配送费 | AA4: 转运费 | AB4: 目的港支出 | AC4: 汇率 | AD4: 人民币 | AE4: 起运港+目的港
A5: JOB090364 | B5: COLL004256 | C5: 240726000055 | D5: 45547 | E5: Sam.Pao | F5: Sam.Pao | G5: ShanShan | H5: 5.09 | I5: 677 | J5: 13067 | P5: =SUBTOTAL(9,J5) -> 13067 | Q5: =SUM(P5:P29) -> 158115.17 | R5: 登凯=41647 赛捷=1280 拖车费=1670 杂费=73 过磅费=68 | S5: =SUM(44738/68)*H5 -> 3348.7709 | U5: =SUM(1300/68)*H5 -> 97.308824 | X5: =SUM(S5:W5) -> 3446.0797 | Y5: =SUM(10737.46/68)*H5 -> 803.73046 | Z5: 47.2 | AB5: =SUM(Y5:AA5) -> 850.93046 | AC5: 7.12 | AD5: =SUM(AB5*AC5) -> 6058.6249 | AE5: =SUM(X5+AD5) -> 9504.7046 | AF5: =SUM(P5-AE5) -> 3562.2954
C6: 240813000017 | D6: 45547 | E6: Sam.Pao | F6: Sam.Pao | G6: AiGeLi | H6: 2.1368 | I6: 256 | J6: 5889 | P6: =SUBTOTAL(9,J6) -> 5889 | S6: =SUM(44738/68)*H6 -> 1405.8259 | U6: =SUM(1300/68)*H6 -> 40.850588 | X6: =SUM(S6:W6) -> 1446.6764 | Y6: =SUM(10737.46/68)*H6 -> 337.40889 | AB6: =SUM(Y6:AA6) -> 337.40889 | AC6: 7.12 | AD6: =SUM(AB6*AC6) -> 2402.3513 | AE6: =SUM(X6+AD6) -> 3849.0277 | AF6: =SUM(P6-AE6) -> 2039.9723
C7: 240902000015 | D7: 45547 | E7: 黄颖 | F7: ying | G7: Ms PEJU | H7: 3.028 | I7: 338 | J7: 7000 | P7: =SUBTOTAL(9,J7) -> 7000 | S7: =SUM(44738/68)*H7 -> 1992.1568 | U7: =SUM(1300/68)*H7 -> 57.888235 | X7: =SUM(S7:W7) -> 2050.0451 | Y7: =SUM(10737.46/68)*H7 -> 478.13278 | AB7: =SUM(Y7:AA7) -> 478.13278 | AC7: 7.12 | AD7: =SUM(AB7*AC7) -> 3404.3054 | AE7: =SUM(X7+AD7) -> 5454.3504 | AF7: =SUM(P7-AE7) -> 1545.6496
C8: 240902000056 | D8: 45547 | E8: 吕沛霖 | F8: 喵喵速运-Layne | G8: Hu Hai Liang | H8: 3.078 | I8: 521 | K8: 1738835 | M8: =SUM(K8/N8) -> 1754.4319 | N8: 991.11 | O8: 7.23 | P8: =SUM(N8*O8) -> 7165.7253 | S8: =SUM(44738/68)*H8 -> 2025.0524 | U8: =SUM(1300/68)*H8 -> 58.844118 | V8: 580 | X8: =SUM(S8:W8) -> 2663.8965 | Y8: =SUM(10737.46/68)*H8 -> 486.02797 | AB8: =SUM(Y8:AA8) -> 486.02797 | AC8: 7.12 | AD8: =SUM(AB8*AC8) -> 3460.5191 | AE8: =SUM(X8+AD8) -> 6124.4157 | AF8: =SUM(P8-AE8) -> 1041.3096
C9: 240904000027 | D9: 45547 | E9: 黄颖 | F9: ying | G9: zhounengquan | H9: 0.0074 | I9: 6 | K9: 7260 | M9: =SUM(K9/N9) -> 2261.6822 | N9: 3.21 | O9: 7.12 | P9: 22.9 | S9: =SUM(44738/68)*H9 -> 4.8685471 | U9: =SUM(1300/68)*H9 -> 0.14147059 | X9: =SUM(S9:W9) -> 5.0100176 | Y9: =SUM(10737.46/68)*H9 -> 1.1684883 | AB9: =SUM(Y9:AA9) -> 1.1684883 | AC9: 7.12 | AD9: =SUM(AB9*AC9) -> 8.3196367 | AE9: =SUM(X9+AD9) -> 13.329654 | AF9: =SUM(P9-AE9) -> 9.5703457
C10: 240904000032 | D10: 45547 | E10: 黄颖 | F10: ying | G10: Bruce | H10: 2.736 | I10: 1216 | J10: 5623 | P10: =SUBTOTAL(9,J10) -> 5623 | S10: =SUM(44738/68)*H10 -> 1800.0466 | U10: =SUM(1300/68)*H10 -> 52.305882 | X10: =SUM(S10:W10) -> 1852.3525 | Y10: =SUM(10737.46/68)*H10 -> 432.02486 | AB10: =SUM(Y10:AA10) -> 432.02486 | AC10: 7.12 | AD10: =SUM(AB10*AC10) -> 3076.017 | AE10: =SUM(X10+AD10) -> 4928.3695 | AF10: =SUM(P10-AE10) -> 694.63052
C11: 240904000040 | D11: 45547 | E11: 朱小飞 | F11: Isabel Zhu | G11: Victor Nnamdi | H11: 1.449 | I11: 227 | K11: 761250 | M11: =SUM(K11/N11) -> 1751.1952 | N11: 434.70312 | O11: 7.08 | P11: =SUM(N11*O11) -> 3077.6981 | S11: =SUM(44738/68)*H11 -> 953.31415 | U11: =SUM(1300/68)*H11 -> 27.701471 | X11: =SUM(S11:W11) -> 981.01562 | Y11: =SUM(10737.46/68)*H11 -> 228.80264 | AB11: =SUM(Y11:AA11) -> 228.80264 | AC11: 7.12 | AD11: =SUM(AB11*AC11) -> 1629.0748 | AE11: =SUM(X11+AD11) -> 2610.0904 | AF11: =SUM(P11-AE11) -> 467.60767
C12: 240828000061 | D12: 45539 | E12: Sam.Pao | F12: Sam.Pao | G12: JunYue hotel | H12: 5.2294 | I12: 555 | J12: 11683.3 | P12: =SUBTOTAL(9,J12) -> 11683.3 | S12: =SUM(44738/68)*H12 -> 3440.4838 | U12: =SUM(1300/68)*H12 -> 99.973824 | X12: =SUM(S12:W12) -> 3540.4576 | Y12: =SUM(10737.46/68)*H12 -> 825.74225 | AB12: =SUM(Y12:AA12) -> 825.74225 | AC12: 7.12 | AD12: =SUM(AB12*AC12) -> 5879.2849 | AE12: =SUM(X12+AD12) -> 9419.7425 | AF12: =SUM(P12-AE12) -> 2263.5575
C13: 240905000026 | D13: 45547 | E13: 陆总 | F13: 陆梓龙 | G13: xiantian | H13: 6.2 | I13: 4920 | J13: 14483.2 | P13: =SUBTOTAL(9,J13) -> 14483.2 | S13: =SUM(44738/68)*H13 -> 4079.0529 | U13: =SUM(1300/68)*H13 -> 118.52941 | X13: =SUM(S13:W13) -> 4197.5824 | Y13: =SUM(10737.46/68)*H13 -> 979.00371 | AB13: =SUM(Y13:AA13) -> 979.00371 | AC13: 7.12 | AD13: =SUM(AB13*AC13) -> 6970.5064 | AE13: =SUM(X13+AD13) -> 11168.089 | AF13: =SUM(P13-AE13) -> 3315.1113
C14: 240905000027 | D14: 45547 | E14: 陆总 | F14: 陆梓龙 | G14: luk | H14: 0.3485 | I14: 70 | J14: 686.93 | P14: =SUBTOTAL(9,J14) -> 686.93 | S14: =SUM(44738/68)*H14 -> 229.28225 | U14: =SUM(1300/68)*H14 -> 6.6625 | X14: =SUM(S14:W14) -> 235.94475 | Y14: =SUM(10737.46/68)*H14 -> 55.029483 | AB14: =SUM(Y14:AA14) -> 55.029483 | AC14: 7.12 | AD14: =SUM(AB14*AC14) -> 391.80992 | AE14: =SUM(X14+AD14) -> 627.75467 | AF14: =SUM(P14-AE14) -> 59.175335
C15: 240905000028 | D15: 45547 | E15: 黄颖 | F15: ying | G15: Bruce | H15: 2.499 | I15: 970 | J15: 5265 | P15: =SUBTOTAL(9,J15) -> 5265 | S15: =SUM(44738/68)*H15 -> 1644.1215 | U15: =SUM(1300/68)*H15 -> 47.775 | X15: =SUM(S15:W15) -> 1691.8965 | Y15: =SUM(10737.46/68)*H15 -> 394.60165 | AB15: =SUM(Y15:AA15) -> 394.60165 | AC15: 7.12 | AD15: =SUM(AB15*AC15) -> 2809.5638 | AE15: =SUM(X15+AD15) -> 4501.4603 | AF15: =SUM(P15-AE15) -> 763.53972
C16: 240905000029 | D16: 45547 | E16: 黄颖 | F16: ying | G16: zhounengquan | H16: 0.0359 | I16: 12 | K16: 63180 | M16: =SUM(K16/N16) -> 1730.4848 | N16: 36.51 | O16: 7.12 | P16: =SUM(N16*O16) -> 259.9512 | S16: =SUM(44738/68)*H16 -> 23.619032 | U16: =SUM(1300/68)*H16 -> 0.68632353 | X16: =SUM(S16:W16) -> 24.305356 | Y16: =SUM(10737.46/68)*H16 -> 5.6687473 | Z16: 7.06 | AB16: =SUM(Y16:AA16) -> 12.728747 | AC16: 7.12 | AD16: =SUM(AB16*AC16) -> 90.628681 | AE16: =SUM(X16+AD16) -> 114.93404 | AF16: =SUM(P16-AE16) -> 145.01716
C17: 240905000039 | D17: 45547 | E17: 吕沛霖 | F17: 喵喵速运-Layne | G17: Mr.Wang | H17: 1.0166 | I17: 193 | K17: 466616 | M17: =SUM(K17/N17) -> 1700 | N17: 274.48 | O17: 7.27 | P17: =SUM(N17*O17) -> 1995.4696 | S17: =SUM(44738/68)*H17 -> 668.8331 | U17: =SUM(1300/68)*H17 -> 19.435 | X17: =SUM(S17:W17) -> 688.2681 | Y17: =SUM(10737.46/68)*H17 -> 160.52503 | AB17: =SUM(Y17:AA17) -> 160.52503 | AC17: 7.12 | AD17: =SUM(AB17*AC17) -> 1142.9382 | AE17: =SUM(X17+AD17) -> 1831.2063 | AF17: =SUM(P17-AE17) -> 164.26331
C18: 240816000024 | D18: 45554 | E18: 黄颖 | F18: ying | G18: Sunday Adelena | H18: 22.5 | I18: 11357 | J18: 51447.45 | P18: =SUBTOTAL(9,J18) -> 51447.45 | S18: =SUM(44738/68)*H18 -> 14803.015 | U18: =SUM(1300/68)*H18 -> 430.14706 | X18: =SUM(S18:W18) -> 15233.162 | Y18: =SUM(10737.46/68)*H18 -> 3552.836 | AB18: =SUM(Y18:AA18) -> 3552.836 | AC18: 7.12 | AD18: =SUM(AB18*AC18) -> 25296.193 | AE18: =SUM(X18+AD18) -> 40529.354 | AF18: =SUM(P18-AE18) -> 10918.096
C19: 240906000030 | D19: 45547 | E19: 无人 | F19: dejare James | G19: James | H19: 1.934 | I19: 395 | L19: 580.5 | M19: =SUM(K19/N19) -> 0 | N19: 580.5 | O19: 7.08 | P19: =SUM(N19*O19) -> 4109.94 | S19: =SUM(44738/68)*H19 -> 1272.4014 | U19: =SUM(1300/68)*H19 -> 36.973529 | X19: =SUM(S19:W19) -> 1309.3749 | Y19: =SUM(10737.46/68)*H19 -> 305.38599 | AB19: =SUM(Y19:AA19) -> 305.38599 | AC19: 7.12 | AD19: =SUM(AB19*AC19) -> 2174.3483 | AE19: =SUM(X19+AD19) -> 3483.7232 | AF19: =SUM(P19-AE19) -> 626.21684
C20: 240906000035 | D20: 45547 | E20: 黄颖 | F20: ying | G20: Sanusi samad | H20: 2.343 | I20: 480 | J20: 5181.75 | P20: =SUBTOTAL(9,J20) -> 5181.75 | S20: =SUM(44738/68)*H20 -> 1541.4873 | U20: =SUM(1300/68)*H20 -> 44.792647 | X20: =SUM(S20:W20) -> 1586.2799 | Y20: =SUM(10737.46/68)*H20 -> 369.96866 | AB20: =SUM(Y20:AA20) -> 369.96866 | AC20: 7.12 | AD20: =SUM(AB20*AC20) -> 2634.1768 | AE20: =SUM(X20+AD20) -> 4220.4568 | AF20: =SUM(P20-AE20) -> 961.29324
C21: 240906000040 | D21: 45547 | E21: 陆总 | F21: 陆梓龙 | G21: jizong | H21: 0.714 | I21: 240 | J21: 1563.66 | P21: =SUBTOTAL(9,J21) -> 1563.66 | S21: =SUM(44738/68)*H21 -> 469.749 | U21: =SUM(1300/68)*H21 -> 13.65 | X21: =SUM(S21:W21) -> 483.399 | Y21: =SUM(10737.46/68)*H21 -> 112.74333 | AB21: =SUM(Y21:AA21) -> 112.74333 | AC21: 7.12 | AD21: =SUM(AB21*AC21) -> 802.73251 | AE21: =SUM(X21+AD21) -> 1286.1315 | AF21: =SUM(P21-AE21) -> 277.52849
C22: 240908000020 | D22: 45547 | E22: Sam.Pao | F22: Sam.Pao | G22: MaiKaiNian | H22: 0.164 | I22: 156 | J22: 569.4 | P22: =SUBTOTAL(9,J22) -> 569.4 | S22: =SUM(44738/68)*H22 -> 107.89753 | U22: =SUM(1300/68)*H22 -> 3.1352941 | X22: =SUM(S22:W22) -> 111.03282 | Y22: =SUM(10737.46/68)*H22 -> 25.896227 | AB22: =SUM(Y22:AA22) -> 25.896227 | AC22: 7.12 | AD22: =SUM(AB22*AC22) -> 184.38114 | AE22: =SUM(X22+AD22) -> 295.41396 | AF22: =SUM(P22-AE22) -> 273.98604
C23: 240909000018 | D23: 45547 | E23: 罗伟健 | F23: MailMail速运-演员 | G23: Mr.Joseph Ezekiel | H23: 0.42 | I23: 106 | J23: 500 | K23: 214855 | M23: =SUM(K23/N23) -> 1802.6261 | N23: 119.19 | O23: 7.08 | P23: =SUM(N23*O23)+J23 -> 1343.8652 | S23: =SUM(44738/68)*H23 -> 276.32294 | U23: =SUM(1300/68)*H23 -> 8.0294118 | X23: =SUM(S23:W23) -> 284.35235 | Y23: =SUM(10737.46/68)*H23 -> 66.319606 | AB23: =SUM(Y23:AA23) -> 66.319606 | AC23: 7.12 | AD23: =SUM(AB23*AC23) -> 472.19559 | AE23: =SUM(X23+AD23) -> 756.54795 | AF23: =SUM(P23-AE23) -> 587.31725
C24: 240909000038 | D24: 45547 | E24: 朱小飞 | F24: Isabel Zhu | G24: Lin Bao Zhen | H24: 0.577 | I24: 154 | K24: 305348.4 | M24: =SUM(K24/N24) -> 1762.7907 | N24: 173.21875 | O24: 7.08 | P24: =SUM(N24*O24) -> 1226.3888 | S24: =SUM(44738/68)*H24 -> 379.61509 | U24: =SUM(1300/68)*H24 -> 11.030882 | X24: =SUM(S24:W24) -> 390.64597 | Y24: =SUM(10737.46/68)*H24 -> 91.110506 | AB24: =SUM(Y24:AA24) -> 91.110506 | AC24: 7.12 | AD24: =SUM(AB24*AC24) -> 648.7068 | AE24: =SUM(X24+AD24) -> 1039.3528 | AF24: =SUM(P24-AE24) -> 187.03598
C25: 240909000047 | D25: 45547 | E25: 黄颖 | F25: ying | G25: Bruce | H25: 2.709 | I25: 1034 | J25: 5562 | P25: =SUM(J25) -> 5562 | S25: =SUM(44738/68)*H25 -> 1782.283 | U25: =SUM(1300/68)*H25 -> 51.789706 | X25: =SUM(S25:W25) -> 1834.0727 | Y25: =SUM(10737.46/68)*H25 -> 427.76146 | AB25: =SUM(Y25:AA25) -> 427.76146 | AC25: 7.12 | AD25: =SUM(AB25*AC25) -> 3045.6616 | AE25: =SUM(X25+AD25) -> 4879.7343 | AF25: =SUM(P25-AE25) -> 682.26574
C26: 240728000003 | D26: 45506 | E26: Sam.Pao | F26: Sam.Pao | G26: Nick Wang | H26: 0.145 | I26: 52 | J26: 396 | P26: =SUBTOTAL(9,J26) -> 396 | S26: =SUM(44738/68)*H26 -> 95.397206 | U26: =SUM(1300/68)*H26 -> 2.7720588 | X26: =SUM(S26:W26) -> 98.169265 | Y26: =SUM(10737.46/68)*H26 -> 22.896054 | AB26: =SUM(Y26:AA26) -> 22.896054 | AC26: 7.12 | AD26: =SUM(AB26*AC26) -> 163.01991 | AE26: =SUM(X26+AD26) -> 261.18917 | AF26: =SUM(P26-AE26) -> 134.81083
C27: 240910000031 | D27: 45547 | E27: 罗伟健 | F27: MailMail速运-演员 | G27: Mr.Joseph Ezekiel | H27: 2.926 | I27: 2628 | K27: 2040383 | M27: =SUM(K27/N27) -> 1763.8928 | N27: 1156.75 | O27: 7.08 | P27: =SUM(N27*O27) -> 8189.79 | S27: =SUM(44738/68)*H27 -> 1925.0498 | U27: =SUM(1300/68)*H27 -> 55.938235 | X27: =SUM(S27:W27) -> 1980.9881 | Y27: =SUM(10737.46/68)*H27 -> 462.02659 | AB27: =SUM(Y27:AA27) -> 462.02659 | AC27: 7.12 | AD27: =SUM(AB27*AC27) -> 3289.6293 | AE27: =SUM(X27+AD27) -> 5270.6174 | AF27: =SUM(P27-AE27) -> 2919.1726
C28: 240911000011 | D28: 45547 | E28: 黄颖 | F28: ying | G28: Bruce | H28: 1.019 | I28: 374 | J28: 2095 | P28: =SUBTOTAL(9,J28) -> 2095 | S28: =SUM(44738/68)*H28 -> 670.41209 | U28: =SUM(1300/68)*H28 -> 19.480882 | X28: =SUM(S28:W28) -> 689.89297 | Y28: =SUM(10737.46/68)*H28 -> 160.904 | AB28: =SUM(Y28:AA28) -> 160.904 | AC28: 7.12 | AD28: =SUM(AB28*AC28) -> 1145.6365 | AE28: =SUM(X28+AD28) -> 1835.5294 | AF28: =SUM(P28-AE28) -> 259.47058
C29: 240911000023 | D29: 45547 | E29: 陆总 | F29: 陆梓龙 | G29: luk | H29: 0.0849 | I29: 40 | J29: 210.75 | P29: =SUBTOTAL(9,J29) -> 210.75 | S29: =SUM(44738/68)*H29 -> 55.856709 | U29: =SUM(1300/68)*H29 -> 1.6230882 | X29: =SUM(S29:W29) -> 57.479797 | Y29: =SUM(10737.46/68)*H29 -> 13.406035 | AB29: =SUM(Y29:AA29) -> 13.406035 | AC29: 7.12 | AD29: =SUM(AB29*AC29) -> 95.450966 | AE29: =SUM(X29+AD29) -> 152.93076 | AF29: =SUM(P29-AE29) -> 57.819236
A30: 合计 | J30: =SUM(J4:J4) -> 0 | N30: =SUM(N4:N4) -> 0 | P30: =SUM(P4:P4) -> 0 | Q30: =SUM(Q4:Q4) -> 0 | X30: =SUM(X4:X4) -> 0 | AD30: =SUM(AD4:AD4) -> 0 | AF30: =SUM(AF4:AF29) -> 33956.712

Sheet JOB090366
A1: 2024年09月份LOS毛利表（海运）
A2: PSL表 | B2: 体积cbm | C2: 11.0092
A3: JOB | B3: 集装编号 | C3: 运单编号 | D3: 日期 | E3: 业务 | F3: 发货人 | G3: 收货人 | H3: 计费体积 | I3: 计费重量 | J3: 应 收 | Q3: 总应收 | R3: 起 运 港 成 本 | W3: 代垫运费 | X3: 起运港成本 合计 | Y3: 目的港成本 | AE3: 总支出 | AF3: 利润
J4: 应收RMB | K4: LOS Income(NGN)收到(奈拉) | L4: LOS 收到USD | M4: 美元汇率 dollar currency rate | N4: 应收 到付款USD | O4: 汇率 | P4: 人民币 | R4: 代理商 | S4: 运费+出口报关费 | T4: 提货费 | U4: 装卸费 | V4: 包装费 | Y4: 进口报关费 | Z4: 到门配送费 | AA4: 转运费 | AB4: 目的港支出 | AC4: 汇率 | AD4: 人民币 | AE4: 起运港+目的港
A5: JOB090366 | B5: COLL004158 | C5: 240812000038 | D5: 45518 | E5: 吕沛霖 | F5: 喵喵速运-Layne | G5: Candice Ding | H5: 3.8495 | I5: 2234 | K5: 2249445 | M5: =SUM(K5/N5) -> 1750.2855 | N5: 1285.1875 | O5: 7.1 | P5: =SUM(N5*O5) -> 9124.8312 | Q5: =SUM(P5:P9) -> 23751.728 | R5: 赛捷 | S5: =SUM(20857/11.0091)*H5 -> 7292.9687 | T5: =SUM(351/11.0091)*H5 -> 122.73251 | X5: =SUM(S5:W5) -> 7415.7012 | Z5: 53.1 | AA5: =SUM(82.6/11.0091)*H5 -> 28.882352 | AB5: =SUM(Y5:AA5) -> 81.982352 | AC5: 7.12 | AD5: =SUM(AB5*AC5) -> 583.71435 | AE5: =SUM(X5+AD5) -> 7999.4155 | AF5: =SUM(P5-AE5) -> 1125.4157
C6: 240812000053 | D6: 45518 | E6: Sam.Pao | F6: Sam.Pao | G6: Yusky | H6: 1.2271 | I6: 166 | J6: 2491.03 | P6: =SUBTOTAL(9,J6) -> 2491.03 | S6: =SUM(20857/11.0091)*H6 -> 2324.7699 | T6: =SUM(351/11.0091)*H6 -> 39.12328 | X6: =SUM(S6:W6) -> 2363.8932 | AA6: =SUM(82.6/11.0091)*H6 -> 9.2067889 | AB6: =SUM(Y6:AA6) -> 9.2067889 | AC6: 7.12 | AD6: =SUM(AB6*AC6) -> 65.552337 | AE6: =SUM(X6+AD6) -> 2429.4456 | AF6: =SUM(P6-AE6) -> 61.584447
C7: 240812000057 | D7: 45518 | E7: Bella | F7: Bella Chan | G7: zhong zi xin | H7: 2.0765 | I7: 1506 | K7: 1325000 | M7: =SUM(K7/N7) -> 1924.5854 | N7: 688.45996 | O7: 7.12 | P7: =SUM(N7*O7) -> 4901.8349 | S7: =SUM(20857/11.0091)*H7 -> 3933.9783 | T7: =SUM(351/11.0091)*H7 -> 66.204458 | X7: =SUM(S7:W7) -> 4000.1828 | AA7: =SUM(82.6/11.0091)*H7 -> 15.579739 | AB7: =SUM(Y7:AA7) -> 15.579739 | AC7: 7.12 | AD7: =SUM(AB7*AC7) -> 110.92774 | AE7: =SUM(X7+AD7) -> 4111.1105 | AF7: =SUM(P7-AE7) -> 790.72442
C8: 240813000031 | D8: 45518 | E8: Sam.Pao | F8: Sam.Pao | G8: Yusky | H8: 2.3157 | I8: 122 | M8: =SUM(K8/N8) -> 0 | N8: 648.4 | O8: 7.08 | P8: =SUM(N8*O8) -> 4590.672 | S8: =SUM(20857/11.0091)*H8 -> 4387.1484 | T8: =SUM(351/11.0091)*H8 -> 73.830804 | X8: =SUM(S8:W8) -> 4460.9792 | AA8: =SUM(82.6/11.0091)*H8 -> 17.374428 | AB8: =SUM(Y8:AA8) -> 17.374428 | AC8: 7.12 | AD8: =SUM(AB8*AC8) -> 123.70593 | AE8: =SUM(X8+AD8) -> 4584.6851 | AF8: =SUM(P8-AE8) -> 5.986916
C9: 240814000030 | D9: 45518 | E9: Sam.Pao | F9: Sam.Pao | G9: LuZhiLong | H9: 1.5403 | I9: 189.9 | J9: 2643.36 | P9: =SUBTOTAL(9,J9) -> 2643.36 | S9: =SUM(20857/11.0091)*H9 -> 2918.1347 | T9: =SUM(351/11.0091)*H9 -> 49.108946 | X9: =SUM(S9:W9) -> 2967.2437 | AA9: =SUM(82.6/11.0091)*H9 -> 11.556692 | AB9: =SUM(Y9:AA9) -> 11.556692 | AC9: 7.12 | AD9: =SUM(AB9*AC9) -> 82.283648 | AE9: =SUM(X9+AD9) -> 3049.5273 | AF9: =SUM(P9-AE9) -> -406.16733
A10: 合计 | J10: =SUM(J4:J4) -> 0 | N10: =SUM(N4:N4) -> 0 | P10: =SUM(P4:P4) -> 0 | Q10: =SUM(Q4:Q4) -> 0 | X10: =SUM(X4:X4) -> 0 | AD10: =SUM(AD4:AD4) -> 0 | AF10: =SUM(AF4:AF9) -> 1577.5442

Sheet JOB090367
A1: 2024年09月份LOS毛利表（海运）
A2: JOB | B2: 集装编号 | C2: 运单编号 | D2: 日期 | E2: 业务 | F2: 发货人 | G2: 收货人 | H2: 计费体积 | I2: 计费重量 | J2: 应 收 | Q2: 总应收 | R2: 起 运 港 成 本 | W2: 代垫运费 | X2: 起运港成本 合计 | Y2: 目的港成本 | AE2: 总支出 | AF2: 利润
J3: 应收RMB | K3: LOS Income(NGN)收到(奈拉) | L3: LOS 收到USD | M3: 美元汇率 dollar currency rate | N3: 应收 到付款USD | O3: 汇率 | P3: 人民币 | R3: 代理商 | S3: 运费+出口报关费 | T3: 提货费 | U3: 装卸费 | V3: 包装费 | Y3: 进口报关费 | Z3: 到门配送费 | AA3: 转运费 | AB3: 目的港支出 | AC3: 汇率 | AD3: 人民币 | AE3: 起运港+目的港
A4: JOB090367 | B4: COLL004161 | C4: 240830000002 | D4: 45583 | E4: Sam.Pao | F4: Sam.Pao | G4: Mr. Jason | H4: 只清关 | K4: 18000000 | M4: =SUM(K4/N4) -> 1744.9909 | N4: 10315.24 | O4: 7.12 | P4: =SUM(N4*O4) -> 73444.509 | Q4: =SUM(P4) -> 73444.509 | X4: =SUM(S4:W4) -> 0 | Y4: 10324.48 | AB4: =SUM(Y4:AA4) -> 10324.48 | AC4: 7.12 | AD4: =SUM(AB4*AC4) -> 73510.298 | AE4: =SUM(X4+AD4) -> 73510.298 | AF4: =SUM(P4-AE4) -> -65.7888
A5: 合计 | J5: =SUM(J3:J3) -> 0 | N5: =SUM(N3:N3) -> 0 | P5: =SUM(P3:P3) -> 0 | Q5: =SUM(Q3:Q3) -> 0 | X5: =SUM(X3:X3) -> 0 | AD5: =SUM(AD3:AD3) -> 0 | AF5: =SUM(AF3:AF4) -> -65.7888

Sheet JOB090368
A1: 2024年09月份LOS毛利表（海运）
A2: JOB | B2: 集装编号 | C2: 运单编号 | D2: 日期 | E2: 业务 | F2: 发货人 | G2: 收货人 | H2: 计费体积 | I2: 计费重量 | J2: 应 收 | Q2: 总应收 | R2: 起 运 港 成 本 | W2: 代垫运费 | X2: 起运港成本 合计 | Y2: 目的港成本 | AE2: 总支出 | AF2: 利润
J3: 应收RMB | K3: LOS Income(NGN)收到(奈拉) | L3: LOS 收到USD | M3: 美元汇率 dollar currency rate | N3: 应收 到付款USD | O3: 汇率 | P3: 人民币 | R3: 代理商 | S3: 运费+出口报关费 | T3: 提货费 | U3: 装卸费 | V3: 包装费 | Y3: 进口报关费 | Z3: 到门配送费 | AA3: 转运费 | AB3: 目的港支出 | AC3: 汇率 | AD3: 人民币 | AE3: 起运港+目的港
A4: JOB090368 | B4: COLL004162 | C4: 240830000001 | D4: 45583 | E4: Sam.Pao | F4: Sam.Pao | G4: Mr. Jason | H4: 只清关 | K4: 15200000 | M4: =SUM(K4/N4) -> 1710.999 | N4: 8883.699 | O4: 7.12 | P4: =SUM(N4*O4) -> 63251.937 | Q4: =SUM(P4) -> 63251.937 | X4: =SUM(S4:W4) -> 0 | Y4: 7374.63 | AB4: =SUM(Y4:AA4) -> 7374.63 | AC4: 7.12 | AD4: =SUM(AB4*AC4) -> 52507.366 | AE4: =SUM(X4+AD4) -> 52507.366 | AF4: =SUM(P4-AE4) -> 10744.571
A5: 合计 | J5: =SUM(J3:J3) -> 0 | N5: =SUM(N3:N3) -> 0 | P5: =SUM(P3:P3) -> 0 | Q5: =SUM(Q3:Q3) -> 0 | X5: =SUM(X3:X3) -> 0 | AD5: =SUM(AD3:AD3) -> 0 | AF5: =SUM(AF3:AF4) -> 10744.571

Sheet JOB090375
A1: 2024年09月份LOS毛利表（海运）
A2: PSL表 | B2: 体积cbm | C2: 69.7395
A3: JOB | B3: 集装编号 | C3: 运单编号 | D3: 日期 | E3: 业务 | F3: 发货人 | G3: 收货人 | H3: 计费体积 | I3: 计费重量 | J3: 应 收 | Q3: 总应收 | R3: 起 运 港 成 本 | W3: 代垫运费 | X3: 起运港成本 合计 | Y3: 目的港成本 | AE3: 总支出 | AF3: 利润
J4: 应收RMB | K4: LOS Income(NGN)收到(奈拉) | L4: LOS 收到USD | M4: 美元汇率 dollar currency rate | N4: 应收 到付款USD | O4: 汇率 | P4: 人民币 | R4: 代理商 | S4: 运费+出口报关费 | T4: 提货费 | U4: 装卸费 | V4: 包装费 | Y4: 进口报关费 | Z4: 到门配送费 | AA4: 转运费 | AB4: 目的港支出 | AC4: 汇率 | AD4: 人民币 | AE4: 起运港+目的港
A5: JOB090375 | B5: COLL004167 | C5: 240816000024 | D5: 45554 | E5: 黄颖 | F5: ying | G5: Sunday Adelena | H5: 4.5226 | I5: 5204 | J5: 10335.77 | P5: =SUBTOTAL(9,J5) -> 10335.77 | Q5: =SUM(P5:P25) -> 147850.34 | R5: 卓志=41025 赛捷=2800 拖车费=1670 杂费=61 过磅费=67 | S5: =SUM(45623/68)*H5 -> 3034.3321 | U5: =SUM(1600/68)*H5 -> 106.41412 | X5: =SUM(S5:W5) -> 3140.7462 | Y5: =SUM(10737.46/68)*H5 -> 714.13583 | AA5: =SUM(53.1/68)*H5 -> 3.5316185 | AB5: =SUM(Y5:AA5) -> 717.66745 | AC5: 7.18 | AD5: =SUM(AB5*AC5) -> 5152.8523 | AE5: =SUM(X5+AD5) -> 8293.5985 | AF5: =SUM(P5-AE5) -> 2042.1715
C6: 240828000061 | D6: 45554 | E6: Sam.Pao | F6: Sam.Pao | G6: JunYue hotel | H6: 8.526 | I6: 1229 | J6: 19021 | P6: =SUBTOTAL(9,J6) -> 19021 | S6: =SUM(45623/68)*H6 -> 5720.3191 | U6: =SUM(1600/68)*H6 -> 200.61176 | X6: =SUM(S6:W6) -> 5920.9309 | Y6: =SUM(10737.46/68)*H6 -> 1346.288 | AA6: =SUM(53.1/68)*H6 -> 6.6578029 | AB6: =SUM(Y6:AA6) -> 1352.9458 | AC6: 7.18 | AD6: =SUM(AB6*AC6) -> 9714.1509 | AE6: =SUM(X6+AD6) -> 15635.082 | AF6: =SUM(P6-AE6) -> 3385.9183
C7: 240905000030 | D7: 45554 | E7: 吕沛霖 | F7: 喵喵速运-Layne | G7: Hu Hai Liang | H7: 6.5636 | I7: 3760 | K7: 3334275 | M7: =SUM(K7/N7) -> 1750.0459 | N7: 1905.25 | O7: 7.23 | P7: =SUM(N7*O7) -> 13774.958 | S7: =SUM(45623/68)*H7 -> 4403.693 | U7: =SUM(1600/68)*H7 -> 154.43765 | X7: =SUM(S7:W7) -> 4558.1306 | Y7: =SUM(10737.46/68)*H7 -> 1036.4175 | AA7: =SUM(53.1/68)*H7 -> 5.1253994 | AB7: =SUM(Y7:AA7) -> 1041.5429 | AC7: 7.18 | AD7: =SUM(AB7*AC7) -> 7478.2783 | AE7: =SUM(X7+AD7) -> 12036.409 | AF7: =SUM(P7-AE7) -> 1738.5486
C8: 240909000050 | D8: 45554 | E8: 无人 | F8: dejare James | G8: James | H8: 0.0321 | I8: 3.5 | L8: 8.99 | M8: =SUM(K8/N8) -> 0 | N8: 8.990002 | O8: 7.08 | P8: =SUM(N8*O8) -> 63.649214 | S8: =SUM(45623/68)*H8 -> 21.53674 | U8: =SUM(1600/68)*H8 -> 0.75529412 | X8: =SUM(S8:W8) -> 22.292034 | Y8: =SUM(10737.46/68)*H8 -> 5.0687127 | AA8: =SUM(53.1/68)*H8 -> 0.025066324 | AB8: =SUM(Y8:AA8) -> 5.0937791 | AC8: 7.18 | AD8: =SUM(AB8*AC8) -> 36.573334 | AE8: =SUM(X8+AD8) -> 58.865367 | AF8: =SUM(P8-AE8) -> 4.7838467
C9: 240911000014 | D9: 45554 | E9: 黄颖 | F9: ying | G9: jiangnan | H9: 0.546 | I9: 153 | J9: 1212.75 | P9: =SUBTOTAL(9,J9) -> 1212.75 | S9: =SUM(45623/68)*H9 -> 366.32585 | U9: =SUM(1600/68)*H9 -> 12.847059 | X9: =SUM(S9:W9) -> 379.17291 | Y9: =SUM(10737.46/68)*H9 -> 86.215488 | AA9: =SUM(53.1/68)*H9 -> 0.42636176 | AB9: =SUM(Y9:AA9) -> 86.641849 | AC9: 7.18 | AD9: =SUM(AB9*AC9) -> 622.08848 | AE9: =SUM(X9+AD9) -> 1001.2614 | AF9: =SUM(P9-AE9) -> 211.48861
C10: 240912000025 | D10: 45554 | E10: 朱小飞 | F10: Isabel Zhu | G10: Halifa Success | H10: 0.0329 | I10: 7.28 | J10: 221.13 | P10: =SUBTOTAL(9,J10) -> 221.13 | S10: =SUM(45623/68)*H10 -> 22.073481 | U10: =SUM(1600/68)*H10 -> 0.77411765 | X10: =SUM(S10:W10) -> 22.847599 | Y10: =SUM(10737.46/68)*H10 -> 5.1950358 | AA10: =SUM(53.1/68)*H10 -> 0.025691029 | AB10: =SUM(Y10:AA10) -> 5.2207268 | AC10: 7.18 | AD10: =SUM(AB10*AC10) -> 37.484819 | AE10: =SUM(X10+AD10) -> 60.332417 | AF10: =SUM(P10-AE10) -> 160.79758
C11: 240912000029 | D11: 45554 | E11: 黄颖 | F11: ying | G11: Bruce | H11: 1.2975 | I11: 506 | J11: 2649 | P11: =SUBTOTAL(9,J11) -> 2649 | S11: =SUM(45623/68)*H11 -> 870.5271 | U11: =SUM(1600/68)*H11 -> 30.529412 | X11: =SUM(S11:W11) -> 901.05651 | Y11: =SUM(10737.46/68)*H11 -> 204.88021 | AA11: =SUM(53.1/68)*H11 -> 1.0131949 | AB11: =SUM(Y11:AA11) -> 205.89341 | AC11: 7.18 | AD11: =SUM(AB11*AC11) -> 1478.3147 | AE11: =SUM(X11+AD11) -> 2379.3712 | AF11: =SUM(P11-AE11) -> 269.62884
C12: 240912000039 | D12: 45554 | E12: 黄颖 | F12: ying | G12: Sunday Adelena | H12: 2.7009 | I12: 1774 | J12: 5427.88 | P12: =SUBTOTAL(9,J12) -> 5427.88 | S12: =SUM(45623/68)*H12 -> 1812.1053 | U12: =SUM(1600/68)*H12 -> 63.550588 | X12: =SUM(S12:W12) -> 1875.6559 | Y12: =SUM(10737.46/68)*H12 -> 426.48244 | AA12: =SUM(53.1/68)*H12 -> 2.1090851 | AB12: =SUM(Y12:AA12) -> 428.59152 | AC12: 7.18 | AD12: =SUM(AB12*AC12) -> 3077.2871 | AE12: =SUM(X12+AD12) -> 4952.943 | AF12: =SUM(P12-AE12) -> 474.93698
C13: 240913000002 | D13: 45554 | E13: 朱小飞 | F13: Isabel Zhu | G13: Lin Bao Zhen | H13: 0.64 | I13: 208 | K13: 485452.8 | M13: =SUM(K13/N13) -> 1764.0001 | N13: 275.19998 | O13: 7.08 | P13: =SUM(N13*O13) -> 1948.4159 | S13: =SUM(45623/68)*H13 -> 429.39294 | U13: =SUM(1600/68)*H13 -> 15.058824 | X13: =SUM(S13:W13) -> 444.45176 | Y13: =SUM(10737.46/68)*H13 -> 101.05845 | AA13: =SUM(53.1/68)*H13 -> 0.49976471 | AB13: =SUM(Y13:AA13) -> 101.55821 | AC13: 7.18 | AD13: =SUM(AB13*AC13) -> 729.18796 | AE13: =SUM(X13+AD13) -> 1173.6397 | AF13: =SUM(P13-AE13) -> 774.77613
C14: 240913000030 | D14: 45554 | E14: 黄颖 | F14: ying | G14: jiangnan | H14: 0.6324 | I14: 181 | J14: 1411.2 | P14: =SUBTOTAL(9,J14) -> 1411.2 | S14: =SUM(45623/68)*H14 -> 424.2939 | U14: =SUM(1600/68)*H14 -> 14.88 | X14: =SUM(S14:W14) -> 439.1739 | Y14: =SUM(10737.46/68)*H14 -> 99.858378 | AA14: =SUM(53.1/68)*H14 -> 0.49383 | AB14: =SUM(Y14:AA14) -> 100.35221 | AC14: 7.18 | AD14: =SUM(AB14*AC14) -> 720.52885 | AE14: =SUM(X14+AD14) -> 1159.7028 | AF14: =SUM(P14-AE14) -> 251.49725
C15: 240913000032 | D15: 45554 | E15: 朱小飞 | F15: Isabel Zhu | G15: Gbenga | H15: 0.2805 | I15: 35 | K15: 156631 | M15: =SUM(K15/N15) -> 1744.9979 | N15: 89.759995 | O15: 7.08 | P15: =SUM(N15*O15) -> 635.50076 | S15: =SUM(45623/68)*H15 -> 188.19487 | U15: =SUM(1600/68)*H15 -> 6.6 | X15: =SUM(S15:W15) -> 194.79487 | Y15: =SUM(10737.46/68)*H15 -> 44.292023 | AA15: =SUM(53.1/68)*H15 -> 0.2190375 | AB15: =SUM(Y15:AA15) -> 44.51106 | AC15: 7.18 | AD15: =SUM(AB15*AC15) -> 319.58941 | AE15: =SUM(X15+AD15) -> 514.38429 | AF15: =SUM(P15-AE15) -> 121.11648
C16: 240911000008 | D16: 45559 | E16: 陆总 | F16: 陆梓龙 | G16: jizong | H16: 6.1104 | I16: 5000 | J16: 15665.8 | P16: =SUBTOTAL(9,J16) -> 15665.8 | S16: =SUM(45623/68)*H16 -> 4099.6291 | U16: =SUM(1600/68)*H16 -> 143.77412 | X16: =SUM(S16:W16) -> 4243.4032 | Y16: =SUM(10737.46/68)*H16 -> 964.85552 | AA16: =SUM(53.1/68)*H16 -> 4.7715035 | AB16: =SUM(Y16:AA16) -> 969.62703 | AC16: 7.18 | AD16: =SUM(AB16*AC16) -> 6961.9221 | AE16: =SUM(X16+AD16) -> 11205.325 | AF16: =SUM(P16-AE16) -> 4460.4747
C17: 240914000051 | D17: 45554 | E17: Bella | F17: Bella Chan | G17: Shuaibu musa | H17: 0.3911 | I17: 120 | J17: 907.12 | P17: =SUBTOTAL(9,J17) -> 907.12 | S17: =SUM(45623/68)*H17 -> 262.39934 | U17: =SUM(1600/68)*H17 -> 9.2023529 | X17: =SUM(S17:W17) -> 271.6017 | Y17: =SUM(10737.46/68)*H17 -> 61.756185 | AA17: =SUM(53.1/68)*H17 -> 0.30540309 | AB17: =SUM(Y17:AA17) -> 62.061588 | AC17: 7.18 | AD17: =SUM(AB17*AC17) -> 445.60221 | AE17: =SUM(X17+AD17) -> 717.2039 | AF17: =SUM(P17-AE17) -> 189.9161
C18: 240917000017 | D18: 45554 | E18: 黄颖 | F18: ying | G18: makus | H18: 1.7265 | I18: 349 | J18: 4987.5 | P18: =SUBTOTAL(9,J18) -> 4987.5 | S18: =SUM(45623/68)*H18 -> 1158.3546 | U18: =SUM(1600/68)*H18 -> 40.623529 | X18: =SUM(S18:W18) -> 1198.9781 | Y18: =SUM(10737.46/68)*H18 -> 272.62095 | AA18: =SUM(53.1/68)*H18 -> 1.3481934 | AB18: =SUM(Y18:AA18) -> 273.96914 | AC18: 7.18 | AD18: =SUM(AB18*AC18) -> 1967.0985 | AE18: =SUM(X18+AD18) -> 3166.0765 | AF18: =SUM(P18-AE18) -> 1821.4235
