Workbook

Sheet 6月份
A1: 尼日利亚拉各斯（LOS） 应收明细表（海运）
A3: JOB | B3: 集装编号 | C3: 运单编号 | D3: 日期 | E3: 发货人 | F3: 收货人 | G3: 计费体积 | H3: 计费重量 | I3: 应 收 | P3: 总应收 | Q3: 起 运 港 成 本 | V3: 代垫运费 | W3: 起运港成本 合计 | X3: 目的港成本 | AD3: 总支出 | AE3: 利润
I4: 应收RMB | J4: LOS Income(NGN)收到(奈拉) | K4: LOS 收到USD | L4: 美元汇率 dollar currency rate | M4: 应收 到付款USD | N4: 汇率 | O4: 人民币 | Q4: 代理商 | R4: 运费+出口报关费 | S4: 提货费 | T4: 装卸费 | U4: 包装费 | X4: 进口报关费 | Y4: 到门配送费 | Z4: 转运费 | AA4: 目的港支出 | AB4: 汇率 | AC4: 人民币 | AD4: 起运港+目的港
A5: JOB060359 | B5: COLL004009 | C5: 240605000016 | D5: 45456 | E5: Bella Chan | F5: james | G5: 1.9688 | H5: 441 | K5: 807.21 | L5: =SUM(J5/M5) -> 0 | M5: 807.21 | N5: 7.12 | O5: =SUM(M5*N5) -> 5747.3352 | P5: =SUM(O5:O9) -> 36897.902 | Q5: 智托（陆总代付） | R5: 31274.1 | S5: 250 | W5: =SUM(R5:V9) -> 31524.1 | AA5: =SUM(X5:Z9) -> 0 | AC5: =SUM(AA5*AB5) -> 0 | AD5: =SUM(W5+AC5) -> 31524.1 | AE5: =SUM(P5-AD5) -> 5373.8022
C6: 240607000057 | D6: 45456 | E6: Sam.Pao | F6: MaiKaiNian | G6: 3.5715 | H6: 587 | I6: 9711.62 | O6: =SUBTOTAL(9,I6) -> 9711.62
C7: 240608000016 | D7: 45456 | E7: Isabel Zhu | F7: Halifa Success | G7: 0.6486 | H7: 105 | I7: 1701.18 | O7: =SUBTOTAL(9,I7) -> 1701.18
C8: 241031000031 | D8: 45456 | E8: Shirley | F8: LUZILONG | G8: 4.4495 | H8: 795 | I8: 10251.65 | O8: =SUBTOTAL(9,I8) -> 10251.65
C9: 240611000023 | D9: 45456 | E9: Bella Chan | F9: Shuaibu musa | G9: 3.0276 | H9: 667 | J9: 2173116 | L9: =SUM(J9/M9) -> 1631.0769 | M9: 1332.3198 | N9: 7.12 | O9: =SUM(M9*N9) -> 9486.117
A10: JOB060384 | B10: COLL004033 | C10: 240611000035 | D10: 45470 | E10: ying | F10: Zhangqing | G10: 9.409 | H10: 4580 | I10: 30088 | O10: =SUM(I10) -> 30088 | P10: =SUM(O10:O23) -> 173903.7 | Q10: 华茂青松 | R10: 65426 | S10: =SUM(203+330) -> 533 | T10: 850 | W10: =SUM(R10:V23) -> 66809 | X10: 10644.17 | Z10: 43.56 | AA10: =SUM(X10:Z23) -> 10716.03 | AB10: 7.12 | AC10: =SUM(AA10*AB10) -> 76298.134 | AD10: =SUM(W10+AC10) -> 143107.13 | AE10: =SUM(P10-AD10) -> 30796.565
C11: 240617000014 | D11: 45470 | E11: 喵喵速运-Layne | F11: Abdulsheldu | G11: 0.3223 | H11: 145 | J11: 282730 | L11: =SUM(J11/M11) -> 1744.4931 | M11: 162.07 | N11: 7.12 | O11: =SUM(M11*N11) -> 1153.9384 | Y11: 17.26
C12: 240617000031 | D12: 45470 | E12: Bella Chan | F12: zhang jian fei | G12: 1.883 | H12: 1442 | I12: 5247 | O12: =SUBTOTAL(9,I12) -> 5247 | Y12: 5.56
C13: 240618000013 | D13: 45470 | E13: Isabel Zhu | F13: Lilon | G13: 17.0878 | H13: 12818 | I13: 44822.88 | O13: =SUBTOTAL(9,I13) -> 44822.88
C14: 240619000002 | D14: 45470 | E14: Sam.Pao | F14: JUNDA YU | G14: 4.1762 | H14: 308 | I14: 10081.3 | O14: =SUBTOTAL(9,I14) -> 10081.3
C15: 240622000007 | D15: 45470 | E15: Sam.Pao | F15: MaiKaiNian | G15: 0.1344 | H15: 44 | I15: 426 | O15: =SUBTOTAL(9,I15) -> 426
C16: 240624000032 | D16: 45470 | E16: ying | F16: chuks | G16: 14.1194 | H16: 5232 | I16: 30090 | O16: =SUM(I16) -> 30090
C17: 240624000052 | D17: 45470 | E17: ying | F17: Adindu | G17: 0.098 | H17: 5.56 | J17: 69566 | L17: =SUM(J17/M17) -> 1639.934 | M17: 42.42 | N17: 7.12 | O17: =SUM(M17*N17) -> 302.0304 | Y17: 5.48
C18: 240625000041 | D18: 45470 | E18: Sam.Pao | F18: SKY JET | G18: 19.56 | H18: 2429.25 | I18: 35563.01 | O18: =SUBTOTAL(9,I18) -> 35563.01
C19: 240626000037 | D19: 45470 | E19: Sam.Pao | F19: LuZhiLong | G19: 0.9428 | H19: 188 | I19: 3034.1 | O19: =SUM(I19) -> 3034.1
C20: 240626000038 | D20: 45470 | E20: Sam.Pao | F20: LuZhiLong | G20: 2.178 | H20: 178 | I20: 5331.74 | O20: =SUBTOTAL(9,I20) -> 5331.74
C21: 240626000039 | D21: 45470 | E21: Sam.Pao | F21: LuZhiLong | G21: 1.1137 | H21: 719 | I21: 2807.28 | O21: =SUBTOTAL(9,I21) -> 2807.28
C22: 240627000004 | D22: 45470 | E22: Isabel Zhu | F22: Victor Nnamdi | G22: 1.0982 | H22: 111.44 | J22: 649440 | L22: =SUM(J22/M22) -> 1640 | M22: 396 | N22: 7.12 | O22: =SUM(M22*N22) -> 2819.52
C23: 240627000022 | D23: 45470 | E23: Sam.Pao | F23: JunYue hotel | G23: 0.8852 | H23: 140.4 | I23: 2136.9 | O23: =SUBTOTAL(9,I23) -> 2136.9
A24: JOB060385 | B24: COLL004034 | C24: 240619000007 | D24: 45471 | E24: Isabel Zhu | F24: Jiang Li | G24: 0.917 | H24: 510 | I24: 2914 | O24: =SUBTOTAL(9,I24) -> 2914 | P24: =SUM(O24:O29) -> 28646.262 | Q24: 赛捷 | R24: 20340 | S24: 215.1 | W24: =SUM(R24:V29) -> 20555.1 | X24: 221.6 | Y24: 73.61 | AA24: =SUM(X24:Z29) -> 295.21 | AB24: 7.1 | AC24: =SUM(AA24*AB24) -> 2095.991 | AD24: =SUM(W24+AC24) -> 22651.091 | AE24: =SUM(P24-AD24) -> 5995.171
C25: 240617000031 | D25: 45470 | E25: Bella Chan | F25: zhang jian fei | G25: 0.1218 | H25: 88 | I25: 339 | O25: =SUBTOTAL(9,I25) -> 339
C26: 240626000021 | D26: 45470 | E26: Isabel Zhu | F26: Ife Oyelami | G26: 0.5044 | H26: 54.9 | J26: 311202 | L26: =SUM(J26/M26) -> 1695 | M26: 183.6 | N26: 7.12 | O26: =SUM(M26*N26) -> 1307.232
C27: 240621000002 | D27: 45470 | E27: 喵喵速运-Layne | F27: Ka Ka 4分部 | G27: 7.215 | H27: 975 | I27: 21110.59 | O27: =SUM(I27) -> 21110.59
C28: 240625000038 | D28: 45471 | E28: Sam.Pao | F28: MaiKaiNian | G28: 0.8478 | H28: 220 | I28: 2197.44 | O28: =SUBTOTAL(9,I28) -> 2197.44
C29: 240627000005 | D29: 45471 | E29: Isabel Zhu | F29: Jiang Li | G29: 0.2937 | H29: 24 | I29: 778 | O29: =SUBTOTAL(9,I29) -> 778
A30: 合 计 | G30: =SUM(G5:G29) -> 96.5737 | H30: =SUM(H5:H29) -> 32807.55 | I30: =SUM(I5:I29) -> 218631.69 | J30: =SUM(J5:J28) -> 3486054 | K30: =SUM(K5:K28) -> 807.21 | M30: =SUM(M5:M29) -> 2923.6198 | N30: 7.12 | O30: =SUM(O5:O29) -> 239447.86 | P30: =SUM(P5:P28) -> 239447.86 | R30: =SUM(R5:R29) -> 117040.1 | S30: =SUM(S5:S29) -> 998.1 | T30: =SUM(T5:T29) -> 850 | U30: =SUM(U5:U29) -> 0 | V30: =SUM(V5:V29) -> 0 | W30: =SUM(W5:W29) -> 118888.2 | X30: =SUM(X5:X29) -> 10865.77 | Y30: =SUM(Y5:Y29) -> 101.91 | ... AA30: =SUM(AA5:AA29) -> 11011.24 | AB30: 7.12 | AC30: =SUM(AC10:AC29) -> 78394.125 | AD30: =SUM(AD5:AD28) -> 197282.32 | AE30: =SUM(AE5:AE29) -> 42165.538
G32: 月份 | H32: 到付 (USD) | I32: 目的港成本合计 | J32: 应收到付款 （USD） | K32: 汇率 | L32: 应收 LOS到付款(人民币)
G33: 6 | H33: =SUM(M30) -> 2923.6198 | I33: =SUM(AA30) -> 11011.24 | J33: =SUM(H33-I33) -> -8087.6202 | K33: 7.12 | L33: =SUM(J33*K33) -> -57583.856
G35: 月份 | H35: 应 收 | L35: 总应收 | M35: 起运港 成本合计 | N35: 目的港 成本合计 | O35: 利润
H36: 应收RMB | I36: LOS已收款 (USD) | J36: 汇率 | K36: LOS已收 （RMB）
G37: 6 | H37: =SUM(I30) -> 218631.69 | I37: =SUM(M30) -> 2923.6198 | J37: 7.12 | K37: =SUM(M30*J37) -> 20816.173 | L37: =SUM(H37+K37) -> 239447.86 | M37: =SUM(W30) -> 118888.2 | N37: =SUM(AC30) -> 78394.125 | O37: =SUM(L37-M37-N37) -> 42165.538

Sheet 7月份
A1: 尼日利亚拉各斯（LOS） 应收利润明细表
A2: JOB | B2: 集装编号 | C2: 运单编号 | D2: 日期 | E2: 发货人 | F2: 收货人 | G2: 计费体积 | H2: 计费重量 | I2: 应 收 | P2: 总应收 | Q2: 起 运 港 成 本 | V2: 代垫运费 | W2: 起运港成本 合计 | X2: 目的港成本 | AD2: 总支出 | AE2: 利润
I3: 应收RMB | J3: LOS Income(NGN)收到(奈拉) | K3: LOS 收到USD | L3: 美元汇率 dollar currency rate | M3: 应收 到付款USD | N3: 汇率 | O3: 人民币 | Q3: 代理商 | R3: 运费+ 出口报关费 | S3: 提货费 | T3: 装卸费 | U3: 包装费 | X3: 进口报关费 | Y3: 到门配送费 | Z3: 转运费 | AA3: 目的港支出 | AB3: 汇率 | AC3: 人民币 | AD3: 起运港+目的港
A4: JOB070344 | B4: COLL004043 | C4: 240624000034 | D4: 45477 | E4: ying | F4: baikaibo | G4: 3.024 | H4: 2000 | J4: 2320436 | L4: 1651.8616 | M4: 1404.74 | N4: 7.12 | O4: 10001.749 | P4: 168759.19 | Q4: 华茂青松=60177 赛捷=1300 | R4: 61477 | T4: 1250 | W4: 64164 | X4: 10640.25 | Y4: 5.49 | AA4: 10687.2 | AB4: 7.1 | AC4: 75879.12 | AD4: 140043.12 | AE4: 28716.072
C5: 240624000036 | D5: 45478 | E5: ying | F5: Sunday Adelena | G5: 10.2263 | H5: 7008 | I5: 26828 | O5: 26828 | U5: 120
C6: 240624000056 | D6: 45477 | E6: Sam.Pao | F6: TOLUBOD MOVERS | G6: 0.509 | H6: 207 | I6: 1893.7 | O6: 1893.7 | U6: 270
C7: 240626000044 | D7: 45477 | E7: Sam.Pao | F7: JunYue hotel | G7: 0.6356 | H7: 450 | I7: 1714.8 | O7: 1714.8
C8: 240628000020 | D8: 45477 | E8: ying | F8: baikaibo | G8: 0.472 | H8: 420 | J8: 439900 | L8: 1705.0388 | M8: 258 | N8: 7.12 | O8: 1836.96
C9: 240628000031 | D9: 45477 | E9: Isabel Zhu | F9: Wang Hui Feng | G9: 1.7537 | H9: 2930 | J9: 2405060 | L9: 1640 | M9: 1466.5 | N9: 7.12 | O9: 10441.48
C10: 240628000036 | D10: 45477 | E10: Isabel Zhu | F10: Halifa Success | G10: 0.6693 | H10: 116.5 | I10: 1662.94 | O10: 1662.94
C11: 240701000015 | D11: 45477 | E11: 喵喵速运-Layne | F11: YA | G11: 0.3978 | H11: 49.5 | I11: 1385.08 | O11: 1385.08 | Y11: 41.46
C12: 240701000020 | D12: 45477 | E12: 喵喵速运-Layne | F12: Jinggang Pan | G12: 0.5519 | H12: 82 | I12: 1460.33 | O12: 1460.33
C13: 240701000054 | D13: 45477 | E13: Mailmail Abv sales person 1 | F13: Adams | G13: 2.5358 | H13: 1140 | J13: 1490760 | L13: 1639.9991 | M13: 909.0005 | N13: 7.12 | O13: 6472.0836 | U13: 120
C14: 240702000007 | D14: 45477 | E14: Isabel Zhu | F14: Halifa Success | G14: 0.8928 | H14: 218 | I14: 2361.55 | O14: 2361.55 | V14: 292
C15: 240702000008 | D15: 45477 | E15: Isabel Zhu | F15: Halifa Success | G15: 2.232 | H15: 1028 | I15: 6070.88 | O15: 6070.88 | S15: 215 | V15: 420
C16: 240702000009 | D16: 45477 | E16: Isabel Zhu | F16: Halifa Success | G16: 5.8065 | H16: 650 | I16: 13360.1 | O16: 13360.1
C17: 240703000022 | D17: 45477 | E17: Isabel Zhu | F17: Lilon | G17: 2.6714 | H17: 1555 | I17: 7525.12 | O17: 7525.12
C18: 240703000028 | D18: 45477 | E18: Sam.Pao | F18: Mr. Jiang | G18: 0.9089 | H18: 232 | I18: 3294.7 | O18: 3294.7
C19: 240703000030 | D19: 45477 | E19: Sam.Pao | F19: JunYue hotel | G19: 1.1081 | H19: 861 | I19: 2989.7 | O19: 2989.7
C20: 240704000029 | D20: 45482 | E20: Sam.Pao | F20: LuZhiLong | G20: 0.7168 | H20: 230 | I20: 1792 | O20: 1792
C21: 240607000053 | D21: 45478 | E21: 喵喵速运-Layne | F21: KE ZONG | G21: 1.3088 | H21: 352 | I21: 3425 | O21: 3425
C22: 240617000035 | D22: 45490 | E22: ying | F22: Huangpu | G22: 0.0887 | H22: 106 | I22: 332 | O22: 332
C23: 240703000031 | D23: 45478 | E23: Sam.Pao | F23: SKY JET | G23: 36.23 | H23: 4650 | I23: 63805.02 | O23: 63805.02
C24: 240704000018 | D24: 45477 | E24: Sam.Pao | F24: MaiKaiNian | G24: 0.0287 | H24: 25 | I24: 106 | O24: 106
A25: JOB070349 | B25: COLL004049 | C25: 240607000053 | D25: 45478 | E25: 喵喵速运-Layne | F25: KE ZONG | G25: 1.3459 | H25: 622 | I25: 3524.24 | O25: 3524.24 | P25: 156852.59 | Q25: 华茂青松=60177 赛捷=800 | R25: 60977 | S25: 125.62 | T25: 1150 | U25: 120 | W25: 62492.62 | X25: 10579.27 | Z25: 57.93 | AA25: 10637.2 | AB25: 7.1 | AC25: 75524.12 | AD25: 138016.74 | AE25: 18835.85
C26: 240624000036 | D26: 45478 | E26: ying | F26: Sunday Adelena | G26: 1.1026 | H26: 1089 | I26: 2892 | O26: 2892 | U26: 120
C27: 240624000037 | D27: 45478 | E27: ying | F27: Sunday Adelena | G27: 14.6754 | H27: 11776.5 | I27: 43280 | O27: 43280
C28: 240704000029 | D28: 45482 | E28: Sam.Pao | F28: LuZhiLong | G28: 13.9646 | H28: 3568 | I28: 34908 | O28: 34908
C29: 240617000035 | D29: 45490 | E29: ying | F29: Huangpu | G29: 1.6952 | H29: 322.7 | I29: 6330 | O29: 6330
C30: 240703000031 | D30: 45478 | E30: Sam.Pao | F30: SKY JET | G30: 7.89 | H30: 615 | I30: 13912.77 | O30: 13912.77
C31: 240705000003 | D31: 45478 | E31: Sam.Pao | F31: SKY JET | G31: 29.53 | H31: 3724 | I31: 52005.58 | O31: 52005.58
A32: JOB070360 | B32: COLL004060 | C32: 240618000026 | D32: 45482 | E32: Sam.Pao | F32: Joshua | G32: 9.004 | H32: 5844 | I32: 32609 | O32: 32609 | P32: 184530.54 | Q32: 华茂青松=60177 赛捷=1500 | R32: 61677 | T32: 2200 | U32: 120 | V32: 1600 | W32: 65597 | X32: 10235.99 | Y32: 513.28 | Z32: 77.88 | AA32: 10827.15 | AB32: 7.12 | AC32: 77089.308 | AD32: 142686.31 | AE32: 41844.232
C33: 240704000029 | D33: 45482 | E33: Sam.Pao | F33: LuZhiLong | G33: 14.9276 | H33: 11064 | I33: 37314.5 | O33: 37314.5
C34: 240617000035 | D34: 45490 | E34: ying | F34: Huangpu | G34: 12.8123 | H34: 5331.1 | I34: 47840 | O34: 47840
C35: 240707000003 | D35: 45482 | E35: Sam.Pao | F35: LuZhiLong | G35: 0.1208 | H35: 69 | I35: 330.48 | O35: 330.48
C36: 240708000038 | D36: 45482 | E36: 喵喵速运-江 | F36: LUZHILONG | G36: 1.6 | H36: 1009 | I36: 3916.8 | O36: 3916.8
C37: 240708000062 | D37: 45482 | E37: Sam.Pao | F37: SKY JET | G37: 35.79 | H37: 4290.5 | I37: 62519.76 | O37: 62519.76
A38: JOB070370 | B38: COLL004070 | C38: 240617000035 | D38: 45490 | E38: ying | F38: Huangpu | G38: 4.9371 | H38: 11872 | I38: 18452 | O38: 18452 | P38: 164523.2 | Q38: 华茂青松=60177 赛捷=2300 | R38: 62477 | S38: 770 | T38: 2400 | V38: 2630 | W38: 68477 | X38: 10235.99 | Y38: 471.98 | Z38: 35.4 | AA38: 10802.37 | AB38: 7.26 | AC38: 78425.206 | AD38: 146902.21 | AE38: 17620.994
C39: 240702000004 | D39: 45490 | E39: ying | F39: liangyu | G39: 1.9054 | H39: 586.7 | I39: 7303 | O39: 7303
C40: 240702000027 | D40: 45490 | E40: Sam.Pao | F40: Ikenna | G40: 0.9364 | H40: 230 | J40: 539654 | L40: 1694.9997 | M40: 318.38 | N40: 7.08 | O40: 2254.1304
...

Sheet 8月份
A1: 尼日利亚拉各斯（LOS） 应收明细表（海运）
A3: JOB | B3: 集装编号 | C3: 运单编号 | D3: 日期 | E3: 发货人 | F3: 收货人 | G3: 计费体积 | H3: 计费重量 | I3: 应 收 | P3: 总应收 | Q3: 起 运 港 成 本 | V3: 代垫运费 | W3: 起运港成本 合计 | X3: 目的港成本 | AD3: 总支出 | AE3: 利润
I4: 应收RMB | J4: LOS Income(NGN)收到(奈拉) | K4: LOS 收到USD | L4: 美元汇率 dollar currency rate | M4: 应收 到付款USD | N4: 汇率 | O4: 人民币 | Q4: 代理商 | R4: 运费+ 出口报关费 | S4: 提货费 | T4: 装卸费 | U4: 包装费 | X4: 进口报关费 | Y4: 到门配送费 | Z4: 转运费 | AA4: 目的港支出 | AB4: 汇率 | AC4: 人民币 | AD4: 起运港+目的港
A5: JOB080389 | B5: COLL004124 | C5: 240708000003 | D5: 45491 | E5: MailMail速运-演员 | F5: zeng hai | G5: 2.2272 | H5: 11222 | J5: 8906452 | L5: =SUM(J5/M5) -> 1620.0015 | M5: 5497.8047 | N5: 7.12 | O5: =SUM(M5*N5) -> 39144.369 | P5: =SUM(O5:O9) -> 58091.472 | Q5: 赛捷 | R5: 19204 | S5: 40.68 | U5: 350 | W5: =SUM(R5:V9) -> 19664.68 | Z5: 100.29 | AA5: =SUM(X5:Z9) -> 208.15 | AB5: 7.15 | AC5: =SUM(AA5*AB5) -> 1488.2725 | AD5: =SUM(W5+AC5) -> 21152.952 | AE5: =SUM(P5-AD5) -> 36938.519
C6: 240715000049 | D6: 45490 | E6: Sam.Pao | F6: Yusky | G6: 0.4043 | H6: 55 | I6: 923.29 | O6: =SUBTOTAL(9,I6) -> 923.29
C7: 240709000025 | D7: 45491 | E7: ying | F7: Huangpu | G7: 0.1112 | H7: 57 | I7: 556 | O7: =SUBTOTAL(9,I7) -> 556 | Y7: 37.06
C8: 240713000006 | D8: 45491 | E8: Isabel Zhu | F8: Anthonia | G8: 1.7306 | H8: 346 | I8: 5462 | O8: =SUM(I8) -> 5462 | Y8: 70.8
C9: 240718000002 | D9: 45491 | E9: MailMail速运-演员 | F9: zeng hai | G9: 5.3938 | H9: 1414 | J9: 2909624 | L9: =SUM(J9/M9) -> 1711 | M9: 1700.54 | N9: 7.06 | O9: =SUM(M9*N9) -> 12005.812 | U9: 70
A10: JOB080353 | B10: COLL004085 | C10: 240719000024 | D10: 45505 | E10: Paul | F10: Paul | G10: 0.0423 | H10: 12.5 | I10: 356 | O10: =SUBTOTAL(9,I10) -> 356 | P10: =SUM(O10:O21) -> 156015.34 | Q10: 华茂青松=56567 赛捷=1280 | R10: =SUM(56567+1280) -> 57847 | T10: =SUM(1000+400) -> 1400 | W10: =SUM(R10:V21) -> 59247 | X10: 10235.99 | Y10: 9.09 | AA10: =SUM(X10:Z21) -> 10923.55 | AB10: 7.08 | AC10: =SUM(AA10*AB10) -> 77338.734 | AD10: =SUM(W10+AC10) -> 136585.73 | AE10: =SUM(P10-AD10) -> 19429.606
C11: 240717000037 | D11: 45498 | E11: Isabel Zhu | F11: Mr Michael | G11: 6.1861 | H11: 1004.71 | I11: 14822 | O11: =SUBTOTAL(9,I11) -> 14822
C12: 240724000023 | D12: 45505 | E12: Sam.Pao | F12: Yusky | G12: 0.158 | H12: 156 | I12: 337.92 | O12: =SUBTOTAL(9,I12) -> 337.92
C13: 240718000039 | D13: 45511 | E13: ying | F13: Idris | G13: 0.5054 | H13: 412 | I13: 2582 | O13: =SUBTOTAL(9,I13) -> 2582
C14: 240726000053 | D14: 45505 | E14: Isabel Zhu | F14: Halifa Success | G14: 0.2452 | H14: 41 | I14: 611.38 | O14: =SUBTOTAL(9,I14) -> 611.38
C15: 240727000003 | D15: 45505 | E15: Sam.Pao | F15: Nick Wang | G15: 4.7589 | H15: 760 | I15: 17244.43 | O15: =SUBTOTAL(9,I15) -> 17244.43 | Y15: 678.47
C16: 240729000009 | D16: 45505 | E16: Isabel Zhu | F16: Joy | G16: 2.2224 | H16: 3202 | J16: 2787617 | L16: =SUM(J16/M16) -> 1741.2595 | M16: 1600.9199 | N16: 7.12 | O16: =SUM(M16*N16) -> 11398.55
C17: 240729000055 | D17: 45505 | E17: 喵喵速运-江 | F17: LUZHILONG | G17: 22.022 | H17: 12675 | I17: 54288.61 | O17: =SUBTOTAL(9,I17) -> 54288.61
C18: 240730000017 | D18: 45505 | E18: Sam.Pao | F18: MaiKaiNian | G18: 0.2622 | H18: 392 | I18: 1290.24 | O18: =SUBTOTAL(9,I18) -> 1290.24
C19: 240801000003 | D19: 45505 | E19: Sam.Pao | F19: Yusky | G19: 2.1 | H19: 352 | I19: 4491.38 | O19: =SUBTOTAL(9,I19) -> 4491.38
C20: 240801000001 | D20: 45506 | E20: Sam.Pao | F20: SKY JET | G20: 28.4144 | H20: 2700 | I20: 48216.84 | O20: =SUBTOTAL(9,I20) -> 48216.84
C21: 240801000004 | D21: 45505 | E21: Sam.Pao | F21: Yusky | G21: 0.1758 | H21: 34 | I21: 375.99 | O21: =SUBTOTAL(9,I21) -> 375.99
A22: JOB080361 | B22: COLL004096 | C22: 240707000004 | D22: 45506 | E22: Sam.Pao | F22: ShanShan | G22: 9.3447 | H22: 5042.5 | I22: 28642.1 | O22: =SUBTOTAL(9,I22) -> 28642.1 | P22: =SUM(O22:O42) -> 165882.73 | Q22: 华茂青松=56567 赛捷=2300 | R22: =SUM(56567+2300) -> 58867 | T22: =SUM(1000+700+300) -> 2000 | W22: =SUM(R22:V42) -> 60867 | X22: 10117.99 | Y22: 88.5 | Z22: =SUM(41.3+50.15) -> 91.45 | AA22: =SUM(X22:Z42) -> 10743.72 | AB22: 7.15 | AC22: =SUM(AA22*AB22) -> 76817.598 | AD22: =SUM(W22+AC22) -> 137684.6 | AE22: =SUM(P22-AD22) -> 28198.136
C23: 240719000020 | D23: 45506 | E23: Sam.Pao | F23: Wendy | G23: 0.645 | H23: 148 | I23: 2922.21 | O23: =SUBTOTAL(9,I23) -> 2922.21 | Y23: 160.91
C24: 240719000037 | D24: 45506 | E24: 喵喵速运-Layne | F24: Hu Hai Liang | G24: 0.9193 | H24: 430 | J24: 579841.5 | L24: =SUM(J24/M24) -> 1744.5663 | M24: 332.37 | N24: 7.12 | O24: =SUM(M24*N24) -> 2366.4744
C25: 240723000028 | D25: 45506 | E25: Isabel Zhu | F25: Musa Garuba | G25: 0.4159 | H25: 53.8 | J25: 286650 | L25: =SUM(J25/M25) -> 1750 | M25: 163.8 | N25: 7.12 | O25: =SUM(M25*N25) -> 1166.256
C26: 240717000037 | D26: 45498 | E26: Isabel Zhu | F26: Mr Michael | G26: 8.2 | H26: 882 | I26: 19661.07 | O26: =SUBTOTAL(9,I26) -> 19661.07
C27: 240718000039 | D27: 45511 | E27: ying | F27: Idris | G27: 2.7869 | H27: 2167 | I27: 14238 | O27: =SUBTOTAL(9,I27) -> 14238
C28: 240630000010 | D28: 45511 | E28: 喵喵速运-Layne | F28: WEI PING | G28: 1.6128 | H28: 637 | I28: 3432 | O28: =SUM(I28) -> 3432
C29: 240726000008 | D29: 45506 | E29: Bella Chan | F29: zhong zi xin | G29: 0.835 | H29: 1254 | J29: 1830068.5 | L29: =SUM(J29/M29) -> 1711 | M29: 1069.59 | N29: 7.12 | O29: =SUM(M29*N29) -> 7615.4808 | Y29: 284.87
C30: 240729000013 | D30: 45506 | E30: Isabel Zhu | F30: Halifa Success | G30: 0.3557 | H30: 50 | I30: 801.54 | O30: =SUBTOTAL(9,I30) -> 801.54
C31: 240724000026 | D31: 45506 | E31: Bella Chan | F31: zhong zi xin | G31: 3.0722 | H31: 4949 | J31: 1723658 | L31: =SUM(J31/M31) -> 1711.0136 | M31: 1007.39 | N31: 7.12 | O31: =SUM(M31*N31) -> 7172.6168
C32: 240729000017 | D32: 45506 | E32: Bella Chan | F32: zhang jian fei | G32: 1.1178 | H32: 1055 | J32: 776250 | L32: =SUM(J32/M32) -> 1725 | M32: 450 | N32: 7.12 | O32: =SUM(M32*N32) -> 3204
C33: 240729000020 | D33: 45506 | E33: ying | F33: zhounengquan | G33: 0.0032 | H33: 2.7 | I33: 235.2 | O33: =SUBTOTAL(9,I33) -> 235.2
C34: 240730000010 | D34: 45506 | E34: Isabel Zhu | F34: Halifa Success | G34: 3.0014 | H34: 502 | I34: 6679.5 | O34: =SUBTOTAL(9,I34) -> 6679.5
C35: 240731000018 | D35: 45506 | E35: Sam.Pao | F35: Sampao | G35: 7.4377 | H35: 4500 | M35: 0 | N35: 7.15 | O35: =SUM(M35*N35) -> 0
C36: 240731000038 | D36: 45506 | E36: 喵喵速运-江 | F36: LUZHILONG | G36: 3.6015 | H36: 1074 | I36: 8038.58 | O36: =SUBTOTAL(9,I36) -> 8038.58
C37: 240801000001 | D37: 45506 | E37: Sam.Pao | F37: SKY JET | G37: 32.88 | H37: 4188 | I37: 51584.98 | O37: =SUBTOTAL(9,I37) -> 51584.98
C38: 240728000003 | D38: 45506 | E38: Sam.Pao | F38: Nick Wang | G38: 0.2595 | H38: 100 | I38: 699 | O38: =SUBTOTAL(9,I38) -> 699
C39: 240801000022 | D39: 45506 | E39: Bella Chan | F39: new hope 边鹏飞 | G39: 1.8732 | H39: 1420 | J39: 1129654.4 | L39: =SUM(J39/M39) -> 1739 | M39: 649.6 | N39: 7.06 | O39: =SUM(M39*N39) -> 4586.176
C40: 240802000022 | D40: 45506 | E40: Sam.Pao | F40: ShanShan | G40: 0.02 | H40: 5.5 | I40: 61.48 | O40: =SUBTOTAL(9,I40) -> 61.48
C41: 240802000026 | D41: 45506 | E41: 喵喵速运-江 | F41: LUZHILONG | G41: 0.0391 | H41: 42.5 | I41: 98.57 | O41: =SUBTOTAL(9,I41) -> 98.57
...

Sheet 9月份
A1: 尼日利亚拉各斯（LOS） 应收明细表（海运）
A3: JOB | B3: 集装编号 | C3: 运单编号 | D3: 日期 | E3: 发货人 | F3: 收货人 | G3: 计费体积 | H3: 计费重量 | I3: 应 收 | P3: 总应收 | Q3: 起 运 港 成 本 | V3: 代垫运费 | W3: 起运港成本 合计 | X3: 目的港成本 | AD3: 总支出 | AE3: 利润
I4: 应收RMB | J4: LOS Income(NGN)收到(奈拉) | K4: LOS 收到USD | L4: 美元汇率 dollar currency rate | M4: 应收 到付款USD | N4: 汇率 | O4: 人民币 | Q4: 代理商 | R4: 运费+ 出口报关费 | S4: 提货费 | T4: 装卸费 | U4: 包装费 | X4: 进口报关费 | Y4: 到门配送费 | Z4: 转运费 | AA4: 目的港支出 | AB4: 汇率 | AC4: 人民币 | AD4: 起运港+目的港
A5: JOB090350 | B5: COLL004142 | C5: 240807000019 | D5: 45539 | E5: Sam.Pao | F5: Nick Wang | G5: 55.0796 | H5: 14200 | I5: 26216.12 | J5: 21550555 | L5: =SUM(J5/M5) -> 1560.2607 | M5: 13812.15 | N5: 7.24 | O5: =SUM(M5*N5+I5) -> 126216.09 | P5: =SUM(O5:O17) -> 196493.64 | Q5: 登凯=48459 赛捷=1120 拖车费=1670 杂费=81 过磅费=61 | R5: 51391 | T5: 1450 | U5: 600 | V5: =SUM(235.5+800) -> 1035.5 | W5: =SUM(R5:V17) -> 54716.5 | X5: 10737.46 | Y5: 1858.41 | AA5: =SUM(X5:Z17) -> 12805.3 | AB5: 7.12 | AC5: =SUM(AA5*AB5) -> 91173.736 | AD5: =SUM(W5+AC5) -> 145890.24 | AE5: =SUM(P5-AD5) -> 50603.403
C6: 240827000016 | D6: 45539 | E6: Bella Chan | F6: new hope 边鹏飞 | G6: 0.2537 | H6: 138 | J6: 202127.5 | L6: =SUM(J6/M6) -> 1735 | M6: 116.5 | N6: 7.12 | O6: =SUM(M6*N6) -> 829.48 | V6: 240
C7: 240827000023 | D7: 45539 | E7: Sam.Pao | F7: Adesoye | G7: 3.027 | H7: 2480 | J7: 1916044.9 | L7: =SUM(J7/M7) -> 1745 | M7: 1098.02 | N7: 7.12 | O7: =SUM(M7*N7) -> 7817.9024
C8: 240828000016 | D8: 45539 | E8: 喵喵速运-Layne | F8: SHAEK | G8: 0.1625 | H8: 169 | I8: 1258.39 | O8: =SUBTOTAL(9,I8) -> 1258.39 | Y8: 93.95
C9: 240828000064 | D9: 45539 | E9: Bella Chan | F9: zhong zi xin | G9: 2.368 | H9: 2617 | J9: 2020000 | L9: =SUM(J9/M9) -> 1688.522 | M9: 1196.3125 | N9: 7.23 | O9: =SUM(M9*N9) -> 8649.3394 | Y9: 70.8
C10: 240830000003 | D10: 45539 | E10: Sam.Pao | F10: ERICA | G10: 0.1448 | H10: 20 | I10: 333.6 | O10: =SUBTOTAL(9,I10) -> 333.6 | Y10: 5.9
C11: 240830000027 | D11: 45539 | E11: MailMail速运-演员 | F11: Harvey Wang | G11: 0.866 | H11: 98 | I11: 1871 | O11: =SUBTOTAL(9,I11) -> 1871
C12: 240830000048 | D12: 45539 | E12: dejare James | F12: James | G12: 2.146 | H12: 268 | K12: 640.17 | L12: =SUM(J12/M12) -> 0 | M12: 640.17 | N12: 7.3 | O12: =SUM(M12*N12) -> 4673.241
C13: 240728000003 | D13: 45506 | E13: Sam.Pao | F13: Nick Wang | G13: 0.42 | H13: 160 | I13: 1132 | O13: =SUBTOTAL(9,I13) -> 1132 | Y13: 31.76
C14: 240904000001 | D14: 45539 | E14: Sam.Pao | F14: SKY JET | G14: 19.05 | H14: 2484 | I14: 25671.21 | O14: =SUBTOTAL(9,I14) -> 25671.21
C15: 240904000027 | D15: 45539 | E15: ying | F15: zhounengquan | G15: 0.057 | H15: 22 | J15: 55920 | L15: =SUM(J15/M15) -> 1679.2793 | M15: 33.3 | N15: 7.12 | O15: 237.1 | Y15: 7.02
C16: 240904000002 | D16: 45539 | E16: Sam.Pao | F16: SKY JET | G16: 12.5 | H16: 19 | I16: 16844.63 | O16: =SUBTOTAL(9,I16) -> 16844.63
C17: 240904000021 | D17: 45539 | E17: 陆梓龙 | F17: luk | G17: 0.469 | H17: 105 | I17: 959.66 | O17: =SUBTOTAL(9,I17) -> 959.66
A18: JOB090351 | B18: COLL004143 | C18: 240828000043 | D18: 45539 | E18: 喵喵速运-Layne | F18: ABDUL | G18: 6.8939 | H18: 3722 | J18: 3417687 | L18: =SUM(J18/M18) -> 1690 | M18: 2022.3 | N18: 7.3 | O18: =SUM(M18*N18) -> 14762.79 | P18: =SUM(O18:O28) -> 153607.29 | Q18: 登凯=44776 赛捷=1750 拖车费=2270 杂费=1388 过磅费=65 | R18: 50249 | S18: 116.62 | T18: 1750 | W18: =SUM(R18:V28) -> 52615.62 | X18: 10737.46 | Y18: 91.45 | Z18: 70.8 | AA18: =SUM(X18:Z28) -> 12415.93 | AB18: 7.12 | AC18: =SUM(AA18*AB18) -> 88401.422 | AD18: =SUM(W18+AC18) -> 141017.04 | AE18: =SUM(P18-AD18) -> 12590.247
C19: 240828000069 | D19: 45539 | E19: 陆梓龙 | F19: xiantian | G19: 3.615 | H19: 1442 | I19: 9176.76 | O19: =SUBTOTAL(9,I19) -> 9176.76 | Y19: 100.29
C20: 240819000017 | D20: 45516 | E20: 喵喵速运-Layne | F20: WEI PING | G20: 4.904 | H20: 848 | I20: 10475 | O20: =SUBTOTAL(9,I20) -> 10475
C21: 240902000041 | D21: 45539 | E21: Isabel Zhu | F21: Mr Qiu | G21: 0.5458 | H21: 230 | J21: 436950 | L21: =SUM(J21/M21) -> 1779.04 | M21: 245.60999 | N21: 7.08 | O21: =SUM(M21*N21) -> 1738.9187
C22: 240902000057 | D22: 45539 | E22: 陆梓龙 | F22: WANG | G22: 0.2102 | H22: 74 | I22: 573.06 | O22: =SUBTOTAL(9,I22) -> 573.06
C23: 240903000009 | D23: 45539 | E23: Sam.Pao | F23: MaiKaiNian | G23: 0.2574 | H23: 150 | I23: 630.11 | O23: =SUBTOTAL(9,I23) -> 630.11
C24: 240903000015 | D24: 45539 | E24: Isabel Zhu | F24: Halifa Success | G24: 0.42 | H24: 62 | I24: 959.18 | O24: =SUBTOTAL(9,I24) -> 959.18
C25: 240902000056 | D25: 45547 | E25: 喵喵速运-Layne | F25: Hu Hai Liang | G25: 0.512 | H25: 51 | J25: 289240 | L25: =SUM(J25/M25) -> 1752.9697 | M25: 165 | N25: 7.23 | O25: =SUM(M25*N25) -> 1192.95
C26: 240813000017 | D26: 45539 | E26: Sam.Pao | F26: AiGeLi | G26: 21.51 | H26: 13906 | I26: 59293 | O26: =SUBTOTAL(9,I26) -> 59293 | U26: 500 | Y26: 1415.93
C27: 240828000061 | D27: 45539 | E27: Sam.Pao | F27: JunYue hotel | G27: 2.6171 | H27: 719.5 | I27: 5838 | O27: =SUBTOTAL(9,I27) -> 5838
C28: 240904000002 | D28: 45539 | E28: Sam.Pao | F28: SKY JET | G28: 30.96 | H28: 3682.5 | I28: 48967.52 | O28: =SUBTOTAL(9,I28) -> 48967.52
A29: JOB090364 | B29: COLL004256 | C29: 240726000055 | D29: 45547 | E29: Sam.Pao | F29: ShanShan | G29: 5.09 | H29: 677 | I29: 13067 | O29: =SUBTOTAL(9,I29) -> 13067 | P29: =SUM(O29:O53) -> 158115.17 | Q29: 登凯=41647 赛捷=1280 拖车费=1670 杂费=73 过磅费=68 | R29: 44738 | T29: 1300 | W29: =SUM(R29:V53) -> 46618 | X29: 10737.46 | Y29: 47.2 | AA29: =SUM(X29:Z53) -> 10791.72 | AB29: 7.12 | AC29: =SUM(AA29*AB29) -> 76837.046 | AD29: =SUM(W29+AC29) -> 123455.05 | AE29: =SUM(P29-AD29) -> 34660.122
C30: 240813000017 | D30: 45547 | E30: Sam.Pao | F30: AiGeLi | G30: 2.1368 | H30: 256 | I30: 5889 | O30: =SUBTOTAL(9,I30) -> 5889
C31: 240902000015 | D31: 45547 | E31: ying | F31: Ms PEJU | G31: 3.028 | H31: 338 | I31: 7000 | O31: =SUBTOTAL(9,I31) -> 7000
C32: 240902000056 | D32: 45547 | E32: 喵喵速运-Layne | F32: Hu Hai Liang | G32: 3.078 | H32: 521 | J32: 1738835 | L32: =SUM(J32/M32) -> 1754.4319 | M32: 991.11 | N32: 7.23 | O32: =SUM(M32*N32) -> 7165.7253 | U32: 580
C33: 240904000027 | D33: 45547 | E33: ying | F33: zhounengquan | G33: 0.0074 | H33: 6 | J33: 7260 | L33: =SUM(J33/M33) -> 2261.6822 | M33: 3.21 | N33: 7.12 | O33: 22.9
C34: 240904000032 | D34: 45547 | E34: ying | F34: Bruce | G34: 2.736 | H34: 1216 | I34: 5623 | O34: =SUBTOTAL(9,I34) -> 5623
C35: 240904000040 | D35: 45547 | E35: Isabel Zhu | F35: Victor Nnamdi | G35: 1.449 | H35: 227 | J35: 761250 | L35: =SUM(J35/M35) -> 1751.1952 | M35: 434.70312 | N35: 7.08 | O35: =SUM(M35*N35) -> 3077.6981
C36: 240828000061 | D36: 45539 | E36: Sam.Pao | F36: JunYue hotel | G36: 5.2294 | H36: 555 | I36: 11683.3 | O36: =SUBTOTAL(9,I36) -> 11683.3
C37: 240905000026 | D37: 45547 | E37: 陆梓龙 | F37: xiantian | G37: 6.2 | H37: 4920 | I37: 14483.2 | O37: =SUBTOTAL(9,I37) -> 14483.2
C38: 240905000027 | D38: 45547 | E38: 陆梓龙 | F38: luk | G38: 0.3485 | H38: 70 | I38: 686.93 | O38: =SUBTOTAL(9,I38) -> 686.93
C39: 240905000028 | D39: 45547 | E39: ying | F39: Bruce | G39: 2.499 | H39: 970 | I39: 5265 | O39: =SUBTOTAL(9,I39) -> 5265
C40: 240905000029 | D40: 45547 | E40: ying | F40: zhounengquan | G40: 0.0359 | H40: 12 | J40: 63180 | L40: =SUM(J40/M40) -> 1730.4848 | M40: 36.51 | N40: 7.12 | O40: =SUM(M40*N40) -> 259.9512 | Y40: 7.06
C41: 240905000039 | D41: 45547 | E41: 喵喵速运-Layne | F41: Mr.Wang | G41: 1.0166 | H41: 193 | J41: 466616 | L41: =SUM(J41/M41) -> 1700 | M41: 274.48 | N41: 7.27 | O41: =SUM(M41*N41) -> 1995.4696
...

Sheet 10月份
A1: 尼日利亚拉各斯（LOS） 应收明细表（海运）
A3: JOB | B3: 集装编号 | C3: 运单编号 | D3: 日期 | E3: 发货人 | F3: 收货人 | G3: 计费体积 | H3: 计费重量 | I3: 应 收 | P3: 总应收 | Q3: 起 运 港 成 本 | V3: 代垫运费 | W3: 起运港成本 合计 | X3: 目的港成本 | AD3: 总支出 | AE3: 利润
I4: 应收RMB | J4: LOS Income(NGN)收到(奈拉) | K4: LOS 收到USD | L4: 美元汇率 dollar currency rate | M4: 应收 到付款USD | N4: 汇率 | O4: 人民币 | Q4: 代理商 | R4: 运费+ 出口报关费 | S4: 提货费 | T4: 装卸费 | U4: 包装费 | X4: 进口报关费 | Y4: 到门配送费 | Z4: 转运费 | AA4: 目的港支出 | AB4: 汇率 | AC4: 人民币 | AD4: 起运港+目的港
A5: JOB100326 | B5: COLL004189 | C5: 240613000018 | D5: 45532 | E5: Sam.Pao | F5: ChenGaoHong | G5: 21.6755 | H5: 6691 | I5: 46755 | O5: =SUBTOTAL(9,I5) -> 46755 | P5: =SUM(O5:O29) -> 179091.83 | Q5: 登凯=48262.5 赛捷=2800 拖车费=1670 杂费=61 过磅费=63 | R5: 52856.5 | T5: 1500 | U5: 420 | W5: =SUM(R5:V29) -> 55076.5 | X5: 10737.46 | Z5: =SUM(176.99+70.8) -> 247.79 | AA5: =SUM(X5:Z29) -> 11108.92 | AB5: 7.12 | AC5: =SUM(AA5*AB5) -> 79095.51 | AD5: =SUM(W5+AC5) -> 134172.01 | AE5: =SUM(P5-AD5) -> 44919.816
C6: 240816000038 | D6: 45532 | E6: Isabel Zhu | F6: Nicolas | G6: 0.1557 | H6: 40.2 | I6: 602 | O6: =SUM(I6) -> 602 | Y6: 21.12
C7: 240818000042 | D7: 45532 | E7: ying | F7: zhounengquan | G7: 0.0276 | H7: 60 | J7: 120050 | L7: =SUM(J7/M7) -> 1800.66 | M7: 66.67 | N7: 7.12 | O7: =SUM(M7*N7) -> 474.6904 | Y7: 35.4
C8: 240819000004 | D8: 45532 | E8: Bella Chan | F8: FENG | G8: 0.0982 | H8: 59 | I8: 212 | O8: =SUBTOTAL(9,I8) -> 212
C9: 240819000033 | D9: 45532 | E9: 喵喵速运-Layne | F9: Candice Ding | G9: 0.2086 | H9: 344 | J9: 383195 | L9: =SUM(J9/M9) -> 1811.7967 | M9: 211.5 | N9: 7.3 | O9: =SUM(M9*N9) -> 1543.95 | Y9: 46.5
C10: 240820000001 | D10: 45532 | E10: Isabel Zhu | F10: Mr Michael | G10: 7.0865 | H10: 599 | I10: 17258.7 | O10: =SUBTOTAL(9,I10) -> 17258.7 | U10: 300
C11: 240823000021 | D11: 45532 | E11: 喵喵速运-Layne | F11: FRANK | G11: 7.4589 | H11: 3300 | J11: 3229875 | L11: =SUM(J11/M11) -> 1650 | M11: 1957.5 | N11: 7.12 | O11: =SUM(M11*N11) -> 13937.4
C12: 240826000011 | D12: 45532 | E12: Shirley | F12: Yusky | G12: 6.3305 | H12: 880 | I12: 10555.28 | O12: =SUBTOTAL(9,I12) -> 10555.28
C13: 240826000013 | D13: 45532 | E13: Shirley | F13: Yusky | G13: 0.699 | H13: 105 | I13: 1165.58 | O13: =SUBTOTAL(9,I13) -> 1165.58
C14: 240826000015 | D14: 45532 | E14: Shirley | F14: Yusky | G14: 0.2907 | H14: 36 | I14: 483.58 | O14: =SUBTOTAL(9,I14) -> 483.58
C15: 240826000016 | D15: 45532 | E15: Shirley | F15: Yusky | G15: 0.5572 | H15: 42 | I15: 928.8 | O15: =SUBTOTAL(9,I15) -> 928.8
C16: 240826000017 | D16: 45532 | E16: Shirley | F16: Yusky | G16: 0.1598 | H16: 78 | I16: 266.44 | O16: =SUBTOTAL(9,I16) -> 266.44
C17: 240826000018 | D17: 45532 | E17: Shirley | F17: Yusky | G17: 0.141 | H17: 37 | I17: 235.26 | O17: =SUBTOTAL(9,I17) -> 235.26
C18: 240826000019 | D18: 45532 | E18: Shirley | F18: Yusky | G18: 1.4354 | H18: 186 | I18: 2392.86 | O18: =SUBTOTAL(9,I18) -> 2392.86
C19: 240826000039 | D19: 45532 | E19: Isabel Zhu | F19: Lin Bao Zhen | G19: 1.823 | H19: 321 | J19: 964731.6 | L19: =SUM(J19/M19) -> 1764.005 | M19: 546.89844 | N19: 7.23 | O19: =SUM(M19*N19) -> 3954.0757
C20: 240826000045 | D20: 45532 | E20: ying | F20: Nura | G20: 0.4085 | H20: 179 | I20: 904 | O20: =SUBTOTAL(9,I20) -> 904
C21: 240827000034 | D21: 45532 | E21: 陆梓龙 | F21: jizong | G21: 9.2 | H21: 7350 | I21: 24057.26 | O21: =SUBTOTAL(9,I21) -> 24057.26
C22: 240807000019 | D22: 45506 | E22: Sam.Pao | F22: Nick Wang | G22: 7.5437 | H22: 1504 | I22: 17283 | O22: =SUBTOTAL(9,I22) -> 17283
C23: 240728000003 | D23: 45506 | E23: Sam.Pao | F23: Nick Wang | G23: 0.193 | H23: 47 | I23: 520 | O23: =SUBTOTAL(9,I23) -> 520
C24: 240828000002 | D24: 45532 | E24: Sam.Pao | F24: SKY JET | G24: 17.63 | H24: 2193 | I24: 25894.59 | O24: =SUBTOTAL(9,I24) -> 25894.59
C25: 240828000003 | D25: 45532 | E25: Shirley | F25: Yusky | G25: 0.807 | H25: 46 | I25: 1345.67 | O25: =SUBTOTAL(9,I25) -> 1345.67
C26: 240828000005 | D26: 45532 | E26: Shirley | F26: Yusky | G26: 0.6964 | H26: 42 | I26: 1161.45 | O26: =SUBTOTAL(9,I26) -> 1161.45
C27: 240828000008 | D27: 45532 | E27: Shirley | F27: Yusky | G27: 0.0844 | H27: 25 | I27: 140.94 | O27: =SUBTOTAL(9,I27) -> 140.94
C28: 240828000017 | D28: 45532 | E28: 喵喵速运-Layne | F28: Sule Adekunle | G28: 0.1138 | H28: 45 | I28: 421 | O28: =SUM(I28) -> 421 | Y28: 20.65
C29: 240828000062 | D29: 45532 | E29: Shirley | F29: Yusky | G29: 1.8606 | H29: 279 | I29: 6598.3 | O29: =SUBTOTAL(9,I29) -> 6598.3
A30: JOB100351 | B30: COLL004217 | C30: 241015000029 | D30: 45547 | E30: Bella Chan | F30: Yang Bo | G30: 181.1178 | H30: 72959.88 | I30: 257973.5 | J30: 60800000 | K30: 到付 | L30: =SUM(J30/M30) -> 1770.0001 | M30: 34350.28 | N30: 7.12 | O30: =SUM(M30*N30)+I30 -> 502547.49 | P30: =SUM(O30) -> 502547.49 | Q30: 鼎程=245686.66 鼎程出口=750 | R30: 246436.66 | W30: =SUM(R30:V30) -> 246436.66 | X30: 31498.56 | AA30: =SUM(X30:Z30) -> 31498.56 | AB30: 7.12 | AC30: =SUM(AA30*AB30) -> 224269.75 | AD30: =SUM(W30+AC30) -> 470706.41 | AE30: =SUM(P30-AD30) -> 31841.086
A31: JOB100358 | B31: COLL004182 | C31: 240907000011 | D31: 45563 | E31: 喵喵速运-Layne | F31: MA ZONG | G31: 0.4074 | H31: 404 | I31: 1549.3 | O31: =SUBTOTAL(9,I31) -> 1549.3 | P31: =SUM(O31:O51) -> 163992.94 | Q31: 登凯=36617 赛捷=1660 拖车费=1670 杂费=499 过磅费=69 | R31: 40515 | T31: 2200 | W31: =SUM(R31:V51) -> 42775 | X31: 10381.23 | Y31: 48.54 | AA31: =SUM(X31:Z51) -> 10856.01 | AB31: 7.23 | AC31: =SUM(AA31*AB31) -> 78488.952 | AD31: =SUM(W31+AC31) -> 121263.95 | AE31: =SUM(P31-AD31) -> 42728.987
C32: 240909000011 | D32: 45563 | E32: ying | F32: ying | G32: 0.036 | H32: 12 | J32: 87324 | L32: =SUM(J32/M32) -> 5916.2594 | M32: 14.760002 | N32: 7.24 | O32: =SUM(M32*N32) -> 106.86241 | Y32: 0.54
C33: 240915000027 | D33: 45563 | E33: 喵喵速运-Layne | F33: Gao Hui | G33: 0.554 | H33: 177 | I33: 1986.97 | O33: =SUM(I33) -> 1986.97 | U33: 60 | Z33: 83.97
C34: 240919000042 | D34: 45563 | E34: ying | F34: MISS Huang | G34: 0.2211 | H34: 118 | I34: 468.7 | O34: =SUBTOTAL(9,I34) -> 468.7
C35: 240920000027 | D35: 45563 | E35: 喵喵速运-Layne | F35: YA | G35: 1.1252 | H35: 111 | I35: 3500.8 | O35: =SUBTOTAL(9,I35) -> 3500.8 | Y35: 8.31 | Z35: 117.69
C36: 240920000030 | D36: 45563 | E36: ying | F36: baikaibo | G36: 0.319 | H36: 321 | J36: 385317 | L36: =SUM(J36/M36) -> 1767.347 | M36: 218.02 | N36: 7.24 | O36: =SUM(M36*N36) -> 1578.4648 | Y36: 85.03
C37: 240923000009 | D37: 45563 | E37: Isabel Zhu | F37: Wu Jiao Xing | G37: 0.5281 | H37: 104.5 | J37: 313621.07 | L37: =SUM(J37/M37) -> 1855.8559 | M37: 168.98999 | N37: 7.26 | O37: =SUM(M37*N37) -> 1226.8673
C38: 240923000035 | D38: 45547 | E38: ying | F38: Bruce | G38: 1.0584 | H38: 465 | I38: 2082 | O38: =SUBTOTAL(9,I38) -> 2082
C39: 240923000047 | D39: 45563 | E39: 喵喵速运-Layne | F39: WYLB | G39: 0.8 | H39: 197 | J39: 390880 | L39: =SUM(J39/M39) -> 1744.9998 | M39: 224.00003 | N39: 7.21 | O39: =SUM(M39*N39) -> 1615.0402
C40: 240924000001 | D40: 45563 | E40: Sam.Pao | F40: Yusky | G40: 8.51 | H40: 209 | I40: 14859.77 | O40: =SUBTOTAL(9,I40) -> 14859.77
C41: 240925000028 | D41: 45563 | E41: Isabel Zhu | F41: Halifa Success | G41: 1.2354 | H41: 125 | I41: 2382.35 | O41: =SUBTOTAL(9,I41) -> 2382.35
...

Sheet 11月份
A1: 尼日利亚拉各斯（LOS） 应收明细表（海运）
A3: JOB | B3: 集装编号 | C3: 运单编号 | D3: 日期 | E3: 发货人 | F3: 收货人 | G3: 计费体积 | H3: 计费重量 | I3: 应 收 | P3: 总应收 | Q3: 起 运 港 成 本 | V3: 代垫运费 | W3: 起运港成本 合计 | X3: 目的港成本 | AD3: 总支出 | AE3: 利润
I4: 应收RMB | J4: LOS Income(NGN)收到(奈拉) | K4: LOS 收到USD | L4: 美元汇率 dollar currency rate | M4: 应收 到付款USD | N4: 汇率 | O4: 人民币 | Q4: 代理商 | R4: 运费+ 出口报关费 | S4: 提货费 | T4: 装卸费 | U4: 包装费 | X4: 进口报关费 | Y4: 到门配送费 | Z4: 转运费 | AA4: 目的港支出 | AB4: 汇率 | AC4: 人民币 | AD4: 起运港+目的港
A5: JOB110331 | B5: COLL004224 | C5: 241018000035 | D5: 45551 | E5: Sam.Pao | F5: ShanShan | G5: 68 | H5: 16880.28 | I5: 51892 | J5: 21300000 | K5: 到付 | L5: =SUM(J5/M5) -> 1745.0005 | M5: 12206.3 | N5: 7.12 | O5: =SUM(M5*N5)+I5 -> 138800.86 | P5: =SUM(O5) -> 138800.86 | Q5: 登凯=41647 陆总=2000 拖车费=1670 杂费=101 过磅费=58 | R5: 45476 | W5: =SUM(R5:V5) -> 45476 | X5: 10888.25 | AA5: =SUM(X5:Z5) -> 10888.25 | AB5: 7.12 | AC5: =SUM(AA5*AB5) -> 77524.34 | AD5: =SUM(W5+AC5) -> 123000.34 | AE5: =SUM(P5-AD5) -> 15800.516
A6: 合 计 | G6: =SUM(G5) -> 68 | H6: =SUM(H5) -> 16880.28 | I6: =SUM(I5) -> 51892 | J6: =SUM(J5) -> 21300000 | K6: =SUM(K5) -> 0 | L6: =SUM(L5) -> 1745.0005 | M6: =SUM(M5) -> 12206.3 | N6: =SUM(N5) -> 7.12 | ... P6: =SUM(P5) -> 138800.86 | Q6: =SUM(#REF!) -> #REF! | R6: =SUM(R5) -> 45476 | S6: =SUM(S5) -> 0 | T6: =SUM(T5) -> 0 | W6: =SUM(W5) -> 45476 | X6: =SUM(X5) -> 10888.25 | AA6: =SUM(AA5) -> 10888.25 | AB6: =SUM(AB5) -> 7.12 | AC6: =SUM(AC5) -> 77524.34 | AD6: =SUM(AD5) -> 123000.34 | AE6: =SUM(AE5) -> 15800.516
G8: 月份 | H8: 到付 (USD) | I8: 目的港成本合计 | J8: 应收到付款 （USD） | K8: 汇率 | L8: 应收 LOS到付款(人民币)
G9: 11 | H9: =SUM(M6) -> 12206.3 | I9: =SUM(AA6) -> 10888.25 | J9: =SUM(H9-I9) -> 1318.05 | K9: 7.12 | L9: =SUM(J9*K9) -> 9384.516
G11: 月份 | H11: 应 收 | L11: 总应收 | M11: 起运港 成本合计 | N11: 目的港 成本合计 | O11: 利润
H12: 应收RMB | I12: LOS已收款 (USD) | J12: 汇率 | K12: LOS已收 （RMB）
G13: 11 | H13: =SUM(I6) -> 51892 | I13: =SUM(M6) -> 12206.3 | J13: 7.12 | K13: =SUM(I13*J13) -> 86908.856 | L13: =SUM(H13+K13) -> 138800.86 | M13: =SUM(W6) -> 45476 | N13: =SUM(AC6) -> 77524.34 | O13: =SUM(L13-M13-N13) -> 15800.516

Sheet 12月份
A1: 尼日利亚拉各斯（LOS） 应收明细表（海运）
A3: JOB | B3: 集装编号 | C3: 运单编号 | D3: 日期 | E3: 发货人 | F3: 收货人 | G3: 计费体积 | H3: 计费重量 | I3: 应 收 | P3: 总应收 | Q3: 起 运 港 成 本 | V3: 代垫运费 | W3: 起运港成本 合计 | X3: 目的港成本 | AD3: 总支出 | AE3: 利润
I4: 应收RMB | J4: LOS Income(NGN)收到(奈拉) | K4: LOS 收到USD | L4: 美元汇率 dollar currency rate | M4: 应收 到付款USD | N4: 汇率 | O4: 人民币 | Q4: 代理商 | R4: 运费+出口报关费 | S4: 提货费 | T4: 装卸费 | U4: 包装费 | X4: 进口报关费 | Y4: 到门配送费 | Z4: 转运费 | AA4: 目的港支出 | AB4: 汇率 | AC4: 人民币 | AD4: 起运港+目的港
A5: JOB120359 | B5: COLL004280 | C5: 241120000026 | D5: 45592 | E5: Sam.Pao | F5: ShanShan | G5: 68 | I5: 50836 | J5: 21300000 | L5: =SUM(J5/M5) -> 1669.0004 | M5: 12762.13 | N5: 7.3 | O5: =SUM(M5*N5+I5) -> 143999.55 | P5: =SUM(O5) -> 143999.55 | Q5: 登凯=44060 陆总=2500 拖车费=1670 杂费=101 过磅费=68 | R5: 48399 | W5: =SUM(R5:V5) -> 48399 | X5: 11545.4 | AA5: =SUM(X5:Z5) -> 11545.4 | AB5: 7.27 | AC5: =SUM(AA5*AB5) -> 83935.058 | AD5: =SUM(W5+AC5) -> 132334.06 | AE5: =SUM(P5-AD5) -> 11665.491
A6: JOB120361 | B6: COLL004287 | C6: 240910000015 | D6: 45601 | E6: 喵喵速运-Layne | F6: Hu Hai Liang | G6: 5.1959 | H6: 743 | J6: 2382640 | L6: =SUM(J6/M6) -> 1580 | M6: 1508 | N6: 7.29 | O6: =SUM(M6*N6) -> 10993.32 | P6: =SUM(O6:O22) -> 165324.28 | Q6: 登凯=46189.5 陆总=1200 拖车费=1670 杂费=89 过磅费=66 | R6: 49214.5 | S6: =SUM(56.82+56.82) -> 113.64 | T6: 2400 | W6: =SUM(R6:V22) -> 52097.14 | X6: 10949.72 | AA6: =SUM(X6:Z22) -> 11256.42 | AB6: 7.33 | AC6: =SUM(AA6*AB6) -> 82509.559 | AD6: =SUM(W6+AC6) -> 134606.7 | AE6: =SUM(P6-AD6) -> 30717.58
C7: 241023000029 | D7: 45601 | E7: ying | F7: Wole Rasak | G7: 0.0288 | H7: 5 | I7: 224.75 | O7: =SUBTOTAL(9,I7) -> 224.75
C8: 241025000058 | D8: 45601 | E8: KAY | F8: BOYOU 吕 | G8: 13.7 | H8: 2550 | J8: 7067746.5 | L8: =SUM(J8/M8) -> 1648.8039 | M8: 4286.59 | N8: 7.29 | O8: =SUM(M8*N8) -> 31249.241 | Y8: 90.97
C9: 241026000006 | D9: 45601 | E9: 喵喵速运-Layne | F9: LEO WEI | G9: 0.6549 | H9: 72 | J9: 363730 | L9: =SUM(J9/M9) -> 1683.0002 | M9: 216.12 | N9: 7.3 | O9: =SUM(M9*N9) -> 1577.676
C10: 241027000011 | D10: 45601 | E10: Isabel Zhu | F10: Maryam Tukur | G10: 0.5618 | H10: 55 | J10: 434000 | L10: =SUM(J10/M10) -> 1671.8028 | M10: 259.6 | N10: 7.3 | O10: =SUM(M10*N10) -> 1895.08 | U10: 310 | V10: 59
C11: 241031000033 | D11: 45601 | E11: ying | F11: Bruce | G11: 1.9968 | H11: 845 | J11: 960734 | L11: =SUM(J11/M11) -> 1653.0179 | M11: 581.2 | N11: 7.29 | O11: =SUM(M11*N11) -> 4236.948
C12: 241028000022 | D12: 45601 | E12: ying | F12: Barrister Hammed | G12: 1.211 | H12: 331 | I12: 2690 | O12: =SUBTOTAL(9,I12) -> 2690
C13: 241028000025 | D13: 45601 | E13: 喵喵速运-Layne | F13: Candice Ding | G13: 0.7015 | H13: 168 | J13: 432424.8 | L13: =SUM(J13/M13) -> 1710 | M13: 252.88 | N13: 7.3 | O13: =SUM(M13*N13) -> 1846.024 | Y13: 42.43
C14: 241028000036 | D14: 45601 | E14: Sam.Pao | F14: Chizoba | G14: 19.1974 | H14: 2413 | I14: 38000 | O14: =SUBTOTAL(9,I14) -> 38000
C15: 241028000057 | D15: 45601 | E15: Isabel Zhu | F15: Halifa Success | G15: 0.8721 | H15: 153 | I15: 1785.59 | O15: =SUBTOTAL(9,I15) -> 1785.59
C16: 241029000017 | D16: 45601 | E16: ying | F16: jiangnan | G16: 0.2948 | H16: 65 | I16: 683.5 | O16: =SUBTOTAL(9,I16) -> 683.5
C17: 241030000002 | D17: 45601 | E17: 喵喵速运-Layne | F17: Mu Shi Shi | G17: 7.4945 | H17: 520 | I17: 18324.8 | O17: =SUBTOTAL(9,I17) -> 18324.8 | Y17: 47.85
C18: 241030000039 | D18: 45601 | E18: ying | F18: jiangnan | G18: 1.069 | H18: 138 | I18: 2506 | O18: =SUBTOTAL(9,I18) -> 2506
C19: 241030000041 | D19: 45601 | E19: 喵喵速运-Layne | F19: WEI PING | G19: 1.5338 | H19: 336 | J19: 755361 | L19: =SUM(J19/M19) -> 1700 | M19: 444.33 | N19: 7.27 | O19: =SUM(M19*N19) -> 3230.2791 | Y19: 29.9
C20: 241101000029 | D20: 45601 | E20: 喵喵速运-Layne | F20: YA | G20: 0.8656 | H20: 346 | I20: 2978.64 | O20: =SUM(I20) -> 2978.64 | Y20: 12.36 | Z20: 83.19
C21: 241101000033 | D21: 45601 | E21: Isabel Zhu | F21: Halifa Success | G21: 0.8844 | H21: 155 | I21: 1806.11 | O21: =SUBTOTAL(9,I21) -> 1806.11
C22: 241209000060 | D22: 45601 | E22: 陆梓龙 | F22: xinlong | G22: 17.902 | H22: 17472 | I22: 41296.32 | O22: =SUBTOTAL(9,I22) -> 41296.32
A23: JOB120362 | B23: COLL004290 | C23: 241028000047 | D23: 45602 | E23: Sam.Pao | F23: Nick Wang | G23: 3.0981 | H23: 231 | I23: 8037.16 | O23: =SUBTOTAL(9,I23) -> 8037.16 | P23: =SUM(O23:O36) -> 134933.06 | Q23: 登凯=46189.5 陆总=800 拖车费=1670 杂费=61 过磅费=68 | R23: 48788.5 | T23: 1800 | W23: =SUM(R23:V36) -> 50588.5 | X23: 10716.46 | Z23: 50.64 | AA23: =SUM(X23:Z36) -> 10831.69 | AB23: 7.33 | AC23: =SUM(AA23*AB23) -> 79396.288 | AD23: =SUM(W23+AC23) -> 129984.79 | AE23: =SUM(P23-AD23) -> 4948.2733
C24: 241029000048 | D24: 45602 | E24: ying | F24: Sunday Adelena | G24: 0.4438 | H24: 310 | I24: 964.05 | O24: =SUBTOTAL(9,I24) -> 964.05
C25: 241030000021 | D25: 45602 | E25: 喵喵速运-Layne | F25: MA ZONG | G25: 0.6626 | H25: 405 | I25: 1624.5 | O25: =SUBTOTAL(9,I25) -> 1624.5 | Y25: 35.38
C26: 241030000025 | D26: 45602 | E26: ying | F26: Nura | G26: 0.4092 | H26: 180 | I26: 876.05 | O26: =SUBTOTAL(9,I26) -> 876.05
C27: 241031000033 | D27: 45602 | E27: ying | F27: Bruce | G27: 0.5837 | H27: 247 | J27: 280840 | L27: =SUM(J27/M27) -> 1652.9723 | M27: 169.9 | N27: 7.29 | O27: =SUM(M27*N27) -> 1238.571
C28: 241101000057 | D28: 45602 | E28: 陆梓龙 | F28: jizong | G28: 1.1063 | H28: 567 | I28: 2422.8 | O28: =SUBTOTAL(9,I28) -> 2422.8
C29: 241104000038 | D29: 45602 | E29: ying | F29: Sunday Adelena | G29: 0.0737 | H29: 26 | I29: 214.23 | O29: =SUBTOTAL(9,I29) -> 214.23
C30: 241022000035 | D30: 45602 | E30: Bella Chan | F30: zhong zi xin | G30: 27.424 | H30: 19896 | I30: 60720 | O30: =SUBTOTAL(9,I30) -> 60720
C31: 241105000034 | D31: 45602 | E31: Isabel Zhu | F31: Joy | G31: 0.7455 | H31: 854 | J31: 641427.2 | L31: =SUM(J31/M31) -> 1643 | M31: 390.4 | N31: 7.3 | O31: =SUM(M31*N31) -> 2849.92 | Y31: 29.21
C32: 241106000001 | D32: 45602 | E32: Sam.Pao | F32: MaiKaiNian | G32: 0.4542 | H32: 69 | I32: 1060.98 | O32: =SUBTOTAL(9,I32) -> 1060.98
C33: 241106000002 | D33: 45602 | E33: Sam.Pao | F33: Angel | G33: 0.3458 | H33: 98 | I33: 757 | O33: =SUBTOTAL(9,I33) -> 757
C34: 241106000018 | D34: 45602 | E34: Bella Chan | F34: zhang long ting | G34: 0.0019 | H34: 1 | J34: 51150 | L34: =SUM(J34/M34) -> 1650 | M34: 31 | N34: 7.2 | O34: =SUM(M34*N34) -> 223.2
C35: 241106000037 | D35: 45602 | E35: Sam.Pao | F35: JunYue hotel | G35: 0.6996 | H35: 76 | I35: 1583.01 | O35: =SUBTOTAL(9,I35) -> 1583.01
C36: 241107000022 | D36: 45602 | E36: Shirley | F36: SKY JET | G36: 32.635 | H36: 4165 | I36: 52361.59 | O36: =SUBTOTAL(9,I36) -> 52361.59
A37: JOB120363 | B37: COLL004291 | C37: 240930000009 | D37: 45608 | E37: ying | F37: Tom chen | G37: 0.0977 | H37: 28.5 | J37: 132820 | L37: =SUM(J37/M37) -> 1648.9137 | M37: 80.55 | N37: 7.3 | O37: =SUM(M37*N37) -> 588.015 | P37: =SUM(O37:O58) -> 188664.54 | Q37: 登凯=43330 陆总=8000 拖车费=1670 杂费=93 过磅费=125 | R37: 53218 | T37: 1955 | W37: =SUM(R37:V58) -> 55823 | X37: 11360.84 | Y37: 11.38 | Z37: 53.34 | AA37: =SUM(X37:Z58) -> 12551.34 | AB37: 7.3 | AC37: =SUM(AA37*AB37) -> 91624.782 | AD37: =SUM(W37+AC37) -> 147447.78 | AE37: =SUM(P37-AD37) -> 41216.755
C38: 241015000034 | D38: 45608 | E38: Isabel Zhu | F38: Halifa Success | G38: 4.77 | H38: 451 | I38: 9789.95 | O38: =SUBTOTAL(9,I38) -> 9789.95
C39: 241021000005 | D39: 45608 | E39: 喵喵速运-Layne | F39: Hu Hai Liang | G39: 1.1795 | H39: 335 | J39: 583853 | L39: =SUM(J39/M39) -> 1650.0015 | M39: 353.84998 | N39: 7.3 | O39: =SUM(M39*N39) -> 2583.1049
C40: 241022000035 | D40: 45608 | E40: Bella Chan | F40: zhong zi xin | G40: 28.3553 | H40: 15100 | I40: 62780 | O40: =SUBTOTAL(9,I40) -> 62780 | U40: 300 | Y40: =SUM(413.88+371.27) -> 785.15
C41: 241024000054 | D41: 45608 | E41: Sam.Pao | F41: ShanShan | G41: 16.835 | H41: 7500 | I41: 48779 | O41: =SUBTOTAL(9,I41) -> 48779 | Y41: 97.38
...

Sheet 应收统计表
A1: 2024年6-12月份海运应收LOS统计表(Statistical tables receivable)
A2: 月份 month | B2: 到付金额 Amount paid | C2: 目的港成本 Port of destination cost | D2: 应收到付款（USD） Payment due | E2: 汇率 exchange rate | F2: 应收到付款 Payment due (RMB) | G2: 实收（LOS）拉各斯金额 Collection(LOS) Lagos amount | H2: 欠款金额 Amount owed | I2: 备注 remarks
A3: 上月余额 | H3: 0
A4: 45473 | B4: =SUM('6月份'!M30) -> 2923.6198 | C4: =SUM('6月份'!AA30) -> 11011.24 | D4: =SUM(B4-C4) -> -8087.6202 | E4: 7.12 | F4: =SUM(D4*E4) -> -57583.856 | H4: =SUM(H3+F4-G4) -> -57583.856
A5: 45504 | B5: =SUM('7月份'!M70) -> 9966.9906 | C5: =SUM('7月份'!AA70) -> 53789.19 | D5: =SUM(B5-C5) -> -43822.199 | E5: 8.1160773 | F5: =SUM(D5*E5) -> -355664.36 | H5: =SUM(H4+F5-G5) -> -413248.21
A6: 45535 | B6: =SUM('8月份'!M115) -> 38626.596 | C6: =SUM('8月份'!AA115) -> 88314.16 | D6: =SUM(B6-C6) -> -49687.564 | E6: 7.1301013 | F6: =SUM(D6*E6) -> -354277.37 | H6: =SUM(H5+F6-G6) -> -767525.58
A7: 45930 | B7: =SUM('9月份'!M106) -> 54126.621 | C7: =SUM('9月份'!AA106) -> 86219.44 | D7: =SUM(B7-C7) -> -32092.819 | E7: 7.16861 | F7: =SUM(D7*E7) -> -230060.9 | H7: =SUM(H6+F7-G7) -> -997586.48
A8: 45961 | B8: =SUM('10月份'!M202) -> 80141.838 | C8: =SUM('10月份'!AA202) -> 152383.16 | D8: =SUM(B8-C8) -> -72241.322 | E8: 7.203337 | F8: =SUM(D8*E8) -> -520378.58 | H8: =SUM(H7+F8-G8) -> -1517965.1
A9: 45991 | B9: =SUM('11月份'!M6) -> 12206.3 | C9: =SUM('11月份'!AA6) -> 10888.25 | D9: =SUM(B9-C9) -> 1318.05 | E9: 7.12 | F9: =SUM(D9*E9) -> 9384.516 | H9: =SUM(H8+F9-G9) -> -1508580.5
A10: 46022 | B10: =SUM('12月份'!M288) -> 90368.23 | C10: =SUM('12月份'!AA288) -> 203119.41 | D10: =SUM(B10-C10) -> -112751.18 | E10: 7.2693173 | F10: =SUM(D10*E10) -> -819624.1 | H10: =SUM(H9+F10-G10) -> -2328204.6
A11: 合计 | F11: =SUM(F4:F10) -> -2328204.6 | G11: =SUM(G4:G10) -> 0 | H11: =SUM(H3+F11-G11) -> -2328204.6

Sheet 24年6-12月份利润表
A1: 24年6-12月份海运利润分成表
A2: 月份 | B2: 应 收 | F2: 总应收 | G2: 起运港 成本合计 | H2: 目的港 成本合计 | I2: 总支出 | J2: 利润
B3: 应收RMB | C3: LOS已收款 (USD) | D3: 汇率 | E3: LOS已收 （RMB） | I3: 起运港+目的港
A4: 6 | B4: =SUM('6月份'!I30) -> 218631.69 | C4: =SUM('6月份'!M30) -> 2923.6198 | D4: 7.12 | E4: =SUM(C4*D4) -> 20816.173 | F4: =SUM(B4+E4) -> 239447.86 | G4: =SUM('6月份'!W30) -> 118888.2 | H4: =SUM('6月份'!AC30) -> 78394.125 | I4: =SUM(G4:H4) -> 197282.32 | J4: =SUM(F4-I4) -> 42165.538
A5: 7 | B5: =SUM('7月份'!I70) -> 769507.52 | C5: =SUM('7月份'!M70) -> 9966.9906 | D5: 8.1160773 | E5: =SUM(C5*D5) -> 80892.866 | F5: =SUM(B5+E5) -> 850400.39 | G5: =SUM('7月份'!W70) -> 324549.62 | H5: =SUM('7月份'!AC70) -> 383414.76 | I5: =SUM(G5:H5) -> 707964.38 | J5: =SUM(F5-I5) -> 142436.01
A6: 8 | B6: =SUM('8月份'!I115) -> 1199917.2 | C6: =SUM('8月份'!M115) -> 38626.596 | D6: 7.1301013 | E6: =SUM(C6*D6) -> 275411.54 | F6: =SUM(B6+E6) -> 1475328.8 | G6: =SUM('8月份'!W115) -> 559823.56 | H6: =SUM('8月份'!AC115) -> 626139.49 | I6: =SUM(G6:H6) -> 1185963.1 | J6: =SUM(F6-I6) -> 289365.73
A7: 9 | B7: =SUM('9月份'!I106) -> 723931.46 | C7: =SUM('9月份'!M106) -> 54126.621 | D7: 7.16861 | E7: =SUM(C7*D7) -> 388012.64 | F7: =SUM(B7+E7) -> 1111944.1 | G7: =SUM('9月份'!W106) -> 310293.82 | H7: =SUM('9月份'!AC106) -> 615824.71 | I7: =SUM(G7:H7) -> 926118.53 | J7: =SUM(F7-I7) -> 185825.56
A8: 10 | B8: =SUM('10月份'!I202) -> 1576194.1 | C8: =SUM('10月份'!M202) -> 80141.838 | D8: 7.203337 | E8: =SUM(C8*D8) -> 577288.67 | F8: =SUM(B8+E8) -> 2153482.8 | G8: =SUM('10月份'!W202) -> 761230.6 | H8: =SUM('10月份'!AC202) -> 1101621.4 | I8: =SUM(G8:H8) -> 1862852 | J8: =SUM(F8-I8) -> 290630.82
A9: 11 | B9: =SUM('11月份'!I6) -> 51892 | C9: =SUM('11月份'!M6) -> 12206.3 | D9: 7.12 | E9: =SUM(C9*D9) -> 86908.856 | F9: =SUM(B9+E9) -> 138800.86 | G9: =SUM('11月份'!W6) -> 45476 | H9: =SUM('11月份'!AC6) -> 77524.34 | I9: =SUM(G9:H9) -> 123000.34 | J9: =SUM(F9-I9) -> 15800.516
A10: 12 | B10: =SUM('12月份'!I288) -> 2079762.4 | C10: =SUM('12月份'!M288) -> 90368.23 | D10: 7.2693173 | E10: =SUM(C10*D10) -> 656915.34 | F10: =SUM(B10+E10) -> 2736677.7 | G10: =SUM('12月份'!W288) -> 899667.7 | H10: =SUM('12月份'!AC288) -> 1479152.8 | I10: =SUM(G10:H10) -> 2378820.5 | J10: =SUM(F10-I10) -> 357857.18
A11: 合计 | B11: =SUM(B4:B9) -> 4540074 | C11: =SUM(C4:C9) -> 197991.97 | E11: =SUM(E4:E9) -> 1429330.7 | F11: =SUM(F4:F9) -> 5969404.8 | G11: =SUM(G4:G9) -> 2120261.8 | H11: =SUM(H4:H9) -> 2882918.8 | I11: =SUM(I4:I10) -> 7382001.1 | J11: =SUM(J4:J10) -> 1324081.4

Sheet 利润总额
A1: 2024年6-12月份海运毛利总表-立方
A2: 月份 科目 | B2: 6月份 | C2: 7月份 | D2: 8月份 | E2: 9月份 | F2: 10月份 | G2: 11月份 | H2: 12月份 | I2: 合计
A3: 主营营业收入 | B3: =SUM('6月份'!O30) -> 239447.86 | C3: =SUM('7月份'!O70) -> 850400.39 | D3: =SUM('8月份'!O115) -> 1475328.8 | E3: =SUM('9月份'!O106) -> 1111944.4 | F3: =SUM('10月份'!O202) -> 2153482.8 | G3: =SUM('11月份'!P6) -> 138800.86 | H3: =SUM('12月份'!O288) -> 2736677.7 | I3: =SUM(B3:H3) -> 8706082.8
A4: 主营营业成本 | B4: =SUM('6月份'!AD30) -> 197282.32 | C4: =SUM('7月份'!AD70) -> 707964.38 | D4: =SUM('8月份'!AD115) -> 1185963.1 | E4: =SUM('9月份'!AD106) -> 926118.53 | F4: =SUM('10月份'!AD202) -> 1862852 | G4: =SUM('11月份'!AD6) -> 123000.34 | H4: =SUM('12月份'!AD288) -> 2378820.5 | I4: =SUM(B4:H4) -> 7382001.1
A5: 毛利=营业收入-营业成本 | B5: =SUM(B3-B4) -> 42165.538 | C5: =SUM(C3-C4) -> 142436.01 | D5: =SUM(D3-D4) -> 289365.73 | E5: =SUM(E3-E4) -> 185825.89 | F5: =SUM(F3-F4) -> 290630.82 | G5: =SUM(G3-G4) -> 15800.516 | H5: =SUM(H3-H4) -> 357857.18 | I5: =SUM(B5:H5) -> 1324081.7
A6: 主营营业收入 | B6: 239447.86 | C6: 850400.39 | D6: 1654420.6 | E6: 1753117.7 | F6: 1615843 | G6: 1257555.8 | H6: 1335122.3 | I6: =SUM(B6:H6) -> 8705907.7
A7: 毛利率=毛利/营业收入 | B7: =SUM(B5/B6) -> 0.17609486 | C7: =SUM(C5/C6) -> 0.16749287 | D7: =SUM(D5/D6) -> 0.17490457 | E7: =SUM(E5/E6) -> 0.10599739 | F7: =SUM(F5/F6) -> 0.17986328 | G7: =SUM(G5/G6) -> 0.012564465 | H7: =SUM(H5/H6) -> 0.26803325
A9: 2024年6-12月份海运 利润总额=毛利-营业费用
A10: 月份 名称 | B10: 6月份 | C10: 7月份 | D10: 8月份 | E10: 9月份 | F10: 10月份 | G10: 11月份 | H10: 12月份 | I10: 合计
A11: 毛利--立方 | B11: 42165.538 | C11: 142436.01 | D11: 289365.73 | E11: 185825.89 | F11: 290630.82 | G11: 15800.516 | H11: 357857.18 | I11: =SUM(B11:H11) -> 1324081.7
A12: 业务员提成按（68） | B12: 4279.3593 | C12: 29329.537 | D12: 37562.208 | E12: 22988.503 | F12: 29605.378 | G12: 18532.95 | H12: 22873.9 | I12: =SUM(B12:H12) -> 165171.84
A13: 佛山海运仓人员工资及提成 | B13: 17799.44 | C13: 17799.44 | D13: 25832.12 | E13: 22999.44 | F13: 25938.76 | G13: 23799.44 | H13: 24930.32 | I13: =SUM(B13:H13) -> 159098.96
A14: 业务人员公司部分社保费 | B14: =SUM(日常经营汇总!B34:B37) -> 4647.36 | C14: =SUM(日常经营汇总!C34:C37) -> 4776.96 | D14: 4776.96 | E14: 4776.96 | F14: 4776.96 | G14: 4776.96 | H14: 4776.96 | I14: =SUM(B14:H14) -> 33309.12 | J14: =SUM(I14:I15) -> 56051.43
A15: 佛山海运仓人员公司部分社保费 | B15: 1189.89 | C15: 1222.29 | D15: 3592.07 | E15: 3592.07 | F15: 3592.07 | G15: 4776.96 | H15: 4776.96 | I15: =SUM(B15:H15) -> 22742.31
A16: LOS海运仓人员工资 | F16: =SUM(日常经营汇总!B46) -> 1434.4262 | G16: =SUM(日常经营汇总!C46) -> 1428.5714 | H16: =SUM(日常经营汇总!D46) -> 1548.6726 | I16: =SUM(B16:H16) -> 4411.6702
A17: （佛山仓+LOS仓） 房租水电/日常经营费用 | B17: 471465.6 | C17: 111769.51 | D17: 32326.94 | E17: 31406.74 | F17: 311151.9 | G17: 122311.85 | H17: 80591.535 | I17: =SUM(B17:H17) -> 1161024.1
A18: 财务费用 | B18: 3190.5244 | C18: 1862.2804 | D18: 8200.502 | E18: 2965.3617 | F18: 3630.8465 | G18: 3903.076 | H18: 15163.979 | I18: =SUM(B18:H18) -> 38916.57
A19: 营业费用合计 | B19: =SUM(B12:B18) -> 502572.18 | C19: =SUM(C12:C18) -> 166760.02 | D19: =SUM(D12:D18) -> 112290.8 | E19: =SUM(E12:E18) -> 88729.074 | F19: =SUM(F12:F18) -> 380130.34 | G19: =SUM(G12:G18) -> 179529.8 | H19: =SUM(H12:H18) -> 154662.33 | I19: =SUM(I12:I18) -> 1584674.5
A20: 利润总额=毛利-营业费用 | B20: =SUM(B11-B19) -> -460406.64 | C20: =SUM(C11-C19) -> -24324.012 | D20: =SUM(D11-D19) -> 177074.93 | E20: =SUM(E11-E19) -> 97096.819 | F20: =SUM(F11-F19) -> -89499.518 | G20: =SUM(G11-G19) -> -163729.29 | H20: =SUM(H11-H19) -> 203194.86 | I20: =SUM(I11-I19) -> -260592.85

Sheet 日常经营汇总
A1: 2024年6-12月份海运营业费用
A2: 一、24年5-12月海运仓（佛山仓+LOS仓）租赁费及设备等日常经营费用
A3: 月 份 名 称 | B3: 5月份 | C3: 6月份 | D3: 7月份 | E3: 8月份 | F3: 9月份 | G3: 10月份 | H3: 11月份 | I3: 12月份 | J3: 合计
A4: 金额 | B4: 325350.29 | C4: 146115.31 | D4: 111769.51 | E4: 32326.94 | F4: 31406.74 | G4: 311151.9 | H4: 122311.85 | I4: 80591.535 | J4: =SUM(B4:I4) -> 1161024.1
A6: 二、24年6-12月财务费用
A7: 月 份 名 称 | B7: 6月份 | C7: 7月份 | D7: 8月份 | E7: 9月份 | F7: 10月份 | G7: 11月份 | H7: 12月份 | I7: 合计
A8: 金额 | B8: 3190.5244 | C8: 1862.2804 | D8: 8200.502 | E8: 2965.3617 | F8: 3630.8465 | G8: 3903.076 | H8: 15163.979 | I8: =SUM(B8:H8) -> 38916.57
A10: 三、24年6-12月海运业务员提成（按68³）
A11: 月 份 姓 名 | B11: 6月份 | C11: 7月份 | D11: 8月份 | E11: 9月份 | F11: 10月份 | G11: 11月份 | H11: 12月份 | I11: 合计
A12: 陆总 | B12: 904.72164 | C12: 6437.0556 | D12: 9218.3049 | E12: 8757.3454 | F12: 10865.23 | G12: 6335.4168 | I12: =SUM(B12:H12) -> 42518.075
A13: 朱小飞 | B13: 1016.8909 | C13: 1163.9345 | D13: 3953.4459 | E13: 62.229425 | F13: 4571.7208 | G13: 701.66059 | I13: =SUM(B13:H13) -> 11469.882
A14: 陈三凤 | B14: 442.199 | C14: 292.78738 | D14: 2070.0471 | E14: 4853.235 | F14: 165.31583 | G14: 293.62705 | H14: 8575.4677 | I14: =SUM(B14:H14) -> 16692.679
A15: 黄 颖 | B15: 1915.5477 | C15: 21435.76 | D15: 19017.72 | E15: 8331.1365 | F15: 10006.54 | G15: 9937.0319 | H15: 4811.6173 | I15: =SUM(B15:H15) -> 75455.354
A16: 吕沛霖 | D16: 3302.69 | E16: 984.55621 | F16: 3996.5702 | G16: 1265.2139 | H16: 9486.8152 | I16: =SUM(B16:H16) -> 19035.846
A17: 共计 | B17: =SUM(B12:B16) -> 4279.3593 | C17: =SUM(C12:C16) -> 29329.537 | D17: =SUM(D12:D16) -> 37562.208 | E17: =SUM(E12:E16) -> 22988.503 | F17: =SUM(F12:F16) -> 29605.378 | G17: =SUM(G12:G16) -> 18532.95 | H17: =SUM(H12:H16) -> 22873.9 | I17: =SUM(B17:H17) -> 165171.84
A19: 四、24年6-12月海运仓仓管人员工资及提成
A20: 月 份 姓 名 | B20: 6月份 | D20: 7月份 | F20: 8月份 | H20: 9月份 | J20: 10月份 | L20: 11月份 | N20: 12月份 | P20: 年终奖 | Q20: 合计
B21: 工资 | C21: 提成 | D21: 工资 | E21: 提成 | F21: 工资 | G21: 提成 | H21: 工资 | I21: 提成 | J21: 工资 | K21: 提成 | L21: 工资 | M21: 提成 | N21: 工资 | O21: 提成
A22: 罗伟健 | B22: 4448.36 | D22: 4448.36 | F22: 4748.36 | G22: 1706.67 | H22: 4748.36 | I22: 1000 | J22: 4748.36 | K22: 1733.33 | L22: 4748.36 | M22: 1200 | N22: 4731.08 | O22: 1000 | P22: 500 | Q22: =SUM(B22:P22) -> 39761.24
A23: 林志军 | B23: 4449.36 | D23: 4449.36 | F23: 4749.36 | G23: 1707.67 | H23: 4749.36 | I23: 1000 | J23: 4749.36 | K23: 1734.33 | L23: 4749.36 | M23: 1200 | N23: 4732.08 | O23: 1000 | P23: 500 | Q23: =SUM(B23:P23) -> 39770.24
A24: 莫祖勇 | B24: 4450.36 | D24: 4450.36 | F24: 4750.36 | G24: 1708.67 | H24: 4750.36 | I24: 1000 | J24: 4750.36 | K24: 1735.33 | L24: 4750.36 | M24: 1200 | N24: 4733.08 | O24: 1000 | P24: 500 | Q24: =SUM(B24:P24) -> 39779.24
A25: 罗珮文 | B25: 4451.36 | D25: 4451.36 | F25: 4751.36 | G25: 1709.67 | H25: 4751.36 | I25: 1000 | J25: 4751.36 | K25: 1736.33 | L25: 4751.36 | M25: 1200 | N25: 4734.08 | O25: 1000 | P25: 500 | Q25: =SUM(B25:P25) -> 39788.24
A26: 共计 | B26: =SUM(B22:B25) -> 17799.44 | D26: =SUM(D22:D25) -> 17799.44 | F26: =SUM(F22:F25) -> 18999.44 | G26: =SUM(G22:G25) -> 6832.68 | H26: =SUM(H22:H25) -> 18999.44 | I26: =SUM(I22:I25) -> 4000 | J26: =SUM(J22:J25) -> 18999.44 | K26: =SUM(K22:K25) -> 6939.32 | L26: =SUM(L22:L25) -> 18999.44 | M26: =SUM(M22:M25) -> 4800 | ... Q26: =SUM(Q22:Q25) -> 159098.96
G27: =SUM(F26:G26) -> 25832.12 | I27: =SUM(H26:I26) -> 22999.44 | K27: =SUM(J26:K26) -> 25938.76 | M27: =SUM(L26:M26) -> 23799.44 | O27: =SUM(N26:O26) -> 22930.32 | P27: =SUM(P26) -> 2000
A28: 五、24年6-12月海运仓仓管人员公司部分社保费
A29: 月 份 姓 名 | B29: 6月份 | C29: 7月份 | D29: 8月份 | E29: 9月份 | F29: 10月份 | G29: 11月份 | H29: 12月份 | I29: 合计
A30: 罗伟健 | B30: 1189.89 | C30: 1222.29 | D30: 1222.29 | E30: 1222.29 | F30: 1222.29 | G30: 1222.29 | H30: 1222.29 | I30: =SUM(B30:H30) -> 8523.63
A31: 林志军 | D31: 1184.89 | E31: 1184.89 | F31: 1184.89 | G31: 1184.89 | H31: 1184.89 | I31: =SUM(B31:H31) -> 5924.45
A32: 莫祖勇 | D32: 1184.89 | E32: 1184.89 | F32: 1184.89 | G32: 1184.89 | H32: 1184.89 | I32: =SUM(B32:H32) -> 5924.45
A33: 罗珮文 | G33: 1184.89 | H33: 1184.89 | I33: =SUM(B33:H33) -> 2369.78
A34: 黄 颖 | B34: 1189.89 | C34: 1222.29 | D34: 1222.29 | E34: 1222.29 | F34: 1222.29 | G34: 1222.29 | H34: 1222.29 | I34: =SUM(B34:H34) -> 8523.63
A35: 陈三凤 | B35: 1152.49 | C35: 1184.89 | D35: 1184.89 | E35: 1184.89 | F35: 1184.89 | G35: 1184.89 | H35: 1184.89 | I35: =SUM(B35:H35) -> 8261.83
A36: 朱小飞 | B36: 1152.49 | C36: 1184.89 | D36: 1184.89 | E36: 1184.89 | F36: 1184.89 | G36: 1184.89 | H36: 1184.89 | I36: =SUM(B36:H36) -> 8261.83
A37: 吕沛霖 | B37: 1152.49 | C37: 1184.89 | D37: 1184.89 | E37: 1184.89 | F37: 1184.89 | G37: 1184.89 | H37: 1184.89 | I37: =SUM(B37:H37) -> 8261.83
A38: 共计 | B38: =SUM(B30:B37) -> 5837.25 | C38: =SUM(C30:C37) -> 5999.25 | D38: =SUM(D30:D37) -> 8369.03 | E38: =SUM(E30:E37) -> 8369.03 | F38: =SUM(F30:F37) -> 8369.03 | G38: =SUM(G30:G37) -> 9553.92 | H38: =SUM(H30:H37) -> 9553.92 | I38: =SUM(B38:H38) -> 56051.43
A40: 六、2024年10-12月份LOS海运仓员工工资
A41: 月 份 姓 名 | B41: 10月份 | C41: 11月份 | D41: 12月份 | E41: 合计
A42: 莫杜佩奥拉·马利克 | B42: 409.83607 | C42: 408.16327 | D42: 442.47788 | E42: =SUM(B42:D42) -> 1260.4772
A43: 达米洛拉·科拉沃勒 | B43: 368.85246 | C43: 367.34694 | D43: 398.23009 | E43: =SUM(B43:D43) -> 1134.4295
A44: 埃马纽埃尔·加布里埃尔 | B44: 327.86885 | C44: 326.53061 | D44: 353.9823 | E44: =SUM(B44:D44) -> 1008.3818
...

Sheet 经营-明细
A1: 海运仓租赁费及设备等日常经营费用及账务费用
A2: 5月份 | D2: 6月份 | G2: 7月份 | J2: 8月份 | M2: 9月份
A3: 海运仓5月份租赁水电费 | B3: 26390 | D3: 海运仓6月份租赁水电费 | E3: 27107 | G3: 福利费-海运仓零食 | H3: 120 | J3: 24年8月份海运仓租赁费 | K3: 28543 | M3: 福利费-海运仓9月份零食 | N3: 120
A4: 押金:三个月 | B4: 79170 | D4: 海运仓办公费-烟 | E4: 98 | G4: 海运仓库7月份租赁费 | H4: 27994 | J4: 福利-24年月份海运仓零食 | K4: 120 | M4: 海运仓9月份租赁费 | N4: 27280
A5: 海运仓用品-叉车套 | B5: 680 | D5: 海运仓办公费-交通费 | E5: 221.16 | G5: 海运仓购木板/木条费用 | H5: 2980 | J5: 办公费-罗珮文到海仓交通费 | K5: 270 | M5: 海运仓6月份多收租赁费 | N5: 540
A6: 海运仓用品-加货叉加长 | B6: 150 | D6: 海运仓办公费-加油费 | E6: 150 | G6: 海运仓采购仓库用品 | H6: 442.64 | J6: 海运仓库宽带 | K6: 500 | M6: 海运仓托盘40张 | N6: 3400
A7: 办公费-海运仓监控费用 | B7: 5680 | D7: 海运仓办公费-停车费 | E7: 52 | G7: 海运仓采购办公用品 | H7: 2000.88 | J7: 海运仓加装一个摄像头 | K7: 500 | M7: 罗月梅到海运仓打车费用 | N7: 66.74
A8: 海运仓桶押金5*20=100 | B8: 100 | D8: 海运仓办公费-库宽带 | E8: 500 | G8: 海运仓福利-饮料 | H8: 119.8 | J8: 海运仓240807000019吊车费用 | K8: 900 | N8: =SUM(N3:N13) -> 31406.74
A9: 海运仓怡宝桶装水 | B9: 650 | D9: 海运仓库叉车运输费用 | E9: 500 | G9: 柴油平衡重式叉车 | H9: 65300 | J9: 海运仓用品 | K9: 924 | M9: 账务费用
A10: 海运仓调安装加雪种费用 | B10: 1210 | D10: 海运仓防水膜的费用 | E10: 4288 | G10: 叉车7.44方运费 | H10: 12812.19 | J10: 海运仓办公用品 | K10: 352.75 | M10: 银行各项手续费 | N10: 139.5
A11: 海运仓空窗帘费用 | B11: 350 | D11: 海运仓240527000051包装费 | E11: 200 | H11: =SUM(H3:H10) -> 111769.51 | J11: 海运仓领用纸箱 | K11: 217.19 | M11: 信使费 | N11: 3
A12: 海运仓加油费 | B12: 200 | D12: 海运仓库装柜人工JOB060384 | E12: 850 | G12: 账务费用 | K12: =SUM(K3:K12) -> 32326.94 | M12: LOS：增值税/员工工资税费 | N12: 2500.5946
A13: 海运仓叉搬公司用品 | B13: 250 | D13: 海运仓仓库用品 | E13: 516.08 | G13: 对公跨行手续费 | H13: 76.5 | J13: 账务费用 | M13: 公众号转帐手续费 | N13: 322.26714
A14: 海运仓交通费 | B14: 136.69 | D14: 海运仓办公用品 | E14: 408.45 | G14: 余额颤动手续费 | H14: 30 | J14: 对公跨行手续费 | K14: 93 | N14: =SUM(N10:N13) -> 2965.3617
A15: 海运仓办公用品 | B15: 163 | D15: LOS卡车 | E15: 108374.38 | G15: 对公工行证书 | H15: 100 | J15: 余额颤动手续费 | K15: 30
A16: 海运仓网络安装 | B16: 399 | D16: 冷冻柜(LOS采购) | E16: 2850.24 | G16: 证书工本费 | H16: 32.96 | J16: 自助打印回单手续费 | K16: 450
A17: 海运仓装修尾款 | B17: 34846 | E17: =SUM(E3:E16) -> 146115.31 | G17: 喵喵变更信息服务费 | H17: 100 | J17: 信使费 | K17: 3
A18: 海运仓托盘的费用 | B18: 5100 | D18: 账务费用 | G18: 信使费 | H18: 3 | J18: LOS：增值税/员工工资税费 | K18: 7068.89
A19: 海运仓苹果13手机一台 | B19: 4050 | D19: 银行各项手续费 | E19: 111.5 | G19: LOS：增值税/员工工资税费 | H19: 1278.02 | J19: 公众号转帐手续费 | K19: 455.61201
A20: 海运仓采购纸箱 | B20: 1200 | D20: 信使费 | E20: 3 | G20: 公众号转帐手续费 | H20: 241.80039 | J20: 手续费 | K20: 100
A21: 海运仓仓库用品 | B21: 6743.41 | D21: LOS：增值税/员工工资税费 | E21: 2619.81 | H21: =SUM(H13:H20) -> 1862.2804 | K21: =SUM(K14:K20) -> 8200.502
A22: 海运仓采购办公用品 | B22: 3654.91 | D22: 公众号转帐手续费 | E22: 456.21441
A23: 海运仓采购打印机 | B23: 1129 | E23: =SUM(E19:E22) -> 3190.5244
A24: 海运仓采购办公椅子 | B24: 649
A25: 海运仓采购显示器鼠标 | B25: 920.24
A26: 海运仓采购叉车 | B26: 1200 | D26: 10月份 | G26: 11月份 | J26: 12月份
A27: 1.5t 步行式电动搬运车 | B27: 4750 | D27: 海运仓库10月份租赁费 | E27: 27849 | G27: 24年12月份海运仓租赁费 | H27: 27722 | J27: 海运仓库12月份租赁费 | K27: 27289
