Workbook

Sheet 总表 
A1: 2024年12月份LOS毛利表（海运）
A2: JOB | B2: 集装编号 | C2: 利润
A4: JOB120360 | B4: COLL004315 | C4: =SUM('JOB120360'!AF41) -> 24290.936
A40: JOB120375 | B40: COLL004323 | C40: =SUM('JOB120375'!AF18) -> 24315.892
A53: JOB120376 | B53: COLL004324 | C53: =SUM('JOB120376'!AF13) -> -3608.7565
A61: JOB120381 | B61: COLL004325 | C61: =SUM('JOB120381'!AF15) -> 764.62021
A71: JOB120387 | B71: COLL004326 | C71: =SUM('JOB120387'!AF28) -> 20710.74
A94: JOB120390 | B94: COLL004328 | C94: =SUM('JOB120390'!AF12) -> 7182.2738
A101: JOB120399 | B101: COLL004330 | C101: =SUM('JOB120399'!AF36) -> 25144.544
A132: JOB120404 | B132: COLL004342 | C132: =SUM('JOB120404'!AF18) -> 11861.717
A133: JOB120404 | B133: COLL004342
A145: JOB0202178 | B145: COLL004395 | C145: =SUM('JOB0202178'!AF6) -> 4067
A146: 合计 | C146: =SUM(C3:C145) -> 114728.96

Sheet 总表  (2)
A1: 2024年12月份LOS毛利表（海运）
A2: JOB | B2: 集装编号 | C2: 运单编号 | D2: 日期 | E2: 业务 | F2: 发货人 | G2: 收货人 | H2: 计费体积 | I2: 计费重量 | J2: 应 收 | Q2: 总应收 | R2: 起 运 港 成 本 | W2: 代垫运费 | X2: 起运港成本 合计 | Y2: 目的港成本 | AE2: 总支出 | AF2: 利润
J3: 应收RMB | K3: LOS Income(NGN)收到(奈拉) | L3: LOS 收到USD | M3: 美元汇率 dollar currency rate | N3: 应收 到付款USD | O3: 汇率 | P3: 人民币 | R3: 代理商 | S3: 运费+出口报关费 | T3: 提货费 | U3: 装卸费 | V3: 包装费 | Y3: 进口报关费 | Z3: 到门配送费 | AA3: 转运费 | AB3: 目的港支出 | AC3: 汇率 | AD3: 人民币 | AE3: 起运港+目的港
A4: JOB120360 | B4: COLL004315 | C4: 240925000017 | D4: 45631 | E4: 无人 | F4: dejare James | G4: James | H4: 0.1799 | I4: 17 | K4: 84600 | M4: =SUM(K4/N4) -> 1679.5713 | N4: 50.369995 | O4: 7.27 | P4: =SUM(N4*O4) -> 366.18986 | Q4: =SUM(P4:P39) -> 162259.24 | R4: 登凯=43870.25 创泽=1270 拖车费=1670 杂费=84 过磅费=69 | S4: =SUM(46963.25/68)*H4 -> 124.24542 | U4: =SUM(2500/68)*H4 -> 6.6139706 | X4: =SUM(S4:W4) -> 130.85939 | Y4: =SUM(11081/68)*H4 -> 29.315763 | AB4: =SUM(Y4:AA4) -> 29.315763 | AC4: 7.24 | AD4: =SUM(AB4*AC4) -> 212.24613 | AE4: =SUM(X4+AD4) -> 343.10552 | AF4: =SUM(P4-AE4) -> 23.084346
C5: 241118000063 | D5: 45631 | E5: 罗珮文 | F5: Shirley | G5: Yusky | H5: 1.6585 | I5: 270 | K5: 719837.28 | M5: =SUM(K5/N5) -> 1608 | N5: 447.66 | O5: 7.3 | P5: =SUM(N5*O5) -> 3267.918 | S5: =SUM(46963.25/68)*H5 -> 1145.4199 | U5: =SUM(2500/68)*H5 -> 60.974265 | X5: =SUM(S5:W5) -> 1206.3941 | Y5: =SUM(11081/68)*H5 -> 270.26233 | AB5: =SUM(Y5:AA5) -> 270.26233 | AC5: 7.24 | AD5: =SUM(AB5*AC5) -> 1956.6993 | AE5: =SUM(X5+AD5) -> 3163.0934 | AF5: =SUM(P5-AE5) -> 104.8246
C6: 241118000066 | D6: 45631 | E6: 罗珮文 | F6: Shirley | G6: Yusky | H6: 1.2581 | I6: 125 | K6: 546173.28 | M6: =SUM(K6/N6) -> 1608 | N6: 339.66 | O6: 7.3 | P6: =SUM(N6*O6) -> 2479.518 | S6: =SUM(46963.25/68)*H6 -> 868.88919 | U6: =SUM(2500/68)*H6 -> 46.253676 | X6: =SUM(S6:W6) -> 915.14287 | Y6: =SUM(11081/68)*H6 -> 205.0148 | AB6: =SUM(Y6:AA6) -> 205.0148 | AC6: 7.24 | AD6: =SUM(AB6*AC6) -> 1484.3071 | AE6: =SUM(X6+AD6) -> 2399.45 | AF6: =SUM(P6-AE6) -> 80.068015
C7: 241120000012 | D7: 45631 | E7: Bella | F7: Bella Chan | G7: FENG | H7: 0.1878 | I7: 62 | K7: 94651.2 | M7: =SUM(K7/N7) -> 1680.0001 | N7: 56.339996 | O7: 7.3 | P7: =SUM(N7*O7) -> 411.28197 | S7: =SUM(46963.25/68)*H7 -> 129.70145 | U7: =SUM(2500/68)*H7 -> 6.9044118 | X7: =SUM(S7:W7) -> 136.60586 | Y7: =SUM(11081/68)*H7 -> 30.603115 | AB7: =SUM(Y7:AA7) -> 30.603115 | AC7: 7.24 | AD7: =SUM(AB7*AC7) -> 221.56655 | AE7: =SUM(X7+AD7) -> 358.17241 | AF7: =SUM(P7-AE7) -> 53.109562
C8: 241120000023 | D8: 45631 | E8: Sam.Pao | F8: Sam.Pao | G8: Mr. Jiang | H8: 1.3317 | I8: 326 | J8: 4965 | P8: =SUBTOTAL(9,J8) -> 4965 | S8: =SUM(46963.25/68)*H8 -> 919.72 | U8: =SUM(2500/68)*H8 -> 48.959559 | V8: 500 | X8: =SUM(S8:W8) -> 1468.6796 | Y8: =SUM(11081/68)*H8 -> 217.00835 | AB8: =SUM(Y8:AA8) -> 217.00835 | AC8: 7.24 | AD8: =SUM(AB8*AC8) -> 1571.1404 | AE8: =SUM(X8+AD8) -> 3039.82 | AF8: =SUM(P8-AE8) -> 1925.18
C9: 241121000013 | D9: 45631 | E9: Sam.Pao | F9: Sam.Pao | G9: Mr. Jiang | H9: 2.2982 | I9: 612 | J9: 7707 | P9: =SUBTOTAL(9,J9) -> 7707 | S9: =SUM(46963.25/68)*H9 -> 1587.2197 | U9: =SUM(2500/68)*H9 -> 84.492647 | V9: 400 | X9: =SUM(S9:W9) -> 2071.7124 | Y9: =SUM(11081/68)*H9 -> 374.50521 | AB9: =SUM(Y9:AA9) -> 374.50521 | AC9: 7.24 | AD9: =SUM(AB9*AC9) -> 2711.4177 | AE9: =SUM(X9+AD9) -> 4783.1301 | AF9: =SUM(P9-AE9) -> 2923.8699
C10: 241121000018 | D10: 45631 | E10: Sam.Pao | F10: Sam.Pao | G10: Nick Wang | H10: 0.0768 | I10: 14 | J10: 296.22 | P10: =SUBTOTAL(9,J10) -> 296.22 | S10: =SUM(46963.25/68)*H10 -> 53.040847 | U10: =SUM(2500/68)*H10 -> 2.8235294 | X10: =SUM(S10:W10) -> 55.864376 | Y10: =SUM(11081/68)*H10 -> 12.515012 | Z10: 4.51 | AB10: =SUM(Y10:AA10) -> 17.025012 | AC10: 7.24 | AD10: =SUM(AB10*AC10) -> 123.26109 | AE10: =SUM(X10+AD10) -> 179.12546 | AF10: =SUM(P10-AE10) -> 117.09454
C11: 241121000019 | D11: 45631 | E11: Sam.Pao | F11: Sam.Pao | G11: Mr. Jiang | H11: 1.4834 | I11: 471 | J11: 3598 | P11: =SUBTOTAL(9,J11) -> 3598 | S11: =SUM(46963.25/68)*H11 -> 1024.4895 | U11: =SUM(2500/68)*H11 -> 54.536765 | X11: =SUM(S11:W11) -> 1079.0263 | Y11: =SUM(11081/68)*H11 -> 241.72876 | AB11: =SUM(Y11:AA11) -> 241.72876 | AC11: 7.24 | AD11: =SUM(AB11*AC11) -> 1750.1162 | AE11: =SUM(X11+AD11) -> 2829.1424 | AF11: =SUM(P11-AE11) -> 768.85756
C12: 241123000017 | D12: 45631 | E12: 黄颖 | F12: ying | G12: Nura | H12: 0.3608 | I12: 202 | J12: 792 | P12: =SUBTOTAL(9,J12) -> 792 | S12: =SUM(46963.25/68)*H12 -> 249.18148 | U12: =SUM(2500/68)*H12 -> 13.264706 | X12: =SUM(S12:W12) -> 262.44619 | Y12: =SUM(11081/68)*H12 -> 58.794482 | AB12: =SUM(Y12:AA12) -> 58.794482 | AC12: 7.24 | AD12: =SUM(AB12*AC12) -> 425.67205 | AE12: =SUM(X12+AD12) -> 688.11824 | AF12: =SUM(P12-AE12) -> 103.88176
C13: 241123000018 | D13: 45631 | E13: Bella | F13: Bella Chan | G13: zhong zi xin | H13: 11.1459 | I13: 16993 | J13: 36986 | P13: =SUBTOTAL(9,J13) -> 36986 | S13: =SUM(46963.25/68)*H13 -> 7697.7601 | U13: =SUM(2500/68)*H13 -> 409.77574 | V13: 280 | X13: =SUM(S13:W13) -> 8387.5359 | Y13: =SUM(11081/68)*H13 -> 1816.29 | Z13: 288.81 | AB13: =SUM(Y13:AA13) -> 2105.1 | AC13: 7.24 | AD13: =SUM(AB13*AC13) -> 15240.924 | AE13: =SUM(X13+AD13) -> 23628.46 | AF13: =SUM(P13-AE13) -> 13357.54
C14: 241125000061 | D14: 45631 | E14: 黄颖 | F14: ying | G14: makus | H14: 0.8795 | I14: 210 | J14: 2670.5 | P14: =SUBTOTAL(9,J14) -> 2670.5 | S14: =SUM(46963.25/68)*H14 -> 607.41439 | U14: =SUM(2500/68)*H14 -> 32.334559 | X14: =SUM(S14:W14) -> 639.74895 | Y14: =SUM(11081/68)*H14 -> 143.3197 | Z14: 104.36 | AB14: =SUM(Y14:AA14) -> 247.6797 | AC14: 7.24 | AD14: =SUM(AB14*AC14) -> 1793.201 | AE14: =SUM(X14+AD14) -> 2432.95 | AF14: =SUM(P14-AE14) -> 237.55004
C15: 241125000067 | D15: 45631 | E15: 无人 | F15: dejare James | G15: Adam e | H15: 1.0967 | I15: 203 | K15: 552736 | M15: =SUM(K15/N15) -> 1679.9977 | N15: 329.00998 | O15: 7.27 | P15: =SUM(N15*O15) -> 2391.9026 | S15: =SUM(46963.25/68)*H15 -> 757.42053 | U15: =SUM(2500/68)*H15 -> 40.319853 | X15: =SUM(S15:W15) -> 797.74039 | Y15: =SUM(11081/68)*H15 -> 178.71372 | AB15: =SUM(Y15:AA15) -> 178.71372 | AC15: 7.24 | AD15: =SUM(AB15*AC15) -> 1293.8873 | AE15: =SUM(X15+AD15) -> 2091.6277 | AF15: =SUM(P15-AE15) -> 300.27486
C16: 241127000012 | D16: 45631 | E16: 罗珮文 | F16: Shirley | G16: Yusky | H16: 3.0636 | I16: 768 | K16: 1330089.4 | M16: =SUM(K16/N16) -> 1608 | N16: 827.17 | O16: 7.3 | P16: =SUM(N16*O16) -> 6038.341 | S16: =SUM(46963.25/68)*H16 -> 2115.8325 | U16: =SUM(2500/68)*H16 -> 112.63235 | X16: =SUM(S16:W16) -> 2228.4649 | Y16: =SUM(11081/68)*H16 -> 499.23164 | AB16: =SUM(Y16:AA16) -> 499.23164 | AC16: 7.24 | AD16: =SUM(AB16*AC16) -> 3614.4371 | AE16: =SUM(X16+AD16) -> 5842.902 | AF16: =SUM(P16-AE16) -> 195.43903
C17: 241127000014 | D17: 45631 | E17: 罗珮文 | F17: Shirley | G17: Yusky | H17: 0.4158 | I17: 55 | K17: 180530.16 | M17: =SUM(K17/N17) -> 1608 | N17: 112.27 | O17: 7.3 | P17: =SUM(N17*O17) -> 819.571 | S17: =SUM(46963.25/68)*H17 -> 287.16646 | U17: =SUM(2500/68)*H17 -> 15.286765 | X17: =SUM(S17:W17) -> 302.45323 | Y17: =SUM(11081/68)*H17 -> 67.757056 | AB17: =SUM(Y17:AA17) -> 67.757056 | AC17: 7.24 | AD17: =SUM(AB17*AC17) -> 490.56108 | AE17: =SUM(X17+AD17) -> 793.01431 | AF17: =SUM(P17-AE17) -> 26.55669
C18: 241127000042 | D18: 45631 | E18: 黄颖 | F18: ying | G18: wangweijun | H18: 0.3625 | I18: 15 | J18: 870 | P18: =SUBTOTAL(9,J18) -> 870 | S18: =SUM(46963.25/68)*H18 -> 250.35556 | U18: =SUM(2500/68)*H18 -> 13.327206 | W18: =SUM(26+36) -> 62 | X18: =SUM(S18:W18) -> 325.68277 | Y18: =SUM(11081/68)*H18 -> 59.071507 | AB18: =SUM(Y18:AA18) -> 59.071507 | AC18: 7.24 | AD18: =SUM(AB18*AC18) -> 427.67771 | AE18: =SUM(X18+AD18) -> 753.36048 | AF18: =SUM(P18-AE18) -> 116.63952
C19: 241127000053 | D19: 45631 | E19: 黄颖 | F19: ying | G19: baikaibo | H19: 0.6069 | I19: 165 | J19: 2195 | P19: =SUBTOTAL(9,J19) -> 2195 | S19: =SUM(46963.25/68)*H19 -> 419.14701 | U19: =SUM(2500/68)*H19 -> 22.3125 | X19: =SUM(S19:W19) -> 441.45951 | Y19: =SUM(11081/68)*H19 -> 98.897925 | Z19: 111.31 | AB19: =SUM(Y19:AA19) -> 210.20792 | AC19: 7.24 | AD19: =SUM(AB19*AC19) -> 1521.9054 | AE19: =SUM(X19+AD19) -> 1963.3649 | AF19: =SUM(P19-AE19) -> 231.63512
C20: 241128000039 | D20: 45631 | E20: 无人 | F20: dejare James | G20: James | H20: 0.5074 | I20: 252 | K20: 239442 | M20: =SUM(K20/N20) -> 1572.9993 | N20: 152.22003 | O20: 7.27 | P20: =SUM(N20*O20) -> 1106.6396 | S20: =SUM(46963.25/68)*H20 -> 350.42872 | U20: =SUM(2500/68)*H20 -> 18.654412 | X20: =SUM(S20:W20) -> 369.08313 | Y20: =SUM(11081/68)*H20 -> 82.683815 | AB20: =SUM(Y20:AA20) -> 82.683815 | AC20: 7.24 | AD20: =SUM(AB20*AC20) -> 598.63082 | AE20: =SUM(X20+AD20) -> 967.71395 | AF20: =SUM(P20-AE20) -> 138.92567
C21: 241128000041 | D21: 45631 | E21: 黄颖 | F21: ying | G21: linxiao | H21: 0.2074 | I21: 60 | J21: 463 | P21: =SUBTOTAL(9,J21) -> 463 | S21: =SUM(46963.25/68)*H21 -> 143.23791 | U21: =SUM(2500/68)*H21 -> 7.625 | X21: =SUM(S21:W21) -> 150.86291 | Y21: =SUM(11081/68)*H21 -> 33.79705 | AB21: =SUM(Y21:AA21) -> 33.79705 | AC21: 7.24 | AD21: =SUM(AB21*AC21) -> 244.69064 | AE21: =SUM(X21+AD21) -> 395.55355 | AF21: =SUM(P21-AE21) -> 67.446445
C22: 241129000029 | D22: 45631 | E22: 陆总 | F22: 陆梓龙 | G22: xiantian | H22: 0.19 | I22: 24 | J22: 369.36 | P22: =SUBTOTAL(9,J22) -> 369.36 | S22: =SUM(46963.25/68)*H22 -> 131.22085 | U22: =SUM(2500/68)*H22 -> 6.9852941 | X22: =SUM(S22:W22) -> 138.20614 | Y22: =SUM(11081/68)*H22 -> 30.961618 | AB22: =SUM(Y22:AA22) -> 30.961618 | AC22: 7.24 | AD22: =SUM(AB22*AC22) -> 224.16211 | AE22: =SUM(X22+AD22) -> 362.36825 | AF22: =SUM(P22-AE22) -> 6.9917485
C23: 241129000035 | D23: 45631 | E23: 黄颖 | F23: ying | G23: liangdawei | H23: 0.3468 | I23: 269 | J23: 1003 | P23: =SUBTOTAL(9,J23) -> 1003 | S23: =SUM(46963.25/68)*H23 -> 239.51257 | U23: =SUM(2500/68)*H23 -> 12.75 | X23: =SUM(S23:W23) -> 252.26257 | Y23: =SUM(11081/68)*H23 -> 56.5131 | AB23: =SUM(Y23:AA23) -> 56.5131 | AC23: 7.24 | AD23: =SUM(AB23*AC23) -> 409.15484 | AE23: =SUM(X23+AD23) -> 661.41742 | AF23: =SUM(P23-AE23) -> 341.58258
C24: 241130000012 | D24: 45631 | E24: 吕沛霖 | F24: Paul | G24: Paul | H24: 0.0882 | I24: 30 | K24: 56179 | M24: =SUM(K24/N24) -> 1679.994 | N24: 33.44 | O24: 7.27 | P24: =SUM(N24*O24) -> 243.1088 | S24: =SUM(46963.25/68)*H24 -> 60.914098 | U24: =SUM(2500/68)*H24 -> 3.2426471 | X24: =SUM(S24:W24) -> 64.156745 | Y24: =SUM(11081/68)*H24 -> 14.372709 | AB24: =SUM(Y24:AA24) -> 14.372709 | AC24: 7.24 | AD24: =SUM(AB24*AC24) -> 104.05841 | AE24: =SUM(X24+AD24) -> 168.21516 | AF24: =SUM(P24-AE24) -> 74.893643
C25: 241202000005 | D25: 45631 | E25: 朱小飞 | F25: Isabel Zhu | G25: Ife Oyelami | H25: 0.8261 | I25: 59 | K25: 424545 | M25: =SUM(K25/N25) -> 1657.7959 | N25: 256.09003 | O25: 7.27 | P25: =SUM(N25*O25) -> 1861.7745 | S25: =SUM(46963.25/68)*H25 -> 570.53442 | U25: =SUM(2500/68)*H25 -> 30.371324 | X25: =SUM(S25:W25) -> 600.90575 | Y25: =SUM(11081/68)*H25 -> 134.61785 | AB25: =SUM(Y25:AA25) -> 134.61785 | AC25: 7.24 | AD25: =SUM(AB25*AC25) -> 974.63327 | AE25: =SUM(X25+AD25) -> 1575.539 | AF25: =SUM(P25-AE25) -> 286.2355
C26: 241202000011 | D26: 45631 | E26: 朱小飞 | F26: Isabel Zhu | G26: Halifa Success | H26: 0.4399 | I26: 73 | J26: 900.59 | P26: =SUBTOTAL(9,J26) -> 900.59 | S26: =SUM(46963.25/68)*H26 -> 303.81079 | U26: =SUM(2500/68)*H26 -> 16.172794 | X26: =SUM(S26:W26) -> 319.98358 | Y26: =SUM(11081/68)*H26 -> 71.684293 | AB26: =SUM(Y26:AA26) -> 71.684293 | AC26: 7.24 | AD26: =SUM(AB26*AC26) -> 518.99428 | AE26: =SUM(X26+AD26) -> 838.97786 | AF26: =SUM(P26-AE26) -> 61.612138
C27: 241202000031 | D27: 45631 | E27: 黄颖 | F27: ying | G27: Jacky | H27: 0.6255 | I27: 265 | K27: 283185 | M27: =SUM(K27/N27) -> 1588.5172 | N27: 178.27002 | O27: 7.27 | P27: =SUM(N27*O27) -> 1296.023 | S27: =SUM(46963.25/68)*H27 -> 431.99284 | U27: =SUM(2500/68)*H27 -> 22.996324 | X27: =SUM(S27:W27) -> 454.98916 | Y27: =SUM(11081/68)*H27 -> 101.9289 | AB27: =SUM(Y27:AA27) -> 101.9289 | AC27: 7.24 | AD27: =SUM(AB27*AC27) -> 737.96527 | AE27: =SUM(X27+AD27) -> 1192.9544 | AF27: =SUM(P27-AE27) -> 103.06862
C28: 241202000042 | D28: 45631 | E28: 无人 | F28: dejare James | G28: James | H28: 0.1256 | I28: 54 | K28: 63300 | M28: =SUM(K28/N28) -> 1679.9359 | N28: 37.680008 | O28: 7.27 | P28: =SUM(N28*O28) -> 273.93366 | S28: =SUM(46963.25/68)*H28 -> 86.743885 | U28: =SUM(2500/68)*H28 -> 4.6176471 | X28: =SUM(S28:W28) -> 91.361532 | Y28: =SUM(11081/68)*H28 -> 20.467259 | AB28: =SUM(Y28:AA28) -> 20.467259 | AC28: 7.24 | AD28: =SUM(AB28*AC28) -> 148.18295 | AE28: =SUM(X28+AD28) -> 239.54449 | AF28: =SUM(P28-AE28) -> 34.389172
C29: 241204000039 | D29: 45631 | E29: 陆总 | F29: 陆梓龙 | G29: xinlong | H29: 0.0608 | I29: 12 | J29: 113.83 | P29: =SUBTOTAL(9,J29) -> 113.83 | S29: =SUM(46963.25/68)*H29 -> 41.990671 | U29: =SUM(2500/68)*H29 -> 2.2352941 | X29: =SUM(S29:W29) -> 44.225965 | Y29: =SUM(11081/68)*H29 -> 9.9077176 | AB29: =SUM(Y29:AA29) -> 9.9077176 | AC29: 7.24 | AD29: =SUM(AB29*AC29) -> 71.731876 | AE29: =SUM(X29+AD29) -> 115.95784 | AF29: =SUM(P29-AE29) -> -2.1278405
C30: 241204000043 | D30: 45631 | E30: 罗珮文 | F30: Shirley | G30: Yusky | H30: 1.3963 | I30: 248 | K30: 606216 | M30: =SUM(K30/N30) -> 1608 | N30: 377 | O30: 7.3 | P30: =SUM(N30*O30) -> 2752.1 | S30: =SUM(46963.25/68)*H30 -> 964.33509 | U30: =SUM(2500/68)*H30 -> 51.334559 | X30: =SUM(S30:W30) -> 1015.6696 | Y30: =SUM(11081/68)*H30 -> 227.5353 | AB30: =SUM(Y30:AA30) -> 227.5353 | AC30: 7.24 | AD30: =SUM(AB30*AC30) -> 1647.3556 | AE30: =SUM(X30+AD30) -> 2663.0252 | AF30: =SUM(P30-AE30) -> 89.074792
C31: 241204000044 | D31: 45631 | E31: 罗珮文 | F31: Shirley | G31: Yusky | H31: 0.7235 | I31: 107 | K31: 314122.8 | M31: =SUM(K31/N31) -> 1608 | N31: 195.35 | O31: 7.3 | P31: =SUM(N31*O31) -> 1426.055 | S31: =SUM(46963.25/68)*H31 -> 499.67517 | U31: =SUM(2500/68)*H31 -> 26.599265 | X31: =SUM(S31:W31) -> 526.27443 | Y31: =SUM(11081/68)*H31 -> 117.89858 | AB31: =SUM(Y31:AA31) -> 117.89858 | AC31: 7.24 | AD31: =SUM(AB31*AC31) -> 853.58573 | AE31: =SUM(X31+AD31) -> 1379.8602 | AF31: =SUM(P31-AE31) -> 46.194842
C32: 241204000045 | D32: 45631 | E32: 罗珮文 | F32: Shirley | G32: Yusky | H32: 0.26 | I32: 48 | K32: 112929.84 | M32: =SUM(K32/N32) -> 1608 | N32: 70.23 | O32: 7.3 | P32: =SUM(N32*O32) -> 512.679 | S32: =SUM(46963.25/68)*H32 -> 179.56537 | U32: =SUM(2500/68)*H32 -> 9.5588235 | X32: =SUM(S32:W32) -> 189.12419 | Y32: =SUM(11081/68)*H32 -> 42.368529 | AB32: =SUM(Y32:AA32) -> 42.368529 | AC32: 7.24 | AD32: =SUM(AB32*AC32) -> 306.74815 | AE32: =SUM(X32+AD32) -> 495.87234 | AF32: =SUM(P32-AE32) -> 16.806656
C33: 241204000046 | D33: 45631 | E33: 罗珮文 | F33: Shirley | G33: Yusky | H33: 0.2492 | I33: 51 | K33: 108090.06 | M33: =SUM(K33/N33) -> 1606.5705 | N33: 67.28 | O33: 7.3 | P33: =SUM(N33*O33) -> 491.144 | S33: =SUM(46963.25/68)*H33 -> 172.1065 | U33: =SUM(2500/68)*H33 -> 9.1617647 | X33: =SUM(S33:W33) -> 181.26826 | Y33: =SUM(11081/68)*H33 -> 40.608606 | AB33: =SUM(Y33:AA33) -> 40.608606 | AC33: 7.24 | AD33: =SUM(AB33*AC33) -> 294.00631 | AE33: =SUM(X33+AD33) -> 475.27457 | AF33: =SUM(P33-AE33) -> 15.86943
C34: 241204000047 | D34: 45631 | E34: 罗珮文 | F34: Shirley | G34: Yusky | H34: 0.2023 | I34: 17 | K34: 87064.28 | M34: =SUM(K34/N34) -> 1594 | N34: 54.62 | O34: 7.29 | P34: =SUM(N34*O34) -> 398.1798 | S34: =SUM(46963.25/68)*H34 -> 139.71567 | U34: =SUM(2500/68)*H34 -> 7.4375 | X34: =SUM(S34:W34) -> 147.15317 | Y34: =SUM(11081/68)*H34 -> 32.965975 | AB34: =SUM(Y34:AA34) -> 32.965975 | AC34: 7.24 | AD34: =SUM(AB34*AC34) -> 238.67366 | AE34: =SUM(X34+AD34) -> 385.82683 | AF34: =SUM(P34-AE34) -> 12.352972
C35: 241204000048 | D35: 45631 | E35: 罗珮文 | F35: Shirley | G35: Yusky | H35: 0.5307 | I35: 90 | K35: 228404.26 | M35: =SUM(K35/N35) -> 1594 | N35: 143.29 | O35: 7.29 | P35: =SUM(N35*O35) -> 1044.5841 | S35: =SUM(46963.25/68)*H35 -> 366.52054 | U35: =SUM(2500/68)*H35 -> 19.511029 | X35: =SUM(S35:W35) -> 386.03157 | Y35: =SUM(11081/68)*H35 -> 86.480687 | AB35: =SUM(Y35:AA35) -> 86.480687 | AC35: 7.24 | AD35: =SUM(AB35*AC35) -> 626.12017 | AE35: =SUM(X35+AD35) -> 1012.1517 | AF35: =SUM(P35-AE35) -> 32.432358
C36: 241204000050 | D36: 45631 | E36: 罗珮文 | F36: Shirley | G36: Yusky | H36: 14.6981 | I36: 2994 | K36: 6392673.2 | M36: =SUM(K36/N36) -> 1594 | N36: 4010.46 | O36: 7.27 | P36: =SUM(N36*O36) -> 29156.044 | S36: =SUM(46963.25/68)*H36 -> 10151.037 | U36: =SUM(2500/68)*H36 -> 540.37132 | X36: =SUM(S36:W36) -> 10691.409 | Y36: =SUM(11081/68)*H36 -> 2395.1419 | AB36: =SUM(Y36:AA36) -> 2395.1419 | AC36: 7.24 | AD36: =SUM(AB36*AC36) -> 17340.827 | AE36: =SUM(X36+AD36) -> 28032.236 | AF36: =SUM(P36-AE36) -> 1123.8084
C37: 241204000052 | D37: 45631 | E37: 罗珮文 | F37: Shirley | G37: Yusky | H37: 21.052 | I37: 2202 | K37: 9257809 | M37: =SUM(K37/N37) -> 1616.7908 | N37: 5726.04 | O37: 7.22 | P37: =SUM(N37*O37) -> 41342.009 | S37: =SUM(46963.25/68)*H37 -> 14539.27 | U37: =SUM(2500/68)*H37 -> 773.97059 | X37: =SUM(S37:W37) -> 15313.24 | Y37: =SUM(11081/68)*H37 -> 3430.5472 | AB37: =SUM(Y37:AA37) -> 3430.5472 | AC37: 7.24 | AD37: =SUM(AB37*AC37) -> 24837.162 | AE37: =SUM(X37+AD37) -> 40150.402 | AF37: =SUM(P37-AE37) -> 1191.6065
C38: 241204000053 | D38: 45631 | E38: 罗珮文 | F38: Shirley | G38: Yusky | H38: 0.1958 | I38: 447 | K38: 85649.4 | M38: =SUM(K38/N38) -> 1620 | N38: 52.87 | O38: 7.22 | P38: =SUM(N38*O38) -> 381.7214 | S38: =SUM(46963.25/68)*H38 -> 135.22653 | U38: =SUM(2500/68)*H38 -> 7.1985294 | X38: =SUM(S38:W38) -> 142.42506 | Y38: =SUM(11081/68)*H38 -> 31.906762 | AB38: =SUM(Y38:AA38) -> 31.906762 | AC38: 7.24 | AD38: =SUM(AB38*AC38) -> 231.00496 | AE38: =SUM(X38+AD38) -> 373.43002 | AF38: =SUM(P38-AE38) -> 8.2913809
C39: 241204000060 | D39: 45631 | E39: 朱小飞 | F39: Isabel Zhu | G39: Halifa Success | H39: 0.6256 | I39: 144 | J39: 1269.02 | P39: =SUBTOTAL(9,J39) -> 1269.02 | S39: =SUM(46963.25/68)*H39 -> 432.0619 | U39: =SUM(2500/68)*H39 -> 23 | X39: =SUM(S39:W39) -> 455.0619 | Y39: =SUM(11081/68)*H39 -> 101.9452 | AB39: =SUM(Y39:AA39) -> 101.9452 | AC39: 7.24 | AD39: =SUM(AB39*AC39) -> 738.08325 | AE39: =SUM(X39+AD39) -> 1193.1451 | AF39: =SUM(P39-AE39) -> 75.874852
A40: JOB120375 | B40: COLL004323 | C40: 241109000014 | D40: 45636 | E40: 吕沛霖 | F40: 喵喵速运-Layne | G40: KE ZONG | H40: 1.5052 | I40: 360 | J40: 3329.55 | P40: =SUBTOTAL(9,J40) -> 3329.55 | Q40: =SUM(P40:P52) -> 166063.23 | R40: 登凯=46552.5 创泽=1215 拖车费=1670 杂费=61 过磅费=70 | S40: =SUM(49568.5/68)*H40 -> 1097.2133 | U40: =SUM(2100/68)*H40 -> 46.484118 | X40: =SUM(S40:W40) -> 1143.6974 | Y40: =SUM(11623/68)*H40 -> 257.27852 | AA40: =SUM(55.62/68)*H40 -> 1.2311651 | AB40: =SUM(Y40:AA40) -> 258.50969 | AC40: 7.3 | AD40: =SUM(AB40*AC40) -> 1887.1207 | AE40: =SUM(X40+AD40) -> 3030.8182 | AF40: =SUM(P40-AE40) -> 298.73183
...

Sheet JOB120360
A1: 2024年12月份LOS毛利表（海运）
A2: PSL表 | B2: 体积cbm | C2: 69.7576
A3: JOB | B3: 集装编号 | C3: 运单编号 | D3: 日期 | E3: 业务 | F3: 发货人 | G3: 收货人 | H3: 计费体积 | I3: 计费重量 | J3: 应 收 | Q3: 总应收 | R3: 起 运 港 成 本 | W3: 代垫运费 | X3: 起运港成本 合计 | Y3: 目的港成本 | AE3: 总支出 | AF3: 利润
J4: 应收RMB | K4: LOS Income(NGN)收到(奈拉) | L4: LOS 收到USD | M4: 美元汇率 dollar currency rate | N4: 应收 到付款USD | O4: 汇率 | P4: 人民币 | R4: 代理商 | S4: 运费+出口报关费 | T4: 提货费 | U4: 装卸费 | V4: 包装费 | Y4: 进口报关费 | Z4: 到门配送费 | AA4: 转运费 | AB4: 目的港支出 | AC4: 汇率 | AD4: 人民币 | AE4: 起运港+目的港
A5: JOB120360 | B5: COLL004315 | C5: 240925000017 | D5: 45631 | E5: 无人 | F5: dejare James | G5: James | H5: 0.1799 | I5: 17 | K5: 84600 | M5: =SUM(K5/N5) -> 1679.5713 | N5: 50.369995 | O5: 7.27 | P5: =SUM(N5*O5) -> 366.18986 | Q5: =SUM(P5:P40) -> 162259.24 | R5: 登凯=43870.25 创泽=1270 拖车费=1670 杂费=84 过磅费=69 | S5: =SUM(46963.25/68)*H5 -> 124.24542 | U5: =SUM(2500/68)*H5 -> 6.6139706 | X5: =SUM(S5:W5) -> 130.85939 | Y5: =SUM(11081/68)*H5 -> 29.315763 | AB5: =SUM(Y5:AA5) -> 29.315763 | AC5: 7.24 | AD5: =SUM(AB5*AC5) -> 212.24613 | AE5: =SUM(X5+AD5) -> 343.10552 | AF5: =SUM(P5-AE5) -> 23.084346
C6: 241118000063 | D6: 45631 | E6: 罗珮文 | F6: Shirley | G6: Yusky | H6: 1.6585 | I6: 270 | K6: 719837.28 | M6: =SUM(K6/N6) -> 1608 | N6: 447.66 | O6: 7.3 | P6: =SUM(N6*O6) -> 3267.918 | S6: =SUM(46963.25/68)*H6 -> 1145.4199 | U6: =SUM(2500/68)*H6 -> 60.974265 | X6: =SUM(S6:W6) -> 1206.3941 | Y6: =SUM(11081/68)*H6 -> 270.26233 | AB6: =SUM(Y6:AA6) -> 270.26233 | AC6: 7.24 | AD6: =SUM(AB6*AC6) -> 1956.6993 | AE6: =SUM(X6+AD6) -> 3163.0934 | AF6: =SUM(P6-AE6) -> 104.8246
C7: 241118000066 | D7: 45631 | E7: 罗珮文 | F7: Shirley | G7: Yusky | H7: 1.2581 | I7: 125 | K7: 546173.28 | M7: =SUM(K7/N7) -> 1608 | N7: 339.66 | O7: 7.3 | P7: =SUM(N7*O7) -> 2479.518 | S7: =SUM(46963.25/68)*H7 -> 868.88919 | U7: =SUM(2500/68)*H7 -> 46.253676 | X7: =SUM(S7:W7) -> 915.14287 | Y7: =SUM(11081/68)*H7 -> 205.0148 | AB7: =SUM(Y7:AA7) -> 205.0148 | AC7: 7.24 | AD7: =SUM(AB7*AC7) -> 1484.3071 | AE7: =SUM(X7+AD7) -> 2399.45 | AF7: =SUM(P7-AE7) -> 80.068015
C8: 241120000012 | D8: 45631 | E8: Bella | F8: Bella Chan | G8: FENG | H8: 0.1878 | I8: 62 | K8: 94651.2 | M8: =SUM(K8/N8) -> 1680.0001 | N8: 56.339996 | O8: 7.3 | P8: =SUM(N8*O8) -> 411.28197 | S8: =SUM(46963.25/68)*H8 -> 129.70145 | U8: =SUM(2500/68)*H8 -> 6.9044118 | X8: =SUM(S8:W8) -> 136.60586 | Y8: =SUM(11081/68)*H8 -> 30.603115 | AB8: =SUM(Y8:AA8) -> 30.603115 | AC8: 7.24 | AD8: =SUM(AB8*AC8) -> 221.56655 | AE8: =SUM(X8+AD8) -> 358.17241 | AF8: =SUM(P8-AE8) -> 53.109562
C9: 241120000023 | D9: 45631 | E9: Sam.Pao | F9: Sam.Pao | G9: Mr. Jiang | H9: 1.3317 | I9: 326 | J9: 4965 | P9: =SUBTOTAL(9,J9) -> 4965 | S9: =SUM(46963.25/68)*H9 -> 919.72 | U9: =SUM(2500/68)*H9 -> 48.959559 | V9: 500 | X9: =SUM(S9:W9) -> 1468.6796 | Y9: =SUM(11081/68)*H9 -> 217.00835 | AB9: =SUM(Y9:AA9) -> 217.00835 | AC9: 7.24 | AD9: =SUM(AB9*AC9) -> 1571.1404 | AE9: =SUM(X9+AD9) -> 3039.82 | AF9: =SUM(P9-AE9) -> 1925.18
C10: 241121000013 | D10: 45631 | E10: Sam.Pao | F10: Sam.Pao | G10: Mr. Jiang | H10: 2.2982 | I10: 612 | J10: 7707 | P10: =SUBTOTAL(9,J10) -> 7707 | S10: =SUM(46963.25/68)*H10 -> 1587.2197 | U10: =SUM(2500/68)*H10 -> 84.492647 | V10: 400 | X10: =SUM(S10:W10) -> 2071.7124 | Y10: =SUM(11081/68)*H10 -> 374.50521 | AB10: =SUM(Y10:AA10) -> 374.50521 | AC10: 7.24 | AD10: =SUM(AB10*AC10) -> 2711.4177 | AE10: =SUM(X10+AD10) -> 4783.1301 | AF10: =SUM(P10-AE10) -> 2923.8699
C11: 241121000018 | D11: 45631 | E11: Sam.Pao | F11: Sam.Pao | G11: Nick Wang | H11: 0.0768 | I11: 14 | J11: 296.22 | P11: =SUBTOTAL(9,J11) -> 296.22 | S11: =SUM(46963.25/68)*H11 -> 53.040847 | U11: =SUM(2500/68)*H11 -> 2.8235294 | X11: =SUM(S11:W11) -> 55.864376 | Y11: =SUM(11081/68)*H11 -> 12.515012 | Z11: 4.51 | AB11: =SUM(Y11:AA11) -> 17.025012 | AC11: 7.24 | AD11: =SUM(AB11*AC11) -> 123.26109 | AE11: =SUM(X11+AD11) -> 179.12546 | AF11: =SUM(P11-AE11) -> 117.09454
C12: 241121000019 | D12: 45631 | E12: Sam.Pao | F12: Sam.Pao | G12: Mr. Jiang | H12: 1.4834 | I12: 471 | J12: 3598 | P12: =SUBTOTAL(9,J12) -> 3598 | S12: =SUM(46963.25/68)*H12 -> 1024.4895 | U12: =SUM(2500/68)*H12 -> 54.536765 | X12: =SUM(S12:W12) -> 1079.0263 | Y12: =SUM(11081/68)*H12 -> 241.72876 | AB12: =SUM(Y12:AA12) -> 241.72876 | AC12: 7.24 | AD12: =SUM(AB12*AC12) -> 1750.1162 | AE12: =SUM(X12+AD12) -> 2829.1424 | AF12: =SUM(P12-AE12) -> 768.85756
C13: 241123000017 | D13: 45631 | E13: 黄颖 | F13: ying | G13: Nura | H13: 0.3608 | I13: 202 | J13: 792 | P13: =SUBTOTAL(9,J13) -> 792 | S13: =SUM(46963.25/68)*H13 -> 249.18148 | U13: =SUM(2500/68)*H13 -> 13.264706 | X13: =SUM(S13:W13) -> 262.44619 | Y13: =SUM(11081/68)*H13 -> 58.794482 | AB13: =SUM(Y13:AA13) -> 58.794482 | AC13: 7.24 | AD13: =SUM(AB13*AC13) -> 425.67205 | AE13: =SUM(X13+AD13) -> 688.11824 | AF13: =SUM(P13-AE13) -> 103.88176
C14: 241123000018 | D14: 45631 | E14: Bella | F14: Bella Chan | G14: zhong zi xin | H14: 11.1459 | I14: 16993 | J14: 36986 | P14: =SUBTOTAL(9,J14) -> 36986 | S14: =SUM(46963.25/68)*H14 -> 7697.7601 | U14: =SUM(2500/68)*H14 -> 409.77574 | V14: 280 | X14: =SUM(S14:W14) -> 8387.5359 | Y14: =SUM(11081/68)*H14 -> 1816.29 | Z14: 288.81 | AB14: =SUM(Y14:AA14) -> 2105.1 | AC14: 7.24 | AD14: =SUM(AB14*AC14) -> 15240.924 | AE14: =SUM(X14+AD14) -> 23628.46 | AF14: =SUM(P14-AE14) -> 13357.54
C15: 241125000061 | D15: 45631 | E15: 黄颖 | F15: ying | G15: makus | H15: 0.8795 | I15: 210 | J15: 2670.5 | P15: =SUBTOTAL(9,J15) -> 2670.5 | S15: =SUM(46963.25/68)*H15 -> 607.41439 | U15: =SUM(2500/68)*H15 -> 32.334559 | X15: =SUM(S15:W15) -> 639.74895 | Y15: =SUM(11081/68)*H15 -> 143.3197 | Z15: 104.36 | AB15: =SUM(Y15:AA15) -> 247.6797 | AC15: 7.24 | AD15: =SUM(AB15*AC15) -> 1793.201 | AE15: =SUM(X15+AD15) -> 2432.95 | AF15: =SUM(P15-AE15) -> 237.55004
C16: 241125000067 | D16: 45631 | E16: 无人 | F16: dejare James | G16: Adam e | H16: 1.0967 | I16: 203 | K16: 552736 | M16: =SUM(K16/N16) -> 1679.9977 | N16: 329.00998 | O16: 7.27 | P16: =SUM(N16*O16) -> 2391.9026 | S16: =SUM(46963.25/68)*H16 -> 757.42053 | U16: =SUM(2500/68)*H16 -> 40.319853 | X16: =SUM(S16:W16) -> 797.74039 | Y16: =SUM(11081/68)*H16 -> 178.71372 | AB16: =SUM(Y16:AA16) -> 178.71372 | AC16: 7.24 | AD16: =SUM(AB16*AC16) -> 1293.8873 | AE16: =SUM(X16+AD16) -> 2091.6277 | AF16: =SUM(P16-AE16) -> 300.27486
C17: 241127000012 | D17: 45631 | E17: 罗珮文 | F17: Shirley | G17: Yusky | H17: 3.0636 | I17: 768 | K17: 1330089.4 | M17: =SUM(K17/N17) -> 1608 | N17: 827.17 | O17: 7.3 | P17: =SUM(N17*O17) -> 6038.341 | S17: =SUM(46963.25/68)*H17 -> 2115.8325 | U17: =SUM(2500/68)*H17 -> 112.63235 | X17: =SUM(S17:W17) -> 2228.4649 | Y17: =SUM(11081/68)*H17 -> 499.23164 | AB17: =SUM(Y17:AA17) -> 499.23164 | AC17: 7.24 | AD17: =SUM(AB17*AC17) -> 3614.4371 | AE17: =SUM(X17+AD17) -> 5842.902 | AF17: =SUM(P17-AE17) -> 195.43903
C18: 241127000014 | D18: 45631 | E18: 罗珮文 | F18: Shirley | G18: Yusky | H18: 0.4158 | I18: 55 | K18: 180530.16 | M18: =SUM(K18/N18) -> 1608 | N18: 112.27 | O18: 7.3 | P18: =SUM(N18*O18) -> 819.571 | S18: =SUM(46963.25/68)*H18 -> 287.16646 | U18: =SUM(2500/68)*H18 -> 15.286765 | X18: =SUM(S18:W18) -> 302.45323 | Y18: =SUM(11081/68)*H18 -> 67.757056 | AB18: =SUM(Y18:AA18) -> 67.757056 | AC18: 7.24 | AD18: =SUM(AB18*AC18) -> 490.56108 | AE18: =SUM(X18+AD18) -> 793.01431 | AF18: =SUM(P18-AE18) -> 26.55669
C19: 241127000042 | D19: 45631 | E19: 黄颖 | F19: ying | G19: wangweijun | H19: 0.3625 | I19: 15 | J19: 870 | P19: =SUBTOTAL(9,J19) -> 870 | S19: =SUM(46963.25/68)*H19 -> 250.35556 | U19: =SUM(2500/68)*H19 -> 13.327206 | W19: =SUM(26+36) -> 62 | X19: =SUM(S19:W19) -> 325.68277 | Y19: =SUM(11081/68)*H19 -> 59.071507 | AB19: =SUM(Y19:AA19) -> 59.071507 | AC19: 7.24 | AD19: =SUM(AB19*AC19) -> 427.67771 | AE19: =SUM(X19+AD19) -> 753.36048 | AF19: =SUM(P19-AE19) -> 116.63952
C20: 241127000053 | D20: 45631 | E20: 黄颖 | F20: ying | G20: baikaibo | H20: 0.6069 | I20: 165 | J20: 2195 | P20: =SUBTOTAL(9,J20) -> 2195 | S20: =SUM(46963.25/68)*H20 -> 419.14701 | U20: =SUM(2500/68)*H20 -> 22.3125 | X20: =SUM(S20:W20) -> 441.45951 | Y20: =SUM(11081/68)*H20 -> 98.897925 | Z20: 111.31 | AB20: =SUM(Y20:AA20) -> 210.20792 | AC20: 7.24 | AD20: =SUM(AB20*AC20) -> 1521.9054 | AE20: =SUM(X20+AD20) -> 1963.3649 | AF20: =SUM(P20-AE20) -> 231.63512
C21: 241128000039 | D21: 45631 | E21: 无人 | F21: dejare James | G21: James | H21: 0.5074 | I21: 252 | K21: 239442 | M21: =SUM(K21/N21) -> 1572.9993 | N21: 152.22003 | O21: 7.27 | P21: =SUM(N21*O21) -> 1106.6396 | S21: =SUM(46963.25/68)*H21 -> 350.42872 | U21: =SUM(2500/68)*H21 -> 18.654412 | X21: =SUM(S21:W21) -> 369.08313 | Y21: =SUM(11081/68)*H21 -> 82.683815 | AB21: =SUM(Y21:AA21) -> 82.683815 | AC21: 7.24 | AD21: =SUM(AB21*AC21) -> 598.63082 | AE21: =SUM(X21+AD21) -> 967.71395 | AF21: =SUM(P21-AE21) -> 138.92567
C22: 241128000041 | D22: 45631 | E22: 黄颖 | F22: ying | G22: linxiao | H22: 0.2074 | I22: 60 | J22: 463 | P22: =SUBTOTAL(9,J22) -> 463 | S22: =SUM(46963.25/68)*H22 -> 143.23791 | U22: =SUM(2500/68)*H22 -> 7.625 | X22: =SUM(S22:W22) -> 150.86291 | Y22: =SUM(11081/68)*H22 -> 33.79705 | AB22: =SUM(Y22:AA22) -> 33.79705 | AC22: 7.24 | AD22: =SUM(AB22*AC22) -> 244.69064 | AE22: =SUM(X22+AD22) -> 395.55355 | AF22: =SUM(P22-AE22) -> 67.446445
C23: 241129000029 | D23: 45631 | E23: 陆总 | F23: 陆梓龙 | G23: xiantian | H23: 0.19 | I23: 24 | J23: 369.36 | P23: =SUBTOTAL(9,J23) -> 369.36 | S23: =SUM(46963.25/68)*H23 -> 131.22085 | U23: =SUM(2500/68)*H23 -> 6.9852941 | X23: =SUM(S23:W23) -> 138.20614 | Y23: =SUM(11081/68)*H23 -> 30.961618 | AB23: =SUM(Y23:AA23) -> 30.961618 | AC23: 7.24 | AD23: =SUM(AB23*AC23) -> 224.16211 | AE23: =SUM(X23+AD23) -> 362.36825 | AF23: =SUM(P23-AE23) -> 6.9917485
C24: 241129000035 | D24: 45631 | E24: 黄颖 | F24: ying | G24: liangdawei | H24: 0.3468 | I24: 269 | J24: 1003 | P24: =SUBTOTAL(9,J24) -> 1003 | S24: =SUM(46963.25/68)*H24 -> 239.51257 | U24: =SUM(2500/68)*H24 -> 12.75 | X24: =SUM(S24:W24) -> 252.26257 | Y24: =SUM(11081/68)*H24 -> 56.5131 | AB24: =SUM(Y24:AA24) -> 56.5131 | AC24: 7.24 | AD24: =SUM(AB24*AC24) -> 409.15484 | AE24: =SUM(X24+AD24) -> 661.41742 | AF24: =SUM(P24-AE24) -> 341.58258
C25: 241130000012 | D25: 45631 | E25: 吕沛霖 | F25: Paul | G25: Paul | H25: 0.0882 | I25: 30 | K25: 56179 | M25: =SUM(K25/N25) -> 1679.994 | N25: 33.44 | O25: 7.27 | P25: =SUM(N25*O25) -> 243.1088 | S25: =SUM(46963.25/68)*H25 -> 60.914098 | U25: =SUM(2500/68)*H25 -> 3.2426471 | X25: =SUM(S25:W25) -> 64.156745 | Y25: =SUM(11081/68)*H25 -> 14.372709 | AB25: =SUM(Y25:AA25) -> 14.372709 | AC25: 7.24 | AD25: =SUM(AB25*AC25) -> 104.05841 | AE25: =SUM(X25+AD25) -> 168.21516 | AF25: =SUM(P25-AE25) -> 74.893643
C26: 241202000005 | D26: 45631 | E26: 朱小飞 | F26: Isabel Zhu | G26: Ife Oyelami | H26: 0.8261 | I26: 59 | K26: 424545 | M26: =SUM(K26/N26) -> 1657.7959 | N26: 256.09003 | O26: 7.27 | P26: =SUM(N26*O26) -> 1861.7745 | S26: =SUM(46963.25/68)*H26 -> 570.53442 | U26: =SUM(2500/68)*H26 -> 30.371324 | X26: =SUM(S26:W26) -> 600.90575 | Y26: =SUM(11081/68)*H26 -> 134.61785 | AB26: =SUM(Y26:AA26) -> 134.61785 | AC26: 7.24 | AD26: =SUM(AB26*AC26) -> 974.63327 | AE26: =SUM(X26+AD26) -> 1575.539 | AF26: =SUM(P26-AE26) -> 286.2355
C27: 241202000011 | D27: 45631 | E27: 朱小飞 | F27: Isabel Zhu | G27: Halifa Success | H27: 0.4399 | I27: 73 | J27: 900.59 | P27: =SUBTOTAL(9,J27) -> 900.59 | S27: =SUM(46963.25/68)*H27 -> 303.81079 | U27: =SUM(2500/68)*H27 -> 16.172794 | X27: =SUM(S27:W27) -> 319.98358 | Y27: =SUM(11081/68)*H27 -> 71.684293 | AB27: =SUM(Y27:AA27) -> 71.684293 | AC27: 7.24 | AD27: =SUM(AB27*AC27) -> 518.99428 | AE27: =SUM(X27+AD27) -> 838.97786 | AF27: =SUM(P27-AE27) -> 61.612138
C28: 241202000031 | D28: 45631 | E28: 黄颖 | F28: ying | G28: Jacky | H28: 0.6255 | I28: 265 | K28: 283185 | M28: =SUM(K28/N28) -> 1588.5172 | N28: 178.27002 | O28: 7.27 | P28: =SUM(N28*O28) -> 1296.023 | S28: =SUM(46963.25/68)*H28 -> 431.99284 | U28: =SUM(2500/68)*H28 -> 22.996324 | X28: =SUM(S28:W28) -> 454.98916 | Y28: =SUM(11081/68)*H28 -> 101.9289 | AB28: =SUM(Y28:AA28) -> 101.9289 | AC28: 7.24 | AD28: =SUM(AB28*AC28) -> 737.96527 | AE28: =SUM(X28+AD28) -> 1192.9544 | AF28: =SUM(P28-AE28) -> 103.06862
C29: 241202000042 | D29: 45631 | E29: 无人 | F29: dejare James | G29: James | H29: 0.1256 | I29: 54 | K29: 63300 | M29: =SUM(K29/N29) -> 1679.9359 | N29: 37.680008 | O29: 7.27 | P29: =SUM(N29*O29) -> 273.93366 | S29: =SUM(46963.25/68)*H29 -> 86.743885 | U29: =SUM(2500/68)*H29 -> 4.6176471 | X29: =SUM(S29:W29) -> 91.361532 | Y29: =SUM(11081/68)*H29 -> 20.467259 | AB29: =SUM(Y29:AA29) -> 20.467259 | AC29: 7.24 | AD29: =SUM(AB29*AC29) -> 148.18295 | AE29: =SUM(X29+AD29) -> 239.54449 | AF29: =SUM(P29-AE29) -> 34.389172
C30: 241204000039 | D30: 45631 | E30: 陆总 | F30: 陆梓龙 | G30: xinlong | H30: 0.0608 | I30: 12 | J30: 113.83 | P30: =SUBTOTAL(9,J30) -> 113.83 | S30: =SUM(46963.25/68)*H30 -> 41.990671 | U30: =SUM(2500/68)*H30 -> 2.2352941 | X30: =SUM(S30:W30) -> 44.225965 | Y30: =SUM(11081/68)*H30 -> 9.9077176 | AB30: =SUM(Y30:AA30) -> 9.9077176 | AC30: 7.24 | AD30: =SUM(AB30*AC30) -> 71.731876 | AE30: =SUM(X30+AD30) -> 115.95784 | AF30: =SUM(P30-AE30) -> -2.1278405
C31: 241204000043 | D31: 45631 | E31: 罗珮文 | F31: Shirley | G31: Yusky | H31: 1.3963 | I31: 248 | K31: 606216 | M31: =SUM(K31/N31) -> 1608 | N31: 377 | O31: 7.3 | P31: =SUM(N31*O31) -> 2752.1 | S31: =SUM(46963.25/68)*H31 -> 964.33509 | U31: =SUM(2500/68)*H31 -> 51.334559 | X31: =SUM(S31:W31) -> 1015.6696 | Y31: =SUM(11081/68)*H31 -> 227.5353 | AB31: =SUM(Y31:AA31) -> 227.5353 | AC31: 7.24 | AD31: =SUM(AB31*AC31) -> 1647.3556 | AE31: =SUM(X31+AD31) -> 2663.0252 | AF31: =SUM(P31-AE31) -> 89.074792
C32: 241204000044 | D32: 45631 | E32: 罗珮文 | F32: Shirley | G32: Yusky | H32: 0.7235 | I32: 107 | K32: 314122.8 | M32: =SUM(K32/N32) -> 1608 | N32: 195.35 | O32: 7.3 | P32: =SUM(N32*O32) -> 1426.055 | S32: =SUM(46963.25/68)*H32 -> 499.67517 | U32: =SUM(2500/68)*H32 -> 26.599265 | X32: =SUM(S32:W32) -> 526.27443 | Y32: =SUM(11081/68)*H32 -> 117.89858 | AB32: =SUM(Y32:AA32) -> 117.89858 | AC32: 7.24 | AD32: =SUM(AB32*AC32) -> 853.58573 | AE32: =SUM(X32+AD32) -> 1379.8602 | AF32: =SUM(P32-AE32) -> 46.194842
C33: 241204000045 | D33: 45631 | E33: 罗珮文 | F33: Shirley | G33: Yusky | H33: 0.26 | I33: 48 | K33: 112929.84 | M33: =SUM(K33/N33) -> 1608 | N33: 70.23 | O33: 7.3 | P33: =SUM(N33*O33) -> 512.679 | S33: =SUM(46963.25/68)*H33 -> 179.56537 | U33: =SUM(2500/68)*H33 -> 9.5588235 | X33: =SUM(S33:W33) -> 189.12419 | Y33: =SUM(11081/68)*H33 -> 42.368529 | AB33: =SUM(Y33:AA33) -> 42.368529 | AC33: 7.24 | AD33: =SUM(AB33*AC33) -> 306.74815 | AE33: =SUM(X33+AD33) -> 495.87234 | AF33: =SUM(P33-AE33) -> 16.806656
C34: 241204000046 | D34: 45631 | E34: 罗珮文 | F34: Shirley | G34: Yusky | H34: 0.2492 | I34: 51 | K34: 108090.06 | M34: =SUM(K34/N34) -> 1606.5705 | N34: 67.28 | O34: 7.3 | P34: =SUM(N34*O34) -> 491.144 | S34: =SUM(46963.25/68)*H34 -> 172.1065 | U34: =SUM(2500/68)*H34 -> 9.1617647 | X34: =SUM(S34:W34) -> 181.26826 | Y34: =SUM(11081/68)*H34 -> 40.608606 | AB34: =SUM(Y34:AA34) -> 40.608606 | AC34: 7.24 | AD34: =SUM(AB34*AC34) -> 294.00631 | AE34: =SUM(X34+AD34) -> 475.27457 | AF34: =SUM(P34-AE34) -> 15.86943
C35: 241204000047 | D35: 45631 | E35: 罗珮文 | F35: Shirley | G35: Yusky | H35: 0.2023 | I35: 17 | K35: 87064.28 | M35: =SUM(K35/N35) -> 1594 | N35: 54.62 | O35: 7.29 | P35: =SUM(N35*O35) -> 398.1798 | S35: =SUM(46963.25/68)*H35 -> 139.71567 | U35: =SUM(2500/68)*H35 -> 7.4375 | X35: =SUM(S35:W35) -> 147.15317 | Y35: =SUM(11081/68)*H35 -> 32.965975 | AB35: =SUM(Y35:AA35) -> 32.965975 | AC35: 7.24 | AD35: =SUM(AB35*AC35) -> 238.67366 | AE35: =SUM(X35+AD35) -> 385.82683 | AF35: =SUM(P35-AE35) -> 12.352972
C36: 241204000048 | D36: 45631 | E36: 罗珮文 | F36: Shirley | G36: Yusky | H36: 0.5307 | I36: 90 | K36: 228404.26 | M36: =SUM(K36/N36) -> 1594 | N36: 143.29 | O36: 7.29 | P36: =SUM(N36*O36) -> 1044.5841 | S36: =SUM(46963.25/68)*H36 -> 366.52054 | U36: =SUM(2500/68)*H36 -> 19.511029 | X36: =SUM(S36:W36) -> 386.03157 | Y36: =SUM(11081/68)*H36 -> 86.480687 | AB36: =SUM(Y36:AA36) -> 86.480687 | AC36: 7.24 | AD36: =SUM(AB36*AC36) -> 626.12017 | AE36: =SUM(X36+AD36) -> 1012.1517 | AF36: =SUM(P36-AE36) -> 32.432358
C37: 241204000050 | D37: 45631 | E37: 罗珮文 | F37: Shirley | G37: Yusky | H37: 14.6981 | I37: 2994 | K37: 6392673.2 | M37: =SUM(K37/N37) -> 1594 | N37: 4010.46 | O37: 7.27 | P37: =SUM(N37*O37) -> 29156.044 | S37: =SUM(46963.25/68)*H37 -> 10151.037 | U37: =SUM(2500/68)*H37 -> 540.37132 | X37: =SUM(S37:W37) -> 10691.409 | Y37: =SUM(11081/68)*H37 -> 2395.1419 | AB37: =SUM(Y37:AA37) -> 2395.1419 | AC37: 7.24 | AD37: =SUM(AB37*AC37) -> 17340.827 | AE37: =SUM(X37+AD37) -> 28032.236 | AF37: =SUM(P37-AE37) -> 1123.8084
C38: 241204000052 | D38: 45631 | E38: 罗珮文 | F38: Shirley | G38: Yusky | H38: 21.052 | I38: 2202 | K38: 9257809 | M38: =SUM(K38/N38) -> 1616.7908 | N38: 5726.04 | O38: 7.22 | P38: =SUM(N38*O38) -> 41342.009 | S38: =SUM(46963.25/68)*H38 -> 14539.27 | U38: =SUM(2500/68)*H38 -> 773.97059 | X38: =SUM(S38:W38) -> 15313.24 | Y38: =SUM(11081/68)*H38 -> 3430.5472 | AB38: =SUM(Y38:AA38) -> 3430.5472 | AC38: 7.24 | AD38: =SUM(AB38*AC38) -> 24837.162 | AE38: =SUM(X38+AD38) -> 40150.402 | AF38: =SUM(P38-AE38) -> 1191.6065
C39: 241204000053 | D39: 45631 | E39: 罗珮文 | F39: Shirley | G39: Yusky | H39: 0.1958 | I39: 447 | K39: 85649.4 | M39: =SUM(K39/N39) -> 1620 | N39: 52.87 | O39: 7.22 | P39: =SUM(N39*O39) -> 381.7214 | S39: =SUM(46963.25/68)*H39 -> 135.22653 | U39: =SUM(2500/68)*H39 -> 7.1985294 | X39: =SUM(S39:W39) -> 142.42506 | Y39: =SUM(11081/68)*H39 -> 31.906762 | AB39: =SUM(Y39:AA39) -> 31.906762 | AC39: 7.24 | AD39: =SUM(AB39*AC39) -> 231.00496 | AE39: =SUM(X39+AD39) -> 373.43002 | AF39: =SUM(P39-AE39) -> 8.2913809
C40: 241204000060 | D40: 45631 | E40: 朱小飞 | F40: Isabel Zhu | G40: Halifa Success | H40: 0.6256 | I40: 144 | J40: 1269.02 | P40: =SUBTOTAL(9,J40) -> 1269.02 | S40: =SUM(46963.25/68)*H40 -> 432.0619 | U40: =SUM(2500/68)*H40 -> 23 | X40: =SUM(S40:W40) -> 455.0619 | Y40: =SUM(11081/68)*H40 -> 101.9452 | AB40: =SUM(Y40:AA40) -> 101.9452 | AC40: 7.24 | AD40: =SUM(AB40*AC40) -> 738.08325 | AE40: =SUM(X40+AD40) -> 1193.1451 | AF40: =SUM(P40-AE40) -> 75.874852
...

Sheet JOB120375
A1: 2024年12月份LOS毛利表（海运）
A2: PSL表 | B2: 体积cbm | C2: 69.9989
A3: JOB | B3: 集装编号 | C3: 运单编号 | D3: 日期 | E3: 业务 | F3: 发货人 | G3: 收货人 | H3: 计费体积 | I3: 计费重量 | J3: 应 收 | Q3: 总应收 | R3: 起 运 港 成 本 | W3: 代垫运费 | X3: 起运港成本 合计 | Y3: 目的港成本 | AE3: 总支出 | AF3: 利润
J4: 应收RMB | K4: LOS Income(NGN)收到(奈拉) | L4: LOS 收到USD | M4: 美元汇率 dollar currency rate | N4: 应收 到付款USD | O4: 汇率 | P4: 人民币 | R4: 代理商 | S4: 运费+出口报关费 | T4: 提货费 | U4: 装卸费 | V4: 包装费 | Y4: 进口报关费 | Z4: 到门配送费 | AA4: 转运费 | AB4: 目的港支出 | AC4: 汇率 | AD4: 人民币 | AE4: 起运港+目的港
A5: JOB120375 | B5: COLL004323 | C5: 241109000014 | D5: 45636 | E5: 吕沛霖 | F5: 喵喵速运-Layne | G5: KE ZONG | H5: 1.5052 | I5: 360 | J5: 3329.55 | P5: =SUBTOTAL(9,J5) -> 3329.55 | Q5: =SUM(P5:P17) -> 166063.23 | R5: 登凯=46552.5 创泽=1215 拖车费=1670 杂费=61 过磅费=70 | S5: =SUM(49568.5/68)*H5 -> 1097.2133 | U5: =SUM(2100/68)*H5 -> 46.484118 | X5: =SUM(S5:W5) -> 1143.6974 | Y5: =SUM(11623/68)*H5 -> 257.27852 | AA5: =SUM(55.62/68)*H5 -> 1.2311651 | AB5: =SUM(Y5:AA5) -> 258.50969 | AC5: 7.3 | AD5: =SUM(AB5*AC5) -> 1887.1207 | AE5: =SUM(X5+AD5) -> 3030.8182 | AF5: =SUM(P5-AE5) -> 298.73183
C6: 241127000004 | D6: 45636 | E6: 吕沛霖 | F6: 喵喵速运-Layne | G6: Candice Ding | H6: 2.3335 | I6: 2600 | K6: 1863312 | M6: =SUM(K6/N6) -> 1600 | N6: 1164.57 | O6: 7.28 | P6: =SUM(N6*O6) -> 8478.0696 | S6: =SUM(49568.5/68)*H6 -> 1701.0014 | U6: =SUM(2100/68)*H6 -> 72.063971 | X6: =SUM(S6:W6) -> 1773.0654 | Y6: =SUM(11623/68)*H6 -> 398.85692 | AA6: =SUM(55.62/68)*H6 -> 1.9086657 | AB6: =SUM(Y6:AA6) -> 400.76558 | AC6: 7.3 | AD6: =SUM(AB6*AC6) -> 2925.5888 | AE6: =SUM(X6+AD6) -> 4698.6541 | AF6: =SUM(P6-AE6) -> 3779.4155
C7: 241128000012 | D7: 45636 | E7: Bella | F7: Bella Chan | G7: FENG | H7: 0.196 | I7: 106 | K7: 98784 | M7: =SUM(K7/N7) -> 1679.9994 | N7: 58.80002 | O7: 7.3 | P7: =SUM(N7*O7) -> 429.24015 | S7: =SUM(49568.5/68)*H7 -> 142.87391 | U7: =SUM(2100/68)*H7 -> 6.0529412 | X7: =SUM(S7:W7) -> 148.92685 | Y7: =SUM(11623/68)*H7 -> 33.501588 | AA7: =SUM(55.62/68)*H7 -> 0.16031647 | AB7: =SUM(Y7:AA7) -> 33.661905 | AC7: 7.3 | AD7: =SUM(AB7*AC7) -> 245.7319 | AE7: =SUM(X7+AD7) -> 394.65876 | AF7: =SUM(P7-AE7) -> 34.581389
C8: 241202000044 | D8: 45636 | E8: 黄颖 | F8: ying | G8: Jacky | H8: 3.774 | I8: 1521 | K8: 1698783.8 | M8: =SUM(K8/N8) -> 1579.397 | N8: 1075.5901 | O8: 7.27 | P8: =SUM(N8*O8) -> 7819.54 | S8: =SUM(49568.5/68)*H8 -> 2751.0518 | U8: =SUM(2100/68)*H8 -> 116.55 | X8: =SUM(S8:W8) -> 2867.6017 | Y8: =SUM(11623/68)*H8 -> 645.0765 | AA8: =SUM(55.62/68)*H8 -> 3.08691 | AB8: =SUM(Y8:AA8) -> 648.16341 | AC8: 7.3 | AD8: =SUM(AB8*AC8) -> 4731.5929 | AE8: =SUM(X8+AD8) -> 7599.1946 | AF8: =SUM(P8-AE8) -> 220.34538
C9: 241203000015 | D9: 45636 | E9: Bella | F9: Bella Chan | G9: zhong zi xin | H9: 7.8671 | I9: 16682 | J9: 33835.5 | P9: =SUM(J9) -> 33835.5 | S9: =SUM(49568.5/68)*H9 -> 5734.711 | U9: =SUM(2100/68)*H9 -> 242.95456 | X9: =SUM(S9:W9) -> 5977.6655 | Y9: =SUM(11623/68)*H9 -> 1344.6956 | AA9: =SUM(55.62/68)*H9 -> 6.434825 | AB9: =SUM(Y9:AA9) -> 1351.1305 | AC9: 7.3 | AD9: =SUM(AB9*AC9) -> 9863.2524 | AE9: =SUM(X9+AD9) -> 15840.918 | AF9: =SUM(P9-AE9) -> 17994.582
C10: 241204000049 | D10: 45636 | E10: 罗珮文 | F10: Shirley | G10: Yusky | H10: 14.985 | I10: 2696 | K10: 6707917.9 | M10: =SUM(K10/N10) -> 1582.8774 | N10: 4237.8 | O10: 7.18 | P10: =SUM(N10*O10) -> 30427.404 | S10: =SUM(49568.5/68)*H10 -> 10923.294 | U10: =SUM(2100/68)*H10 -> 462.77206 | X10: =SUM(S10:W10) -> 11386.066 | Y10: =SUM(11623/68)*H10 -> 2561.3332 | AA10: =SUM(55.62/68)*H10 -> 12.256849 | AB10: =SUM(Y10:AA10) -> 2573.59 | AC10: 7.3 | AD10: =SUM(AB10*AC10) -> 18787.207 | AE10: =SUM(X10+AD10) -> 30173.273 | AF10: =SUM(P10-AE10) -> 254.13115
C11: 241204000051 | D11: 45636 | E11: 罗珮文 | F11: Shirley | G11: Yusky | H11: 2.1818 | I11: 358 | K11: 966443.8 | M11: =SUM(K11/N11) -> 1582 | N11: 610.9 | O11: 7.18 | P11: =SUM(N11*O11) -> 4386.262 | S11: =SUM(49568.5/68)*H11 -> 1590.4199 | U11: =SUM(2100/68)*H11 -> 67.379118 | X11: =SUM(S11:W11) -> 1657.799 | Y11: =SUM(11623/68)*H11 -> 372.92737 | AA11: =SUM(55.62/68)*H11 -> 1.7845841 | AB11: =SUM(Y11:AA11) -> 374.71196 | AC11: 7.3 | AD11: =SUM(AB11*AC11) -> 2735.3973 | AE11: =SUM(X11+AD11) -> 4393.1963 | AF11: =SUM(P11-AE11) -> -6.9343095
C12: 241205000007 | D12: 45636 | E12: 黄颖 | F12: ying | G12: Jacky | H12: 1.2288 | I12: 508 | K12: 552776.25 | M12: =SUM(K12/N12) -> 1578.4138 | N12: 350.20996 | O12: 7.27 | P12: =SUM(N12*O12) -> 2546.0264 | S12: =SUM(49568.5/68)*H12 -> 895.73195 | U12: =SUM(2100/68)*H12 -> 37.948235 | X12: =SUM(S12:W12) -> 933.68019 | Y12: =SUM(11623/68)*H12 -> 210.03445 | AA12: =SUM(55.62/68)*H12 -> 1.0050861 | AB12: =SUM(Y12:AA12) -> 211.03953 | AC12: 7.3 | AD12: =SUM(AB12*AC12) -> 1540.5886 | AE12: =SUM(X12+AD12) -> 2474.2688 | AF12: =SUM(P12-AE12) -> 71.757629
C13: 241206000037 | D13: 45636 | E13: Sam.Pao | F13: Sam.Pao | G13: Mr. Jiang | H13: 0.6414 | I13: 108 | J13: 2673 | P13: =SUBTOTAL(9,J13) -> 2673 | S13: =SUM(49568.5/68)*H13 -> 467.54759 | U13: =SUM(2100/68)*H13 -> 19.807941 | V13: 300 | X13: =SUM(S13:W13) -> 787.35553 | Y13: =SUM(11623/68)*H13 -> 109.63224 | AA13: =SUM(55.62/68)*H13 -> 0.52462747 | AB13: =SUM(Y13:AA13) -> 110.15687 | AC13: 7.3 | AD13: =SUM(AB13*AC13) -> 804.14512 | AE13: =SUM(X13+AD13) -> 1591.5006 | AF13: =SUM(P13-AE13) -> 1081.4994
C14: 241206000040 | D14: 45636 | E14: Sam.Pao | F14: Sam.Pao | G14: Mr. Jiang | H14: 0.7876 | I14: 213 | J14: 2732 | P14: =SUBTOTAL(9,J14) -> 2732 | S14: =SUM(49568.5/68)*H14 -> 574.11986 | U14: =SUM(2100/68)*H14 -> 24.322941 | V14: 300 | X14: =SUM(S14:W14) -> 898.4428 | Y14: =SUM(11623/68)*H14 -> 134.62169 | AA14: =SUM(55.62/68)*H14 -> 0.64421047 | AB14: =SUM(Y14:AA14) -> 135.2659 | AC14: 7.3 | AD14: =SUM(AB14*AC14) -> 987.44106 | AE14: =SUM(X14+AD14) -> 1885.8839 | AF14: =SUM(P14-AE14) -> 846.11614
C15: 241216000026 | D15: 45638 | E15: 陆总 | F15: 陆梓龙 | G15: luk | H15: 12.7436 | I15: 1324.23 | J15: 22939.2 | P15: =SUBTOTAL(9,J15) -> 22939.2 | S15: =SUM(49568.5/68)*H15 -> 9289.4285 | U15: =SUM(2100/68)*H15 -> 393.55235 | X15: =SUM(S15:W15) -> 9682.9808 | Y15: =SUM(11623/68)*H15 -> 2178.2186 | AA15: =SUM(55.62/68)*H15 -> 10.423515 | AB15: =SUM(Y15:AA15) -> 2188.6421 | AC15: 7.3 | AD15: =SUM(AB15*AC15) -> 15977.087 | AE15: =SUM(X15+AD15) -> 25660.068 | AF15: =SUM(P15-AE15) -> -2720.8681
C16: 241208000009 | D16: 45636 | E16: 无人 | F16: Mailmail Abv sales person 1 | G16: Obetta U | H16: 4.1388 | I16: 540 | K16: 2050281 | M16: =SUM(K16/N16) -> 1597.9993 | N16: 1283.03 | O16: 7.27 | P16: =SUM(N16*O16) -> 9327.6281 | S16: =SUM(49568.5/68)*H16 -> 3016.9722 | U16: =SUM(2100/68)*H16 -> 127.81588 | X16: =SUM(S16:W16) -> 3144.7881 | Y16: =SUM(11623/68)*H16 -> 707.43048 | AA16: =SUM(55.62/68)*H16 -> 3.3852949 | AB16: =SUM(Y16:AA16) -> 710.81577 | AC16: 7.3 | AD16: =SUM(AB16*AC16) -> 5188.9551 | AE16: =SUM(X16+AD16) -> 8333.7432 | AF16: =SUM(P16-AE16) -> 993.88491
C17: 241210000005 | D17: 45636 | E17: 罗珮文 | F17: Shirley | G17: Abubakar Badaru Abubakar | H17: 17.6161 | I17: 1662 | K17: 7918392 | M17: =SUM(K17/N17) -> 1550 | N17: 5108.64 | O17: 7.27 | P17: =SUM(N17*O17) -> 37139.813 | S17: =SUM(49568.5/68)*H17 -> 12841.23 | U17: =SUM(2100/68)*H17 -> 544.02662 | V17: 200 | X17: =SUM(S17:W17) -> 13585.257 | Y17: =SUM(11623/68)*H17 -> 3011.0578 | AA17: =SUM(55.62/68)*H17 -> 14.408934 | AB17: =SUM(Y17:AA17) -> 3025.4667 | AC17: 7.3 | AD17: =SUM(AB17*AC17) -> 22085.907 | AE17: =SUM(X17+AD17) -> 35671.164 | AF17: =SUM(P17-AE17) -> 1468.6488
A18: 合计 | J18: =SUM(J4:J4) -> 0 | N18: =SUM(N4:N4) -> 0 | P18: =SUM(P4:P4) -> 0 | Q18: =SUM(Q4:Q4) -> 0 | X18: =SUM(X4:X4) -> 0 | AD18: =SUM(AD4:AD4) -> 0 | AF18: =SUM(AF4:AF17) -> 24315.892

Sheet JOB120376
A1: 2024年12月份LOS毛利表（海运）
A2: PSL表 | B2: 体积cbm | C2: 72.8326
A3: JOB | B3: 集装编号 | C3: 运单编号 | D3: 日期 | E3: 业务 | F3: 发货人 | G3: 收货人 | H3: 计费体积 | I3: 计费重量 | J3: 应 收 | Q3: 总应收 | R3: 起 运 港 成 本 | W3: 代垫运费 | X3: 起运港成本 合计 | Y3: 目的港成本 | AE3: 总支出 | AF3: 利润
J4: 应收RMB | K4: LOS Income(NGN)收到(奈拉) | L4: LOS 收到USD | M4: 美元汇率 dollar currency rate | N4: 应收 到付款USD | O4: 汇率 | P4: 人民币 | R4: 代理商 | S4: 运费+出口报关费 | T4: 提货费 | U4: 装卸费 | V4: 包装费 | Y4: 进口报关费 | Z4: 到门配送费 | AA4: 转运费 | AB4: 目的港支出 | AC4: 汇率 | AD4: 人民币 | AE4: 起运港+目的港
A5: JOB120376 | B5: COLL004324 | C5: 241122000025 | D5: 45636 | E5: 吕沛霖 | F5: 喵喵速运-Layne | G5: WENDY | H5: 3.6276 | I5: 1507 | K5: 2696680 | M5: =SUM(K5/N5) -> 1630.0048 | N5: 1654.4 | O5: 7.27 | P5: =SUM(N5*O5) -> 12027.488 | Q5: =SUM(P5:P12) -> 148560.87 | R5: 登凯=46552.5 报关=500 拖车费=1670 杂费=61 过磅费=68 | S5: =SUM(48851.5/68)*H5 -> 2606.0838 | U5: =SUM(1000/68)*H5 -> 53.347059 | X5: =SUM(S5:W5) -> 2659.4309 | Y5: =SUM(11570.25/68)*H5 -> 617.23881 | Z5: 315.51 | AA5: =SUM(140.12/68)*H5 -> 7.4749899 | AB5: =SUM(Y5:AA5) -> 940.2238 | AC5: 7.25 | AD5: =SUM(AB5*AC5) -> 6816.6225 | AE5: =SUM(X5+AD5) -> 9476.0534 | AF5: =SUM(P5-AE5) -> 2551.4346
C6: 241202000029 | D6: 45636 | E6: 吕沛霖 | F6: 喵喵速运-Layne | G6: Mr. Wen Pu | H6: 8.2313 | I6: 1683 | K6: 4862127 | M6: =SUM(K6/N6) -> 1630 | N6: 2982.9 | O6: 7.28 | P6: =SUM(N6*O6) -> 21715.512 | S6: =SUM(48851.5/68)*H6 -> 5913.4022 | U6: =SUM(1000/68)*H6 -> 121.04853 | X6: =SUM(S6:W6) -> 6034.4508 | Y6: =SUM(11570.25/68)*H6 -> 1400.5617 | Z6: 715.9 | AA6: =SUM(140.12/68)*H6 -> 16.96132 | AB6: =SUM(Y6:AA6) -> 2133.4231 | AC6: 7.25 | AD6: =SUM(AB6*AC6) -> 15467.317 | AE6: =SUM(X6+AD6) -> 21501.768 | AF6: =SUM(P6-AE6) -> 213.744
C7: 241203000014 | D7: 45636 | E7: Bella | F7: Bella Chan | G7: zhong zi xin | H7: 13.3392 | I7: 17441 | J7: 35368.5 | P7: =SUM(J7) -> 35368.5 | S7: =SUM(48851.5/68)*H7 -> 9582.9401 | U7: =SUM(1000/68)*H7 -> 196.16471 | X7: =SUM(S7:W7) -> 9779.1048 | Y7: =SUM(11570.25/68)*H7 -> 2269.6747 | AA7: =SUM(140.12/68)*H7 -> 27.486599 | AB7: =SUM(Y7:AA7) -> 2297.1613 | AC7: 7.25 | AD7: =SUM(AB7*AC7) -> 16654.419 | AE7: =SUM(X7+AD7) -> 26433.524 | AF7: =SUM(P7-AE7) -> 8934.9758
C8: 241204000017 | D8: 45636 | E8: 吕沛霖 | F8: 喵喵速运-Layne | G8: Frank | H8: 0.5672 | I8: 104 | K8: 270180 | M8: =SUM(K8/N8) -> 1580 | N8: 171 | O8: 7.29 | P8: =SUM(N8*O8) -> 1246.59 | S8: =SUM(48851.5/68)*H8 -> 407.47898 | U8: =SUM(1000/68)*H8 -> 8.3411765 | X8: =SUM(S8:W8) -> 415.82016 | Y8: =SUM(11570.25/68)*H8 -> 96.509497 | Z8: 49.33 | AA8: =SUM(140.12/68)*H8 -> 1.1687656 | AB8: =SUM(Y8:AA8) -> 147.00826 | AC8: 7.25 | AD8: =SUM(AB8*AC8) -> 1065.8099 | AE8: =SUM(X8+AD8) -> 1481.6301 | AF8: =SUM(P8-AE8) -> -235.04006
C9: 241209000071 | D9: 45636 | E9: Sam.Pao | F9: Sam.Pao | G9: ShanShan | H9: 0.1971 | I9: 30.5 | J9: 788.4 | P9: =SUBTOTAL(9,J9) -> 788.4 | S9: =SUM(48851.5/68)*H9 -> 141.59751 | U9: =SUM(1000/68)*H9 -> 2.8985294 | X9: =SUM(S9:W9) -> 144.49604 | Y9: =SUM(11570.25/68)*H9 -> 33.53671 | Z9: 0.84 | AA9: =SUM(140.12/68)*H9 -> 0.40614194 | AB9: =SUM(Y9:AA9) -> 34.782852 | AC9: 7.25 | AD9: =SUM(AB9*AC9) -> 252.17568 | AE9: =SUM(X9+AD9) -> 396.67172 | AF9: =SUM(P9-AE9) -> 391.72828
C10: 241216000026 | D10: 45638 | E10: 陆总 | F10: 陆梓龙 | G10: luk | H10: 11.0893 | I10: 1146.94 | J10: 19958.4 | P10: =SUBTOTAL(9,J10) -> 19958.4 | S10: =SUM(48851.5/68)*H10 -> 7966.602 | U10: =SUM(1000/68)*H10 -> 163.07794 | X10: =SUM(S10:W10) -> 8129.68 | Y10: =SUM(11570.25/68)*H10 -> 1886.8525 | AA10: =SUM(140.12/68)*H10 -> 22.850481 | AB10: =SUM(Y10:AA10) -> 1909.703 | AC10: 7.25 | AD10: =SUM(AB10*AC10) -> 13845.347 | AE10: =SUM(X10+AD10) -> 21975.027 | AF10: =SUM(P10-AE10) -> -2016.627
C11: 241210000006 | D11: 45636 | E11: 罗珮文 | F11: Shirley | G11: SKY JET | H11: 35.4 | I11: 5354 | J11: 56540.88 | P11: =SUBTOTAL(9,J11) -> 56540.88 | S11: =SUM(48851.5/68)*H11 -> 25431.516 | U11: =SUM(1000/68)*H11 -> 520.58824 | X11: =SUM(S11:W11) -> 25952.104 | Y11: =SUM(11570.25/68)*H11 -> 6023.336 | AA11: =SUM(140.12/68)*H11 -> 72.944824 | AB11: =SUM(Y11:AA11) -> 6096.2809 | AC11: 7.25 | AD11: =SUM(AB11*AC11) -> 44198.036 | AE11: =SUM(X11+AD11) -> 70150.141 | AF11: =SUM(P11-AE11) -> -13609.261
C12: 241216000056 | D12: 45636 | E12: 吕沛霖 | F12: 喵喵速运-Layne | G12: LEO WEI | H12: 0.3809 | I12: 90 | K12: 197726.1 | M12: =SUM(K12/N12) -> 1573 | N12: 125.7 | O12: 7.28 | P12: =SUM(N12*O12) -> 915.096 | S12: =SUM(48851.5/68)*H12 -> 273.64024 | U12: =SUM(1000/68)*H12 -> 5.6014706 | X12: =SUM(S12:W12) -> 279.24171 | Y12: =SUM(11570.25/68)*H12 -> 64.810415 | AA12: =SUM(140.12/68)*H12 -> 0.78487806 | AB12: =SUM(Y12:AA12) -> 65.595293 | AC12: 7.25 | AD12: =SUM(AB12*AC12) -> 475.56588 | AE12: =SUM(X12+AD12) -> 754.80759 | AF12: =SUM(P12-AE12) -> 160.28841
A13: 合计 | J13: =SUM(J4:J4) -> 0 | N13: =SUM(N4:N4) -> 0 | P13: =SUM(P4:P4) -> 0 | Q13: =SUM(Q4:Q4) -> 0 | X13: =SUM(X4:X4) -> 0 | AD13: =SUM(AD4:AD4) -> 0 | AF13: =SUM(AF4:AF12) -> -3608.7565

Sheet JOB120381
A1: 2024年12月份LOS毛利表（海运）
A2: PSL表 | B2: 体积cbm | C2: 72.3035
A3: JOB | B3: 集装编号 | C3: 运单编号 | D3: 日期 | E3: 业务 | F3: 发货人 | G3: 收货人 | H3: 计费体积 | I3: 计费重量 | J3: 应 收 | Q3: 总应收 | R3: 起 运 港 成 本 | W3: 代垫运费 | X3: 起运港成本 合计 | Y3: 目的港成本 | AE3: 总支出 | AF3: 利润
J4: 应收RMB | K4: LOS Income(NGN)收到(奈拉) | L4: LOS 收到USD | M4: 美元汇率 dollar currency rate | N4: 应收 到付款USD | O4: 汇率 | P4: 人民币 | R4: 代理商 | S4: 运费+出口报关费 | T4: 提货费 | U4: 装卸费 | V4: 包装费 | Y4: 进口报关费 | Z4: 到门配送费 | AA4: 转运费 | AB4: 目的港支出 | AC4: 汇率 | AD4: 人民币 | AE4: 起运港+目的港
A5: JOB120381 | B5: COLL004325 | C5: 241023000034 | D5: 45638 | E5: Sam.Pao | F5: Sam.Pao | G5: Nick Wang | H5: 0.3134 | I5: 126 | J5: 906 | P5: =SUBTOTAL(9,J5) -> 906 | Q5: =SUM(P5:P14) -> 146435.81 | R5: 登凯=46552.5 报关=300 拖车费=1670 杂费=166 过磅费=71 | S5: =SUM(48759.5/68)*H5 -> 224.72393 | U5: =SUM(1800/68)*H5 -> 8.2958824 | X5: =SUM(S5:W5) -> 233.01981 | Y5: =SUM(11621.97/68)*H5 -> 53.563609 | AA5: =SUM(140.12/68)*H5 -> 0.64578835 | AB5: =SUM(Y5:AA5) -> 54.209397 | AC5: 7.25 | AD5: =SUM(AB5*AC5) -> 393.01813 | AE5: =SUM(X5+AD5) -> 626.03794 | AF5: =SUM(P5-AE5) -> 279.96206
C6: 241115000013 | D6: 45638 | E6: Sam.Pao | F6: Sam.Pao | G6: ChenGaoHong | H6: 0.367 | I6: 106 | J6: 780 | P6: =SUBTOTAL(9,J6) -> 780 | S6: =SUM(48759.5/68)*H6 -> 263.15789 | U6: =SUM(1800/68)*H6 -> 9.7147059 | V6: 240 | X6: =SUM(S6:W6) -> 512.8726 | Y6: =SUM(11621.97/68)*H6 -> 62.724456 | AA6: =SUM(140.12/68)*H6 -> 0.75623588 | AB6: =SUM(Y6:AA6) -> 63.480692 | AC6: 7.25 | AD6: =SUM(AB6*AC6) -> 460.23501 | AE6: =SUM(X6+AD6) -> 973.10761 | AF6: =SUM(P6-AE6) -> -193.10761
C7: 241126000049 | D7: 45638 | E7: Sam.Pao | F7: Sam.Pao | G7: AiGeLi | H7: 2.7422 | I7: 1148 | J7: 7878 | P7: =SUBTOTAL(9,J7) -> 7878 | S7: =SUM(48759.5/68)*H7 -> 1966.2985 | U7: =SUM(1800/68)*H7 -> 72.587647 | V7: 1000 | X7: =SUM(S7:W7) -> 3038.8862 | Y7: =SUM(11621.97/68)*H7 -> 468.67303 | AA7: =SUM(140.12/68)*H7 -> 5.6505451 | AB7: =SUM(Y7:AA7) -> 474.32358 | AC7: 7.25 | AD7: =SUM(AB7*AC7) -> 3438.8459 | AE7: =SUM(X7+AD7) -> 6477.7321 | AF7: =SUM(P7-AE7) -> 1400.2679
C8: 241209000082 | D8: 45638 | E8: 吕沛霖 | F8: 喵喵速运-Layne | G8: BI AN | H8: 2.4778 | I8: 1373 | J8: 6015.2 | P8: =SUBTOTAL(9,J8) -> 6015.2 | S8: =SUM(48759.5/68)*H8 -> 1776.7101 | U8: =SUM(1800/68)*H8 -> 65.588824 | X8: =SUM(S8:W8) -> 1842.299 | Y8: =SUM(11621.97/68)*H8 -> 423.48408 | AA8: =SUM(140.12/68)*H8 -> 5.1057255 | AB8: =SUM(Y8:AA8) -> 428.5898 | AC8: 7.25 | AD8: =SUM(AB8*AC8) -> 3107.2761 | AE8: =SUM(X8+AD8) -> 4949.575 | AF8: =SUM(P8-AE8) -> 1065.625
C9: 241209000084 | D9: 45638 | E9: 罗珮文 | F9: Shirley | G9: Yusky | H9: 3.5753 | I9: 397 | K9: 1527152.1 | M9: =SUM(K9/N9) -> 1582 | N9: 965.33 | O9: 7.18 | P9: =SUM(N9*O9) -> 6931.0694 | S9: =SUM(48759.5/68)*H9 -> 2563.6741 | U9: =SUM(1800/68)*H9 -> 94.640294 | X9: =SUM(S9:W9) -> 2658.3144 | Y9: =SUM(11621.97/68)*H9 -> 611.05926 | AA9: =SUM(140.12/68)*H9 -> 7.3672211 | AB9: =SUM(Y9:AA9) -> 618.42648 | AC9: 7.25 | AD9: =SUM(AB9*AC9) -> 4483.592 | AE9: =SUM(X9+AD9) -> 7141.9064 | AF9: =SUM(P9-AE9) -> -210.83697
C10: 241211000002 | D10: 45638 | E10: Bella | F10: Bella Chan | G10: zhong zi xin | H10: 13.0793 | I10: 19192 | J10: 38909 | P10: =SUM(J10) -> 38909 | S10: =SUM(48759.5/68)*H10 -> 9378.5313 | U10: =SUM(1800/68)*H10 -> 346.21676 | X10: =SUM(S10:W10) -> 9724.7481 | Y10: =SUM(11621.97/68)*H10 -> 2235.4005 | AA10: =SUM(140.12/68)*H10 -> 26.951052 | AB10: =SUM(Y10:AA10) -> 2262.3515 | AC10: 7.25 | AD10: =SUM(AB10*AC10) -> 16402.049 | AE10: =SUM(X10+AD10) -> 26126.797 | AF10: =SUM(P10-AE10) -> 12782.203
C11: 241211000045 | D11: 45638 | E11: 罗珮文 | F11: Shirley | G11: Yusky | H11: 10.4649 | I11: 835 | K11: 4470020.1 | M11: =SUM(K11/N11) -> 1582 | N11: 2825.55 | O11: 7.18 | P11: =SUM(N11*O11) -> 20287.449 | S11: =SUM(48759.5/68)*H11 -> 7503.8719 | U11: =SUM(1800/68)*H11 -> 277.01206 | X11: =SUM(S11:W11) -> 7780.884 | Y11: =SUM(11621.97/68)*H11 -> 1788.5699 | AA11: =SUM(140.12/68)*H11 -> 21.56385 | AB11: =SUM(Y11:AA11) -> 1810.1338 | AC11: 7.25 | AD11: =SUM(AB11*AC11) -> 13123.47 | AE11: =SUM(X11+AD11) -> 20904.354 | AF11: =SUM(P11-AE11) -> -616.90475
C12: 241212000002 | D12: 45638 | E12: 罗珮文 | F12: Shirley | G12: SKY JET | H12: 29.57 | I12: 4902 | J12: 47229.2 | P12: =SUBTOTAL(9,J12) -> 47229.2 | S12: =SUM(48759.5/68)*H12 -> 21203.212 | U12: =SUM(1800/68)*H12 -> 782.73529 | X12: =SUM(S12:W12) -> 21985.947 | Y12: =SUM(11621.97/68)*H12 -> 5053.8478 | AA12: =SUM(140.12/68)*H12 -> 60.931594 | AB12: =SUM(Y12:AA12) -> 5114.7794 | AC12: 7.25 | AD12: =SUM(AB12*AC12) -> 37082.151 | AE12: =SUM(X12+AD12) -> 59068.098 | AF12: =SUM(P12-AE12) -> -11838.898
C13: 241212000013 | D13: 45638 | E13: 陆总 | F13: 陆梓龙 | G13: luk | H13: 0.0957 | I13: 26 | J13: 186.05 | P13: =SUBTOTAL(9,J13) -> 186.05 | S13: =SUM(48759.5/68)*H13 -> 68.621826 | U13: =SUM(1800/68)*H13 -> 2.5332353 | X13: =SUM(S13:W13) -> 71.155061 | Y13: =SUM(11621.97/68)*H13 -> 16.356214 | AA13: =SUM(140.12/68)*H13 -> 0.19719829 | AB13: =SUM(Y13:AA13) -> 16.553412 | AC13: 7.25 | AD13: =SUM(AB13*AC13) -> 120.01224 | AE13: =SUM(X13+AD13) -> 191.1673 | AF13: =SUM(P13-AE13) -> -5.1172977
C14: 241216000026 | D14: 45638 | E14: 陆总 | F14: 陆梓龙 | G14: luk | H14: 9.6179 | I14: 931.83 | J14: 17313.84 | P14: =SUBTOTAL(9,J14) -> 17313.84 | S14: =SUM(48759.5/68)*H14 -> 6896.5293 | U14: =SUM(1800/68)*H14 -> 254.59147 | X14: =SUM(S14:W14) -> 7151.1208 | Y14: =SUM(11621.97/68)*H14 -> 1643.808 | AA14: =SUM(140.12/68)*H14 -> 19.818532 | AB14: =SUM(Y14:AA14) -> 1663.6266 | AC14: 7.25 | AD14: =SUM(AB14*AC14) -> 12061.292 | AE14: =SUM(X14+AD14) -> 19212.413 | AF14: =SUM(P14-AE14) -> -1898.5733
A15: 合计 | J15: =SUM(J4:J4) -> 0 | N15: =SUM(N4:N4) -> 0 | P15: =SUM(P4:P4) -> 0 | Q15: =SUM(Q4:Q4) -> 0 | X15: =SUM(X4:X4) -> 0 | AD15: =SUM(AD4:AD4) -> 0 | AF15: =SUM(AF4:AF14) -> 764.62021

Sheet JOB120387
A1: 2024年12月份LOS毛利表（海运）
A2: PSL表 | B2: 体积cbm | C2: 73.6909
A3: JOB | B3: 集装编号 | C3: 运单编号 | D3: 日期 | E3: 业务 | F3: 发货人 | G3: 收货人 | H3: 计费体积 | I3: 计费重量 | J3: 应 收 | Q3: 总应收 | R3: 起 运 港 成 本 | W3: 代垫运费 | X3: 起运港成本 合计 | Y3: 目的港成本 | AE3: 总支出 | AF3: 利润
J4: 应收RMB | K4: LOS Income(NGN)收到(奈拉) | L4: LOS 收到USD | M4: 美元汇率 dollar currency rate | N4: 应收 到付款USD | O4: 汇率 | P4: 人民币 | R4: 代理商 | S4: 运费+出口报关费 | T4: 提货费 | U4: 装卸费 | V4: 包装费 | Y4: 进口报关费 | Z4: 到门配送费 | AA4: 转运费 | AB4: 目的港支出 | AC4: 汇率 | AD4: 人民币 | AE4: 起运港+目的港
A5: JOB120387 | B5: COLL004326 | C5: 241127000030 | D5: 45643 | E5: 黄颖 | F5: ying | G5: baikaibo | H5: 0.4598 | I5: 114 | J5: 860.5 | P5: =SUBTOTAL(9,J5) -> 860.5 | Q5: =SUM(P5:P27) -> 185884.77 | R5: 登凯=45460.5 报关=2800 拖车费=1670 杂费=86 过磅费=64 | S5: =SUM(50080.5/68)*H5 -> 338.63256 | U5: =SUM(2000/68)*H5 -> 13.523529 | X5: =SUM(S5:W5) -> 352.15609 | Y5: =SUM(12270/68)*H5 -> 82.966853 | Z5: 76.28 | AA5: =SUM(55.42/68)*H5 -> 0.374737 | AB5: =SUM(Y5:AA5) -> 159.62159 | AC5: 7.25 | AD5: =SUM(AB5*AC5) -> 1157.2565 | AE5: =SUM(X5+AD5) -> 1509.4126 | AF5: =SUM(P5-AE5) -> -648.91261
C6: 241209000067 | D6: 45643 | E6: Sam.Pao | F6: Sam.Pao | G6: MaiKaiNian | H6: 0.023 | I6: 43 | J6: 152.5 | P6: =SUBTOTAL(9,J6) -> 152.5 | S6: =SUM(50080.5/68)*H6 -> 16.938993 | U6: =SUM(2000/68)*H6 -> 0.67647059 | X6: =SUM(S6:W6) -> 17.615463 | Y6: =SUM(12270/68)*H6 -> 4.1501471 | AA6: =SUM(55.42/68)*H6 -> 0.018745 | AB6: =SUM(Y6:AA6) -> 4.1688921 | AC6: 7.25 | AD6: =SUM(AB6*AC6) -> 30.224467 | AE6: =SUM(X6+AD6) -> 47.839931 | AF6: =SUM(P6-AE6) -> 104.66007
C7: 241209000092 | D7: 45643 | E7: 黄颖 | F7: ying | G7: yuhuichao | H7: 0.1652 | I7: 33 | J7: 565 | P7: =SUBTOTAL(9,J7) -> 565 | S7: =SUM(50080.5/68)*H7 -> 121.66616 | U7: =SUM(2000/68)*H7 -> 4.8588235 | X7: =SUM(S7:W7) -> 126.52498 | Y7: =SUM(12270/68)*H7 -> 29.808882 | Z7: 19.6 | AA7: =SUM(55.42/68)*H7 -> 0.134638 | AB7: =SUM(Y7:AA7) -> 49.54352 | AC7: 7.25 | AD7: =SUM(AB7*AC7) -> 359.19052 | AE7: =SUM(X7+AD7) -> 485.7155 | AF7: =SUM(P7-AE7) -> 79.284498
C8: 241210000030 | D8: 45643 | E8: 黄颖 | F8: ying | G8: Frank | H8: 0.5114 | I8: 65 | K8: 312494 | M8: =SUM(K8/N8) -> 1651.485 | N8: 189.22 | O8: 7.27 | P8: =SUM(N8*O8) -> 1375.6294 | S8: =SUM(50080.5/68)*H8 -> 376.63482 | U8: =SUM(2000/68)*H8 -> 15.041176 | X8: =SUM(S8:W8) -> 391.676 | Y8: =SUM(12270/68)*H8 -> 92.277618 | AA8: =SUM(55.42/68)*H8 -> 0.416791 | AB8: =SUM(Y8:AA8) -> 92.694409 | AC8: 7.25 | AD8: =SUM(AB8*AC8) -> 672.03446 | AE8: =SUM(X8+AD8) -> 1063.7105 | AF8: =SUM(P8-AE8) -> 311.91894
C9: 241210000041 | D9: 45643 | E9: 黄颖 | F9: ying | G9: Mr Rell | H9: 0.7637 | I9: 207 | J9: 1810.4 | P9: =SUBTOTAL(9,J9) -> 1810.4 | S9: =SUM(50080.5/68)*H9 -> 562.4482 | U9: =SUM(2000/68)*H9 -> 22.461765 | X9: =SUM(S9:W9) -> 584.90997 | Y9: =SUM(12270/68)*H9 -> 137.80293 | AA9: =SUM(55.42/68)*H9 -> 0.6224155 | AB9: =SUM(Y9:AA9) -> 138.42534 | AC9: 7.25 | AD9: =SUM(AB9*AC9) -> 1003.5837 | AE9: =SUM(X9+AD9) -> 1588.4937 | AF9: =SUM(P9-AE9) -> 221.9063
C10: 241211000027 | D10: 45643 | E10: Sam.Pao | F10: Sam.Pao | G10: ShanShan | H10: 23.8172 | I10: 4565 | J10: 54267 | P10: =SUBTOTAL(9,J10) -> 54267 | S10: =SUM(50080.5/68)*H10 -> 17540.842 | U10: =SUM(2000/68)*H10 -> 700.50588 | X10: =SUM(S10:W10) -> 18241.348 | Y10: =SUM(12270/68)*H10 -> 4297.6036 | Z10: 136.87 | AA10: =SUM(55.42/68)*H10 -> 19.411018 | AB10: =SUM(Y10:AA10) -> 4453.8846 | AC10: 7.25 | AD10: =SUM(AB10*AC10) -> 32290.663 | AE10: =SUM(X10+AD10) -> 50532.012 | AF10: =SUM(P10-AE10) -> 3734.9883
C11: 241212000006 | D11: 45643 | E11: 黄颖 | F11: ying | G11: MISS Huang | H11: 3.0701 | I11: 1383 | K11: 1406444 | M11: =SUM(K11/N11) -> 1607.4013 | N11: 874.98 | O11: 7.3 | P11: =SUM(N11*O11) -> 6387.354 | S11: =SUM(50080.5/68)*H11 -> 2261.0609 | U11: =SUM(2000/68)*H11 -> 90.297059 | X11: =SUM(S11:W11) -> 2351.358 | Y11: =SUM(12270/68)*H11 -> 553.97246 | AA11: =SUM(55.42/68)*H11 -> 2.5021315 | AB11: =SUM(Y11:AA11) -> 556.47459 | AC11: 7.25 | AD11: =SUM(AB11*AC11) -> 4034.4408 | AE11: =SUM(X11+AD11) -> 6385.7987 | AF11: =SUM(P11-AE11) -> 1.5552554
