Workbook

Sheet 总表 
A1: 2024年11月份LOS毛利表（海运）
A2: JOB | B2: 集装编号 | C2: 利润
A4: JOB120361 | B4: COLL004287 | C4: =SUM('JOB120361'!AF22) -> 18752.529
A21: JOB120362 | B21: COLL004290 | C21: =SUM('JOB120362'!AF19) -> 3646.6843
A35: JOB120363 | B35: COLL004291 | C35: =SUM('JOB120363'!AF27) -> 16693.821
A57: JOB120364 | B57: COLL004298 | C57: =SUM('JOB120364'!AF25) -> 1768.3255
A77: JOB120365 | B77: COLL004301 | C77: =SUM('JOB120365'!AF22) -> 22745.723
A94: JOB120366 | B94: COLL004305 | C94: =SUM('JOB120366'!AF19) -> 6096.0564
A108: JOB120367 | B108: COLL004308 | C108: =SUM('JOB120367'!AF20) -> -13853.56
A123: JOB120368 | B123: COLL004310 | C123: =SUM('JOB120368'!AF26) -> 4132.9719
A144: 合计 | C144: =SUM(C3:C143) -> 59982.552

Sheet 总表  (2)
A1: 2024年11月份LOS毛利表（海运）
A2: JOB | B2: 集装编号 | C2: 运单编号 | D2: 日期 | E2: 业务 | F2: 发货人 | G2: 收货人 | H2: 计费体积 | I2: 计费重量 | J2: 应 收 | Q2: 总应收 | R2: 起 运 港 成 本 | W2: 代垫运费 | X2: 起运港成本 合计 | Y2: 目的港成本 | AE2: 总支出 | AF2: 利润
J3: 应收RMB | K3: LOS Income(NGN)收到(奈拉) | L3: LOS 收到USD | M3: 美元汇率 dollar currency rate | N3: 应收 到付款USD | O3: 汇率 | P3: 人民币 | R3: 代理商 | S3: 运费+出口报关费 | T3: 提货费 | U3: 装卸费 | V3: 包装费 | Y3: 进口报关费 | Z3: 到门配送费 | AA3: 转运费 | AB3: 目的港支出 | AC3: 汇率 | AD3: 人民币 | AE3: 起运港+目的港
A4: JOB120361 | B4: COLL004287 | C4: 240910000015 | D4: 45601 | E4: 吕沛霖 | F4: 喵喵速运-Layne | G4: Hu Hai Liang | H4: 5.1959 | I4: 743 | K4: 2382640 | M4: =SUM(K4/N4) -> 1580 | N4: 1508 | O4: 7.29 | P4: =SUM(N4*O4) -> 10993.32 | Q4: =SUM(P4:P20) -> 165324.28 | R4: 登凯=46189.5 陆总=1200 拖车费=1670 杂费=89 过磅费=66 | S4: =SUM(49214.5/68)*H4 -> 3760.4944 | T4: =SUM(113.64/68)*H4 -> 8.6832658 | U4: =SUM(2400/68)*H4 -> 183.38471 | X4: =SUM(S4:W4) -> 3952.5624 | Y4: =SUM(10949.72/68)*H4 -> 836.67133 | AB4: =SUM(Y4:AA4) -> 836.67133 | AC4: 7.33 | AD4: =SUM(AB4*AC4) -> 6132.8008 | AE4: =SUM(X4+AD4) -> 10085.363 | AF4: =SUM(P4-AE4) -> 907.95679
C5: 241023000029 | D5: 45601 | E5: 黄颖 | F5: ying | G5: Wole Rasak | H5: 0.0288 | I5: 5 | J5: 224.75 | P5: =SUBTOTAL(9,J5) -> 224.75 | S5: =SUM(49214.5/68)*H5 -> 20.843788 | T5: =SUM(113.64/68)*H5 -> 0.048129882 | U5: =SUM(2400/68)*H5 -> 1.0164706 | X5: =SUM(S5:W5) -> 21.908389 | Y5: =SUM(10949.72/68)*H5 -> 4.6375285 | AB5: =SUM(Y5:AA5) -> 4.6375285 | AC5: 7.33 | AD5: =SUM(AB5*AC5) -> 33.993084 | AE5: =SUM(X5+AD5) -> 55.901472 | AF5: =SUM(P5-AE5) -> 168.84853
C6: 241025000058 | D6: 45601 | E6: 苏慧琪 | F6: KAY | G6: BOYOU 吕 | H6: 13.7 | I6: 2550 | K6: 7067746.5 | M6: =SUM(K6/N6) -> 1648.8039 | N6: 4286.59 | O6: 7.29 | P6: =SUM(N6*O6) -> 31249.241 | S6: =SUM(49214.5/68)*H6 -> 9915.2743 | T6: =SUM(113.64/68)*H6 -> 22.895118 | U6: =SUM(2400/68)*H6 -> 483.52941 | X6: =SUM(S6:W6) -> 10421.699 | Y6: =SUM(10949.72/68)*H6 -> 2206.0465 | Z6: 90.97 | AB6: =SUM(Y6:AA6) -> 2297.0165 | AC6: 7.33 | AD6: =SUM(AB6*AC6) -> 16837.131 | AE6: =SUM(X6+AD6) -> 27258.83 | AF6: =SUM(P6-AE6) -> 3990.4111
C7: 241026000006 | D7: 45601 | E7: 吕沛霖 | F7: 喵喵速运-Layne | G7: LEO WEI | H7: 0.6549 | I7: 72 | K7: 363730 | M7: =SUM(K7/N7) -> 1683.0002 | N7: 216.12 | O7: 7.3 | P7: =SUM(N7*O7) -> 1577.676 | S7: =SUM(49214.5/68)*H7 -> 473.97906 | T7: =SUM(113.64/68)*H7 -> 1.0944535 | U7: =SUM(2400/68)*H7 -> 23.114118 | X7: =SUM(S7:W7) -> 498.18763 | Y7: =SUM(10949.72/68)*H7 -> 105.45547 | AB7: =SUM(Y7:AA7) -> 105.45547 | AC7: 7.33 | AD7: =SUM(AB7*AC7) -> 772.98856 | AE7: =SUM(X7+AD7) -> 1271.1762 | AF7: =SUM(P7-AE7) -> 306.49981
C8: 241027000011 | D8: 45601 | E8: 朱小飞 | F8: Isabel Zhu | G8: Maryam Tukur | H8: 0.5618 | I8: 55 | K8: 434000 | M8: =SUM(K8/N8) -> 1671.8028 | N8: 259.6 | O8: 7.3 | P8: =SUM(N8*O8) -> 1895.08 | S8: =SUM(49214.5/68)*H8 -> 406.59862 | T8: =SUM(113.64/68)*H8 -> 0.93886694 | U8: =SUM(2400/68)*H8 -> 19.828235 | V8: 310 | W8: 59 | X8: =SUM(S8:W8) -> 796.36572 | Y8: =SUM(10949.72/68)*H8 -> 90.46401 | AB8: =SUM(Y8:AA8) -> 90.46401 | AC8: 7.33 | AD8: =SUM(AB8*AC8) -> 663.1012 | AE8: =SUM(X8+AD8) -> 1459.4669 | AF8: =SUM(P8-AE8) -> 435.61308
C9: 241031000033 | D9: 45601 | E9: 黄颖 | F9: ying | G9: Bruce | H9: 1.9968 | I9: 845 | K9: 960734 | M9: =SUM(K9/N9) -> 1653.0179 | N9: 581.2 | O9: 7.29 | P9: =SUM(N9*O9) -> 4236.948 | S9: =SUM(49214.5/68)*H9 -> 1445.1693 | T9: =SUM(113.64/68)*H9 -> 3.3370052 | U9: =SUM(2400/68)*H9 -> 70.475294 | X9: =SUM(S9:W9) -> 1518.9816 | Y9: =SUM(10949.72/68)*H9 -> 321.53531 | AB9: =SUM(Y9:AA9) -> 321.53531 | AC9: 7.33 | AD9: =SUM(AB9*AC9) -> 2356.8538 | AE9: =SUM(X9+AD9) -> 3875.8354 | AF9: =SUM(P9-AE9) -> 361.11258
C10: 241028000022 | D10: 45601 | E10: 黄颖 | F10: ying | G10: Barrister Hammed | H10: 1.211 | I10: 331 | J10: 2690 | P10: =SUBTOTAL(9,J10) -> 2690 | S10: =SUM(49214.5/68)*H10 -> 876.45235 | T10: =SUM(113.64/68)*H10 -> 2.0237947 | U10: =SUM(2400/68)*H10 -> 42.741176 | X10: =SUM(S10:W10) -> 921.21732 | Y10: =SUM(10949.72/68)*H10 -> 195.00163 | AB10: =SUM(Y10:AA10) -> 195.00163 | AC10: 7.33 | AD10: =SUM(AB10*AC10) -> 1429.362 | AE10: =SUM(X10+AD10) -> 2350.5793 | AF10: =SUM(P10-AE10) -> 339.42073
C11: 241028000025 | D11: 45601 | E11: 吕沛霖 | F11: 喵喵速运-Layne | G11: Candice Ding | H11: 0.7015 | I11: 168 | K11: 432424.8 | M11: =SUM(K11/N11) -> 1710 | N11: 252.88 | O11: 7.3 | P11: =SUM(N11*O11) -> 1846.024 | S11: =SUM(49214.5/68)*H11 -> 507.70547 | T11: =SUM(113.64/68)*H11 -> 1.1723303 | U11: =SUM(2400/68)*H11 -> 24.758824 | X11: =SUM(S11:W11) -> 533.63662 | Y11: =SUM(10949.72/68)*H11 -> 112.95924 | Z11: 42.43 | AB11: =SUM(Y11:AA11) -> 155.38924 | AC11: 7.33 | AD11: =SUM(AB11*AC11) -> 1139.0032 | AE11: =SUM(X11+AD11) -> 1672.6398 | AF11: =SUM(P11-AE11) -> 173.38422
C12: 241028000036 | D12: 45601 | E12: Sam.Pao | F12: Sam.Pao | G12: Chizoba | H12: 19.1974 | I12: 2413 | J12: 38000 | P12: =SUBTOTAL(9,J12) -> 38000 | S12: =SUM(49214.5/68)*H12 -> 13893.977 | T12: =SUM(113.64/68)*H12 -> 32.082243 | U12: =SUM(2400/68)*H12 -> 677.55529 | X12: =SUM(S12:W12) -> 14603.615 | Y12: =SUM(10949.72/68)*H12 -> 3091.267 | AB12: =SUM(Y12:AA12) -> 3091.267 | AC12: 7.33 | AD12: =SUM(AB12*AC12) -> 22658.987 | AE12: =SUM(X12+AD12) -> 37262.602 | AF12: =SUM(P12-AE12) -> 737.3984
C13: 241028000057 | D13: 45601 | E13: 朱小飞 | F13: Isabel Zhu | G13: Halifa Success | H13: 0.8721 | I13: 153 | J13: 1785.59 | P13: =SUBTOTAL(9,J13) -> 1785.59 | S13: =SUM(49214.5/68)*H13 -> 631.17596 | T13: =SUM(113.64/68)*H13 -> 1.457433 | U13: =SUM(2400/68)*H13 -> 30.78 | X13: =SUM(S13:W13) -> 663.4134 | Y13: =SUM(10949.72/68)*H13 -> 140.43016 | AB13: =SUM(Y13:AA13) -> 140.43016 | AC13: 7.33 | AD13: =SUM(AB13*AC13) -> 1029.3531 | AE13: =SUM(X13+AD13) -> 1692.7665 | AF13: =SUM(P13-AE13) -> 92.823539
C14: 241029000017 | D14: 45601 | E14: 黄颖 | F14: ying | G14: jiangnan | H14: 0.2948 | I14: 65 | J14: 683.5 | P14: =SUBTOTAL(9,J14) -> 683.5 | S14: =SUM(49214.5/68)*H14 -> 213.35933 | T14: =SUM(113.64/68)*H14 -> 0.49266282 | U14: =SUM(2400/68)*H14 -> 10.404706 | X14: =SUM(S14:W14) -> 224.2567 | Y14: =SUM(10949.72/68)*H14 -> 47.470257 | AB14: =SUM(Y14:AA14) -> 47.470257 | AC14: 7.33 | AD14: =SUM(AB14*AC14) -> 347.95698 | AE14: =SUM(X14+AD14) -> 572.21368 | AF14: =SUM(P14-AE14) -> 111.28632
C15: 241030000002 | D15: 45601 | E15: 吕沛霖 | F15: 喵喵速运-Layne | G15: Mu Shi Shi | H15: 7.4945 | I15: 520 | J15: 18324.8 | P15: =SUBTOTAL(9,J15) -> 18324.8 | S15: =SUM(49214.5/68)*H15 -> 5424.0893 | T15: =SUM(113.64/68)*H15 -> 12.524632 | U15: =SUM(2400/68)*H15 -> 264.51176 | X15: =SUM(S15:W15) -> 5701.1257 | Y15: =SUM(10949.72/68)*H15 -> 1206.8041 | Z15: 47.85 | AB15: =SUM(Y15:AA15) -> 1254.6541 | AC15: 7.33 | AD15: =SUM(AB15*AC15) -> 9196.6143 | AE15: =SUM(X15+AD15) -> 14897.74 | AF15: =SUM(P15-AE15) -> 3427.06
C16: 241030000039 | D16: 45601 | E16: 黄颖 | F16: ying | G16: jiangnan | H16: 1.069 | I16: 138 | J16: 2506 | P16: =SUBTOTAL(9,J16) -> 2506 | S16: =SUM(49214.5/68)*H16 -> 773.68089 | T16: =SUM(113.64/68)*H16 -> 1.7864876 | U16: =SUM(2400/68)*H16 -> 37.729412 | X16: =SUM(S16:W16) -> 813.19679 | Y16: =SUM(10949.72/68)*H16 -> 172.13604 | AB16: =SUM(Y16:AA16) -> 172.13604 | AC16: 7.33 | AD16: =SUM(AB16*AC16) -> 1261.7572 | AE16: =SUM(X16+AD16) -> 2074.954 | AF16: =SUM(P16-AE16) -> 431.04604
C17: 241030000041 | D17: 45601 | E17: 吕沛霖 | F17: 喵喵速运-Layne | G17: WEI PING | H17: 1.5338 | I17: 336 | K17: 755361 | M17: =SUM(K17/N17) -> 1700 | N17: 444.33 | O17: 7.27 | P17: =SUM(N17*O17) -> 3230.2791 | S17: =SUM(49214.5/68)*H17 -> 1110.0765 | T17: =SUM(113.64/68)*H17 -> 2.5632505 | U17: =SUM(2400/68)*H17 -> 54.134118 | X17: =SUM(S17:W17) -> 1166.7738 | Y17: =SUM(10949.72/68)*H17 -> 246.9806 | Z17: 29.9 | AB17: =SUM(Y17:AA17) -> 276.8806 | AC17: 7.33 | AD17: =SUM(AB17*AC17) -> 2029.5348 | AE17: =SUM(X17+AD17) -> 3196.3086 | AF17: =SUM(P17-AE17) -> 33.97049
C18: 241101000029 | D18: 45601 | E18: 吕沛霖 | F18: 喵喵速运-Layne | G18: YA | H18: 0.8656 | I18: 346 | J18: 2978.64 | P18: =SUM(J18) -> 2978.64 | S18: =SUM(49214.5/68)*H18 -> 626.47164 | T18: =SUM(113.64/68)*H18 -> 1.4465704 | U18: =SUM(2400/68)*H18 -> 30.550588 | X18: =SUM(S18:W18) -> 658.46879 | Y18: =SUM(10949.72/68)*H18 -> 139.38349 | Z18: 12.36 | AA18: 83.19 | AB18: =SUM(Y18:AA18) -> 234.93349 | AC18: 7.33 | AD18: =SUM(AB18*AC18) -> 1722.0625 | AE18: =SUM(X18+AD18) -> 2380.5313 | AF18: =SUM(P18-AE18) -> 598.10869
C19: 241101000033 | D19: 45601 | E19: 朱小飞 | F19: Isabel Zhu | G19: Halifa Success | H19: 0.8844 | I19: 155 | J19: 1806.11 | P19: =SUBTOTAL(9,J19) -> 1806.11 | S19: =SUM(49214.5/68)*H19 -> 640.078 | T19: =SUM(113.64/68)*H19 -> 1.4779885 | U19: =SUM(2400/68)*H19 -> 31.214118 | X19: =SUM(S19:W19) -> 672.7701 | Y19: =SUM(10949.72/68)*H19 -> 142.41077 | AB19: =SUM(Y19:AA19) -> 142.41077 | AC19: 7.33 | AD19: =SUM(AB19*AC19) -> 1043.8709 | AE19: =SUM(X19+AD19) -> 1716.641 | AF19: =SUM(P19-AE19) -> 89.468952
C20: 241209000060 | D20: 45601 | E20: 陆总 | F20: 陆梓龙 | G20: xinlong | H20: 17.902 | I20: 17472 | J20: 41296.32 | P20: =SUBTOTAL(9,J20) -> 41296.32 | S20: =SUM(49214.5/68)*H20 -> 12956.441 | T20: =SUM(113.64/68)*H20 -> 29.917401 | U20: =SUM(2400/68)*H20 -> 631.83529 | X20: =SUM(S20:W20) -> 13618.194 | Y20: =SUM(10949.72/68)*H20 -> 2882.6748 | AB20: =SUM(Y20:AA20) -> 2882.6748 | AC20: 7.33 | AD20: =SUM(AB20*AC20) -> 21130.006 | AE20: =SUM(X20+AD20) -> 34748.2 | AF20: =SUM(P20-AE20) -> 6548.12
A21: JOB120362 | B21: COLL004290 | C21: 241028000047 | D21: 45602 | E21: Sam.Pao | F21: Sam.Pao | G21: Nick Wang | H21: 3.0981 | I21: 231 | J21: 8037.16 | P21: =SUBTOTAL(9,J21) -> 8037.16 | Q21: =SUM(P21:P34) -> 134933.06 | R21: 登凯=46189.5 陆总=800 拖车费=1670 杂费=61 过磅费=68 | S21: =SUM(48788.5/68)*H21 -> 2222.8184 | U21: =SUM(1800/68)*H21 -> 82.008529 | X21: =SUM(S21:W21) -> 2304.8269 | Y21: =SUM(10716.46/68)*H21 -> 488.24507 | AA21: =SUM(50.64/68)*H21 -> 2.3071733 | AB21: =SUM(Y21:AA21) -> 490.55224 | AC21: 7.33 | AD21: =SUM(AB21*AC21) -> 3595.7479 | AE21: =SUM(X21+AD21) -> 5900.5749 | AF21: =SUM(P21-AE21) -> 2136.5851
C22: 241029000048 | D22: 45602 | E22: 黄颖 | F22: ying | G22: Sunday Adelena | H22: 0.4438 | I22: 310 | J22: 964.05 | P22: =SUBTOTAL(9,J22) -> 964.05 | S22: =SUM(48788.5/68)*H22 -> 318.41671 | U22: =SUM(1800/68)*H22 -> 11.747647 | X22: =SUM(S22:W22) -> 330.16436 | Y22: =SUM(10716.46/68)*H22 -> 69.940661 | AA22: =SUM(50.64/68)*H22 -> 0.33050047 | AB22: =SUM(Y22:AA22) -> 70.271161 | AC22: 7.33 | AD22: =SUM(AB22*AC22) -> 515.08761 | AE22: =SUM(X22+AD22) -> 845.25197 | AF22: =SUM(P22-AE22) -> 118.79803
C23: 241030000021 | D23: 45602 | E23: 吕沛霖 | F23: 喵喵速运-Layne | G23: MA ZONG | H23: 0.6626 | I23: 405 | J23: 1624.5 | P23: =SUBTOTAL(9,J23) -> 1624.5 | S23: =SUM(48788.5/68)*H23 -> 475.40088 | U23: =SUM(1800/68)*H23 -> 17.539412 | X23: =SUM(S23:W23) -> 492.9403 | Y23: =SUM(10716.46/68)*H23 -> 104.42245 | Z23: 35.38 | AA23: =SUM(50.64/68)*H23 -> 0.49344212 | AB23: =SUM(Y23:AA23) -> 140.29589 | AC23: 7.33 | AD23: =SUM(AB23*AC23) -> 1028.3689 | AE23: =SUM(X23+AD23) -> 1521.3092 | AF23: =SUM(P23-AE23) -> 103.19084
C24: 241030000025 | D24: 45602 | E24: 黄颖 | F24: ying | G24: Nura | H24: 0.4092 | I24: 180 | J24: 876.05 | P24: =SUBTOTAL(9,J24) -> 876.05 | S24: =SUM(48788.5/68)*H24 -> 293.59197 | U24: =SUM(1800/68)*H24 -> 10.831765 | X24: =SUM(S24:W24) -> 304.42374 | Y24: =SUM(10716.46/68)*H24 -> 64.487874 | AA24: =SUM(50.64/68)*H24 -> 0.30473365 | AB24: =SUM(Y24:AA24) -> 64.792608 | AC24: 7.33 | AD24: =SUM(AB24*AC24) -> 474.92981 | AE24: =SUM(X24+AD24) -> 779.35355 | AF24: =SUM(P24-AE24) -> 96.696448
C25: 241031000033 | D25: 45602 | E25: 黄颖 | F25: ying | G25: Bruce | H25: 0.5837 | I25: 247 | K25: 280840 | M25: =SUM(K25/N25) -> 1652.9723 | N25: 169.9 | O25: 7.29 | P25: =SUM(N25*O25) -> 1238.571 | S25: =SUM(48788.5/68)*H25 -> 418.79187 | U25: =SUM(1800/68)*H25 -> 15.450882 | X25: =SUM(S25:W25) -> 434.24276 | Y25: =SUM(10716.46/68)*H25 -> 91.988202 | AA25: =SUM(50.64/68)*H25 -> 0.43468482 | AB25: =SUM(Y25:AA25) -> 92.422886 | AC25: 7.33 | AD25: =SUM(AB25*AC25) -> 677.45976 | AE25: =SUM(X25+AD25) -> 1111.7025 | AF25: =SUM(P25-AE25) -> 126.86849
C26: 241101000057 | D26: 45602 | E26: 陆总 | F26: 陆梓龙 | G26: jizong | H26: 1.1063 | I26: 567 | J26: 2422.8 | P26: =SUBTOTAL(9,J26) -> 2422.8 | S26: =SUM(48788.5/68)*H26 -> 793.74585 | U26: =SUM(1800/68)*H26 -> 29.284412 | X26: =SUM(S26:W26) -> 823.03026 | Y26: =SUM(10716.46/68)*H26 -> 174.34735 | AA26: =SUM(50.64/68)*H26 -> 0.82386812 | AB26: =SUM(Y26:AA26) -> 175.17122 | AC26: 7.33 | AD26: =SUM(AB26*AC26) -> 1284.005 | AE26: =SUM(X26+AD26) -> 2107.0353 | AF26: =SUM(P26-AE26) -> 315.76472
C27: 241104000038 | D27: 45602 | E27: 黄颖 | F27: ying | G27: Sunday Adelena | H27: 0.0737 | I27: 26 | J27: 214.23 | P27: =SUBTOTAL(9,J27) -> 214.23 | S27: =SUM(48788.5/68)*H27 -> 52.878124 | U27: =SUM(1800/68)*H27 -> 1.9508824 | X27: =SUM(S27:W27) -> 54.829007 | Y27: =SUM(10716.46/68)*H27 -> 11.614752 | AA27: =SUM(50.64/68)*H27 -> 0.054884824 | AB27: =SUM(Y27:AA27) -> 11.669636 | AC27: 7.33 | AD27: =SUM(AB27*AC27) -> 85.538434 | AE27: =SUM(X27+AD27) -> 140.36744 | AF27: =SUM(P27-AE27) -> 73.862559
C28: 241022000035 | D28: 45602 | E28: Bella | F28: Bella Chan | G28: zhong zi xin | H28: 27.424 | I28: 19896 | J28: 60720 | P28: =SUBTOTAL(9,J28) -> 60720 | S28: =SUM(48788.5/68)*H28 -> 19676.115 | U28: =SUM(1800/68)*H28 -> 725.92941 | X28: =SUM(S28:W28) -> 20402.044 | Y28: =SUM(10716.46/68)*H28 -> 4321.8853 | AA28: =SUM(50.64/68)*H28 -> 20.422814 | AB28: =SUM(Y28:AA28) -> 4342.3081 | AC28: 7.33 | AD28: =SUM(AB28*AC28) -> 31829.118 | AE28: =SUM(X28+AD28) -> 52231.163 | AF28: =SUM(P28-AE28) -> 8488.8372
C29: 241105000034 | D29: 45602 | E29: 朱小飞 | F29: Isabel Zhu | G29: Joy | H29: 0.7455 | I29: 854 | K29: 641427.2 | M29: =SUM(K29/N29) -> 1643 | N29: 390.4 | O29: 7.3 | P29: =SUM(N29*O29) -> 2849.92 | S29: =SUM(48788.5/68)*H29 -> 534.87981 | U29: =SUM(1800/68)*H29 -> 19.733824 | X29: =SUM(S29:W29) -> 554.61363 | Y29: =SUM(10716.46/68)*H29 -> 117.48707 | Z29: 29.21 | AA29: =SUM(50.64/68)*H29 -> 0.55517824 | AB29: =SUM(Y29:AA29) -> 147.25225 | AC29: 7.33 | AD29: =SUM(AB29*AC29) -> 1079.359 | AE29: =SUM(X29+AD29) -> 1633.9726 | AF29: =SUM(P29-AE29) -> 1215.9474
C30: 241106000001 | D30: 45602 | E30: Sam.Pao | F30: Sam.Pao | G30: MaiKaiNian | H30: 0.4542 | I30: 69 | J30: 1060.98 | P30: =SUBTOTAL(9,J30) -> 1060.98 | S30: =SUM(48788.5/68)*H30 -> 325.87848 | U30: =SUM(1800/68)*H30 -> 12.022941 | X30: =SUM(S30:W30) -> 337.90142 | Y30: =SUM(10716.46/68)*H30 -> 71.579649 | AA30: =SUM(50.64/68)*H30 -> 0.33824541 | AB30: =SUM(Y30:AA30) -> 71.917894 | AC30: 7.33 | AD30: =SUM(AB30*AC30) -> 527.15817 | AE30: =SUM(X30+AD30) -> 865.05959 | AF30: =SUM(P30-AE30) -> 195.92041
C31: 241106000002 | D31: 45602 | E31: Sam.Pao | F31: Sam.Pao | G31: Angel | H31: 0.3458 | I31: 98 | J31: 757 | P31: =SUBTOTAL(9,J31) -> 757 | S31: =SUM(48788.5/68)*H31 -> 248.10387 | U31: =SUM(1800/68)*H31 -> 9.1535294 | X31: =SUM(S31:W31) -> 257.2574 | Y31: =SUM(10716.46/68)*H31 -> 54.496351 | AA31: =SUM(50.64/68)*H31 -> 0.25751929 | AB31: =SUM(Y31:AA31) -> 54.75387 | AC31: 7.33 | AD31: =SUM(AB31*AC31) -> 401.34587 | AE31: =SUM(X31+AD31) -> 658.60327 | AF31: =SUM(P31-AE31) -> 98.396729
C32: 241106000018 | D32: 45602 | E32: Bella | F32: Bella Chan | G32: zhang long ting | H32: 0.0019 | I32: 1 | K32: 51150 | M32: =SUM(K32/N32) -> 1650 | N32: 31 | O32: 7.2 | P32: =SUM(N32*O32) -> 223.2 | S32: =SUM(48788.5/68)*H32 -> 1.3632081 | U32: =SUM(1800/68)*H32 -> 0.050294118 | X32: =SUM(S32:W32) -> 1.4135022 | Y32: =SUM(10716.46/68)*H32 -> 0.2994305 | AA32: =SUM(50.64/68)*H32 -> 0.0014149412 | AB32: =SUM(Y32:AA32) -> 0.30084544 | AC32: 7.33 | AD32: =SUM(AB32*AC32) -> 2.2051971 | AE32: =SUM(X32+AD32) -> 3.6186993 | AF32: =SUM(P32-AE32) -> 219.5813
C33: 241106000037 | D33: 45602 | E33: Sam.Pao | F33: Sam.Pao | G33: JunYue hotel | H33: 0.6996 | I33: 76 | J33: 1583.01 | P33: =SUBTOTAL(9,J33) -> 1583.01 | S33: =SUM(48788.5/68)*H33 -> 501.94757 | U33: =SUM(1800/68)*H33 -> 18.518824 | X33: =SUM(S33:W33) -> 520.46639 | Y33: =SUM(10716.46/68)*H33 -> 110.25346 | AA33: =SUM(50.64/68)*H33 -> 0.52099624 | AB33: =SUM(Y33:AA33) -> 110.77446 | AC33: 7.33 | AD33: =SUM(AB33*AC33) -> 811.97678 | AE33: =SUM(X33+AD33) -> 1332.4432 | AF33: =SUM(P33-AE33) -> 250.56683
C34: 241107000022 | D34: 45602 | E34: 罗珮文 | F34: Shirley | G34: SKY JET | H34: 32.635 | I34: 4165 | J34: 52361.59 | P34: =SUBTOTAL(9,J34) -> 52361.59 | S34: =SUM(48788.5/68)*H34 -> 23414.893 | U34: =SUM(1800/68)*H34 -> 863.86765 | X34: =SUM(S34:W34) -> 24278.76 | Y34: =SUM(10716.46/68)*H34 -> 5143.1128 | AA34: =SUM(50.64/68)*H34 -> 24.303476 | AB34: =SUM(Y34:AA34) -> 5167.4163 | AC34: 7.33 | AD34: =SUM(AB34*AC34) -> 37877.161 | AE34: =SUM(X34+AD34) -> 62155.922 | AF34: =SUM(P34-AE34) -> -9794.3317
A35: JOB120363 | B35: COLL004291 | C35: 240930000009 | D35: 45608 | E35: 黄颖 | F35: ying | G35: Tom chen | H35: 0.0977 | I35: 28.5 | K35: 132820 | M35: =SUM(K35/N35) -> 1648.9137 | N35: 80.55 | O35: 7.3 | P35: =SUM(N35*O35) -> 588.015 | Q35: =SUM(P35:P56) -> 188664.54 | R35: 登凯=43330 陆总=8000 拖车费=1670 杂费=93 过磅费=125 | S35: =SUM(53218/68)*H35 -> 76.461744 | U35: =SUM(1955/68)*H35 -> 2.808875 | X35: =SUM(S35:W35) -> 79.270619 | Y35: =SUM(11360.84/68)*H35 -> 16.322854 | Z35: 11.38 | AA35: =SUM(53.54/68)*H35 -> 0.076924382 | AB35: =SUM(Y35:AA35) -> 27.779778 | AC35: 7.3 | AD35: =SUM(AB35*AC35) -> 202.79238 | AE35: =SUM(X35+AD35) -> 282.063 | AF35: =SUM(P35-AE35) -> 305.952
C36: 241015000034 | D36: 45608 | E36: 朱小飞 | F36: Isabel Zhu | G36: Halifa Success | H36: 4.77 | I36: 451 | J36: 9789.95 | P36: =SUBTOTAL(9,J36) -> 9789.95 | S36: =SUM(53218/68)*H36 -> 3733.0862 | U36: =SUM(1955/68)*H36 -> 137.1375 | X36: =SUM(S36:W36) -> 3870.2237 | Y36: =SUM(11360.84/68)*H36 -> 796.92951 | AA36: =SUM(53.54/68)*H36 -> 3.7556735 | AB36: =SUM(Y36:AA36) -> 800.68519 | AC36: 7.3 | AD36: =SUM(AB36*AC36) -> 5845.0019 | AE36: =SUM(X36+AD36) -> 9715.2255 | AF36: =SUM(P36-AE36) -> 74.724471
C37: 241021000005 | D37: 45608 | E37: 吕沛霖 | F37: 喵喵速运-Layne | G37: Hu Hai Liang | H37: 1.1795 | I37: 335 | K37: 583853 | M37: =SUM(K37/N37) -> 1650.0015 | N37: 353.84998 | O37: 7.3 | P37: =SUM(N37*O37) -> 2583.1049 | S37: =SUM(53218/68)*H37 -> 923.09751 | U37: =SUM(1955/68)*H37 -> 33.910625 | X37: =SUM(S37:W37) -> 957.00814 | Y37: =SUM(11360.84/68)*H37 -> 197.06045 | AA37: =SUM(53.54/68)*H37 -> 0.92868279 | AB37: =SUM(Y37:AA37) -> 197.98914 | AC37: 7.3 | AD37: =SUM(AB37*AC37) -> 1445.3207 | AE37: =SUM(X37+AD37) -> 2402.3288 | AF37: =SUM(P37-AE37) -> 180.77603
C38: 241022000035 | D38: 45608 | E38: Bella | F38: Bella Chan | G38: zhong zi xin | H38: 28.3553 | I38: 15100 | J38: 62780 | P38: =SUBTOTAL(9,J38) -> 62780 | S38: =SUM(53218/68)*H38 -> 22191.358 | U38: =SUM(1955/68)*H38 -> 815.21488 | V38: 300 | X38: =SUM(S38:W38) -> 23306.573 | Y38: =SUM(11360.84/68)*H38 -> 4737.3533 | Z38: =SUM(413.88+371.27) -> 785.15 | AA38: =SUM(53.54/68)*H38 -> 22.325629 | AB38: =SUM(Y38:AA38) -> 5544.829 | AC38: 7.3 | AD38: =SUM(AB38*AC38) -> 40477.251 | AE38: =SUM(X38+AD38) -> 63783.824 | AF38: =SUM(P38-AE38) -> -1003.8244
C39: 241024000054 | D39: 45608 | E39: Sam.Pao | F39: Sam.Pao | G39: ShanShan | H39: 16.835 | I39: 7500 | J39: 48779 | P39: =SUBTOTAL(9,J39) -> 48779 | S39: =SUM(53218/68)*H39 -> 13175.368 | U39: =SUM(1955/68)*H39 -> 484.00625 | X39: =SUM(S39:W39) -> 13659.374 | Y39: =SUM(11360.84/68)*H39 -> 2812.6433 | Z39: 97.38 | AA39: =SUM(53.54/68)*H39 -> 13.255087 | AB39: =SUM(Y39:AA39) -> 2923.2783 | AC39: 7.3 | AD39: =SUM(AB39*AC39) -> 21339.932 | AE39: =SUM(X39+AD39) -> 34999.306 | AF39: =SUM(P39-AE39) -> 13779.694
C40: 241104000057 | D40: 45608 | E40: 朱小飞 | F40: Isabel Zhu | G40: Halifa Success | H40: 2.3978 | I40: 447 | J40: 4925.76 | P40: =SUBTOTAL(9,J40) -> 4925.76 | S40: =SUM(53218/68)*H40 -> 1876.5606 | U40: =SUM(1955/68)*H40 -> 68.93675 | X40: =SUM(S40:W40) -> 1945.4973 | Y40: =SUM(11360.84/68)*H40 -> 400.60327 | AA40: =SUM(53.54/68)*H40 -> 1.8879149 | AB40: =SUM(Y40:AA40) -> 402.49118 | AC40: 7.3 | AD40: =SUM(AB40*AC40) -> 2938.1856 | AE40: =SUM(X40+AD40) -> 4883.683 | AF40: =SUM(P40-AE40) -> 42.077029
...

Sheet JOB120361
A1: 2024年11月份LOS毛利表（海运）
A2: PSL表 | B2: 体积cbm | C2: 74.1647
A3: JOB | B3: 集装编号 | C3: 运单编号 | D3: 日期 | E3: 业务 | F3: 发货人 | G3: 收货人 | H3: 计费体积 | I3: 计费重量 | J3: 应 收 | Q3: 总应收 | R3: 起 运 港 成 本 | W3: 代垫运费 | X3: 起运港成本 合计 | Y3: 目的港成本 | AE3: 总支出 | AF3: 利润
J4: 应收RMB | K4: LOS Income(NGN)收到(奈拉) | L4: LOS 收到USD | M4: 美元汇率 dollar currency rate | N4: 应收 到付款USD | O4: 汇率 | P4: 人民币 | R4: 代理商 | S4: 运费+出口报关费 | T4: 提货费 | U4: 装卸费 | V4: 包装费 | Y4: 进口报关费 | Z4: 到门配送费 | AA4: 转运费 | AB4: 目的港支出 | AC4: 汇率 | AD4: 人民币 | AE4: 起运港+目的港
A5: JOB120361 | B5: COLL004287 | C5: 240910000015 | D5: 45601 | E5: 吕沛霖 | F5: 喵喵速运-Layne | G5: Hu Hai Liang | H5: 5.1959 | I5: 743 | K5: 2382640 | M5: =SUM(K5/N5) -> 1580 | N5: 1508 | O5: 7.29 | P5: =SUM(N5*O5) -> 10993.32 | Q5: =SUM(P5:P21) -> 165324.28 | R5: 登凯=46189.5 陆总=1200 拖车费=1670 杂费=89 过磅费=66 | S5: =SUM(49214.5/68)*H5 -> 3760.4944 | T5: =SUM(113.64/68)*H5 -> 8.6832658 | U5: =SUM(2400/68)*H5 -> 183.38471 | X5: =SUM(S5:W5) -> 3952.5624 | Y5: =SUM(10949.72/68)*H5 -> 836.67133 | AB5: =SUM(Y5:AA5) -> 836.67133 | AC5: 7.33 | AD5: =SUM(AB5*AC5) -> 6132.8008 | AE5: =SUM(X5+AD5) -> 10085.363 | AF5: =SUM(P5-AE5) -> 907.95679
C6: 241023000029 | D6: 45601 | E6: 黄颖 | F6: ying | G6: Wole Rasak | H6: 0.0288 | I6: 5 | J6: 224.75 | P6: =SUBTOTAL(9,J6) -> 224.75 | S6: =SUM(49214.5/68)*H6 -> 20.843788 | T6: =SUM(113.64/68)*H6 -> 0.048129882 | U6: =SUM(2400/68)*H6 -> 1.0164706 | X6: =SUM(S6:W6) -> 21.908389 | Y6: =SUM(10949.72/68)*H6 -> 4.6375285 | AB6: =SUM(Y6:AA6) -> 4.6375285 | AC6: 7.33 | AD6: =SUM(AB6*AC6) -> 33.993084 | AE6: =SUM(X6+AD6) -> 55.901472 | AF6: =SUM(P6-AE6) -> 168.84853
C7: 241025000058 | D7: 45601 | E7: 苏慧琪 | F7: KAY | G7: BOYOU 吕 | H7: 13.7 | I7: 2550 | K7: 7067746.5 | M7: =SUM(K7/N7) -> 1648.8039 | N7: 4286.59 | O7: 7.29 | P7: =SUM(N7*O7) -> 31249.241 | S7: =SUM(49214.5/68)*H7 -> 9915.2743 | T7: =SUM(113.64/68)*H7 -> 22.895118 | U7: =SUM(2400/68)*H7 -> 483.52941 | X7: =SUM(S7:W7) -> 10421.699 | Y7: =SUM(10949.72/68)*H7 -> 2206.0465 | Z7: 90.97 | AB7: =SUM(Y7:AA7) -> 2297.0165 | AC7: 7.33 | AD7: =SUM(AB7*AC7) -> 16837.131 | AE7: =SUM(X7+AD7) -> 27258.83 | AF7: =SUM(P7-AE7) -> 3990.4111
C8: 241026000006 | D8: 45601 | E8: 吕沛霖 | F8: 喵喵速运-Layne | G8: LEO WEI | H8: 0.6549 | I8: 72 | K8: 363730 | M8: =SUM(K8/N8) -> 1683.0002 | N8: 216.12 | O8: 7.3 | P8: =SUM(N8*O8) -> 1577.676 | S8: =SUM(49214.5/68)*H8 -> 473.97906 | T8: =SUM(113.64/68)*H8 -> 1.0944535 | U8: =SUM(2400/68)*H8 -> 23.114118 | X8: =SUM(S8:W8) -> 498.18763 | Y8: =SUM(10949.72/68)*H8 -> 105.45547 | AB8: =SUM(Y8:AA8) -> 105.45547 | AC8: 7.33 | AD8: =SUM(AB8*AC8) -> 772.98856 | AE8: =SUM(X8+AD8) -> 1271.1762 | AF8: =SUM(P8-AE8) -> 306.49981
C9: 241027000011 | D9: 45601 | E9: 朱小飞 | F9: Isabel Zhu | G9: Maryam Tukur | H9: 0.5618 | I9: 55 | K9: 434000 | M9: =SUM(K9/N9) -> 1671.8028 | N9: 259.6 | O9: 7.3 | P9: =SUM(N9*O9) -> 1895.08 | S9: =SUM(49214.5/68)*H9 -> 406.59862 | T9: =SUM(113.64/68)*H9 -> 0.93886694 | U9: =SUM(2400/68)*H9 -> 19.828235 | V9: 310 | W9: 59 | X9: =SUM(S9:W9) -> 796.36572 | Y9: =SUM(10949.72/68)*H9 -> 90.46401 | AB9: =SUM(Y9:AA9) -> 90.46401 | AC9: 7.33 | AD9: =SUM(AB9*AC9) -> 663.1012 | AE9: =SUM(X9+AD9) -> 1459.4669 | AF9: =SUM(P9-AE9) -> 435.61308
C10: 241031000033 | D10: 45601 | E10: 黄颖 | F10: ying | G10: Bruce | H10: 1.9968 | I10: 845 | K10: 960734 | M10: =SUM(K10/N10) -> 1653.0179 | N10: 581.2 | O10: 7.29 | P10: =SUM(N10*O10) -> 4236.948 | S10: =SUM(49214.5/68)*H10 -> 1445.1693 | T10: =SUM(113.64/68)*H10 -> 3.3370052 | U10: =SUM(2400/68)*H10 -> 70.475294 | X10: =SUM(S10:W10) -> 1518.9816 | Y10: =SUM(10949.72/68)*H10 -> 321.53531 | AB10: =SUM(Y10:AA10) -> 321.53531 | AC10: 7.33 | AD10: =SUM(AB10*AC10) -> 2356.8538 | AE10: =SUM(X10+AD10) -> 3875.8354 | AF10: =SUM(P10-AE10) -> 361.11258
C11: 241028000022 | D11: 45601 | E11: 黄颖 | F11: ying | G11: Barrister Hammed | H11: 1.211 | I11: 331 | J11: 2690 | P11: =SUBTOTAL(9,J11) -> 2690 | S11: =SUM(49214.5/68)*H11 -> 876.45235 | T11: =SUM(113.64/68)*H11 -> 2.0237947 | U11: =SUM(2400/68)*H11 -> 42.741176 | X11: =SUM(S11:W11) -> 921.21732 | Y11: =SUM(10949.72/68)*H11 -> 195.00163 | AB11: =SUM(Y11:AA11) -> 195.00163 | AC11: 7.33 | AD11: =SUM(AB11*AC11) -> 1429.362 | AE11: =SUM(X11+AD11) -> 2350.5793 | AF11: =SUM(P11-AE11) -> 339.42073
C12: 241028000025 | D12: 45601 | E12: 吕沛霖 | F12: 喵喵速运-Layne | G12: Candice Ding | H12: 0.7015 | I12: 168 | K12: 432424.8 | M12: =SUM(K12/N12) -> 1710 | N12: 252.88 | O12: 7.3 | P12: =SUM(N12*O12) -> 1846.024 | S12: =SUM(49214.5/68)*H12 -> 507.70547 | T12: =SUM(113.64/68)*H12 -> 1.1723303 | U12: =SUM(2400/68)*H12 -> 24.758824 | X12: =SUM(S12:W12) -> 533.63662 | Y12: =SUM(10949.72/68)*H12 -> 112.95924 | Z12: 42.43 | AB12: =SUM(Y12:AA12) -> 155.38924 | AC12: 7.33 | AD12: =SUM(AB12*AC12) -> 1139.0032 | AE12: =SUM(X12+AD12) -> 1672.6398 | AF12: =SUM(P12-AE12) -> 173.38422
C13: 241028000036 | D13: 45601 | E13: Sam.Pao | F13: Sam.Pao | G13: Chizoba | H13: 19.1974 | I13: 2413 | J13: 38000 | P13: =SUBTOTAL(9,J13) -> 38000 | S13: =SUM(49214.5/68)*H13 -> 13893.977 | T13: =SUM(113.64/68)*H13 -> 32.082243 | U13: =SUM(2400/68)*H13 -> 677.55529 | X13: =SUM(S13:W13) -> 14603.615 | Y13: =SUM(10949.72/68)*H13 -> 3091.267 | AB13: =SUM(Y13:AA13) -> 3091.267 | AC13: 7.33 | AD13: =SUM(AB13*AC13) -> 22658.987 | AE13: =SUM(X13+AD13) -> 37262.602 | AF13: =SUM(P13-AE13) -> 737.3984
C14: 241028000057 | D14: 45601 | E14: 朱小飞 | F14: Isabel Zhu | G14: Halifa Success | H14: 0.8721 | I14: 153 | J14: 1785.59 | P14: =SUBTOTAL(9,J14) -> 1785.59 | S14: =SUM(49214.5/68)*H14 -> 631.17596 | T14: =SUM(113.64/68)*H14 -> 1.457433 | U14: =SUM(2400/68)*H14 -> 30.78 | X14: =SUM(S14:W14) -> 663.4134 | Y14: =SUM(10949.72/68)*H14 -> 140.43016 | AB14: =SUM(Y14:AA14) -> 140.43016 | AC14: 7.33 | AD14: =SUM(AB14*AC14) -> 1029.3531 | AE14: =SUM(X14+AD14) -> 1692.7665 | AF14: =SUM(P14-AE14) -> 92.823539
C15: 241029000017 | D15: 45601 | E15: 黄颖 | F15: ying | G15: jiangnan | H15: 0.2948 | I15: 65 | J15: 683.5 | P15: =SUBTOTAL(9,J15) -> 683.5 | S15: =SUM(49214.5/68)*H15 -> 213.35933 | T15: =SUM(113.64/68)*H15 -> 0.49266282 | U15: =SUM(2400/68)*H15 -> 10.404706 | X15: =SUM(S15:W15) -> 224.2567 | Y15: =SUM(10949.72/68)*H15 -> 47.470257 | AB15: =SUM(Y15:AA15) -> 47.470257 | AC15: 7.33 | AD15: =SUM(AB15*AC15) -> 347.95698 | AE15: =SUM(X15+AD15) -> 572.21368 | AF15: =SUM(P15-AE15) -> 111.28632
C16: 241030000002 | D16: 45601 | E16: 吕沛霖 | F16: 喵喵速运-Layne | G16: Mu Shi Shi | H16: 7.4945 | I16: 520 | J16: 18324.8 | P16: =SUBTOTAL(9,J16) -> 18324.8 | S16: =SUM(49214.5/68)*H16 -> 5424.0893 | T16: =SUM(113.64/68)*H16 -> 12.524632 | U16: =SUM(2400/68)*H16 -> 264.51176 | X16: =SUM(S16:W16) -> 5701.1257 | Y16: =SUM(10949.72/68)*H16 -> 1206.8041 | Z16: 47.85 | AB16: =SUM(Y16:AA16) -> 1254.6541 | AC16: 7.33 | AD16: =SUM(AB16*AC16) -> 9196.6143 | AE16: =SUM(X16+AD16) -> 14897.74 | AF16: =SUM(P16-AE16) -> 3427.06
C17: 241030000039 | D17: 45601 | E17: 黄颖 | F17: ying | G17: jiangnan | H17: 1.069 | I17: 138 | J17: 2506 | P17: =SUBTOTAL(9,J17) -> 2506 | S17: =SUM(49214.5/68)*H17 -> 773.68089 | T17: =SUM(113.64/68)*H17 -> 1.7864876 | U17: =SUM(2400/68)*H17 -> 37.729412 | X17: =SUM(S17:W17) -> 813.19679 | Y17: =SUM(10949.72/68)*H17 -> 172.13604 | AB17: =SUM(Y17:AA17) -> 172.13604 | AC17: 7.33 | AD17: =SUM(AB17*AC17) -> 1261.7572 | AE17: =SUM(X17+AD17) -> 2074.954 | AF17: =SUM(P17-AE17) -> 431.04604
C18: 241030000041 | D18: 45601 | E18: 吕沛霖 | F18: 喵喵速运-Layne | G18: WEI PING | H18: 1.5338 | I18: 336 | K18: 755361 | M18: =SUM(K18/N18) -> 1700 | N18: 444.33 | O18: 7.27 | P18: =SUM(N18*O18) -> 3230.2791 | S18: =SUM(49214.5/68)*H18 -> 1110.0765 | T18: =SUM(113.64/68)*H18 -> 2.5632505 | U18: =SUM(2400/68)*H18 -> 54.134118 | X18: =SUM(S18:W18) -> 1166.7738 | Y18: =SUM(10949.72/68)*H18 -> 246.9806 | Z18: 29.9 | AB18: =SUM(Y18:AA18) -> 276.8806 | AC18: 7.33 | AD18: =SUM(AB18*AC18) -> 2029.5348 | AE18: =SUM(X18+AD18) -> 3196.3086 | AF18: =SUM(P18-AE18) -> 33.97049
C19: 241101000029 | D19: 45601 | E19: 吕沛霖 | F19: 喵喵速运-Layne | G19: YA | H19: 0.8656 | I19: 346 | J19: 2978.64 | P19: =SUM(J19) -> 2978.64 | S19: =SUM(49214.5/68)*H19 -> 626.47164 | T19: =SUM(113.64/68)*H19 -> 1.4465704 | U19: =SUM(2400/68)*H19 -> 30.550588 | X19: =SUM(S19:W19) -> 658.46879 | Y19: =SUM(10949.72/68)*H19 -> 139.38349 | Z19: 12.36 | AA19: 83.19 | AB19: =SUM(Y19:AA19) -> 234.93349 | AC19: 7.33 | AD19: =SUM(AB19*AC19) -> 1722.0625 | AE19: =SUM(X19+AD19) -> 2380.5313 | AF19: =SUM(P19-AE19) -> 598.10869
C20: 241101000033 | D20: 45601 | E20: 朱小飞 | F20: Isabel Zhu | G20: Halifa Success | H20: 0.8844 | I20: 155 | J20: 1806.11 | P20: =SUBTOTAL(9,J20) -> 1806.11 | S20: =SUM(49214.5/68)*H20 -> 640.078 | T20: =SUM(113.64/68)*H20 -> 1.4779885 | U20: =SUM(2400/68)*H20 -> 31.214118 | X20: =SUM(S20:W20) -> 672.7701 | Y20: =SUM(10949.72/68)*H20 -> 142.41077 | AB20: =SUM(Y20:AA20) -> 142.41077 | AC20: 7.33 | AD20: =SUM(AB20*AC20) -> 1043.8709 | AE20: =SUM(X20+AD20) -> 1716.641 | AF20: =SUM(P20-AE20) -> 89.468952
C21: 241209000060 | D21: 45601 | E21: 陆总 | F21: 陆梓龙 | G21: xinlong | H21: 17.902 | I21: 17472 | J21: 41296.32 | P21: =SUBTOTAL(9,J21) -> 41296.32 | S21: =SUM(49214.5/68)*H21 -> 12956.441 | T21: =SUM(113.64/68)*H21 -> 29.917401 | U21: =SUM(2400/68)*H21 -> 631.83529 | X21: =SUM(S21:W21) -> 13618.194 | Y21: =SUM(10949.72/68)*H21 -> 2882.6748 | AB21: =SUM(Y21:AA21) -> 2882.6748 | AC21: 7.33 | AD21: =SUM(AB21*AC21) -> 21130.006 | AE21: =SUM(X21+AD21) -> 34748.2 | AF21: =SUM(P21-AE21) -> 6548.12
A22: 合计 | J22: =SUM(J4:J4) -> 0 | N22: =SUM(N4:N4) -> 0 | P22: =SUM(P4:P4) -> 0 | Q22: =SUM(Q4:Q4) -> 0 | X22: =SUM(X4:X4) -> 0 | AD22: =SUM(AD4:AD4) -> 0 | AF22: =SUM(AF4:AF21) -> 18752.529

Sheet JOB120362
A1: 2024年11月份LOS毛利表（海运）
A2: PSL表 | B2: 体积cbm | C2: 68.6834
A3: JOB | B3: 集装编号 | C3: 运单编号 | D3: 日期 | E3: 业务 | F3: 发货人 | G3: 收货人 | H3: 计费体积 | I3: 计费重量 | J3: 应 收 | Q3: 总应收 | R3: 起 运 港 成 本 | W3: 代垫运费 | X3: 起运港成本 合计 | Y3: 目的港成本 | AE3: 总支出 | AF3: 利润
J4: 应收RMB | K4: LOS Income(NGN)收到(奈拉) | L4: LOS 收到USD | M4: 美元汇率 dollar currency rate | N4: 应收 到付款USD | O4: 汇率 | P4: 人民币 | R4: 代理商 | S4: 运费+出口报关费 | T4: 提货费 | U4: 装卸费 | V4: 包装费 | Y4: 进口报关费 | Z4: 到门配送费 | AA4: 转运费 | AB4: 目的港支出 | AC4: 汇率 | AD4: 人民币 | AE4: 起运港+目的港
A5: JOB120362 | B5: COLL004290 | C5: 241028000047 | D5: 45602 | E5: Sam.Pao | F5: Sam.Pao | G5: Nick Wang | H5: 3.0981 | I5: 231 | J5: 8037.16 | P5: =SUBTOTAL(9,J5) -> 8037.16 | Q5: =SUM(P5:P18) -> 134933.06 | R5: 登凯=46189.5 陆总=800 拖车费=1670 杂费=61 过磅费=68 | S5: =SUM(48788.5/68)*H5 -> 2222.8184 | U5: =SUM(1800/68)*H5 -> 82.008529 | X5: =SUM(S5:W5) -> 2304.8269 | Y5: =SUM(10716.46/68)*H5 -> 488.24507 | AA5: =SUM(50.64/68)*H5 -> 2.3071733 | AB5: =SUM(Y5:AA5) -> 490.55224 | AC5: 7.33 | AD5: =SUM(AB5*AC5) -> 3595.7479 | AE5: =SUM(X5+AD5) -> 5900.5749 | AF5: =SUM(P5-AE5) -> 2136.5851
C6: 241029000048 | D6: 45602 | E6: 黄颖 | F6: ying | G6: Sunday Adelena | H6: 0.4438 | I6: 310 | J6: 964.05 | P6: =SUBTOTAL(9,J6) -> 964.05 | S6: =SUM(48788.5/68)*H6 -> 318.41671 | U6: =SUM(1800/68)*H6 -> 11.747647 | X6: =SUM(S6:W6) -> 330.16436 | Y6: =SUM(10716.46/68)*H6 -> 69.940661 | AA6: =SUM(50.64/68)*H6 -> 0.33050047 | AB6: =SUM(Y6:AA6) -> 70.271161 | AC6: 7.33 | AD6: =SUM(AB6*AC6) -> 515.08761 | AE6: =SUM(X6+AD6) -> 845.25197 | AF6: =SUM(P6-AE6) -> 118.79803
C7: 241030000021 | D7: 45602 | E7: 吕沛霖 | F7: 喵喵速运-Layne | G7: MA ZONG | H7: 0.6626 | I7: 405 | J7: 1624.5 | P7: =SUBTOTAL(9,J7) -> 1624.5 | S7: =SUM(48788.5/68)*H7 -> 475.40088 | U7: =SUM(1800/68)*H7 -> 17.539412 | X7: =SUM(S7:W7) -> 492.9403 | Y7: =SUM(10716.46/68)*H7 -> 104.42245 | Z7: 35.38 | AA7: =SUM(50.64/68)*H7 -> 0.49344212 | AB7: =SUM(Y7:AA7) -> 140.29589 | AC7: 7.33 | AD7: =SUM(AB7*AC7) -> 1028.3689 | AE7: =SUM(X7+AD7) -> 1521.3092 | AF7: =SUM(P7-AE7) -> 103.19084
C8: 241030000025 | D8: 45602 | E8: 黄颖 | F8: ying | G8: Nura | H8: 0.4092 | I8: 180 | J8: 876.05 | P8: =SUBTOTAL(9,J8) -> 876.05 | S8: =SUM(48788.5/68)*H8 -> 293.59197 | U8: =SUM(1800/68)*H8 -> 10.831765 | X8: =SUM(S8:W8) -> 304.42374 | Y8: =SUM(10716.46/68)*H8 -> 64.487874 | AA8: =SUM(50.64/68)*H8 -> 0.30473365 | AB8: =SUM(Y8:AA8) -> 64.792608 | AC8: 7.33 | AD8: =SUM(AB8*AC8) -> 474.92981 | AE8: =SUM(X8+AD8) -> 779.35355 | AF8: =SUM(P8-AE8) -> 96.696448
C9: 241031000033 | D9: 45602 | E9: 黄颖 | F9: ying | G9: Bruce | H9: 0.5837 | I9: 247 | K9: 280840 | M9: =SUM(K9/N9) -> 1652.9723 | N9: 169.9 | O9: 7.29 | P9: =SUM(N9*O9) -> 1238.571 | S9: =SUM(48788.5/68)*H9 -> 418.79187 | U9: =SUM(1800/68)*H9 -> 15.450882 | X9: =SUM(S9:W9) -> 434.24276 | Y9: =SUM(10716.46/68)*H9 -> 91.988202 | AA9: =SUM(50.64/68)*H9 -> 0.43468482 | AB9: =SUM(Y9:AA9) -> 92.422886 | AC9: 7.33 | AD9: =SUM(AB9*AC9) -> 677.45976 | AE9: =SUM(X9+AD9) -> 1111.7025 | AF9: =SUM(P9-AE9) -> 126.86849
C10: 241101000057 | D10: 45602 | E10: 陆总 | F10: 陆梓龙 | G10: jizong | H10: 1.1063 | I10: 567 | J10: 2422.8 | P10: =SUBTOTAL(9,J10) -> 2422.8 | S10: =SUM(48788.5/68)*H10 -> 793.74585 | U10: =SUM(1800/68)*H10 -> 29.284412 | X10: =SUM(S10:W10) -> 823.03026 | Y10: =SUM(10716.46/68)*H10 -> 174.34735 | AA10: =SUM(50.64/68)*H10 -> 0.82386812 | AB10: =SUM(Y10:AA10) -> 175.17122 | AC10: 7.33 | AD10: =SUM(AB10*AC10) -> 1284.005 | AE10: =SUM(X10+AD10) -> 2107.0353 | AF10: =SUM(P10-AE10) -> 315.76472
C11: 241104000038 | D11: 45602 | E11: 黄颖 | F11: ying | G11: Sunday Adelena | H11: 0.0737 | I11: 26 | J11: 214.23 | P11: =SUBTOTAL(9,J11) -> 214.23 | S11: =SUM(48788.5/68)*H11 -> 52.878124 | U11: =SUM(1800/68)*H11 -> 1.9508824 | X11: =SUM(S11:W11) -> 54.829007 | Y11: =SUM(10716.46/68)*H11 -> 11.614752 | AA11: =SUM(50.64/68)*H11 -> 0.054884824 | AB11: =SUM(Y11:AA11) -> 11.669636 | AC11: 7.33 | AD11: =SUM(AB11*AC11) -> 85.538434 | AE11: =SUM(X11+AD11) -> 140.36744 | AF11: =SUM(P11-AE11) -> 73.862559
C12: 241022000035 | D12: 45602 | E12: Bella | F12: Bella Chan | G12: zhong zi xin | H12: 27.424 | I12: 19896 | J12: 60720 | P12: =SUBTOTAL(9,J12) -> 60720 | S12: =SUM(48788.5/68)*H12 -> 19676.115 | U12: =SUM(1800/68)*H12 -> 725.92941 | X12: =SUM(S12:W12) -> 20402.044 | Y12: =SUM(10716.46/68)*H12 -> 4321.8853 | AA12: =SUM(50.64/68)*H12 -> 20.422814 | AB12: =SUM(Y12:AA12) -> 4342.3081 | AC12: 7.33 | AD12: =SUM(AB12*AC12) -> 31829.118 | AE12: =SUM(X12+AD12) -> 52231.163 | AF12: =SUM(P12-AE12) -> 8488.8372
C13: 241105000034 | D13: 45602 | E13: 朱小飞 | F13: Isabel Zhu | G13: Joy | H13: 0.7455 | I13: 854 | K13: 641427.2 | M13: =SUM(K13/N13) -> 1643 | N13: 390.4 | O13: 7.3 | P13: =SUM(N13*O13) -> 2849.92 | S13: =SUM(48788.5/68)*H13 -> 534.87981 | U13: =SUM(1800/68)*H13 -> 19.733824 | X13: =SUM(S13:W13) -> 554.61363 | Y13: =SUM(10716.46/68)*H13 -> 117.48707 | Z13: 29.21 | AA13: =SUM(50.64/68)*H13 -> 0.55517824 | AB13: =SUM(Y13:AA13) -> 147.25225 | AC13: 7.33 | AD13: =SUM(AB13*AC13) -> 1079.359 | AE13: =SUM(X13+AD13) -> 1633.9726 | AF13: =SUM(P13-AE13) -> 1215.9474
C14: 241106000001 | D14: 45602 | E14: Sam.Pao | F14: Sam.Pao | G14: MaiKaiNian | H14: 0.4542 | I14: 69 | J14: 1060.98 | P14: =SUBTOTAL(9,J14) -> 1060.98 | S14: =SUM(48788.5/68)*H14 -> 325.87848 | U14: =SUM(1800/68)*H14 -> 12.022941 | X14: =SUM(S14:W14) -> 337.90142 | Y14: =SUM(10716.46/68)*H14 -> 71.579649 | AA14: =SUM(50.64/68)*H14 -> 0.33824541 | AB14: =SUM(Y14:AA14) -> 71.917894 | AC14: 7.33 | AD14: =SUM(AB14*AC14) -> 527.15817 | AE14: =SUM(X14+AD14) -> 865.05959 | AF14: =SUM(P14-AE14) -> 195.92041
C15: 241106000002 | D15: 45602 | E15: Sam.Pao | F15: Sam.Pao | G15: Angel | H15: 0.3458 | I15: 98 | J15: 757 | P15: =SUBTOTAL(9,J15) -> 757 | S15: =SUM(48788.5/68)*H15 -> 248.10387 | U15: =SUM(1800/68)*H15 -> 9.1535294 | X15: =SUM(S15:W15) -> 257.2574 | Y15: =SUM(10716.46/68)*H15 -> 54.496351 | AA15: =SUM(50.64/68)*H15 -> 0.25751929 | AB15: =SUM(Y15:AA15) -> 54.75387 | AC15: 7.33 | AD15: =SUM(AB15*AC15) -> 401.34587 | AE15: =SUM(X15+AD15) -> 658.60327 | AF15: =SUM(P15-AE15) -> 98.396729
C16: 241106000018 | D16: 45602 | E16: Bella | F16: Bella Chan | G16: zhang long ting | H16: 0.0019 | I16: 1 | K16: 51150 | M16: =SUM(K16/N16) -> 1650 | N16: 31 | O16: 7.2 | P16: =SUM(N16*O16) -> 223.2 | S16: =SUM(48788.5/68)*H16 -> 1.3632081 | U16: =SUM(1800/68)*H16 -> 0.050294118 | X16: =SUM(S16:W16) -> 1.4135022 | Y16: =SUM(10716.46/68)*H16 -> 0.2994305 | AA16: =SUM(50.64/68)*H16 -> 0.0014149412 | AB16: =SUM(Y16:AA16) -> 0.30084544 | AC16: 7.33 | AD16: =SUM(AB16*AC16) -> 2.2051971 | AE16: =SUM(X16+AD16) -> 3.6186993 | AF16: =SUM(P16-AE16) -> 219.5813
C17: 241106000037 | D17: 45602 | E17: Sam.Pao | F17: Sam.Pao | G17: JunYue hotel | H17: 0.6996 | I17: 76 | J17: 1583.01 | P17: =SUBTOTAL(9,J17) -> 1583.01 | S17: =SUM(48788.5/68)*H17 -> 501.94757 | U17: =SUM(1800/68)*H17 -> 18.518824 | X17: =SUM(S17:W17) -> 520.46639 | Y17: =SUM(10716.46/68)*H17 -> 110.25346 | AA17: =SUM(50.64/68)*H17 -> 0.52099624 | AB17: =SUM(Y17:AA17) -> 110.77446 | AC17: 7.33 | AD17: =SUM(AB17*AC17) -> 811.97678 | AE17: =SUM(X17+AD17) -> 1332.4432 | AF17: =SUM(P17-AE17) -> 250.56683
C18: 241107000022 | D18: 45602 | E18: 罗珮文 | F18: Shirley | G18: SKY JET | H18: 32.635 | I18: 4165 | J18: 52361.59 | P18: =SUBTOTAL(9,J18) -> 52361.59 | S18: =SUM(48788.5/68)*H18 -> 23414.893 | U18: =SUM(1800/68)*H18 -> 863.86765 | X18: =SUM(S18:W18) -> 24278.76 | Y18: =SUM(10716.46/68)*H18 -> 5143.1128 | AA18: =SUM(50.64/68)*H18 -> 24.303476 | AB18: =SUM(Y18:AA18) -> 5167.4163 | AC18: 7.33 | AD18: =SUM(AB18*AC18) -> 37877.161 | AE18: =SUM(X18+AD18) -> 62155.922 | AF18: =SUM(P18-AE18) -> -9794.3317
A19: 合计 | J19: =SUM(J4:J4) -> 0 | N19: =SUM(N4:N4) -> 0 | P19: =SUM(P4:P4) -> 0 | Q19: =SUM(Q4:Q4) -> 0 | X19: =SUM(X4:X4) -> 0 | AD19: =SUM(AD4:AD4) -> 0 | AF19: =SUM(AF4:AF18) -> 3646.6843

Sheet JOB120363
A1: 2024年11月份LOS毛利表（海运）
A2: PSL表 | B2: 体积cbm | C2: 80.0396
A3: JOB | B3: 集装编号 | C3: 运单编号 | D3: 日期 | E3: 业务 | F3: 发货人 | G3: 收货人 | H3: 计费体积 | I3: 计费重量 | J3: 应 收 | Q3: 总应收 | R3: 起 运 港 成 本 | W3: 代垫运费 | X3: 起运港成本 合计 | Y3: 目的港成本 | AE3: 总支出 | AF3: 利润
J4: 应收RMB | K4: LOS Income(NGN)收到(奈拉) | L4: LOS 收到USD | M4: 美元汇率 dollar currency rate | N4: 应收 到付款USD | O4: 汇率 | P4: 人民币 | R4: 代理商 | S4: 运费+出口报关费 | T4: 提货费 | U4: 装卸费 | V4: 包装费 | Y4: 进口报关费 | Z4: 到门配送费 | AA4: 转运费 | AB4: 目的港支出 | AC4: 汇率 | AD4: 人民币 | AE4: 起运港+目的港
A5: JOB120363 | B5: COLL004291 | C5: 240930000009 | D5: 45608 | E5: 黄颖 | F5: ying | G5: Tom chen | H5: 0.0977 | I5: 28.5 | K5: 132820 | M5: =SUM(K5/N5) -> 1648.9137 | N5: 80.55 | O5: 7.3 | P5: =SUM(N5*O5) -> 588.015 | Q5: =SUM(P5:P26) -> 188664.54 | R5: 登凯=43330 陆总=8000 拖车费=1670 杂费=93 过磅费=125 | S5: =SUM(53218/68)*H5 -> 76.461744 | U5: =SUM(1955/68)*H5 -> 2.808875 | X5: =SUM(S5:W5) -> 79.270619 | Y5: =SUM(11360.84/68)*H5 -> 16.322854 | Z5: 11.38 | AA5: =SUM(53.54/68)*H5 -> 0.076924382 | AB5: =SUM(Y5:AA5) -> 27.779778 | AC5: 7.3 | AD5: =SUM(AB5*AC5) -> 202.79238 | AE5: =SUM(X5+AD5) -> 282.063 | AF5: =SUM(P5-AE5) -> 305.952
C6: 241015000034 | D6: 45608 | E6: 朱小飞 | F6: Isabel Zhu | G6: Halifa Success | H6: 4.77 | I6: 451 | J6: 9789.95 | P6: =SUBTOTAL(9,J6) -> 9789.95 | S6: =SUM(53218/68)*H6 -> 3733.0862 | U6: =SUM(1955/68)*H6 -> 137.1375 | X6: =SUM(S6:W6) -> 3870.2237 | Y6: =SUM(11360.84/68)*H6 -> 796.92951 | AA6: =SUM(53.54/68)*H6 -> 3.7556735 | AB6: =SUM(Y6:AA6) -> 800.68519 | AC6: 7.3 | AD6: =SUM(AB6*AC6) -> 5845.0019 | AE6: =SUM(X6+AD6) -> 9715.2255 | AF6: =SUM(P6-AE6) -> 74.724471
C7: 241021000005 | D7: 45608 | E7: 吕沛霖 | F7: 喵喵速运-Layne | G7: Hu Hai Liang | H7: 1.1795 | I7: 335 | K7: 583853 | M7: =SUM(K7/N7) -> 1650.0015 | N7: 353.84998 | O7: 7.3 | P7: =SUM(N7*O7) -> 2583.1049 | S7: =SUM(53218/68)*H7 -> 923.09751 | U7: =SUM(1955/68)*H7 -> 33.910625 | X7: =SUM(S7:W7) -> 957.00814 | Y7: =SUM(11360.84/68)*H7 -> 197.06045 | AA7: =SUM(53.54/68)*H7 -> 0.92868279 | AB7: =SUM(Y7:AA7) -> 197.98914 | AC7: 7.3 | AD7: =SUM(AB7*AC7) -> 1445.3207 | AE7: =SUM(X7+AD7) -> 2402.3288 | AF7: =SUM(P7-AE7) -> 180.77603
C8: 241022000035 | D8: 45608 | E8: Bella | F8: Bella Chan | G8: zhong zi xin | H8: 28.3553 | I8: 15100 | J8: 62780 | P8: =SUBTOTAL(9,J8) -> 62780 | S8: =SUM(53218/68)*H8 -> 22191.358 | U8: =SUM(1955/68)*H8 -> 815.21488 | V8: 300 | X8: =SUM(S8:W8) -> 23306.573 | Y8: =SUM(11360.84/68)*H8 -> 4737.3533 | Z8: =SUM(413.88+371.27) -> 785.15 | AA8: =SUM(53.54/68)*H8 -> 22.325629 | AB8: =SUM(Y8:AA8) -> 5544.829 | AC8: 7.3 | AD8: =SUM(AB8*AC8) -> 40477.251 | AE8: =SUM(X8+AD8) -> 63783.824 | AF8: =SUM(P8-AE8) -> -1003.8244
C9: 241024000054 | D9: 45608 | E9: Sam.Pao | F9: Sam.Pao | G9: ShanShan | H9: 16.835 | I9: 7500 | J9: 48779 | P9: =SUBTOTAL(9,J9) -> 48779 | S9: =SUM(53218/68)*H9 -> 13175.368 | U9: =SUM(1955/68)*H9 -> 484.00625 | X9: =SUM(S9:W9) -> 13659.374 | Y9: =SUM(11360.84/68)*H9 -> 2812.6433 | Z9: 97.38 | AA9: =SUM(53.54/68)*H9 -> 13.255087 | AB9: =SUM(Y9:AA9) -> 2923.2783 | AC9: 7.3 | AD9: =SUM(AB9*AC9) -> 21339.932 | AE9: =SUM(X9+AD9) -> 34999.306 | AF9: =SUM(P9-AE9) -> 13779.694
C10: 241104000057 | D10: 45608 | E10: 朱小飞 | F10: Isabel Zhu | G10: Halifa Success | H10: 2.3978 | I10: 447 | J10: 4925.76 | P10: =SUBTOTAL(9,J10) -> 4925.76 | S10: =SUM(53218/68)*H10 -> 1876.5606 | U10: =SUM(1955/68)*H10 -> 68.93675 | X10: =SUM(S10:W10) -> 1945.4973 | Y10: =SUM(11360.84/68)*H10 -> 400.60327 | AA10: =SUM(53.54/68)*H10 -> 1.8879149 | AB10: =SUM(Y10:AA10) -> 402.49118 | AC10: 7.3 | AD10: =SUM(AB10*AC10) -> 2938.1856 | AE10: =SUM(X10+AD10) -> 4883.683 | AF10: =SUM(P10-AE10) -> 42.077029
C11: 241104000071 | D11: 45608 | E11: Bella | F11: Bella Chan | G11: FENG | H11: 0.2523 | I11: 27 | K11: 116127 | M11: =SUM(K11/N11) -> 1684.4648 | N11: 68.94 | O11: 7.3 | P11: =SUM(N11*O11) -> 503.262 | S11: =SUM(53218/68)*H11 -> 197.45443 | U11: =SUM(1955/68)*H11 -> 7.253625 | X11: =SUM(S11:W11) -> 204.70806 | Y11: =SUM(11360.84/68)*H11 -> 42.152058 | AA11: =SUM(53.54/68)*H11 -> 0.19864915 | AB11: =SUM(Y11:AA11) -> 42.350707 | AC11: 7.3 | AD11: =SUM(AB11*AC11) -> 309.16016 | AE11: =SUM(X11+AD11) -> 513.86822 | AF11: =SUM(P11-AE11) -> -10.606218
C12: 241105000024 | D12: 45608 | E12: 陆总 | F12: 陆梓龙 | G12: luk | H12: 2.0026 | I12: 262.5 | J12: 4385.69 | P12: =SUBTOTAL(9,J12) -> 4385.69 | S12: =SUM(53218/68)*H12 -> 1567.2701 | U12: =SUM(1955/68)*H12 -> 57.57475 | X12: =SUM(S12:W12) -> 1624.8448 | Y12: =SUM(11360.84/68)*H12 -> 334.57674 | AA12: =SUM(53.54/68)*H12 -> 1.576753 | AB12: =SUM(Y12:AA12) -> 336.15349 | AC12: 7.3 | AD12: =SUM(AB12*AC12) -> 2453.9205 | AE12: =SUM(X12+AD12) -> 4078.7653 | AF12: =SUM(P12-AE12) -> 306.92467
C13: 241105000025 | D13: 45608 | E13: 黄颖 | F13: ying | G13: Oba Adeoriyomi Oyebo | H13: 3.7323 | I13: 536 | K13: 1998941 | M13: =SUM(K13/N13) -> 1712.4484 | N13: 1167.3 | O13: 7.3 | P13: =SUM(N13*O13) -> 8521.29 | S13: =SUM(53218/68)*H13 -> 2920.9638 | U13: =SUM(1955/68)*H13 -> 107.30362 | W13: 350 | X13: =SUM(S13:W13) -> 3378.2675 | Y13: =SUM(11360.84/68)*H13 -> 623.55975 | AA13: =SUM(53.54/68)*H13 -> 2.9386374 | AB13: =SUM(Y13:AA13) -> 626.49839 | AC13: 7.3 | AD13: =SUM(AB13*AC13) -> 4573.4382 | AE13: =SUM(X13+AD13) -> 7951.7057 | AF13: =SUM(P13-AE13) -> 569.58429
C14: 241105000054 | D14: 45608 | E14: 苏慧琪 | F14: KAY | G14: R李金 | H14: 0.3709 | I14: 167 | K14: 206012.98 | M14: =SUM(K14/N14) -> 1664.8859 | N14: 123.74 | O14: 7.27 | P14: =SUM(N14*O14) -> 899.5898 | S14: =SUM(53218/68)*H14 -> 290.27289 | U14: =SUM(1955/68)*H14 -> 10.663375 | X14: =SUM(S14:W14) -> 300.93626 | Y14: =SUM(11360.84/68)*H14 -> 61.966699 | AA14: =SUM(53.54/68)*H14 -> 0.29202921 | AB14: =SUM(Y14:AA14) -> 62.258729 | AC14: 7.3 | AD14: =SUM(AB14*AC14) -> 454.48872 | AE14: =SUM(X14+AD14) -> 755.42498 | AF14: =SUM(P14-AE14) -> 144.16482
C15: 241106000015 | D15: 45608 | E15: 朱小飞 | F15: Isabel Zhu | G15: Komebility gift | H15: 0.2358 | I15: 43 | K15: 132422.4 | M15: =SUM(K15/N15) -> 1672 | N15: 79.2 | O15: 7.3 | P15: =SUM(N15*O15) -> 578.16 | S15: =SUM(53218/68)*H15 -> 184.54124 | U15: =SUM(1955/68)*H15 -> 6.77925 | X15: =SUM(S15:W15) -> 191.32049 | Y15: =SUM(11360.84/68)*H15 -> 39.395383 | AA15: =SUM(53.54/68)*H15 -> 0.18565782 | AB15: =SUM(Y15:AA15) -> 39.581041 | AC15: 7.3 | AD15: =SUM(AB15*AC15) -> 288.9416 | AE15: =SUM(X15+AD15) -> 480.26209 | AF15: =SUM(P15-AE15) -> 97.897908
C16: 241106000020 | D16: 45608 | E16: 黄颖 | F16: ying | G16: yuhuichao | H16: 0.3 | I16: 65 | J16: 908 | P16: =SUBTOTAL(9,J16) -> 908 | S16: =SUM(53218/68)*H16 -> 234.78529 | U16: =SUM(1955/68)*H16 -> 8.625 | X16: =SUM(S16:W16) -> 243.41029 | Y16: =SUM(11360.84/68)*H16 -> 50.121353 | Z16: 34.85 | AA16: =SUM(53.54/68)*H16 -> 0.23620588 | AB16: =SUM(Y16:AA16) -> 85.207559 | AC16: 7.3 | AD16: =SUM(AB16*AC16) -> 622.01518 | AE16: =SUM(X16+AD16) -> 865.42547 | AF16: =SUM(P16-AE16) -> 42.574526
C17: 241106000026 | D17: 45608 | E17: 吕沛霖 | F17: 喵喵速运-Layne | G17: Mr.Shen | H17: 0.1938 | I17: 63 | K17: 188972 | M17: =SUM(K17/N17) -> 1700 | N17: 111.16 | O17: 7.27 | P17: =SUM(N17*O17) -> 808.1332 | S17: =SUM(53218/68)*H17 -> 151.6713 | U17: =SUM(1955/68)*H17 -> 5.57175 | X17: =SUM(S17:W17) -> 157.24305 | Y17: =SUM(11360.84/68)*H17 -> 32.378394 | Z17: 53.58 | AA17: =SUM(53.54/68)*H17 -> 0.152589 | AB17: =SUM(Y17:AA17) -> 86.110983 | AC17: 7.3 | AD17: =SUM(AB17*AC17) -> 628.61018 | AE17: =SUM(X17+AD17) -> 785.85323 | AF17: =SUM(P17-AE17) -> 22.279974
C18: 241106000034 | D18: 45608 | E18: 黄颖 | F18: ying | G18: Mr.zhang | H18: 0.3814 | I18: 55 | J18: 1213 | P18: =SUBTOTAL(9,J18) -> 1213 | S18: =SUM(53218/68)*H18 -> 298.49037 | U18: =SUM(1955/68)*H18 -> 10.96525 | X18: =SUM(S18:W18) -> 309.45562 | Y18: =SUM(11360.84/68)*H18 -> 63.720947 | Z18: 44.32 | AA18: =SUM(53.54/68)*H18 -> 0.30029641 | AB18: =SUM(Y18:AA18) -> 108.34124 | AC18: 7.3 | AD18: =SUM(AB18*AC18) -> 790.89107 | AE18: =SUM(X18+AD18) -> 1100.3467 | AF18: =SUM(P18-AE18) -> 112.6533
C19: 241106000049 | D19: 45608 | E19: 黄颖 | F19: ying | G19: wuchengxing | H19: 0.0224 | I19: 5.5 | J19: 228 | P19: =SUBTOTAL(9,J19) -> 228 | S19: =SUM(53218/68)*H19 -> 17.530635 | U19: =SUM(1955/68)*H19 -> 0.644 | X19: =SUM(S19:W19) -> 18.174635 | Y19: =SUM(11360.84/68)*H19 -> 3.7423944 | AA19: =SUM(53.54/68)*H19 -> 0.017636706 | AB19: =SUM(Y19:AA19) -> 3.7600311 | AC19: 7.3 | AD19: =SUM(AB19*AC19) -> 27.448227 | AE19: =SUM(X19+AD19) -> 45.622862 | AF19: =SUM(P19-AE19) -> 182.37714
C20: 241107000010 | D20: 45608 | E20: 朱小飞 | F20: Isabel Zhu | G20: Joy | H20: 0.616 | I20: 188 | K20: 331724.8 | M20: =SUM(K20/N20) -> 1672 | N20: 198.4 | O20: 7.3 | P20: =SUM(N20*O20) -> 1448.32 | S20: =SUM(53218/68)*H20 -> 482.09247 | U20: =SUM(1955/68)*H20 -> 17.71 | X20: =SUM(S20:W20) -> 499.80247 | Y20: =SUM(11360.84/68)*H20 -> 102.91584 | Z20: 3.11 | AA20: =SUM(53.54/68)*H20 -> 0.48500941 | AB20: =SUM(Y20:AA20) -> 106.51085 | AC20: 7.3 | AD20: =SUM(AB20*AC20) -> 777.52924 | AE20: =SUM(X20+AD20) -> 1277.3317 | AF20: =SUM(P20-AE20) -> 170.98829
C21: 241107000011 | D21: 45608 | E21: 朱小飞 | F21: Isabel Zhu | G21: Joy | H21: 2.028 | I21: 358 | K21: 1086131.2 | M21: =SUM(K21/N21) -> 1672 | N21: 649.6 | O21: 7.3 | P21: =SUM(N21*O21) -> 4742.08 | S21: =SUM(53218/68)*H21 -> 1587.1486 | U21: =SUM(1955/68)*H21 -> 58.305 | X21: =SUM(S21:W21) -> 1645.4536 | Y21: =SUM(11360.84/68)*H21 -> 338.82035 | Z21: 10.18 | AA21: =SUM(53.54/68)*H21 -> 1.5967518 | AB21: =SUM(Y21:AA21) -> 350.5971 | AC21: 7.3 | AD21: =SUM(AB21*AC21) -> 2559.3588 | AE21: =SUM(X21+AD21) -> 4204.8124 | AF21: =SUM(P21-AE21) -> 537.2676
C22: 241107000012 | D22: 45608 | E22: 朱小飞 | F22: Isabel Zhu | G22: Joy | H22: 7.8483 | I22: 1598 | K22: 4200064 | M22: =SUM(K22/N22) -> 1672 | N22: 2512 | O22: 7.3 | P22: =SUM(N22*O22) -> 18337.6 | S22: =SUM(53218/68)*H22 -> 6142.2181 | U22: =SUM(1955/68)*H22 -> 225.63862 | X22: =SUM(S22:W22) -> 6367.8567 | Y22: =SUM(11360.84/68)*H22 -> 1311.2247 | Z22: 39.27 | AA22: =SUM(53.54/68)*H22 -> 6.1793821 | AB22: =SUM(Y22:AA22) -> 1356.6741 | AC22: 7.3 | AD22: =SUM(AB22*AC22) -> 9903.7209 | AE22: =SUM(X22+AD22) -> 16271.578 | AF22: =SUM(P22-AE22) -> 2066.0224
C23: 241108000001 | D23: 45608 | E23: Sam.Pao | F23: Sam.Pao | G23: Mr. Jiang | H23: 1.6887 | I23: 558 | J23: 5053 | P23: =SUBTOTAL(9,J23) -> 5053 | S23: =SUM(53218/68)*H23 -> 1321.6064 | U23: =SUM(1955/68)*H23 -> 48.550125 | X23: =SUM(S23:W23) -> 1370.1565 | Y23: =SUM(11360.84/68)*H23 -> 282.1331 | Z23: 57.94 | AA23: =SUM(53.54/68)*H23 -> 1.3296029 | AB23: =SUM(Y23:AA23) -> 341.4027 | AC23: 7.3 | AD23: =SUM(AB23*AC23) -> 2492.2397 | AE23: =SUM(X23+AD23) -> 3862.3962 | AF23: =SUM(P23-AE23) -> 1190.6038
C24: 241109000008 | D24: 45608 | E24: 朱小飞 | F24: Isabel Zhu | G24: Komebility gift | H24: 1.344 | I24: 254 | K24: 696622.08 | M24: =SUM(K24/N24) -> 1672 | N24: 416.64 | O24: 7.3 | P24: =SUM(N24*O24) -> 3041.472 | S24: =SUM(53218/68)*H24 -> 1051.8381 | U24: =SUM(1955/68)*H24 -> 38.64 | X24: =SUM(S24:W24) -> 1090.4781 | Y24: =SUM(11360.84/68)*H24 -> 224.54366 | AA24: =SUM(53.54/68)*H24 -> 1.0582024 | AB24: =SUM(Y24:AA24) -> 225.60186 | AC24: 7.3 | AD24: =SUM(AB24*AC24) -> 1646.8936 | AE24: =SUM(X24+AD24) -> 2737.3717 | AF24: =SUM(P24-AE24) -> 304.10028
C25: 241210000044 | D25: 45609 | E25: 罗珮文 | F25: Shirley | G25: SKY JET | H25: 5.104 | I25: 471 | J25: 7929.81 | P25: =SUBTOTAL(9,J25) -> 7929.81 | S25: =SUM(53218/68)*H25 -> 3994.4805 | U25: =SUM(1955/68)*H25 -> 146.74 | X25: =SUM(S25:W25) -> 4141.2205 | Y25: =SUM(11360.84/68)*H25 -> 852.73128 | AA25: =SUM(53.54/68)*H25 -> 4.0186494 | AB25: =SUM(Y25:AA25) -> 856.74993 | AC25: 7.3 | AD25: =SUM(AB25*AC25) -> 6254.2745 | AE25: =SUM(X25+AD25) -> 10395.495 | AF25: =SUM(P25-AE25) -> -2465.685
C26: 241112000025 | D26: 45608 | E26: 陆总 | F26: 陆梓龙 | G26: xinlong | H26: 0.2838 | I26: 166 | J26: 621.3 | P26: =SUBTOTAL(9,J26) -> 621.3 | S26: =SUM(53218/68)*H26 -> 222.10689 | U26: =SUM(1955/68)*H26 -> 8.15925 | X26: =SUM(S26:W26) -> 230.26614 | Y26: =SUM(11360.84/68)*H26 -> 47.4148 | AA26: =SUM(53.54/68)*H26 -> 0.22345076 | AB26: =SUM(Y26:AA26) -> 47.638251 | AC26: 7.3 | AD26: =SUM(AB26*AC26) -> 347.75923 | AE26: =SUM(X26+AD26) -> 578.02537 | AF26: =SUM(P26-AE26) -> 43.274632
A27: 合计 | J27: =SUM(J4:J4) -> 0 | N27: =SUM(N4:N4) -> 0 | P27: =SUM(P4:P4) -> 0 | Q27: =SUM(Q4:Q4) -> 0 | X27: =SUM(X4:X4) -> 0 | AD27: =SUM(AD4:AD4) -> 0 | AF27: =SUM(AF4:AF26) -> 16693.821

Sheet JOB120364
A1: 2024年11月份LOS毛利表（海运）
A2: PSL表 | B2: 体积cbm | C2: 73.881
A3: JOB | B3: 集装编号 | C3: 运单编号 | D3: 日期 | E3: 业务 | F3: 发货人 | G3: 收货人 | H3: 计费体积 | I3: 计费重量 | J3: 应 收 | Q3: 总应收 | R3: 起 运 港 成 本 | W3: 代垫运费 | X3: 起运港成本 合计 | Y3: 目的港成本 | AE3: 总支出 | AF3: 利润
J4: 应收RMB | K4: LOS Income(NGN)收到(奈拉) | L4: LOS 收到USD | M4: 美元汇率 dollar currency rate | N4: 应收 到付款USD | O4: 汇率 | P4: 人民币 | R4: 代理商 | S4: 运费+出口报关费 | T4: 提货费 | U4: 装卸费 | V4: 包装费 | Y4: 进口报关费 | Z4: 到门配送费 | AA4: 转运费 | AB4: 目的港支出 | AC4: 汇率 | AD4: 人民币 | AE4: 起运港+目的港
A5: JOB120364 | B5: COLL004298 | C5: 241030000025 | D5: 45609 | E5: 黄颖 | F5: ying | G5: Nura | H5: 0.0306 | I5: 10 | J5: 65 | P5: =SUBTOTAL(9,J5) -> 65 | Q5: =SUM(P5:P24) -> 145491.1 | R5: 登凯=43330 赛捷=1660 拖车费=1670 杂费=73 过磅费=70 | S5: =SUM(46803/68)*H5 -> 21.06135 | U5: =SUM(1800/68)*H5 -> 0.81 | X5: =SUM(S5:W5) -> 21.87135 | Y5: =SUM(10793.87/68)*H5 -> 4.8572415 | AA5: =SUM(94.98/68)*H5 -> 0.042741 | AB5: =SUM(Y5:AA5) -> 4.8999825 | AC5: 7.33 | AD5: =SUM(AB5*AC5) -> 35.916872 | AE5: =SUM(X5+AD5) -> 57.788222 | AF5: =SUM(P5-AE5) -> 7.2117783
C6: 241102000008 | D6: 45609 | E6: 黄颖 | F6: ying | G6: Bruce | H6: 2.0582 | I6: 755 | K6: 957151 | M6: =SUM(K6/N6) -> 1603.5903 | N6: 596.88 | O6: 7.3 | P6: =SUM(N6*O6) -> 4357.224 | S6: =SUM(46803/68)*H6 -> 1416.6167 | U6: =SUM(1800/68)*H6 -> 54.481765 | X6: =SUM(S6:W6) -> 1471.0984 | Y6: =SUM(10793.87/68)*H6 -> 326.70505 | AA6: =SUM(94.98/68)*H6 -> 2.8748211 | AB6: =SUM(Y6:AA6) -> 329.57987 | AC6: 7.33 | AD6: =SUM(AB6*AC6) -> 2415.8204 | AE6: =SUM(X6+AD6) -> 3886.9189 | AF6: =SUM(P6-AE6) -> 470.30511
C7: 241107000009 | D7: 45609 | E7: 黄颖 | F7: ying | G7: MISS Huang | H7: 1.6128 | I7: 1251 | J7: 3794.79 | P7: =SUBTOTAL(9,J7) -> 3794.79 | S7: =SUM(46803/68)*H7 -> 1110.057 | U7: =SUM(1800/68)*H7 -> 42.691765 | X7: =SUM(S7:W7) -> 1152.7488 | Y7: =SUM(10793.87/68)*H7 -> 256.0052 | AA7: =SUM(94.98/68)*H7 -> 2.2527021 | AB7: =SUM(Y7:AA7) -> 258.2579 | AC7: 7.33 | AD7: =SUM(AB7*AC7) -> 1893.0304 | AE7: =SUM(X7+AD7) -> 3045.7792 | AF7: =SUM(P7-AE7) -> 749.01078
C8: 241104000001 | D8: 45609 | E8: 吕沛霖 | F8: 喵喵速运-Layne | G8: Isa | H8: 0.462 | I8: 90 | K8: 368397.9 | M8: =SUM(K8/N8) -> 1665 | N8: 221.26 | O8: 7.3 | P8: =SUM(N8*O8) -> 1615.198 | S8: =SUM(46803/68)*H8 -> 317.98509 | U8: =SUM(1800/68)*H8 -> 12.229412 | X8: =SUM(S8:W8) -> 330.2145 | Y8: =SUM(10793.87/68)*H8 -> 73.334823 | Z8: 57.94 | AA8: =SUM(94.98/68)*H8 -> 0.64530529 | AB8: =SUM(Y8:AA8) -> 131.92013 | AC8: 7.33 | AD8: =SUM(AB8*AC8) -> 966.97454 | AE8: =SUM(X8+AD8) -> 1297.189 | AF8: =SUM(P8-AE8) -> 318.00896
C9: 241105000045 | D9: 45609 | E9: 吕沛霖 | F9: 喵喵速运-Layne | G9: Abdulsheldu | H9: 0.8486 | I9: 297 | K9: 432928.65 | M9: =SUM(K9/N9) -> 1663.255 | N9: 260.29 | O9: 7.3 | P9: =SUM(N9*O9) -> 1900.117 | S9: =SUM(46803/68)*H9 -> 584.07391 | U9: =SUM(1800/68)*H9 -> 22.462941 | X9: =SUM(S9:W9) -> 606.53685 | Y9: =SUM(10793.87/68)*H9 -> 134.70115 | Z9: 10.07 | AA9: =SUM(94.98/68)*H9 -> 1.1852945 | AB9: =SUM(Y9:AA9) -> 145.95644 | AC9: 7.33 | AD9: =SUM(AB9*AC9) -> 1069.8607 | AE9: =SUM(X9+AD9) -> 1676.3976 | AF9: =SUM(P9-AE9) -> 223.71942
C10: 241108000043 | D10: 45609 | E10: Bella | F10: Bella Chan | G10: weng zixian | H10: 1.4833 | I10: 598 | K10: 1160958 | M10: =SUM(K10/N10) -> 1666.4389 | N10: 696.67 | O10: 7.3 | P10: =SUM(N10*O10) -> 5085.691 | S10: =SUM(46803/68)*H10 -> 1020.9249 | U10: =SUM(1800/68)*H10 -> 39.263824 | X10: =SUM(S10:W10) -> 1060.1887 | Y10: =SUM(10793.87/68)*H10 -> 235.44923 | Z10: 251.65 | AA10: =SUM(94.98/68)*H10 -> 2.0718211 | AB10: =SUM(Y10:AA10) -> 489.17105 | AC10: 7.33 | AD10: =SUM(AB10*AC10) -> 3585.6238 | AE10: =SUM(X10+AD10) -> 4645.8125 | AF10: =SUM(P10-AE10) -> 439.87855
C11: 241111000011 | D11: 45609 | E11: 朱小飞 | F11: Isabel Zhu | G11: Ope Olofinjana | H11: 0.1421 | I11: 36 | K11: 93936 | M11: =SUM(K11/N11) -> 1651.1865 | N11: 56.89 | O11: 7.3 | P11: =SUM(N11*O11) -> 415.297 | S11: =SUM(46803/68)*H11 -> 97.804504 | U11: =SUM(1800/68)*H11 -> 3.7614706 | X11: =SUM(S11:W11) -> 101.56597 | Y11: =SUM(10793.87/68)*H11 -> 22.556014 | Z11: 10 | AA11: =SUM(94.98/68)*H11 -> 0.19848026 | AB11: =SUM(Y11:AA11) -> 32.754494 | AC11: 7.33 | AD11: =SUM(AB11*AC11) -> 240.09044 | AE11: =SUM(X11+AD11) -> 341.65642 | AF11: =SUM(P11-AE11) -> 73.640585
C12: 241111000012 | D12: 45609 | E12: 朱小飞 | F12: Isabel Zhu | G12: Ope Olofinjana | H12: 0.2386 | I12: 52 | K12: 148176 | M12: =SUM(K12/N12) -> 1651.17 | N12: 89.74 | O12: 7.3 | P12: =SUM(N12*O12) -> 655.102 | S12: =SUM(46803/68)*H12 -> 164.22347 | U12: =SUM(1800/68)*H12 -> 6.3158824 | X12: =SUM(S12:W12) -> 170.53935 | Y12: =SUM(10793.87/68)*H12 -> 37.873785 | Z12: 11.3 | AA12: =SUM(94.98/68)*H12 -> 0.33326806 | AB12: =SUM(Y12:AA12) -> 49.507053 | AC12: 7.33 | AD12: =SUM(AB12*AC12) -> 362.8867 | AE12: =SUM(X12+AD12) -> 533.42605 | AF12: =SUM(P12-AE12) -> 121.67595
C13: 241111000032 | D13: 45609 | E13: Bella | F13: Bella Chan | G13: FENG | H13: 0.2174 | I13: 57 | K13: 107613 | M13: =SUM(K13/N13) -> 1650.0003 | N13: 65.21999 | O13: 7.2 | P13: =SUM(N13*O13) -> 469.58393 | S13: =SUM(46803/68)*H13 -> 149.63194 | U13: =SUM(1800/68)*H13 -> 5.7547059 | X13: =SUM(S13:W13) -> 155.38665 | Y13: =SUM(10793.87/68)*H13 -> 34.508637 | AA13: =SUM(94.98/68)*H13 -> 0.30365665 | AB13: =SUM(Y13:AA13) -> 34.812294 | AC13: 7.33 | AD13: =SUM(AB13*AC13) -> 255.17411 | AE13: =SUM(X13+AD13) -> 410.56076 | AF13: =SUM(P13-AE13) -> 59.023163
C14: 241111000039 | D14: 45609 | E14: 无人 | F14: dejare James | G14: James | H14: 1.8662 | I14: 626 | L14: 559.83 | M14: =SUM(K14/N14) -> 0 | N14: 559.82996 | O14: 7.3 | P14: =SUM(N14*O14) -> 4086.7587 | S14: =SUM(46803/68)*H14 -> 1284.467 | U14: =SUM(1800/68)*H14 -> 49.399412 | X14: =SUM(S14:W14) -> 1333.8664 | Y14: =SUM(10793.87/68)*H14 -> 296.22824 | AA14: =SUM(94.98/68)*H14 -> 2.6066423 | AB14: =SUM(Y14:AA14) -> 298.83488 | AC14: 7.33 | AD14: =SUM(AB14*AC14) -> 2190.4597 | AE14: =SUM(X14+AD14) -> 3524.3261 | AF14: =SUM(P14-AE14) -> 562.43258
C15: 241111000055 | D15: 45609 | E15: 朱小飞 | F15: Isabel Zhu | G15: Halifa Success | H15: 2.9026 | I15: 435 | J15: 5972.48 | P15: =SUBTOTAL(9,J15) -> 5972.48 | S15: =SUM(46803/68)*H15 -> 1997.7998 | U15: =SUM(1800/68)*H15 -> 76.833529 | V15: 20 | X15: =SUM(S15:W15) -> 2094.6334 | Y15: =SUM(10793.87/68)*H15 -> 460.73952 | AA15: =SUM(94.98/68)*H15 -> 4.0542492 | AB15: =SUM(Y15:AA15) -> 464.79376 | AC15: 7.33 | AD15: =SUM(AB15*AC15) -> 3406.9383 | AE15: =SUM(X15+AD15) -> 5501.5716 | AF15: =SUM(P15-AE15) -> 470.90835
C16: 241111000056 | D16: 45609 | E16: 朱小飞 | F16: Isabel Zhu | G16: Halifa Success | H16: 2.4588 | I16: 346 | J16: 5048.9 | P16: =SUBTOTAL(9,J16) -> 5048.9 | S16: =SUM(46803/68)*H16 -> 1692.3414 | U16: =SUM(1800/68)*H16 -> 65.085882 | X16: =SUM(S16:W16) -> 1757.4273 | Y16: =SUM(10793.87/68)*H16 -> 390.29364 | AA16: =SUM(94.98/68)*H16 -> 3.4343651 | AB16: =SUM(Y16:AA16) -> 393.72801 | AC16: 7.33 | AD16: =SUM(AB16*AC16) -> 2886.0263 | AE16: =SUM(X16+AD16) -> 4643.4536 | AF16: =SUM(P16-AE16) -> 405.44642
C17: 241112000043 | D17: 45609 | E17: Sam.Pao | F17: Sam.Pao | G17: MaiKaiNian | H17: 4.9039 | I17: 546 | J17: 10739.54 | P17: =SUBTOTAL(9,J17) -> 10739.54 | S17: =SUM(46803/68)*H17 -> 3375.2534 | U17: =SUM(1800/68)*H17 -> 129.80912 | X17: =SUM(S17:W17) -> 3505.0625 | Y17: =SUM(10793.87/68)*H17 -> 778.41263 | AA17: =SUM(94.98/68)*H17 -> 6.8495944 | AB17: =SUM(Y17:AA17) -> 785.26223 | AC17: 7.33 | AD17: =SUM(AB17*AC17) -> 5755.9721 | AE17: =SUM(X17+AD17) -> 9261.0347 | AF17: =SUM(P17-AE17) -> 1478.5053
C18: 241112000044 | D18: 45609 | E18: 朱小飞 | F18: Isabel Zhu | G18: Halifa Success | H18: 0.936 | I18: 422 | J18: 2195.26 | P18: =SUBTOTAL(9,J18) -> 2195.26 | S18: =SUM(46803/68)*H18 -> 644.22953 | U18: =SUM(1800/68)*H18 -> 24.776471 | W18: 266 | X18: =SUM(S18:W18) -> 935.006 | Y18: =SUM(10793.87/68)*H18 -> 148.57445 | Z18: 17.33 | AA18: =SUM(94.98/68)*H18 -> 1.3073718 | AB18: =SUM(Y18:AA18) -> 167.21182 | AC18: 7.33 | AD18: =SUM(AB18*AC18) -> 1225.6626 | AE18: =SUM(X18+AD18) -> 2160.6686 | AF18: =SUM(P18-AE18) -> 34.591377
C19: 241113000012 | D19: 45609 | E19: 罗珮文 | F19: Shirley | G19: Yusky | H19: 5.5016 | I19: 2874 | K19: 2264723.3 | M19: =SUM(K19/N19) -> 1608 | N19: 1408.41 | O19: 7.3 | P19: =SUM(N19*O19) -> 10281.393 | S19: =SUM(46803/68)*H19 -> 3786.638 | U19: =SUM(1800/68)*H19 -> 145.63059 | X19: =SUM(S19:W19) -> 3932.2686 | Y19: =SUM(10793.87/68)*H19 -> 873.28758 | AA19: =SUM(94.98/68)*H19 -> 7.6844407 | AB19: =SUM(Y19:AA19) -> 880.97202 | AC19: 7.33 | AD19: =SUM(AB19*AC19) -> 6457.5249 | AE19: =SUM(X19+AD19) -> 10389.793 | AF19: =SUM(P19-AE19) -> -108.40049
C20: 241113000017 | D20: 45609 | E20: Sam.Pao | F20: Sam.Pao | G20: FanXiangGuo | H20: 1.4152 | I20: 656 | K20: 851651 | M20: =SUM(K20/N20) -> 1671.5099 | N20: 509.51 | O20: 7.29 | P20: =SUM(N20*O20) -> 3714.3279 | S20: =SUM(46803/68)*H20 -> 974.05302 | U20: =SUM(1800/68)*H20 -> 37.461176 | W20: 98.72 | X20: =SUM(S20:W20) -> 1110.2342 | Y20: =SUM(10793.87/68)*H20 -> 224.63948 | AA20: =SUM(94.98/68)*H20 -> 1.9767014 | AB20: =SUM(Y20:AA20) -> 226.61618 | AC20: 7.33 | AD20: =SUM(AB20*AC20) -> 1661.0966 | AE20: =SUM(X20+AD20) -> 2771.3308 | AF20: =SUM(P20-AE20) -> 942.99707
