Workbook

Sheet 总表
A1: 2024年07月份LOS毛利表（海运）
A2: JOB | B2: 集装编号 | C2: 利润
A4: JOB070344 | B4: COLL004043 | C4: =SUM('JOB070344'!AF26) -> 19020.507
A25: JOB070349 | B25: COLL004049 | C25: =SUM('JOB070349'!AF12) -> 14370.871
A32: JOB070360 | B32: COLL004060 | C32: =SUM('JOB070360'!AF11) -> 29212.56
A38: JOB070370 | B38: COLL004070 | C38: =SUM('JOB070370'!AF17) -> 11610.2
A50: JOB070375 | B50: COLL004074 | C50: =SUM('JOB070375'!AF25) -> 9409.1083
A70: 合计 | C70: =SUM(C4:C69) -> 83623.247

Sheet 总表 (2)
A1: 2024年07月份LOS毛利表（海运）
A2: JOB | B2: 集装编号 | C2: 运单编号 | D2: 日期 | E2: 业务 | F2: 发货人 | G2: 收货人 | H2: 计费体积 | I2: 计费重量 | J2: 应 收 | Q2: 总应收 | R2: 起 运 港 成 本 | W2: 代垫运费 | X2: 起运港成本 合计 | Y2: 目的港成本 | AE2: 总支出 | AF2: 利润
J3: 应收RMB | K3: LOS Income(NGN)收到(奈拉) | L3: LOS 收到USD | M3: 美元汇率 dollar currency rate | N3: 应收 到付款USD | O3: 汇率 | P3: 人民币 | R3: 代理商 | S3: 运费+出口报关费 | T3: 提货费 | U3: 装卸费 | V3: 包装费 | Y3: 进口报关费 | Z3: 到门配送费 | AA3: 转运费 | AB3: 目的港支出 | AC3: 汇率 | AD3: 人民币 | AE3: 起运港+目的港
A4: JOB070344 | B4: COLL004043 | C4: 240624000034 | D4: 45477 | E4: 黄颖 | F4: ying | G4: baikaibo | H4: 3.024 | I4: 2000 | K4: 2320436 | M4: =SUM(K4/N4) -> 1651.8616 | N4: 1404.74 | O4: 7.12 | P4: =SUM(N4*O4) -> 10001.749 | Q4: =SUM(P4:P24) -> 168759.19 | R4: 华茂青松=60177 赛捷=1300 | S4: =SUM(61477/68)*H4 -> 2733.9184 | U4: =SUM(1250/68)*H4 -> 55.588235 | X4: =SUM(S4:W4) -> 2789.5066 | Y4: =SUM(10640.25/68)*H4 -> 473.17818 | Z4: 5.49 | AB4: =SUM(Y4:AA4) -> 478.66818 | AC4: 7.1 | AD4: =SUM(AB4*AC4) -> 3398.5441 | AE4: =SUM(X4+AD4) -> 6188.0506 | AF4: =SUM(P4-AE4) -> 3813.6982
C5: 240624000036 | D5: 45478 | E5: 黄颖 | F5: ying | G5: Sunday Adelena | H5: 10.2263 | I5: 7008 | J5: 26828 | P5: =SUBTOTAL(9,J5) -> 26828 | S5: =SUM(61477/68)*H5 -> 9245.3271 | U5: =SUM(1250/68)*H5 -> 187.98346 | V5: 120 | X5: =SUM(S5:W5) -> 9553.3106 | Y5: =SUM(10640.25/68)*H5 -> 1600.1528 | AB5: =SUM(Y5:AA5) -> 1600.1528 | AC5: 7.1 | AD5: =SUM(AB5*AC5) -> 11361.085 | AE5: =SUM(X5+AD5) -> 20914.395 | AF5: =SUM(P5-AE5) -> 5913.6047
C6: 240624000056 | D6: 45477 | E6: Sam.Pao | F6: Sam.Pao | G6: TOLUBOD MOVERS | H6: 0.509 | I6: 207 | J6: 1893.7 | P6: =SUBTOTAL(9,J6) -> 1893.7 | S6: =SUM(61477/68)*H6 -> 460.17343 | U6: =SUM(1250/68)*H6 -> 9.3566176 | V6: 270 | X6: =SUM(S6:W6) -> 739.53004 | Y6: =SUM(10640.25/68)*H6 -> 79.645401 | AB6: =SUM(Y6:AA6) -> 79.645401 | AC6: 7.1 | AD6: =SUM(AB6*AC6) -> 565.48235 | AE6: =SUM(X6+AD6) -> 1305.0124 | AF6: =SUM(P6-AE6) -> 588.68761
C7: 240626000044 | D7: 45477 | E7: Sam.Pao | F7: Sam.Pao | G7: JunYue hotel | H7: 0.6356 | I7: 450 | J7: 1714.8 | P7: =SUM(J7) -> 1714.8 | S7: =SUM(61477/68)*H7 -> 574.62914 | U7: =SUM(1250/68)*H7 -> 11.683824 | X7: =SUM(S7:W7) -> 586.31296 | Y7: =SUM(10640.25/68)*H7 -> 99.455043 | AB7: =SUM(Y7:AA7) -> 99.455043 | AC7: 7.1 | AD7: =SUM(AB7*AC7) -> 706.1308 | AE7: =SUM(X7+AD7) -> 1292.4438 | AF7: =SUM(P7-AE7) -> 422.35624
C8: 240628000020 | D8: 45477 | E8: 黄颖 | F8: ying | G8: baikaibo | H8: 0.472 | I8: 420 | K8: 439900 | M8: =SUM(K8/N8) -> 1705.0388 | N8: 258 | O8: 7.12 | P8: =SUM(N8*O8) -> 1836.96 | S8: =SUM(61477/68)*H8 -> 426.72271 | U8: =SUM(1250/68)*H8 -> 8.6764706 | X8: =SUM(S8:W8) -> 435.39918 | Y8: =SUM(10640.25/68)*H8 -> 73.855853 | AB8: =SUM(Y8:AA8) -> 73.855853 | AC8: 7.1 | AD8: =SUM(AB8*AC8) -> 524.37656 | AE8: =SUM(X8+AD8) -> 959.77573 | AF8: =SUM(P8-AE8) -> 877.18427
C9: 240628000031 | D9: 45477 | E9: 朱小飞 | F9: Isabel Zhu | G9: Wang Hui Feng | H9: 1.7537 | I9: 2930 | K9: 2405060 | M9: =SUM(K9/N9) -> 1640 | N9: 1466.5 | O9: 7.12 | P9: =SUM(N9*O9) -> 10441.48 | S9: =SUM(61477/68)*H9 -> 1585.4737 | U9: =SUM(1250/68)*H9 -> 32.237132 | X9: =SUM(S9:W9) -> 1617.7109 | Y9: =SUM(10640.25/68)*H9 -> 274.40892 | AB9: =SUM(Y9:AA9) -> 274.40892 | AC9: 7.1 | AD9: =SUM(AB9*AC9) -> 1948.3033 | AE9: =SUM(X9+AD9) -> 3566.0142 | AF9: =SUM(P9-AE9) -> 6875.4658
C10: 240628000036 | D10: 45477 | E10: 朱小飞 | F10: Isabel Zhu | G10: Halifa Success | H10: 0.6693 | I10: 116.5 | J10: 1662.94 | P10: =SUBTOTAL(9,J10) -> 1662.94 | S10: =SUM(61477/68)*H10 -> 605.09641 | U10: =SUM(1250/68)*H10 -> 12.303309 | X10: =SUM(S10:W10) -> 617.39972 | Y10: =SUM(10640.25/68)*H10 -> 104.72823 | AB10: =SUM(Y10:AA10) -> 104.72823 | AC10: 7.1 | AD10: =SUM(AB10*AC10) -> 743.5704 | AE10: =SUM(X10+AD10) -> 1360.9701 | AF10: =SUM(P10-AE10) -> 301.96988
C11: 240701000015 | D11: 45477 | E11: 吕沛霖 | F11: 喵喵速运-Layne | G11: YA | H11: 0.3978 | I11: 49.5 | J11: 1385.08 | P11: =SUM(J11) -> 1385.08 | S11: =SUM(61477/68)*H11 -> 359.64045 | U11: =SUM(1250/68)*H11 -> 7.3125 | X11: =SUM(S11:W11) -> 366.95295 | Y11: =SUM(10640.25/68)*H11 -> 62.245463 | Z11: 41.46 | AB11: =SUM(Y11:AA11) -> 103.70546 | AC11: 7.1 | AD11: =SUM(AB11*AC11) -> 736.30878 | AE11: =SUM(X11+AD11) -> 1103.2617 | AF11: =SUM(P11-AE11) -> 281.81827
C12: 240701000020 | D12: 45477 | E12: 吕沛霖 | F12: 喵喵速运-Layne | G12: Jinggang Pan | H12: 0.5519 | I12: 82 | J12: 1460.33 | P12: =SUM(J12) -> 1460.33 | S12: =SUM(61477/68)*H12 -> 498.95818 | U12: =SUM(1250/68)*H12 -> 10.145221 | X12: =SUM(S12:W12) -> 509.1034 | Y12: =SUM(10640.25/68)*H12 -> 86.358147 | AB12: =SUM(Y12:AA12) -> 86.358147 | AC12: 7.1 | AD12: =SUM(AB12*AC12) -> 613.14284 | AE12: =SUM(X12+AD12) -> 1122.2462 | AF12: =SUM(P12-AE12) -> 338.08376
C13: 240701000054 | D13: 45477 | E13: 无人 | F13: Mailmail Abv sales person 1 | G13: Adams | H13: 2.5358 | I13: 1140 | K13: 1490760 | M13: =SUM(K13/N13) -> 1639.9991 | N13: 909.0005 | O13: 7.12 | P13: =SUM(N13*O13) -> 6472.0836 | S13: =SUM(61477/68)*H13 -> 2292.5497 | U13: =SUM(1250/68)*H13 -> 46.613971 | V13: 120 | X13: =SUM(S13:W13) -> 2459.1636 | Y13: =SUM(10640.25/68)*H13 -> 396.78744 | AB13: =SUM(Y13:AA13) -> 396.78744 | AC13: 7.1 | AD13: =SUM(AB13*AC13) -> 2817.1908 | AE13: =SUM(X13+AD13) -> 5276.3545 | AF13: =SUM(P13-AE13) -> 1195.7291
C14: 240702000007 | D14: 45477 | E14: 朱小飞 | F14: Isabel Zhu | G14: Halifa Success | H14: 0.8928 | I14: 218 | J14: 2361.55 | P14: =SUBTOTAL(9,J14) -> 2361.55 | S14: =SUM(61477/68)*H14 -> 807.15685 | U14: =SUM(1250/68)*H14 -> 16.411765 | W14: 292 | X14: =SUM(S14:W14) -> 1115.5686 | Y14: =SUM(10640.25/68)*H14 -> 139.70022 | AB14: =SUM(Y14:AA14) -> 139.70022 | AC14: 7.1 | AD14: =SUM(AB14*AC14) -> 991.87159 | AE14: =SUM(X14+AD14) -> 2107.4402 | AF14: =SUM(P14-AE14) -> 254.1098
C15: 240702000008 | D15: 45477 | E15: 朱小飞 | F15: Isabel Zhu | G15: Halifa Success | H15: 2.232 | I15: 1028 | J15: 6070.88 | P15: =SUBTOTAL(9,J15) -> 6070.88 | S15: =SUM(61477/68)*H15 -> 2017.8921 | T15: =SUM(140+75) -> 215 | U15: =SUM(1250/68)*H15 -> 41.029412 | W15: 420 | X15: =SUM(S15:W15) -> 2693.9215 | Y15: =SUM(10640.25/68)*H15 -> 349.25056 | AB15: =SUM(Y15:AA15) -> 349.25056 | AC15: 7.1 | AD15: =SUM(AB15*AC15) -> 2479.679 | AE15: =SUM(X15+AD15) -> 5173.6005 | AF15: =SUM(P15-AE15) -> 897.2795
C16: 240702000009 | D16: 45477 | E16: 朱小飞 | F16: Isabel Zhu | G16: Halifa Success | H16: 5.8065 | I16: 650 | J16: 13360.1 | P16: =SUBTOTAL(9,J16) -> 13360.1 | S16: =SUM(61477/68)*H16 -> 5249.5029 | U16: =SUM(1250/68)*H16 -> 106.73713 | X16: =SUM(S16:W16) -> 5356.2401 | Y16: =SUM(10640.25/68)*H16 -> 908.56782 | AB16: =SUM(Y16:AA16) -> 908.56782 | AC16: 7.1 | AD16: =SUM(AB16*AC16) -> 6450.8315 | AE16: =SUM(X16+AD16) -> 11807.072 | AF16: =SUM(P16-AE16) -> 1553.0284
C17: 240703000022 | D17: 45477 | E17: 朱小飞 | F17: Isabel Zhu | G17: Lilon | H17: 2.6714 | I17: 1555 | J17: 7525.12 | P17: =SUBTOTAL(9,J17) -> 7525.12 | S17: =SUM(61477/68)*H17 -> 2415.142 | U17: =SUM(1250/68)*H17 -> 49.106618 | X17: =SUM(S17:W17) -> 2464.2486 | Y17: =SUM(10640.25/68)*H17 -> 418.00535 | AB17: =SUM(Y17:AA17) -> 418.00535 | AC17: 7.1 | AD17: =SUM(AB17*AC17) -> 2967.838 | AE17: =SUM(X17+AD17) -> 5432.0866 | AF17: =SUM(P17-AE17) -> 2093.0334
C18: 240703000028 | D18: 45477 | E18: Sam.Pao | F18: Sam.Pao | G18: Mr. Jiang | H18: 0.9089 | I18: 232 | J18: 3294.7 | P18: =SUBTOTAL(9,J18) -> 3294.7 | S18: =SUM(61477/68)*H18 -> 821.71243 | U18: =SUM(1250/68)*H18 -> 16.707721 | X18: =SUM(S18:W18) -> 838.42015 | Y18: =SUM(10640.25/68)*H18 -> 142.21946 | AB18: =SUM(Y18:AA18) -> 142.21946 | AC18: 7.1 | AD18: =SUM(AB18*AC18) -> 1009.7582 | AE18: =SUM(X18+AD18) -> 1848.1783 | AF18: =SUM(P18-AE18) -> 1446.5217
C19: 240703000030 | D19: 45477 | E19: Sam.Pao | F19: Sam.Pao | G19: JunYue hotel | H19: 1.1081 | I19: 861 | J19: 2989.7 | P19: =SUBTOTAL(9,J19) -> 2989.7 | S19: =SUM(61477/68)*H19 -> 1001.8039 | U19: =SUM(1250/68)*H19 -> 20.369485 | X19: =SUM(S19:W19) -> 1022.1734 | Y19: =SUM(10640.25/68)*H19 -> 173.38913 | AB19: =SUM(Y19:AA19) -> 173.38913 | AC19: 7.1 | AD19: =SUM(AB19*AC19) -> 1231.0628 | AE19: =SUM(X19+AD19) -> 2253.2362 | AF19: =SUM(P19-AE19) -> 736.46379
C20: 240704000029 | D20: 45482 | E20: Sam.Pao | F20: Sam.Pao | G20: LuZhiLong | H20: 0.7168 | I20: 230 | J20: 1792 | P20: =SUBTOTAL(9,J20) -> 1792 | S20: =SUM(61477/68)*H20 -> 648.03991 | U20: =SUM(1250/68)*H20 -> 13.176471 | X20: =SUM(S20:W20) -> 661.21638 | Y20: =SUM(10640.25/68)*H20 -> 112.16075 | AB20: =SUM(Y20:AA20) -> 112.16075 | AC20: 7.1 | AD20: =SUM(AB20*AC20) -> 796.34135 | AE20: =SUM(X20+AD20) -> 1457.5577 | AF20: =SUM(P20-AE20) -> 334.44228
C21: 240607000053 | D21: 45478 | E21: 吕沛霖 | F21: 喵喵速运-Layne | G21: KE ZONG | H21: 1.3088 | I21: 352 | J21: 3425 | P21: =SUM(J21) -> 3425 | S21: =SUM(61477/68)*H21 -> 1183.2514 | U21: =SUM(1250/68)*H21 -> 24.058824 | X21: =SUM(S21:W21) -> 1207.3103 | Y21: =SUM(10640.25/68)*H21 -> 204.79352 | AB21: =SUM(Y21:AA21) -> 204.79352 | AC21: 7.1 | AD21: =SUM(AB21*AC21) -> 1454.034 | AE21: =SUM(X21+AD21) -> 2661.3442 | AF21: =SUM(P21-AE21) -> 763.65577
C22: 240617000035 | D22: 45490 | E22: 黄颖 | F22: ying | G22: Huangpu | H22: 0.0887 | I22: 106 | J22: 332 | P22: =SUM(J22) -> 332 | S22: =SUM(61477/68)*H22 -> 80.191322 | U22: =SUM(1250/68)*H22 -> 1.6305147 | X22: =SUM(S22:W22) -> 81.821837 | Y22: =SUM(10640.25/68)*H22 -> 13.879267 | AB22: =SUM(Y22:AA22) -> 13.879267 | AC22: 7.1 | AD22: =SUM(AB22*AC22) -> 98.542798 | AE22: =SUM(X22+AD22) -> 180.36463 | AF22: =SUM(P22-AE22) -> 151.63537
C23: 240703000031 | D23: 45478 | E23: Sam.Pao | F23: Sam.Pao | G23: SKY JET | H23: 36.23 | I23: 4650 | J23: 63805.02 | P23: =SUBTOTAL(9,J23) -> 63805.02 | S23: =SUM(61477/68)*H23 -> 32754.584 | U23: =SUM(1250/68)*H23 -> 665.99265 | X23: =SUM(S23:W23) -> 33420.577 | Y23: =SUM(10640.25/68)*H23 -> 5669.0626 | AB23: =SUM(Y23:AA23) -> 5669.0626 | AC23: 7.1 | AD23: =SUM(AB23*AC23) -> 40250.345 | AE23: =SUM(X23+AD23) -> 73670.921 | AF23: =SUM(P23-AE23) -> -9865.9012
C24: 240704000018 | D24: 45477 | E24: Sam.Pao | F24: Sam.Pao | G24: MaiKaiNian | H24: 0.0287 | I24: 25 | J24: 106 | P24: =SUBTOTAL(9,J24) -> 106 | S24: =SUM(61477/68)*H24 -> 25.94691 | U24: =SUM(1250/68)*H24 -> 0.52757353 | X24: =SUM(S24:W24) -> 26.474484 | Y24: =SUM(10640.25/68)*H24 -> 4.4908114 | AB24: =SUM(Y24:AA24) -> 4.4908114 | AC24: 7.1 | AD24: =SUM(AB24*AC24) -> 31.884761 | AE24: =SUM(X24+AD24) -> 58.359245 | AF24: =SUM(P24-AE24) -> 47.640755
A25: JOB070349 | B25: COLL004049 | C25: 240607000053 | D25: 45478 | E25: 吕沛霖 | F25: 喵喵速运-Layne | G25: KE ZONG | H25: 1.3459 | I25: 622 | J25: 3524.24 | P25: =SUM(J25) -> 3524.24 | Q25: =SUM(P25:P31) -> 156852.59 | R25: 华茂青松=60177 赛捷=800 | S25: =SUM(60977/68)*H25 -> 1206.8962 | T25: =SUM(125.62/68)*H25 -> 2.4863523 | U25: =SUM(1150/68)*H25 -> 22.761544 | V25: 120 | X25: =SUM(S25:W25) -> 1352.1441 | Y25: =SUM(10579.27/68)*H25 -> 209.39176 | AA25: =SUM(57.93/68)*H25 -> 1.146588 | AB25: =SUM(Y25:AA25) -> 210.53835 | AC25: 7.1 | AD25: =SUM(AB25*AC25) -> 1494.8223 | AE25: =SUM(X25+AD25) -> 2846.9664 | AF25: =SUM(P25-AE25) -> 677.27361
C26: 240624000036 | D26: 45478 | E26: 黄颖 | F26: ying | G26: Sunday Adelena | H26: 1.1026 | I26: 1089 | J26: 2892 | P26: =SUBTOTAL(9,J26) -> 2892 | S26: =SUM(60977/68)*H26 -> 988.72412 | T26: =SUM(125.62/68)*H26 -> 2.0368914 | U26: =SUM(1150/68)*H26 -> 18.646912 | V26: 120 | X26: =SUM(S26:W26) -> 1129.4079 | Y26: =SUM(10579.27/68)*H26 -> 171.53975 | AA26: =SUM(57.93/68)*H26 -> 0.93931791 | AB26: =SUM(Y26:AA26) -> 172.47907 | AC26: 7.1 | AD26: =SUM(AB26*AC26) -> 1224.6014 | AE26: =SUM(X26+AD26) -> 2354.0093 | AF26: =SUM(P26-AE26) -> 537.99068
C27: 240624000037 | D27: 45478 | E27: 黄颖 | F27: ying | G27: Sunday Adelena | H27: 14.6754 | I27: 11776.5 | J27: 43280 | P27: =SUBTOTAL(9,J27) -> 43280 | S27: =SUM(60977/68)*H27 -> 13159.733 | T27: =SUM(125.62/68)*H27 -> 27.110643 | U27: =SUM(1150/68)*H27 -> 248.18691 | X27: =SUM(S27:W27) -> 13435.031 | Y27: =SUM(10579.27/68)*H27 -> 2283.162 | AA27: =SUM(57.93/68)*H27 -> 12.502146 | AB27: =SUM(Y27:AA27) -> 2295.6642 | AC27: 7.1 | AD27: =SUM(AB27*AC27) -> 16299.216 | AE27: =SUM(X27+AD27) -> 29734.247 | AF27: =SUM(P27-AE27) -> 13545.753
C28: 240704000029 | D28: 45482 | E28: Sam.Pao | F28: Sam.Pao | G28: LuZhiLong | H28: 13.9646 | I28: 3568 | J28: 34908 | P28: =SUBTOTAL(9,J28) -> 34908 | S28: =SUM(60977/68)*H28 -> 12522.344 | T28: =SUM(125.62/68)*H28 -> 25.797545 | U28: =SUM(1150/68)*H28 -> 236.16603 | X28: =SUM(S28:W28) -> 12784.308 | Y28: =SUM(10579.27/68)*H28 -> 2172.5776 | AA28: =SUM(57.93/68)*H28 -> 11.896607 | AB28: =SUM(Y28:AA28) -> 2184.4742 | AC28: 7.1 | AD28: =SUM(AB28*AC28) -> 15509.767 | AE28: =SUM(X28+AD28) -> 28294.074 | AF28: =SUM(P28-AE28) -> 6613.9255
C29: 240617000035 | D29: 45490 | E29: 黄颖 | F29: ying | G29: Huangpu | H29: 1.6952 | I29: 322.7 | J29: 6330 | P29: =SUM(J29) -> 6330 | S29: =SUM(60977/68)*H29 -> 1520.1207 | T29: =SUM(125.62/68)*H29 -> 3.1316327 | U29: =SUM(1150/68)*H29 -> 28.668824 | X29: =SUM(S29:W29) -> 1551.9212 | Y29: =SUM(10579.27/68)*H29 -> 263.73498 | AA29: =SUM(57.93/68)*H29 -> 1.4441608 | AB29: =SUM(Y29:AA29) -> 265.17914 | AC29: 7.1 | AD29: =SUM(AB29*AC29) -> 1882.7719 | AE29: =SUM(X29+AD29) -> 3434.6931 | AF29: =SUM(P29-AE29) -> 2895.3069
C30: 240703000031 | D30: 45478 | E30: Sam.Pao | F30: Sam.Pao | G30: SKY JET | H30: 7.89 | I30: 615 | J30: 13912.77 | P30: =SUBTOTAL(9,J30) -> 13912.77 | S30: =SUM(60977/68)*H30 -> 7075.1254 | T30: =SUM(125.62/68)*H30 -> 14.575615 | U30: =SUM(1150/68)*H30 -> 133.43382 | X30: =SUM(S30:W30) -> 7223.1349 | Y30: =SUM(10579.27/68)*H30 -> 1227.5065 | AA30: =SUM(57.93/68)*H30 -> 6.7215838 | AB30: =SUM(Y30:AA30) -> 1234.2281 | AC30: 7.1 | AD30: =SUM(AB30*AC30) -> 8763.0192 | AE30: =SUM(X30+AD30) -> 15986.154 | AF30: =SUM(P30-AE30) -> -2073.3841
C31: 240705000003 | D31: 45478 | E31: Sam.Pao | F31: Sam.Pao | G31: SKY JET | H31: 29.53 | I31: 3724 | J31: 52005.58 | P31: =SUBTOTAL(9,J31) -> 52005.58 | S31: =SUM(60977/68)*H31 -> 26480.159 | T31: =SUM(125.62/68)*H31 -> 54.552332 | U31: =SUM(1150/68)*H31 -> 499.40441 | X31: =SUM(S31:W31) -> 27034.116 | Y31: =SUM(10579.27/68)*H31 -> 4594.2036 | AA31: =SUM(57.93/68)*H31 -> 25.156954 | AB31: =SUM(Y31:AA31) -> 4619.3605 | AC31: 7.1 | AD31: =SUM(AB31*AC31) -> 32797.46 | AE31: =SUM(X31+AD31) -> 59831.575 | AF31: =SUM(P31-AE31) -> -7825.9955
A32: JOB070360 | B32: COLL004060 | C32: 240618000026 | D32: 45482 | E32: Sam.Pao | F32: Sam.Pao | G32: Joshua | H32: 9.0048 | I32: 5844 | J32: 32609 | P32: =SUM(J32) -> 32609 | Q32: =SUM(P32:P37) -> 184530.54 | R32: 华茂青松=60177 赛捷=1500 | S32: =SUM(61677/68)*H32 -> 8167.486 | U32: =SUM(2200/68)*H32 -> 291.33176 | V32: 120 | W32: 1600 | X32: =SUM(S32:W32) -> 10178.818 | Y32: =SUM(10235.99/68)*H32 -> 1355.4859 | Z32: 513.28 | AA32: =SUM(77.88/68)*H32 -> 10.313144 | AB32: =SUM(Y32:AA32) -> 1879.0791 | AC32: 7.12 | AD32: =SUM(AB32*AC32) -> 13379.043 | AE32: =SUM(X32+AD32) -> 23557.861 | AF32: =SUM(P32-AE32) -> 9051.1393
C33: 240704000029 | D33: 45482 | E33: Sam.Pao | F33: Sam.Pao | G33: LuZhiLong | H33: 14.9276 | I33: 11064 | J33: 37314.5 | P33: =SUBTOTAL(9,J33) -> 37314.5 | S33: =SUM(61677/68)*H33 -> 13539.553 | U33: =SUM(2200/68)*H33 -> 482.95176 | X33: =SUM(S33:W33) -> 14022.504 | Y33: =SUM(10235.99/68)*H33 -> 2247.0407 | AA33: =SUM(77.88/68)*H33 -> 17.096492 | AB33: =SUM(Y33:AA33) -> 2264.1371 | AC33: 7.12 | AD33: =SUM(AB33*AC33) -> 16120.656 | AE33: =SUM(X33+AD33) -> 30143.161 | AF33: =SUM(P33-AE33) -> 7171.339
C34: 240617000035 | D34: 45490 | E34: 黄颖 | F34: ying | G34: Huangpu | H34: 12.8123 | I34: 5331.1 | J34: 47840 | P34: =SUM(J34) -> 47840 | S34: =SUM(61677/68)*H34 -> 11620.945 | U34: =SUM(2200/68)*H34 -> 414.51559 | X34: =SUM(S34:W34) -> 12035.46 | Y34: =SUM(10235.99/68)*H34 -> 1928.6261 | AA34: =SUM(77.88/68)*H34 -> 14.673852 | AB34: =SUM(Y34:AA34) -> 1943.3 | AC34: 7.12 | AD34: =SUM(AB34*AC34) -> 13836.296 | AE34: =SUM(X34+AD34) -> 25871.756 | AF34: =SUM(P34-AE34) -> 21968.244
C35: 240707000003 | D35: 45482 | E35: Sam.Pao | F35: Sam.Pao | G35: LuZhiLong | H35: 0.1208 | I35: 69 | J35: 330.48 | P35: =SUBTOTAL(9,J35) -> 330.48 | S35: =SUM(61677/68)*H35 -> 109.56738 | U35: =SUM(2200/68)*H35 -> 3.9082353 | X35: =SUM(S35:W35) -> 113.47561 | Y35: =SUM(10235.99/68)*H35 -> 18.183935 | AA35: =SUM(77.88/68)*H35 -> 0.13835153 | AB35: =SUM(Y35:AA35) -> 18.322287 | AC35: 7.12 | AD35: =SUM(AB35*AC35) -> 130.45468 | AE35: =SUM(X35+AD35) -> 243.93029 | AF35: =SUM(P35-AE35) -> 86.549707
C36: 240708000038 | D36: 45482 | E36: 陆总 | F36: 喵喵速运-江 | G36: LUZHILONG | H36: 1.6 | I36: 1009 | J36: 3916.8 | P36: =SUBTOTAL(9,J36) -> 3916.8 | S36: =SUM(61677/68)*H36 -> 1451.2235 | U36: =SUM(2200/68)*H36 -> 51.764706 | X36: =SUM(S36:W36) -> 1502.9882 | Y36: =SUM(10235.99/68)*H36 -> 240.84682 | AA36: =SUM(77.88/68)*H36 -> 1.8324706 | AB36: =SUM(Y36:AA36) -> 242.67929 | AC36: 7.12 | AD36: =SUM(AB36*AC36) -> 1727.8766 | AE36: =SUM(X36+AD36) -> 3230.8648 | AF36: =SUM(P36-AE36) -> 685.93519
C37: 240708000062 | D37: 45482 | E37: Sam.Pao | F37: Sam.Pao | G37: SKY JET | H37: 35.79 | I37: 4290.5 | J37: 62519.76 | P37: =SUBTOTAL(9,J37) -> 62519.76 | S37: =SUM(61677/68)*H37 -> 32462.056 | U37: =SUM(2200/68)*H37 -> 1157.9118 | X37: =SUM(S37:W37) -> 33619.968 | Y37: =SUM(10235.99/68)*H37 -> 5387.4424 | AA37: =SUM(77.88/68)*H37 -> 40.990076 | AB37: =SUM(Y37:AA37) -> 5428.4325 | AC37: 7.12 | AD37: =SUM(AB37*AC37) -> 38650.439 | AE37: =SUM(X37+AD37) -> 72270.407 | AF37: =SUM(P37-AE37) -> -9750.6472
A38: JOB070370 | B38: COLL004070 | C38: 240617000035 | D38: 45490 | E38: 黄颖 | F38: ying | G38: Huangpu | H38: 4.9371 | I38: 11872 | J38: 18452 | P38: =SUM(J38) -> 18452 | Q38: =SUM(P38:P49) -> 164523.2 | R38: 华茂青松=60177 赛捷=2300 | S38: =SUM(62477/68)*H38 -> 4536.1058 | T38: 770 | U38: =SUM(2400/68)*H38 -> 174.25059 | W38: =SUM(830+1800) -> 2630 | X38: =SUM(S38:W38) -> 8110.3564 | Y38: =SUM(10235.99/68)*H38 -> 743.17803 | Z38: 471.98 | AA38: =SUM(35.4/68)*H38 -> 2.5701962 | AB38: =SUM(Y38:AA38) -> 1217.7282 | AC38: 7.26 | AD38: =SUM(AB38*AC38) -> 8840.7069 | AE38: =SUM(X38+AD38) -> 16951.063 | AF38: =SUM(P38-AE38) -> 1500.9366
C39: 240702000004 | D39: 45490 | E39: 黄颖 | F39: ying | G39: liangyu | H39: 1.9054 | I39: 586.7 | J39: 7303 | P39: =SUBTOTAL(9,J39) -> 7303 | S39: =SUM(62477/68)*H39 -> 1750.6423 | U39: =SUM(2400/68)*H39 -> 67.249412 | X39: =SUM(S39:W39) -> 1817.8917 | Y39: =SUM(10235.99/68)*H39 -> 286.81846 | AA39: =SUM(35.4/68)*H39 -> 0.99192882 | AB39: =SUM(Y39:AA39) -> 287.81039 | AC39: 7.26 | AD39: =SUM(AB39*AC39) -> 2089.5034 | AE39: =SUM(X39+AD39) -> 3907.3951 | AF39: =SUM(P39-AE39) -> 3395.6049
C40: 240702000027 | D40: 45490 | E40: Sam.Pao | F40: Sam.Pao | G40: Ikenna | H40: 0.9364 | I40: 230 | K40: 539654 | M40: =SUM(K40/N40) -> 1694.9997 | N40: 318.38 | O40: 7.08 | P40: =SUM(N40*O40) -> 2254.1304 | S40: =SUM(62477/68)*H40 -> 860.34504 | U40: =SUM(2400/68)*H40 -> 33.049412 | X40: =SUM(S40:W40) -> 893.39445 | Y40: =SUM(10235.99/68)*H40 -> 140.9556 | AA40: =SUM(35.4/68)*H40 -> 0.48747882 | AB40: =SUM(Y40:AA40) -> 141.44308 | AC40: 7.26 | AD40: =SUM(AB40*AC40) -> 1026.8768 | AE40: =SUM(X40+AD40) -> 1920.2712 | AF40: =SUM(P40-AE40) -> 333.85917
...

Sheet JOB070344
A1: 2024年07月份LOS毛利表（海运）
A2: PSL表 | B2: 体积cbm | C2: 72.7682
A3: JOB | B3: 集装编号 | C3: 运单编号 | D3: 日期 | E3: 业务 | F3: 发货人 | G3: 收货人 | H3: 计费体积 | I3: 计费重量 | J3: 应 收 | Q3: 总应收 | R3: 起 运 港 成 本 | W3: 代垫运费 | X3: 起运港成本 合计 | Y3: 目的港成本 | AE3: 总支出 | AF3: 利润
J4: 应收RMB | K4: LOS Income(NGN)收到(奈拉) | L4: LOS 收到USD | M4: 美元汇率 dollar currency rate | N4: 应收 到付款USD | O4: 汇率 | P4: 人民币 | R4: 代理商 | S4: 运费+出口报关费 | T4: 提货费 | U4: 装卸费 | V4: 包装费 | Y4: 进口报关费 | Z4: 到门配送费 | AA4: 转运费 | AB4: 目的港支出 | AC4: 汇率 | AD4: 人民币 | AE4: 起运港+目的港
A5: JOB070344 | B5: COLL004043 | C5: 240624000034 | D5: 45477 | E5: 黄颖 | F5: ying | G5: baikaibo | H5: 3.024 | I5: 2000 | K5: 2320436 | M5: =SUM(K5/N5) -> 1651.8616 | N5: 1404.74 | O5: 7.12 | P5: =SUM(N5*O5) -> 10001.749 | Q5: =SUM(P5:P25) -> 168759.19 | R5: 华茂青松=60177 赛捷=1300 | S5: =SUM(61477/68)*H5 -> 2733.9184 | U5: =SUM(1250/68)*H5 -> 55.588235 | X5: =SUM(S5:W5) -> 2789.5066 | Y5: =SUM(10640.25/68)*H5 -> 473.17818 | Z5: 5.49 | AB5: =SUM(Y5:AA5) -> 478.66818 | AC5: 7.1 | AD5: =SUM(AB5*AC5) -> 3398.5441 | AE5: =SUM(X5+AD5) -> 6188.0506 | AF5: =SUM(P5-AE5) -> 3813.6982
C6: 240624000036 | D6: 45478 | E6: 黄颖 | F6: ying | G6: Sunday Adelena | H6: 10.2263 | I6: 7008 | J6: 26828 | P6: =SUBTOTAL(9,J6) -> 26828 | S6: =SUM(61477/68)*H6 -> 9245.3271 | U6: =SUM(1250/68)*H6 -> 187.98346 | V6: 120 | X6: =SUM(S6:W6) -> 9553.3106 | Y6: =SUM(10640.25/68)*H6 -> 1600.1528 | AB6: =SUM(Y6:AA6) -> 1600.1528 | AC6: 7.1 | AD6: =SUM(AB6*AC6) -> 11361.085 | AE6: =SUM(X6+AD6) -> 20914.395 | AF6: =SUM(P6-AE6) -> 5913.6047
C7: 240624000056 | D7: 45477 | E7: Sam.Pao | F7: Sam.Pao | G7: TOLUBOD MOVERS | H7: 0.509 | I7: 207 | J7: 1893.7 | P7: =SUBTOTAL(9,J7) -> 1893.7 | S7: =SUM(61477/68)*H7 -> 460.17343 | U7: =SUM(1250/68)*H7 -> 9.3566176 | V7: 270 | X7: =SUM(S7:W7) -> 739.53004 | Y7: =SUM(10640.25/68)*H7 -> 79.645401 | AB7: =SUM(Y7:AA7) -> 79.645401 | AC7: 7.1 | AD7: =SUM(AB7*AC7) -> 565.48235 | AE7: =SUM(X7+AD7) -> 1305.0124 | AF7: =SUM(P7-AE7) -> 588.68761
C8: 240626000044 | D8: 45477 | E8: Sam.Pao | F8: Sam.Pao | G8: JunYue hotel | H8: 0.6356 | I8: 450 | J8: 1714.8 | P8: =SUM(J8) -> 1714.8 | S8: =SUM(61477/68)*H8 -> 574.62914 | U8: =SUM(1250/68)*H8 -> 11.683824 | X8: =SUM(S8:W8) -> 586.31296 | Y8: =SUM(10640.25/68)*H8 -> 99.455043 | AB8: =SUM(Y8:AA8) -> 99.455043 | AC8: 7.1 | AD8: =SUM(AB8*AC8) -> 706.1308 | AE8: =SUM(X8+AD8) -> 1292.4438 | AF8: =SUM(P8-AE8) -> 422.35624
C9: 240628000020 | D9: 45477 | E9: 黄颖 | F9: ying | G9: baikaibo | H9: 0.472 | I9: 420 | K9: 439900 | M9: =SUM(K9/N9) -> 1705.0388 | N9: 258 | O9: 7.12 | P9: =SUM(N9*O9) -> 1836.96 | S9: =SUM(61477/68)*H9 -> 426.72271 | U9: =SUM(1250/68)*H9 -> 8.6764706 | X9: =SUM(S9:W9) -> 435.39918 | Y9: =SUM(10640.25/68)*H9 -> 73.855853 | AB9: =SUM(Y9:AA9) -> 73.855853 | AC9: 7.1 | AD9: =SUM(AB9*AC9) -> 524.37656 | AE9: =SUM(X9+AD9) -> 959.77573 | AF9: =SUM(P9-AE9) -> 877.18427
C10: 240628000031 | D10: 45477 | E10: 朱小飞 | F10: Isabel Zhu | G10: Wang Hui Feng | H10: 1.7537 | I10: 2930 | K10: 2405060 | M10: =SUM(K10/N10) -> 1640 | N10: 1466.5 | O10: 7.12 | P10: =SUM(N10*O10) -> 10441.48 | S10: =SUM(61477/68)*H10 -> 1585.4737 | U10: =SUM(1250/68)*H10 -> 32.237132 | X10: =SUM(S10:W10) -> 1617.7109 | Y10: =SUM(10640.25/68)*H10 -> 274.40892 | AB10: =SUM(Y10:AA10) -> 274.40892 | AC10: 7.1 | AD10: =SUM(AB10*AC10) -> 1948.3033 | AE10: =SUM(X10+AD10) -> 3566.0142 | AF10: =SUM(P10-AE10) -> 6875.4658
C11: 240628000036 | D11: 45477 | E11: 朱小飞 | F11: Isabel Zhu | G11: Halifa Success | H11: 0.6693 | I11: 116.5 | J11: 1662.94 | P11: =SUBTOTAL(9,J11) -> 1662.94 | S11: =SUM(61477/68)*H11 -> 605.09641 | U11: =SUM(1250/68)*H11 -> 12.303309 | X11: =SUM(S11:W11) -> 617.39972 | Y11: =SUM(10640.25/68)*H11 -> 104.72823 | AB11: =SUM(Y11:AA11) -> 104.72823 | AC11: 7.1 | AD11: =SUM(AB11*AC11) -> 743.5704 | AE11: =SUM(X11+AD11) -> 1360.9701 | AF11: =SUM(P11-AE11) -> 301.96988
C12: 240701000015 | D12: 45477 | E12: 吕沛霖 | F12: 喵喵速运-Layne | G12: YA | H12: 0.3978 | I12: 49.5 | J12: 1385.08 | P12: =SUM(J12) -> 1385.08 | S12: =SUM(61477/68)*H12 -> 359.64045 | U12: =SUM(1250/68)*H12 -> 7.3125 | X12: =SUM(S12:W12) -> 366.95295 | Y12: =SUM(10640.25/68)*H12 -> 62.245463 | Z12: 41.46 | AB12: =SUM(Y12:AA12) -> 103.70546 | AC12: 7.1 | AD12: =SUM(AB12*AC12) -> 736.30878 | AE12: =SUM(X12+AD12) -> 1103.2617 | AF12: =SUM(P12-AE12) -> 281.81827
C13: 240701000020 | D13: 45477 | E13: 吕沛霖 | F13: 喵喵速运-Layne | G13: Jinggang Pan | H13: 0.5519 | I13: 82 | J13: 1460.33 | P13: =SUM(J13) -> 1460.33 | S13: =SUM(61477/68)*H13 -> 498.95818 | U13: =SUM(1250/68)*H13 -> 10.145221 | X13: =SUM(S13:W13) -> 509.1034 | Y13: =SUM(10640.25/68)*H13 -> 86.358147 | AB13: =SUM(Y13:AA13) -> 86.358147 | AC13: 7.1 | AD13: =SUM(AB13*AC13) -> 613.14284 | AE13: =SUM(X13+AD13) -> 1122.2462 | AF13: =SUM(P13-AE13) -> 338.08376
C14: 240701000054 | D14: 45477 | E14: 无人 | F14: Mailmail Abv sales person 1 | G14: Adams | H14: 2.5358 | I14: 1140 | K14: 1490760 | M14: =SUM(K14/N14) -> 1639.9991 | N14: 909.0005 | O14: 7.12 | P14: =SUM(N14*O14) -> 6472.0836 | S14: =SUM(61477/68)*H14 -> 2292.5497 | U14: =SUM(1250/68)*H14 -> 46.613971 | V14: 120 | X14: =SUM(S14:W14) -> 2459.1636 | Y14: =SUM(10640.25/68)*H14 -> 396.78744 | AB14: =SUM(Y14:AA14) -> 396.78744 | AC14: 7.1 | AD14: =SUM(AB14*AC14) -> 2817.1908 | AE14: =SUM(X14+AD14) -> 5276.3545 | AF14: =SUM(P14-AE14) -> 1195.7291
C15: 240702000007 | D15: 45477 | E15: 朱小飞 | F15: Isabel Zhu | G15: Halifa Success | H15: 0.8928 | I15: 218 | J15: 2361.55 | P15: =SUBTOTAL(9,J15) -> 2361.55 | S15: =SUM(61477/68)*H15 -> 807.15685 | U15: =SUM(1250/68)*H15 -> 16.411765 | W15: 292 | X15: =SUM(S15:W15) -> 1115.5686 | Y15: =SUM(10640.25/68)*H15 -> 139.70022 | AB15: =SUM(Y15:AA15) -> 139.70022 | AC15: 7.1 | AD15: =SUM(AB15*AC15) -> 991.87159 | AE15: =SUM(X15+AD15) -> 2107.4402 | AF15: =SUM(P15-AE15) -> 254.1098
C16: 240702000008 | D16: 45477 | E16: 朱小飞 | F16: Isabel Zhu | G16: Halifa Success | H16: 2.232 | I16: 1028 | J16: 6070.88 | P16: =SUBTOTAL(9,J16) -> 6070.88 | S16: =SUM(61477/68)*H16 -> 2017.8921 | T16: =SUM(140+75) -> 215 | U16: =SUM(1250/68)*H16 -> 41.029412 | W16: 420 | X16: =SUM(S16:W16) -> 2693.9215 | Y16: =SUM(10640.25/68)*H16 -> 349.25056 | AB16: =SUM(Y16:AA16) -> 349.25056 | AC16: 7.1 | AD16: =SUM(AB16*AC16) -> 2479.679 | AE16: =SUM(X16+AD16) -> 5173.6005 | AF16: =SUM(P16-AE16) -> 897.2795
C17: 240702000009 | D17: 45477 | E17: 朱小飞 | F17: Isabel Zhu | G17: Halifa Success | H17: 5.8065 | I17: 650 | J17: 13360.1 | P17: =SUBTOTAL(9,J17) -> 13360.1 | S17: =SUM(61477/68)*H17 -> 5249.5029 | U17: =SUM(1250/68)*H17 -> 106.73713 | X17: =SUM(S17:W17) -> 5356.2401 | Y17: =SUM(10640.25/68)*H17 -> 908.56782 | AB17: =SUM(Y17:AA17) -> 908.56782 | AC17: 7.1 | AD17: =SUM(AB17*AC17) -> 6450.8315 | AE17: =SUM(X17+AD17) -> 11807.072 | AF17: =SUM(P17-AE17) -> 1553.0284
C18: 240703000022 | D18: 45477 | E18: 朱小飞 | F18: Isabel Zhu | G18: Lilon | H18: 2.6714 | I18: 1555 | J18: 7525.12 | P18: =SUBTOTAL(9,J18) -> 7525.12 | S18: =SUM(61477/68)*H18 -> 2415.142 | U18: =SUM(1250/68)*H18 -> 49.106618 | X18: =SUM(S18:W18) -> 2464.2486 | Y18: =SUM(10640.25/68)*H18 -> 418.00535 | AB18: =SUM(Y18:AA18) -> 418.00535 | AC18: 7.1 | AD18: =SUM(AB18*AC18) -> 2967.838 | AE18: =SUM(X18+AD18) -> 5432.0866 | AF18: =SUM(P18-AE18) -> 2093.0334
C19: 240703000028 | D19: 45477 | E19: Sam.Pao | F19: Sam.Pao | G19: Mr. Jiang | H19: 0.9089 | I19: 232 | J19: 3294.7 | P19: =SUBTOTAL(9,J19) -> 3294.7 | S19: =SUM(61477/68)*H19 -> 821.71243 | U19: =SUM(1250/68)*H19 -> 16.707721 | X19: =SUM(S19:W19) -> 838.42015 | Y19: =SUM(10640.25/68)*H19 -> 142.21946 | AB19: =SUM(Y19:AA19) -> 142.21946 | AC19: 7.1 | AD19: =SUM(AB19*AC19) -> 1009.7582 | AE19: =SUM(X19+AD19) -> 1848.1783 | AF19: =SUM(P19-AE19) -> 1446.5217
C20: 240703000030 | D20: 45477 | E20: Sam.Pao | F20: Sam.Pao | G20: JunYue hotel | H20: 1.1081 | I20: 861 | J20: 2989.7 | P20: =SUBTOTAL(9,J20) -> 2989.7 | S20: =SUM(61477/68)*H20 -> 1001.8039 | U20: =SUM(1250/68)*H20 -> 20.369485 | X20: =SUM(S20:W20) -> 1022.1734 | Y20: =SUM(10640.25/68)*H20 -> 173.38913 | AB20: =SUM(Y20:AA20) -> 173.38913 | AC20: 7.1 | AD20: =SUM(AB20*AC20) -> 1231.0628 | AE20: =SUM(X20+AD20) -> 2253.2362 | AF20: =SUM(P20-AE20) -> 736.46379
C21: 240704000029 | D21: 45482 | E21: Sam.Pao | F21: Sam.Pao | G21: LuZhiLong | H21: 0.7168 | I21: 230 | J21: 1792 | P21: =SUBTOTAL(9,J21) -> 1792 | S21: =SUM(61477/68)*H21 -> 648.03991 | U21: =SUM(1250/68)*H21 -> 13.176471 | X21: =SUM(S21:W21) -> 661.21638 | Y21: =SUM(10640.25/68)*H21 -> 112.16075 | AB21: =SUM(Y21:AA21) -> 112.16075 | AC21: 7.1 | AD21: =SUM(AB21*AC21) -> 796.34135 | AE21: =SUM(X21+AD21) -> 1457.5577 | AF21: =SUM(P21-AE21) -> 334.44228
C22: 240607000053 | D22: 45478 | E22: 吕沛霖 | F22: 喵喵速运-Layne | G22: KE ZONG | H22: 1.3088 | I22: 352 | J22: 3425 | P22: =SUM(J22) -> 3425 | S22: =SUM(61477/68)*H22 -> 1183.2514 | U22: =SUM(1250/68)*H22 -> 24.058824 | X22: =SUM(S22:W22) -> 1207.3103 | Y22: =SUM(10640.25/68)*H22 -> 204.79352 | AB22: =SUM(Y22:AA22) -> 204.79352 | AC22: 7.1 | AD22: =SUM(AB22*AC22) -> 1454.034 | AE22: =SUM(X22+AD22) -> 2661.3442 | AF22: =SUM(P22-AE22) -> 763.65577
C23: 240617000035 | D23: 45490 | E23: 黄颖 | F23: ying | G23: Huangpu | H23: 0.0887 | I23: 106 | J23: 332 | P23: =SUM(J23) -> 332 | S23: =SUM(61477/68)*H23 -> 80.191322 | U23: =SUM(1250/68)*H23 -> 1.6305147 | X23: =SUM(S23:W23) -> 81.821837 | Y23: =SUM(10640.25/68)*H23 -> 13.879267 | AB23: =SUM(Y23:AA23) -> 13.879267 | AC23: 7.1 | AD23: =SUM(AB23*AC23) -> 98.542798 | AE23: =SUM(X23+AD23) -> 180.36463 | AF23: =SUM(P23-AE23) -> 151.63537
C24: 240703000031 | D24: 45478 | E24: Sam.Pao | F24: Sam.Pao | G24: SKY JET | H24: 36.23 | I24: 4650 | J24: 63805.02 | P24: =SUBTOTAL(9,J24) -> 63805.02 | S24: =SUM(61477/68)*H24 -> 32754.584 | U24: =SUM(1250/68)*H24 -> 665.99265 | X24: =SUM(S24:W24) -> 33420.577 | Y24: =SUM(10640.25/68)*H24 -> 5669.0626 | AB24: =SUM(Y24:AA24) -> 5669.0626 | AC24: 7.1 | AD24: =SUM(AB24*AC24) -> 40250.345 | AE24: =SUM(X24+AD24) -> 73670.921 | AF24: =SUM(P24-AE24) -> -9865.9012
C25: 240704000018 | D25: 45477 | E25: Sam.Pao | F25: Sam.Pao | G25: MaiKaiNian | H25: 0.0287 | I25: 25 | J25: 106 | P25: =SUBTOTAL(9,J25) -> 106 | S25: =SUM(61477/68)*H25 -> 25.94691 | U25: =SUM(1250/68)*H25 -> 0.52757353 | X25: =SUM(S25:W25) -> 26.474484 | Y25: =SUM(10640.25/68)*H25 -> 4.4908114 | AB25: =SUM(Y25:AA25) -> 4.4908114 | AC25: 7.1 | AD25: =SUM(AB25*AC25) -> 31.884761 | AE25: =SUM(X25+AD25) -> 58.359245 | AF25: =SUM(P25-AE25) -> 47.640755
A26: 合计 | H26: =SUM(H5:H25) -> 72.7681 | I26: =SUM(I5:I25) -> 24310 | J26: =SUM(J4:J4) -> 0 | N26: =SUM(N4:N4) -> 0 | P26: =SUM(P4:P4) -> 0 | Q26: =SUM(Q4:Q4) -> 0 | X26: =SUM(X4:X4) -> 0 | AD26: =SUM(AD4:AD4) -> 0 | AF26: =SUM(AF5:AF25) -> 19020.507

Sheet JOB070349
A1: 2024年07月份LOS毛利表（海运）
A2: PSL表 | B2: 体积cbm | C2: 70.2037
A3: JOB | B3: 集装编号 | C3: 运单编号 | D3: 日期 | E3: 业务 | F3: 发货人 | G3: 收货人 | H3: 计费体积 | I3: 计费重量 | J3: 应 收 | Q3: 总应收 | R3: 起 运 港 成 本 | W3: 代垫运费 | X3: 起运港成本 合计 | Y3: 目的港成本 | AE3: 总支出 | AF3: 利润
J4: 应收RMB | K4: LOS Income(NGN)收到(奈拉) | L4: LOS 收到USD | M4: 美元汇率 dollar currency rate | N4: 应收 到付款USD | O4: 汇率 | P4: 人民币 | R4: 代理商 | S4: 运费+出口报关费 | T4: 提货费 | U4: 装卸费 | V4: 包装费 | Y4: 进口报关费 | Z4: 到门配送费 | AA4: 转运费 | AB4: 目的港支出 | AC4: 汇率 | AD4: 人民币 | AE4: 起运港+目的港
A5: JOB070349 | B5: COLL004049 | C5: 240607000053 | D5: 45478 | E5: 吕沛霖 | F5: 喵喵速运-Layne | G5: KE ZONG | H5: 1.3459 | I5: 622 | J5: 3524.24 | P5: =SUM(J5) -> 3524.24 | Q5: =SUM(P5:P11) -> 156852.59 | R5: 华茂青松=60177 赛捷=800 | S5: =SUM(60977/68)*H5 -> 1206.8962 | T5: =SUM(125.62/68)*H5 -> 2.4863523 | U5: =SUM(1150/68)*H5 -> 22.761544 | V5: 120 | X5: =SUM(S5:W5) -> 1352.1441 | Y5: =SUM(10579.27/68)*H5 -> 209.39176 | AA5: =SUM(57.93/68)*H5 -> 1.146588 | AB5: =SUM(Y5:AA5) -> 210.53835 | AC5: 7.1 | AD5: =SUM(AB5*AC5) -> 1494.8223 | AE5: =SUM(X5+AD5) -> 2846.9664 | AF5: =SUM(P5-AE5) -> 677.27361
C6: 240624000036 | D6: 45478 | E6: 黄颖 | F6: ying | G6: Sunday Adelena | H6: 1.1026 | I6: 1089 | J6: 2892 | P6: =SUBTOTAL(9,J6) -> 2892 | S6: =SUM(60977/68)*H6 -> 988.72412 | T6: =SUM(125.62/68)*H6 -> 2.0368914 | U6: =SUM(1150/68)*H6 -> 18.646912 | V6: 120 | X6: =SUM(S6:W6) -> 1129.4079 | Y6: =SUM(10579.27/68)*H6 -> 171.53975 | AA6: =SUM(57.93/68)*H6 -> 0.93931791 | AB6: =SUM(Y6:AA6) -> 172.47907 | AC6: 7.1 | AD6: =SUM(AB6*AC6) -> 1224.6014 | AE6: =SUM(X6+AD6) -> 2354.0093 | AF6: =SUM(P6-AE6) -> 537.99068
C7: 240624000037 | D7: 45478 | E7: 黄颖 | F7: ying | G7: Sunday Adelena | H7: 14.6754 | I7: 11776.5 | J7: 43280 | P7: =SUBTOTAL(9,J7) -> 43280 | S7: =SUM(60977/68)*H7 -> 13159.733 | T7: =SUM(125.62/68)*H7 -> 27.110643 | U7: =SUM(1150/68)*H7 -> 248.18691 | X7: =SUM(S7:W7) -> 13435.031 | Y7: =SUM(10579.27/68)*H7 -> 2283.162 | AA7: =SUM(57.93/68)*H7 -> 12.502146 | AB7: =SUM(Y7:AA7) -> 2295.6642 | AC7: 7.1 | AD7: =SUM(AB7*AC7) -> 16299.216 | AE7: =SUM(X7+AD7) -> 29734.247 | AF7: =SUM(P7-AE7) -> 13545.753
C8: 240704000029 | D8: 45482 | E8: Sam.Pao | F8: Sam.Pao | G8: LuZhiLong | H8: 13.9646 | I8: 3568 | J8: 34908 | P8: =SUBTOTAL(9,J8) -> 34908 | S8: =SUM(60977/68)*H8 -> 12522.344 | T8: =SUM(125.62/68)*H8 -> 25.797545 | U8: =SUM(1150/68)*H8 -> 236.16603 | X8: =SUM(S8:W8) -> 12784.308 | Y8: =SUM(10579.27/68)*H8 -> 2172.5776 | AA8: =SUM(57.93/68)*H8 -> 11.896607 | AB8: =SUM(Y8:AA8) -> 2184.4742 | AC8: 7.1 | AD8: =SUM(AB8*AC8) -> 15509.767 | AE8: =SUM(X8+AD8) -> 28294.074 | AF8: =SUM(P8-AE8) -> 6613.9255
C9: 240617000035 | D9: 45490 | E9: 黄颖 | F9: ying | G9: Huangpu | H9: 1.6952 | I9: 322.7 | J9: 6330 | P9: =SUM(J9) -> 6330 | S9: =SUM(60977/68)*H9 -> 1520.1207 | T9: =SUM(125.62/68)*H9 -> 3.1316327 | U9: =SUM(1150/68)*H9 -> 28.668824 | X9: =SUM(S9:W9) -> 1551.9212 | Y9: =SUM(10579.27/68)*H9 -> 263.73498 | AA9: =SUM(57.93/68)*H9 -> 1.4441608 | AB9: =SUM(Y9:AA9) -> 265.17914 | AC9: 7.1 | AD9: =SUM(AB9*AC9) -> 1882.7719 | AE9: =SUM(X9+AD9) -> 3434.6931 | AF9: =SUM(P9-AE9) -> 2895.3069
C10: 240703000031 | D10: 45478 | E10: Sam.Pao | F10: Sam.Pao | G10: SKY JET | H10: 7.89 | I10: 615 | J10: 13912.77 | P10: =SUBTOTAL(9,J10) -> 13912.77 | S10: =SUM(60977/68)*H10 -> 7075.1254 | T10: =SUM(125.62/68)*H10 -> 14.575615 | U10: =SUM(1150/68)*H10 -> 133.43382 | X10: =SUM(S10:W10) -> 7223.1349 | Y10: =SUM(10579.27/68)*H10 -> 1227.5065 | AA10: =SUM(57.93/68)*H10 -> 6.7215838 | AB10: =SUM(Y10:AA10) -> 1234.2281 | AC10: 7.1 | AD10: =SUM(AB10*AC10) -> 8763.0192 | AE10: =SUM(X10+AD10) -> 15986.154 | AF10: =SUM(P10-AE10) -> -2073.3841
C11: 240705000003 | D11: 45478 | E11: Sam.Pao | F11: Sam.Pao | G11: SKY JET | H11: 29.53 | I11: 3724 | J11: 52005.58 | P11: =SUBTOTAL(9,J11) -> 52005.58 | S11: =SUM(60977/68)*H11 -> 26480.159 | T11: =SUM(125.62/68)*H11 -> 54.552332 | U11: =SUM(1150/68)*H11 -> 499.40441 | X11: =SUM(S11:W11) -> 27034.116 | Y11: =SUM(10579.27/68)*H11 -> 4594.2036 | AA11: =SUM(57.93/68)*H11 -> 25.156954 | AB11: =SUM(Y11:AA11) -> 4619.3605 | AC11: 7.1 | AD11: =SUM(AB11*AC11) -> 32797.46 | AE11: =SUM(X11+AD11) -> 59831.575 | AF11: =SUM(P11-AE11) -> -7825.9955
A12: 合计 | H12: =SUM(H5:H11) -> 70.2037 | I12: =SUM(I5:I11) -> 21717.2 | J12: =SUM(J4:J4) -> 0 | N12: =SUM(N4:N4) -> 0 | P12: =SUM(P4:P4) -> 0 | Q12: =SUM(Q4:Q4) -> 0 | X12: =SUM(X4:X4) -> 0 | AD12: =SUM(AD4:AD4) -> 0 | AF12: =SUM(AF5:AF11) -> 14370.871

Sheet JOB070360
A1: 2024年07月份LOS毛利表（海运）
A2: PSL表 | B2: 体积cbm | C2: 74.2556
A3: JOB | B3: 集装编号 | C3: 运单编号 | D3: 日期 | E3: 业务 | F3: 发货人 | G3: 收货人 | H3: 计费体积 | I3: 计费重量 | J3: 应 收 | Q3: 总应收 | R3: 起 运 港 成 本 | W3: 代垫运费 | X3: 起运港成本 合计 | Y3: 目的港成本 | AE3: 总支出 | AF3: 利润
J4: 应收RMB | K4: LOS Income(NGN)收到(奈拉) | L4: LOS 收到USD | M4: 美元汇率 dollar currency rate | N4: 应收 到付款USD | O4: 汇率 | P4: 人民币 | R4: 代理商 | S4: 运费+出口报关费 | T4: 提货费 | U4: 装卸费 | V4: 包装费 | Y4: 进口报关费 | Z4: 到门配送费 | AA4: 转运费 | AB4: 目的港支出 | AC4: 汇率 | AD4: 人民币 | AE4: 起运港+目的港
A5: JOB070360 | B5: COLL004060 | C5: 240618000026 | D5: 45482 | E5: Sam.Pao | F5: Sam.Pao | G5: Joshua | H5: 9.0048 | I5: 5844 | J5: 32609 | P5: =SUM(J5) -> 32609 | Q5: =SUM(P5:P10) -> 184530.54 | R5: 华茂青松=60177 赛捷=1500 | S5: =SUM(61677/68)*H5 -> 8167.486 | U5: =SUM(2200/68)*H5 -> 291.33176 | V5: 120 | W5: 1600 | X5: =SUM(S5:W5) -> 10178.818 | Y5: =SUM(10235.99/68)*H5 -> 1355.4859 | Z5: 513.28 | AA5: =SUM(77.88/68)*H5 -> 10.313144 | AB5: =SUM(Y5:AA5) -> 1879.0791 | AC5: 7.12 | AD5: =SUM(AB5*AC5) -> 13379.043 | AE5: =SUM(X5+AD5) -> 23557.861 | AF5: =SUM(P5-AE5) -> 9051.1393
C6: 240704000029 | D6: 45482 | E6: Sam.Pao | F6: Sam.Pao | G6: LuZhiLong | H6: 14.9276 | I6: 11064 | J6: 37314.5 | P6: =SUBTOTAL(9,J6) -> 37314.5 | S6: =SUM(61677/68)*H6 -> 13539.553 | U6: =SUM(2200/68)*H6 -> 482.95176 | X6: =SUM(S6:W6) -> 14022.504 | Y6: =SUM(10235.99/68)*H6 -> 2247.0407 | AA6: =SUM(77.88/68)*H6 -> 17.096492 | AB6: =SUM(Y6:AA6) -> 2264.1371 | AC6: 7.12 | AD6: =SUM(AB6*AC6) -> 16120.656 | AE6: =SUM(X6+AD6) -> 30143.161 | AF6: =SUM(P6-AE6) -> 7171.339
C7: 240617000035 | D7: 45490 | E7: 黄颖 | F7: ying | G7: Huangpu | H7: 12.8123 | I7: 5331.1 | J7: 47840 | P7: =SUM(J7) -> 47840 | S7: =SUM(61677/68)*H7 -> 11620.945 | U7: =SUM(2200/68)*H7 -> 414.51559 | X7: =SUM(S7:W7) -> 12035.46 | Y7: =SUM(10235.99/68)*H7 -> 1928.6261 | AA7: =SUM(77.88/68)*H7 -> 14.673852 | AB7: =SUM(Y7:AA7) -> 1943.3 | AC7: 7.12 | AD7: =SUM(AB7*AC7) -> 13836.296 | AE7: =SUM(X7+AD7) -> 25871.756 | AF7: =SUM(P7-AE7) -> 21968.244
C8: 240707000003 | D8: 45482 | E8: Sam.Pao | F8: Sam.Pao | G8: LuZhiLong | H8: 0.1208 | I8: 69 | J8: 330.48 | P8: =SUBTOTAL(9,J8) -> 330.48 | S8: =SUM(61677/68)*H8 -> 109.56738 | U8: =SUM(2200/68)*H8 -> 3.9082353 | X8: =SUM(S8:W8) -> 113.47561 | Y8: =SUM(10235.99/68)*H8 -> 18.183935 | AA8: =SUM(77.88/68)*H8 -> 0.13835153 | AB8: =SUM(Y8:AA8) -> 18.322287 | AC8: 7.12 | AD8: =SUM(AB8*AC8) -> 130.45468 | AE8: =SUM(X8+AD8) -> 243.93029 | AF8: =SUM(P8-AE8) -> 86.549707
C9: 240708000038 | D9: 45482 | E9: 陆总 | F9: 喵喵速运-江 | G9: LUZHILONG | H9: 1.6 | I9: 1009 | J9: 3916.8 | P9: =SUBTOTAL(9,J9) -> 3916.8 | S9: =SUM(61677/68)*H9 -> 1451.2235 | U9: =SUM(2200/68)*H9 -> 51.764706 | X9: =SUM(S9:W9) -> 1502.9882 | Y9: =SUM(10235.99/68)*H9 -> 240.84682 | AA9: =SUM(77.88/68)*H9 -> 1.8324706 | AB9: =SUM(Y9:AA9) -> 242.67929 | AC9: 7.12 | AD9: =SUM(AB9*AC9) -> 1727.8766 | AE9: =SUM(X9+AD9) -> 3230.8648 | AF9: =SUM(P9-AE9) -> 685.93519
C10: 240708000062 | D10: 45482 | E10: Sam.Pao | F10: Sam.Pao | G10: SKY JET | H10: 35.79 | I10: 4290.5 | J10: 62519.76 | P10: =SUBTOTAL(9,J10) -> 62519.76 | S10: =SUM(61677/68)*H10 -> 32462.056 | U10: =SUM(2200/68)*H10 -> 1157.9118 | X10: =SUM(S10:W10) -> 33619.968 | Y10: =SUM(10235.99/68)*H10 -> 5387.4424 | AA10: =SUM(77.88/68)*H10 -> 40.990076 | AB10: =SUM(Y10:AA10) -> 5428.4325 | AC10: 7.12 | AD10: =SUM(AB10*AC10) -> 38650.439 | AE10: =SUM(X10+AD10) -> 72270.407 | AF10: =SUM(P10-AE10) -> -9750.6472
A11: 合计 | H11: =SUM(H5:H10) -> 74.2555 | I11: =SUM(I5:I10) -> 27607.6 | J11: =SUM(J4:J4) -> 0 | N11: =SUM(N4:N4) -> 0 | P11: =SUM(P4:P4) -> 0 | Q11: =SUM(Q4:Q4) -> 0 | X11: =SUM(X4:X4) -> 0 | AD11: =SUM(AD4:AD4) -> 0 | AF11: =SUM(AF5:AF10) -> 29212.56

Sheet JOB070370
A1: 2024年07月份LOS毛利表（海运）
A2: PSL表 | B2: 体积cbm | C2: 70.9311
A3: JOB | B3: 集装编号 | C3: 运单编号 | D3: 日期 | E3: 业务 | F3: 发货人 | G3: 收货人 | H3: 计费体积 | I3: 计费重量 | J3: 应 收 | Q3: 总应收 | R3: 起 运 港 成 本 | W3: 代垫运费 | X3: 起运港成本 合计 | Y3: 目的港成本 | AE3: 总支出 | AF3: 利润
J4: 应收RMB | K4: LOS Income(NGN)收到(奈拉) | L4: LOS 收到USD | M4: 美元汇率 dollar currency rate | N4: 应收 到付款USD | O4: 汇率 | P4: 人民币 | R4: 代理商 | S4: 运费+出口报关费 | T4: 提货费 | U4: 装卸费 | V4: 包装费 | Y4: 进口报关费 | Z4: 到门配送费 | AA4: 转运费 | AB4: 目的港支出 | AC4: 汇率 | AD4: 人民币 | AE4: 起运港+目的港
A5: JOB070370 | B5: COLL004070 | C5: 240617000035 | D5: 45490 | E5: 黄颖 | F5: ying | G5: Huangpu | H5: 4.9371 | I5: 11872 | J5: 18452 | P5: =SUM(J5) -> 18452 | Q5: =SUM(P5:P16) -> 164523.2 | R5: 华茂青松=60177 赛捷=2300 | S5: =SUM(62477/68)*H5 -> 4536.1058 | T5: 770 | U5: =SUM(2400/68)*H5 -> 174.25059 | W5: =SUM(830+1800) -> 2630 | X5: =SUM(S5:W5) -> 8110.3564 | Y5: =SUM(10235.99/68)*H5 -> 743.17803 | Z5: 471.98 | AA5: =SUM(35.4/68)*H5 -> 2.5701962 | AB5: =SUM(Y5:AA5) -> 1217.7282 | AC5: 7.26 | AD5: =SUM(AB5*AC5) -> 8840.7069 | AE5: =SUM(X5+AD5) -> 16951.063 | AF5: =SUM(P5-AE5) -> 1500.9366
C6: 240702000004 | D6: 45490 | E6: 黄颖 | F6: ying | G6: liangyu | H6: 1.9054 | I6: 586.7 | J6: 7303 | P6: =SUBTOTAL(9,J6) -> 7303 | S6: =SUM(62477/68)*H6 -> 1750.6423 | U6: =SUM(2400/68)*H6 -> 67.249412 | X6: =SUM(S6:W6) -> 1817.8917 | Y6: =SUM(10235.99/68)*H6 -> 286.81846 | AA6: =SUM(35.4/68)*H6 -> 0.99192882 | AB6: =SUM(Y6:AA6) -> 287.81039 | AC6: 7.26 | AD6: =SUM(AB6*AC6) -> 2089.5034 | AE6: =SUM(X6+AD6) -> 3907.3951 | AF6: =SUM(P6-AE6) -> 3395.6049
C7: 240702000027 | D7: 45490 | E7: Sam.Pao | F7: Sam.Pao | G7: Ikenna | H7: 0.9364 | I7: 230 | K7: 539654 | M7: =SUM(K7/N7) -> 1694.9997 | N7: 318.38 | O7: 7.08 | P7: =SUM(N7*O7) -> 2254.1304 | S7: =SUM(62477/68)*H7 -> 860.34504 | U7: =SUM(2400/68)*H7 -> 33.049412 | X7: =SUM(S7:W7) -> 893.39445 | Y7: =SUM(10235.99/68)*H7 -> 140.9556 | AA7: =SUM(35.4/68)*H7 -> 0.48747882 | AB7: =SUM(Y7:AA7) -> 141.44308 | AC7: 7.26 | AD7: =SUM(AB7*AC7) -> 1026.8768 | AE7: =SUM(X7+AD7) -> 1920.2712 | AF7: =SUM(P7-AE7) -> 333.85917
C8: 240708000040 | D8: 45490 | E8: 吕沛霖 | F8: 喵喵速运-Layne | G8: Candice Ding | H8: 0.6334 | I8: 1195 | K8: 1077245.4 | M8: =SUM(K8/N8) -> 1744.414 | N8: 617.54 | O8: 7.12 | P8: =SUM(N8*O8) -> 4396.8848 | S8: =SUM(62477/68)*H8 -> 581.95488 | U8: =SUM(2400/68)*H8 -> 22.355294 | X8: =SUM(S8:W8) -> 604.31017 | Y8: =SUM(10235.99/68)*H8 -> 95.345236 | Z8: 59 | AA8: =SUM(35.4/68)*H8 -> 0.32974059 | AB8: =SUM(Y8:AA8) -> 154.67498 | AC8: 7.26 | AD8: =SUM(AB8*AC8) -> 1122.9403 | AE8: =SUM(X8+AD8) -> 1727.2505 | AF8: =SUM(P8-AE8) -> 2669.6343
C9: 240711000027 | D9: 45490 | E9: Bella | F9: Bella Chan | G9: James | H9: 0.8466 | I9: 370 | L9: 296.31 | M9: =SUM(K9/N9) -> 0 | N9: 296.31006 | O9: 7.12 | P9: =SUM(N9*O9) -> 2109.7276 | S9: =SUM(62477/68)*H9 -> 777.83865 | U9: =SUM(2400/68)*H9 -> 29.88 | X9: =SUM(S9:W9) -> 807.71865 | Y9: =SUM(10235.99/68)*H9 -> 127.43808 | AA9: =SUM(35.4/68)*H9 -> 0.44073 | AB9: =SUM(Y9:AA9) -> 127.87881 | AC9: 7.26 | AD9: =SUM(AB9*AC9) -> 928.40013 | AE9: =SUM(X9+AD9) -> 1736.1188 | AF9: =SUM(P9-AE9) -> 373.60885
C10: 240715000001 | D10: 45490 | E10: 朱小飞 | F10: Isabel Zhu | G10: Halifa Success | H10: 0.269 | I10: 184 | J10: 660.29 | P10: =SUBTOTAL(9,J10) -> 660.29 | S10: =SUM(62477/68)*H10 -> 247.15166 | U10: =SUM(2400/68)*H10 -> 9.4941176 | X10: =SUM(S10:W10) -> 256.64578 | Y10: =SUM(10235.99/68)*H10 -> 40.492372 | AA10: =SUM(35.4/68)*H10 -> 0.14003824 | AB10: =SUM(Y10:AA10) -> 40.63241 | AC10: 7.26 | AD10: =SUM(AB10*AC10) -> 294.9913 | AE10: =SUM(X10+AD10) -> 551.63708 | AF10: =SUM(P10-AE10) -> 108.65292
C11: 240715000029 | D11: 45490 | E11: 陆总 | F11: 喵喵速运-江 | G11: LUZHILONG | H11: 7.56 | I11: 5200 | J11: 19595.52 | P11: =SUBTOTAL(9,J11) -> 19595.52 | S11: =SUM(62477/68)*H11 -> 6945.9724 | U11: =SUM(2400/68)*H11 -> 266.82353 | X11: =SUM(S11:W11) -> 7212.7959 | Y11: =SUM(10235.99/68)*H11 -> 1138.0012 | AA11: =SUM(35.4/68)*H11 -> 3.9356471 | AB11: =SUM(Y11:AA11) -> 1141.9369 | AC11: 7.26 | AD11: =SUM(AB11*AC11) -> 8290.4618 | AE11: =SUM(X11+AD11) -> 15503.258 | AF11: =SUM(P11-AE11) -> 4092.2623
C12: 240715000048 | D12: 45490 | E12: Sam.Pao | F12: Sam.Pao | G12: Yusky | H12: 11.5846 | I12: 2575.5 | J12: 24968.54 | P12: =SUBTOTAL(9,J12) -> 24968.54 | S12: =SUM(62477/68)*H12 -> 10643.692 | U12: =SUM(2400/68)*H12 -> 408.86824 | X12: =SUM(S12:W12) -> 11052.56 | Y12: =SUM(10235.99/68)*H12 -> 1743.8213 | AA12: =SUM(35.4/68)*H12 -> 6.0308065 | AB12: =SUM(Y12:AA12) -> 1749.8521 | AC12: 7.26 | AD12: =SUM(AB12*AC12) -> 12703.926 | AE12: =SUM(X12+AD12) -> 23756.487 | AF12: =SUM(P12-AE12) -> 1212.0534
C13: 240715000049 | D13: 45490 | E13: Sam.Pao | F13: Sam.Pao | G13: Yusky | H13: 5.0829 | I13: 911 | J13: 10979.06 | P13: =SUBTOTAL(9,J13) -> 10979.06 | S13: =SUM(62477/68)*H13 -> 4670.0639 | U13: =SUM(2400/68)*H13 -> 179.39647 | X13: =SUM(S13:W13) -> 4849.4603 | Y13: =SUM(10235.99/68)*H13 -> 765.1252 | AA13: =SUM(35.4/68)*H13 -> 2.6460979 | AB13: =SUM(Y13:AA13) -> 767.7713 | AC13: 7.26 | AD13: =SUM(AB13*AC13) -> 5574.0196 | AE13: =SUM(X13+AD13) -> 10423.48 | AF13: =SUM(P13-AE13) -> 555.58004
C14: 240716000001 | D14: 45490 | E14: 朱小飞 | F14: Isabel Zhu | G14: Victor Nnamdi | H14: 0.9605 | I14: 145 | K14: 591555 | M14: =SUM(K14/N14) -> 1710.7842 | N14: 345.78003 | O14: 7.06 | P14: =SUM(N14*O14) -> 2441.207 | S14: =SUM(62477/68)*H14 -> 882.48762 | U14: =SUM(2400/68)*H14 -> 33.9 | X14: =SUM(S14:W14) -> 916.38762 | Y14: =SUM(10235.99/68)*H14 -> 144.58336 | AA14: =SUM(35.4/68)*H14 -> 0.500025 | AB14: =SUM(Y14:AA14) -> 145.08338 | AC14: 7.26 | AD14: =SUM(AB14*AC14) -> 1053.3054 | AE14: =SUM(X14+AD14) -> 1969.693 | AF14: =SUM(P14-AE14) -> 471.51402
C15: 240716000007 | D15: 45490 | E15: 陆总 | F15: 喵喵速运-江 | G15: LUZHILONG | H15: 12.4652 | I15: 1110 | J15: 29367.14 | P15: =SUBTOTAL(9,J15) -> 29367.14 | S15: =SUM(62477/68)*H15 -> 11452.769 | U15: =SUM(2400/68)*H15 -> 439.94824 | V15: 200 | X15: =SUM(S15:W15) -> 12092.717 | Y15: =SUM(10235.99/68)*H15 -> 1876.3774 | AA15: =SUM(35.4/68)*H15 -> 6.4892365 | AB15: =SUM(Y15:AA15) -> 1882.8666 | AC15: 7.26 | AD15: =SUM(AB15*AC15) -> 13669.612 | AE15: =SUM(X15+AD15) -> 25762.329 | AF15: =SUM(P15-AE15) -> 3604.8109
C16: 240716000037 | D16: 45490 | E16: Sam.Pao | F16: Sam.Pao | G16: SKY JET | H16: 23.75 | I16: 3022 | J16: 41995.7 | P16: =SUBTOTAL(9,J16) -> 41995.7 | S16: =SUM(62477/68)*H16 -> 21821.011 | U16: =SUM(2400/68)*H16 -> 838.23529 | X16: =SUM(S16:W16) -> 22659.246 | Y16: =SUM(10235.99/68)*H16 -> 3575.07 | AA16: =SUM(35.4/68)*H16 -> 12.363971 | AB16: =SUM(Y16:AA16) -> 3587.434 | AC16: 7.26 | AD16: =SUM(AB16*AC16) -> 26044.771 | AE16: =SUM(X16+AD16) -> 48704.017 | AF16: =SUM(P16-AE16) -> -6708.3172
A17: 合计 | H17: =SUM(H5:H16) -> 70.9311 | I17: =SUM(I5:I16) -> 27401.2 | J17: =SUM(J4:J4) -> 0 | N17: =SUM(N4:N4) -> 0 | P17: =SUM(P4:P4) -> 0 | Q17: =SUM(Q4:Q4) -> 0 | X17: =SUM(X4:X4) -> 0 | AD17: =SUM(AD4:AD4) -> 0 | AF17: =SUM(AF5:AF16) -> 11610.2

Sheet JOB070375
A1: 2024年07月份LOS毛利表（海运）
A2: PSL表 | B2: 体积cbm | C2: 82.1642
A3: JOB | B3: 集装编号 | C3: 运单编号 | D3: 日期 | E3: 业务 | F3: 发货人 | G3: 收货人 | H3: 计费体积 | I3: 计费重量 | J3: 应 收 | Q3: 总应收 | R3: 起 运 港 成 本 | W3: 代垫运费 | X3: 起运港成本 合计 | Y3: 目的港成本 | AE3: 总支出 | AF3: 利润
J4: 应收RMB | K4: LOS Income(NGN)收到(奈拉) | L4: LOS 收到USD | M4: 美元汇率 dollar currency rate | N4: 应收 到付款USD | O4: 汇率 | P4: 人民币 | R4: 代理商 | S4: 运费+出口报关费 | T4: 提货费 | U4: 装卸费 | V4: 包装费 | Y4: 进口报关费 | Z4: 到门配送费 | AA4: 转运费 | AB4: 目的港支出 | AC4: 汇率 | AD4: 人民币 | AE4: 起运港+目的港
A5: JOB070375 | B5: COLL004074 | C5: 240715000042 | D5: 45498 | E5: 苏慧琪 | F5: Danny | G5: Austin Efe | H5: 0.3636 | I5: 253.4 | J5: 1117.2 | P5: =SUBTOTAL(9,J5) -> 1117.2 | Q5: =SUM(P5:P24) -> 175734.86 | R5: 华茂青松=60177 赛捷=1300 | S5: =SUM(61477/68)*H5 -> 328.72114 | T5: =SUM(600/68)*H5 -> 3.2082353 | U5: =SUM(1150/68)*H5 -> 6.1491176 | X5: =SUM(S5:W5) -> 338.07849 | Y5: =SUM(10510.33/68)*H5 -> 56.199353 | AA5: =SUM(35.4/68)*H5 -> 0.18928588 | AB5: =SUM(Y5:AA5) -> 56.388639 | AC5: 7.06 | AD5: =SUM(AB5*AC5) -> 398.10379 | AE5: =SUM(X5+AD5) -> 736.18228 | AF5: =SUM(P5-AE5) -> 381.01772
C6: 240716000022 | D6: 45498 | E6: 黄颖 | F6: ying | G6: Huangpu | H6: 0.0648 | I6: 67.5 | J6: 630 | P6: =SUM(J6) -> 630 | S6: =SUM(61477/68)*H6 -> 58.583965 | T6: =SUM(600/68)*H6 -> 0.57176471 | U6: =SUM(1150/68)*H6 -> 1.0958824 | X6: =SUM(S6:W6) -> 60.251612 | Y6: =SUM(10510.33/68)*H6 -> 10.015726 | Z6: 30.54 | AA6: =SUM(35.4/68)*H6 -> 0.033734118 | AB6: =SUM(Y6:AA6) -> 40.58946 | AC6: 7.06 | AD6: =SUM(AB6*AC6) -> 286.56159 | AE6: =SUM(X6+AD6) -> 346.8132 | AF6: =SUM(P6-AE6) -> 283.1868
C7: 240717000017 | D7: 45498 | E7: 黄颖 | F7: ying | G7: Nura | H7: 0.6221 | I7: 294 | J7: 1390 | P7: =SUM(J7) -> 1390 | S7: =SUM(61477/68)*H7 -> 562.42414 | T7: =SUM(600/68)*H7 -> 5.4891176 | U7: =SUM(1150/68)*H7 -> 10.520809 | X7: =SUM(S7:W7) -> 578.43407 | Y7: =SUM(10510.33/68)*H7 -> 96.154063 | AA7: =SUM(35.4/68)*H7 -> 0.32385794 | AB7: =SUM(Y7:AA7) -> 96.477921 | AC7: 7.06 | AD7: =SUM(AB7*AC7) -> 681.13412 | AE7: =SUM(X7+AD7) -> 1259.5682 | AF7: =SUM(P7-AE7) -> 130.43181
C8: 240717000037 | D8: 45498 | E8: 朱小飞 | F8: Isabel Zhu | G8: Mr Michael | H8: 0.9774 | I8: 169.65 | J8: 2342 | P8: =SUBTOTAL(9,J8) -> 2342 | S8: =SUM(61477/68)*H8 -> 883.64147 | T8: =SUM(600/68)*H8 -> 8.6241176 | U8: =SUM(1150/68)*H8 -> 16.529559 | W8: 52 | X8: =SUM(S8:W8) -> 960.79514 | Y8: =SUM(10510.33/68)*H8 -> 151.07054 | AA8: =SUM(35.4/68)*H8 -> 0.50882294 | AB8: =SUM(Y8:AA8) -> 151.57936 | AC8: 7.06 | AD8: =SUM(AB8*AC8) -> 1070.1503 | AE8: =SUM(X8+AD8) -> 2030.9454 | AF8: =SUM(P8-AE8) -> 311.05457
C9: 240718000030 | D9: 45498 | E9: 黄颖 | F9: ying | G9: liangyu | H9: 0.2438 | I9: 26.5 | J9: 606.5 | P9: =SUBTOTAL(9,J9) -> 606.5 | S9: =SUM(61477/68)*H9 -> 220.41313 | T9: =SUM(600/68)*H9 -> 2.1511765 | U9: =SUM(1150/68)*H9 -> 4.1230882 | X9: =SUM(S9:W9) -> 226.68739 | Y9: =SUM(10510.33/68)*H9 -> 37.682624 | AA9: =SUM(35.4/68)*H9 -> 0.12691941 | AB9: =SUM(Y9:AA9) -> 37.809544 | AC9: 7.06 | AD9: =SUM(AB9*AC9) -> 266.93538 | AE9: =SUM(X9+AD9) -> 493.62277 | AF9: =SUM(P9-AE9) -> 112.87723
C10: 240719000002 | D10: 45498 | E10: 黄颖 | F10: ying | G10: chuks | H10: 0.8911 | I10: 332 | J10: 2500 | P10: =SUBTOTAL(9,J10) -> 2500 | S10: =SUM(61477/68)*H10 -> 805.61992 | T10: =SUM(600/68)*H10 -> 7.8626471 | U10: =SUM(1150/68)*H10 -> 15.070074 | X10: =SUM(S10:W10) -> 828.55264 | Y10: =SUM(10510.33/68)*H10 -> 137.73169 | Z10: 41.3 | AA10: =SUM(35.4/68)*H10 -> 0.46389618 | AB10: =SUM(Y10:AA10) -> 179.49559 | AC10: 7.06 | AD10: =SUM(AB10*AC10) -> 1267.2389 | AE10: =SUM(X10+AD10) -> 2095.7915 | AF10: =SUM(P10-AE10) -> 404.2085
C11: 240719000036 | D11: 45498 | E11: 朱小飞 | F11: Isabel Zhu | G11: Halifa Success | H11: 1.8646 | I11: 213 | J11: 4300.07 | P11: =SUBTOTAL(9,J11) -> 4300.07 | S11: =SUM(61477/68)*H11 -> 1685.7355 | T11: =SUM(600/68)*H11 -> 16.452353 | U11: =SUM(1150/68)*H11 -> 31.533676 | X11: =SUM(S11:W11) -> 1733.7215 | Y11: =SUM(10510.33/68)*H11 -> 288.19943 | AA11: =SUM(35.4/68)*H11 -> 0.97068882 | AB11: =SUM(Y11:AA11) -> 289.17012 | AC11: 7.06 | AD11: =SUM(AB11*AC11) -> 2041.541 | AE11: =SUM(X11+AD11) -> 3775.2626 | AF11: =SUM(P11-AE11) -> 524.80742
C12: 240720000015 | D12: 45498 | E12: 朱小飞 | F12: Isabel Zhu | G12: Halifa Success | H12: 0.3673 | I12: 57 | J12: 880.38 | P12: =SUBTOTAL(9,J12) -> 880.38 | S12: =SUM(61477/68)*H12 -> 332.06621 | T12: =SUM(600/68)*H12 -> 3.2408824 | U12: =SUM(1150/68)*H12 -> 6.2116912 | X12: =SUM(S12:W12) -> 341.51878 | Y12: =SUM(10510.33/68)*H12 -> 56.771238 | AA12: =SUM(35.4/68)*H12 -> 0.19121206 | AB12: =SUM(Y12:AA12) -> 56.96245 | AC12: 7.06 | AD12: =SUM(AB12*AC12) -> 402.1549 | AE12: =SUM(X12+AD12) -> 743.67368 | AF12: =SUM(P12-AE12) -> 136.70632
C13: 240724000014 | D13: 45498 | E13: 黄颖 | F13: ying | G13: Huangpu | H13: 0.2732 | I13: 264 | J13: 894 | P13: =SUBTOTAL(9,J13) -> 894 | S13: =SUM(61477/68)*H13 -> 246.99289 | T13: =SUM(600/68)*H13 -> 2.4105882 | U13: =SUM(1150/68)*H13 -> 4.6202941 | X13: =SUM(S13:W13) -> 254.02377 | Y13: =SUM(10510.33/68)*H13 -> 42.226796 | AA13: =SUM(35.4/68)*H13 -> 0.14222471 | AB13: =SUM(Y13:AA13) -> 42.369021 | AC13: 7.06 | AD13: =SUM(AB13*AC13) -> 299.12529 | AE13: =SUM(X13+AD13) -> 553.14906 | AF13: =SUM(P13-AE13) -> 340.85094
C14: 240724000017 | D14: 45498 | E14: 罗伟健 | F14: MailMail速运-演员 | G14: zeng hai | H14: 0.2991 | I14: 1311 | K14: 1137000 | M14: =SUM(K14/N14) -> 1689.7013 | N14: 672.9 | O14: 7.06 | P14: =SUM(N14*O14) -> 4750.674 | S14: =SUM(61477/68)*H14 -> 270.40839 | T14: =SUM(600/68)*H14 -> 2.6391176 | U14: =SUM(1150/68)*H14 -> 5.0583088 | V14: 210 | W14: 330 | X14: =SUM(S14:W14) -> 818.10582 | Y14: =SUM(10510.33/68)*H14 -> 46.229996 | AA14: =SUM(35.4/68)*H14 -> 0.15570794 | AB14: =SUM(Y14:AA14) -> 46.385704 | AC14: 7.06 | AD14: =SUM(AB14*AC14) -> 327.48307 | AE14: =SUM(X14+AD14) -> 1145.5889 | AF14: =SUM(P14-AE14) -> 3605.0851
C15: 240724000022 | D15: 45498 | E15: Sam.Pao | F15: Sam.Pao | G15: Yusky | H15: 6.0843 | I15: 633 | J15: 12265.92 | P15: =SUBTOTAL(9,J15) -> 12265.92 | S15: =SUM(61477/68)*H15 -> 5500.6546 | T15: =SUM(600/68)*H15 -> 53.685 | U15: =SUM(1150/68)*H15 -> 102.89625 | X15: =SUM(S15:W15) -> 5657.2358 | Y15: =SUM(10510.33/68)*H15 -> 940.41178 | AA15: =SUM(35.4/68)*H15 -> 3.167415 | AB15: =SUM(Y15:AA15) -> 943.57919 | AC15: 7.06 | AD15: =SUM(AB15*AC15) -> 6661.6691 | AE15: =SUM(X15+AD15) -> 12318.905 | AF15: =SUM(P15-AE15) -> -52.984919
C16: 240724000024 | D16: 45498 | E16: Sam.Pao | F16: Sam.Pao | G16: Yusky | H16: 0.6352 | I16: 38 | J16: 1280.59 | P16: =SUBTOTAL(9,J16) -> 1280.59 | S16: =SUM(61477/68)*H16 -> 574.26751 | T16: =SUM(600/68)*H16 -> 5.6047059 | U16: =SUM(1150/68)*H16 -> 10.742353 | X16: =SUM(S16:W16) -> 590.61456 | Y16: =SUM(10510.33/68)*H16 -> 98.178847 | AA16: =SUM(35.4/68)*H16 -> 0.33067765 | AB16: =SUM(Y16:AA16) -> 98.509525 | AC16: 7.06 | AD16: =SUM(AB16*AC16) -> 695.47725 | AE16: =SUM(X16+AD16) -> 1286.0918 | AF16: =SUM(P16-AE16) -> -5.5018108
C17: 240724000025 | D17: 45498 | E17: 陆总 | F17: 喵喵速运-江 | G17: LUZHILONG | H17: 24.4728 | I17: 3060 | J17: 57259.8 | P17: =SUBTOTAL(9,J17) -> 57259.8 | S17: =SUM(61477/68)*H17 -> 22125.211 | T17: =SUM(600/68)*H17 -> 215.93647 | U17: =SUM(1150/68)*H17 -> 413.87824 | X17: =SUM(S17:W17) -> 22755.025 | Y17: =SUM(10510.33/68)*H17 -> 3782.6059 | AA17: =SUM(35.4/68)*H17 -> 12.740252 | AB17: =SUM(Y17:AA17) -> 3795.3462 | AC17: 7.06 | AD17: =SUM(AB17*AC17) -> 26795.144 | AE17: =SUM(X17+AD17) -> 49550.17 | AF17: =SUM(P17-AE17) -> 7709.6305
C18: 240724000026 | D18: 45498 | E18: Bella | F18: Bella Chan | G18: zhong zi xin | H18: 15.7603 | I18: 8373 | K18: 8696280.7 | M18: =SUM(K18/N18) -> 1710.9973 | N18: 5082.58 | O18: 7.12 | P18: =SUM(N18*O18) -> 36187.97 | S18: =SUM(61477/68)*H18 -> 14248.47 | T18: =SUM(600/68)*H18 -> 139.06147 | U18: =SUM(1150/68)*H18 -> 266.53449 | X18: =SUM(S18:W18) -> 14654.066 | Y18: =SUM(10510.33/68)*H18 -> 2435.9699 | Z18: 217.7 | AA18: =SUM(35.4/68)*H18 -> 8.2046268 | AB18: =SUM(Y18:AA18) -> 2661.8745 | AC18: 7.06 | AD18: =SUM(AB18*AC18) -> 18792.834 | AE18: =SUM(X18+AD18) -> 33446.9 | AF18: =SUM(P18-AE18) -> 2741.0694
C19: 240724000044 | D19: 45498 | E19: Sam.Pao | F19: Sam.Pao | G19: SKY JET | H19: 20.87 | I19: 2559.5 | J19: 34224.71 | P19: =SUBTOTAL(9,J19) -> 34224.71 | S19: =SUM(61477/68)*H19 -> 18868.015 | T19: =SUM(600/68)*H19 -> 184.14706 | U19: =SUM(1150/68)*H19 -> 352.94853 | X19: =SUM(S19:W19) -> 19405.11 | Y19: =SUM(10510.33/68)*H19 -> 3225.7439 | AA19: =SUM(35.4/68)*H19 -> 10.864676 | AB19: =SUM(Y19:AA19) -> 3236.6086 | AC19: 7.06 | AD19: =SUM(AB19*AC19) -> 22850.457 | AE19: =SUM(X19+AD19) -> 42255.567 | AF19: =SUM(P19-AE19) -> -8030.8569
C20: 240724000046 | D20: 45498 | E20: Sam.Pao | F20: Sam.Pao | G20: Yusky | H20: 0.6621 | I20: 270 | J20: 1334.81 | P20: =SUBTOTAL(9,J20) -> 1334.81 | S20: =SUM(61477/68)*H20 -> 598.58708 | T20: =SUM(600/68)*H20 -> 5.8420588 | U20: =SUM(1150/68)*H20 -> 11.197279 | X20: =SUM(S20:W20) -> 615.62642 | Y20: =SUM(10510.33/68)*H20 -> 102.33661 | AA20: =SUM(35.4/68)*H20 -> 0.34468147 | AB20: =SUM(Y20:AA20) -> 102.68129 | AC20: 7.06 | AD20: =SUM(AB20*AC20) -> 724.92992 | AE20: =SUM(X20+AD20) -> 1340.5563 | AF20: =SUM(P20-AE20) -> -5.7463412
C21: 240724000047 | D21: 45498 | E21: Sam.Pao | F21: Sam.Pao | G21: Yusky | H21: 0.2282 | I21: 54 | J21: 460.08 | P21: =SUBTOTAL(9,J21) -> 460.08 | S21: =SUM(61477/68)*H21 -> 206.30958 | T21: =SUM(600/68)*H21 -> 2.0135294 | U21: =SUM(1150/68)*H21 -> 3.8592647 | X21: =SUM(S21:W21) -> 212.18237 | Y21: =SUM(10510.33/68)*H21 -> 35.271431 | AA21: =SUM(35.4/68)*H21 -> 0.11879824 | AB21: =SUM(Y21:AA21) -> 35.390229 | AC21: 7.06 | AD21: =SUM(AB21*AC21) -> 249.85502 | AE21: =SUM(X21+AD21) -> 462.03739 | AF21: =SUM(P21-AE21) -> -1.9573917
C22: 240724000048 | D22: 45498 | E22: Sam.Pao | F22: Sam.Pao | G22: Yusky | H22: 3.0687 | I22: 528 | J22: 6208.07 | P22: =SUBTOTAL(9,J22) -> 6208.07 | S22: =SUM(61477/68)*H22 -> 2774.3304 | T22: =SUM(600/68)*H22 -> 27.076765 | U22: =SUM(1150/68)*H22 -> 51.897132 | X22: =SUM(S22:W22) -> 2853.3043 | Y22: =SUM(10510.33/68)*H22 -> 474.30955 | AA22: =SUM(35.4/68)*H22 -> 1.5975291 | AB22: =SUM(Y22:AA22) -> 475.90708 | AC22: 7.06 | AD22: =SUM(AB22*AC22) -> 3359.904 | AE22: =SUM(X22+AD22) -> 6213.2083 | AF22: =SUM(P22-AE22) -> -5.1383435
C23: 240724000054 | D23: 45498 | E23: Sam.Pao | F23: Sam.Pao | G23: LuZhiLong | H23: 2.7 | I23: 992.8 | J23: 6294.95 | P23: =SUBTOTAL(9,J23) -> 6294.95 | S23: =SUM(61477/68)*H23 -> 2440.9985 | T23: =SUM(600/68)*H23 -> 23.823529 | U23: =SUM(1150/68)*H23 -> 45.661765 | X23: =SUM(S23:W23) -> 2510.4838 | Y23: =SUM(10510.33/68)*H23 -> 417.32193 | AA23: =SUM(35.4/68)*H23 -> 1.4055882 | AB23: =SUM(Y23:AA23) -> 418.72751 | AC23: 7.06 | AD23: =SUM(AB23*AC23) -> 2956.2163 | AE23: =SUM(X23+AD23) -> 5466.7001 | AF23: =SUM(P23-AE23) -> 828.24992
C24: 240725000032 | D24: 45498 | E24: Sam.Pao | F24: Sam.Pao | G24: Yusky | H24: 0.3976 | I24: 178 | J24: 807.14 | P24: =SUBTOTAL(9,J24) -> 807.14 | S24: =SUM(61477/68)*H24 -> 359.45964 | T24: =SUM(600/68)*H24 -> 3.5082353 | U24: =SUM(1150/68)*H24 -> 6.7241176 | X24: =SUM(S24:W24) -> 369.69199 | Y24: =SUM(10510.33/68)*H24 -> 61.454518 | AA24: =SUM(35.4/68)*H24 -> 0.20698588 | AB24: =SUM(Y24:AA24) -> 61.661504 | AC24: 7.06 | AD24: =SUM(AB24*AC24) -> 435.33022 | AE24: =SUM(X24+AD24) -> 805.0222 | AF24: =SUM(P24-AE24) -> 2.117796
A25: 合计 | H25: =SUM(H5:H24) -> 80.8462 | I25: =SUM(I5:I24) -> 19674.35 | J25: =SUM(J4:J4) -> 0 | N25: =SUM(N4:N4) -> 0 | P25: =SUM(P4:P4) -> 0 | Q25: =SUM(Q4:Q4) -> 0 | X25: =SUM(X4:X4) -> 0 | AD25: =SUM(AD4:AD4) -> 0 | AF25: =SUM(AF5:AF24) -> 9409.1083
