Workbook

Sheet 1月份 
A1: 尼日利亚拉各斯（LOS） 应收利润明细表
A2: JOB | B2: 集装编号 | C2: 运单编号 | D2: 日期 | E2: 发货人 | F2: 收货人 | G2: 计费重量 | H2: 应 收 | O2: 总应收 | P2: 起 运 港 成 本 | U2: 代垫运费 | V2: 起运港成本 合计 | W2: 目的港成本 | AC2: 总支出 | AD2: 利润
H3: 应收RMB | I3: LOS Income(NGN) 收到(奈拉) | J3: LOS 收到USD | K3: 美元汇率 dollar currency rate | L3: 应收 到付款USD | M3: 汇率 | N3: 人民币 | P3: 代理商 | Q3: 运费 | R3: 提货费 | S3: 送货费 | T3: 包装费 | W3: 进口报关费 | X3: 到门配送费 | Y3: 转运费 | Z3: 目的港支出 | AA3: 汇率 | AB3: 人民币 | AC3: 起运港+目的港
A4: JOB010270 | B4: COLL003764 | C4: 231219000049 | D4: 45293 | E4: ying | F4: yanjian | G4: 3.5 | H4: 325.4 | N4: 325.4 | O4: 175736.21 | P4: 顶派=95589 广州通达=4832.8 | Q4: 100421.8 | S4: 243 | V4: 101389.8 | W4: 2817.74 | X4: 9.1 | Z4: 2861.99 | AA4: 7.17 | AB4: 20520.468 | AC4: 121910.27 | AD4: 53825.946
C5: 231222000006 | D5: 45293 | E5: Kaylee | F5: Tengsifan | G5: 9.5 | I5: 120120 | K5: 1262.0298 | L5: 95.18 | M5: 7.17 | N5: 682.4406 | T5: 40
C6: 231222000020 | D6: 45293 | E6: Isabel Zhu | F6: Zi Xuan Wang | G6: 6 | I6: 71400 | K6: 1254.833 | L6: 56.9 | M6: 7.17 | N6: 407.973
C7: 231223000002 | D7: 45293 | E7: Kaylee | F7: Ezeilo Eugene | G7: 40.5 | H7: 2106 | N7: 2106
C8: 231223000003 | D8: 45293 | E8: Kaylee | F8: kevin | G8: 0.98 | I8: 12848 | K8: 1262.0825 | L8: 10.18 | M8: 7.17 | N8: 72.9906
C9: 231223000005 | D9: 45293 | E9: 喵喵速运-Layne | F9: ZUBBY EQUIPMENT TECHNOLOGY | G9: 15 | I9: 132060 | K9: 1240 | L9: 106.5 | M9: 7.17 | N9: 763.605
C10: 231223000006 | D10: 45293 | E10: 喵喵速运-Layne | F10: Lukas | G10: 2.5 | I10: 22250 | K10: 1276.5347 | L10: 17.43 | M10: 7.17 | N10: 124.9731
C11: 231223000008 | D11: 45293 | E11: 喵喵速运-Layne | F11: fast hours DM NIGHT LED | G11: 3 | I11: 39362.4 | K11: 1325.3333 | L11: 29.7 | M11: 7.17 | N11: 212.949
C12: 231223000010 | D12: 45293 | E12: ying | F12: SEGUN | G12: 48.5 | H12: 3197 | N12: 3197 | U12: 190
C13: 231225000001 | D13: 45293 | E13: Isabel Zhu | F13: Mr Xiang | G13: 4 | H13: 283 | N13: 283
C14: 231225000004 | D14: 45293 | E14: Isabel Zhu | F14: Ope Olofinjana | G14: 32 | I14: 362435 | K14: 1239.9418 | L14: 292.3 | M14: 7.17 | N14: 2095.791
C15: 231225000006 | D15: 45293 | E15: Kaylee | F15: Wangpengtao王鹏涛 | G15: 47.5 | H15: 3105 | N15: 3105 | U15: 10
C16: 231225000008 | D16: 45293 | E16: Bella Chan | F16: Jimmy | G16: 33.5 | H16: 1708.5 | N16: 1708.5
C17: 231225000010 | D17: 45293 | E17: 喵喵速运-Layne | F17: Miss Yang Jun | G17: 73.5 | H17: 3864 | N17: 3864
C18: 231225000012 | D18: 45293 | E18: ying | F18: felix | G18: 38.5 | H18: 1963.5 | N18: 1963.5
C19: 231225000014 | D19: 45293 | E19: 喵喵速运-Layne | F19: Ye Hui | G19: 33 | H19: 1716 | N19: 1716
C20: 231225000016 | D20: 45293 | E20: 喵喵速运-Layne | F20: William Xu | G20: 5.5 | I20: 68670 | K20: 1563.1687 | L20: 43.93 | M20: 7.17 | N20: 314.9781 | T20: 40
C21: 231225000018 | D21: 45293 | E21: 喵喵速运-Layne | F21: ZHABV | G21: 1.5 | H21: 123 | N21: 123
C22: 231225000023 | D22: 45293 | E22: 喵喵速运-Layne | F22: SF 覃晓 | G22: 411.5 | H22: 18517.5 | N22: 18517.5
C23: 231225000025 | D23: 45293 | E23: 喵喵速运-Layne | F23: Leon | G23: 3.5 | I23: 36960 | K23: 1262.2951 | L23: 29.28 | M23: 7.17 | N23: 209.9376
C24: 231225000027 | D24: 45293 | E24: ying | F24: abu | G24: 6 | H24: 318 | N24: 318
C25: 231225000028 | D25: 45293 | E25: Sam.Pao | F25: AiGeLi | G25: 30.5 | H25: 1925 | N25: 1925
C26: 231225000029 | D26: 45293 | E26: Bella Chan | F26: li tao | G26: 2 | H26: 113 | N26: 113
C27: 231225000030 | D27: 45293 | E27: 喵喵速运-Layne | F27: Wen Yi Min | G27: 51.5 | I27: 528360 | K27: 1326.4712 | L27: 398.32 | M27: 7.17 | N27: 2855.9544
C28: 231225000031 | D28: 45293 | E28: DUDUHE鹤 | F28: SHAN NAN | G28: 23 | I28: 260896 | K28: 1240 | L28: 210.4 | M28: 7.17 | N28: 1508.568
C29: 231225000033 | D29: 45293 | E29: ying | F29: LI XING MAO | G29: 37.5 | I29: 455087 | K29: 1254.7547 | L29: 362.69 | M29: 7.17 | N29: 2600.4873 | U29: 80
C30: 231225000034 | D30: 45293 | E30: ying | F30: Mark Hu | G30: 13.5 | H30: 910.5 | N30: 910.5
C31: 231225000036 | D31: 45293 | E31: Sam.Pao | F31: David Wei | G31: 159 | I31: 1564420 | K31: 1276.0983 | L31: 1225.94 | M31: 7.17 | N31: 8789.9898
C32: 231225000039 | D32: 45293 | E32: 喵喵速运-Layne | F32: Zhou Ji BBQ | G32: 20 | H32: 1140 | N32: 1140 | T32: 40
C33: 231226000001 | D33: 45293 | E33: 喵喵速运-Layne | F33: REMI | G33: 13.5 | I33: 148500 | K33: 1577.4379 | L33: 94.14 | M33: 7.17 | N33: 674.9838
C34: 231226000003 | D34: 45293 | E34: Isabel Zhu | F34: Mr Zheng | G34: 50.5 | I34: 521362 | K34: 1295.0519 | L34: 402.58 | M34: 7.17 | N34: 2886.4986
C35: 231226000005 | D35: 45293 | E35: ying | F35: yunus | G35: 14 | I35: 166144 | K35: 1262.0129 | L35: 131.65 | M35: 7.17 | N35: 943.9305
C36: 231226000015 | D36: 45293 | E36: 喵喵速运-Layne | F36: REMI | G36: 3 | I36: 33000 | K36: 1577.4379 | L36: 20.92 | M36: 7.17 | N36: 149.9964
C37: 231226000016 | D37: 45293 | E37: ying | F37: liangyu | G37: 17.5 | H37: 916 | N37: 916
C38: 231226000017 | D38: 45293 | E38: Sam.Pao | F38: Wilson Liang | G38: 241 | I38: 2497680 | K38: 1278.0891 | L38: 1954.23 | M38: 7.17 | N38: 14011.829
C39: 231226000020 | D39: 45293 | E39: Bella Chan | F39: John Jiang | G39: 43.5 | H39: 2295 | N39: 2295 | X39: 35.15
C40: 231226000021 | D40: 45293 | E40: Isabel Zhu | F40: Halifa Success | G40: 5 | H40: 282.5 | N40: 282.5
...

Sheet 2月份
A1: 尼日利亚拉各斯（LOS） 应收利润明细表
A2: JOB | B2: 集装编号 | C2: 运单编号 | D2: 日期 | E2: 发货人 | F2: 收货人 | G2: 计费重量 | H2: 应 收 | O2: 总应收 | P2: 起 运 港 成 本 | U2: 代垫运费 | V2: 起运港成本 合计 | W2: 目的港成本 | AC2: 总支出 | AD2: 利润
H3: 应收RMB | I3: LOS Income(NGN) 收到(奈拉) | J3: LOS 收到USD | K3: 美元汇率 dollar currency rate | L3: 应收 到付款USD | M3: 汇率 | N3: 人民币 | P3: 代理商 | Q3: 运费 | R3: 提货费 | S3: 送货费 | T3: 包装费 | W3: 进口报关费 | X3: 到门配送费 | Y3: 转运费 | Z3: 目的港支出 | AA3: 汇率 | AB3: 人民币 | AC3: 起运港+目的港
A4: JOB020137 | B4: COLL003812 | C4: 240125000046 | D4: 45324 | E4: ying | F4: peter | G4: 18 | H4: 2250 | N4: 2250 | O4: 3774 | P4: 富姐 | Q4: 2200 | S4: 0 | V4: 2224 | W4: 44.57 | Z4: 44.57 | AA4: 7.19 | AB4: 320.4583 | AC4: 2544.4583 | AD4: 1229.5417
C5: 240126000040 | D5: 45324 | E5: 喵喵速运-Layne | F5: Tia | G5: 2 | H5: 250 | N5: 250
C6: 240126000043 | D6: 45324 | E6: Sam.Pao | F6: David Zhao | G6: 8.5 | H6: 1062.5 | N6: 1062.5
C7: 240129000048 | D7: 45324 | E7: ying | F7: Sagamu | G7: 1.5 | H7: 211.5 | N7: 211.5 | U7: 24
A8: JOB020138 | B8: COLL003814 | C8: 240202000025 | D8: 45324 | E8: Sam.Pao | F8: Sampao | G8: 551 | H8: 27558 | N8: 27558 | O8: 27558 | P8: 顶派 | Q8: 41352 | V8: 41352 | W8: 497.42 | Z8: 497.42 | AA8: 7.19 | AB8: 3576.4498 | AC8: 44928.45 | AD8: -17370.45
A9: JOB020139 | B9: COLL003815 | C9: 240202000026 | D9: 45324 | E9: Sam.Pao | F9: Sampao | G9: 296 | H9: 14808 | N9: 14808 | O9: 14808 | V9: 0 | W9: 303.62 | X9: 3167 | Z9: 3470.62 | AA9: 7.19 | AB9: 24953.758 | AC9: 24953.758 | AD9: -10145.758
A10: JOB020140 | B10: COLL003817 | C10: 240126000027 | D10: 45325 | E10: ying | F10: xiongge | G10: 1.5 | H10: 0 | N10: 0 | O10: 24252.585 | P10: 富姐 | Q10: 11400 | S10: 205.43 | V10: 11605.43 | W10: 369.41 | Z10: 374.21 | AA10: 7.19 | AB10: 2690.5699 | AC10: 14296 | AD10: 9956.5847
C11: 240127000011 | D11: 45325 | E11: ying | F11: Steven Abuja | G11: 0.73 | I11: 27950 | K11: 1545.9071 | L11: 18.08 | M11: 7.19 | N11: 129.9952
C12: 240128000005 | D12: 45325 | E12: Julie LEE | F12: Julie lee | G12: 3 | H12: 390 | N12: 390
C13: 240129000036 | D13: 45325 | E13: 易小羔 | F13: Robin Tai | G13: 2 | H13: 250 | N13: 250
C14: 240129000037 | D14: 45325 | E14: 喵喵速运-Layne | F14: William Xu | G14: 0.6 | I14: 34880 | K14: 1567.6404 | L14: 22.25 | M14: 7.19 | N14: 159.9775
C15: 240129000039 | D15: 45325 | E15: ying | F15: xiongge | G15: 8 | I15: 215000 | K15: 1545.8729 | L15: 139.08 | M15: 7.19 | N15: 999.9852
C16: 240129000064 | D16: 45325 | E16: 喵喵速运-Layne | F16: GONG | G16: 20 | I16: 666500 | K16: 1545.8657 | L16: 431.15 | M16: 7.19 | N16: 3099.9685
C17: 240129000065 | D17: 45325 | E17: 喵喵速运-Layne | F17: GONG | G17: 20 | I17: 666500 | K17: 1545.8657 | L17: 431.15 | M17: 7.19 | N17: 3099.9685
C18: 240129000070 | D18: 45325 | E18: Bella Chan | F18: wang hong sheng | G18: 2.5 | I18: 68127.48 | K18: 1547.9999 | L18: 44.010002 | M18: 7.19 | N18: 316.43191
C19: 240129000073 | D19: 45325 | E19: ying | F19: felix | G19: 3 | H19: 410 | N19: 410 | X19: 4.8
C20: 240130000008 | D20: 45325 | E20: 喵喵速运-Layne | F20: MA ZONG | G20: 0.26 | H20: 130 | N20: 130
C21: 240130000025 | D21: 45325 | E21: Bella Chan | F21: chi de jian | G21: 0.38 | H21: 125 | N21: 125
C22: 240130000040 | D22: 45325 | E22: Sam.Pao | F22: Angel | G22: 7 | H22: 875 | N22: 875
C23: 240131000008 | D23: 45325 | E23: 喵喵速运-Layne | F23: Song Wen Tao | G23: 1.5 | I23: 65600 | K23: 1474.1573 | L23: 44.5 | M23: 7.19 | N23: 319.955
C24: 240131000013 | D24: 45325 | E24: Bella Chan | F24: Zhang cui | G24: 3 | H24: 219 | N24: 219
C25: 240131000023 | D25: 45325 | E25: ying | F25: xiongge | G25: 3 | I25: 90625 | K25: 1737.7756 | L25: 52.15 | M25: 7.19 | N25: 374.9585
C26: 240131000026 | D26: 45325 | E26: 喵喵速运-Layne | F26: GONG | G26: 7.5 | I26: 267375 | K26: 1653.7296 | L26: 161.68 | M26: 7.19 | N26: 1162.4792
C27: 240131000029 | D27: 45325 | E27: 喵喵速运-Layne | F27: GONG | G27: 7.5 | I27: 249937.5 | K27: 1545.8777 | L27: 161.68 | M27: 7.19 | N27: 1162.4792
C28: 240131000030 | D28: 45325 | E28: 喵喵速运-Layne | F28: GONG | G28: 7.5 | I28: 249937.5 | K28: 1545.8777 | L28: 161.68 | M28: 7.19 | N28: 1162.4792
C29: 240131000035 | D29: 45325 | E29: 喵喵速运-Layne | F29: Guo Hui 郭总 | G29: 1 | I29: 50640 | K29: 1517.5307 | L29: 33.37 | M29: 7.19 | N29: 239.9303
C30: 240131000040 | D30: 45325 | E30: Sam.Pao | F30: Angel | G30: 1 | H30: 125 | N30: 125
C31: 240131000041 | D31: 45325 | E31: 易小羔 | F31: yuanbiao | G31: 13 | H31: 1690 | N31: 1690
C32: 240131000045 | D32: 45325 | E32: Bella Chan | F32: tang qiao lin | G32: 1.5 | I32: 86000 | K32: 1545.9285 | L32: 55.63 | M32: 7.19 | N32: 399.9797
C33: 240131000047 | D33: 45325 | E33: 易小羔 | F33: PAN | G33: 11.5 | I33: 294687.5 | K33: 1473.9534 | L33: 199.93 | M33: 7.19 | N33: 1437.4967
C34: 240131000052 | D34: 45325 | E34: ying | F34: mr | G34: 7.5 | H34: 1127.5 | N34: 1127.5
C35: 240201000002 | D35: 45325 | E35: Isabel Zhu | F35: Long Er | G35: 4 | H35: 520 | N35: 520
C36: 240201000016 | D36: 45325 | E36: 易小羔 | F36: laohuang | G36: 4.5 | H36: 562.5 | N36: 562.5
C37: 240201000035 | D37: 45325 | E37: 易小羔 | F37: zhouyicheng | G37: 4 | H37: 520 | N37: 520
C38: 240202000012 | D38: 45325 | E38: 喵喵速运-Layne | F38: Lee Wen Wei | G38: 3 | H38: 375 | N38: 375
C39: 240202000020 | D39: 45325 | E39: ying | F39: Chinex | G39: 18.5 | H39: 2867.5 | N39: 2867.5
A40: JOB020141 | B40: COLL003819 | C40: 240202000041 | D40: 45326 | E40: 喵喵速运-Layne | F40: NENG SHI | G40: 0.812 | H40: 2278 | N40: 2278 | O40: 4870 | P40: 捷道 | Q40: 3386.8 | V40: 3386.8 | Z40: 0 | AB40: 0 | AC40: 3386.8 | AD40: 1483.2
...

Sheet 3月份
A1: 尼日利亚拉各斯（LOS） 应收利润明细表
A2: JOB | B2: 集装编号 | C2: 运单编号 | D2: 日期 | E2: 发货人 | F2: 收货人 | G2: 计费重量 | H2: 应 收 | O2: 总应收 | P2: 起 运 港 成 本 | U2: 代垫运费 | V2: 起运港成本 合计 | W2: 目的港成本 | AC2: 总支出 | AD2: 利润
H3: 应收RMB | I3: LOS Income(NGN) 收到(奈拉) | J3: LOS 收到USD | K3: 美元汇率 dollar currency rate | L3: 应收 到付款USD | M3: 汇率 | N3: 人民币 | P3: 代理商 | Q3: 运费 | R3: 提货费 | S3: 送货费 | T3: 包装费 | W3: 进口报关费 | X3: 到门配送费 | Y3: 转运费 | Z3: 目的港支出 | AA3: 汇率 | AB3: 人民币 | AC3: 起运港+目的港
A4: JOB030324 | B4: COLL003836 | C4: 240220000004 | D4: 45353 | E4: Bella Chan | F4: li tao | G4: 1.5 | H4: 88.2 | N4: 88.2 | O4: 80342.69 | P4: 顶派 | Q4: 63773.2 | S4: 125 | V4: 64800.2 | W4: 1114.79 | Z4: 1114.79 | AA4: 7.19 | AB4: 8015.3401 | AC4: 72815.54 | AD4: 7527.1495
C5: 240220000041 | D5: 45353 | E5: Isabel Zhu | F5: Emmanuel | G5: 0.97 | H5: 125 | N5: 125
C6: 240221000024 | D6: 45353 | E6: 喵喵速运-Layne | F6: Mr.Cheng | G6: 78.5 | I6: 769350 | K6: 1603.3804 | L6: 479.83 | M6: 7.19 | N6: 3449.9777
C7: 240222000009 | D7: 45353 | E7: ying | F7: chuks | G7: 281 | I7: 3822220 | K7: 1603.3744 | L7: 2383.86 | M7: 7.19 | N7: 17139.953 | T7: 280
C8: 240223000006 | D8: 45353 | E8: 喵喵速运-Layne | F8: Wang Jiu Lin | G8: 31 | H8: 1981.2 | N8: 1981.2 | T8: 160
C9: 240223000009 | D9: 45353 | E9: Mikey | F9: Chenyun | G9: 6 | H9: 324 | N9: 324
C10: 240223000010 | D10: 45353 | E10: Mikey | F10: SIMON OMALE | G10: 6.5 | H10: 397.2 | N10: 397.2
C11: 240223000011 | D11: 45353 | E11: ying | F11: qianqian | G11: 10 | H11: 588 | N11: 588
C12: 240223000018 | D12: 45353 | E12: Isabel Zhu | F12: Colin | G12: 33.5 | I12: 395664 | K12: 1600 | L12: 247.29 | M12: 7.19 | N12: 1778.0151
C13: 240223000020 | D13: 45353 | E13: Mikey | F13: Blessing | G13: 56.5 | H13: 3729 | N13: 3729
C14: 240224000001 | D14: 45353 | E14: Isabel Zhu | F14: Lisa | G14: 9 | H14: 547 | N14: 547
C15: 240224000004 | D15: 45353 | E15: Isabel Zhu | F15: Sesan | G15: 30 | H15: 1671 | N15: 1671
C16: 240224000007 | D16: 45353 | E16: Isabel Zhu | F16: Joy | G16: 15 | I16: 240000 | K16: 1600 | L16: 150 | M16: 7.19 | N16: 1078.5
C17: 240226000002 | D17: 45353 | E17: Isabel Zhu | F17: Lynda | G17: 31 | H17: 1646 | N17: 1646 | U17: 65
C18: 240226000003 | D18: 45353 | E18: Isabel Zhu | F18: Wu Jiao Xing | G18: 0.36 | H18: 60 | N18: 60
C19: 240226000004 | D19: 45353 | E19: Isabel Zhu | F19: Shan Nan | G19: 6 | H19: 378 | N19: 378
C20: 240226000010 | D20: 45353 | E20: 喵喵速运-Layne | F20: Yang Peng Tao | G20: 2 | I20: 27875 | K20: 1603.855 | L20: 17.38 | M20: 7.19 | N20: 124.9622
C21: 240226000026 | D21: 45353 | E21: MailMail速运 | F21: chen a tong | G21: 8.5 | H21: 456 | N21: 456
C22: 240226000027 | D22: 45353 | E22: MailMail速运 | F22: John 张 | G22: 3 | H22: 194.4 | N22: 194.4
C23: 240226000044 | D23: 45353 | E23: ying | F23: Chinex | G23: 408.5 | H23: 21026.25 | N23: 21026.25 | U23: 397
C24: 240227000009 | D24: 45353 | E24: ying | F24: Wu Zhe | G24: 10 | H24: 535.2 | N24: 535.2
C25: 240227000015 | D25: 45353 | E25: Isabel Zhu | F25: Shan Nan | G25: 1.5 | I25: 19968 | K25: 1600 | L25: 12.48 | M25: 7.19 | N25: 89.7312
C26: 240227000020 | D26: 45353 | E26: Sam.Pao | F26: Nkechi | G26: 115.5 | H26: 5297.5 | N26: 5297.5
C27: 240227000030 | D27: 45353 | E27: 喵喵速运-Layne | F27: Zhang Guo Ren | G27: 2 | H27: 135.8 | N27: 135.8
C28: 240227000032 | D28: 45353 | E28: Isabel Zhu | F28: Halifa Success | G28: 1.5 | H28: 147 | N28: 147
C29: 240227000033 | D29: 45353 | E29: Isabel Zhu | F29: Halifa Success | G29: 3 | H29: 172.8 | N29: 172.8
C30: 240301000026 | D30: 45353 | E30: Sam.Pao | F30: SKY JET | G30: 390.5 | H30: 17182 | N30: 17182
A31: JOB030325 | B31: COLL003838 | C31: 240223000030 | D31: 45353 | E31: Sam.Pao | F31: MR HE | G31: 4.5 | I31: 121696 | K31: 1600 | L31: 76.06 | M31: 7.19 | N31: 546.8714 | O31: 8365.283 | P31: 富姐 | Q31: 4400 | S31: 68.81 | V31: 4486.81 | W31: 172.57 | Z31: 172.57 | AA31: 7.19 | AB31: 1240.7783 | AC31: 5727.5883 | AD31: 2637.6947
C32: 240226000015 | D32: 45353 | E32: 喵喵速运-Layne | F32: Cheng | G32: 4.5 | H32: 1035 | N32: 1035
C33: 240227000005 | D33: 45353 | E33: Isabel Zhu | F33: Long Er | G33: 2.5 | H33: 300 | N33: 300
C34: 240227000011 | D34: 45353 | E34: ying | F34: Shang yafei | G34: 25.5 | H34: 3060 | N34: 3060
C35: 240227000022 | D35: 45353 | E35: Bella Chan | F35: han bin | G35: 0.52 | H35: 180 | N35: 180
C36: 240227000023 | D36: 45353 | E36: Bella Chan | F36: Eric Qu | G36: 2 | H36: 290 | N36: 290
C37: 240227000024 | D37: 45353 | E37: 喵喵速运-Layne | F37: Ke Ren | G37: 3.5 | H37: 391 | N37: 391
C38: 240227000031 | D38: 45353 | F38: Jinggang Pan | G38: 3.5 | I38: 90704 | K38: 1599.9999 | L38: 56.690002 | M38: 7.19 | N38: 407.60111
C39: 240227000034 | D39: 45353 | E39: Sam.Pao | F39: YunLong Hu | G39: 15 | I39: 388720 | K39: 1600 | L39: 242.95 | M39: 7.19 | N39: 1746.8105
C40: 240228000025 | D40: 45353 | E40: Sam.Pao | F40: MaiKaiNian | G40: 1.5 | H40: 235.5 | N40: 235.5 | U40: 18
...

Sheet 4月份
A1: 尼日利亚拉各斯（LOS） 应收利润明细表
A2: JOB | B2: 集装编号 | C2: 运单编号 | D2: 日期 | E2: 发货人 | F2: 收货人 | G2: 计费重量 | H2: 应 收 | O2: 总应收 | P2: 起 运 港 成 本 | U2: 代垫运费 | V2: 起运港成本 合计 | W2: 目的港成本 | AC2: 总支出 | AD2: 利润
H3: 应收RMB | I3: LOS Income(NGN) 收到(奈拉) | J3: LOS 收到USD | K3: 美元汇率 dollar currency rate | L3: 应收 到付款USD | M3: 汇率 | N3: 人民币 | P3: 代理商 | Q3: 运费 | R3: 提货费 | S3: 送货费 | T3: 包装费 | W3: 进口报关费 | X3: 到门配送费 | Y3: 转运费 | Z3: 目的港支出 | AA3: 汇率 | AB3: 人民币 | AC3: 起运港+目的港
A4: JOB040316 | B4: COLL003887 | C4: 240326000032 | D4: 45383 | E4: 喵喵速运-Layne | F4: William Xu | G4: 16.5 | I4: 312840 | K4: 1142.3772 | L4: 273.85 | M4: 7.23 | N4: 1979.9355 | O4: 4182.9204 | P4: 富姐 | Q4: 2200 | S4: 68.81 | V4: 2268.81 | W4: 57.01 | Z4: 57.01 | AA4: 7.23 | AB4: 412.1823 | AC4: 2680.9923 | AD4: 1501.9281
C5: 240328000011 | D5: 45383 | E5: Sam.Pao | F5: Jhon | G5: 11 | I5: 260590 | L5: 174.96 | M5: 7.23 | N5: 1264.9608
C6: 240329000017 | D6: 45383 | E6: Isabel Zhu | F6: Long Er | G6: 2.5 | H6: 300 | N6: 300
C7: 240329000024 | D7: 45383 | E7: ying | F7: luzong | G7: 4.5 | H7: 517.5 | N7: 517.5
C8: 240331000001 | D8: 45383 | E8: Bella Chan | F8: zhang jian fei | G8: 0.24933334 | I8: 22505 | L8: 16.67 | M8: 7.23 | N8: 120.5241
A9: JOB040317 | B9: COLL003882 | C9: 240324000003 | D9: 45383 | E9: ying | F9: Shijianguo | G9: 39 | H9: 2028 | N9: 2028 | O9: 101407.31 | P9: 顶派=80256 广州通达=3039.4 | Q9: 83295.4 | R9: 85.35 | S9: 217.54 | V9: 84738.29 | W9: 1563.98 | Z9: 1563.98 | AA9: 7.23 | AB9: 11307.575 | AC9: 96045.865 | AD9: 5361.4451
C10: 240325000034 | D10: 45383 | E10: Bella Chan | F10: huang peng | G10: 55 | H10: 2758 | N10: 2758
C11: 240325000037 | D11: 45383 | E11: ying | F11: wangweijun | G11: 5.5 | I11: 55907 | K11: 1323.2426 | L11: 42.25 | M11: 7.23 | N11: 305.4675
C12: 240325000038 | D12: 45383 | E12: ying | F12: lituo | G12: 7 | H12: 412 | N12: 412
C13: 240325000039 | D13: 45383 | E13: ying | F13: Huangpu | G13: 81 | I13: 615195 | K13: 1120.6554 | L13: 548.96 | M13: 7.23 | N13: 3968.9808
C14: 240325000043 | D14: 45383 | E14: dejare James | F14: Adam e | G14: 2.5 | I14: 24885 | K14: 1260 | L14: 19.75 | M14: 7.23 | N14: 142.7925
C15: 240326000012 | D15: 45383 | E15: Bella Chan | F15: los徐周鹏 | G15: 104 | I15: 982232.8 | K15: 1360 | L15: 722.23 | M15: 7.23 | N15: 5221.7229
C16: 240326000013 | D16: 45383 | E16: 喵喵速运-Layne | F16: ZHENWEI YUE | G16: 54.5 | I16: 422375 | K16: 1120.6553 | L16: 376.9 | M16: 7.23 | N16: 2724.987
C17: 240326000015 | D17: 45383 | E17: ying | F17: zhangjingcheng | G17: 7.5 | H17: 396 | N17: 396
C18: 240326000016 | D18: 45383 | E18: ying | F18: FeLiX | G18: 4 | H18: 200 | N18: 200
C19: 240326000017 | D19: 45383 | E19: Bella Chan | F19: Chi de jian | G19: 701.5 | H19: 33620.5 | N19: 33620.5 | U19: 650
C20: 240326000024 | D20: 45383 | E20: Isabel Zhu | F20: Shen Zhuo Wei | G20: 4 | H20: 223 | N20: 223
C21: 240326000030 | D21: 45383 | E21: 喵喵速运-Layne | F21: Spring 盛世飞扬 | G21: 3 | H21: 141 | N21: 141
C22: 240327000003 | D22: 45383 | E22: 喵喵速运-Layne | F22: ABV 胡立新 | G22: 2 | H22: 125 | N22: 125
C23: 240327000004 | D23: 45383 | E23: 喵喵速运-Layne | F23: Tuntex | G23: 4 | I23: 39438 | L23: 31.3 | M23: 7.23 | N23: 226.299
C24: 240327000009 | D24: 45383 | E24: 喵喵速运-Layne | F24: Zhao Xin | G24: 4 | H24: 247 | N24: 247
C25: 240327000010 | D25: 45383 | E25: Isabel Zhu | F25: Ope Olofinjana | G25: 0.86 | I25: 10340.2 | K25: 1261 | L25: 8.2 | M25: 7.23 | N25: 59.286
C26: 240327000011 | D26: 45383 | E26: Bella Chan | F26: fang ming | G26: 9.5 | H26: 522.5 | N26: 522.5
C27: 240327000015 | D27: 45383 | E27: ying | F27: Mr.Kola | G27: 173 | H27: 8827 | N27: 8827 | U27: 350
C28: 240327000017 | D28: 45383 | E28: ying | F28: xiaosichaoshi | G28: 0.43 | H28: 58 | N28: 58
C29: 240327000018 | D29: 45383 | E29: 喵喵速运-Layne | F29: REMI | G29: 4.5 | I29: 34618.5 | K29: 1135.4051 | L29: 30.49 | M29: 7.23 | N29: 220.4427
C30: 240327000021 | D30: 45383 | E30: ying | F30: abu | G30: 6.5 | H30: 344 | N30: 344
C31: 240327000032 | D31: 45383 | E31: Bella Chan | F31: james | G31: 87 | I31: 756378 | K31: 1260 | L31: 600.3 | M31: 7.23 | N31: 4340.169
C32: 240328000002 | D32: 45383 | E32: clarkzeng2 | F32: zengyugui | G32: 27.5 | H32: 1521.5 | N32: 1521.5
C33: 240328000004 | D33: 45383 | E33: ying | F33: Cindy | G33: 4 | H33: 223 | N33: 223
C34: 240328000005 | D34: 45383 | E34: 喵喵速运-Layne | F34: William Xu | G34: 19 | I34: 212135 | K34: 1467.7576 | L34: 144.53 | M34: 7.23 | N34: 1044.9519
C35: 240328000009 | D35: 45383 | E35: ying | F35: zoukai | G35: 18 | H35: 1100 | N35: 1100 | T35: 50
C36: 240328000010 | D36: 45383 | E36: ying | F36: mr | G36: 5 | H36: 278 | N36: 278
C37: 240328000012 | D37: 45383 | E37: Sam.Pao | F37: Jhon | G37: 20.5 | I37: 231750 | L37: 155.6 | M37: 7.23 | N37: 1124.988
C38: 240328000014 | D38: 45383 | E38: Mikey | F38: chenxiaoru | G38: 38 | H38: 1859 | N38: 1859
C39: 240328000018 | D39: 45383 | E39: 喵喵速运-Layne | F39: fast hours DM NIGHT LED | G39: 4.5 | I39: 43086 | K39: 1243.8222 | L39: 34.64 | M39: 7.23 | N39: 250.4472
C40: 240328000025 | D40: 45383 | E40: Sam.Pao | F40: XiongQiJun | G40: 5 | H40: 278 | N40: 278
...

Sheet 5月份
A1: 尼日利亚拉各斯（LOS） 应收利润明细表
A2: JOB | B2: 集装编号 | C2: 运单编号 | D2: 日期 | E2: 发货人 | F2: 收货人 | G2: 计费重量 | H2: 应 收 | O2: 总应收 | P2: 起 运 港 成 本 | U2: 代垫运费 | V2: 起运港成本 合计 | W2: 目的港成本 | AC2: 总支出 | AD2: 利润
H3: 应收RMB | I3: LOS Income(NGN) 收到(奈拉) | J3: LOS 收到USD | K3: 美元汇率 dollar currency rate | L3: 应收 到付款USD | M3: 汇率 | N3: 人民币 | P3: 代理商 | Q3: 运费 | R3: 提货费 | S3: 送货费 | T3: 包装费 | W3: 进口报关费 | X3: 到门配送费 | Y3: 转运费 | Z3: 目的港支出 | AA3: 汇率 | AB3: 人民币 | AC3: 起运港+目的港
A4: JOB050323 | B4: COLL003928 | C4: 240426000049 | D4: 45413 | E4: Isabel Zhu | F4: Kelly He | G4: 2.5 | H4: 287 | N4: 287 | O4: 4185.1776 | P4: 富姐 | Q4: 1600 | S4: 69.27 | V4: 1685.27 | W4: 77.9 | Z4: 77.9 | AA4: 7.22 | AB4: 562.438 | AC4: 2247.708 | AD4: 1937.4696
C5: 240428000011 | D5: 45413 | E5: 喵喵速运-Layne | F5: CHENG ZHONG | G5: 1.5 | I5: 32564 | K5: 1488.9803 | L5: 21.87 | M5: 7.22 | N5: 157.9014
C6: 240428000022 | D6: 45413 | E6: ying | F6: leoyang | G6: 2.5 | H6: 397 | N6: 397
C7: 240428000039 | D7: 45413 | E7: Bella Chan | F7: shangyafei | G7: 4 | H7: 472 | N7: 472
C8: 240428000047 | D8: 45413 | E8: 13635229849 | F8: weng zixian | G8: 0.98 | I8: 23540 | K8: 1412.9652 | L8: 16.66 | M8: 7.22 | N8: 120.2852
C9: 240429000016 | D9: 45413 | E9: ying | F9: IVAN | G9: 2.5 | I9: 59400 | K9: 1429.6029 | L9: 41.55 | M9: 7.22 | N9: 299.991
C10: 240429000022 | D10: 45413 | E10: Bella Chan | F10: YEMI | G10: 2.5 | H10: 303.5 | N10: 303.5 | U10: 16
C11: 240429000024 | D11: 45413 | E11: Bella Chan | F11: shangyafei | G11: 3 | H11: 360 | N11: 360
C12: 240430000004 | D12: 45413 | E12: Bella Chan | F12: huang peng | G12: 14.5 | H12: 1667.5 | N12: 1667.5
C13: 240430000027 | D13: 45413 | E13: Sam.Pao | F13: SHI | G13: 0.64 | H13: 120 | N13: 120
A14: JOB050324 | B14: COLL003920 | C14: 240423000032 | D14: 45413 | E14: 喵喵速运-Layne | F14: Brian | G14: 3 | I14: 37515 | K14: 1466.0023 | L14: 25.59 | M14: 7.22 | N14: 184.7598 | O14: 152511.02 | P14: 顶派 | Q14: 108643.8 | S14: 130 | V14: 109353.8 | W14: 2475.24 | Z14: 2481.47 | AA14: 7.22 | AB14: 17916.213 | AC14: 127270.01 | AD14: 25241.004
C15: 240423000041 | D15: 45413 | E15: 喵喵速运-Layne | F15: GONG | G15: 34.5 | H15: 1878.5 | N15: 1878.5 | T15: 50
C16: 240424000007 | D16: 45413 | E16: ying | F16: Ajibola Awojobi | G16: 171 | H16: 17756 | N16: 17756
C17: 240424000019 | D17: 45413 | E17: 喵喵速运-Layne | F17: Japhia 于佳慧 | G17: 3 | H17: 184.8 | N17: 184.8
C18: 240424000022 | D18: 45413 | E18: ying | F18: chenhuaping | G18: 10 | H18: 550 | N18: 550
C19: 240424000025 | D19: 45413 | E19: MailMail速运-演员 | F19: Steve | G19: 3 | H19: 184.8 | N19: 184.8
C20: 240424000027 | D20: 45413 | E20: ying | F20: kasle | G20: 0.32 | H20: 63.8 | N20: 63.8
C21: 240424000031 | D21: 45413 | E21: ying | F21: Effiong Okonessien | G21: 7.5 | H21: 565 | N21: 565 | T21: 30
C22: 240425000008 | D22: 45413 | E22: 喵喵速运-Layne | F22: Kola | G22: 10.5 | H22: 651 | N22: 651
C23: 240425000009 | D23: 45413 | E23: 喵喵速运-Layne | F23: Allen Answer | G23: 8 | H23: 464.2 | N23: 464.2
C24: 240425000014 | D24: 45413 | E24: 喵喵速运-Layne | F24: CHENG ZHONG | G24: 3 | I24: 38431 | K24: 1480.9634 | L24: 25.95 | M24: 7.22 | N24: 187.359
C25: 240425000016 | D25: 45413 | E25: Sam.Pao | F25: ShanShan | G25: 366 | H25: 26290 | N25: 26290 | T25: 400
C26: 240425000017 | D26: 45413 | E26: Isabel Zhu | F26: Mr Atama CSO | G26: 10 | H26: 700 | N26: 700
C27: 240425000018 | D27: 45413 | E27: ying | F27: Engr. Kola Balogun | G27: 3 | H27: 320 | N27: 320 | X27: 6.23
C28: 240425000019 | D28: 45413 | E28: Bella Chan | F28: zhang yong chong | G28: 0.89 | I28: 12950.53 | K28: 1466.6512 | L28: 8.83 | M28: 7.22 | N28: 63.7526
C29: 240425000027 | D29: 45413 | E29: Sam.Pao | F29: MR HU | G29: 92.5 | H29: 5596 | N29: 5596
C30: 240425000028 | D30: 45413 | E30: Sam.Pao | F30: ChenGaoHong | G30: 182.5 | H30: 10682.65 | N30: 10682.65 | T30: 50
C31: 240426000003 | D31: 45413 | E31: 喵喵速运-Layne | F31: fast hours DM NIGHT LED | G31: 7.5 | I31: 93415 | K31: 1465.1035 | L31: 63.76 | M31: 7.22 | N31: 460.3472
C32: 240426000014 | D32: 45413 | E32: 喵喵速运-Layne | F32: Lukas | G32: 3 | I32: 62496 | K32: 1516.5251 | L32: 41.21 | M32: 7.22 | N32: 297.5362
C33: 240426000018 | D33: 45413 | E33: 喵喵速运-Layne | F33: SHD-Egbe | G33: 68.5 | H33: 4110 | N33: 4110
C34: 240426000019 | D34: 45413 | E34: Sam.Pao | F34: Mr. Jiang | G34: 163 | H34: 13979 | N34: 13979
C35: 240426000020 | D35: 45413 | E35: Kaylee Tan | F35: EY | G35: 6.5 | H35: 508 | N35: 508
C36: 240426000023 | D36: 45413 | E36: Isabel Zhu | F36: Gao Yang | G36: 2 | H36: 158 | N36: 158
C37: 240426000029 | D37: 45413 | E37: 袁安医生 Dr. Andy | F37: Andy Yuan | G37: 10 | I37: 171678 | K37: 1481.0041 | L37: 115.92 | M37: 7.22 | N37: 836.9424
C38: 240426000032 | D38: 45413 | E38: 喵喵速运-Layne | F38: Hu Hai Liang | G38: 26 | I38: 392700 | K38: 1516.2162 | L38: 259 | M38: 7.22 | N38: 1869.98 | T38: 50
C39: 240426000033 | D39: 45413 | E39: Isabel Zhu | F39: Dou Dou | G39: 12.5 | H39: 762 | N39: 762
C40: 240426000035 | D40: 45413 | E40: Isabel Zhu | F40: Halifa Success | G40: 7.5 | H40: 561 | N40: 561
...

Sheet 6月份
A1: 尼日利亚拉各斯（LOS） 应收利润明细表
A2: JOB | B2: 集装编号 | C2: 运单编号 | D2: 日期 | E2: 发货人 | F2: 收货人 | G2: 计费重量 | H2: 应 收 | O2: 总应收 | P2: 起 运 港 成 本 | U2: 代垫运费 | V2: 起运港成本 合计 | W2: 目的港成本 | AC2: 总支出 | AD2: 利润
H3: 应收RMB | I3: LOS Income(NGN) 收到(奈拉) | J3: LOS 收到USD | K3: 美元汇率 dollar currency rate | L3: 应收 到付款USD | M3: 汇率 | N3: 人民币 | P3: 代理商 | Q3: 运费 | R3: 提货费 | S3: 送货费 | T3: 包装费 | W3: 进口报关费 | X3: 到门配送费 | Y3: 转运费 | Z3: 目的港支出 | AA3: 汇率 | AB3: 人民币 | AC3: 起运港+目的港
A4: JOB060330 | B4: COLL003976 | C4: 240529000001 | D4: 45447 | E4: Julie LEE | F4: Julie lee | G4: 1.5 | H4: 180 | N4: 180 | O4: 4233.4424 | P4: 富姐 | Q4: 2400 | R4: 52.41 | V4: 2482.41 | W4: 37.28 | Z4: 37.28 | AA4: 7.24 | AB4: 269.9072 | AC4: 2752.3172 | AD4: 1481.1252
C5: 240529000005 | D5: 45447 | E5: Isabel Zhu | F5: Li Chuan Qiang | G5: 0.6 | H5: 250 | N5: 250
C6: 240530000014 | D6: 45447 | E6: Bella Chan | F6: YEMI | G6: 3.5 | H6: 402.5 | N6: 402.5
C7: 240530000019 | D7: 45447 | E7: Isabel Zhu | F7: Emmanuel Folu | G7: 0.66 | I7: 23920 | K7: 1506.2972 | L7: 15.88 | M7: 7.24 | N7: 114.9712
C8: 240530000026 | D8: 45447 | E8: 喵喵速运-Layne | F8: WEI PING | G8: 6 | H8: 690 | N8: 690
C9: 240531000014 | D9: 45447 | E9: ying | F9: yuwang | G9: 3 | H9: 375 | N9: 375 | T9: 30
C10: 240531000042 | D10: 45447 | E10: ying | F10: leoyang | G10: 0.2 | H10: 115 | N10: 115
C11: 240601000003 | D11: 45447 | E11: Isabel Zhu | F11: Mr Q | G11: 18 | I11: 430560 | K11: 1480.198 | L11: 290.88 | M11: 7.24 | N11: 2105.9712
A12: JOB060332 | B12: COLL003978 | C12: 240527000014 | D12: 45449 | E12: ying | F12: Sunday Adelena | G12: 725 | H12: 40025 | N12: 40025 | O12: 171150.17 | P12: 顶派 | Q12: 130662 | S12: 320.61 | T12: 150 | V12: 132715.61 | W12: 2144.68 | Z12: 2144.68 | AA12: 7.24 | AB12: 15527.483 | AC12: 148243.09 | AD12: 22907.082
C13: 240531000007 | D13: 45449 | E13: 喵喵速运-Layne | F13: Lin Qing Yuan | G13: 333.5 | I13: 3711855 | K13: 1520.4046 | L13: 2441.36 | M13: 7.24 | N13: 17675.446
C14: 240531000027 | D14: 45449 | E14: 喵喵速运-Layne | F14: ZHENWEI YUE | G14: 38 | I14: 416898 | K14: 1498.7166 | L14: 278.17 | M14: 7.24 | N14: 2013.9508
C15: 240531000037 | D15: 45449 | E15: Bella Chan | F15: los徐周鹏 | G15: 39 | I15: 487872 | K15: 1584 | L15: 308 | M15: 7.24 | N15: 2229.92 | T15: 80
C16: 240531000044 | D16: 45449 | E16: 喵喵速运-Layne | F16: MA ZONG | G16: 5 | H16: 290 | N16: 290
C17: 240601000006 | D17: 45449 | E17: Isabel Zhu | F17: Zhou Jia Liang | G17: 5.5 | H17: 322 | N17: 322
C18: 240601000011 | D18: 45449 | E18: 喵喵速运-Layne | F18: Mr.Cheng | G18: 1 | H18: 53 | N18: 53
C19: 240601000012 | D19: 45449 | E19: Anny | F19: Anny | G19: 2 | H19: 119 | N19: 119
C20: 240602000002 | D20: 45449 | E20: 东东 | F20: Yang | G20: 0.62 | H20: 67 | N20: 67
C21: 240602000003 | D21: 45449 | E21: 东东 | F21: Yang | G21: 2.5 | H21: 163 | N21: 163
C22: 240602000005 | D22: 45449 | E22: 喵喵速运-Layne | F22: Amy | G22: 31.5 | I22: 345586.5 | K22: 1498.7055 | L22: 230.59 | M22: 7.24 | N22: 1669.4716
C23: 240602000011 | D23: 45449 | E23: 喵喵速运-Layne | F23: Li Ce | G23: 1.5 | H23: 138 | N23: 138 | U23: 13
C24: 240602000013 | D24: 45449 | E24: 喵喵速运-Layne | F24: ZHENWEI YUE | G24: 0.92 | I24: 10971 | K24: 1498.7705 | L24: 7.32 | M24: 7.24 | N24: 52.9968
C25: 240603000013 | D25: 45449 | E25: Sam.Pao | F25: WuTao | G25: 1756 | H25: 91396 | N25: 91396 | T25: 1490
C26: 240603000016 | D26: 45449 | E26: 喵喵速运-Layne | F26: REMI | G26: 116.5 | I26: 1346041 | K26: 1578.3228 | L26: 852.83 | M26: 7.24 | N26: 6174.4892
C27: 240603000028 | D27: 45449 | E27: Isabel Zhu | F27: Halifa Success | G27: 159 | H27: 8760.9 | N27: 8760.9
A28: JOB060333 | B28: COLL003982 | C28: 240530000023 | D28: 45450 | E28: Isabel Zhu | F28: Musa Mohammed | G28: 0.92 | H28: 145 | N28: 145 | O28: 4875.118 | P28: 富姐 | Q28: 2400 | S28: 54.77 | V28: 2454.77 | W28: 130.24 | Z28: 130.24 | AA28: 7.24 | AB28: 942.9376 | AC28: 3397.7076 | AD28: 1477.4104
C29: 240531000008 | D29: 45450 | E29: 喵喵速运-Layne | F29: LUO XIANG DONG | G29: 3.5 | H29: 417.5 | N29: 417.5
C30: 240602000004 | D30: 45450 | E30: Paul | F30: Paul | G30: 3 | I30: 75100 | K30: 1502 | L30: 50 | M30: 7.24 | N30: 362
C31: 240602000008 | D31: 45450 | E31: 喵喵速运-Layne | F31: William Xu | G31: 0.62 | I31: 36320 | K31: 1644.1829 | L31: 22.09 | M31: 7.24 | N31: 159.9316
C32: 240602000009 | D32: 45450 | E32: Julie LEE | F32: Julie lee | G32: 6.5 | H32: 780 | N32: 780
C33: 240604000011 | D33: 45450 | E33: ying | F33: leoyang | G33: 4.5 | H33: 517.5 | N33: 517.5
C34: 240604000021 | D34: 45450 | E34: Bella Chan | F34: YEMI | G34: 0.67 | H34: 115 | N34: 115
C35: 240604000029 | D35: 45450 | E35: ying | F35: weixiangmin | G35: 0.14 | H35: 120 | N35: 120
C36: 240605000026 | D36: 45450 | E36: Bella Chan | F36: zheng xian sheng | G36: 2.5 | H36: 990 | N36: 990
C37: 240606000010 | D37: 45450 | E37: 鸿 | F37: Mr.Leo | G37: 5 | I37: 119949.72 | K37: 1502 | L37: 79.86 | M37: 7.24 | N37: 578.1864
C38: 240606000013 | D38: 45450 | E38: MailMail速运-演员 | F38: Chuanwei | G38: 6 | H38: 690 | N38: 690
A39: JOB060334 | B39: COLL003983 | C39: 240605000039 | D39: 45451 | E39: Isabel Zhu | F39: luka | G39: 0.44 | I39: 31050 | K39: 1499.2757 | L39: 20.71 | M39: 7.24 | N39: 149.9404 | O39: 4614.9404 | P39: 富姐 | Q39: 2400 | S39: 54.19 | V39: 2454.19 | W39: 123.17 | Z39: 123.17 | AA39: 7.24 | AB39: 891.7508 | AC39: 3345.9408 | AD39: 1268.9996
C40: 240605000047 | D40: 45451 | E40: 喵喵速运-Layne | F40: Lee Wen Wei | G40: 8.5 | H40: 1600 | N40: 1600
...

Sheet 7月份
A1: 尼日利亚拉各斯（LOS） 应收利润明细表
A2: JOB | B2: 集装编号 | C2: 运单编号 | D2: 日期 | E2: 发货人 | F2: 收货人 | G2: 计费重量 | H2: 应 收 | O2: 总应收 | P2: 起 运 港 成 本 | U2: 代垫运费 | V2: 起运港成本 合计 | W2: 目的港成本 | AC2: 总支出 | AD2: 利润
H3: 应收RMB | I3: LOS Income(NGN) 收到(奈拉) | J3: LOS 收到USD | K3: 美元汇率 dollar currency rate | L3: 应收 到付款USD | M3: 汇率 | N3: 人民币 | P3: 代理商 | Q3: 运费 | R3: 提货费 | S3: 送货费 | T3: 包装费 | W3: 进口报关费 | X3: 到门配送费 | Y3: 转运费 | Z3: 目的港支出 | AA3: 汇率 | AB3: 人民币 | AC3: 起运港+目的港
A4: JOB070339 | B4: COLL004040 | C4: 240626000043 | D4: 45477 | E4: Sam.Pao | F4: ShanShan | G4: 0.56 | H4: 115 | N4: 115 | O4: 9541.5796 | P4: 富姐 | Q4: 5000 | S4: 113.54 | V4: 5113.54 | W4: 220.25 | Z4: 231.25 | AA4: 7.26 | AB4: 1678.875 | AC4: 6792.415 | AD4: 2749.1646
C5: 240627000010 | D5: 45477 | E5: 喵喵速运-Layne | F5: Li 明亮 | G5: 13 | I5: 363285 | K5: 1764.2045 | L5: 205.92 | M5: 7.26 | N5: 1494.9792
C6: 240627000012 | D6: 45477 | E6: 喵喵速运-Layne | F6: Rose 徐艳秋 | G6: 1.5 | I6: 38100 | K6: 1536.91 | L6: 24.79 | M6: 7.26 | N6: 179.9754
C7: 240628000026 | D7: 45477 | E7: ying | F7: luzong | G7: 3 | H7: 515 | N7: 515 | X7: 11
C8: 240628000034 | D8: 45477 | E8: Bella Chan | F8: Henry Yu | G8: 2.5 | H8: 300 | N8: 300
C9: 240628000039 | D9: 45477 | E9: Bella Chan | F9: fang ming | G9: 3.5 | H9: 420 | N9: 420
C10: 240628000041 | D10: 45477 | E10: JiaFeng | F10: jiafeng | G10: 3 | I10: 72170 | K10: 1506.0518 | L10: 47.92 | M10: 7.26 | N10: 347.8992
C11: 240630000004 | D11: 45477 | E11: 鸿 | F11: Mr.Leo | G11: 6 | I11: 144319.98 | K11: 1506 | L11: 95.83 | M11: 7.26 | N11: 695.7258
C12: 240701000001 | D12: 45477 | E12: MailMail速运-演员 | F12: chen a tong | G12: 0.1 | H12: 120 | N12: 120
C13: 240701000012 | D13: 45477 | E13: Isabel Zhu | F13: Long Er | G13: 2.5 | H13: 300 | N13: 300
C14: 240701000039 | D14: 45477 | E14: Isabel Zhu | F14: Sadiq bangaje | G14: 0.37 | H14: 120 | N14: 120
C15: 240701000040 | D15: 45477 | E15: Sam.Pao | F15: Mr Guan | G15: 2 | H15: 310 | N15: 310
C16: 240701000051 | D16: 45477 | E16: Sam.Pao | F16: SHI | G16: 19 | H16: 2280 | N16: 2280
C17: 240701000057 | D17: 45477 | E17: Sam.Pao | F17: ChenBin | G17: 1 | H17: 123 | N17: 123
C18: 240702000015 | D18: 45477 | E18: Isabel Zhu | F18: KeKe | G18: 0.89416665 | H18: 120 | N18: 120
C19: 240702000025 | D19: 45477 | E19: 喵喵速运-Layne | F19: Jack | G19: 9.5 | H19: 2100 | N19: 2100
A20: JOB070340 | B20: COLL004035 | C20: 240625000028 | D20: 45477 | E20: Bella Chan | F20: huang peng | G20: 10 | H20: 576 | N20: 576 | O20: 122449.58 | P20: 顶派=93163 广州通达=5204.2 | Q20: 98367.2 | S20: 239.19 | V20: 99816.39 | W20: 1201.83 | Z20: 1251.76 | AA20: 7.26 | AB20: 9087.7776 | AC20: 108904.17 | AD20: 13545.408
C21: 240625000037 | D21: 45477 | E21: Sam.Pao | F21: MaiKaiNian | G21: 31 | H21: 1713 | N21: 1713
C22: 240625000042 | D22: 45477 | E22: ying | F22: liangyu | G22: 8.5 | H22: 490.5 | N22: 490.5
C23: 240625000046 | D23: 45477 | E23: Bella Chan | F23: huang | G23: 5.5 | H23: 333 | N23: 333
C24: 240626000007 | D24: 45477 | E24: Bella Chan | F24: Zou Qiyang | G24: 10.5 | H24: 630 | N24: 630
C25: 240626000008 | D25: 45477 | E25: 喵喵速运-Layne | F25: Lin Kai | G25: 74 | H25: 350 | K25: 0 | L25: 564.73 | M25: 7.26 | N25: 4449.9398 | T25: 30
C26: 240626000024 | D26: 45477 | E26: Isabel Zhu | F26: Ope Olofinjana | G26: 0.26 | I26: 14062.4 | K26: 1598 | L26: 8.8 | M26: 7.26 | N26: 63.888
C27: 240626000028 | D27: 45477 | E27: Bella Chan | F27: Los王红升 | G27: 6.5 | I27: 89077 | K27: 1704.823 | L27: 52.25 | M27: 7.26 | N27: 379.335 | X27: 3.79
C28: 240626000031 | D28: 45477 | E28: 喵喵速运-Layne | F28: OTW 埃德维 | G28: 1.5 | H28: 132.5 | N28: 132.5
C29: 240626000034 | D29: 45477 | E29: ying | F29: wangweijun | G29: 0.6586667 | I29: 13850 | K29: 1597.4625 | L29: 8.67 | M29: 7.26 | N29: 62.9442
C30: 240626000036 | D30: 45477 | E30: ying | F30: yingyunjiao | G30: 4 | H30: 267 | N30: 267
C31: 240626000042 | D31: 45477 | E31: 土狗泥 | F31: TOYIN S.ADEKUNLE | G31: 9.5 | H31: 602.25 | N31: 602.25
C32: 240627000001 | D32: 45477 | E32: 东东 | F32: Yang | G32: 0.32 | H32: 69 | N32: 69
C33: 240627000006 | D33: 45477 | E33: Isabel Zhu | F33: Ope Olofinjana | G33: 0.52 | I33: 14062.4 | K33: 1598 | L33: 8.8 | M33: 7.26 | N33: 63.888
C34: 240627000008 | D34: 45477 | E34: 喵喵速运-Layne | F34: SHAEK | G34: 0.62 | H34: 55 | N34: 55
C35: 240627000011 | D35: 45477 | E35: 喵喵速运-Layne | F35: William Xu | G35: 15.5 | I35: 211110 | K35: 1643.5189 | L35: 128.45 | M35: 7.26 | N35: 932.547
C36: 240627000013 | D36: 45477 | E36: 喵喵速运-Layne | F36: Robin Tai | G36: 10 | H36: 576 | N36: 576
C37: 240627000014 | D37: 45477 | E37: 喵喵速运-Layne | F37: Mr.Bernie | G37: 0.62 | I37: 15525 | K37: 1634.2105 | L37: 9.5 | M37: 7.26 | N37: 68.97
C38: 240627000015 | D38: 45477 | E38: ying | F38: huangdan | G38: 0.2 | H38: 63 | N38: 63
C39: 240627000016 | D39: 45477 | E39: 喵喵速运-Layne | F39: Hu Hai Liang | G39: 64 | I39: 862400 | K39: 1778.7311 | L39: 484.84 | M39: 7.26 | N39: 3519.9384
C40: 240627000020 | D40: 45477 | E40: ying | F40: Hillter | G40: 1.5 | H40: 82.5 | N40: 82.5
...

Sheet 8月份
A1: 尼日利亚拉各斯（LOS） 应收利润明细表
A2: JOB | B2: 集装编号 | C2: 运单编号 | D2: 日期 | E2: 发货人 | F2: 收货人 | G2: 计费重量 | H2: 应 收 | O2: 总应收 | P2: 起 运 港 成 本 | U2: 代垫运费 | V2: 起运港成本 合计 | W2: 目的港成本 | AC2: 总支出 | AD2: 利润
H3: 应收RMB | I3: LOS Income(NGN) 收到(奈拉) | J3: LOS 收到USD | K3: 美元汇率 dollar currency rate | L3: 应收 到付款USD | M3: 汇率 | N3: 人民币 | P3: 代理商 | Q3: 运费 | R3: 提货费 | S3: 送货费 | T3: 包装费 | W3: 进口报关费 | X3: 到门配送费 | Y3: 转运费 | Z3: 目的港支出 | AA3: 汇率 | AB3: 人民币 | AC3: 起运港+目的港
A4: JOB080355 | B4: COLL004086 | C4: 240729000061 | D4: 45509 | E4: 喵喵速运-Layne | F4: SHAEK | G4: 25.5 | I4: 286905 | K4: 1594.5368 | L4: 179.93 | M4: 7.15 | N4: 1286.4995 | O4: 64818.44 | P4: 顶派 | Q4: 49189 | S4: 181.75 | V4: 49658.75 | W4: 855.97 | Z4: 876.41 | AA4: 7.15 | AB4: 6266.3315 | AC4: 55925.082 | AD4: 8893.3585
C5: 240730000028 | D5: 45509 | E5: ying | F5: zhounengquan | G5: 3 | H5: 159 | N5: 159
C6: 240730000034 | D6: 45509 | E6: ying | F6: zhounengquan | G6: 0.28 | H6: 53 | N6: 53
C7: 240731000002 | D7: 45509 | E7: Isabel Zhu | F7: Wu Jiao Xing | G7: 3.5 | I7: 52182 | K7: 1592.8571 | L7: 32.76 | M7: 7.15 | N7: 234.234
C8: 240731000005 | D8: 45509 | E8: 喵喵速运-Layne | F8: Jinggang Pan | G8: 0.69 | I8: 14291 | K8: 1623.9773 | L8: 8.8 | M8: 7.15 | N8: 62.92
C9: 240731000006 | D9: 45509 | E9: 喵喵速运-Layne | F9: SHAEK | G9: 62.5 | I9: 737238 | K9: 1594.4763 | L9: 462.37 | M9: 7.15 | N9: 3305.9455 | U9: 181
C10: 240731000007 | D10: 45509 | E10: 喵喵速运-Layne | F10: Xiao Xiao | G10: 0.36 | H10: 94 | N10: 94 | X10: 3.44
C11: 240731000021 | D11: 45509 | E11: ying | F11: zhaojiqiang | G11: 648.5 | H11: 35667.5 | N11: 35667.5
C12: 240731000025 | D12: 45509 | E12: 喵喵速运-Layne | F12: REMI | G12: 0.36 | I12: 19120 | K12: 1710.1968 | L12: 11.18 | M12: 7.15 | N12: 79.937 | U12: 12
C13: 240731000026 | D13: 45509 | E13: Bella Chan | F13: li tao | G13: 4.5 | H13: 273 | N13: 273
C14: 240731000028 | D14: 45509 | E14: 喵喵速运-Layne | F14: William Xu | G14: 30.5 | I14: 401563 | K14: 1623.067 | L14: 247.41 | M14: 7.15 | N14: 1768.9815
C15: 240731000029 | D15: 45509 | E15: ying | F15: chenxiaojie | G15: 7 | I15: 93483 | K15: 1650.4767 | L15: 56.64 | M15: 7.15 | N15: 404.976
C16: 240731000033 | D16: 45509 | E16: ying | F16: Miss Yemisi | G16: 1 | H16: 63 | N16: 63
C17: 240731000035 | D17: 45509 | E17: Sam.Pao | F17: MaiKaiNian | G17: 27.5 | H17: 1585.5 | N17: 1585.5 | U17: 65
C18: 240731000037 | D18: 45509 | E18: Bella Chan | F18: new hope 边鹏飞 | G18: 94 | I18: 1160368.8 | K18: 1616 | L18: 718.05 | M18: 7.15 | N18: 5134.0575
C19: 240731000039 | D19: 45509 | E19: clarkzeng2 | F19: zengyugui | G19: 7.5 | H19: 478.5 | N19: 478.5
C20: 240801000002 | D20: 45509 | E20: Sam.Pao | F20: LiGuoFeng | G20: 12.5 | I20: 179939 | K20: 1623.9982 | L20: 110.8 | M20: 7.15 | N20: 792.22
C21: 240801000007 | D21: 45509 | E21: Isabel Zhu | F21: Gbenga | G21: 25.5 | I21: 336980 | K21: 1773.5789 | L21: 190 | M21: 7.15 | N21: 1358.5 | X21: 17
C22: 240801000008 | D22: 45509 | E22: Bella Chan | F22: new hope 边鹏飞 | G22: 0.82 | I22: 12346.24 | L22: 7.6400003 | M22: 7.15 | N22: 54.626002
C23: 240801000009 | D23: 45509 | E23: ying | F23: zhounengquan | G23: 2.5 | H23: 132.5 | N23: 132.5
C24: 240801000010 | D24: 45509 | E24: 喵喵速运-Layne | F24: Lin Qing Yuan | G24: 2 | I24: 25520 | K24: 1659.2978 | L24: 15.38 | M24: 7.15 | N24: 109.967
C25: 240801000011 | D25: 45509 | E25: 喵喵速运-Layne | F25: Ka Ka 4分部 | G25: 10 | H25: 600 | N25: 600
C26: 240801000012 | D26: 45509 | E26: 喵喵速运-Layne | F26: LEO WEI | G26: 31 | I26: 397358 | K26: 1580.2036 | L26: 251.46 | M26: 7.15 | N26: 1797.939
C27: 240801000016 | D27: 45509 | E27: Mr Wang | F27: Sowsco Well Services Nig Ltd | G27: 4 | H27: 374 | N27: 374
C28: 240801000021 | D28: 45509 | E28: Sam.Pao | F28: Jhon | G28: 2 | I28: 39144 | K28: 1666.4112 | L28: 23.49 | M28: 7.15 | N28: 167.9535
C29: 240802000003 | D29: 45509 | E29: Isabel Zhu | F29: Liang Liu Liu | G29: 2 | H29: 135 | N29: 135
C30: 240802000007 | D30: 45509 | E30: 喵喵速运-Layne | F30: REMI | G30: 67 | I30: 848689 | K30: 1708.8615 | L30: 496.64 | M30: 7.15 | N30: 3550.976
C31: 240802000011 | D31: 45509 | E31: 喵喵速运-Layne | F31: CHENG ZHONG | G31: 9 | I31: 123700 | K31: 1623.9989 | L31: 76.17 | M31: 7.15 | N31: 544.6155 | T31: 30
C32: 240802000014 | D32: 45509 | E32: Bella Chan | F32: Mary Oyebade | G32: 10 | I32: 129757.6 | K32: 1624 | L32: 79.9 | M32: 7.15 | N32: 571.285
C33: 240802000027 | D33: 45509 | E33: ying | F33: wangweijun | G33: 1.5 | I33: 20553 | K33: 1581 | L33: 13 | M33: 7.15 | N33: 92.95
C34: 240802000030 | D34: 45509 | E34: Isabel Zhu | F34: Latoyaandstyles | G34: 0.54 | I34: 14191.2 | K34: 1612.6364 | L34: 8.8 | M34: 7.15 | N34: 62.92
C35: 240802000031 | D35: 45509 | E35: 喵喵速运-Layne | F35: SF Jerry 顾 | G35: 4.5 | H35: 238.5 | N35: 238.5
C36: 240802000039 | D36: 45509 | E36: 喵喵速运-Layne | F36: William Xu | G36: 3 | I36: 39498 | K36: 1623.4279 | L36: 24.33 | M36: 7.15 | N36: 173.9595
C37: 240802000040 | D37: 45509 | E37: 喵喵速运-Layne | F37: Hu Hai Liang | G37: 60.5 | I37: 785592.5 | K37: 1751.756 | L37: 448.46 | M37: 7.15 | N37: 3206.489
C38: 240802000041 | D38: 45509 | E38: 喵喵速运-Layne | F38: William Xu | G38: 3.5 | I38: 46081 | K38: 1623.142 | L38: 28.39 | M38: 7.15 | N38: 202.9885
A39: JOB080356 | B39: COLL004090 | C39: 240731000036 | D39: 45510 | E39: 喵喵速运-Layne | F39: Ye Hui | G39: 8.5 | I39: 219895 | K39: 1580.1595 | L39: 139.16 | M39: 7.15 | N39: 994.994 | O39: 4889.91 | P39: 富姐 | Q39: 2400 | S39: 63.65 | U39: 75.5 | V39: 2539.15 | W39: 108.19 | Z39: 108.19 | AA39: 7.15 | AB39: 773.5585 | AC39: 3312.7085 | AD39: 1577.2015
C40: 240802000034 | D40: 45510 | E40: 喵喵速运-Layne | F40: SF Jerry 顾 | G40: 9 | H40: 1035 | N40: 1035
...

Sheet 9月份
A1: 尼日利亚拉各斯（LOS） 应收利润明细表
A2: JOB | B2: 集装编号 | C2: 运单编号 | D2: 日期 | E2: 发货人 | F2: 收货人 | G2: 计费重量 | H2: 应 收 | O2: 总应收 | P2: 起 运 港 成 本 | U2: 代垫运费 | V2: 起运港成本 合计 | W2: 目的港成本 | AC2: 总支出 | AD2: 利润
H3: 应收RMB | I3: LOS Income(NGN) 收到(奈拉) | J3: LOS 收到USD | K3: 美元汇率 dollar currency rate | L3: 应收 到付款USD | M3: 汇率 | N3: 人民币 | P3: 代理商 | Q3: 运费 | R3: 提货费 | S3: 送货费 | T3: 包装费 | W3: 进口报关费 | X3: 到门配送费 | Y3: 转运费 | Z3: 目的港支出 | AA3: 汇率 | AB3: 人民币 | AC3: 起运港+目的港
A4: JOB090348 | B4: COLL004137 | C4: 240823000023 | D4: 45537 | E4: MailMail速运-演员 | F4: chenchen | G4: 2.5 | H4: 319.5 | N4: 319.5 | O4: 5142.9024 | P4: 富姐 | Q4: 2500 | S4: 71.98 | V4: 2669.98 | W4: 129.27 | Z4: 129.27 | AA4: 7.08 | AB4: 915.2316 | AC4: 3585.2116 | AD4: 1557.6908
C5: 240828000001 | D5: 45537 | E5: Sam.Pao | F5: YunLong Hu | G5: 9 | I5: 238050 | K5: 1628.4717 | L5: 146.18 | M5: 7.08 | N5: 1034.9544
C6: 240828000006 | D6: 45537 | E6: Isabel Zhu | F6: KeKe | G6: 3.5 | H6: 420 | N6: 420
C7: 240828000068 | D7: 45537 | E7: Bella Chan | F7: Ai Ge Li | G7: 0.85866666 | H7: 255 | N7: 255
C8: 240829000002 | D8: 45537 | E8: Isabel Zhu | F8: Jumoke | G8: 3.5 | H8: 402 | N8: 402
C9: 240829000008 | D9: 45537 | E9: 喵喵速运-Layne | F9: Chen Yi | G9: 1.5 | I9: 56643 | K9: 1678.3111 | L9: 33.75 | M9: 7.08 | N9: 238.95
C10: 240829000027 | D10: 45537 | E10: 喵喵速运-Layne | F10: Mr.Jin | G10: 1.5 | H10: 172.5 | N10: 172.5
C11: 240829000035 | D11: 45537 | E11: 喵喵速运-Layne | F11: NAN GUA | G11: 0.52 | H11: 170 | N11: 170
C12: 240829000038 | D12: 45537 | E12: 喵喵速运-Layne | F12: MA ZONG | G12: 0.94 | H12: 120 | N12: 120
C13: 240830000006 | D13: 45537 | E13: Isabel Zhu | F13: Liu Mao | G13: 0.5 | H13: 170 | N13: 170
C14: 240830000007 | D14: 45537 | E14: Isabel Zhu | F14: Liu Mao | G14: 0.8 | H14: 255 | N14: 255
C15: 240830000008 | D15: 45537 | E15: Isabel Zhu | F15: Liu Mao | G15: 0.9 | H15: 170 | N15: 170
C16: 240830000009 | D16: 45537 | E16: Isabel Zhu | F16: Liu Mao | G16: 0.8 | H16: 170 | N16: 170
C17: 240830000011 | D17: 45537 | E17: Isabel Zhu | F17: Liu Mao | G17: 0.68 | H17: 170 | N17: 170
C18: 240830000043 | D18: 45537 | E18: 喵喵速运-Layne | F18: Lin Qing Yuan | G18: 6.5 | I18: 207025 | K18: 1734.6041 | L18: 119.35 | M18: 7.08 | N18: 844.998 | U18: 98
C19: 240831000001 | D19: 45537 | E19: Sam.Pao | F19: ChenBin | G19: 2 | H19: 230 | N19: 230
A20: JOB090349 | B20: COLL004140 | C20: 240829000031 | D20: 45538 | E20: Bella Chan | F20: Jahnson | G20: 2 | H20: 360 | N20: 360 | O20: 10760 | P20: 富姐 | Q20: 4800 | S20: 55.98 | V20: 4855.98 | W20: 252.83 | Z20: 273.95 | AA20: 7.08 | AB20: 1939.566 | AC20: 6795.546 | AD20: 3964.454
C21: 240830000010 | D21: 45538 | E21: Isabel Zhu | F21: Liu Mao | G21: 0.68 | H21: 170 | N21: 170
C22: 240830000012 | D22: 45538 | E22: Isabel Zhu | F22: Liu Mao | G22: 0.9 | H22: 170 | N22: 170
C23: 240830000032 | D23: 45538 | E23: ying | F23: luzong | G23: 0.56 | H23: 115 | N23: 115
C24: 240831000017 | D24: 45538 | E24: 喵喵速运-Layne | F24: LING | G24: 2 | H24: 340 | N24: 340
C25: 240831000018 | D25: 45538 | E25: 喵喵速运-Layne | F25: MA ZONG | G25: 6.5 | H25: 780 | N25: 780
C26: 240901000007 | D26: 45538 | E26: ying | F26: Han | G26: 2 | H26: 300 | N26: 300
C27: 240901000008 | D27: 45538 | E27: 喵喵速运-Layne | F27: Zheng Hao | G27: 15 | H27: 1800 | N27: 1800
C28: 240902000001 | D28: 45538 | E28: Julie LEE | F28: Julie lee | G28: 6 | H28: 720 | N28: 720
C29: 240902000004 | D29: 45538 | E29: Julie LEE | F29: Julie lee | G29: 1.5 | H29: 180 | N29: 180
C30: 240902000019 | D30: 45538 | E30: 喵喵速运-Layne | F30: Sule Adekunle | G30: 8 | H30: 950 | N30: 950 | X30: 21.12
C31: 240902000051 | D31: 45538 | E31: 喵喵速运-Layne | F31: Rabiu Mohammed | G31: 7.5 | H31: 1560 | N31: 1560
C32: 240902000052 | D32: 45538 | E32: 喵喵速运-Layne | F32: Rabiu Mohammed | G32: 5.5 | H32: 1365 | N32: 1365
C33: 240902000053 | D33: 45538 | E33: 喵喵速运-Layne | F33: Rabiu Mohammed | G33: 9 | H33: 1950 | N33: 1950
A34: JOB090353 | B34: COLL004146 | C34: 240830000034 | D34: 45540 | E34: ying | F34: jj | G34: 0.7475 | I34: 35550 | K34: 1678.4703 | L34: 21.18 | M34: 7.08 | N34: 149.9544 | O34: 8272.4544 | P34: 富姐 | Q34: 4800 | S34: 51.08 | V34: 4946.08 | W34: 177.2 | Z34: 177.2 | AA34: 7.08 | AB34: 1254.576 | AC34: 6200.656 | AD34: 2071.7984
C35: 240902000002 | D35: 45540 | E35: Julie LEE | F35: Julie lee | G35: 1.5 | H35: 120 | N35: 120
C36: 240902000010 | D36: 45540 | E36: 喵喵速运-Layne | F36: Lee Wen Wei | G36: 5 | H36: 800 | N36: 800
C37: 240902000026 | D37: 45540 | E37: Isabel Zhu | F37: Mr.Wang Mian | G37: 0.76 | H37: 115 | N37: 115
C38: 240902000035 | D38: 45540 | E38: Isabel Zhu | F38: Long Er | G38: 9 | H38: 1080 | N38: 1080
C39: 240903000023 | D39: 45540 | E39: Bella Chan | F39: shangyafei | G39: 45.5 | H39: 5555 | N39: 5555 | T39: 95
C40: 240903000036 | D40: 45540 | E40: Sam.Pao | F40: MaiKaiNian | G40: 1.5 | H40: 172.5 | N40: 172.5
...

Sheet 10月份
A1: 尼日利亚拉各斯（LOS） 应收利润明细表
A2: JOB | B2: 集装编号 | C2: 运单编号 | D2: 日期 | E2: 发货人 | F2: 收货人 | G2: 计费重量 | H2: 应 收 | O2: 总应收 | P2: 起 运 港 成 本 | U2: 代垫运费 | V2: 起运港成本 合计 | W2: 目的港成本 | AC2: 总支出 | AD2: 利润
H3: 应收RMB | I3: LOS Income(NGN) 收到(奈拉) | J3: LOS 收到USD | K3: 美元汇率 dollar currency rate | L3: 应收 到付款USD | M3: 汇率 | N3: 人民币 | P3: 代理商 | Q3: 运费 | R3: 提货费 | S3: 送货费 | T3: 包装费 | W3: 进口报关费 | X3: 到门配送费 | Y3: 转运费 | Z3: 目的港支出 | AA3: 汇率 | AB3: 人民币 | AC3: 起运港+目的港
A4: JOB100324 | B4: COLL004186 | C4: 240930000011 | D4: 45572 | E4: ying | F4: zhang feng | G4: 17.5 | H4: 2537.5 | N4: 2537.5 | O4: 9845.6346 | P4: 富姐 | Q4: 4800 | S4: 50.98 | V4: 4850.98 | W4: 217.37 | Z4: 217.37 | AA4: 7.11 | AB4: 1545.5007 | AC4: 6396.4807 | AD4: 3449.1539
C5: 240930000013 | D5: 45572 | E5: Isabel Zhu | F5: Liu Mao | G5: 5.5 | H5: 632 | N5: 632
C6: 240930000049 | D6: 45572 | E6: KAY | F6: YEMBA BOB MAI | G6: 0.1 | H6: 120 | N6: 120
C7: 241002000009 | D7: 45572 | E7: Sam.Pao | F7: ChengZhen | G7: 8 | H7: 1620 | N7: 1620
C8: 241002000012 | D8: 45572 | E8: Sam.Pao | F8: MaiKaiNian | G8: 1.5 | H8: 172.5 | N8: 172.5
C9: 241003000001 | D9: 45572 | E9: Isabel Zhu | F9: Tony | G9: 5.5 | H9: 660 | N9: 660
C10: 241004000010 | D10: 45572 | E10: Julie LEE | F10: Julie lee | G10: 9.5 | H10: 1140 | N10: 1140
C11: 241004000013 | D11: 45572 | E11: JiaFeng | F11: jiafeng | G11: 2 | I11: 56224 | K11: 1711.0164 | L11: 32.86 | M11: 7.11 | N11: 233.6346
C12: 241004000014 | D12: 45572 | E12: Bella Chan | F12: Dan Dan | G12: 21.5 | H12: 2580 | N12: 2580
C13: 241004000018 | D13: 45572 | E13: KAY | F13: CHIMEZIE MARTIN | G13: 0.1 | H13: 150 | N13: 150
A14: JOB100325 | B14: COLL004190 | C14: 241005000006 | D14: 45575 | E14: Isabel Zhu | F14: A Lan | G14: 3 | I14: 88896 | K14: 1728.4853 | L14: 51.43 | M14: 7.11 | N14: 365.6673 | O14: 4808.8697 | P14: 富姐 | Q14: 2400 | S14: 78.67 | V14: 2509.67 | W14: 140.27 | Z14: 146.59 | AA14: 7.11 | AB14: 1042.2549 | AC14: 3551.9249 | AD14: 1256.9448
C15: 241005000009 | D15: 45575 | E15: Isabel Zhu | F15: Lin Ming Ze | G15: 0.5 | I15: 65660 | K15: 1742.1067 | L15: 37.69 | M15: 7.11 | N15: 267.9759 | U15: 18
C16: 241006000008 | D16: 45575 | E16: Sam.Pao | F16: Diana | G16: 6 | I16: 137655 | K16: 1702.1763 | L16: 80.87 | M16: 7.11 | N16: 574.9857
C17: 241006000010 | D17: 45575 | E17: Julie LEE | F17: Julie lee | G17: 2 | H17: 240 | N17: 240
C18: 241007000002 | D18: 45575 | E18: Sam.Pao | F18: Angel | G18: 1.5 | H18: 172.5 | N18: 172.5
C19: 241007000003 | D19: 45575 | E19: Sam.Pao | F19: XianShiRenSheng | G19: 3 | H19: 435 | N19: 435
C20: 241007000005 | D20: 45575 | E20: Isabel Zhu | F20: Liu Mao | G20: 0.58 | H20: 115 | N20: 115
C21: 241008000011 | D21: 45575 | E21: 喵喵速运-Layne | F21: BFSH | G21: 3.5 | H21: 420 | N21: 420
C22: 241008000025 | D22: 45575 | E22: 喵喵速运-Layne | F22: jeason Cai | G22: 1 | H22: 145 | N22: 145
C23: 241008000062 | D23: 45575 | E23: JiaFeng | F23: jiafeng | G23: 1.5 | I23: 42200 | K23: 1712.6623 | L23: 24.64 | M23: 7.11 | N23: 175.1904
C24: 241008000070 | D24: 45575 | E24: Kelly | F24: AKai | G24: 0.42 | I24: 28181 | K24: 1711.0504 | L24: 16.47 | M24: 7.11 | N24: 117.1017
C25: 241008000079 | D25: 45575 | E25: Bella Chan | F25: YEMI | G25: 0.8 | I25: 31104 | K25: 1728 | L25: 18 | M25: 7.11 | N25: 127.98 | U25: 13
C26: 241008000081 | D26: 45575 | E26: 喵喵速运-Layne | F26: Sue | G26: 2 | H26: 275 | N26: 275 | X26: 6.32
C27: 241008000090 | D27: 45575 | E27: ying | F27: wangmeng | G27: 0.1 | H27: 115 | N27: 115
C28: 241008000093 | D28: 45575 | E28: ying | F28: Wangjianshe | G28: 0.5 | H28: 190 | N28: 190
C29: 241008000097 | D29: 45575 | E29: MailMail速运-演员 | F29: Miss Chen | G29: 0.4 | H29: 145 | N29: 145
C30: 241008000104 | D30: 45575 | E30: 喵喵速运-Layne | F30: SF Jerry 顾 | G30: 6.5 | H30: 812.5 | N30: 812.5
C31: 241008000107 | D31: 45575 | E31: Sam.Pao | F31: Diana | G31: 0.28 | I31: 27945 | K31: 1728.2004 | L31: 16.17 | M31: 7.11 | N31: 114.9687
A32: JOB100328 | B32: COLL004193 | C32: 240928000020 | D32: 45578 | E32: Sam.Pao | F32: JACK | G32: 5.5 | I32: 89424 | K32: 1728 | L32: 51.75 | M32: 7.11 | N32: 367.9425 | O32: 4037.9821 | P32: 富姐 | Q32: 2400 | S32: 55.98 | V32: 2473.98 | W32: 130.03 | Z32: 130.03 | AA32: 7.11 | AB32: 924.5133 | AC32: 3398.4933 | AD32: 639.4888
C33: 241008000005 | D33: 45578 | E33: 喵喵速运-Layne | F33: Robin Tai | G33: 0.78 | I33: 28002.5 | K33: 1731.7563 | L33: 16.17 | M33: 7.11 | N33: 114.9687
C34: 241008000033 | D34: 45578 | E34: 喵喵速运-Layne | F34: SHAEK | G34: 3.5 | H34: 402.5 | N34: 402.5
C35: 241008000052 | D35: 45578 | E35: Isabel Zhu | F35: Cammille | G35: 4.5 | I35: 132300 | K35: 1742.1649 | L35: 75.94 | M35: 7.11 | N35: 539.9334
C36: 241008000067 | D36: 45578 | E36: ying | F36: DAVID | G36: 0.79 | H36: 106.2 | N36: 106.2 | U36: 18
C37: 241009000024 | D37: 45578 | E37: Kelly | F37: AKai | G37: 2.5 | I37: 66944.1 | K37: 1630 | L37: 41.07 | M37: 7.11 | N37: 292.0077
C38: 241009000025 | D38: 45578 | E38: Kelly | F38: AKai | G38: 7 | I38: 187450 | K38: 1630 | L38: 115 | M38: 7.11 | N38: 817.65
C39: 241009000034 | D39: 45578 | E39: 13635229849 | F39: weng zixian | G39: 0.56 | I39: 29627 | K39: 1728.5298 | L39: 17.14 | M39: 7.11 | N39: 121.8654
C40: 241009000039 | D40: 45578 | E40: 土狗泥 | F40: TOYIN S.ADEKUNLE | G40: 3.5 | H40: 402.5 | N40: 402.5
...

Sheet 11月份
A1: 尼日利亚拉各斯（LOS） 应收利润明细表
A2: JOB | B2: 集装编号 | C2: 运单编号 | D2: 日期 | E2: 发货人 | F2: 收货人 | G2: 计费重量 | H2: 应 收 | O2: 总应收 | P2: 起 运 港 成 本 | U2: 代垫运费 | V2: 起运港成本 合计 | W2: 目的港成本 | AC2: 总支出 | AD2: 利润
H3: 应收RMB | I3: LOS Income(NGN) 收到(奈拉) | J3: LOS 收到USD | K3: 美元汇率 dollar currency rate | L3: 应收 到付款USD | M3: 汇率 | N3: 人民币 | P3: 代理商 | Q3: 运费 | R3: 提货费 | S3: 送货费 | T3: 包装费 | W3: 进口报关费 | X3: 到门配送费 | Y3: 转运费 | Z3: 目的港支出 | AA3: 汇率 | AB3: 人民币 | AC3: 起运港+目的港
A4: JOB110333 | B4: COLL004227 | C4: 241028000050 | D4: 45598 | E4: ying | F4: leoyang | G4: 2 | H4: 230 | N4: 230 | O4: 12226.288 | P4: 富姐 | Q4: 7200 | S4: 55.98 | V4: 7255.98 | W4: 194.17 | Z4: 199.97 | AA4: 7.2 | AB4: 1439.784 | AC4: 8695.764 | AD4: 3530.524
C5: 241029000015 | D5: 45598 | E5: ying | F5: CAO ZHIJUN | G5: 1.5 | I5: 29645 | K5: 1764.5833 | L5: 16.8 | M5: 7.2 | N5: 120.96
C6: 241029000043 | D6: 45598 | E6: dejare James | F6: COD victor | G6: 1.5 | L6: 25.35 | M6: 7.2 | N6: 182.52
C7: 241030000018 | D7: 45598 | E7: ying | F7: chenxiaojie | G7: 49.5 | I7: 1383277.5 | K7: 1749.6111 | L7: 790.62 | M7: 7.2 | N7: 5692.464
C8: 241030000023 | D8: 45598 | E8: 喵喵速运-Layne | F8: Le Bin | G8: 0.9375 | H8: 120 | N8: 120
C9: 241031000004 | D9: 45598 | E9: 喵喵速运-Layne | F9: FEN | G9: 5 | H9: 550 | N9: 550
C10: 241031000005 | D10: 45598 | E10: 喵喵速运-Layne | F10: MO JI | G10: 0.14 | I10: 29400 | K10: 1764.7059 | L10: 16.66 | M10: 7.2 | N10: 119.952
C11: 241031000010 | D11: 45598 | E11: Julie LEE | F11: Julie lee | G11: 0.83 | H11: 120 | N11: 120
C12: 241031000016 | D12: 45598 | E12: Bella Chan | F12: zhang yong chong | G12: 0.1 | I12: 28251 | K12: 1744.9661 | L12: 16.189999 | M12: 7.2 | N12: 116.56799
C13: 241031000017 | D13: 45598 | E13: ying | F13: chenxiaojie | G13: 3 | I13: 83835 | K13: 1749.8435 | L13: 47.91 | M13: 7.2 | N13: 344.952
C14: 241031000038 | D14: 45598 | E14: Julie LEE | F14: Julie lee | G14: 3 | H14: 360 | N14: 360
C15: 241031000040 | D15: 45598 | E15: Isabel Zhu | F15: Mr Li | G15: 7.5 | I15: 219466 | K15: 1748.1759 | L15: 125.54 | M15: 7.2 | N15: 903.888 | X15: 5.8
C16: 241031000049 | D16: 45598 | E16: 喵喵速运-Layne | F16: Li Li | G16: 1.5 | H16: 370 | N16: 370
C17: 241101000001 | D17: 45598 | E17: 喵喵速运-Layne | F17: Li Li | G17: 0.7 | H17: 330 | N17: 330
C18: 241101000007 | D18: 45598 | E18: Sam.Pao | F18: Mr. Jiang | G18: 6 | H18: 690 | N18: 690
C19: 241101000013 | D19: 45598 | E19: 喵喵速运-Layne | F19: Kola | G19: 5.5 | H19: 660 | N19: 660
C20: 241101000014 | D20: 45598 | E20: Bella Chan | F20: shangyafei | G20: 10 | H20: 1200 | N20: 1200
C21: 241101000036 | D21: 45598 | E21: 喵喵速运-Layne | F21: jeason Cai | G21: 0.36 | I21: 28175 | K21: 1764.2455 | L21: 15.97 | M21: 7.2 | N21: 114.984
A22: JOB110334 | B22: COLL004228 | C22: 241031000009 | D22: 45599 | E22: Julie LEE | F22: Julie lee | G22: 2 | H22: 240 | N22: 240 | O22: 3612.452 | P22: 富姐 | Q22: 2400 | S22: 55.98 | V22: 2455.98 | W22: 49.44 | Z22: 49.44 | AA22: 7.2 | AB22: 355.968 | AC22: 2811.948 | AD22: 800.504
C23: 241031000014 | D23: 45599 | E23: Isabel Zhu | F23: Bruce | G23: 8 | H23: 920 | N23: 920
C24: 241101000006 | D24: 45599 | E24: 喵喵速运-Layne | F24: Rabiu Mohammed | G24: 11.5 | H24: 1322.5 | N24: 1322.5
C25: 241102000020 | D25: 45599 | E25: 喵喵速运-Layne | F25: Rabiu Mohammed | G25: 5.5 | H25: 632.5 | N25: 632.5
C26: 241102000021 | D26: 45599 | E26: 喵喵速运-Layne | F26: DIKE | G26: 2 | I26: 51450 | K26: 1764.4033 | L26: 29.16 | M26: 7.2 | N26: 209.952
C27: 241102000024 | D27: 45599 | E27: 喵喵速运-Layne | F27: YI YUE | G27: 2.5 | H27: 287.5 | N27: 287.5
A28: JOB110337 | B28: COLL004231 | C28: 241029000022 | D28: 45600 | E28: Bella Chan | F28: Zou Qiyang | G28: 106 | H28: 12850 | N28: 12850 | O28: 100026.98 | P28: 方显 | Q28: 76600 | S28: 174.5 | V28: 77442.5 | W28: 1337.25 | Z28: 1580.82 | AA28: 7.2 | AB28: 11381.904 | AC28: 88824.404 | AD28: 11202.58
C29: 241029000033 | D29: 45600 | E29: ying | F29: Vicky Kuo | G29: 162.5 | H29: 10093 | N29: 10093 | T29: 120 | U29: 548
C30: 241031000011 | D30: 45600 | E30: Isabel Zhu | F30: Mr Chen | G30: 131 | H30: 8160 | N30: 8160 | X30: 42.19
C31: 241101000044 | D31: 45600 | E31: 喵喵速运-Layne | F31: Sun Li | G31: 719.5 | I31: 10931900 | K31: 1764.0006 | L31: 6197.22 | M31: 7.2 | N31: 44619.984 | X31: 201.38
C32: 241101000055 | D32: 45600 | E32: 陆梓龙 | F32: lagosxu | G32: 434 | H32: 24304 | N32: 24304
A33: JOB110338 | B33: COLL004219 | C33: 241026000011 | D33: 45601 | E33: 喵喵速运-Layne | F33: LING | G33: 0.68 | H33: 72 | N33: 72 | O33: 147005.59 | P33: 顶派=113263 广州通达=6034.4 | Q33: 119297.4 | R33: 76.68 | S33: 188.91 | V33: 120784.99 | W33: 1322.57 | Z33: 1374.6 | AA33: 7.2 | AB33: 9897.12 | AC33: 130682.11 | AD33: 16323.478
C34: 241027000013 | D34: 45601 | E34: Sam.Pao | F34: XianShiRenSheng | G34: 11.5 | H34: 731 | N34: 731
C35: 241028000004 | D35: 45601 | E35: 喵喵速运-Layne | F35: Shu He | G35: 4 | H35: 263 | N35: 263
C36: 241028000007 | D36: 45601 | E36: 喵喵速运-Layne | F36: Li Yang Yang | G36: 65.5 | I36: 1013198 | K36: 1764.0162 | L36: 574.37 | M36: 7.2 | N36: 4135.464
C37: 241028000016 | D37: 45601 | E37: Isabel Zhu | F37: Zhao Zi Cheng | G37: 5.5 | H37: 439 | N37: 439
C38: 241028000019 | D38: 45601 | E38: Bella Chan | F38: zhang yong chong | G38: 1.5 | I38: 24900 | K38: 1744.9194 | L38: 14.27 | M38: 7.2 | N38: 102.744
C39: 241028000033 | D39: 45601 | E39: ying | F39: Arvin | G39: 1.5 | H39: 106.5 | N39: 106.5
C40: 241028000042 | D40: 45601 | E40: Bella Chan | F40: chidi | G40: 103 | I40: 1538741 | K40: 1745 | L40: 881.8 | M40: 7.2 | N40: 6348.96
...

Sheet 12月份
A1: 尼日利亚拉各斯（LOS） 应收利润明细表
A2: JOB | B2: 集装编号 | C2: 运单编号 | D2: 日期 | E2: 发货人 | F2: 收货人 | G2: 计费重量 | H2: 应 收 | O2: 总应收 | P2: 起 运 港 成 本 | U2: 代垫运费 | V2: 起运港成本 合计 | W2: 目的港成本 | AC2: 总支出 | AD2: 利润
H3: 应收RMB | I3: LOS Income(NGN) 收到(奈拉) | J3: LOS 收到USD | K3: 美元汇率 dollar currency rate | L3: 应收 到付款USD | M3: 汇率 | N3: 人民币 | P3: 代理商 | Q3: 运费 | R3: 提货费 | S3: 送货费 | T3: 包装费 | W3: 进口报关费 | X3: 到门配送费 | Y3: 转运费 | Z3: 目的港支出 | AA3: 汇率 | AB3: 人民币 | AC3: 起运港+目的港
A4: JOB120355 | B4: COLL004274 | C4: 241126000002 | D4: 45628 | E4: Isabel Zhu | F4: Yang Xin Hui | G4: 1.5 | H4: 180 | N4: 180 | O4: 13623.496 | P4: 富姐 | Q4: 7740 | S4: 70.98 | V4: 7810.98 | W4: 288.25 | Z4: 293.11 | AA4: 7.27 | AB4: 2130.9097 | AC4: 9941.8897 | AD4: 3681.606
C5: 241127000016 | D5: 45628 | E5: KAY | F5: Liu | G5: 2 | H5: 230 | N5: 230
C6: 241127000018 | D6: 45628 | E6: 喵喵速运-Layne | F6: Li Li | G6: 1.5 | H6: 172.5 | N6: 172.5
C7: 241127000020 | D7: 45628 | E7: 喵喵速运-Layne | F7: Liu Yan | G7: 1.5 | I7: 78880 | K7: 1686.9119 | L7: 46.76 | M7: 7.27 | N7: 339.9452
C8: 241127000029 | D8: 45628 | E8: Isabel Zhu | F8: Eric | G8: 5 | H8: 575 | N8: 575
C9: 241128000004 | D9: 45628 | E9: Isabel Zhu | F9: Liu Mao | G9: 37.5 | H9: 4312 | N9: 4312
C10: 241128000006 | D10: 45628 | E10: Isabel Zhu | F10: Ibrahim Abdullahi | G10: 3 | H10: 360 | N10: 360
C11: 241128000018 | D11: 45628 | E11: Isabel Zhu | F11: Wu Jiao Xing | G11: 1.5 | H11: 172.5 | N11: 172.5
C12: 241128000032 | D12: 45628 | E12: KAY | F12: Ah Ming | G12: 2.5 | H12: 287.5 | N12: 287.5
C13: 241129000004 | D13: 45628 | E13: Isabel Zhu | F13: Ge Ge | G13: 1.5 | H13: 373 | N13: 373
C14: 241129000007 | D14: 45628 | E14: Isabel Zhu | F14: Wu Jiao Xing | G14: 3.5 | H14: 402.5 | N14: 402.5
C15: 241129000016 | D15: 45628 | E15: Bella Chan | F15: Doris | G15: 2 | I15: 56350 | K15: 1781.5365 | L15: 31.63 | M15: 7.27 | N15: 229.9501
C16: 241129000030 | D16: 45628 | E16: Mailmail Abv sales person 1 | F16: Fafunso | G16: 0.1 | I16: 27900 | K16: 1747.0258 | L16: 15.969999 | M16: 7.27 | N16: 116.10189
C17: 241129000032 | D17: 45628 | E17: 喵喵速运-Layne | F17: Jimmy | G17: 2.5 | H17: 680 | N17: 680
C18: 241129000041 | D18: 45628 | E18: Isabel Zhu | F18: Liu Mao | G18: 12.5 | H18: 1437.5 | N18: 1437.5
C19: 241129000047 | D19: 45628 | E19: ying | F19: liangdawei | G19: 0.45 | H19: 150 | N19: 150 | X19: 4.86
C20: 241129000048 | D20: 45628 | E20: ying | F20: liangdawei | G20: 0.56666666 | H20: 145 | N20: 145
C21: 241129000049 | D21: 45628 | E21: ying | F21: liangdawei | G21: 0.38 | H21: 115 | N21: 115
C22: 241129000050 | D22: 45628 | E22: ying | F22: liangdawei | G22: 1 | H22: 145 | N22: 145
